Workbook

Sheet README
A1: Tokenomics v6.0 — Block 1＋2＋3＋4＋5＋6＋第 0 層 Source：機架規格、每 GW 成本、各層級產出與每 token 成本、訓練與研發計畫、理論營收與單價前緣、harness 與每成功任務成本、研發與服務算力配置（Alloc）、L1 常用推算值、Interface 下游介面
A2: 第 0 層規格來源。理論營收為理想上限；實際營收在下游模型。
A4: 用途 | B4: 回答：每 1 GW IT 電力，各世代可容納多少機架、資本支出與持有成本（Block 1）；各層級 SLO 下的產出與依『世代 × 層級 × token 類型』的每 M token 成本（Block 2）；各層級代表模型的訓練與研發計畫需要多少 GPU 小時、成本與 1 GW 年，其中後訓練占多少（Block 3）；每 GW 的理論營收（理想上限）、含中國廠商的單價前緣、訓練攤提、快取儲存與 1 GW 參考機隊（Block 4）；harness 對每個成功任務的 token、成本與成功率的影響（Block 5）。實際營收（需求、市占、訂閱方案）在下游。
A5: 版本 | B5: 20261015_Tokenomics_v6.0（主版：下游契約定義變更，工作單 docs/workorders/20261015_稽核修正1.md r0——D7 `_Prod` 為重解 SLO 後的產能（IFW_TokGW_*_Prod 讀 Theory_Rev_Prod；m 下限與前緣單價改用重解後的付費產能比 AL_ProdRatioPaid），`_Life` 唯一定義為 IFW_*_Life（IF_*_Life 為過渡別名，下一個主版刪除），Checks Z1 為 _Prod 恆等式；D8 SLO 不可達輸出文字、不輸出 0（Perf／Training 消費端），Fleet_1GW 排除不可達層級並重新正規化；D11 回本溢價分母改為付費 token（IF_AmortBU_*／IF_FullCost_*／IF_FullCostDefault_* 上升）；Decisions D7／D8／D11）。以下為 v5.36（判斷類，工作單 docs/workorders/20261015_v5.36.md r0：token 分母閉合——推論支出改 OpenAI 端 SRC_DEM_004 8.4（區間 7.5–8.8；SRC_DEM_073 查核財報營業成本 7.5），Microsoft 端 SRC_DEM_018 12.6 改為對照列；計價倍數 2.0 → 1.3（1.0–1.6）；新增請求形狀修正 κ（1.0；0.65–1.2）取代 GapISL；落差分解改正（GapPrompt 有效倍數 1.3013、GapUtil 1.7143）與缺口恆等式（Cap_In J 節、Checks M5）；L1 新增 L1_ScaleServe2000、L1_PriceRealFleet／PriceRealDemand／PriceReqBE／PriceRho；DB_Evidence E344–E365、Decisions X45–X47；AL_ServeGWSpend 1.3471 → 0.8981、L1_ScaleServe 7.378 → 4.919、L1_MFleet 0.8098 → 0.7896；全部 IF_ 不變）。以下為 v5.35（判斷類，工作單 docs/workorders/20261014_v5.35.md r0：m 序列三項修正＋L 拆分——Cap_In H10 三分營收改以 m 分子營收為基底、廣告每欄各自輸入（Q1 0／Q2 0.5／FY2026 1.0）、2026 消費訂閱占付費 token 份額 0.65（2026 Q2 m_API 0.340、m_消費訂閱 5.399、m_商用席次 4.557、m_整體 1.343）；新增 I 節「L 拆分」L_total＝L_price × L_demote（基準 0.7412 × 0.867＝0.6426；g −0.10、T1 4、ρ 0.5、T＝IF_DeprLifeIT 6）與回本所需 L（m＝L1_MFleet 0.3645）；L1 新增 L1_LPrice、L1_LDemote、L1_LTotal、L1_LReqFleet；SRC_DEM_072、DB_Evidence E338–E343、Decisions X42–X44；既有 IF_、L1_ 數值全部不變；CTL_PriceLife／CTL_Monetize 不改）。以下為 v5.34（判斷類，工作單 docs/workorders/20261014_v5.34.md r0.1：變現率 m 細化——Cap_In 新增 H8「m 分拆」（營收三分 消費訂閱／商用席次／API × token 三分 → m_API 0.56、m_消費訂閱 4.26、m_商用席次 1.83、m_整體 1.743＝L1_MImplied；m_API＝折讓因子 × 隱含組合因子；訂閱 m 下限（方案上限讀法）；「必須為真」；J21 Anthropic 對照）、H9「token 帳三路線」（需求／機隊／上限、殘差、閉合解 τ* ≈ 13,950）、H10「m 季度序列」（2025／2026 Q1／Q2／FY2026；份額每欄各自輸入）；L1 新增 L1_MAPI、L1_MSub、L1_MSeat、L1_MixFactorAPI、L1_TokPerPromptClose、L1_MAPI_Anthropic；Checks M4；B4_Disc 高端 0.3 → 0.4（Cap_In E12；IF_Price* 不變）；SRC_DEM_069–071、DB_Evidence E325–E337、Decisions X35–X41；既有 IF_、L1_ 數值全部不變；CTL_Monetize 不改）。以下為 v5.33（判斷類，工作單 docs/workorders/20261012_v5.33.md r1；A 段查證 PR #40：付費 token 數量校準——Alloc_In 2025 基準年世代組合改 Hopper 0.6／GB200 0.4／GB300 0／VR200 0（J8）、每則提示 token 數高端 6,400 → 11,000（J9）；Cap_In 新增 H7「機隊口徑」（支出路線服務 GW ÷ Azure 倍數 × 利用率修正 → 機隊付費 token 點估計與上限 → 機隊 m、m 下限、「必須為真」三列、非文字對照）；L1 新增 L1_MFleet、L1_TokCeiling，Checks M2、M3；SRC_DEM_049–068、DB_Evidence E302–E324、Decisions X27–X34；IF_AllocQ1／Q1_R2／Q2／ServeGW／ImpliedNk 與 Alloc 相關 L1 隨世代組合改變，其餘 IF_ 不變；CTL_Monetize 不改）。以下為 v5.32（判斷類，工作單 docs/workorders/20261011_v5.32.md r1；A 段查證 PR #38：變現率 m 追蹤——Cap_In 新增 H 節「m 追蹤」（隱含 m＝付費營收 ÷（付費 token × 混合有效單價），訂閱、API、合併 × 模型 token、外部 token 兩種分母；程式代理對照列），L1 新增 L1_MImplied、L1_MImplied_Ext（外部欄＝CTL_Monetize），Checks M1（區間外 WARN）；SRC_DEM_019–048、DB_Evidence E279–E301、Decisions X21–X26；CTL_Monetize 與既有 IF_／L1_ 數值不變）。以下為 v5.31（判斷類，工作單 docs/workorders/20261008_v5.31.md r1；A 段查證 PR #34：J1 GB300 機架價格 4.0／5.0／6.5 → 4.0／4.3／5.0 $M；J2／J3 IT 維護改為機齡兩段（保固 3 年，保固期內 0.25／0.5／1.0%、期滿後 2／3／5%），Inputs 第 30 列改為壽命期等值費率公式（WACC、IT 折舊年限年金加權），Interface I 節（續）新增 IF_MaintITWarr、IF_MaintITPost、IF_WarrantyYrs；J4／J5 註記；J6 SRC_DC_014（IREN 29.0 $M/IT MW）與 L1_CapexITMW_GB300_vsIREN；DB_Evidence E263–E278；Decisions X16–X20）。以下為 v5.30（X15 定義更正，不改任何輸入值：(a) Interface J 節四層瀑布改為逐層累乘、單調遞減——IFW_*_Prod＝_Util × CTL_ProdDerate（營收列維持讀 G 節重解值；token 產能列改線性乘法）、IFW_*_Life＝_Prod × CTL_PriceLife × CTL_Monetize（營收列）；Front 四列 _Prod／_Life 改公式；Checks K3 改為來源比對＋單調檢查；(b) L1_HoldEconMW_* 改為不除以 1000（1 $B/GW＝1 $M/MW；GB300 0.0127 → 12.72 $M/MW/年）；(c) IFW_RevGW*／IFW_RevGWFleet*／IFW_RevGWFront* 四層與 IFW_TokGW_*_100 的 Decision Use 附「上限，不得作預測」（Checks K2 擴充）；其餘 IF_、L1 與模型頁數值逐格不變；Decisions X15a–c；工作單 docs/workorders/20261008_v5.30.md）。以下為 v5.29（X14 (a)–(m)：Interface 新增 R–U 輸出契約欄 Confidence／Decision Use／口徑層／最弱輸入更新日（IFC_；由公式自 Gov_Map 徙出，依賴列由 builder 反查）與 J 節四層瀑布 IFW_<name>_100／_Util／_Prod／_Life（8 個營收列、3 個 IF_TokGW 列）；L1 新增 L1_FleetBreakeven、L1_FleetMargin、L1_HoldEconMW_*、L1_TokMW_Gen_ratio_*、L1_HarVsGen_*、L1_PretrainFLOP_Astra_Ext、L1_AstraScale、L1_ScaleRD、L1_ScaleServe 與 token 對帳落差分解 L1_Gap*；新頁 Load_Bearing（高段 Assumed／Analogy 格清單）；SRC_Price 新增 X–AB 分層欄；Checks K 節；判斷類：新增 SRC_DEM_018（推論支出 Azure 帳單 12.6 $B，只用於支出路線服務 GW；SRC_DEM_004 8.4 維持 Active，供比例類公式——r2）、Alloc_In 每則提示 token 數 2,000 → 4,000（2,000–6,400）——L1_Ans1–3、L1_ExtServeGW／ExtDaily／ExtFreeShare 與 IF_Alloc* 連動改變；其餘 IF_ 與模型頁數值不變；DB_Evidence E256–E262；Decisions X14a–m、G16；工作單 docs/workorders/20261008_v5.29.md r1＋r2）。r2（2026-10-08，chat 端審查 PR #31 第九節）：SRC_DEM_004 與 SRC_DEM_018 兩筆並列 Active、只有支出路線服務 GW 用 018；Checks K4 改為比對含 CTL_ProdDerate × L × m 的 Theory_Rev 比值（應為 0）；反轉門檻改為 Gov_Map AK 欄（Excel 擁有，Load_Bearing K 欄以公式讀取）；L1_HoldEconMW_GB300、L1_FleetMargin 外部欄改「—」（對照改寫入讀法文字）。以下為 v5.27（X13：J8 證據與 L1 外部對照——SRC_MOD_055 登錄 Epoch 區間低 5e26／高 2e27，L1 第 36 列外部欄改連 _Lo／_Hi；L1 第 39 列（L1_Ans3）外部對照連 SRC_DEM_006（OpenAI 2025 訓練支出）；Grok-3 查核：Epoch 1e25 頁仍為 4.6e26，SRC_MOD_033 不改（E252）；SRC_Model 新增 SRC_MOD_057–062（Kimi K3 架構，純證據）；DB_Evidence E251–E255；Gov_Map 理由欄附註；Decisions X13；模型輸入值與所有模型頁數值不變；工作單 docs/workorders/20261008_v5.27.md）。以下為 v5.26（Interface 新增 I 節「DC_Cost 構件」：IF_DeprLifeIT、IF_DeprIT、IF_DeprFac、IF_AvgDraw、IF_PowerPrice、IF_MaintIT、IF_MaintFac、IF_StaffSW、IF_TaxIns、IF_OpexGW（DC_Cost 第 38–42、44–48 列，下游公司模型用）與加總核對列；數值與既有公式不變；工作單 docs/workorders/20261007_v5.26.md）。以下為 v5.25（X12：證據登錄——SRC_Demand 新增 SRC_DEM_014–017（OpenRouter《State of AI》，arXiv 2601.10088v1；純證據）、SRC_Model 新增 SRC_MOD_055（Epoch GPT-6 Astra 訓練算力 1.0001e27）、DB_Evidence E247–E250；L1 第 36 列（L1_PretrainFLOP_Astra）外部對照由 SRC_MOD_033 改為 SRC_MOD_055；Gov_Map GM248 區間下限 512→400；Decisions X11、X12；模型輸入值與所有模型頁數值不變；工作單 docs/workorders/20261007_v5.25.md）。以下為 v5.24（SRC_Perf 第 60–63 列（SRC_PERF_056–059）W 欄刪除 v5.21 遺留句「（第二來源欄依 W1 規則不手動填）」；數值與公式不變；工作單 docs/workorders/20261007_v5.24.md）。以下為 v5.23（X10：Perf_Batch 側新增 VR200 批次口徑 η_d 倍數 CAL_BatchEtaD（Calib I 節，VR200 基準 0.75、區間 0.70–1.0，其餘世代 1），Perf_Batch 與 Perf_Batch_Prod 第 53 列 C:Q 乘以該倍數（訓練相關輸出數值改變，營收與服務側 Perf 不變）；Decisions X10；SRC_Perf 第 56–63 列備註文字修正；工作單 docs/workorders/20261007_v5.23.md）。以下為 v5.22（X7：新增壽命期價格係數 L（CTL_PriceLife）與變現率 m（CTL_Monetize）兩個控制參數（Cap_In G 節，基準 1、區間 0.3–1.0），Interface H 節並列輸出 IF_RevGW_Luna／Sol／Astra_Life 與 IF_RevGWFleet_Life（＝對應基準列 × L × m），Checks X7 自我檢查；X8 補充：DB_Evidence E246（產業租金指數，L 的類比證據，不建 SRC）；X9 Q2：SRC_PERF_052–059 互填第二來源（W1 −8）；Decisions X7／X8／X9；既有 IF_RevGW_*、IF_RevGWFleet、L1 與 _Prod 列數值逐格不變；工作單 docs/workorders/20261006_v5.22.md）。以下為 v5.21（X6：X4 結案——MLPerf Inference v6.1 一手結果（summary.csv，repo HEAD 4bb63cd）寫入：SRC_Perf 027／028 升為 1 級、新增 SRC_PERF_052–059，DB_Evidence E245 取代 E244，Gov_Map GM344、Decisions X4／X6；Calib F67 與所有數值不改；Alloc_In G7 備註補區間；工作單 docs/workorders/20261006_v5.21.md）。以下為 v5.20（X3：X2 新高段 8 列補齊——DB_Evidence E236–E243、Gov_Map GM205／203／459／270／290／578 判 6.2 齊備、GM275／354 併入 Decisions C2；Alloc_In E7（N_refresh 區間上限）4 → 6；X4：DB_Evidence E244 記錄 Calib F67 衝突證據（F67 不改）；X5：Interface A3 與 README 加註攤提耦合；工作單 docs/workorders/20261006_v5.20.md）。以下為 v5.19（X1：Interface G 節新增七列生產折減並列輸出 IF_FullCost_Luna／Sol／Astra_Prod、IF_RevGW_Luna／Sol／Astra_Prod、IF_RevGWFleet_Prod，由新輸入格 CTL_ProdDerate（Serving!C28，預設 0.85）驅動，推導鏈以 8 個 *_Prod 鏡像頁重算，Checks X1 自我檢查；Serving!C18 維持 1.0（G0-11）；X2：Gov_Map P 欄升段 11 格；Decisions 新增 X1、X2；既有模型頁、Interface 既有列、L1 數值逐格不變；工作單 docs/workorders/20261006_v5.19.md）。以下為 v5.18（Stage 2 第一批寫入，工作單 docs/workorders/20261005_v5.18.md r2：SRC 等級依 S1 (a)、G15、H1 規則升級並登錄 DB_Evidence；Train_In C44、Calib C69 改公式；SRC_PERF_009／010 改為內插值；Arch KV 區間、Hopper 占機隊 0.57、Train_In C21 Hopper 倍數 1.0、SRC_MOD_015 拆為 Flash／Pro 兩筆；VR200 機架功率與價格、GB200／GB300 機架功率更新；Rubin Ultra 欄改為單架 72 封裝並新增 SRC_HW_061–064、SRC_MOD_054；Workload／Serving 區間依 Copilot 追蹤擴大；Gov_Map P 欄改 B 法「O＋L1」分段；Checks 第 21 列改述為 InferenceX 內部常數）。以下為 v5.17（收尾小項：L1!I43 讀法文字改為「依定義 ≥ 1」；數值與公式不變）。以下為 v5.16（L1 Answers 修正：第 5 題新增理論毛利率兩列（L1_Ans5_GM 毛利口徑、L1_Ans5_FullMargin 全成本口徑；毛利口徑附 2025 推論毛利隱含值對照）；第 6 題拆為 FLOPs 口徑（L1_Ans6）與 GPU 小時口徑（L1_Ans6_GPUh）；第 7 題改為 OpenAI 單價 ÷ 前緣單價；第 8 題改連 IF_HarR_Sol（選定 ÷ 標準）；L1 欄位約定：D＝基準、E＝低、F＝高，無區間時 E＝F＝D；Checks 新增 H3（L1 的 E ≤ D ≤ F 檢查，WARN）。模型頁、Interface、SRC、Gov_Map 不動）。以下為 v5.15（Block 6 Alloc：研發與服務的算力配置。新增 Alloc_In（輸入：N_major、N_refresh、k、服務世代組合、g、API 全年平均比例、每則提示 token 數、免費占比；全部 Assumed 或 Decision，附區間，登錄 Gov_Map）與 Alloc（需求 D → 服務 GW → 研發 GW → Q1、Q2 → 校準反推 → 外部對照 → 敏感度表）；Interface F 節新增 IF_AllocQ1、IF_AllocQ1_R2、IF_AllocQ2、IF_AllocServeGW、IF_AllocRDGW、IF_AllocDemand、IF_AllocImpliedNk；L1 新增 Answers 9 題（L1_Ans1–9）與外部對照 3 列；SRC_Demand 新增 SRC_DEM_010–013，DB_Evidence 新增 E166–E169，Decisions 新增 A9、A10 並將 A1–A8 狀態改為「v5.15 已建」；Checks 新增 H 節（H1 世代組合合計、H2 敏感度自我檢查），計入 GOV_Errors；既有模型頁、Interface 既有列、既有 L1 列的數值逐格不變）。以下為 v5.14（L1 第 O、P 欄加檢查 D 欄是否為數字：v5.13 在 SLO 不可達情境（生產折減 0.7、Tech_Registry T07–T09 開啟）下 L1!O35、P35 出現錯誤值，CC 第 13 輪發現；SRC 各頁 X 欄的比對範圍改為與 SRC_Index 相同（最後一筆紀錄＋50 列），全簿重算約減三成；基準數值不變；Block 6 改為 v5.15）。以下為 v5.13（切片二 B–E 包：Source 遷入、Gov_Map 擴及切片二頁、模型邏輯、寫回 Andy 審閱；v5.13 E：v5.11、C 包、D 包審閱檔 Andy 2026-10-03 全部依建議，寫入 Gov_Map 與 Decisions（原話 83 項確認、CV1 維持 4×HGX、G0-9 文字修正、輪數下限與快取命中區間修正）；Block 6 於 v5.14。v5.13 D：Arch 第 21–23 列 KV bytes 改公式（新增「KV 推導輸入」5 列），Arch C9、C10 連結 V4-Flash 官方 config（SRC_MOD_052、053），Cap_In 中國廠商旗標改公式，Checks 的外部比對移入 L1（新增 7 列）、樣本外實測值連結 SRC_Perf；數值不變。v5.13 C：切片二頁 515 個數值藍字格登錄 Gov_Map 129 列（分類、可比 SRC、區間、理由；Andy 2026-10-03 審閱「all ok」），Checks E12 擴及全部範圍。v5.13 B：新增 SRC_Price 44、SRC_Cap 21、SRC_Harness 15、SRC_Demand 9 筆（Stage 0 審閱的等級與立場），S30 一手原文補登 SRC_Perf 11 筆；Cap_In、Har_In、Workload 第 40 列 75 格改連結 SRC（值相等者），Checks C9:C10、最終訓練占研發區間、OpenAI 2025 對帳常數改連結 SRC_Price／SRC_Demand；數值逐格不變。以下為 v5.12（工程基礎）：新增 SRC_Index（各 SRC 頁 ID 依序堆疊），Gov_Map 的 SRC 狀態與等級改為每列 1 次 MATCH；SRC 各頁 X 欄改以 AH 同指標鍵比對；Checks 加 E13；Sources 更名 Sources_Legacy；公式內常數移到具名輸入格（CST_CtxKV、CST_STMult、CST_Eps、CST_MainMin），Sens_Train 情境倍數統一放在第 8 列；數值逐格不變。以下為 v5.11：Block 1＋2＋3＋4＋5＋治理 Stage 1 切片一；v5.11 建第 0 層 Source：SRC_HW、SRC_DC、SRC_Model、SRC_Perf（164 筆），模型頁原始數據改以公式連結 SRC_ID（數值逐格不變），DB_Evidence 加狀態與 SRC_ID 欄並登錄遷移紀錄，新增 Decisions、Gov_Map、L1 與 Checks G 節治理檢查；F14：Interface 與模型頁的每 GW 值除以 Inputs!E5，DC_Cost 改標為設施合計；v5.10 加成功任務成本前緣的可靠度下限 p_min（M1 (b)），Interface E 節增列每次嘗試成本、有效時間範圍與前緣；v5.9 加 Block 5：Har_In、Harness、Sens_Har，Workload 改為 harness 參數組，Block 4 補 SLO 不可達保護、K6 預設 (c)、機隊層級貢獻列、中國廠商旗標；v5.8 加 Block 4：Cap_In、Capability、Price_Frontier、Cache_Store、Fleet_1GW、Amortize、Theory_Rev、Sens_Rev；v5.2 加第二來源驗證與生產折減；v5.3、v5.4 依 CC 回饋補具名範圍與驗證表；v5.5 加 Block 3：Tech_Registry、Train_In、Perf_Batch、Training、Sens_Train，並更正 Hopper FP8 峰值；v5.6 非同步 RL 併入基準、補 TR_ 與訓練世代具名範圍；v5.7 改為 Excel 優先：輸入值由 Excel 擁有，新增 DB_Evidence 證據登錄表）。v4 的 Config／TL_Param／WP_Param／Revenue_Model 由 Arch、Serving、Workload、Calib、Perf、Unit_Cost 取代。
A6: 電力口徑 | B6: GW＝IT 關鍵電力（Andy 2026-09-30 確認）。設施電力＝IT × PUE，於 DC_Cost 與 Interface 並列。v5.11 起 DC_Cost 為設施合計（Inputs!E5 GW）；Interface、L1 與模型頁的每 GW 值一律除以 E5（F14）。
A7: 資料架構（v5.11） | B7: DB_Evidence（所有新訊息入口）→ 擇優 → SRC_*（第 0 層：只存原始訊息；SRC_ID 具名範圍）→ 模型頁（原始數據以公式連結 SRC；Analogy、Assumed、Decision 留在模型頁並登錄於 Gov_Map）→ Checks G 節（治理檢查，ERROR 必須為 0）→ L1（常用推算值，即時公式，附外部對照）／Interface（推算構件）→ 下游。規劃書：repo docs/plan/Tokenomics_governance_plan.md。
A8: Excel 擁有的治理頁（v5.11） | B8: SRC_HW、SRC_DC、SRC_Model、SRC_Perf、SRC_Price、SRC_Cap、SRC_Harness、SRC_Demand（v5.13）、Decisions、DB_Evidence，以及 Gov_Map 的 A–P 欄：builder 只在不存在時建立，之後不覆寫（v5.13 起既有 SRC 頁的新紀錄只在 ID 不存在時附加；Gov_Map 判斷欄的更新只在該格仍為舊值時寫入）。builder 每次重建：模型頁的 SRC 連結（gov_seed.FORMULA_MAP、gov_seed2.FORMULA_MAP2）、SRC 的 X–Z 與 AH 檢查欄、Gov_Map 的 Q–AF 欄、SRC_Index（v5.12）、L1、Checks G 節，以及 SRC_／L1_／GOV_／IDX_ 具名範圍；v5.12 起新輸入格的 Gov_Map 列只在未登錄時附加。
A9: 工作表 | B9: Inputs → Spec_Rack → Arch → Serving → Workload → Calib → Tech_Registry → Perf → Sens_Perf → Unit_Cost → DC_Cost → Train_In → Perf_Batch → Training → Sens_Train → Cap_In → Capability → Price_Frontier → Cache_Store → Fleet_1GW → Amortize → Theory_Rev → Sens_Rev → Har_In → Harness → Sens_Har → Alloc_In → Alloc → Perf_Prod → Perf_Batch_Prod → Training_Prod → Unit_Cost_Prod → Interface_Prod → Fleet_1GW_Prod → Amortize_Prod → Theory_Rev_Prod（v5.19 X1 鏡像頁）→ Interface → L1；Energy、NonNV、Sensitivity、Checks、Gov_Map、Decisions、SRC_HW、SRC_DC、SRC_Model、SRC_Perf、SRC_Price、SRC_Cap、SRC_Harness、SRC_Demand、SRC_Index（builder 擁有的查找索引）、Sources_Legacy（v5.12 起凍結）、DB_Evidence。
A10: Block 6 推導（v5.15） | B10: 實驗室年度算力＝研發需求＋服務需求。需求 D（token 路線，A9）：API＝SRC_DEM_010 × 525,600 × 全年平均比例；ChatGPT＝SRC_DEM_012 × 每則提示 token 數 × 365。服務 GW＝D ÷ 世代組合後每 GW 年產能（依 Cap_In 層級組合與 IF_TokGW_*、IF_Util，寫法同 Fleet_1GW 第 19–29 列）。研發 GW 年＝k ×（N_major × 家族計畫＋N_refresh × 改版計畫），家族計畫＝IF_ProgGWyr 三層級合計，改版計畫＝後訓練 GPU 小時 × 研發倍數換算 GW 年（訓練世代＝IF_TrainGenDefault）。Q1＝研發 GW ÷（研發＋服務 GW）；Q2 以各世代 IF_HoldEcon 加權，利用率不進入。研發占比的物理部分只給下限，實際占比由策略變數決定。隱含 N × k 由 2025 支出比反推（A3）。SLO 不可達時回傳文字。決策 A1–A10 見 Decisions。
A11: Block 3 推導 | B11: 預訓練：FLOPs＝3 ×（2 × 啟用參數＋注意力 FLOPs × 被注意 token）× token；GPU 小時＝FLOPs ÷（FP8 訓練峰值 × MFU × goodput）。RL、蒸餾、合成資料、評測的推論型運算以 Perf_Batch（與 Perf 同公式，只換速度下限與參考任務）計價；RL 有效 MFU 為推導值。研發計畫＝最終訓練 GPU 小時 × 研發倍數。
A12: Block 3 決策 | B12: J7 訓練精度 FP8（NVFP4 預訓練在 Tech_Registry）；J8 Astra 預訓練與 Arch 一致，前沿錨點列 Checks；J9 RL 由下而上，基準校到 RL÷預訓練 GPU 小時 Luna／Sol 0.3、Astra 1.0；J10 研發倍數 8，家族合計、依最終訓練比例分攤；J11 用途 × 型態只列單一計畫；J12 rollout NVFP4（FP8 為情境）；J13 下游預設 VR200、GB300 並列；J14 主流＝至少兩家實驗室公開採用，可覆寫。
A13: Excel 優先（v5.7） | B13: 藍字＝輸入，由本活頁簿擁有：要改輸入，直接改 Excel。builder 重建 Block 2、3 時會先讀取所有藍字輸入，重建後依『工作表＋欄 A 標籤＋欄位』寫回，程式內的預設值只用於新增的輸入列。公式頁不要手改（重建時會被覆寫）。
A14: DB_Evidence（v5.7） | B14: 證據登錄表：所有比對過的新資訊（含不採納者），記錄主張、來源、標記、對應參數、當時值、新值、判定與處理版本。builder 只在本頁不存在時建立。
A15: Tech_Registry | B15: 每列＝技術 × 作用物理量；有效倍數＝1＋開關 × 採用比例 ×（倍數−1）；已在基準者不套倍數。掛鉤彙總表連到 Perf、Perf_Batch、Training。全部開關為 0 時 Block 2 數值與 v5.4 相同。
... A39: L 拆分（v5.35） | B39: Cap_In I 節：L_total＝L_price × L_demote。L_price＝((1+g)^T − 1) ÷ (T × LN(1+g))（g＝中階 token 牌價年變化率 Assumed −0.10、−0.25～+0.05；T＝IF_DeprLifeIT 6 年）＝0.7412；L_total＝[((1+g)^T1 − 1) ＋ ρ((1+g)^T − (1+g)^T1)] ÷ (T × LN(1+g))（T1＝降級前服務中階年數 Assumed 4、3–5；ρ＝降級後價值比 Assumed 0.5、低端 IF_PriceRef_Luna ÷ IF_PriceRef_Sol 0.05、高端 1.0）＝0.6426；L_demote＝L_total ÷ L_price＝0.867。對照 CTL_PriceLife（基準 1，不改）與 E246 類比區間 0.42–0.70；回本所需 L＝L1_FleetBreakeven ÷（IF_Util × CTL_ProdDerate × m）：m＝L1_MFleet → 0.3645、m＝L1_MAPI → 0.5237；L_total 基準 ≥ 所需 L → 回本（L_total 口徑）。L1_LPrice／L1_LDemote／L1_LTotal／L1_LReqFleet 各含 _Lo／_Hi。H10 的「L_price」列為顯示用連結，不乘入單價。H10 修正（J23）：三分營收以 m 分子營收為基底、廣告每欄各自輸入、2026 消費份額 0.65。

Sheet Inputs
A1: Inputs — 全域輸入（藍字可改）
A2: 低成本／基準／高成本為角落情境；單值輸入只填基準欄
A3: 參數 | B3: 單位 | D3: 低成本 | E3: 基準 | F3: 高成本 | G3: 標記 | H3: 來源／說明
A4: 控制
A5: IT 電力規模 | B5: GW | D5: =E5 -> 1 | E5: 1 | F5: =E5 -> 1 | G5: Decision | H5: 口徑：IT 關鍵電力。v5.11 起 DC_Cost 為設施合計；Interface、L1 與模型頁的「每 GW」一律已除以本格（F14）
A6: 功率情境（1 低／2 基準／3 高） | B6: 選擇 | D6: =E6 -> 2 | E6: 2 | F6: =E6 -> 2 | G6: Decision | H6: 決定每架配電設計功率；見 Spec_Rack 第 9–11 列
A7: 規模與電力
A8: 機架外 IT 電力占比 | B8: % | D8: =E8 -> 0.08 | E8: 0.08 | F8: =E8 -> 0.08 | G8: Assumed | H8: 管理、儲存、網路機櫃等；區間 5–12%（見 Sensitivity）。v4 未計
A9: PUE | B9: x | D9: 1.1 | E9: 1.2 | F9: 1.3 | G9: Analogy | H9: 液冷 AI 設施；v4＝1.2。S14
A10: 平均用電 ÷ 配電設計功率 | B10: % | D10: 0.7 | E10: 0.8 | F10: 0.9 | G10: Assumed | H10: Block 2 以逐步能量模型閉合檢查
A11: 電價 | B11: $/kWh | D11: 0.06 | E11: 0.08 | F11: 0.1 | G11: Verified/Analogy | H11: EIA 美國工業電價 2026 年約 8.6–8.7¢（S13）；低端為 PPA（v4＝0.06）
A12: IT 設備（機架以外）
A13: Scale-out 網路 ÷ 機架價格 | B13: % | D13: 0.05 | E13: 0.1 | F13: =SRC_DC_002 -> 0.15 | G13: Analogy | H13: 1,024 GPU 叢集網路約為 GPU BOM 4–8%（S10）；GW 級多一層以上交換，取 5–15%
A14: 儲存與管理設備 | B14: $/GPU | D14: 300 | E14: 500 | F14: 800 | G14: Assumed | H14: v4 約 $350/GPU（$25K/架）
A15: 廠房（每 MW IT，$M）
A16: 土地 | B16: $M/MW | D16: 0.02 | E16: 0.02 | F16: 0.02 | G16: Assumed | H16: v4：100 英畝 × $200K／GW
A17: 建物與基地工程 | B17: $M/MW | D17: 3 | E17: 3.6 | F17: 4.5 | G17: Assumed | H17: 分項為假設；總額以 JLL 校準（S12）
A18: 電力設施（變電、中壓、發電機、UPS） | B18: $M/MW | D18: 3.8 | E18: 4.5 | F18: 5.5 | G18: Assumed | H18: 同上
A19: 機械與散熱（液冷迴路、散熱設備） | B19: $M/MW | D19: 2 | E19: 2.5 | F19: 3.2 | G19: Assumed | H19: 機架內冷板與 manifold 含在機架價格
A20: 光纖、佈線、保全、BMS | B20: $M/MW | D20: 0.3 | E20: 0.4 | F20: 0.5 | G20: Assumed | H20: 同上
A21: 設計、管理與預備費 | B21: % 廠房 | D21: 0.12 | E21: 0.15 | F21: 0.18 | G21: Assumed | H21: v4＝15%
A22: 年限與資金成本
A23: IT 設備折舊年限 | B23: 年 | D23: =SRC_DC_007 -> 6 | E23: =SRC_DC_007 -> 6 | F23: =SRC_DC_008 -> 4 | G23: Verified | H23: CoreWeave 與主要 hyperscaler 6 年；Nebius 4 年、Lambda 5 年（S15）。高成本情境取 4
A24: 建物年限 | B24: 年 | D24: =E24 -> 30 | E24: 30 | F24: =E24 -> 30 | G24: Analogy | H24: v4
A25: 電力設施年限 | B25: 年 | D25: =E25 -> 20 | E25: 20 | F25: =E25 -> 20 | G25: Analogy | H25: v4
A26: 機械與散熱年限 | B26: 年 | D26: =E26 -> 15 | E26: 15 | F26: =E26 -> 15 | G26: Analogy | H26: v4
A27: 光纖與保全年限 | B27: 年 | D27: =E27 -> 10 | E27: 10 | F27: =E27 -> 10 | G27: Analogy | H27: v4
A28: WACC（經濟口徑） | B28: % | D28: 0.08 | E28: 0.1 | F28: 0.13 | G28: Assumed | H28: 與擁有者無關的單一假設；下游公司模型以自身 WACC 覆寫（Andy 2026-09-30 決定）
A29: 營運費用
A30: IT 維護（壽命期等值；由兩段費率計算） | B30: % IT 資本/年 | D30: =IF(D28=0,(D37*MIN(D36,D23)+D38*(D23-MIN(D36,D23)))/D23,(D37*(1-(1+D28)^(-MIN(D36,D23)))+D38*((1+D28)^(-MIN(D36,D23))-(1+D28)^(-D23)))/(1-(1+D28)^(-D23))) -> 0.01024435 | E30: =IF(E28=0,(E37*MIN(E36,E23)+E38*(E23-MIN(E36,E23)))/E23,(E37*(1-(1+E28)^(-MIN(E36,E23)))+E38*((1+E28)^(-MIN(E36,E23))-(1+E28)^(-E23)))/(1-(1+E28)^(-E23))) -> 0.015725011 | F30: =IF(F28=0,(F37*MIN(F36,F23)+F38*(F23-MIN(F36,F23)))/F23,(F37*(1-(1+F28)^(-MIN(F36,F23)))+F38*((1+F28)^(-MIN(F36,F23))-(1+F28)^(-F23)))/(1-(1+F28)^(-F23))) -> 0.018247768 | G30: Derived | H30: v5.31 X17：壽命期等值單一費率＝Σ r_y ÷ (1＋WACC)^y ÷ Σ 1 ÷ (1＋WACC)^y（y＝1…IT 折舊年限；r_y＝保固期內費率（y ≤ 保固年限）或保固期滿後費率，第 36–38 列）；各欄用同欄 WACC（第 28 列）與 IT 折舊年限（第 23 列）。DC_Cost 第 44 列仍為 IT 資本 × 本列。v5.30 以前為 2%／3%／4%（v4 沿用，Analogy→Assumed）
A31: 廠房維護 | B31: % 廠房資本/年 | D31: 0.015 | E31: 0.02 | F31: 0.025 | G31: Analogy | H31: v4＝2%
A32: 人員 | B32: $M/GW/年 | D32: 50 | E32: 75 | F32: 100 | G32: Assumed | H32: v4：500 FTE × $150K
A33: 軟體授權與連線 | B33: $M/GW/年 | D33: 150 | E33: 200 | F33: 250 | G33: Assumed | H33: v4＝$200M
A34: 水與耗材 | B34: $M/MW/年 | D34: 0.04 | E34: 0.05 | F34: 0.06 | G34: Assumed | H34: v4＝$50K/MW
A35: 財產稅與保險 | B35: % 總資本/年 | D35: 0.003 | E35: 0.005 | F35: 0.008 | G35: Analogy | H35: v4＝0.5%
A36: IT 原廠保固年限 | B36: 年 | D36: =E36 -> 3 | E36: =SRC_DC_015 -> 3 | F36: =E36 -> 3 | G36: Verified | H36: v5.31 X18：HPE GB300 NVL72 QuickSpecs（2026-09-08）3 年零件、3 年人工、3 年到場（SRC_DC_015）；Supermicro GPU 系統人工 3 年、零件 1 年（SRC_DC_016；零件 1 年由保固期內高情境 1% 涵蓋）；Dell XE9680 經銷頁 3 年 ProSupport。單值（低、高＝基準）
A37: IT 維護（保固期內） | B37: % IT 資本/年 | D37: 0.0025 | E37: 0.005 | F37: 0.01 | G37: Analogy | H37: v5.31 X17：保固期內零件與人工由原廠負擔（保固費已含在機架售價），只剩備品、物流與保固外損壞；CoreWeave 2026 Q2 營運成本反推約 0–0.8%（E276，Derived）；區間 0.25–1%（高端涵蓋 Supermicro 零件 1 年）
A38: IT 維護（保固期滿後） | B38: % IT 資本/年 | D38: 0.02 | E38: 0.03 | F38: 0.05 | G38: Analogy | H38: v5.31 X17：NVIDIA DGX B200 原廠支援續約 1 年 ≈ 系統價 3.8%（SRC_DC_017，英國經銷牌價）；Introl 企業 TCO 5%（Interested-party，E275）作高端；大型買家應低於零售牌價 → 基準 3%

Sheet Spec_Rack
A1: Spec_Rack — 各世代機架規格（Block 1 只含功率與價格；效能規格於 Block 2 加入）
A2: 價格為買方取得價（CSP/hyperscaler 口徑）；Hopper 以 4 台 HGX 構成一架（32 GPU）以便比較
A4: 世代 | C4: Hopper H100 | D4: GB200 NVL72 | E4: GB300 NVL72 | F4: VR200 NVL72 | G4: Rubin Ultra（MGX NVL 單架，72 GPU） | H4: 標記／來源
A5: 平台／出貨 | C5: HGX ×4（32 GPU） | D5: 2024–25 出貨 | E5: 2025–26 主力 | F5: 2026 下半年開始出貨 | G5: 2027 預估（NVL576＝8 個單架互連）
A6: GPU 封裝／架 | C6: 32 | D6: =SRC_HW_047 -> 72 | E6: =SRC_HW_047 -> 72 | F6: =SRC_HW_047 -> 72 | G6: =SRC_HW_061 -> 72
A7: 冷卻 | C7: 氣冷 | D7: 液冷 | E7: 液冷 | F7: 液冷（必須） | G7: 液冷
A8: 配電設計功率 低（kW） | C8: 38 | D8: =SRC_HW_004_Lo -> 120 | E8: =SRC_HW_005_Lo -> 132 | F8: =SRC_HW_011 -> 188 | G8: 300
A9: 配電設計功率 基準（kW） | C9: 41 | D9: =SRC_HW_004_Hi -> 132 | E9: 136 | F9: =SRC_HW_014 -> 227 | G9: 340
A10: 配電設計功率 高（kW） | C10: 44 | D10: 140 | E10: =SRC_HW_005_Hi -> 140 | F10: =SRC_HW_012 -> 230 | G10: 454
A11: 機架價格 低（$M） | C11: 0.9 | D11: =SRC_HW_006_Lo -> 2.8 | E11: =SRC_HW_052 -> 4 | F11: 7.8 | G11: =F12*1.5 -> 12.6
A12: 機架價格 基準（$M） | C12: 1.1 | D12: 3.1 | E12: 4.3 | F12: 8.4 | G12: =F12*2 -> 16.8
A13: 機架價格 高（$M） | C13: 1.3 | D13: =SRC_HW_006_Hi -> 3.4 | E13: =SRC_HW_010 -> 5 | F13: 9.1 | G13: =F12*2.5 -> 21
A14: 價格涵蓋範圍 | C14: 8 GPU 伺服器 + CPU、NIC、機內儲存；以部署當時取得價計 | D14: 運算匣＋NVLink 交換匣＋機架內冷卻 | E14: 同上 | F14: 運算匣＋交換匣＋冷卻＋約 $1M NAND；是否含部分網路待查（S11）；Bernstein 平均約 $9.1M 含網路約 $1.2M；本模型另計 Scale-out 網路，高情境約重複 2%（v5.31 J4） | G14: 72 封裝（單架）；價格＝VR200 機架價格（F12，售價口徑）× 1.5／2.0／2.5（公式；倍數 Assumed；J2）
A15: 功率來源 | C15: DGX H100 最大 10.2 kW／8 GPU（S1） | D15: 約 120–132 kW（SemiAnalysis 約 120；HPE QuickSpecs TDP 132 nominal；S3）；基準 132；v4＝139 | E15: 132–140 kW（wing.vc；S3、S5）；基準 136（區間中點） | F15: Max-Q 188、Max-P 227 kW（Schneider Electric 的 NVIDIA VR NVL72 參考設計 MaxQ 188／MaxP 227，2026-05-08；S7）；Supermicro 產品頁 DLC-2 冷卻 sized for 227 kW per rack（SRC_HW_064，口徑不同） | G15: 單架 300／340／454 kW（Derived：低＝舊路線圖 600 kW 依封裝數等比；基準＝72×3.6 kW＋VR 機架非 GPU 功率 61–97 kW 取 340；高＝VR 整架／GPU 功率比值等比；NVIDIA 未公布單架 kW）
A16: 價格來源 | C16: HGX H100 8 GPU 伺服器約 $220–320K（S2，弱證據） | D16: $2.8–3.4M（S4）；Barron's 約 $3M | E16: v5.31 J1：低 4.0＝Morgan Stanley BOM 推算（VR200 BOM 7.8 ÷ 1.95，SRC_HW_052）；基準 4.3＝BOM ×（1＋代工毛利 7.5%），與 VR200 F12 算法相同，與 Wolfe Research 4.3（SRC_HW_065，Alt）相符；高 5.0＝Data Gravity 2026-08 採購單（不含 CDU，SRC_HW_010）；媒體 $6–6.5M（SRC_HW_007）改列 Alt；公司揭露對照：IREN 每 IT MW 29.0（SRC_DC_014，L1_CapexITMW_GB300_vsIREN） | F16: MS 物料成本 BOM $7.8M（自購記憶體 $6.7M）；Bernstein $9.09M；報價 $5–7M（S9）；v5.18：基準 8.4＝MS BOM 7.8 ×（1＋代工毛利約 7.5%，區間 5–10%，Assumed）；低 7.8（零毛利 BOM 下限）、高 9.1（不變，Bernstein） | G16: 無公開報價；純推估，不進基準比較
A17: 標記 | C17: Analogy | D17: Interested-party | E17: Derived／Interested-party | F17: Interested-party | G17: Derived／Assumed
A19: 註：GPU 數為封裝數。Rubin Ultra 欄為 MGX NVL 單架 72 封裝（NVIDIA 2026-09 技術部落格：NVL576＝8 個單架互連為單一 576-GPU NVLink 域；『GPU』＝封裝為推斷 [Derived]，部落格未明載）；Kyber NVL144 屬 Feynman 世代，不納入。
A21: B2. 效能規格（Block 2；藍字＝輸入；每 GPU 封裝）
A22: 服務精度 | C22: FP8 | D22: NVFP4 | E22: NVFP4 | F22: NVFP4 | G22: NVFP4 | H22: Hopper 不支援 FP4，以 FP8 服務
A23: 峰值 dense（基準）PF/GPU | C23: =SRC_HW_040 -> 1.979 | D23: =SRC_HW_022 -> 10 | E23: =SRC_HW_025 -> 15 | F23: =SRC_HW_028 -> 35 | G23: 70 | H23: Interested-party（NVIDIA 規格）：H100 FP8 dense 1,979 TF（v5.5 更正；v5.4 誤填 BF16 的 989）；GB200 FP4 10 PF（HGX B200 為 9）；B300 15；Rubin NVFP4 訓練 35（DGX VR 頁 2,520 PF÷72，Dense）；RU 單架 72 封裝：2×35＝70 [Derived；v5.18]。S28
A24: 峰值（高情境：NVFP4 推論口徑）PF/GPU | C24: =C23 -> 1.979 | D24: =SRC_HW_022 -> 10 | E24: =SRC_HW_025 -> 15 | F24: =SRC_HW_027 -> 50 | G24: 100 | H24: Rubin 50 PF 含自適應壓縮（Sparse）；RU 每封裝 2×50＝100 [Derived；v5.18，舊 15 EF÷144＝104]。J2：只作高情境
A25: HBM 容量 GB/GPU | C25: =SRC_HW_020 -> 80 | D25: 186 | E25: =SRC_HW_026 -> 288 | F25: =SRC_HW_029 -> 288 | G25: 1024 | H25: GB200 NVL72 13.4 TB ÷ 72；InferenceX 以 192 計。RU HBM4e 約 1 TB/封裝。S28
A26: HBM 頻寬 TB/s/GPU | C26: =SRC_HW_021 -> 3.35 | D26: =SRC_HW_023 -> 8 | E26: =SRC_HW_059 -> 8 | F26: =SRC_HW_030 -> 22 | G26: 32 | H26: Rubin 22 TB/s（NVIDIA 2026 上修）；RU 4.6 PB/s ÷ 144。S28
A27: EP 通訊頻寬 TB/s/GPU（單向） | C27: =SRC_HW_060/8/1000 -> 0.05 | D27: =SRC_HW_048 -> 0.9 | E27: =SRC_HW_048 -> 0.9 | F27: =SRC_HW_049 -> 1.8 | G27: 1.8 | H27: Hopper EP 跨節點走 400G IB；NVLink 5＝900 GB/s；NVLink 6＝1.8 TB/s（InferenceX 規格表 S20）；RU 取同 VR [Assumed]
A28: Scale-up 域 GPU 數 | C28: =SRC_HW_053 -> 8 | D28: =SRC_HW_047 -> 72 | E28: =SRC_HW_047 -> 72 | F28: =SRC_HW_047 -> 72 | G28: =SRC_HW_062 -> 576
A29: decode EP 基準寬度 | C29: 64 | D29: 32 | E29: =SRC_PERF_008 -> 32 | F29: 32 | G29: 64 | H29: GB300 公開配方 dep32（S21）；Hopper 跨節點 [Analogy DeepSeek]；RU [Assumed]。權重放不下時自動加寬
A30: 專家權重 bytes/param | C30: =SRC_HW_055 -> 1 | D30: =SRC_HW_050 -> 0.5625 | E30: =SRC_HW_050 -> 0.5625 | F30: =SRC_HW_050 -> 0.5625 | G30: =SRC_HW_050 -> 0.5625 | H30: NVFP4＝4 bit＋每 16 值 8 bit scale＝0.5625 B；Hopper FP8
A31: 非專家權重 bytes/param | C31: 1 | D31: 1 | E31: 1 | F31: 1 | G31: 1 | H31: 注意力、路由、embedding 以 FP8 存放 [Analogy V4]
A32: 每 prefill 實例 GPU 數（算 TTFT） | C32: 8 | D32: 4 | E32: =SRC_PERF_007 -> 4 | F32: 4 | G32: 8 | H32: GB300 配方 dep4 prefill（S21）
A33: GPU 功率 W/封裝（能量用） | C33: =SRC_HW_056 -> 700 | D33: =SRC_HW_057 -> 1200 | E33: =SRC_HW_058 -> 1400 | F33: =SRC_HW_046*1000 -> 1800 | G33: 3600 | H33: Interested-party；Rubin 約 1.8 kW、RU 推估。僅用於能量下限估算
A34: HBM 存取能量 pJ/byte | C34: 31 | D34: 25 | E34: 25 | F34: =SRC_HW_034*8 -> 20 | G34: 18 | H34: Analogy：HBM3 約 3.9 pJ/bit、HBM3e 約 3、HBM4 約 2.5；區間 ±30%（S29）
A35: 計算用峰值 PF/GPU（依 Serving 峰值情境） | C35: =IF(Serving!$C$16=2,C24,C23) -> 1.979 | D35: =IF(Serving!$C$16=2,D24,D23) -> 10 | E35: =IF(Serving!$C$16=2,E24,E23) -> 15 | F35: =IF(Serving!$C$16=2,F24,F23) -> 35 | G35: =IF(Serving!$C$16=2,G24,G23) -> 70
A36: Ridge point（FLOP/byte） | C36: =C35*1000/C26 -> 590.74627 | D36: =D35*1000/D26 -> 1250 | E36: =E35*1000/E26 -> 1875 | F36: =F35*1000/F26 -> 1590.9091 | G36: =G35*1000/G26 -> 2187.5
A38: B3. 訓練峰值（Block 3；dense；每 GPU 封裝；MFU 以 FP8 列為分母，J7）
A39: BF16 dense PF/GPU | C39: =SRC_HW_019 -> 0.989 | D39: =SRC_HW_042 -> 2.5 | E39: =SRC_HW_042 -> 2.5 | F39: =SRC_HW_039/SRC_HW_047 -> 4 | G39: 8 | H39: Interested-party（NVIDIA）：H100 989 TF；GB200／GB300 2.5；VR NVL72 288 PF ÷ 72＝4.0（S36）；RU 取 VR×2 [Assumed]
A40: FP8 dense PF/GPU（訓練基準，J7） | C40: =SRC_HW_040 -> 1.979 | D40: =SRC_HW_043 -> 5 | E40: =SRC_HW_043 -> 5 | F40: =SRC_HW_038/SRC_HW_047 -> 17.5 | G40: 35 | H40: Interested-party（NVIDIA）：H100 1,979 TF；GB200／GB300 FP8 5 PF（B300 未提升 FP8）；VR NVL72 1,260 PF ÷ 72＝17.5（S36）；RU＝2×VR 17.5（1,260 PF÷72，Dense）＝35.0 [Derived；v5.18，舊 5 EF÷144＝34.7]
A41: NVFP4 訓練 dense PF/GPU（Tech_Registry 情境） | C41: =C40 -> 1.979 | D41: 10 | E41: 15 | F41: =SRC_HW_037/SRC_HW_047 -> 35 | G41: 70 | H41: Hopper 無 FP4，取 FP8；GB200 10（NVIDIA：Rubin 為 Blackwell 3.5 倍）；GB300 15 [Assumed，區間 10–15]；VR 2,520 PF ÷ 72＝35（S36）；RU＝2×VR 35＝70 [Derived；v5.18，舊 VR×104/50＝73]

Sheet Arch
A1: Arch — 三層級代表架構（D5：每層級一個代表；參數為公開模型卡或推估）
A2: Luna／Sol 以公開權重模型為物理代表 [Analogy：對應封閉層級]；Astra 為封閉前沿代理，KV 以情境處理（J1）
A4: 參數 | B4: 單位 | C4: Luna（低層） | D4: Sol（中層） | E4: Astra（頂層） | F4: 標記 | G4: 來源／說明
A5: 代表架構 | C5: DeepSeek V4-Flash 類 | D5: DeepSeek V4-Pro 類 | E5: 封閉前沿代理 | F5: Decision | G5: D5；Andy 2026-09-30 確認
A6: 總參數 | B6: B | C6: =SRC_MOD_005 -> 284 | D6: =SRC_MOD_001 -> 1600 | E6: 4000 | F6: Verified／Assumed | G6: V4-Flash 284B、V4-Pro 1.6T（模型卡，S27）；Astra 4T [Assumed，區間 2–10T]
A7: 啟用參數 | B7: B | C7: =SRC_MOD_006 -> 13 | D7: =SRC_MOD_002 -> 49 | E7: 180 | F7: Verified／Assumed | G7: V4-Flash 13B、V4-Pro 49B；Astra 180B [Assumed，區間 60–250B]
A8: 層數 | B8: 層 | C8: =SRC_MOD_007 -> 43 | D8: =SRC_MOD_003 -> 61 | E8: 100 | F8: Verified／Assumed | G8: V4-Pro 61（config.json）；V4-Flash 43（二手）；Astra [Assumed]
A9: d_model | C9: =SRC_MOD_052 -> 4096 | D9: =SRC_MOD_004 -> 7168 | E9: 12288 | F9: Verified／Assumed | G9: V4-Pro 7168；V4-Flash 4096（官方 config.json hidden_size，v5.13 讀原文）；Astra [Assumed]
A10: query heads | C10: =SRC_MOD_053 -> 64 | D10: =SRC_MOD_008 -> 128 | E10: 96 | F10: Verified／Assumed | G10: V4-Pro 128；V4-Flash 64（官方 config.json num_attention_heads，v5.13 讀原文）；Astra [Assumed]
A11: head_dim | C11: =SRC_MOD_009 -> 512 | D11: =SRC_MOD_009 -> 512 | E11: 128 | F11: Verified／Assumed | G11: V4 單一 512 維 KV head；Astra 128
A12: routed experts | C12: =SRC_MOD_010 -> 256 | D12: =SRC_MOD_011 -> 384 | E12: 512 | F12: Verified／Assumed
A13: 每 token 啟用 routed experts | C13: =SRC_MOD_012 -> 6 | D13: =SRC_MOD_012 -> 6 | E13: 16 | F13: Verified／Assumed
A14: shared experts | C14: =SRC_MOD_013 -> 1 | D14: =SRC_MOD_013 -> 1 | E14: 1 | F14: Verified
A15: vocab | C15: =SRC_MOD_014 -> 129280 | D15: =SRC_MOD_014 -> 129280 | E15: 200000 | F15: Verified／Assumed
A16: 全注意力層比例 | B16: % | C16: =SRC_MOD_015 -> 0.512 | D16: =SRC_MOD_054 -> 0.492 | E16: 1 | F16: Verified／Assumed | G16: V4：CSA 與 HCA 約各半；Astra 全層注意力
A17: 全注意力層跨度上限（0＝全上下文） | B17: tok | C17: =SRC_MOD_018*SRC_MOD_019+SRC_MOD_017 -> 4224 | D17: =SRC_MOD_018*SRC_MOD_019+SRC_MOD_017 -> 4224 | E17: 0 | F17: Derived | G17: V4 CSA：top-k 1,024 壓縮塊 × 4 ＋ 128 窗口
A18: 其他層壓縮比 | B18: x | C18: =SRC_MOD_016 -> 128 | D18: =SRC_MOD_016 -> 128 | E18: 1 | F18: Verified | G18: V4 HCA 128× 壓縮
A19: 其他層滑動窗 | B19: tok | C19: =SRC_MOD_017 -> 128 | D19: =SRC_MOD_017 -> 128 | E19: 0 | F19: Verified
A20: Astra KV 情境（1 混合／2 全層 MLA／3 GQA-8） | B20: 選擇 | E20: 2 | F20: Decision | G20: J1：基準 2（Andy 2026-09-30 確認）
A21: KV bytes/token — 情境 1 | B21: B | C21: =C34*C8 -> 2795 | D21: =D34*D8 -> 3965 | E21: =E36*E35*E8*$C$38 -> 14976 | F21: Derived（公式） | G21: Luna／Sol＝每層 KV bytes × 層數；Astra 混合＝MLA 層比例 × MLA 每層 KV 元素 × 層數 × 每元素 bytes（v5.13 改公式，值不變）
A22: KV bytes/token — 情境 2 | B22: B | C22: =C34*C8 -> 2795 | D22: =D34*D8 -> 3965 | E22: =E35*E8*$C$38 -> 57600 | F22: Derived（公式） | G22: Astra 全層 MLA＝MLA 每層 KV 元素 × 層數 × 每元素 bytes
A23: KV bytes/token — 情境 3 | B23: B | C23: =C34*C8 -> 2795 | D23: =D34*D8 -> 3965 | E23: =E37*E11*2*E8*$C$38 -> 204800 | F23: Derived（公式） | G23: Astra GQA＝KV heads × head_dim × 2（K、V）× 層數 × 每元素 bytes
A24: 導出
A25: KV bytes/token（採用） | B25: B | C25: =CHOOSE(IF(C20="",1,C20),C21,C22,C23) -> 2795 | D25: =CHOOSE(IF(D20="",1,D20),D21,D22,D23) -> 3965 | E25: =CHOOSE(IF(E20="",1,E20),E21,E22,E23) -> 57600
A26: Embedding＋LM head 參數 | B26: B | C26: =C15*C9*2/1000000000 -> 1.0590618 | D26: =D15*D9*2/1000000000 -> 1.8533581 | E26: =E15*E9*2/1000000000 -> 4.9152
A27: 每 routed expert 參數 | B27: B | C27: =(C6-C7)/(C8*(C12-C13)) -> 0.025209302 | D27: =(D6-D7)/(D8*(D12-D13)) -> 0.067265157 | E27: =(E6-E7)/(E8*(E12-E13)) -> 0.077016129 | G27: 由公開總參數與啟用參數反推，確保總數吻合（v4 方法）
A28: 非專家參數（注意力、路由、embedding） | B28: B | C28: =C7-C8*(C13+C14)*C27 -> 5.412 | D28: =D7-D8*(D13+D14)*D27 -> 20.277778 | E28: =E7-E8*(E13+E14)*E27 -> 49.072581
A29: 專家參數 | B29: B | C29: =C6-C28 -> 278.588 | D29: =D6-D28 -> 1579.7222 | E29: =E6-E28 -> 3950.9274
A30: 注意力 FLOPs／每個被注意的 token | B30: FLOP | C30: =4*C10*C11*C8 -> 5636096 | D30: =4*D10*D11*D8 -> 15990784 | E30: =4*E10*E11*E8 -> 4915200
A31: 128K 上下文每序列 KV | B31: GB | C31: =C25*CST_CtxKV/1000000000 -> 0.35776 | D31: =D25*CST_CtxKV/1000000000 -> 0.50752 | E31: =E25*CST_CtxKV/1000000000 -> 7.3728
A32: 上下文長度（上一列顯示用） | B32: tok | C32: 128000 | F32: 結構選擇 | G32: 顯示列的口徑：128,000（非 131,072）；三層級共用本格（CST_CtxKV）。不影響任何產出
A33: KV 推導輸入（v5.13 D：第 21–23 列由此計算）
A34: 每層 KV bytes/token（壓縮後平均，FP8） | B34: B | C34: 65 | D34: 65 | F34: Assumed | G34: v4 推導值；V4 官方 config：KV head 512（SRC_MOD_009）、CSA 壓縮 4×、HCA 128×、滑動窗 128，以結構重算會改值，Stage 2 處理
A35: MLA 每層 KV 元素數（Astra 情境 1、2） | B35: 元素 | E35: 576 | F35: Analogy | G35: 比照 DeepSeek-V3 MLA：512 latent＋64 RoPE（SRC_MOD_028）
A36: MLA 層比例（Astra 情境 1 混合） | B36: % | E36: 0.26 | F36: Assumed | G36: 混合注意力：其餘層為線性注意力（KV 不隨上下文成長，本列不計）
A37: GQA KV heads（Astra 情境 3） | B37: 個 | E37: 8 | F37: Assumed | G37: GQA-8（結構選擇）
A38: KV 每元素 bytes（FP8；三層級共用） | B38: B | C38: =SRC_HW_055 -> 1 | F38: 原始數據 | G38: FP8 每元素 1 byte（SRC_HW_055）

Sheet Serving
A1: Serving — 服務設定與各層級 SLO（主流：分離式 P/D、wide EP、attention DP、NVFP4、MTP、前綴快取）
A2: 藍字＝輸入。SLO 依 J3 採市場觀測輸出速度（Artificial Analysis 2026-09，S26）
A4: 全域設定 | B4: 單位 | C4: 值 | D4: 標記 | F4: 說明
A5: 服務架構 | C5: 分離式 P/D＋wide EP＋attention DP | D5: Decision | F5: D6 與 Block 2 命題
A6: MTP 草稿數 N | B6: tok | C6: 3 | D6: Analogy | F6: DeepSeek MTP；區間 1–5
A7: 每個草稿 token 接受率 α | B7: % | C7: =SRC_PERF_005 -> 0.7 | D7: Verified-measured | F7: SGLang 修正後 0.57→0.70（S21）；區間 0.6–0.8
A8: 每步期望接受 token a | B8: tok | C8: =(1-C7^(C6+1))/(1-C7) -> 2.533 | D8: Derived | F8: (1−α^(N+1))/(1−α)
A9: HBM 保留比例（啟用值、工作區） | B9: % | C9: 0.1 | D9: Assumed | F9: 區間 5–20%
A10: 非專家權重占可用 HBM 上限 | B10: % | C10: 0.2 | D10: Assumed | F10: 超過時自動以注意力 TP 切分
A11: 專家權重占可用 HBM 上限 | B11: % | C11: 0.4 | D11: Assumed | F11: 超過時自動加寬 EP
A12: EP 啟用值 bytes/元素（dispatch＋combine） | B12: B | C12: 3 | D12: Analogy | F12: FP8 dispatch 1 B＋BF16 combine 2 B
A13: KV 讀取頻寬效率 η_mem | B13: % | C13: 0.7 | D13: Analogy | F13: 區間 0.5–0.85
A14: EP 通訊效率 η_link | B14: % | C14: 0.7 | D14: Analogy | F14: 區間 0.5–0.85
A15: 快取命中 KV 載入頻寬 | B15: TB/s/GPU | C15: 0.1 | D15: Assumed | F15: 主機記憶體／SSD 經 NIC 載入；區間 0.05–0.4。未計快取儲存成本
A16: 峰值情境（1＝dense 基準／2＝NVFP4 推論高） | B16: 選擇 | C16: 1 | D16: Decision | F16: J2：基準 1
A17: 基準利用率（第 0 層） | B17: % | C17: 0.6 | D17: Assumed | F17: J6：Andy 尚未給值，暫沿用 OpenAI v0.5 的 60%（區間 40–80%）。Unit_Cost 同時輸出 100% 版
A18: 實測→生產效率折減 | B18: x | C18: 1 | D18: Assumed | F18: 待 Andy 決定。基準測試為固定長度、穩態負載；生產環境另有長度變異、路由不均、故障。1.0＝不折減。作用：η_p、η_d 乘此值，每層延遲除以此值。第二來源（MLPerf、DeepSeek 自揭）目前均高於本模型，見 Calib H 節
A19: 各層級 SLO 與參考任務
A20: 項目 | B20: 單位 | C20: =Arch!C4 -> Luna（低層） | D20: =Arch!D4 -> Sol（中層） | E20: =Arch!E4 -> Astra（頂層） | F20: 說明
A21: SLO：每用戶 decode 速度下限 | B21: tok/s | C21: =SRC_PERF_018 -> 120 | D21: 65 | E21: 55 | F21: Verified-measured（市場觀測）：GPT-5.6 Luna 約 120、GPT-5.6 Sol 約 68、GPT-6 Astra 約 52–56、Opus 5 約 54 tok/s（S26）。區間 Luna 100–300、Sol 50–100、Astra 30–75
A22: TTFT 上限（只作檢查） | B22: s | C22: 2 | D22: 3 | E22: 5 | F22: Assumed
A23: 參考 ISL（每次請求輸入） | B23: tok | C23: 8192 | D23: 16384 | E23: 32768 | F23: Assumed：Astra 用於長任務；上下文敏感度見 Sens_Perf
A24: 參考 OSL（含思考） | B24: tok | C24: 1024 | D24: 2048 | E24: 4096 | F24: Assumed
A25: decode 平均上下文 | B25: tok | C25: =C23+C24/2 -> 8704 | D25: =D23+D24/2 -> 17408 | E25: =E23+E24/2 -> 34816 | F25: Derived
A26: prefill 平均位置 | B26: tok | C26: =C23/2 -> 4096 | D26: =D23/2 -> 8192 | E26: =E23/2 -> 16384 | F26: Derived
A28: 並列輸出用生產折減（情境值，X1；非估計值） | B28: x | C28: 0.85 | D28: 情境值 | F28: v5.19 X1：只驅動 Interface G 節的 _Prod 並列輸出（Perf_Prod 第 50 列）；Serving!C18 維持 1.0（G0-11），不受影響。0.85＝C18 區間 0.7–1.0 的中點，不是估計值；Andy 日後給 C18 值時，本格可保留作並列情境

Sheet Workload
A1: Workload — 任務制工作負載（每任務的 token 結構；思考 token 在物理上屬 decode）
A2: 任務組合權重不在第 0 層（J5）；本頁只定義標準任務。列 5–14＝標準 harness；harness 檔案在 Har_In，依 Tech_Registry T12 混合（Block 5，L1）
A4: 參數 | B4: 單位 | C4: 一般聊天 | D4: 推理聊天 | E4: 單代理（工具迴圈） | F4: 多代理研究 | G4: Coding agent（長程） | H4: 說明
A5: 輪數 T | B5: 輪 | C5: 1 | D5: 1 | E5: 4 | F5: 4 | G5: 30 | H5: Assumed；整段對話的每任務指標約 ×2–2.5（LMSYS 2.0、WildChat 2.52；E235）
A6: 初始上下文 S（系統提示、歷史、工具定義） | B6: tok | C6: 2000 | D6: 2000 | E6: 3000 | F6: 3000 | G6: 12000 | H6: Assumed
A7: 每輪新輸入 u（使用者或工具結果） | B7: tok | C7: 500 | D7: 500 | E7: 1200 | F7: 1200 | G7: 2000 | H7: Assumed
A8: 每輪思考 token h | B8: tok | C8: 0 | D8: 3000 | E8: 400 | F8: 400 | G8: 600 | H8: Assumed；服務端思考占比待查
A9: 每輪可見輸出 o | B9: tok | C9: 500 | D9: 700 | E9: 200 | F9: 200 | G9: 400 | H9: Assumed
A10: 思考保留於上下文比例 ρ | B10: % | C10: 0 | D10: 0 | E10: 0 | F10: 0 | G10: 0 | H10: Assumed：多數 API 不保留前輪思考（標準 harness）
A11: 歷史快取命中率 χ | B11: % | C11: 0.5 | D11: 0.5 | E11: 0.9 | F11: 0.9 | G11: 0.9 | H11: Assumed；代理迴圈前綴重用高
A12: 並行子代理數 m | B12: 個 | C12: 0 | D12: 0 | E12: 0 | F12: 3 | G12: 0 | H12: Assumed：子代理沿用單代理參數
A13: harness token 倍數 | B13: x | C13: 1 | D13: 1 | E13: 1 | F13: 1 | G13: 1 | H13: v5.9 起為殘差倍數（預設 1.0）；harness 效果改由 Har_In 參數組表達（L1）
A14: 歷史保留比 c（壓縮後保留的歷史比例；1＝不壓縮） | B14: x | C14: 1 | D14: 1 | E14: 1 | F14: 1 | G14: 1 | H14: 標準 harness 不壓縮；v5.9 新增（L1）
A16: 有效參數（標準＋w ×（Har_In 選定檔案−標準）；w＝B5_W）
A17: harness 混合權重 w（Tech_Registry T12 開關 × 採用比例） | B17: x | C17: =B5_W -> 0 | D17: =B5_W -> 0 | E17: =B5_W -> 0 | F17: =B5_W -> 0 | G17: =B5_W -> 0
A18: 有效輪數 T | B18: 輪 | C18: =C5*(1+B5_W*(INDEX(B5_SelT,1,1)-1)) -> 1 | D18: =D5*(1+B5_W*(INDEX(B5_SelT,1,2)-1)) -> 1 | E18: =E5*(1+B5_W*(INDEX(B5_SelT,1,3)-1)) -> 4 | F18: =F5*(1+B5_W*(INDEX(B5_SelT,1,4)-1)) -> 4 | G18: =G5*(1+B5_W*(INDEX(B5_SelT,1,5)-1)) -> 30
A19: 有效每輪思考 h | B19: tok | C19: =C8*(1+B5_W*(INDEX(B5_SelH,1,1)-1)) -> 0 | D19: =D8*(1+B5_W*(INDEX(B5_SelH,1,2)-1)) -> 3000 | E19: =E8*(1+B5_W*(INDEX(B5_SelH,1,3)-1)) -> 400 | F19: =F8*(1+B5_W*(INDEX(B5_SelH,1,4)-1)) -> 400 | G19: =G8*(1+B5_W*(INDEX(B5_SelH,1,5)-1)) -> 600
A20: 有效思考保留 ρ | B20: % | C20: =C10+B5_W*(INDEX(B5_Selrho,1,1)-C10) -> 0 | D20: =D10+B5_W*(INDEX(B5_Selrho,1,2)-D10) -> 0 | E20: =E10+B5_W*(INDEX(B5_Selrho,1,3)-E10) -> 0 | F20: =F10+B5_W*(INDEX(B5_Selrho,1,4)-F10) -> 0 | G20: =G10+B5_W*(INDEX(B5_Selrho,1,5)-G10) -> 0
A21: 有效快取命中 χ | B21: % | C21: =MIN(1,MAX(0,C11+B5_W*INDEX(B5_SelDChi,1,1))) -> 0.5 | D21: =MIN(1,MAX(0,D11+B5_W*INDEX(B5_SelDChi,1,2))) -> 0.5 | E21: =MIN(1,MAX(0,E11+B5_W*INDEX(B5_SelDChi,1,3))) -> 0.9 | F21: =MIN(1,MAX(0,F11+B5_W*INDEX(B5_SelDChi,1,4))) -> 0.9 | G21: =MIN(1,MAX(0,G11+B5_W*INDEX(B5_SelDChi,1,5))) -> 0.9
A22: 有效子代理數 m | B22: 個 | C22: =C12+B5_W*INDEX(B5_SelDM,1,1) -> 0 | D22: =D12+B5_W*INDEX(B5_SelDM,1,2) -> 0 | E22: =E12+B5_W*INDEX(B5_SelDM,1,3) -> 0 | F22: =F12+B5_W*INDEX(B5_SelDM,1,4) -> 3 | G22: =G12+B5_W*INDEX(B5_SelDM,1,5) -> 0
A23: 有效歷史保留比 c | B23: x | C23: =C14+B5_W*(INDEX(B5_SelC,1,1)-C14) -> 1 | D23: =D14+B5_W*(INDEX(B5_SelC,1,2)-D14) -> 1 | E23: =E14+B5_W*(INDEX(B5_SelC,1,3)-E14) -> 1 | F23: =F14+B5_W*(INDEX(B5_SelC,1,4)-F14) -> 1 | G23: =G14+B5_W*(INDEX(B5_SelC,1,5)-G14) -> 1
A25: 導出（每任務；用有效參數）
A26: 每輪上下文增量 u＋o＋ρh | B26: tok | C26: =C7+C9+C20*C19 -> 1000 | D26: =D7+D9+D20*D19 -> 1200 | E26: =E7+E9+E20*E19 -> 1400 | F26: =F7+F9+F20*F19 -> 1400 | G26: =G7+G9+G20*G19 -> 2400
A27: 單代理輸入總量 | B27: tok | C27: =C18*(C6+C7)+C23*C26*C18*(C18-1)/2 -> 2500 | D27: =D18*(D6+D7)+D23*D26*D18*(D18-1)/2 -> 2500 | E27: =E18*(E6+E7)+E23*E26*E18*(E18-1)/2 -> 25200 | F27: =F18*(F6+F7)+F23*F26*F18*(F18-1)/2 -> 25200 | G27: =G18*(G6+G7)+G23*G26*G18*(G18-1)/2 -> 1464000
A28: 其中可快取（前綴） | B28: tok | C28: =C21*(C18*C6+C23*C26*C18*(C18-1)/2) -> 1000 | D28: =D21*(D18*D6+D23*D26*D18*(D18-1)/2) -> 1000 | E28: =E21*(E18*E6+E23*E26*E18*(E18-1)/2) -> 18360 | F28: =F21*(F18*F6+F23*F26*F18*(F18-1)/2) -> 18360 | G28: =G21*(G18*G6+G23*G26*G18*(G18-1)/2) -> 1263600
A29: 其中新鮮 | B29: tok | C29: =C27-C28 -> 1500 | D29: =D27-D28 -> 1500 | E29: =E27-E28 -> 6840 | F29: =F27-F28 -> 6840 | G29: =G27-G28 -> 200400
A30: 單代理 decode（思考＋可見） | B30: tok | C30: =C18*(C19+C9) -> 500 | D30: =D18*(D19+D9) -> 3700 | E30: =E18*(E19+E9) -> 2400 | F30: =F18*(F19+F9) -> 2400 | G30: =G18*(G19+G9) -> 30000
A31: 系統倍數（1＋m）× harness 殘差倍數 | B31: x | C31: =(1+C22)*C13 -> 1 | D31: =(1+D22)*D13 -> 1 | E31: =(1+E22)*E13 -> 1 | F31: =(1+F22)*F13 -> 4 | G31: =(1+G22)*G13 -> 1
A32: 任務新鮮 prefill | B32: tok | C32: =C29*C31 -> 1500 | D32: =D29*D31 -> 1500 | E32: =E29*E31 -> 6840 | F32: =F29*F31 -> 27360 | G32: =G29*G31 -> 200400
A33: 任務快取 prefill | B33: tok | C33: =C28*C31 -> 1000 | D33: =D28*D31 -> 1000 | E33: =E28*E31 -> 18360 | F33: =F28*F31 -> 73440 | G33: =G28*G31 -> 1263600
A34: 任務 decode | B34: tok | C34: =C30*C31 -> 500 | D34: =D30*D31 -> 3700 | E34: =E30*E31 -> 2400 | F34: =F30*F31 -> 9600 | G34: =G30*G31 -> 30000
A35: 任務總 token | B35: tok | C35: =C32+C33+C34 -> 3000 | D35: =D32+D33+D34 -> 6200 | E35: =E32+E33+E34 -> 27600 | F35: =F32+F33+F34 -> 110400 | G35: =G32+G33+G34 -> 1494000
A36: decode 平均上下文 | B36: tok | C36: =C6+C7+(C18-1)/2*C23*C26+(C19+C9)/2 -> 2750 | D36: =D6+D7+(D18-1)/2*D23*D26+(D19+D9)/2 -> 4350 | E36: =E6+E7+(E18-1)/2*E23*E26+(E19+E9)/2 -> 6600 | F36: =F6+F7+(F18-1)/2*F23*F26+(F19+F9)/2 -> 6600 | G36: =G6+G7+(G18-1)/2*G23*G26+(G19+G9)/2 -> 49300 | H36: Unit_Cost 的 decode 成本取各層級參考上下文；本列顯示任務實際上下文，差距大時看 Sens_Perf 的 ISL 情境
A37: 思考占 decode | B37: % | C37: =IF(C19+C9>0,C19/(C19+C9),0) -> 0 | D37: =IF(D19+D9>0,D19/(D19+D9),0) -> 0.81081081 | E37: =IF(E19+E9>0,E19/(E19+E9),0) -> 0.66666667 | F37: =IF(F19+F9>0,F19/(F19+F9),0) -> 0.66666667 | G37: =IF(G19+G9>0,G19/(G19+G9),0) -> 0.6
A38: 總 token ÷ 一般聊天 | B38: x | C38: =C35/$C$35 -> 1 | D38: =D35/$C$35 -> 2.0666667 | E38: =E35/$C$35 -> 9.2 | F38: =F35/$C$35 -> 36.8 | G38: =G35/$C$35 -> 498
A39: 總 token ÷ 推理聊天 | B39: x | C39: =C35/$D$35 -> 0.48387097 | D39: =D35/$D$35 -> 1 | E39: =E35/$D$35 -> 4.4516129 | F39: =F35/$D$35 -> 17.806452 | G39: =G35/$D$35 -> 240.96774
A40: 參照：Anthropic 揭露倍數（相對聊天） | B40: x | C40: 1 | E40: =SRC_HAR_001 -> 4 | F40: =SRC_HAR_002 -> 15 | H40: Interested-party：Anthropic 2025-06 多代理研究系統文章，agent 約 4 倍、多代理約 15 倍聊天 token（S25）。其『聊天』口徑未說明是否含思考，故兩個倍數並列。本頁列 38 的單代理、多代理倍數高於此參照約 2.3–2.5 倍（Block 2 既有假設，未調整）
A42: 每任務成本（$／任務；經濟口徑、基準成本情境、基準利用率；不含快取儲存，含儲存者見 Harness 頁）
A43: VR200 × Luna | B43: $ | C43: =IF(ISNUMBER(Unit_Cost!M21),(C32*Unit_Cost!M19+C33*Unit_Cost!M20+C34*Unit_Cost!M21)/1000000,"SLO 不可達") -> 9.8538689e-05 | D43: =IF(ISNUMBER(Unit_Cost!M21),(D32*Unit_Cost!M19+D33*Unit_Cost!M20+D34*Unit_Cost!M21)/1000000,"SLO 不可達") -> 0.00065132067 | E43: =IF(ISNUMBER(Unit_Cost!M21),(E32*Unit_Cost!M19+E33*Unit_Cost!M20+E34*Unit_Cost!M21)/1000000,"SLO 不可達") -> 0.00047091996 | F43: =IF(ISNUMBER(Unit_Cost!M21),(F32*Unit_Cost!M19+F33*Unit_Cost!M20+F34*Unit_Cost!M21)/1000000,"SLO 不可達") -> 0.0018836798 | G43: =IF(ISNUMBER(Unit_Cost!M21),(G32*Unit_Cost!M19+G33*Unit_Cost!M20+G34*Unit_Cost!M21)/1000000,"SLO 不可達") -> 0.0068777227
A44: VR200 × Sol | B44: $ | C44: =IF(ISNUMBER(Unit_Cost!M34),(C32*Unit_Cost!M32+C33*Unit_Cost!M33+C34*Unit_Cost!M34)/1000000,"SLO 不可達") -> 0.00031648038 | D44: =IF(ISNUMBER(Unit_Cost!M34),(D32*Unit_Cost!M32+D33*Unit_Cost!M33+D34*Unit_Cost!M34)/1000000,"SLO 不可達") -> 0.0020725124 | E44: =IF(ISNUMBER(Unit_Cost!M34),(E32*Unit_Cost!M32+E33*Unit_Cost!M33+E34*Unit_Cost!M34)/1000000,"SLO 不可達") -> 0.0015102135 | F44: =IF(ISNUMBER(Unit_Cost!M34),(F32*Unit_Cost!M32+F33*Unit_Cost!M33+F34*Unit_Cost!M34)/1000000,"SLO 不可達") -> 0.006040854 | G44: =IF(ISNUMBER(Unit_Cost!M34),(G32*Unit_Cost!M32+G33*Unit_Cost!M33+G34*Unit_Cost!M34)/1000000,"SLO 不可達") -> 0.022186637
...

Sheet Calib
A1: Calib — 以實測錨點校準效率係數（實測只校準係數，不取代推導）
A2: 錨點：DeepSeek V4-Pro（＝Sol 代表架構）、FP4、8K/1K、分離式 P/D，tok/s/GPU 為總 token 口徑。GB300 同一前緣上兩點聯立解出 η_d 與每層延遲；其餘各點為樣本外驗證
A4: A. 輸入
A5: η_p：prefill 達成峰值比例 | B5: % | C5: 0.3 | J5: Analogy：DeepSeek H800 線上 prefill 約 0.37（S30，待查）；區間 0.15–0.45。擬合結果對此不敏感（見 G 節）
A7: B. 錨點（每欄一個實測點）
A8: 項目 | B8: 單位
A9: 用途 | C9: 擬合點 1 | D9: 擬合點 2 | E9: 驗證 | F9: 驗證（舊軟體） | G9: 驗證（舊軟體） | H9: 驗證（口徑待查） | I9: 驗證（口徑待查）
A10: 世代索引 | C10: 3 | D10: 3 | E10: 3 | F10: 3 | G10: 2 | H10: 2 | I10: 3
A11: 世代 | C11: =INDEX(Spec_Rack!$C$4:$G$4,C10) -> GB300 NVL72 | D11: =INDEX(Spec_Rack!$C$4:$G$4,D10) -> GB300 NVL72 | E11: =INDEX(Spec_Rack!$C$4:$G$4,E10) -> GB300 NVL72 | F11: =INDEX(Spec_Rack!$C$4:$G$4,F10) -> GB300 NVL72 | G11: =INDEX(Spec_Rack!$C$4:$G$4,G10) -> GB200 NVL72 | H11: =INDEX(Spec_Rack!$C$4:$G$4,H10) -> GB200 NVL72 | I11: =INDEX(Spec_Rack!$C$4:$G$4,I10) -> GB300 NVL72
A12: 軟體／日期 | C12: InferenceX 最佳前緣（約 2026-07） | D12: InferenceX 最佳前緣（約 2026-07） | E12: SGLang＋MTP，2026-06 | F12: vLLM 無 MTP，2026-05-22 | G12: vLLM 無 MTP，2026-05-22 | H12: InferenceX 比較頁（0813） | I12: InferenceX 比較頁（0813）
A13: MTP（1＝有） | C13: =SRC_PERF_009_MTP -> 1 | D13: =SRC_PERF_010_MTP -> 1 | E13: =SRC_PERF_004_MTP -> 1 | F13: =SRC_PERF_001_MTP -> 0 | G13: =SRC_PERF_002_MTP -> 0 | H13: =SRC_PERF_014_MTP -> 1 | I13: =SRC_PERF_015_MTP -> 1
A14: 每用戶速度 | B14: tok/s | C14: =SRC_PERF_009_Spd -> 72 | D14: =SRC_PERF_010_Spd -> 130 | E14: =SRC_PERF_004_Spd -> 50 | F14: =SRC_PERF_001_Spd -> 27 | G14: =SRC_PERF_002_Spd -> 27 | H14: =SRC_PERF_014_Spd -> 110 | I14: =SRC_PERF_015_Spd -> 110
A15: ISL | B15: tok | C15: =SRC_PERF_009_ISL -> 8192 | D15: =SRC_PERF_010_ISL -> 8192 | E15: =SRC_PERF_004_ISL -> 8192 | F15: =SRC_PERF_001_ISL -> 8192 | G15: =SRC_PERF_002_ISL -> 8192 | H15: =SRC_PERF_014_ISL -> 8192 | I15: =SRC_PERF_015_ISL -> 8192
A16: OSL | B16: tok | C16: =SRC_PERF_009_OSL -> 1024 | D16: =SRC_PERF_010_OSL -> 1024 | E16: =SRC_PERF_004_OSL -> 1024 | F16: =SRC_PERF_001_OSL -> 1024 | G16: =SRC_PERF_002_OSL -> 1024 | H16: =SRC_PERF_014_OSL -> 1024 | I16: =SRC_PERF_015_OSL -> 1024
A17: 實測 tok/s/GPU（總 token） | B17: tok/s | C17: =SRC_PERF_009 -> 9342.1 | D17: =SRC_PERF_010 -> 3405.2 | E17: =SRC_PERF_004 -> 11200 | F17: =SRC_PERF_001 -> 6182 | G17: =SRC_PERF_002 -> 2189 | H17: =SRC_PERF_014 -> 3795.5 | I17: =SRC_PERF_015 -> 6522.4
A18: 來源 | C18: S22 | D18: S22 | E18: S21 | F18: S20 | G18: S20 | H18: S23 | I18: S23
A19: 量測平台（獨立性） | C19: InferenceX（SemiAnalysis） | D19: InferenceX（SemiAnalysis） | E19: InferenceX（SemiAnalysis） | F19: InferenceX（SemiAnalysis） | G19: InferenceX（SemiAnalysis） | H19: InferenceX（SemiAnalysis） | I19: InferenceX（SemiAnalysis） | J19: 七個點全部來自同一平台（S21 為 SGLang 作者轉述 InferenceX 資料，不構成獨立來源）。第二來源見 H 節
A20: 點位標籤（世代｜用途｜速度） | C20: =C11&"｜"&C9&"｜"&TEXT(C14,"0")&" tok/s" -> GB300 NVL72｜擬合點 1｜72 tok/s | D20: =D11&"｜"&D9&"｜"&TEXT(D14,"0")&" tok/s" -> GB300 NVL72｜擬合點 2｜130 tok/s | E20: =E11&"｜"&E9&"｜"&TEXT(E14,"0")&" tok/s" -> GB300 NVL72｜驗證｜50 tok/s | F20: =F11&"｜"&F9&"｜"&TEXT(F14,"0")&" tok/s" -> GB300 NVL72｜驗證（舊軟體）｜27 tok/s | G20: =G11&"｜"&G9&"｜"&TEXT(G14,"0")&" tok/s" -> GB200 NVL72｜驗證（舊軟體）｜27 tok/s | H20: =H11&"｜"&H9&"｜"&TEXT(H14,"0")&" tok/s" -> GB200 NVL72｜驗證（口徑待查）｜110 tok/s | I20: =I11&"｜"&I9&"｜"&TEXT(I14,"0")&" tok/s" -> GB300 NVL72｜驗證（口徑待查）｜110 tok/s
A21: 口徑 | C21: 總 token（輸入＋輸出） | D21: 總 token（輸入＋輸出） | E21: 總 token（輸入＋輸出） | F21: 總 token（輸入＋輸出） | G21: 總 token（輸入＋輸出） | H21: 總 token（輸入＋輸出） | I21: 總 token（輸入＋輸出）
A22: C. 各點的模型量（Sol 架構；與 Perf 同一套公式）
A23: 計算用峰值 | B23: PF/GPU | C23: =INDEX(Spec_Rack!$C$35:$G$35,C10) -> 15 | D23: =INDEX(Spec_Rack!$C$35:$G$35,D10) -> 15 | E23: =INDEX(Spec_Rack!$C$35:$G$35,E10) -> 15 | F23: =INDEX(Spec_Rack!$C$35:$G$35,F10) -> 15 | G23: =INDEX(Spec_Rack!$C$35:$G$35,G10) -> 10 | H23: =INDEX(Spec_Rack!$C$35:$G$35,H10) -> 10 | I23: =INDEX(Spec_Rack!$C$35:$G$35,I10) -> 15
A24: HBM 容量 | B24: GB | C24: =INDEX(Spec_Rack!$C$25:$G$25,C10) -> 288 | D24: =INDEX(Spec_Rack!$C$25:$G$25,D10) -> 288 | E24: =INDEX(Spec_Rack!$C$25:$G$25,E10) -> 288 | F24: =INDEX(Spec_Rack!$C$25:$G$25,F10) -> 288 | G24: =INDEX(Spec_Rack!$C$25:$G$25,G10) -> 186 | H24: =INDEX(Spec_Rack!$C$25:$G$25,H10) -> 186 | I24: =INDEX(Spec_Rack!$C$25:$G$25,I10) -> 288
A25: HBM 頻寬 | B25: TB/s | C25: =INDEX(Spec_Rack!$C$26:$G$26,C10) -> 8 | D25: =INDEX(Spec_Rack!$C$26:$G$26,D10) -> 8 | E25: =INDEX(Spec_Rack!$C$26:$G$26,E10) -> 8 | F25: =INDEX(Spec_Rack!$C$26:$G$26,F10) -> 8 | G25: =INDEX(Spec_Rack!$C$26:$G$26,G10) -> 8 | H25: =INDEX(Spec_Rack!$C$26:$G$26,H10) -> 8 | I25: =INDEX(Spec_Rack!$C$26:$G$26,I10) -> 8
A26: EP 通訊頻寬 | B26: TB/s | C26: =INDEX(Spec_Rack!$C$27:$G$27,C10) -> 0.9 | D26: =INDEX(Spec_Rack!$C$27:$G$27,D10) -> 0.9 | E26: =INDEX(Spec_Rack!$C$27:$G$27,E10) -> 0.9 | F26: =INDEX(Spec_Rack!$C$27:$G$27,F10) -> 0.9 | G26: =INDEX(Spec_Rack!$C$27:$G$27,G10) -> 0.9 | H26: =INDEX(Spec_Rack!$C$27:$G$27,H10) -> 0.9 | I26: =INDEX(Spec_Rack!$C$27:$G$27,I10) -> 0.9
A27: EP 基準寬度 | C27: =INDEX(Spec_Rack!$C$29:$G$29,C10) -> 32 | D27: =INDEX(Spec_Rack!$C$29:$G$29,D10) -> 32 | E27: =INDEX(Spec_Rack!$C$29:$G$29,E10) -> 32 | F27: =INDEX(Spec_Rack!$C$29:$G$29,F10) -> 32 | G27: =INDEX(Spec_Rack!$C$29:$G$29,G10) -> 32 | H27: =INDEX(Spec_Rack!$C$29:$G$29,H10) -> 32 | I27: =INDEX(Spec_Rack!$C$29:$G$29,I10) -> 32
A28: 專家 bytes/param | B28: B | C28: =INDEX(Spec_Rack!$C$30:$G$30,C10) -> 0.5625 | D28: =INDEX(Spec_Rack!$C$30:$G$30,D10) -> 0.5625 | E28: =INDEX(Spec_Rack!$C$30:$G$30,E10) -> 0.5625 | F28: =INDEX(Spec_Rack!$C$30:$G$30,F10) -> 0.5625 | G28: =INDEX(Spec_Rack!$C$30:$G$30,G10) -> 0.5625 | H28: =INDEX(Spec_Rack!$C$30:$G$30,H10) -> 0.5625 | I28: =INDEX(Spec_Rack!$C$30:$G$30,I10) -> 0.5625
A29: 非專家 bytes/param | B29: B | C29: =INDEX(Spec_Rack!$C$31:$G$31,C10) -> 1 | D29: =INDEX(Spec_Rack!$C$31:$G$31,D10) -> 1 | E29: =INDEX(Spec_Rack!$C$31:$G$31,E10) -> 1 | F29: =INDEX(Spec_Rack!$C$31:$G$31,F10) -> 1 | G29: =INDEX(Spec_Rack!$C$31:$G$31,G10) -> 1 | H29: =INDEX(Spec_Rack!$C$31:$G$31,H10) -> 1 | I29: =INDEX(Spec_Rack!$C$31:$G$31,I10) -> 1
A30: 啟用參數 | B30: B | C30: =Arch!$D$7 -> 49 | D30: =Arch!$D$7 -> 49 | E30: =Arch!$D$7 -> 49 | F30: =Arch!$D$7 -> 49 | G30: =Arch!$D$7 -> 49 | H30: =Arch!$D$7 -> 49 | I30: =Arch!$D$7 -> 49
A31: 層數 | C31: =Arch!$D$8 -> 61 | D31: =Arch!$D$8 -> 61 | E31: =Arch!$D$8 -> 61 | F31: =Arch!$D$8 -> 61 | G31: =Arch!$D$8 -> 61 | H31: =Arch!$D$8 -> 61 | I31: =Arch!$D$8 -> 61
A32: d_model | C32: =Arch!$D$9 -> 7168 | D32: =Arch!$D$9 -> 7168 | E32: =Arch!$D$9 -> 7168 | F32: =Arch!$D$9 -> 7168 | G32: =Arch!$D$9 -> 7168 | H32: =Arch!$D$9 -> 7168 | I32: =Arch!$D$9 -> 7168
A33: 啟用專家 | C33: =Arch!$D$13 -> 6 | D33: =Arch!$D$13 -> 6 | E33: =Arch!$D$13 -> 6 | F33: =Arch!$D$13 -> 6 | G33: =Arch!$D$13 -> 6 | H33: =Arch!$D$13 -> 6 | I33: =Arch!$D$13 -> 6
A34: 非專家參數 | B34: B | C34: =Arch!$D$28 -> 20.277778 | D34: =Arch!$D$28 -> 20.277778 | E34: =Arch!$D$28 -> 20.277778 | F34: =Arch!$D$28 -> 20.277778 | G34: =Arch!$D$28 -> 20.277778 | H34: =Arch!$D$28 -> 20.277778 | I34: =Arch!$D$28 -> 20.277778
A35: 專家參數 | B35: B | C35: =Arch!$D$29 -> 1579.7222 | D35: =Arch!$D$29 -> 1579.7222 | E35: =Arch!$D$29 -> 1579.7222 | F35: =Arch!$D$29 -> 1579.7222 | G35: =Arch!$D$29 -> 1579.7222 | H35: =Arch!$D$29 -> 1579.7222 | I35: =Arch!$D$29 -> 1579.7222
A36: KV bytes/token | B36: B | C36: =Arch!$D$25 -> 3965 | D36: =Arch!$D$25 -> 3965 | E36: =Arch!$D$25 -> 3965 | F36: =Arch!$D$25 -> 3965 | G36: =Arch!$D$25 -> 3965 | H36: =Arch!$D$25 -> 3965 | I36: =Arch!$D$25 -> 3965
A37: 注意力 FLOPs／被注意 token | C37: =Arch!$D$30 -> 15990784 | D37: =Arch!$D$30 -> 15990784 | E37: =Arch!$D$30 -> 15990784 | F37: =Arch!$D$30 -> 15990784 | G37: =Arch!$D$30 -> 15990784 | H37: =Arch!$D$30 -> 15990784 | I37: =Arch!$D$30 -> 15990784
A38: 全注意力層比例 | B38: % | C38: =Arch!$D$16 -> 0.492 | D38: =Arch!$D$16 -> 0.492 | E38: =Arch!$D$16 -> 0.492 | F38: =Arch!$D$16 -> 0.492 | G38: =Arch!$D$16 -> 0.492 | H38: =Arch!$D$16 -> 0.492 | I38: =Arch!$D$16 -> 0.492
A39: 跨度上限 | C39: =Arch!$D$17 -> 4224 | D39: =Arch!$D$17 -> 4224 | E39: =Arch!$D$17 -> 4224 | F39: =Arch!$D$17 -> 4224 | G39: =Arch!$D$17 -> 4224 | H39: =Arch!$D$17 -> 4224 | I39: =Arch!$D$17 -> 4224
A40: 壓縮比 | C40: =Arch!$D$18 -> 128 | D40: =Arch!$D$18 -> 128 | E40: =Arch!$D$18 -> 128 | F40: =Arch!$D$18 -> 128 | G40: =Arch!$D$18 -> 128 | H40: =Arch!$D$18 -> 128 | I40: =Arch!$D$18 -> 128
A41: 滑動窗 | C41: =Arch!$D$19 -> 128 | D41: =Arch!$D$19 -> 128 | E41: =Arch!$D$19 -> 128 | F41: =Arch!$D$19 -> 128 | G41: =Arch!$D$19 -> 128 | H41: =Arch!$D$19 -> 128 | I41: =Arch!$D$19 -> 128
A42: decode 平均上下文 | B42: tok | C42: =C15+C16/2 -> 8704 | D42: =D15+D16/2 -> 8704 | E42: =E15+E16/2 -> 8704 | F42: =F15+F16/2 -> 8704 | G42: =G15+G16/2 -> 8704 | H42: =H15+H16/2 -> 8704 | I42: =I15+I16/2 -> 8704
...

Sheet Tech_Registry
A1: Tech_Registry — 新技術登錄與掛鉤（每列＝技術 × 作用物理量；基準值只在『已在基準＝否』且開關＝1 時套用）
A2: 有效倍數＝1＋開關 × 採用比例 ×（所選倍數−1）；已在基準者恆為 1，避免重複計算。主流判定（J14）：至少兩家實驗室公開採用；L 欄可由 Andy 覆寫
A4: ID | B4: 技術 | C4: 掛鉤代碼 | D4: 作用物理量 | E4: 倍數 低 | F4: 倍數 基準 | G4: 倍數 高 | H4: 情境（1／2／3） | I4: 狀態 | J4: 公開採用實驗室數 | K4: 主流判定（J14） | L4: Andy 覆寫 | M4: 已在基準 | N4: 採用比例 | O4: 開關（0／1） | P4: 有效倍數 | Q4: 證據標記 | R4: 來源／說明 | S4: 下次檢查觸發 | T4: 一致性檢查
A5: T01 | B5: MTP 推測解碼 | C5: — | D5: Serving!C6:C8（N、α） | E5: 1 | F5: 1 | G5: 1 | H5: 2 | I5: 主流 | J5: 3 | K5: =IF(J5>=CST_MainMin,"主流","非主流") -> 主流 | M5: 是 | N5: 1 | O5: 1 | P5: =IF(M5="是",1,1+O5*N5*(CHOOSE(H5,E5,F5,G5)-1)) -> 1 | Q5: Verified | R5: DeepSeek V3／V4、GLM-4.5、MiMo 公開採用；已在 Serving 基準 | S5: — | T5: =IF(AND(IF(L5="",K5,L5)="主流",M5="否"),"主流但未入基準：須 Andy 判定",IF(AND(IF(L5="",K5,L5)="非主流",M5="是",I5<>"早期採用"),"非主流卻在基準","一致")) -> 一致
A6: T02 | B6: 壓縮／稀疏注意力（CSA/HCA 類） | C6: — | D6: Arch 列 16–19 | E6: 1 | F6: 1 | G6: 1 | H6: 2 | I6: 主流 | J6: 3 | K6: =IF(J6>=CST_MainMin,"主流","非主流") -> 主流 | M6: 是 | N6: 1 | O6: 1 | P6: =IF(M6="是",1,1+O6*N6*(CHOOSE(H6,E6,F6,G6)-1)) -> 1 | Q6: Verified | R6: DeepSeek V4 CSA/HCA、DeepSeek／GLM 稀疏注意力、Qwen3-Next 混合注意力；Luna／Sol 基準已含（S27、S35） | S6: — | T6: =IF(AND(IF(L6="",K6,L6)="主流",M6="否"),"主流但未入基準：須 Andy 判定",IF(AND(IF(L6="",K6,L6)="非主流",M6="是",I6<>"早期採用"),"非主流卻在基準","一致")) -> 一致
A7: T03 | B7: FP4 權重推論（NVFP4／MXFP4） | C7: — | D7: Spec_Rack 專家 bytes/param | E7: 1 | F7: 1 | G7: 1 | H7: 2 | I7: 主流 | J7: 2 | K7: =IF(J7>=CST_MainMin,"主流","非主流") -> 主流 | M7: 是 | N7: 1 | O7: 1 | P7: =IF(M7="是",1,1+O7*N7*(CHOOSE(H7,E7,F7,G7)-1)) -> 1 | Q7: Verified | R7: DeepSeek V4 原生 FP4 專家權重、OpenAI gpt-oss MXFP4；已在基準 | S7: — | T7: =IF(AND(IF(L7="",K7,L7)="主流",M7="否"),"主流但未入基準：須 Andy 判定",IF(AND(IF(L7="",K7,L7)="非主流",M7="是",I7<>"早期採用"),"非主流卻在基準","一致")) -> 一致
A8: T04 | B8: FP4 量化感知訓練（後訓練） | C8: — | D8: Spec_Rack 專家 bytes/param | E8: 1 | F8: 1 | G8: 1 | H8: 2 | I8: 主流 | J8: 2 | K8: =IF(J8>=CST_MainMin,"主流","非主流") -> 主流 | M8: 是 | N8: 1 | O8: 1 | P8: =IF(M8="是",1,1+O8*N8*(CHOOSE(H8,E8,F8,G8)-1)) -> 1 | Q8: Interested-party | R8: DeepSeek V4：主權重量化到 FP4 再反量化到 FP8 計算，沿用 FP8 訓練框架（S35） | S8: — | T8: =IF(AND(IF(L8="",K8,L8)="主流",M8="否"),"主流但未入基準：須 Andy 判定",IF(AND(IF(L8="",K8,L8)="非主流",M8="是",I8<>"早期採用"),"非主流卻在基準","一致")) -> 一致
A9: T05 | B9: On-policy 蒸餾（多專家整合） | C9: — | D9: Training G 節 | E9: 1 | F9: 1 | G9: 1 | H9: 2 | I9: 主流 | J9: 2 | K9: =IF(J9>=CST_MainMin,"主流","非主流") -> 主流 | M9: 是 | N9: 1 | O9: 1 | P9: =IF(M9="是",1,1+O9*N9*(CHOOSE(H9,E9,F9,G9)-1)) -> 1 | Q9: Interested-party | R9: DeepSeek V4（專家 SFT＋GRPO 後以 on-policy 蒸餾整合，S35）、Qwen3；已在 Training 基準 | S9: — | T9: =IF(AND(IF(L9="",K9,L9)="主流",M9="否"),"主流但未入基準：須 Andy 判定",IF(AND(IF(L9="",K9,L9)="非主流",M9="是",I9<>"早期採用"),"非主流卻在基準","一致")) -> 一致
A10: T06 | B10: Muon 優化器 | C10: H_TOK | D10: 預訓練所需 token | E10: 0.7 | F10: 0.85 | G10: 1 | H10: 2 | I10: 早期採用 | J10: 2 | K10: =IF(J10>=CST_MainMin,"主流","非主流") -> 主流 | M10: 是 | N10: 1 | O10: 0 | P10: =IF(M10="是",1,1+O10*N10*(CHOOSE(H10,E10,F10,G10)-1)) -> 1 | Q10: Interested-party | R10: Moonshot Kimi K2、DeepSeek V4 採用；Luna／Sol 的 token 數為實際值，已隱含其效果，故不套倍數 | S10: 第三家前沿實驗室採用，或公開同品質 token 節省的對照實驗 | T10: =IF(AND(IF(L10="",K10,L10)="主流",M10="否"),"主流但未入基準：須 Andy 判定",IF(AND(IF(L10="",K10,L10)="非主流",M10="是",I10<>"早期採用"),"非主流卻在基準","一致")) -> 一致
A11: T07 | B11: NVFP4 預訓練 | C11: H_TPK | D11: 訓練峰值 | E11: 1.5 | F11: 2 | G11: 3 | H11: 2 | I11: 早期採用 | J11: 1 | K11: =IF(J11>=CST_MainMin,"主流","非主流") -> 非主流 | M11: 否 | N11: 1 | O11: 0 | P11: =IF(M11="是",1,1+O11*N11*(CHOOSE(H11,E11,F11,G11)-1)) -> 1 | Q11: Interested-party | R11: 倍數＝NVFP4 訓練峰值 ÷ FP8（VR 35/17.5＝2；GB300 15/5＝3 [Assumed]）。NVIDIA 公開 12B 模型 10T token NVFP4 預訓練；前沿實驗室未見公開採用。MFU 可能同步下降，未計 | S11: 任一前沿實驗室公開以 FP4 完成主預訓練 | T11: =IF(AND(IF(L11="",K11,L11)="主流",M11="否"),"主流但未入基準：須 Andy 判定",IF(AND(IF(L11="",K11,L11)="非主流",M11="是",I11<>"早期採用"),"非主流卻在基準","一致")) -> 一致
A12: T08 | B12: Looped transformer（權重共享迴圈）— 計算量 | C12: H_FLOP | D12: 每 token FLOPs | E12: 1.5 | F12: 2 | G12: 4 | H12: 2 | I12: 研究 | J12: 0 | K12: =IF(J12>=CST_MainMin,"主流","非主流") -> 非主流 | M12: 否 | N12: 1 | O12: 0 | P12: =IF(M12="是",1,1+O12*N12*(CHOOSE(H12,E12,F12,G12)-1)) -> 1 | Q12: Assumed | R12: 同一組權重迴圈 k 次：FLOPs × k、權重 bytes × 1；能力增量於 Block 4（H_CAP）處理 | S12: 前沿模型卡或技術報告揭露迴圈深度 | T12: =IF(AND(IF(L12="",K12,L12)="主流",M12="否"),"主流但未入基準：須 Andy 判定",IF(AND(IF(L12="",K12,L12)="非主流",M12="是",I12<>"早期採用"),"非主流卻在基準","一致")) -> 一致
A13: T09 | B13: Looped transformer — 每層延遲 | C13: H_TL | D13: 每步逐層延遲 | E13: 1.5 | F13: 2 | G13: 4 | H13: 2 | I13: 研究 | J13: 0 | K13: =IF(J13>=CST_MainMin,"主流","非主流") -> 非主流 | M13: 否 | N13: 1 | O13: 0 | P13: =IF(M13="是",1,1+O13*N13*(CHOOSE(H13,E13,F13,G13)-1)) -> 1 | Q13: Assumed | R13: 迴圈使有效層數 × k，逐層延遲同比增加；與 T08 同時開關 | S13: 同 T08 | T13: =IF(AND(IF(L13="",K13,L13)="主流",M13="否"),"主流但未入基準：須 Andy 判定",IF(AND(IF(L13="",K13,L13)="非主流",M13="是",I13<>"早期採用"),"非主流卻在基準","一致")) -> 一致
A14: T10 | B14: 非同步 RL（rollout 與訓練解耦、部分 rollout） | C14: H_ROLL | D14: rollout 效率 | E14: 1.2 | F14: 1.4 | G14: 1.6 | H14: 2 | I14: 主流 | J14: =SRC_MOD_043+SRC_MOD_044+SRC_MOD_045+SRC_MOD_047 -> 4 | K14: =IF(J14>=CST_MainMin,"主流","非主流") -> 主流 | M14: 是 | N14: 1 | O14: 0 | P14: =IF(M14="是",1,1+O14*N14*(CHOOSE(H14,E14,F14,G14)-1)) -> 1 | Q14: Interested-party | R14: 旗艦模型公開採用：DeepSeek V4.1（幾乎全部 RL 與 OPD，S45）、Zhipu GLM-5（slime，S46）、Moonshot Kimi-Researcher（完全非同步 rollout，S47）、Meta Llama 3（LlamaRL，S48）。閉源四家未找到披露。v5.6 起併入基準：Train_In rollout 效率 0.85（Andy 2026-10-01 決定 (a)） | S14: 閉源實驗室披露同步做法，或前沿規模對照實驗顯示 off-policy 偏差抵銷吞吐增益 | T14: =IF(AND(IF(L14="",K14,L14)="主流",M14="否"),"主流但未入基準：須 Andy 判定",IF(AND(IF(L14="",K14,L14)="非主流",M14="是",I14<>"早期採用"),"非主流卻在基準","一致")) -> 一致
A15: T11 | B15: KV 快取壓縮（FP4 KV 等） | C15: H_KV | D15: KV bytes/token | E15: 0.5 | F15: 0.5 | G15: 0.75 | H15: 2 | I15: 早期採用 | J15: 1 | K15: =IF(J15>=CST_MainMin,"主流","非主流") -> 非主流 | M15: 否 | N15: 1 | O15: 0 | P15: =IF(M15="是",1,1+O15*N15*(CHOOSE(H15,E15,F15,G15)-1)) -> 1 | Q15: Assumed | R15: FP8 → FP4 KV：bytes × 0.5；準確率損失待查 | S15: 第二家實驗室在生產服務公開採用 | T15: =IF(AND(IF(L15="",K15,L15)="主流",M15="否"),"主流但未入基準：須 Andy 判定",IF(AND(IF(L15="",K15,L15)="非主流",M15="是",I15<>"早期採用"),"非主流卻在基準","一致")) -> 一致
A16: T12 | B16: Harness（代理框架） | C16: H_HAR | D16: Har_In 選定檔案（混合權重 w＝開關 × 採用比例） | E16: 1 | F16: 1 | G16: 1 | H16: 2 | I16: 追蹤中 | J16: 0 | K16: =IF(J16>=CST_MainMin,"主流","非主流") -> 非主流 | M16: 否 | N16: 1 | O16: 0 | P16: =IF(M16="是",1,1+O16*N16*(CHOOSE(H16,E16,F16,G16)-1)) -> 1 | Q16: Assumed | R16: v5.9：harness 以參數組表達（輪數、思考保留、思考量、歷史壓縮、快取命中、子代理、狀態保留）加成功率（L1、L2）；倍數欄不使用。基準不開（L3）。ARC-AGI-3（ARC Prize 自測）：GPT-6 Astra 標準 harness 最高推理 62.7%、$26,098 → OpenAI Provider Adapter 同檔 98.6%、$17,332（S58）。主流判定（J14）尚未評估 | S16: 中立方（ARC Prize、METR、Artificial Analysis）在同條件下測得第二個 harness 對照 | T16: =IF(AND(IF(L16="",K16,L16)="主流",M16="否"),"主流但未入基準：須 Andy 判定",IF(AND(IF(L16="",K16,L16)="非主流",M16="是",I16<>"早期採用"),"非主流卻在基準","一致")) -> 一致
A17: 門檻 | B17: 主流判定門檻：公開採用實驗室數 ≥ 本格（J14；K 欄共用） | J17: 2 | Q17: Decision | R17: J14：至少兩家實驗室公開採用即為主流（CST_MainMin）
A18: 掛鉤彙總（同一掛鉤多條目時取乘積；Perf、Perf_Batch、Training 連結本表 E 欄）
A19: 代碼 | B19: 意義 | D19: 作用位置 | E19: 倍數
A20: H_ETAD | B20: decode η_d 倍數 | D20: Perf／Perf_Batch：etadm 列 | E20: =EXP(SUMPRODUCT(($C$5:$C$16="H_ETAD")*LN($P$5:$P$16))) -> 1
A21: H_TL | B21: 每層延遲倍數 | D21: Perf／Perf_Batch：tlm 列 | E21: =EXP(SUMPRODUCT(($C$5:$C$16="H_TL")*LN($P$5:$P$16))) -> 1
A22: H_FLOP | B22: 每 token FLOPs 倍數（推論與訓練） | D22: Perf／Perf_Batch：hflop 列；Training：hflop 列 | E22: =EXP(SUMPRODUCT(($C$5:$C$16="H_FLOP")*LN($P$5:$P$16))) -> 1
A23: H_KV | B23: KV bytes/token 倍數 | D23: Perf／Perf_Batch：hkv 列 | E23: =EXP(SUMPRODUCT(($C$5:$C$16="H_KV")*LN($P$5:$P$16))) -> 1
A24: H_WB | B24: 權重 bytes/param 倍數 | D24: Perf／Perf_Batch：hwb 列 | E24: =EXP(SUMPRODUCT(($C$5:$C$16="H_WB")*LN($P$5:$P$16))) -> 1
A25: H_TPK | B25: 訓練峰值倍數 | D25: Training：htpk 列 | E25: =EXP(SUMPRODUCT(($C$5:$C$16="H_TPK")*LN($P$5:$P$16))) -> 1
A26: H_MFU | B26: 訓練 MFU 倍數 | D26: Training：hmfu 列 | E26: =EXP(SUMPRODUCT(($C$5:$C$16="H_MFU")*LN($P$5:$P$16))) -> 1
A27: H_TOK | B27: 達同等預訓練品質所需 token 倍數 | D27: Training：htok 列 | E27: =EXP(SUMPRODUCT(($C$5:$C$16="H_TOK")*LN($P$5:$P$16))) -> 1
A28: H_ROLL | B28: rollout 效率倍數 | D28: Training：hroll 列 | E28: =EXP(SUMPRODUCT(($C$5:$C$16="H_ROLL")*LN($P$5:$P$16))) -> 1
A29: H_CAP | B29: 能力增量（Block 4 占位，尚無作用） | D29: Block 4 | E29: =EXP(SUMPRODUCT(($C$5:$C$16="H_CAP")*LN($P$5:$P$16))) -> 1
A30: H_HAR | B30: harness（v5.9 起不作倍數；T12 的開關 × 採用比例＝Har_In 混合權重 w） | D30: Har_In → Workload B 節、Harness | E30: =EXP(SUMPRODUCT(($C$5:$C$16="H_HAR")*LN($P$5:$P$16))) -> 1
A32: 注意 | B32: 掛鉤作用於全部世代與層級。新條目：在表中插入一列（範圍內），填倍數、狀態與證據；開關預設 0。Sens_Perf 的 η_d 與每層延遲情境為覆寫值，不受 Registry 影響。

Sheet Perf
A1: Perf — 每架產出引擎（世代 × 層級；各層級 SLO 與參考任務；100% 利用率）
A2: decode：每步時間＝固定延遲＋B × 每序列時間；在 SLO 下解出批次 B*，再受 HBM 容量限制。prefill 為算力受限。黃底為關鍵輸出
A4: 世代 | C4: =INDEX(Spec_Rack!$C$4:$G$4,C6) -> Hopper H100 | D4: =INDEX(Spec_Rack!$C$4:$G$4,D6) -> Hopper H100 | E4: =INDEX(Spec_Rack!$C$4:$G$4,E6) -> Hopper H100 | F4: =INDEX(Spec_Rack!$C$4:$G$4,F6) -> GB200 NVL72 | G4: =INDEX(Spec_Rack!$C$4:$G$4,G6) -> GB200 NVL72 | H4: =INDEX(Spec_Rack!$C$4:$G$4,H6) -> GB200 NVL72 | I4: =INDEX(Spec_Rack!$C$4:$G$4,I6) -> GB300 NVL72 | J4: =INDEX(Spec_Rack!$C$4:$G$4,J6) -> GB300 NVL72 | ... Q4: =INDEX(Spec_Rack!$C$4:$G$4,Q6) -> Rubin Ultra（MGX NVL 單架，72 GPU）
A5: 層級 | C5: =INDEX(Arch!$C$4:$E$4,C7) -> Luna（低層） | D5: =INDEX(Arch!$C$4:$E$4,D7) -> Sol（中層） | E5: =INDEX(Arch!$C$4:$E$4,E7) -> Astra（頂層） | F5: =INDEX(Arch!$C$4:$E$4,F7) -> Luna（低層） | G5: =INDEX(Arch!$C$4:$E$4,G7) -> Sol（中層） | H5: =INDEX(Arch!$C$4:$E$4,H7) -> Astra（頂層） | I5: =INDEX(Arch!$C$4:$E$4,I7) -> Luna（低層） | J5: =INDEX(Arch!$C$4:$E$4,J7) -> Sol（中層） | ... Q5: =INDEX(Arch!$C$4:$E$4,Q7) -> Astra（頂層）
A6: 世代索引 | C6: 1 | D6: 1 | E6: 1 | F6: 2 | G6: 2 | H6: 2 | I6: 3 | J6: 3 | K6: 3 | L6: 4 | M6: 4 | N6: 4 | O6: 5 | P6: 5 | Q6: 5
A7: 層級索引 | C7: 1 | D7: 2 | E7: 3 | F7: 1 | G7: 2 | H7: 3 | I7: 1 | J7: 2 | K7: 3 | L7: 1 | M7: 2 | N7: 3 | O7: 1 | P7: 2 | Q7: 3
A9: 0. Tech_Registry 掛鉤（基準＝1；Registry 未啟用任何條目時與 v5.4 相同）
A10: FLOPs/token 倍數（H_FLOP） | B10: x | C10: =Tech_Registry!$E$22 -> 1 | D10: =Tech_Registry!$E$22 -> 1 | E10: =Tech_Registry!$E$22 -> 1 | F10: =Tech_Registry!$E$22 -> 1 | G10: =Tech_Registry!$E$22 -> 1 | H10: =Tech_Registry!$E$22 -> 1 | I10: =Tech_Registry!$E$22 -> 1 | J10: =Tech_Registry!$E$22 -> 1 | ... Q10: =Tech_Registry!$E$22 -> 1
