Workbook

Sheet 0_總覽
A1: 4-3 A 段｜v13.1（20261017_Tokenomics_v13.1.xlsx）B 級死格逐列建議（唯讀；全簿公式格 51,610；死格 3,604，其中已標用途 1,239、無『用途』標記的 B 級 2,365＝fixture 基準名單）
A3: 處置 | B3: 列數 | C3: 格數 | D3: 其中需 Andy 判斷（列） | E3: 需 Andy 判斷（格）
A4: 保留：顯示用 | B4: 155 | C4: 1540 | D4: 0 | E4: 0
A5: 刪除 | B5: 72 | C5: 509 | D5: 19 | E5: 78
A6: 升級 | B6: 15 | C6: 125 | D6: 15 | E6: 125
A7: 接進 Checks | B7: 7 | C7: 45 | D7: 0 | E7: 0
A8: 升級（隨附上游） | B8: 27 | C8: 141 | D8: 0 | E8: 0
A9: 需 Andy 判斷 | B9: 1 | C9: 5 | D9: 1 | E9: 5
A10: 合計 | B10: 277 | C10: 2365 | D10: 35 | E10: 208
A12: 依頁與處置（格數）
A13: 頁 | B13: 保留：顯示用 | C13: 刪除 | D13: 升級 | E13: 接進 Checks | F13: 升級（隨附上游） | G13: 需 Andy 判斷 | H13: 合計
A14: Perf_Batch | B14: 546 | C14: 0 | D14: 0 | E14: 17 | F14: 0 | G14: 0 | H14: 563
A15: Theory_Rev | B15: 313 | C15: 105 | D15: 45 | E15: 0 | F15: 0 | G15: 0 | H15: 463
A16: Training | B16: 195 | C16: 60 | D16: 30 | E16: 0 | F16: 60 | G16: 0 | H16: 345
A17: Harness | B17: 90 | C17: 125 | D17: 0 | E17: 0 | F17: 0 | G17: 0 | H17: 215
A18: Cap_In | B18: 68 | C18: 16 | D18: 30 | E18: 11 | F18: 81 | G18: 0 | H18: 206
A19: Perf | B19: 75 | C19: 0 | D19: 0 | E19: 15 | F19: 0 | G19: 0 | H19: 90
A20: DC_Cost | B20: 90 | C20: 0 | D20: 0 | E20: 0 | F20: 0 | G20: 0 | H20: 90
A21: Cache_Store | B21: 0 | C21: 90 | D21: 0 | E21: 0 | F21: 0 | G21: 0 | H21: 90
A22: Amortize | B22: 75 | C22: 0 | D22: 15 | E22: 0 | F22: 0 | G22: 0 | H22: 90
A23: Workload | B23: 0 | C23: 50 | D23: 5 | E23: 0 | F23: 0 | G23: 0 | H23: 55
A24: Unit_Cost | B24: 0 | C24: 45 | D24: 0 | E24: 0 | F24: 0 | G24: 0 | H24: 45
A25: Fleet_1GW | B25: 45 | C25: 0 | D25: 0 | E25: 0 | F25: 0 | G25: 0 | H25: 45
... A34: Tech_Registry | B34: 1 | C34: 0 | D34: 0 | E34: 0 | F34: 0 | G34: 0 | H34: 1
A36: 4-0 規則編號（依 v13.1 重判）
A37: 規則 | B37: 列數 | C37: 格數
A38: R04 | B38: 1 | C38: 2
A39: R07 | B39: 5 | C39: 5
A40: R12 | B40: 1 | C40: 5
A41: R16 | B41: 62 | C41: 198
A42: R21 | B42: 10 | C42: 36
A43: R22a | B43: 130 | C43: 1398
A44: R22b | B44: 68 | C44: 721
A46: 預估 B 段完成後公式格總數：51,610 − 刪除 509 ＝ 51,101（若連同鏡像頁同列複本格一併清除，再減 0 ＝ 51,101）
A47: 預估 B 段後死格：3,604 − 刪除 509 − 升級／隨附／接進 Checks 後成為核心 311 ＝ 2,784（保留顯示用的格仍為死格，但補『用途』標記後不再是『無標記』）

Sheet 1_逐列建議
A1: 每列＝v13.1 一個 B 級死格列（同列內各欄合併）。處置四選一（升級／保留：顯示用／接進 Checks／刪除），不確定者標『需 Andy 判斷』；『升級（隨附上游）』＝本身不新增名稱，但因下游列升級而成為核心。問題編號對應工作單『已知問題清單』1–11，— 表示不回答任何一題。
A2: 頁 | B2: 列 | C2: 標籤 | D2: 代表值 | E2: 格數 | F2: 格範圍 | G2: 4-0 規則 | H2: 處置 | I2: 回答的問題（編號） | J2: 建議名稱（升級時） | K2: 理由 | L2: 是否需 Andy 判斷 | M2: 代表公式 | N2: 文件引用（檔名） | O2: 鏡像頁同列公式格 | P2: 承重頁（Load_Bearing）
A3: Spec_Rack | B3: 28 | C3: Scale-up 域 GPU 數 | D3: 8 | E3: 5 | F3: C28:G28 | G3: R22b | H3: 保留：顯示用 | I3: — | K3: 規格表列（Scale-up 域 GPU 數＝SRC_HW_053，Gov_Map 登錄）；刪除會讓 Gov_Map 登錄落空（原則 4 治理材料不刪）。補『用途』標記。 | L3: 否 | M3: =SRC_HW_053 | N3: Tokenomics_builder_v5.md | P3: 是
A4: Spec_Rack | B4: 36 | C4: Ridge point（FLOP/byte） | D4: 590.746269 | E4: 5 | F4: C36:G36 | G4: R22a | H4: 保留：顯示用 | I4: — | K4: roofline 推導鏈的讀數（ridge point＝峰值÷頻寬；建模精神 1a 要求露出推導鏈）；同表其他列是核心格。 | L4: 否 | M4: =C35*1000/C26 | P4: 是
A5: Arch | B5: 15 | C5: vocab | D5: 129280 | E5: 2 | F5: C15:D15 | G5: R22b | H5: 保留：顯示用 | I5: — | K5: 架構規格列（vocab＝SRC_MOD_014，Gov_Map 登錄）；刪除會讓 Gov_Map 登錄落空。補『用途』標記。 | L5: 否 | M5: =SRC_MOD_014 | N5: Tokenomics_builder_v5.md | P5: 是
A6: Arch | B6: 26 | C6: Embedding＋LM head 參數 | D6: 1.059062 | E6: 3 | F6: C26:E26 | G6: R22a | H6: 刪除 | I6: — | K6: Embedding＋LM head 參數：只由 vocab 推出、無任何下游、不回答任何一題；非專家參數另由第 28 列推導。Arch 為承重頁，刪除需 Andy 確認。 | L6: 是 | M6: =C15*C9*2/1000000000 | P6: 是
A7: Arch | B7: 31 | C7: 128K 上下文每序列 KV | D7: 0.35776 | E7: 3 | F7: C31:E31 | G7: R22a | H7: 刪除 | I7: — | K7: 128K 上下文每序列 KV：衍生診斷，無下游；Perf 用 KV bytes/token 自行乘上下文長度（單一定義在 Perf）。Arch 為承重頁，需 Andy 確認。 | L7: 是 | M7: =C25*CST_CtxKV/1000000000 | P7: 是
A8: Serving | B8: 25 | C8: decode 平均上下文 | D8: 8704 | E8: 3 | F8: C25:E25 | G8: R22a | H8: 刪除 | I8: — | K8: decode 平均上下文＝ISL＋OSL/2：與 Perf 第 45 列同式（Perf 才是被取用者）；原則 1 同一定義只存一處。Serving 為承重頁，需 Andy 確認。 | L8: 是 | M8: =C23+C24/2 | P8: 是
A9: Serving | B9: 26 | C9: prefill 平均位置 | D9: 4096 | E9: 3 | F9: C26:E26 | G9: R22a | H9: 刪除 | I9: — | K9: prefill 平均位置＝ISL/2：與 Perf 第 46 列同式。同上。 | L9: 是 | M9: =C23/2 | P9: 是
A10: Workload | B10: 17 | C10: harness 混合權重 w（Tech_Registry T12 開關 × 採用比例） | D10: 0 | E10: 5 | F10: C17:G17 | G10: R22a | H10: 刪除 | I10: — | K10: harness 混合權重 w 的顯示複本（＝B5_W＝IF_HarW 已具名輸出）；原則 1。Workload 為承重頁，需 Andy 確認。 | L10: 是 | M10: =B5_W | P10: 是
A11: Workload | B11: 36 | C11: decode 平均上下文 | D11: 2750 | E11: 5 | F11: C36:G36 | G11: R22a | H11: 刪除 | I11: — | K11: 任務 decode 平均上下文：無下游，Perf 不讀 Workload 的上下文；不回答任何一題。需 Andy 確認（承重頁）。 | L11: 是 | M11: =C6+C7+(C18-1)/2*C23*C26+(C19+C9)/2 | P11: 是
A12: Workload | B12: 37 | C12: 思考占 decode | D12: 0 | E12: 5 | F12: C37:G37 | G12: R22a | H12: 刪除 | I12: — | K12: 思考占 decode：衍生比例，可由 Workload 第 19 與 9 列推得；無下游。需 Andy 確認（承重頁）。 | L12: 是 | M12: =IF(C19+C9>0,C19/(C19+C9),0) | P12: 是
A13: Workload | B13: 38 | C13: 總 token ÷ 一般聊天 | D13: 1 | E13: 5 | F13: C38:G38 | G13: R22a | H13: 升級 | I13: 9 | J13: IF_TaskTokMult | K13: 各任務總 token ÷ 一般聊天＝harness 與 agent 用量對 token 的放大倍數（本模型 1／2.07／9.2／36.8／498 對 Anthropic 揭露 4／15，第 40 列已標對照）。目前下游只能自行加總 IF_TaskTok* 再相除。 | L13: 是 | M13: =C35/$C$35 | P13: 是
A14: Workload | B14: 39 | C14: 總 token ÷ 推理聊天 | D14: 0.483871 | E14: 5 | F14: C39:G39 | G14: R22a | H14: 刪除 | I14: — | K14: 總 token ÷ 推理聊天：第 38 列換一個分母，沒有獨立資訊。需 Andy 確認（承重頁）。 | L14: 是 | M14: =C35/$D$35 | P14: 是
A15: Workload | B15: 43 | C15: VR200 × Luna | D15: 8.6e-05 | E15: 5 | F15: C43:G43 | G15: R22b | H15: 刪除 | I15: — | K15: 每任務服務成本（VR200／GB300 × 三層級，不含快取儲存）：Harness 第 67–84 列已有含儲存的現行版，且 IF_CostSuccVR／GB_* 已具名；此為較舊的簡化版，原則 1。Theory_Rev 第 81–86 列隨之刪除。需 Andy 確認（承重頁）。 | L15: 是 | M15: =IF(ISNUMBER(Unit_Cost!M21),(C32*Unit_Cost!M19+C33*Unit_Cost!M20+C34*Unit_Cost!M21)/1000000,"SLO 不可達") | N15: 20261015_稽核0_報告.md | P15: 是
A16: Workload | B16: 44 | C16: VR200 × Sol | D16: 0.000279 | E16: 5 | F16: C44:G44 | G16: R22b | H16: 刪除 | I16: — | K16: 每任務服務成本（VR200／GB300 × 三層級，不含快取儲存）：Harness 第 67–84 列已有含儲存的現行版，且 IF_CostSuccVR／GB_* 已具名；此為較舊的簡化版，原則 1。Theory_Rev 第 81–86 列隨之刪除。需 Andy 確認（承重頁）。 | L16: 是 | M16: =IF(ISNUMBER(Unit_Cost!M34),(C32*Unit_Cost!M32+C33*Unit_Cost!M33+C34*Unit_Cost!M34)/1000000,"SLO 不可達") | N16: 20261015_稽核0_報告.md | P16: 是
A17: Workload | B17: 45 | C17: VR200 × Astra | D17: 0.00129 | E17: 5 | F17: C45:G45 | G17: R22b | H17: 刪除 | I17: — | K17: 每任務服務成本（VR200／GB300 × 三層級，不含快取儲存）：Harness 第 67–84 列已有含儲存的現行版，且 IF_CostSuccVR／GB_* 已具名；此為較舊的簡化版，原則 1。Theory_Rev 第 81–86 列隨之刪除。需 Andy 確認（承重頁）。 | L17: 是 | M17: =IF(ISNUMBER(Unit_Cost!M47),(C32*Unit_Cost!M45+C33*Unit_Cost!M46+C34*Unit_Cost!M47)/1000000,"SLO 不可達") | N17: 20261015_稽核0_報告.md | P17: 是
A18: Workload | B18: 46 | C18: GB300 × Luna | D18: 0.00011 | E18: 5 | F18: C46:G46 | G18: R22b | H18: 刪除 | I18: — | K18: 每任務服務成本（VR200／GB300 × 三層級，不含快取儲存）：Harness 第 67–84 列已有含儲存的現行版，且 IF_CostSuccVR／GB_* 已具名；此為較舊的簡化版，原則 1。Theory_Rev 第 81–86 列隨之刪除。需 Andy 確認（承重頁）。 | L18: 是 | M18: =IF(ISNUMBER(Unit_Cost!J21),(C32*Unit_Cost!J19+C33*Unit_Cost!J20+C34*Unit_Cost!J21)/1000000,"SLO 不可達") | N18: 20261015_稽核0_報告.md | P18: 是
A19: Workload | B19: 47 | C19: GB300 × Sol | D19: 0.000374 | E19: 5 | F19: C47:G47 | G19: R22b | H19: 刪除 | I19: — | K19: 每任務服務成本（VR200／GB300 × 三層級，不含快取儲存）：Harness 第 67–84 列已有含儲存的現行版，且 IF_CostSuccVR／GB_* 已具名；此為較舊的簡化版，原則 1。Theory_Rev 第 81–86 列隨之刪除。需 Andy 確認（承重頁）。 | L19: 是 | M19: =IF(ISNUMBER(Unit_Cost!J34),(C32*Unit_Cost!J32+C33*Unit_Cost!J33+C34*Unit_Cost!J34)/1000000,"SLO 不可達") | N19: 20261015_稽核0_報告.md | P19: 是
A20: Workload | B20: 48 | C20: GB300 × Astra | D20: 0.002046 | E20: 5 | F20: C48:G48 | G20: R22b | H20: 刪除 | I20: — | K20: 每任務服務成本（VR200／GB300 × 三層級，不含快取儲存）：Harness 第 67–84 列已有含儲存的現行版，且 IF_CostSuccVR／GB_* 已具名；此為較舊的簡化版，原則 1。Theory_Rev 第 81–86 列隨之刪除。需 Andy 確認（承重頁）。 | L20: 是 | M20: =IF(ISNUMBER(Unit_Cost!J47),(C32*Unit_Cost!J45+C33*Unit_Cost!J46+C34*Unit_Cost!J47)/1000000,"SLO 不可達") | N20: 20261015_稽核0_報告.md | P20: 是
A21: Tech_Registry | B21: 30 | C21: H_HAR | D21: 1 | E21: 1 | F21: E30 | G21: R22a | H21: 保留：顯示用 | I21: — | K21: 掛鉤彙總表（E20–E29 是核心格）的形狀；H_HAR 的實際作用在 Workload 的 B5_W（T12 開關），此格為同表一致的彙總讀數。 | L21: 否 | M21: =EXP(SUMPRODUCT(($C$5:$C$16="H_HAR")*LN($P$5:$P$16)))
A22: Perf | B22: 73 | C22: 權重占可用 HBM | D22: 0.135624 | E22: 15 | F22: C73:Q73 | G22: R22a | H22: 保留：顯示用 | I22: — | K22: 記憶體配置（E 節）的讀數：權重／KV 占可用 HBM；建模精神 1a 的推導鏈；與 Perf_Batch 同列鏡像（D13 常設測試），刪單邊會使鏡像測試失敗。 | L22: 否 | M22: =C72/C69 | N22: 20261015_稽核2_報告.md
A23: Perf | B23: 89 | C23: 實際每用戶速度 | D23: 84.300059 | E23: 15 | F23: C89:Q89 | G23: R22a | H23: 接進 Checks | I23: — | K23: 實際每用戶速度須 ≥ Serving SLO（B* 取 SLO 與 HBM 上限的較小者，故恆成立；程式或輸入出錯時才會失敗）。屬驗證材料，可寫成能失敗的檢查（原則 4）。Perf 與 Perf_Batch 合為一條檢查。 | L23: 否 | M23: =IF(C87>0,C49/((C79+C87*C83)/1000),0) | N23: 20261015_稽核2_報告.md
A24: Perf | B24: 91 | C24: KV 占可用 HBM | D24: 0.002965 | E24: 15 | F24: C91:Q91 | G24: R22a | H24: 保留：顯示用 | I24: — | K24: 記憶體配置（E 節）的讀數：權重／KV 占可用 HBM；建模精神 1a 的推導鏈；與 Perf_Batch 同列鏡像（D13 常設測試），刪單邊會使鏡像測試失敗。 | L24: 否 | M24: =C87*C34*C45/1000000000/C69 | N24: 20261015_稽核2_報告.md
A25: Perf | B25: 94 | C25: prefill GPU 占比 | D25: 0.255639 | E25: 15 | F25: C94:Q94 | G25: R22b | H25: 保留：顯示用 | I25: — | K25: P:D 配比（prefill GPU 占比，內部名稱 DRV_PreShare）：每架產出推導鏈的讀數；Perf 第 118 列讀它；與 Perf_Batch 鏡像。 | L25: 否 | M25: =IF(ISNUMBER(C93),IF(C93>0,((C43*(1-B4_CacheHit))/C75)/C93,0),C93) | N25: 20261015_v5.36.md、20261015_v5.36A_查證.md、20261015_稽核2_報告.md、Tokenomics_builder_v5.md
A26: Perf | B26: 99 | C26: 每 GW decode 產出 | D26: 12469804501.1635 | E26: 15 | F26: C99:Q99 | G26: R22a | H26: 保留：顯示用 | I26: 5 | K26: 每 GW decode 產出：token 類型拆分的讀數（IF_TokRackD_* 具名、IF_RacksPerGW 具名，下游可相乘）；因與 Perf_Batch 第 99 列鏡像（D13），單邊刪除會破壞鏡像測試，故保留。 | L26: 否 | M26: =IF(ISNUMBER(C96),C96*C25*8760*3600/1000000,C96) | N26: 20261015_稽核0_報告.md、Tokenomics_builder_v5.md
A27: Perf | B27: 118 | C27: 每 decode token 實際能量（平均用電口徑） | D27: 1.385504 | E27: 15 | F27: C118:Q118 | G27: R22a | H27: 保留：顯示用 | I27: — | K27: 每 decode token 實際能量（平均用電口徑）：能量閉合（J 節）的讀數；與 Perf_Batch 鏡像。 | L27: 否 | M27: =IF(ISNUMBER(C96),IF(C96>0,C115*1000*(1-C94)/C96,0),C96)
A28: Unit_Cost | B28: 23 | C28: 參考請求混合 $/M 總 token — 經濟、100% | D28: 0.079418 | E28: 15 | F28: C23:Q23 | G28: R22a | H28: 刪除 | I28: 6 | K28: 『參考請求混合 $/M 總 token（經濟、100%）』：混合數字，Amortize 第 14／23／33 列已有含快取儲存的『參考請求混合服務成本』（IF_FullCost* 的基礎），單價的唯一定義在那裡（原則 1）；三層級分項成本 IF_CostPre／CostDec／CostCache 已具名。 | L28: 否 | M28: =IF(ISNUMBER(C18),(Serving!$C$23*C16+Serving!$C$24*C18)/(Serving!$C$23+Serving!$C$24),C18)
A29: Unit_Cost | B29: 36 | C29: 參考請求混合 $/M 總 token — 經濟、100% | D29: 0.267526 | E29: 15 | F29: C36:Q36 | G29: R22a | H29: 刪除 | I29: 6 | K29: 『參考請求混合 $/M 總 token（經濟、100%）』：混合數字，Amortize 第 14／23／33 列已有含快取儲存的『參考請求混合服務成本』（IF_FullCost* 的基礎），單價的唯一定義在那裡（原則 1）；三層級分項成本 IF_CostPre／CostDec／CostCache 已具名。 | L29: 否 | M29: =IF(ISNUMBER(C31),(Serving!$D$23*C29+Serving!$D$24*C31)/(Serving!$D$23+Serving!$D$24),C31)
A30: Unit_Cost | B30: 49 | C30: 參考請求混合 $/M 總 token — 經濟、100% | D30: 1.215058 | E30: 15 | F30: C49:Q49 | G30: R22a | H30: 刪除 | I30: 6 | K30: 『參考請求混合 $/M 總 token（經濟、100%）』：混合數字，Amortize 第 14／23／33 列已有含快取儲存的『參考請求混合服務成本』（IF_FullCost* 的基礎），單價的唯一定義在那裡（原則 1）；三層級分項成本 IF_CostPre／CostDec／CostCache 已具名。 | L30: 否 | M30: =IF(ISNUMBER(C44),(Serving!$E$23*C42+Serving!$E$24*C44)/(Serving!$E$23+Serving!$E$24),C44)
A31: DC_Cost | B31: 34 | C31: 每 GPU 資本支出（含廠房） | D31: 44.05314 | E31: 15 | F31: C34:Q34 | G31: R22a | H31: 保留：顯示用 | I31: 5 | K31: 敏感度頁（Sensitivity）有同列同標籤的列，常設測試以此核心列為逐格比對基準；刪核心列＝該敏感度列失去比對、變成孤兒定義（6b(a) 敏感度頁保留）。下游已有 IF_Capex*／IF_HoldEcon／IF_AvgDraw 等 具名輸出，核心列保留並補『用途』標記。 | L31: 否 | M31: =C33*1000000/C14
A32: DC_Cost | B32: 35 | C32: 每 MW IT 資本支出 | D32: 31.632269 | E32: 15 | F32: C35:Q35 | G32: R22a | H32: 保留：顯示用 | I32: 5 | K32: 敏感度頁（Sensitivity）有同列同標籤的列，常設測試以此核心列為逐格比對基準；刪核心列＝該敏感度列失去比對、變成孤兒定義（6b(a) 敏感度頁保留）。下游已有 IF_Capex*／IF_HoldEcon／IF_AvgDraw 等 具名輸出，核心列保留並補『用途』標記。 | L32: 否 | M32: =C33*1000/C8
A33: DC_Cost | B33: 59 | C33: 每架小時持有成本 — 經濟 | D33: 34.548636 | E33: 15 | F33: C59:Q59 | G33: R22a | H33: 保留：顯示用 | I33: 5 | K33: 敏感度頁（Sensitivity）有同列同標籤的列，常設測試以此核心列為逐格比對基準；刪核心列＝該敏感度列失去比對、變成孤兒定義（6b(a) 敏感度頁保留）。下游已有 IF_Capex*／IF_HoldEcon／IF_AvgDraw 等 具名輸出，核心列保留並補『用途』標記。 | L33: 否 | M33: =C55*1000000000/(C12*8760)
A34: DC_Cost | B34: 60 | C34: 年用電（設施端） | D34: 6.7452 | E34: 15 | F34: C60:Q60 | G34: R22a | H34: 保留：顯示用 | I34: 5 | K34: 敏感度頁（Sensitivity）有同列同標籤的列，常設測試以此核心列為逐格比對基準；刪核心列＝該敏感度列失去比對、變成孤兒定義（6b(a) 敏感度頁保留）。下游已有 IF_Capex*／IF_HoldEcon／IF_AvgDraw 等 具名輸出，核心列保留並補『用途』標記。 | L34: 否 | M34: =C8*C41*C15*8760/1000000
A35: DC_Cost | B35: 61 | C35: 資本回收占經濟口徑 | D35: 0.836222 | E35: 15 | F35: C61:Q61 | G35: R22a | H35: 保留：顯示用 | I35: 5 | K35: 成本結構讀數（資本回收占經濟口徑、電費占經濟口徑）：同節第 57–58 列為核心格；供人讀取成本組成，下游以 IF_Depr*／IF_PowerCost 自算。 | L35: 否 | M35: =(C53+C54)/C55
A36: DC_Cost | B36: 62 | C36: 電費占經濟口徑 | D36: 0.059595 | E36: 15 | F36: C62:Q62 | G36: R22a | H36: 保留：顯示用 | I36: 5 | K36: 成本結構讀數（資本回收占經濟口徑、電費占經濟口徑）：同節第 57–58 列為核心格；供人讀取成本組成，下游以 IF_Depr*／IF_PowerCost 自算。 | L36: 否 | M36: =C43/C55
A37: Train_In | B37: 44 | C37: DeepSeek R1 RL GPU 小時 ÷ V3 預訓練 | D37: 0.05518 | E37: 1 | F37: C44 | G37: R22b | H37: 保留：顯示用 | I37: 8 | K37: RL 占比的外部對照（DeepSeek R1 RL 為 V3 預訓練 0.055、Grok 4 宣稱 1.0）；Gov_Map 登錄，Checks 第 157–158 列已拿模型 RL 占比對外部。Train_In 為承重頁，不刪。 | L37: 否 | M37: =SRC_MOD_034/SRC_MOD_040 | N37: 20261005_v5.18.md、Tokenomics_builder_v5.md | P37: 是
A38: Train_In | B38: 45 | C38: Grok 4 RL ÷ 預訓練（宣稱） | D38: 1 | E38: 1 | F38: C45 | G38: R22b | H38: 保留：顯示用 | I38: 8 | K38: RL 占比的外部對照（DeepSeek R1 RL 為 V3 預訓練 0.055、Grok 4 宣稱 1.0）；Gov_Map 登錄，Checks 第 157–158 列已拿模型 RL 占比對外部。Train_In 為承重頁，不刪。 | L38: 否 | M38: =SRC_MOD_036 | N38: Tokenomics_builder_v5.md | P38: 是
A39: Perf_Batch | B39: 12 | C39: 權重 bytes/param 倍數（H_WB） | D39: 1 | E39: 2 | F39: R12:S12 | G39: R04 | H39: 保留：顯示用 | I39: — | K39: R–S 欄（VR200 以 FP8 rollout 的未接線情境，4-0 R04）該列的 H_WB 讀取；其餘 R–S 列已標『情境對照（未接線）』，此列補齊同一標記。 | L39: 否 | M39: =Tech_Registry!$E$24
A40: Perf_Batch | B40: 22 | C40: GPU 封裝／架 | D40: 32 | E40: 17 | F40: C22:S22 | G40: R22b | H40: 保留：顯示用 | I40: — | K40: 與 Perf 逐列鏡像（D13；test_perf_batch_differs_only_on_whitelist_rows 以 Perf 為準逐格比對）：批次引擎沿用同一條推導鏈，Training 只取其中幾列，其餘列不進輸出但屬鏡像形狀；刪除須連同 Perf／Perf_Prod 同列並改白名單，收益小。補『用途』標記。 | L40: 否 | M40: =INDEX(Spec_Rack!$C$6:$G$6,C$6)
...

Sheet 2_升級名稱
A1: 升級＝新名稱進入下游契約（IF_／L1_），須 Andy 同意。層級與 token 類型標籤依 CLAUDE.md 第 1a 節；『付費 token（混合）』者，Segment B 實作時須確認能否依層級分列，不能者在名稱後註明為混合口徑。
A2: 建議名稱 | B2: 來源頁 | C2: 來源列 | D2: 標籤 | E2: 代表值 | F2: 格數 | G2: 單位 | H2: 模型層級／口徑 | I2: token 類型 | J2: 備註 | K2: 回答的問題 | L2: 需 Andy 判斷
A3: L1_MAPI_Ser | B3: Cap_In | C3: 206 | D3: m_API | E3: 0.657758 | F3: 4 | G3: 倍（營收 ÷ 標價 token 成本） | H3: API（依模型層級混合，與 L1_MAPI 同口徑） | I3: 新鮮輸入＋快取輸入＋輸出（付費 token，混合） | J3: C:F＝2025／2026 Q1／Q2／FY2026 | K3: 1 | L3: 是
A4: L1_MSub_Ser | B4: Cap_In | C4: 207 | D4: m_消費訂閱 | E4: 4.972653 | F4: 4 | G4: 倍 | H4: 消費訂閱方案 | I4: 付費 token（混合） | J4: 同上 | K4: 1 | L4: 是
A5: L1_MSeat_Ser | B5: Cap_In | C5: 208 | D5: m_商用席次 | E5: 2.131137 | F5: 4 | G5: 倍 | H5: 商用席次方案 | I5: 付費 token（混合） | J5: 同上；席次占比與 token 份額為 Assumed，下游須帶區間 | K5: 1 | L5: 是
A6: L1_MImplied_Ser | B6: Cap_In | C6: 209 | D6: m_整體＝m 分子營收 ÷（(API token ＋ ChatGPT 付費 token) × 單價） | E6: 2.033528 | F6: 4 | G6: 倍 | H6: 整體（token 加權） | I6: 付費 token（混合） | J6: 同上；FY 欄須等於 L1_MImplied 對應口徑 | K6: 1 | L6: 是
A7: L1_MFleet_Ser | B7: Cap_In | C7: 223 | D7: m_fleet＝m 分子營收 ÷（機隊付費 token × 機隊口徑單價 B4_PriceFleet；Cap_In K 節；v6.3 K1） | E7: 0.407295 | F7: 4 | G7: 倍 | H7: 機隊口徑 | I7: 付費 token（混合） | J7: 同上 | K7: 1 | L7: 是
A8: L1_MFleetFloor／_Lo／_Hi | B8: Cap_In | C8: 121 | D8: m 下限（上限讀法）＝營收 ÷（機隊付費 token 上限 × 2025 年度機隊口徑混合有效單價（AL_PriceFleet25：可達層級重新正規化；v6.3 | E8: 0.300967 | F8: 4 | G8: 倍 | H8: 機隊口徑（上限讀法） | I8: 付費 token（混合） | J8: 與 L1_MFleet_Lo(0.184) 區間定義不同，升級後衝突會露出，需 Andy 定義 | K8: 1 | L8: 是
A9: L1_MFleet_P25Lo | B9: Cap_In | C9: 285 | D9: m（2025 單價取低端）＝營收 ÷（機隊付費 token × AL_PriceFleet25_Lo） | E9: 0.783007 | F9: 3 | G9: 倍 | H9: 機隊口徑，2025 單價取低端 | I9: 付費 token（混合） | J9: 契約第 4 節：價格區間不交叉進 _Lo／_Hi，故另立名稱 | K9: 1 | L9: 是
A10: L1_MFleet_P25Hi | B10: Cap_In | C10: 286 | D10: m（2025 單價取高端）＝營收 ÷（機隊付費 token × AL_PriceFleet25_Hi） | E10: 0.236138 | F10: 3 | G10: 倍 | H10: 機隊口徑，2025 單價取高端 | I10: 付費 token（混合） | J10: 同上 | K10: 1 | L10: 是
A11: IF_TaskTokMult | B11: Workload | C11: 38 | D11: 總 token ÷ 一般聊天 | E11: 1 | F11: 5 | G11: 倍（總 token ÷ 一般聊天） | H11: 任務別（聊天／搜尋／程式／agent／長 agent），非模型層級 | I11: 總 token（新鮮＋快取輸入＋思考＋可見輸出） | J11: 橫列＝5 種任務 | K11: 9 | L11: 是
A12: IF_TrainFLOP_Luna／_Sol／_Astra | B12: Training | C12: 109 | D12: 最終訓練 FLOPs | E12: 4.80829842560294e+24 | F12: 15 | G12: FLOPs（單一模型最終訓練） | H12: Luna／Sol／Astra 三世代 | I12: 不適用（訓練側，非 token 計價） | J12: 預訓練＋長上下文＋後訓練＋合成資料＋評測 | K12: 8 | L12: 是
A13: IF_TrainInferShare_Luna／_Sol／_Astra | B13: Training | C13: 114 | D13: 推論型占最終訓練 | E13: 0.617273 | F13: 15 | G13: 比例（0–1） | H13: 三世代 | I13: 不適用（GPU 小時構成） | J13: 推論型占最終訓練 GPU 小時 | K13: 8 | L13: 是
A14: IF_GMDefault_Luna | B14: Theory_Rev | C14: 24 | D14: 理論毛利率（OpenAI 單價；K6 預設 (c) 全成本） | E14: -1.644666 | F14: 15 | G14: 比例（毛利率） | H14: Luna；OpenAI 單價；K6 預設 (c) 全成本 | I14: 付費 token（混合；依層級另列） | J14: H 欄以後依層級／token 類型分列 | K14: 5 | L14: 是
... A17: IF_AmortRevShare | B17: Amortize | C17: 49 | D17: (d) 攤提占付費營收（各層級相同） | E17: 0.599632 | F17: 15 | G17: 比例（攤提 ÷ 付費營收） | H17: 各層級相同（合計口徑） | I17: 付費營收（混合） | J17: 各層級相同故不分列 | K17: 2 | L17: 是

Sheet 3_需Andy判斷
A1: 分類 | B1: 頁 | C1: 列 | D1: 標籤 | E1: 格數 | F1: 建議處置 | G1: 問題 | H1: 建議名稱 | I1: 理由
A2: 刪除承重頁的列 | B2: Arch | C2: 26 | D2: Embedding＋LM head 參數 | E2: 3 | F2: 刪除 | G2: — | I2: Embedding＋LM head 參數：只由 vocab 推出、無任何下游、不回答任何一題；非專家參數另由第 28 列推導。Arch 為承重頁，刪除需 Andy 確認。
A3: 刪除承重頁的列 | B3: Arch | C3: 31 | D3: 128K 上下文每序列 KV | E3: 3 | F3: 刪除 | G3: — | I3: 128K 上下文每序列 KV：衍生診斷，無下游；Perf 用 KV bytes/token 自行乘上下文長度（單一定義在 Perf）。Arch 為承重頁，需 Andy 確認。
A4: 刪除承重頁的列 | B4: Cap_In | C4: 138 | D4: API 占比（顯示；＝API 營收 ÷ 營收） | E4: 3 | F4: 刪除 | G4: 1 | I4: API 占比（顯示）：與 H10-1 第 190 列、H8-1 第 137 列÷第 69 列同義；原則 1。需 Andy 確認（承重頁）。
A5: 刪除承重頁的列 | B5: Cap_In | C5: 204 | D5: L_price（I 節；顯示用，不進 m） | E5: 4 | F5: 刪除 | G5: — | I5: L_price 逐期複本（四欄都等於第 232 列；『顯示用，不進 m』）；L1_LPrice 已具名；原則 1。需 Andy 確認（承重頁）。
A6: 刪除承重頁的列 | B6: Cap_In | C6: 231 | D6: k＝LN(1 ＋ g) | E6: 3 | F6: 刪除 | G6: — | I6: k＝LN(1＋g)：中間量；第 232 列的 L_price 公式自帶 LN，沒有讀它。需 Andy 確認（承重頁）。
A7: 刪除承重頁的列 | B7: Cap_In | C7: 245 | D7: 請求形狀修正 κ（Alloc_In；AL_Kappa） → L1_GapISL＝1 ÷ κ | E7: 3 | F7: 刪除 | G7: — | I7: 請求形狀修正 κ 的複本（＝AL_Kappa；L1_GapISL＝1÷κ 已具名）；原則 1。需 Andy 確認（承重頁）。
A8: 刪除承重頁的列 | B8: Cap_In | C8: 282 | D8: 2025 混合有效單價 ÷ 2026 快照（第 90 列） | E8: 3 | F8: 刪除 | G8: — | I8: 2025 混合有效單價 ÷ 2026 快照：L1_Price25Mix（具名）與第 90 列相除即得。需 Andy 確認（承重頁）。
A9: 刪除承重頁的列 | B9: Serving | C9: 25 | D9: decode 平均上下文 | E9: 3 | F9: 刪除 | G9: — | I9: decode 平均上下文＝ISL＋OSL/2：與 Perf 第 45 列同式（Perf 才是被取用者）；原則 1 同一定義只存一處。Serving 為承重頁，需 Andy 確認。
A10: 刪除承重頁的列 | B10: Serving | C10: 26 | D10: prefill 平均位置 | E10: 3 | F10: 刪除 | G10: — | I10: prefill 平均位置＝ISL/2：與 Perf 第 46 列同式。同上。
A11: 刪除承重頁的列 | B11: Workload | C11: 17 | D11: harness 混合權重 w（Tech_Registry T12 開關 × 採用比例） | E11: 5 | F11: 刪除 | G11: — | I11: harness 混合權重 w 的顯示複本（＝B5_W＝IF_HarW 已具名輸出）；原則 1。Workload 為承重頁，需 Andy 確認。
A12: 刪除承重頁的列 | B12: Workload | C12: 36 | D12: decode 平均上下文 | E12: 5 | F12: 刪除 | G12: — | I12: 任務 decode 平均上下文：無下游，Perf 不讀 Workload 的上下文；不回答任何一題。需 Andy 確認（承重頁）。
A13: 刪除承重頁的列 | B13: Workload | C13: 37 | D13: 思考占 decode | E13: 5 | F13: 刪除 | G13: — | I13: 思考占 decode：衍生比例，可由 Workload 第 19 與 9 列推得；無下游。需 Andy 確認（承重頁）。
... A20: 刪除承重頁的列 | B20: Workload | C20: 48 | D20: GB300 × Astra | E20: 5 | F20: 刪除 | G20: — | I20: 每任務服務成本（VR200／GB300 × 三層級，不含快取儲存）：Harness 第 67–84 列已有含儲存的現行版，且 IF_CostSuccVR／GB_* 已具名；此為較舊的簡化版，原則 1。Theory_Rev 第 81–86 列隨之刪除。需 Andy 確認（承重頁）。
A21: 升級（新名稱進契約） | B21: Amortize | C21: 49 | D21: (d) 攤提占付費營收（各層級相同） | E21: 15 | F21: 升級 | G21: 2 | H21: IF_AmortRevShare | I21: (d) 攤提占付費營收 0.60：訓練攤提吃掉付費營收多少，是『回本嗎』在營收側的直接讀法（各層級相同，故為合計口徑）。目前下游只能自行用 IF_AmortRev_* 與營收相除。
A22: 升級（新名稱進契約） | B22: Cap_In | C22: 121 | D22: m 下限（上限讀法）＝營收 ÷（機隊付費 token 上限 × 2025 年度機隊口徑混合有效單價（AL_PriceFleet25：可達層級重新正規化；v6.3 | E22: 4 | F22: 升級 | G22: 1 | H22: L1_MFleetFloor（含 _Lo／_Hi） | I22: m 下限（上限讀法）0.301：『m 不可能低於此值』的物理下界，目前只出現在說明文字。注意 L1_MFleet_Lo（0.184）低於這個下限，兩者的區間定義不同（前者含 τ 區間），升級後下游才看得到這個衝突。
A23: 升級（新名稱進契約） | B23: Cap_In | C23: 206 | D23: m_API | E23: 4 | F23: 升級 | G23: 1 | H23: L1_MAPI_Ser | I23: m_API 的季度序列（2025 0.66／2026 Q1 0.29／Q2 0.34／FY 0.35）：『m 是多少、由哪些分項組成』的時間序列，目前 L1_MAPI 只有 2025 單點。
A24: 升級（新名稱進契約） | B24: Cap_In | C24: 207 | D24: m_消費訂閱 | E24: 4 | F24: 升級 | G24: 1 | H24: L1_MSub_Ser | I24: m_消費訂閱的季度序列。
A25: 升級（新名稱進契約） | B25: Cap_In | C25: 208 | D25: m_商用席次 | E25: 4 | F25: 升級 | G25: 1 | H25: L1_MSeat_Ser | I25: m_商用席次的季度序列（FY2026 8.04，席次占比與 token 份額為 Assumed）。
A26: 升級（新名稱進契約） | B26: Cap_In | C26: 209 | D26: m_整體＝m 分子營收 ÷（(API token ＋ ChatGPT 付費 token) × 單價） | E26: 4 | F26: 升級 | G26: 1 | H26: L1_MImplied_Ser | I26: m_整體（合併）的季度序列。
A27: 升級（新名稱進契約） | B27: Cap_In | C27: 223 | D27: m_fleet＝m 分子營收 ÷（機隊付費 token × 機隊口徑單價 B4_PriceFleet；Cap_In K 節；v6.3 K1） | E27: 4 | F27: 升級 | G27: 1 | H27: L1_MFleet_Ser | I27: m_fleet（機隊口徑）的季度序列（2025 0.41／2026 Q1 0.20／Q2 0.23／FY 0.30）：問 1『由哪些分項組成』中的機隊項，目前 L1_MFleet 只有 2025 單點。
A28: 升級（新名稱進契約） | B28: Cap_In | C28: 285 | D28: m（2025 單價取低端）＝營收 ÷（機隊付費 token × AL_PriceFleet25_Lo） | E28: 3 | F28: 升級 | G28: 1 | H28: L1_MFleet_P25Lo | I28: m 以 2025 單價低端計（0.78，D／E 欄為 τ 區間端點）。契約第 4 節明定『價格區間不交叉進 m 的 _Lo／_Hi』，所以價格不確定性造成的 m 範圍（0.24–0.78）目前下游完全看不到。
A29: 升級（新名稱進契約） | B29: Cap_In | C29: 286 | D29: m（2025 單價取高端）＝營收 ÷（機隊付費 token × AL_PriceFleet25_Hi） | E29: 3 | F29: 升級 | G29: 1 | H29: L1_MFleet_P25Hi | I29: m 以 2025 單價高端計（0.24）。同上。
A30: 升級（新名稱進契約） | B30: Theory_Rev | C30: 24 | D30: 理論毛利率（OpenAI 單價；K6 預設 (c) 全成本） | E30: 15 | F30: 升級 | G30: 5 | H30: IF_GMDefault_Luna | I30: 理論毛利率（OpenAI 單價；K6 預設 (c) 全成本）：問 5『毛利，分世代與層級』的預設口徑；目前只有 L1_Ans5_FullMargin 一個格（Sol、VR200）。
A31: 升級（新名稱進契約） | B31: Theory_Rev | C31: 42 | D31: 理論毛利率（OpenAI 單價；K6 預設 (c) 全成本） | E31: 15 | F31: 升級 | G31: 5 | H31: IF_GMDefault_Sol | I31: 同上（Sol）。
A32: 升級（新名稱進契約） | B32: Theory_Rev | C32: 60 | D32: 理論毛利率（OpenAI 單價；K6 預設 (c) 全成本） | E32: 15 | F32: 升級 | G32: 5 | H32: IF_GMDefault_Astra | I32: 同上（Astra）。
... A35: 升級（新名稱進契約） | B35: Workload | C35: 38 | D35: 總 token ÷ 一般聊天 | E35: 5 | F35: 升級 | G35: 9 | H35: IF_TaskTokMult | I35: 各任務總 token ÷ 一般聊天＝harness 與 agent 用量對 token 的放大倍數（本模型 1／2.07／9.2／36.8／498 對 Anthropic 揭露 4／15，第 40 列已標對照）。目前下游只能自行加總 IF_TaskTok* 再相除。
A36: 無法決定 | B36: Har_In | C36: 44 | D36: 供應商專屬（1＝是） | E36: 5 | F36: 需 Andy 判斷 | G36: 9 | I36: 『供應商專屬（1＝是）』（內部名稱 B5_SelVendor）沒有任何公式讀取，但 Harness 第 157 列說明稱『選定檔案供應商專屬時，前緣組合綁定該…』。若說明為真，這是未接線的功能（應接進前緣列）；若功能已放棄，應刪除此列與說明。

Sheet 4_接進Checks
A1: 頁 | B1: 列 | C1: 標籤 | D1: 格數 | E1: 格範圍 | F1: 問題 | G1: 接線方式與理由
A2: Perf | B2: 89 | C2: 實際每用戶速度 | D2: 15 | E2: C89:Q89 | F2: — | G2: 實際每用戶速度須 ≥ Serving SLO（B* 取 SLO 與 HBM 上限的較小者，故恆成立；程式或輸入出錯時才會失敗）。屬驗證材料，可寫成能失敗的檢查（原則 4）。Perf 與 Perf_Batch 合為一條檢查。
A3: Perf_Batch | B3: 89 | C3: 實際每用戶速度 | D3: 17 | E3: C89:S89 | F3: — | G3: 實際每用戶速度須 ≥ 速度下限；與 Perf 第 89 列合為一條檢查（見該列）。
A4: Cap_In | B4: 147 | C4: m_整體（token 加權）＝Σ營收 ÷（Σtoken × 單價） | D4: 3 | E4: C147:E147 | F4: 1 | G4: m_整體（token 加權）須等於 L1_MImplied（第 94 列）：第 148 列已有『自我檢查』但只顯示、不進 Checks；寫成 Checks 的能失敗檢查（容差 1e-9）。
A5: Cap_In | B5: 175 | C5: 殘差：需求 ÷ 上限 | D5: 4 | E5: C175:G175 | F5: 4 | G5: 殘差：需求 ÷ 上限須 ≤ 1（需求 token 不可能超過機隊有效產能上限；現值 0.148）。現有 Checks M4 只檢查需求÷點估計（0.5–2 之外為 WARN）；上限讀法可寫成必然失敗的檢查。G175 為說明文字（同類動態文字，保留）。
A6: Cap_In | B6: 215 | C6: 世代組合合計（應為 100%） | D6: 4 | E6: C215:F215 | F6: — | G6: 2026 服務世代組合合計須為 100%（D–F 欄是藍字輸入，可能被改壞）；寫成 Checks 的能失敗檢查，與 Checks D104（Alloc_In 2025 組合）並列。
A7: Alloc_In | B7: 18 | C7: 服務世代組合合計（應為 100%；Checks H1） | D7: 1 | E7: C18:C18 | F7: 3 | G7: 服務世代組合合計（應為 100%）：Checks D104 目前自行重算 SUM(AL_MixGen)；改讓 Checks 讀本格，單一定義（原則 1）且保留失敗能力。
A8: Alloc_In | B8: 33 | C8: 研發世代組合合計（應為 100%；Checks Z2） | D8: 1 | E8: C33:C33 | F8: 3 | G8: 研發世代組合合計（應為 100%）：Checks D140 目前自行重算四格和；改讓 Checks 讀本格。

Sheet 5_鏡像頁同列
A1: 依賴檢查：保留／升級列的上游含刪除列＝0 件；『隨附上游』無人讀取＝0 列。
A2: 頁 | B2: 列 | C2: 鏡像頁 | D2: 鏡像頁同列公式格數 | E2: 本列處置 | F2: 說明
