Workbook

Sheet 說明
A1: token 分母不閉合：研究用活頁簿（Tokenomics v5.35 數值；v5.36 A 段查證）
A3: 要回答的問題 | B3: OpenAI 2025 年的變現率 m 有兩個讀法：用使用量算付費 token 得 m_整體 1.74；用推論支出反推付費 token 得 m_fleet 0.81。兩者差 2.15 倍。差在哪裡？要怎樣才能一致（閉合）？對「1 GW 能不能回本」有什麼影響？
A4: 一句話結論 | B4: 差距全部來自「付費 token 數」的兩種算法；價格不影響差距。模型現值下，沒有任何一個輸入能單獨在證據範圍內把差距補平；最大的單一不確定項是推論支出取 126 億還是 84 億。回本判讀在 L 基準 0.643 下各情境都成立，在 L 低端 0.342 下取決於機隊端的 m。
A5: 建議閱讀順序 | B5: 1 推導鏈（看兩條路線各怎麼算）→ 2 代數推導（為何差距是這個恆等式）→ 3 閉合條件（每個輸入要改多少）→ 4 敏感度（哪個輸入最重要）→ 5 四項口徑差、價格時間錯配（兩個常見誤解）→ 6 證據。
A6: 怎麼自己試 | B6: 改「輸入」頁 H 欄（黃底）任何一格，所有頁面的 H 欄（自訂）會跟著重算。D–G 欄是固定情境，建議不要改。
A7: 顏色 | B7: 藍字＝輸入數值；黑字＝公式；綠字＝引用其他頁；黃底＝可改的自訂輸入；淺綠底＝重點結果列。
A8: 數字來源 | B8: 所有輸入取自 Tokenomics v5.35（model/CURRENT＝20261014_Tokenomics_v5.35.xlsx）的具名範圍或 SRC 列，以及 v5.36 A 段查證（PR #48）。每個輸入的來源與標記在「輸入」頁 L／K 欄。
A9: 與 Tokenomics 的關係 | B9: 本活頁簿是研究用副本，不是 Tokenomics 的一部分；公式逐列對照 Tokenomics 的 Alloc 與 Cap_In H 節（列號寫在推導鏈 I 欄）。模型現值欄應與 Tokenomics 一致：m_fleet 0.810、m_整體 1.743、τ* 13,950、閉合比 0.465。
A10: 限制 | B10: (1) 計價倍數、84 億、計算毛利 70% 的佐證多為二手報導，原文未讀到。(2) κ 的輸入全是類比。(3) 回本門檻用新建 VR200 的成本與產出，m 量的是 2025 年 Hopper／GB200 機隊，兩者時點不同。(4) 免費算力占比的第二個不閉合（21% 對 46%）只列出未解。
A11: 待你決定（B 段） | B11: 推論支出主值用 126 億或 84 億；計價倍數區間；每則 token 區間上緣；是否以 κ 取代 GapISL；L1 是否加實收單價列；DB_Evidence 登錄。詳見 PR #48 報告第 5 節。
A13: 頁面
A14: 輸入 | B14: 全部數值輸入、四個固定情境＋一個自訂情境、區間、標記、來源
A15: 推導鏈 | B15: 需求端 → 機隊端 → 閉合 → 回本，逐步公式
A16: 閉合條件 | B16: 單獨改一個輸入所需的值，與是否落在證據範圍
A17: 代數推導 | B17: 恆等式與閉合條件的推導文字
A18: 敏感度 | B18: 一次動一個輸入的缺口、m_fleet、實收單價與 ln 寬度
A19: 四項口徑差 | B19: 模型 L1 落差分解的重算與重複計入說明
A20: 價格時間錯配 | B20: ρ 的計算與對 m、缺口的影響
A21: 證據 | B21: v5.36A 查證原始紀錄

Sheet 輸入
A1: 輸入：本活頁簿唯一的數值來源（藍字＝輸入；H 欄黃底＝你可以改的自訂情境）
A2: D–G 欄是四個固定情境（只有少數輸入不同）；H 欄預設等於模型現值，改它即可看全部頁面的 H 欄如何變化。I／J 欄是證據或模型的合理區間，供「敏感度」頁使用。
A4: 代號 | B4: 項目 | C4: 單位 | D4: 模型現值（v5.35） | E4: A 段證據：計價倍數 1.5 | F4: A 段證據＋推論支出 84 億 | G4: 閉合例：支出 84 億＋κ 0.75 | H4: 自訂（黃底輸入格可改） | I4: 區間低 | J4: 區間高 | K4: 標記 | L4: 來源與說明
A5: A. 營收與單價
A6: R | B6: OpenAI 2025 營收（毛額） | C6: $B | D6: 13.07 | E6: 13.07 | F6: 13.07 | G6: 13.07 | H6: 13.07 | K6: Interested-party | L6: SRC_DEM_007（OpenAI 外流財報；有吹高營收的誘因）
A7: mixL | B7: 付費層級組合：Luna（低階） | C7: % | D7: 0.4 | E7: 0.4 | F7: 0.4 | G7: 0.4 | H7: 0.4 | K7: Assumed | L7: B4_MixPaid（Tokenomics v5.35）
A8: mixS | B8: 付費層級組合：Sol（中階） | C8: % | D8: 0.45 | E8: 0.45 | F8: 0.45 | G8: 0.45 | H8: 0.45 | K8: Assumed | L8: B4_MixPaid
A9: mixA | B9: 付費層級組合：Astra（高階） | C9: % | D9: 0.15 | E9: 0.15 | F9: 0.15 | G9: 0.15 | H9: 0.15 | K9: Assumed | L9: B4_MixPaid
A10: pL | B10: 參考請求有效單價：Luna | C10: $/M | D10: 0.080355556 | E10: 0.080355556 | F10: 0.080355556 | G10: 0.080355556 | H10: 0.080355556 | K10: Derived | L10: IF_PriceRef_Luna＝GPT-6 牌價快照（16K 入／2K 出、快取命中 0.55）× (1 − 折讓 0.2)
A11: pS | B11: 參考請求有效單價：Sol | C11: $/M | D11: 1.6071111 | E11: 1.6071111 | F11: 1.6071111 | G11: 1.6071111 | H11: 1.6071111 | K11: Derived | L11: IF_PriceRef_Sol（同上）
A12: pA | B12: 參考請求有效單價：Astra | C12: $/M | D12: 8.0355556 | E12: 8.0355556 | F12: 8.0355556 | G12: 8.0355556 | H12: 8.0355556 | K12: Derived | L12: IF_PriceRef_Astra（同上）
A13: B. 需求端（token 從使用量算）
A14: tpm | B14: API token 量（2025-10 時點） | C14: B tok/分鐘 | D14: 6 | E14: 6 | F14: 6 | G14: 6 | H14: 6 | K14: Interested-party | L14: SRC_DEM_010（OpenAI DevDay 2025；有誇大用量的誘因）
A15: apir | B15: API 全年平均 ÷ 10 月時點值 | C15: x | D15: 0.75 | E15: 0.75 | F15: 0.75 | G15: 0.75 | H15: 0.75 | I15: 0.6 | J15: 0.9 | K15: Assumed | L15: Alloc_In C14；區間為本活頁簿設定（A 段同向極端角點用 0.6／0.9）
A16: ppd | B16: ChatGPT 每日訊息數 | C16: B 則/日 | D16: 2.5 | E16: 2.5 | F16: 2.5 | G16: 2.5 | H16: 2.5 | I16: 2.2 | J16: 2.7 | K16: Interested-party | L16: SRC_DEM_012（OpenAI 2025-07）；區間＝v5.33A 內插 2.2–2.7
A17: tau | B17: 每則訊息 token 數 τ（輸入＋上下文＋推理＋輸出） | C17: tok | D17: 4000 | E17: 4000 | F17: 4000 | G17: 4000 | H17: 4000 | I17: 2000 | J17: 11000 | K17: Assumed | L17: Alloc_In C15；v5.33A 五組成法證據中心 4,300（1,650–11,300），Analogy／Assumed；OpenAI 未揭露
A18: fs | B18: ChatGPT token 中免費用戶占比 | C18: % | D18: 0.6 | E18: 0.6 | F18: 0.6 | G18: 0.6 | H18: 0.6 | I18: 0.4 | J18: 0.8 | K18: Assumed | L18: Alloc_In C16；付費占比無揭露（v5.33A 1.2）
A19: C. 機隊產能與成本（每 GW；2025 服務機隊）
A20: mixH | B20: 服務世代組合：Hopper | C20: % | D20: 0.6 | E20: 0.6 | F20: 0.6 | G20: 0.6 | H20: 0.6 | K20: Assumed | L20: Alloc_In C9
A21: mixG | B21: 服務世代組合：GB200 | C21: % | D21: 0.4 | E21: 0.4 | F21: 0.4 | G21: 0.4 | H21: 0.4 | K21: Assumed | L21: Alloc_In C10（兩者合計須為 100%）
A22: cPH | B22: 付費組合每 GW 年產能 @100% 利用率：Hopper | C22: M tok/GW/年 | D22: 1.5376438e+10 | E22: 1.5376438e+10 | F22: 1.5376438e+10 | G22: 1.5376438e+10 | H22: 1.5376438e+10 | K22: Derived | L22: Tokenomics Alloc!C22 ÷ IF_Util 0.6（由 Perf 頁 roofline 推導）
A23: cPG | B23: 付費組合每 GW 年產能 @100%：GB200 | C23: M tok/GW/年 | D23: 7.7458784e+10 | E23: 7.7458784e+10 | F23: 7.7458784e+10 | G23: 7.7458784e+10 | H23: 7.7458784e+10 | K23: Derived | L23: Alloc!D22 ÷ 0.6
A24: cFH | B24: 免費組合每 GW 年產能 @100%：Hopper | C24: M tok/GW/年 | D24: 5.9508389e+10 | E24: 5.9508389e+10 | F24: 5.9508389e+10 | G24: 5.9508389e+10 | H24: 5.9508389e+10 | K24: Derived | L24: Alloc!C23 ÷ 0.6（免費組合 Luna 0.9／Sol 0.1，較便宜所以產能高）
A25: cFG | B25: 免費組合每 GW 年產能 @100%：GB200 | C25: M tok/GW/年 | D25: 2.9032107e+11 | E25: 2.9032107e+11 | F25: 2.9032107e+11 | G25: 2.9032107e+11 | H25: 2.9032107e+11 | K25: Derived | L25: Alloc!D23 ÷ 0.6
A26: hH | B26: 每 GW 年經濟持有成本：Hopper | C26: $B/GW/年 | D26: 9.7030873 | E26: 9.7030873 | F26: 9.7030873 | G26: 9.7030873 | H26: 9.7030873 | K26: Derived | L26: L1_HoldEconGW_Hopper（資本回收 WACC 10%＋營運費用）
A27: hG | B27: 每 GW 年經濟持有成本：GB200 | C27: $B/GW/年 | D27: 8.8281656 | E27: 8.8281656 | F27: 8.8281656 | G27: 8.8281656 | H27: 8.8281656 | K27: Derived | L27: L1_HoldEconGW_GB200
A28: D. 機隊端（token 從推論支出反推）
A29: spend | B29: OpenAI 2025 推論支出 | C29: $B | D29: 12.6 | E29: 12.6 | F29: 8.4 | G29: 8.4 | H29: 12.6 | I29: 8.4 | J29: 13 | K29: Interested-party | L29: 12.6＝SRC_DEM_018（Microsoft 外流 Azure 帳單推估；Microsoft 稱不準確，可能含抵用金）；8.4＝SRC_DEM_004（與營收 13.07、免費推論 3.9 同一組 OpenAI 數字；與「計算毛利約 70%」吻合）
A30: SB | B30: 計價倍數：推論支出 ÷ 持有成本 | C30: x | D30: 2 | E30: 1.5 | F30: 1.5 | G30: 2 | H30: 2 | I30: 1.2 | J30: 3 | K30: Assumed | L30: Alloc_In C23（模型 2.0，1.5–3.0）；A 段證據中心 1.5（1.2–2.0）：Oracle 出租 GPU 毛利約 14%、CoreWeave 營業利益率約 5%、H100 市場價約持有成本 1.3–1.5 倍（皆二手）
A31: U | B31: 模型基準利用率 IF_Util | C31: % | D31: 0.6 | E31: 0.6 | F31: 0.6 | G31: 0.6 | H31: 0.6 | K31: Assumed | L31: Serving!C17；產能列已乘上它
A32: Ua | B32: 實際利用率 × 生產折減 | C32: % | D32: 0.35 | E32: 0.35 | F32: 0.35 | G32: 0.35 | H32: 0.35 | I32: 0.3 | J32: 0.5 | K32: Assumed | L32: Alloc_In C24（模型 0.30–0.40）；無實測（A3 已搜尋未找到）；高端 0.50 為本活頁簿放寬
A33: kap | B33: 請求形狀修正 κ（實際流量每 GPU 秒總 token ÷ 參考請求） | C33: x | D33: 1 | E33: 1 | F33: 1 | G33: 0.75 | H33: 1 | I33: 0.65 | J33: 1.2 | K33: Derived | L33: v5.36A 3.2：以 Sens_Perf 第 93–94 列校準 prefill／decode 成本，代入實際輸入輸出比與快取；Analogy 輸入。模型現值未建此項（等於 1）
A34: fsRep | B34: 對照：免費推論支出占比（支出口徑） | C34: % | D34: 0.46 | E34: 0.46 | F34: 0.46 | G34: 0.46 | H34: 0.46 | K34: Interested-party | L34: IF_FreeShare＝SRC_DEM_005 3.9 ÷ SRC_DEM_004 8.4
A35: E. 回本
A36: Bk | B36: 回本乘積（VR200）：持有成本 ÷ 100% 利用率營收 | C36: x | D36: 0.15054855 | E36: 0.15054855 | F36: 0.15054855 | G36: 0.15054855 | H36: 0.15054855 | K36: Derived | L36: L1_FleetBreakeven＝IF_HoldEcon 122.3 億 ÷ (IF_RevGWFleet 487 億 ÷ 0.6)
A37: dl | B37: 生產折減 δ | C37: % | D37: 0.85 | E37: 0.85 | F37: 0.85 | G37: 0.85 | H37: 0.85 | K37: Assumed | L37: CTL_ProdDerate
A38: L | B38: 壽命期價格係數 L（基準） | C38: x | D38: 0.64260237 | E38: 0.64260237 | F38: 0.64260237 | G38: 0.64260237 | H38: 0.64260237 | I38: 0.342 | J38: 1.162 | K38: Assumed | L38: L1_LTotal（牌價每年 −10%、前 4 年中階後降級、保留一半價值）
A40: 情境差異：E 欄只把計價倍數改 1.5；F 欄再把推論支出改 84 億；G 欄（閉合例）支出 84 億、計價倍數維持 2.0、κ 0.75。其他輸入四欄相同。

Sheet 推導鏈
A1: 推導鏈：需求端與機隊端各算一次「付費 token」，再看兩者為何對不上
A2: 每列一個步驟；I 欄用文字寫出公式。綠字＝引用「輸入」頁，黑字＝本頁計算。五欄情境同一公式。
A4: 步驟 | B4: 項目 | C4: 單位 | D4: 模型現值（v5.35） | E4: A 段證據：計價倍數 1.5 | F4: A 段證據＋推論支出 84 億 | G4: 閉合例：支出 84 億＋κ 0.75 | H4: 自訂（黃底輸入格可改） | I4: 公式（文字）
A5: A. 單價
A6: A1 | B6: 付費 token 混合有效單價 P̄ | C6: $/M | D6: =輸入!$D$7*輸入!$D$10+輸入!$D$8*輸入!$D$11+輸入!$D$9*輸入!$D$12 -> 1.9606756 | E6: =輸入!$E$7*輸入!$E$10+輸入!$E$8*輸入!$E$11+輸入!$E$9*輸入!$E$12 -> 1.9606756 | F6: =輸入!$F$7*輸入!$F$10+輸入!$F$8*輸入!$F$11+輸入!$F$9*輸入!$F$12 -> 1.9606756 | G6: =輸入!$G$7*輸入!$G$10+輸入!$G$8*輸入!$G$11+輸入!$G$9*輸入!$G$12 -> 1.9606756 | H6: =輸入!$H$7*輸入!$H$10+輸入!$H$8*輸入!$H$11+輸入!$H$9*輸入!$H$12 -> 1.9606756 | I6: P̄＝Σ 層級組合 × 該層級參考請求有效單價（Tokenomics Cap_In 第 90 列）
A7: B. 需求端：付費 token 從使用量算
A8: B1 | B8: API token（全年） | C8: M tok/年 | D8: =輸入!$D$14*1000000000*525600*輸入!$D$15/1000000 -> 2365200000 | E8: =輸入!$E$14*1000000000*525600*輸入!$E$15/1000000 -> 2365200000 | F8: =輸入!$F$14*1000000000*525600*輸入!$F$15/1000000 -> 2365200000 | G8: =輸入!$G$14*1000000000*525600*輸入!$G$15/1000000 -> 2365200000 | H8: =輸入!$H$14*1000000000*525600*輸入!$H$15/1000000 -> 2365200000 | I8: 每分鐘 token × 1e9 × 525,600 分鐘 × 全年平均比例 ÷ 1e6（Alloc 第 5 列）
A9: B2 | B9: ChatGPT token（全年） | C9: M tok/年 | D9: =輸入!$D$16*1000000000*輸入!$D$17*365/1000000 -> 3650000000 | E9: =輸入!$E$16*1000000000*輸入!$E$17*365/1000000 -> 3650000000 | F9: =輸入!$F$16*1000000000*輸入!$F$17*365/1000000 -> 3650000000 | G9: =輸入!$G$16*1000000000*輸入!$G$17*365/1000000 -> 3650000000 | H9: =輸入!$H$16*1000000000*輸入!$H$17*365/1000000 -> 3650000000 | I9: 每日訊息 × 1e9 × 每則 token τ × 365 ÷ 1e6（Alloc 第 6 列）
A10: B3 | B10: 免費 token D_free | C10: M tok/年 | D10: =D9*輸入!$D$18 -> 2190000000 | E10: =E9*輸入!$E$18 -> 2190000000 | F10: =F9*輸入!$F$18 -> 2190000000 | G10: =G9*輸入!$G$18 -> 2190000000 | H10: =H9*輸入!$H$18 -> 2190000000 | I10: B2 × 免費占比
A11: B4 | B11: 付費 token D_paid（需求端） | C11: M tok/年 | D11: =D8+D9*(1-輸入!$D$18) -> 3825200000 | E11: =E8+E9*(1-輸入!$E$18) -> 3825200000 | F11: =F8+F9*(1-輸入!$F$18) -> 3825200000 | G11: =G8+G9*(1-輸入!$G$18) -> 3825200000 | H11: =H8+H9*(1-輸入!$H$18) -> 3825200000 | I11: API ＋ ChatGPT ×（1 − 免費占比）（Alloc 第 9 列）
A12: B5 | B12: 免費 ÷ 付費 token 比 r | C12: x | D12: =D10/D11 -> 0.57251908 | E12: =E10/E11 -> 0.57251908 | F12: =F10/F11 -> 0.57251908 | G12: =G10/G11 -> 0.57251908 | H12: =H10/H11 -> 0.57251908 | I12: B3 ÷ B4；機隊端沿用同一個 r 分配免費與付費（Cap_In 第 112 列）
A13: B6 | B13: m_整體（需求端） | C13: x | D13: =輸入!$D$6*1000000000/(D11*D6) -> 1.7426722 | E13: =輸入!$E$6*1000000000/(E11*E6) -> 1.7426722 | F13: =輸入!$F$6*1000000000/(F11*F6) -> 1.7426722 | G13: =輸入!$G$6*1000000000/(G11*G6) -> 1.7426722 | H13: =輸入!$H$6*1000000000/(H11*H6) -> 1.7426722 | I13: 營收 ÷（需求端付費 token × P̄）→ L1_MImplied
A14: B7 | B14: 實收單價（需求端） | C14: $/M | D14: =輸入!$D$6*1000000000/D11 -> 3.4168148 | E14: =輸入!$E$6*1000000000/E11 -> 3.4168148 | F14: =輸入!$F$6*1000000000/F11 -> 3.4168148 | G14: =輸入!$G$6*1000000000/G11 -> 3.4168148 | H14: =輸入!$H$6*1000000000/H11 -> 3.4168148 | I14: 營收 ÷ 需求端付費 token ＝ m_整體 × P̄
A15: C. 每 GW 產能與 token 路線服務 GW
A16: C1 | B16: 付費每 GW 年產能（世代組合，含基準利用率） | C16: M tok/GW/年 | D16: =輸入!$D$31*(輸入!$D$20*輸入!$D$22+輸入!$D$21*輸入!$D$23) -> 2.4125626e+10 | E16: =輸入!$E$31*(輸入!$E$20*輸入!$E$22+輸入!$E$21*輸入!$E$23) -> 2.4125626e+10 | F16: =輸入!$F$31*(輸入!$F$20*輸入!$F$22+輸入!$F$21*輸入!$F$23) -> 2.4125626e+10 | G16: =輸入!$G$31*(輸入!$G$20*輸入!$G$22+輸入!$G$21*輸入!$G$23) -> 2.4125626e+10 | H16: =輸入!$H$31*(輸入!$H$20*輸入!$H$22+輸入!$H$21*輸入!$H$23) -> 2.4125626e+10 | I16: IF_Util × Σ 世代占比 × 世代產能@100%（Alloc 第 24 列）
A17: C2 | B17: 免費每 GW 年產能（世代組合，含基準利用率） | C17: M tok/GW/年 | D17: =輸入!$D$31*(輸入!$D$20*輸入!$D$24+輸入!$D$21*輸入!$D$25) -> 9.1100077e+10 | E17: =輸入!$E$31*(輸入!$E$20*輸入!$E$24+輸入!$E$21*輸入!$E$25) -> 9.1100077e+10 | F17: =輸入!$F$31*(輸入!$F$20*輸入!$F$24+輸入!$F$21*輸入!$F$25) -> 9.1100077e+10 | G17: =輸入!$G$31*(輸入!$G$20*輸入!$G$24+輸入!$G$21*輸入!$G$25) -> 9.1100077e+10 | H17: =輸入!$H$31*(輸入!$H$20*輸入!$H$24+輸入!$H$21*輸入!$H$25) -> 9.1100077e+10 | I17: 同上，免費層級組合（Alloc 第 25 列）
A18: C3 | B18: 世代組合後每 GW 年持有成本 | C18: $B/GW/年 | D18: =輸入!$D$20*輸入!$D$26+輸入!$D$21*輸入!$D$27 -> 9.3531186 | E18: =輸入!$E$20*輸入!$E$26+輸入!$E$21*輸入!$E$27 -> 9.3531186 | F18: =輸入!$F$20*輸入!$F$26+輸入!$F$21*輸入!$F$27 -> 9.3531186 | G18: =輸入!$G$20*輸入!$G$26+輸入!$G$21*輸入!$G$27 -> 9.3531186 | H18: =輸入!$H$20*輸入!$H$26+輸入!$H$21*輸入!$H$27 -> 9.3531186 | I18: Σ 世代占比 × 持有成本（Alloc 第 61 列分母）
A19: C4 | B19: token 路線服務 GW（需求端需要多少 GW） | C19: GW | D19: =D11/D16+D10/D17 -> 0.1825929 | E19: =E11/E16+E10/E17 -> 0.1825929 | F19: =F11/F16+F10/F17 -> 0.1825929 | G19: =G11/G16+G10/G17 -> 0.1825929 | H19: =H11/H16+H10/H17 -> 0.1825929 | I19: 付費 D ÷ 付費產能 ＋ 免費 D ÷ 免費產能（Alloc 第 28 列）
A20: D. 機隊端：付費 token 從推論支出反推
A21: D1 | B21: 支出路線服務 GW（帳面） | C21: GW | D21: =輸入!$D$29/D18 -> 1.3471443 | E21: =輸入!$E$29/E18 -> 1.3471443 | F21: =輸入!$F$29/F18 -> 0.89809617 | G21: =輸入!$G$29/G18 -> 0.89809617 | H21: =輸入!$H$29/H18 -> 1.3471443 | I21: 推論支出 ÷ 每 GW 持有成本（Alloc 第 61 列）
A22: D2 | B22: 扣除計價倍數後的 GW | C22: GW | D22: =D21/輸入!$D$30 -> 0.67357213 | E22: =E21/輸入!$E$30 -> 0.89809617 | F22: =F21/輸入!$F$30 -> 0.59873078 | G22: =G21/輸入!$G$30 -> 0.44904809 | H22: =H21/輸入!$H$30 -> 0.67357213 | I22: D1 ÷ 計價倍數（支出含雲端利潤與資本回收，不全是算力）
A23: D3 | B23: 利用率修正 | C23: x | D23: =輸入!$D$32/輸入!$D$31 -> 0.58333333 | E23: =輸入!$E$32/輸入!$E$31 -> 0.58333333 | F23: =輸入!$F$32/輸入!$F$31 -> 0.58333333 | G23: =輸入!$G$32/輸入!$G$31 -> 0.58333333 | H23: =輸入!$H$32/輸入!$H$31 -> 0.58333333 | I23: 實際利用率 ÷ IF_Util（產能列已含 IF_Util，故換成實際值）
A24: D4 | B24: 有效服務 GW | C24: GW | D24: =D22*D23*輸入!$D$33 -> 0.39291707 | E24: =E22*E23*輸入!$E$33 -> 0.52388943 | F24: =F22*F23*輸入!$F$33 -> 0.34925962 | G24: =G22*G23*輸入!$G$33 -> 0.19645854 | H24: =H22*H23*輸入!$H$33 -> 0.39291707 | I24: D2 × D3 × κ（Cap_In 第 177 列；κ 為 A 段新增）
A25: D5 | B25: 付費 token T_fleet（機隊端） | C25: M tok/年 | D25: =D24/(1/D16+D12/D17) -> 8.2313519e+09 | E25: =E24/(1/E16+E12/E17) -> 1.0975136e+10 | F25: =F24/(1/F16+F12/F17) -> 7.3167573e+09 | G25: =G24/(1/G16+G12/G17) -> 4.115676e+09 | H25: =H24/(1/H16+H12/H17) -> 8.2313519e+09 | I25: 有效 GW ÷（1 ÷ 付費產能 ＋ r ÷ 免費產能）：每 1 個付費 token 連帶 r 個免費 token 一起占 GW（Cap_In 第 116 列）
A26: D6 | B26: m_fleet（機隊端） | C26: x | D26: =輸入!$D$6*1000000000/(D25*D6) -> 0.80983899 | E26: =輸入!$E$6*1000000000/(E25*E6) -> 0.60737924 | F26: =輸入!$F$6*1000000000/(F25*F6) -> 0.91106886 | G26: =輸入!$G$6*1000000000/(G25*G6) -> 1.619678 | H26: =輸入!$H$6*1000000000/(H25*H6) -> 0.80983899 | I26: 營收 ÷（機隊端付費 token × P̄）→ L1_MFleet
A27: D7 | B27: 實收單價（機隊端） | C27: $/M | D27: =輸入!$D$6*1000000000/D25 -> 1.5878315 | E27: =輸入!$E$6*1000000000/E25 -> 1.1908736 | F27: =輸入!$F$6*1000000000/F25 -> 1.7863105 | G27: =輸入!$G$6*1000000000/G25 -> 3.175663 | H27: =輸入!$H$6*1000000000/H25 -> 1.5878315 | I27: 營收 ÷ 機隊端付費 token ＝ m_fleet × P̄
A28: E. 閉合：兩端是否一致
A29: E1 | B29: 閉合比：需求 ÷ 機隊 | C29: x | D29: =D11/D25 -> 0.46471103 | E29: =E11/E25 -> 0.34853327 | F29: =F11/F25 -> 0.5227999 | G29: =G11/G25 -> 0.92942205 | H29: =H11/H25 -> 0.46471103 | I29: B4 ÷ D5（Cap_In 第 174 列；1＝閉合；Checks M4 在 <0.5 或 >2 時警告）
A30: E2 | B30: 缺口：機隊 ÷ 需求（＝m_整體 ÷ m_fleet） | C30: x | D30: =D25/D11 -> 2.1518749 | E30: =E25/E11 -> 2.8691666 | F30: =F25/F11 -> 1.9127777 | G30: =G25/G11 -> 1.0759375 | H30: =H25/H11 -> 2.1518749 | I30: D5 ÷ B4；同一營收、同一 P̄，所以兩個 m 的比值只剩 token 比
A31: E3 | B31: 服務端規模係數（ScaleServe） | C31: x | D31: =D21/D19 -> 7.3778569 | E31: =E21/E19 -> 7.3778569 | F31: =F21/F19 -> 4.9185712 | G31: =G21/G19 -> 4.9185712 | H31: =H21/H19 -> 7.3778569 | I31: D1 ÷ C4（L1_ScaleServe）
A32: E4 | B32: 恆等式驗算：ScaleServe ÷（計價倍數 × IF_Util ÷（實際利用率 × κ）） | C32: x | D32: =D31/(輸入!$D$30*輸入!$D$31/(輸入!$D$32*輸入!$D$33)) -> 2.1518749 | E32: =E31/(輸入!$E$30*輸入!$E$31/(輸入!$E$32*輸入!$E$33)) -> 2.8691666 | F32: =F31/(輸入!$F$30*輸入!$F$31/(輸入!$F$32*輸入!$F$33)) -> 1.9127777 | G32: =G31/(輸入!$G$30*輸入!$G$31/(輸入!$G$32*輸入!$G$33)) -> 1.0759375 | H32: =H31/(輸入!$H$30*輸入!$H$31/(輸入!$H$32*輸入!$H$33)) -> 2.1518749 | I32: 應等於 E2（見「代數推導」第 4 步）
A33: E5 | B33: 驗算差 | C33: x | D33: =D32-D30 -> 0 | E33: =E32-E30 -> 0 | F33: =F32-F30 -> 0 | G33: =G32-G30 -> 0 | H33: =H32-H30 -> 0 | I33: 應為 0
A34: E6 | B34: 閉合所需 ChatGPT 年 token T_chat* | C34: M tok/年 | D34: =(D24-D8/D16)/((1-輸入!$D$18)/D16+輸入!$D$18/D17) -> 1.2728985e+10 | E34: =(E24-E8/E16)/((1-輸入!$E$18)/E16+輸入!$E$18/E17) -> 1.838262e+10 | F34: =(F24-F8/F16)/((1-輸入!$F$18)/F16+輸入!$F$18/F17) -> 1.084444e+10 | G34: =(G24-G8/G16)/((1-輸入!$G$18)/G16+輸入!$G$18/G17) -> 4.248533e+09 | H34: =(H24-H8/H16)/((1-輸入!$H$18)/H16+輸入!$H$18/H17) -> 1.2728985e+10 | I34: 令需求端用滿有效 GW：[有效 GW − API ÷ 付費產能] ÷ [(1−免費占比) ÷ 付費產能 ＋ 免費占比 ÷ 免費產能]（Cap_In 第 178 列）
A35: E7 | B35: 閉合所需每則 token τ* | C35: tok | D35: =D34*1000000/(輸入!$D$16*1000000000*365) -> 13949.573 | E35: =E34*1000000/(輸入!$E$16*1000000000*365) -> 20145.337 | F35: =F34*1000000/(輸入!$F$16*1000000000*365) -> 11884.318 | G35: =G34*1000000/(輸入!$G$16*1000000000*365) -> 4655.9265 | H35: =H34*1000000/(輸入!$H$16*1000000000*365) -> 13949.573 | I35: T_chat* ÷（每日訊息 × 365）→ L1_TokPerPromptClose
A36: E8 | B36: τ* 是否在證據區間（1,650–11,300） | D36: =IF(D35>11300,"高於證據區間",IF(D35<1650,"低於證據區間","在證據區間內")) -> 高於證據區間 | E36: =IF(E35>11300,"高於證據區間",IF(E35<1650,"低於證據區間","在證據區間內")) -> 高於證據區間 | F36: =IF(F35>11300,"高於證據區間",IF(F35<1650,"低於證據區間","在證據區間內")) -> 高於證據區間 | G36: =IF(G35>11300,"高於證據區間",IF(G35<1650,"低於證據區間","在證據區間內")) -> 在證據區間內 | H36: =IF(H35>11300,"高於證據區間",IF(H35<1650,"低於證據區間","在證據區間內")) -> 高於證據區間 | I36: v5.33A 五組成法區間
A37: E9 | B37: 閉合下的免費算力占比 | C37: % | D37: =(D34*輸入!$D$18/D17)/D24 -> 0.21336609 | E37: =(E34*輸入!$E$18/E17)/E24 -> 0.23110018 | F37: =(F34*輸入!$F$18/F17)/F24 -> 0.20449904 | G37: =(G34*輸入!$G$18/G17)/G24 -> 0.14242971 | H37: =(H34*輸入!$H$18/H17)/H24 -> 0.21336609 | I37: 以 T_chat* 重算免費 GW ÷ 有效 GW；對照支出口徑 0.46（Cap_In 第 181 列）
A38: E10 | B38: 對照：免費推論支出占比（支出口徑） | C38: % | D38: =輸入!$D$34 -> 0.46 | E38: =輸入!$E$34 -> 0.46 | F38: =輸入!$F$34 -> 0.46 | G38: =輸入!$G$34 -> 0.46 | H38: =輸入!$H$34 -> 0.46 | I38: IF_FreeShare；與 E9 不一致是第二個不閉合（v5.34 檢核 C6）
A39: F. 回本（L × m ≥ 門檻；以實收單價表示）
A40: F1 | B40: 回本門檻 L × m（線性口徑） | C40: x | D40: =輸入!$D$36/(輸入!$D$31*輸入!$D$37) -> 0.29519323 | E40: =輸入!$E$36/(輸入!$E$31*輸入!$E$37) -> 0.29519323 | F40: =輸入!$F$36/(輸入!$F$31*輸入!$F$37) -> 0.29519323 | G40: =輸入!$G$36/(輸入!$G$31*輸入!$G$37) -> 0.29519323 | H40: =輸入!$H$36/(輸入!$H$31*輸入!$H$37) -> 0.29519323 | I40: 回本乘積 ÷（IF_Util × δ）＝0.1505 ÷ 0.51
A41: F2 | B41: 回本所需實收單價（L 基準） | C41: $/M | D41: =D40*D6/輸入!$D$38 -> 0.90067853 | E41: =E40*E6/輸入!$E$38 -> 0.90067853 | F41: =F40*F6/輸入!$F$38 -> 0.90067853 | G41: =G40*G6/輸入!$G$38 -> 0.90067853 | H41: =H40*H6/輸入!$H$38 -> 0.90067853 | I41: 門檻 × P̄ ÷ L
...

Sheet 閉合條件
A1: 閉合條件：其他輸入不動，單獨改一個輸入要改到多少才能閉合（缺口＝1）
A2: 因為缺口 ＝ 支出 × 實際利用率 × κ ÷（計價倍數 × 常數）÷ 需求 token，前四項是乘除關係，單獨改一項所需的值可以直接解出；τ 另由 E7 解。
A4: # | B4: 單獨調整的輸入 | C4: 單位 | D4: 模型現值（v5.35） | E4: A 段證據：計價倍數 1.5 | F4: A 段證據＋推論支出 84 億 | G4: 閉合例：支出 84 億＋κ 0.75 | H4: 自訂（黃底輸入格可改） | I4: 解法與判讀
A5: 1 | B5: 推論支出 需降到 | C5: $B | D5: =輸入!$D$29/推導鏈!D30 -> 5.8553589 | E5: =輸入!$E$29/推導鏈!E30 -> 4.3915192 | F5: =輸入!$F$29/推導鏈!F30 -> 4.3915192 | G5: =輸入!$G$29/推導鏈!G30 -> 7.8071452 | H5: =輸入!$H$29/推導鏈!H30 -> 5.8553589 | I5: 支出 ÷ 缺口；證據下限 8.4（SRC_DEM_004）
A6: 2 | B6: 計價倍數 需升到 | C6: x | D6: =輸入!$D$30*推導鏈!D30 -> 4.3037498 | E6: =輸入!$E$30*推導鏈!E30 -> 4.3037498 | F6: =輸入!$F$30*推導鏈!F30 -> 2.8691666 | G6: =輸入!$G$30*推導鏈!G30 -> 2.1518749 | H6: =輸入!$H$30*推導鏈!H30 -> 4.3037498 | I6: 計價倍數 × 缺口；證據 1.2–2.0，模型上限 3.0
A7: 3 | B7: 實際利用率×折減 需降到 | C7: % | D7: =輸入!$D$32/推導鏈!D30 -> 0.16264886 | E7: =輸入!$E$32/推導鏈!E30 -> 0.12198664 | F7: =輸入!$F$32/推導鏈!F30 -> 0.18297997 | G7: =輸入!$G$32/推導鏈!G30 -> 0.32529772 | H7: =輸入!$H$32/推導鏈!H30 -> 0.16264886 | I7: 實際利用率 ÷ 缺口；模型區間 0.30–0.40
A8: 4 | B8: κ 需降到 | C8: x | D8: =輸入!$D$33/推導鏈!D30 -> 0.46471103 | E8: =輸入!$E$33/推導鏈!E30 -> 0.34853327 | F8: =輸入!$F$33/推導鏈!F30 -> 0.5227999 | G8: =輸入!$G$33/推導鏈!G30 -> 0.69706654 | H8: =輸入!$H$33/推導鏈!H30 -> 0.46471103 | I8: κ ÷ 缺口；A 段區間 0.65–1.2
A9: 5 | B9: 每則 token τ 需升到 | C9: tok | D9: =推導鏈!D35 -> 13949.573 | E9: =推導鏈!E35 -> 20145.337 | F9: =推導鏈!F35 -> 11884.318 | G9: =推導鏈!G35 -> 4655.9265 | H9: =推導鏈!H35 -> 13949.573 | I9: τ*（推導鏈 E7）；證據 1,650–11,300
A11: 判讀（模型現值欄）
B12: 推論支出 | D12: =IF(D5<8.4,"需低於 84 億：超出證據","可在證據內閉合") -> 需低於 84 億：超出證據
B13: 計價倍數 | D13: =IF(D6>3,"需高於 3.0：超出模型上限",IF(D6>2.2,"需高於 2.2：超出 A 段證據","可在證據內閉合")) -> 需高於 3.0：超出模型上限
B14: 實際利用率 | D14: =IF(D7<0.3,"需低於 0.30：超出模型區間","可在區間內閉合") -> 需低於 0.30：超出模型區間
B15: κ | D15: =IF(D8<0.65,"需低於 0.65：超出 A 段區間","可在區間內閉合") -> 需低於 0.65：超出 A 段區間
B16: τ | D16: =IF(D9>11300,"需高於 11,300：超出證據","可在證據內閉合") -> 需高於 11,300：超出證據
A18: 結論
A19: 1. 模型現值下，五個輸入沒有一個能「單獨」在證據範圍內閉合：支出要低於 84 億、計價倍數要高於 3、實際利用率要低於 0.30、κ 要低於 0.65 或 τ 要高於 11,300，五者都在邊界之外（數值見上表 D 欄）。
A20: 2. 兩項以上同時移動才閉合，例如「推論支出 84 億＋κ 0.75」（G 欄）缺口約 1.08，所需 τ 約 4,700，與需求證據中心 4,300 一致。
A21: 3. A 段證據把計價倍數拉低到 1.5（E 欄），缺口反而變大到約 2.9：這是「新證據讓問題更難閉合」的方向。
A22: 4. 缺口只影響「m 該取哪個值」，不影響營收與實收單價的美元觀測；回本判讀見「推導鏈」F 節與「回本」頁。

Sheet 代數推導
A1: 代數推導：缺口從哪裡來、為什麼價格不影響缺口
A3: 符號 | B3: R＝營收；P̄＝混合有效單價；D_p、D_f＝需求端付費、免費 token；r＝D_f ÷ D_p；cap_P、cap_F＝付費、免費每 GW 年產能（含 IF_Util）；S＝推論支出；H＝每 GW 持有成本；SB＝計價倍數；U＝IF_Util；U_a＝實際利用率×折減；κ＝請求形狀修正。
A4: 1 | B4: 需求端需要的 GW：GW_token ＝ D_p ÷ cap_P ＋ D_f ÷ cap_F ＝ D_p ×（1 ÷ cap_P ＋ r ÷ cap_F）。（推導鏈 C4）
A5: 2 | B5: 機隊端有效 GW：GW_eff ＝（S ÷ H）÷ SB ×（U_a ÷ U）× κ。（推導鏈 D1–D4）
A6: 3 | B6: 機隊端付費 token：T_fleet ＝ GW_eff ÷（1 ÷ cap_P ＋ r ÷ cap_F）。因為機隊端沿用需求端的 r，分母與第 1 步相同。（推導鏈 D5）
A7: 4 | B7: 缺口 ＝ T_fleet ÷ D_p ＝ GW_eff ÷ GW_token ＝［（S ÷ H）÷ GW_token］÷［SB × U ÷（U_a × κ）］＝ ScaleServe ÷（SB × U ÷（U_a × κ））。模型現值：7.378 ÷（2.0 × 0.6 ÷ 0.35）＝ 7.378 ÷ 3.429 ＝ 2.152。（推導鏈 E3–E5 驗算）
A8: 5 | B8: 兩個 m：m_整體 ＝ R ÷（D_p × P̄）；m_fleet ＝ R ÷（T_fleet × P̄）。相除得 m_整體 ÷ m_fleet ＝ T_fleet ÷ D_p ＝ 缺口。R 與 P̄ 都約掉，所以「價格時間錯配」（2025 實際單價 ≠ 2026 牌價快照）只會讓兩個 m 同比例變動，對缺口的貢獻為 0。（見「價格時間錯配」頁）
A9: 6 | B9: 閉合條件：缺口＝1 ⇔ D_p ＝ T_fleet ⇔ S × U_a × κ ÷ SB ＝ H × U × GW_token。左邊是機隊端的四個輸入，右邊由需求端決定。單獨改一項所需的值：S* ＝ S ÷ 缺口、SB* ＝ SB × 缺口、U_a* ＝ U_a ÷ 缺口、κ* ＝ κ ÷ 缺口。（閉合條件頁第 1–4 列）
A10: 7 | B10: 改需求端的 τ：令（D_p ＋ D_f）剛好用滿 GW_eff。ChatGPT 年 token T_chat 滿足 API ÷ cap_P ＋ T_chat ×［(1 − f) ÷ cap_P ＋ f ÷ cap_F］＝ GW_eff，解得 T_chat* ＝（GW_eff − API ÷ cap_P）÷［(1 − f) ÷ cap_P ＋ f ÷ cap_F］，τ* ＝ T_chat* ÷（每日訊息 × 365）。f＝免費占比。（推導鏈 E6–E7）
A11: 8 | B11: τ 為何要變很多：API 部分不隨 τ 變，所以 τ 加倍時需求 token 不會加倍。模型現值下 τ 由 2,000 加到 4,000，GW_token 只由 0.1403 增為 0.1826（×1.30）。這也是「四項口徑差」把 τ 的倍數記成 2.0 會高估的原因。（見「四項口徑差」頁）
A12: 9 | B12: 第二個不閉合：閉合後免費算力只占約 21%（推導鏈 E9），但 OpenAI 自己的支出數字顯示免費推論占 46%（E10）。若要同時滿足，免費 token 必須多很多，m 會再往上修。這一項本活頁簿只列出，未解。
A13: 10 | B13: 回本：L × m ≥ 門檻，門檻 ＝ 回本乘積 ÷（U × δ）＝ 0.1505 ÷ 0.51 ＝ 0.295。換成實收單價：L × 實收單價 ≥ 0.295 × P̄ ＝ 0.579 $/M。L＝0.643 時需實收 0.90 $/M，L＝0.342 時需 1.69 $/M。注意：門檻用的是新建 VR200 每 GW 的成本與產出，m 量的是 2025 年 Hopper／GB200 機隊的實收；兩者時點不同，本活頁簿沿用模型的做法並列，不做調整。

Sheet 敏感度
A1: 敏感度：從模型現值出發，一次只把一個輸入移到區間低或高（區間在「輸入」頁 I／J 欄）
A2: C–J 欄是該列實際使用的輸入（被調整的那一格為藍字，其餘引用模型現值）；K 欄起是同一條推導鏈的閉式公式。最右欄「ln 寬度」＝ ln(高端缺口 ÷ 低端缺口) 的絕對值，數字越大越重要。
A4: 調整的輸入 | B4: 端點 | C4: 每則 token τ | D4: 免費占比 | E4: API 全年比例 | F4: 每日訊息 | G4: 推論支出 | H4: 計價倍數 | I4: 實際利用率×折減 | J4: κ | K4: 需求付費 token | L4: 免費 token | M4: 有效 GW | N4: 機隊付費 token | O4: 缺口 | P4: m_fleet | Q4: 實收單價 $/M | R4: τ* | S4: L 基準判讀 | T4: 缺口 ln 寬度
A5: （基準：模型現值） | B5: 基準 | C5: =輸入!$D$17 -> 4000 | D5: =輸入!$D$18 -> 0.6 | E5: =輸入!$D$15 -> 0.75 | F5: =輸入!$D$16 -> 2.5 | G5: =輸入!$D$29 -> 12.6 | H5: =輸入!$D$30 -> 2 | I5: =輸入!$D$32 -> 0.35 | J5: =輸入!$D$33 -> 1 | K5: =輸入!$D$14*1000000000*525600*E5/1000000+F5*1000000000*C5*365/1000000*(1-D5) -> 3825200000 | L5: =F5*1000000000*C5*365/1000000*D5 -> 2190000000 | M5: =G5/推導鏈!$D$18/H5*(I5/輸入!$D$31)*J5 -> 0.39291707 | N5: =M5/(1/推導鏈!$D$16+(L5/K5)/推導鏈!$D$17) -> 8.2313519e+09 | O5: =N5/K5 -> 2.1518749 | P5: =輸入!$D$6*1000000000/(N5*推導鏈!$D$6) -> 0.80983899 | Q5: =輸入!$D$6*1000000000/N5 -> 1.5878315 | R5: =(M5-(輸入!$D$14*1000000000*525600*E5/1000000)/推導鏈!$D$16)/((1-D5)/推導鏈!$D$16+D5/推導鏈!$D$17)*1000000/(F5*1000000000*365) -> 13949.573 | S5: =IF(Q5>=推導鏈!$D$41,"回本","不回本") -> 回本
A6: 每則 token τ | B6: 低 | C6: =輸入!$I$17 -> 2000 | D6: =輸入!$D$18 -> 0.6 | E6: =輸入!$D$15 -> 0.75 | F6: =輸入!$D$16 -> 2.5 | G6: =輸入!$D$29 -> 12.6 | H6: =輸入!$D$30 -> 2 | I6: =輸入!$D$32 -> 0.35 | J6: =輸入!$D$33 -> 1 | K6: =輸入!$D$14*1000000000*525600*E6/1000000+F6*1000000000*C6*365/1000000*(1-D6) -> 3095200000 | L6: =F6*1000000000*C6*365/1000000*D6 -> 1095000000 | M6: =G6/推導鏈!$D$18/H6*(I6/輸入!$D$31)*J6 -> 0.39291707 | N6: =M6/(1/推導鏈!$D$16+(L6/K6)/推導鏈!$D$17) -> 8.667342e+09 | O6: =N6/K6 -> 2.8002526 | P6: =輸入!$D$6*1000000000/(N6*推導鏈!$D$6) -> 0.76910196 | Q6: =輸入!$D$6*1000000000/N6 -> 1.5079594 | R6: =(M6-(輸入!$D$14*1000000000*525600*E6/1000000)/推導鏈!$D$16)/((1-D6)/推導鏈!$D$16+D6/推導鏈!$D$17)*1000000/(F6*1000000000*365) -> 13949.573 | S6: =IF(Q6>=推導鏈!$D$41,"回本","不回本") -> 回本 | T6: =ABS(LN(O7/O6)) -> 0.85691741
A7: 每則 token τ | B7: 高 | C7: =輸入!$J$17 -> 11000 | D7: =輸入!$D$18 -> 0.6 | E7: =輸入!$D$15 -> 0.75 | F7: =輸入!$D$16 -> 2.5 | G7: =輸入!$D$29 -> 12.6 | H7: =輸入!$D$30 -> 2 | I7: =輸入!$D$32 -> 0.35 | J7: =輸入!$D$33 -> 1 | K7: =輸入!$D$14*1000000000*525600*E7/1000000+F7*1000000000*C7*365/1000000*(1-D7) -> 6380200000 | L7: =F7*1000000000*C7*365/1000000*D7 -> 6022500000 | M7: =G7/推導鏈!$D$18/H7*(I7/輸入!$D$31)*J7 -> 0.39291707 | N7: =M7/(1/推導鏈!$D$16+(L7/K7)/推導鏈!$D$17) -> 7.5836277e+09 | O7: =N7/K7 -> 1.1886191 | P7: =輸入!$D$6*1000000000/(N7*推導鏈!$D$6) -> 0.87900804 | Q7: =輸入!$D$6*1000000000/N7 -> 1.7234496 | R7: =(M7-(輸入!$D$14*1000000000*525600*E7/1000000)/推導鏈!$D$16)/((1-D7)/推導鏈!$D$16+D7/推導鏈!$D$17)*1000000/(F7*1000000000*365) -> 13949.573 | S7: =IF(Q7>=推導鏈!$D$41,"回本","不回本") -> 回本
A8: 免費占比 | B8: 低 | C8: =輸入!$D$17 -> 4000 | D8: =輸入!$I$18 -> 0.4 | E8: =輸入!$D$15 -> 0.75 | F8: =輸入!$D$16 -> 2.5 | G8: =輸入!$D$29 -> 12.6 | H8: =輸入!$D$30 -> 2 | I8: =輸入!$D$32 -> 0.35 | J8: =輸入!$D$33 -> 1 | K8: =輸入!$D$14*1000000000*525600*E8/1000000+F8*1000000000*C8*365/1000000*(1-D8) -> 4555200000 | L8: =F8*1000000000*C8*365/1000000*D8 -> 1460000000 | M8: =G8/推導鏈!$D$18/H8*(I8/輸入!$D$31)*J8 -> 0.39291707 | N8: =M8/(1/推導鏈!$D$16+(L8/K8)/推導鏈!$D$17) -> 8.7377134e+09 | O8: =N8/K8 -> 1.9181844 | P8: =輸入!$D$6*1000000000/(N8*推導鏈!$D$6) -> 0.7629078 | Q8: =輸入!$D$6*1000000000/N8 -> 1.4958147 | R8: =(M8-(輸入!$D$14*1000000000*525600*E8/1000000)/推導鏈!$D$16)/((1-D8)/推導鏈!$D$16+D8/推導鏈!$D$17)*1000000/(F8*1000000000*365) -> 11044.082 | S8: =IF(Q8>=推導鏈!$D$41,"回本","不回本") -> 回本 | T8: =ABS(LN(O9/O8)) -> 0.24487441
A9: 免費占比 | B9: 高 | C9: =輸入!$D$17 -> 4000 | D9: =輸入!$J$18 -> 0.8 | E9: =輸入!$D$15 -> 0.75 | F9: =輸入!$D$16 -> 2.5 | G9: =輸入!$D$29 -> 12.6 | H9: =輸入!$D$30 -> 2 | I9: =輸入!$D$32 -> 0.35 | J9: =輸入!$D$33 -> 1 | K9: =輸入!$D$14*1000000000*525600*E9/1000000+F9*1000000000*C9*365/1000000*(1-D9) -> 3095200000 | L9: =F9*1000000000*C9*365/1000000*D9 -> 2920000000 | M9: =G9/推導鏈!$D$18/H9*(I9/輸入!$D$31)*J9 -> 0.39291707 | N9: =M9/(1/推導鏈!$D$16+(L9/K9)/推導鏈!$D$17) -> 7.584495e+09 | O9: =N9/K9 -> 2.4504055 | P9: =輸入!$D$6*1000000000/(N9*推導鏈!$D$6) -> 0.87890753 | Q9: =輸入!$D$6*1000000000/N9 -> 1.7232525 | R9: =(M9-(輸入!$D$14*1000000000*525600*E9/1000000)/推導鏈!$D$16)/((1-D9)/推導鏈!$D$16+D9/推導鏈!$D$17)*1000000/(F9*1000000000*365) -> 18929.595 | S9: =IF(Q9>=推導鏈!$D$41,"回本","不回本") -> 回本
A10: API 全年比例 | B10: 低 | C10: =輸入!$D$17 -> 4000 | D10: =輸入!$D$18 -> 0.6 | E10: =輸入!$I$15 -> 0.6 | F10: =輸入!$D$16 -> 2.5 | G10: =輸入!$D$29 -> 12.6 | H10: =輸入!$D$30 -> 2 | I10: =輸入!$D$32 -> 0.35 | J10: =輸入!$D$33 -> 1 | K10: =輸入!$D$14*1000000000*525600*E10/1000000+F10*1000000000*C10*365/1000000*(1-D10) -> 3352160000 | L10: =F10*1000000000*C10*365/1000000*D10 -> 2190000000 | M10: =G10/推導鏈!$D$18/H10*(I10/輸入!$D$31)*J10 -> 0.39291707 | N10: =M10/(1/推導鏈!$D$16+(L10/K10)/推導鏈!$D$17) -> 8.0812137e+09 | O10: =N10/K10 -> 2.4107482 | P10: =輸入!$D$6*1000000000/(N10*推導鏈!$D$6) -> 0.82488472 | Q10: =輸入!$D$6*1000000000/N10 -> 1.6173313 | R10: =(M10-(輸入!$D$14*1000000000*525600*E10/1000000)/推導鏈!$D$16)/((1-D10)/推導鏈!$D$16+D10/推導鏈!$D$17)*1000000/(F10*1000000000*365) -> 14877.117 | S10: =IF(Q10>=推導鏈!$D$41,"回本","不回本") -> 回本 | T10: =ABS(LN(O11/O10)) -> 0.21559719
A11: API 全年比例 | B11: 高 | C11: =輸入!$D$17 -> 4000 | D11: =輸入!$D$18 -> 0.6 | E11: =輸入!$J$15 -> 0.9 | F11: =輸入!$D$16 -> 2.5 | G11: =輸入!$D$29 -> 12.6 | H11: =輸入!$D$30 -> 2 | I11: =輸入!$D$32 -> 0.35 | J11: =輸入!$D$33 -> 1 | K11: =輸入!$D$14*1000000000*525600*E11/1000000+F11*1000000000*C11*365/1000000*(1-D11) -> 4298240000 | L11: =F11*1000000000*C11*365/1000000*D11 -> 2190000000 | M11: =G11/推導鏈!$D$18/H11*(I11/輸入!$D$31)*J11 -> 0.39291707 | N11: =M11/(1/推導鏈!$D$16+(L11/K11)/推導鏈!$D$17) -> 8.3523723e+09 | O11: =N11/K11 -> 1.9432075 | P11: =輸入!$D$6*1000000000/(N11*推導鏈!$D$6) -> 0.79810495 | Q11: =輸入!$D$6*1000000000/N11 -> 1.5648249 | R11: =(M11-(輸入!$D$14*1000000000*525600*E11/1000000)/推導鏈!$D$16)/((1-D11)/推導鏈!$D$16+D11/推導鏈!$D$17)*1000000/(F11*1000000000*365) -> 13022.029 | S11: =IF(Q11>=推導鏈!$D$41,"回本","不回本") -> 回本
A12: 每日訊息 | B12: 低 | C12: =輸入!$D$17 -> 4000 | D12: =輸入!$D$18 -> 0.6 | E12: =輸入!$D$15 -> 0.75 | F12: =輸入!$I$16 -> 2.2 | G12: =輸入!$D$29 -> 12.6 | H12: =輸入!$D$30 -> 2 | I12: =輸入!$D$32 -> 0.35 | J12: =輸入!$D$33 -> 1 | K12: =輸入!$D$14*1000000000*525600*E12/1000000+F12*1000000000*C12*365/1000000*(1-D12) -> 3650000000 | L12: =F12*1000000000*C12*365/1000000*D12 -> 1927200000 | M12: =G12/推導鏈!$D$18/H12*(I12/輸入!$D$31)*J12 -> 0.39291707 | N12: =M12/(1/推導鏈!$D$16+(L12/K12)/推導鏈!$D$17) -> 8.3164928e+09 | O12: =N12/K12 -> 2.2784912 | P12: =輸入!$D$6*1000000000/(N12*推導鏈!$D$6) -> 0.80154819 | Q12: =輸入!$D$6*1000000000/N12 -> 1.5715759 | R12: =(M12-(輸入!$D$14*1000000000*525600*E12/1000000)/推導鏈!$D$16)/((1-D12)/推導鏈!$D$16+D12/推導鏈!$D$17)*1000000/(F12*1000000000*365) -> 15851.788 | S12: =IF(Q12>=推導鏈!$D$41,"回本","不回本") -> 回本 | T12: =ABS(LN(O13/O12)) -> 0.093551012
A13: 每日訊息 | B13: 高 | C13: =輸入!$D$17 -> 4000 | D13: =輸入!$D$18 -> 0.6 | E13: =輸入!$D$15 -> 0.75 | F13: =輸入!$J$16 -> 2.7 | G13: =輸入!$D$29 -> 12.6 | H13: =輸入!$D$30 -> 2 | I13: =輸入!$D$32 -> 0.35 | J13: =輸入!$D$33 -> 1 | K13: =輸入!$D$14*1000000000*525600*E13/1000000+F13*1000000000*C13*365/1000000*(1-D13) -> 3942000000 | L13: =F13*1000000000*C13*365/1000000*D13 -> 2365200000 | M13: =G13/推導鏈!$D$18/H13*(I13/輸入!$D$31)*J13 -> 0.39291707 | N13: =M13/(1/推導鏈!$D$16+(L13/K13)/推導鏈!$D$17) -> 8.1796606e+09 | O13: =N13/K13 -> 2.0750027 | P13: =輸入!$D$6*1000000000/(N13*推導鏈!$D$6) -> 0.81495677 | Q13: =輸入!$D$6*1000000000/N13 -> 1.5978658 | R13: =(M13-(輸入!$D$14*1000000000*525600*E13/1000000)/推導鏈!$D$16)/((1-D13)/推導鏈!$D$16+D13/推導鏈!$D$17)*1000000/(F13*1000000000*365) -> 12916.271 | S13: =IF(Q13>=推導鏈!$D$41,"回本","不回本") -> 回本
A14: 推論支出 | B14: 低 | C14: =輸入!$D$17 -> 4000 | D14: =輸入!$D$18 -> 0.6 | E14: =輸入!$D$15 -> 0.75 | F14: =輸入!$D$16 -> 2.5 | G14: =輸入!$I$29 -> 8.4 | H14: =輸入!$D$30 -> 2 | I14: =輸入!$D$32 -> 0.35 | J14: =輸入!$D$33 -> 1 | K14: =輸入!$D$14*1000000000*525600*E14/1000000+F14*1000000000*C14*365/1000000*(1-D14) -> 3825200000 | L14: =F14*1000000000*C14*365/1000000*D14 -> 2190000000 | M14: =G14/推導鏈!$D$18/H14*(I14/輸入!$D$31)*J14 -> 0.26194472 | N14: =M14/(1/推導鏈!$D$16+(L14/K14)/推導鏈!$D$17) -> 5.487568e+09 | O14: =N14/K14 -> 1.4345833 | P14: =輸入!$D$6*1000000000/(N14*推導鏈!$D$6) -> 1.2147585 | Q14: =輸入!$D$6*1000000000/N14 -> 2.3817473 | R14: =(M14-(輸入!$D$14*1000000000*525600*E14/1000000)/推導鏈!$D$16)/((1-D14)/推導鏈!$D$16+D14/推導鏈!$D$17)*1000000/(F14*1000000000*365) -> 7753.8087 | S14: =IF(Q14>=推導鏈!$D$41,"回本","不回本") -> 回本 | T14: =ABS(LN(O15/O14)) -> 0.43671765
A15: 推論支出 | B15: 高 | C15: =輸入!$D$17 -> 4000 | D15: =輸入!$D$18 -> 0.6 | E15: =輸入!$D$15 -> 0.75 | F15: =輸入!$D$16 -> 2.5 | G15: =輸入!$J$29 -> 13 | H15: =輸入!$D$30 -> 2 | I15: =輸入!$D$32 -> 0.35 | J15: =輸入!$D$33 -> 1 | K15: =輸入!$D$14*1000000000*525600*E15/1000000+F15*1000000000*C15*365/1000000*(1-D15) -> 3825200000 | L15: =F15*1000000000*C15*365/1000000*D15 -> 2190000000 | M15: =G15/推導鏈!$D$18/H15*(I15/輸入!$D$31)*J15 -> 0.40539063 | N15: =M15/(1/推導鏈!$D$16+(L15/K15)/推導鏈!$D$17) -> 8.4926647e+09 | O15: =N15/K15 -> 2.2201884 | P15: =輸入!$D$6*1000000000/(N15*推導鏈!$D$6) -> 0.78492087 | Q15: =輸入!$D$6*1000000000/N15 -> 1.5389752 | R15: =(M15-(輸入!$D$14*1000000000*525600*E15/1000000)/推導鏈!$D$16)/((1-D15)/推導鏈!$D$16+D15/推導鏈!$D$17)*1000000/(F15*1000000000*365) -> 14539.646 | S15: =IF(Q15>=推導鏈!$D$41,"回本","不回本") -> 回本
A16: 計價倍數 | B16: 低 | C16: =輸入!$D$17 -> 4000 | D16: =輸入!$D$18 -> 0.6 | E16: =輸入!$D$15 -> 0.75 | F16: =輸入!$D$16 -> 2.5 | G16: =輸入!$D$29 -> 12.6 | H16: =輸入!$I$30 -> 1.2 | I16: =輸入!$D$32 -> 0.35 | J16: =輸入!$D$33 -> 1 | K16: =輸入!$D$14*1000000000*525600*E16/1000000+F16*1000000000*C16*365/1000000*(1-D16) -> 3825200000 | L16: =F16*1000000000*C16*365/1000000*D16 -> 2190000000 | M16: =G16/推導鏈!$D$18/H16*(I16/輸入!$D$31)*J16 -> 0.65486179 | N16: =M16/(1/推導鏈!$D$16+(L16/K16)/推導鏈!$D$17) -> 1.371892e+10 | O16: =N16/K16 -> 3.5864582 | P16: =輸入!$D$6*1000000000/(N16*推導鏈!$D$6) -> 0.48590339 | Q16: =輸入!$D$6*1000000000/N16 -> 0.95269891 | R16: =(M16-(輸入!$D$14*1000000000*525600*E16/1000000)/推導鏈!$D$16)/((1-D16)/推導鏈!$D$16+D16/推導鏈!$D$17)*1000000/(F16*1000000000*365) -> 26341.102 | S16: =IF(Q16>=推導鏈!$D$41,"回本","不回本") -> 回本 | T16: =ABS(LN(O17/O16)) -> 0.91629073
A17: 計價倍數 | B17: 高 | C17: =輸入!$D$17 -> 4000 | D17: =輸入!$D$18 -> 0.6 | E17: =輸入!$D$15 -> 0.75 | F17: =輸入!$D$16 -> 2.5 | G17: =輸入!$D$29 -> 12.6 | H17: =輸入!$J$30 -> 3 | I17: =輸入!$D$32 -> 0.35 | J17: =輸入!$D$33 -> 1 | K17: =輸入!$D$14*1000000000*525600*E17/1000000+F17*1000000000*C17*365/1000000*(1-D17) -> 3825200000 | L17: =F17*1000000000*C17*365/1000000*D17 -> 2190000000 | M17: =G17/推導鏈!$D$18/H17*(I17/輸入!$D$31)*J17 -> 0.26194472 | N17: =M17/(1/推導鏈!$D$16+(L17/K17)/推導鏈!$D$17) -> 5.487568e+09 | O17: =N17/K17 -> 1.4345833 | P17: =輸入!$D$6*1000000000/(N17*推導鏈!$D$6) -> 1.2147585 | Q17: =輸入!$D$6*1000000000/N17 -> 2.3817473 | R17: =(M17-(輸入!$D$14*1000000000*525600*E17/1000000)/推導鏈!$D$16)/((1-D17)/推導鏈!$D$16+D17/推導鏈!$D$17)*1000000/(F17*1000000000*365) -> 7753.8087 | S17: =IF(Q17>=推導鏈!$D$41,"回本","不回本") -> 回本
A18: 實際利用率×折減 | B18: 低 | C18: =輸入!$D$17 -> 4000 | D18: =輸入!$D$18 -> 0.6 | E18: =輸入!$D$15 -> 0.75 | F18: =輸入!$D$16 -> 2.5 | G18: =輸入!$D$29 -> 12.6 | H18: =輸入!$D$30 -> 2 | I18: =輸入!$I$32 -> 0.3 | J18: =輸入!$D$33 -> 1 | K18: =輸入!$D$14*1000000000*525600*E18/1000000+F18*1000000000*C18*365/1000000*(1-D18) -> 3825200000 | L18: =F18*1000000000*C18*365/1000000*D18 -> 2190000000 | M18: =G18/推導鏈!$D$18/H18*(I18/輸入!$D$31)*J18 -> 0.33678606 | N18: =M18/(1/推導鏈!$D$16+(L18/K18)/推導鏈!$D$17) -> 7.0554445e+09 | O18: =N18/K18 -> 1.8444642 | P18: =輸入!$D$6*1000000000/(N18*推導鏈!$D$6) -> 0.94481215 | Q18: =輸入!$D$6*1000000000/N18 -> 1.8524701 | R18: =(M18-(輸入!$D$14*1000000000*525600*E18/1000000)/推導鏈!$D$16)/((1-D18)/推導鏈!$D$16+D18/推導鏈!$D$17)*1000000/(F18*1000000000*365) -> 11294.245 | S18: =IF(Q18>=推導鏈!$D$41,"回本","不回本") -> 回本 | T18: =ABS(LN(O19/O18)) -> 0.51082562
A19: 實際利用率×折減 | B19: 高 | C19: =輸入!$D$17 -> 4000 | D19: =輸入!$D$18 -> 0.6 | E19: =輸入!$D$15 -> 0.75 | F19: =輸入!$D$16 -> 2.5 | G19: =輸入!$D$29 -> 12.6 | H19: =輸入!$D$30 -> 2 | I19: =輸入!$J$32 -> 0.5 | J19: =輸入!$D$33 -> 1 | K19: =輸入!$D$14*1000000000*525600*E19/1000000+F19*1000000000*C19*365/1000000*(1-D19) -> 3825200000 | L19: =F19*1000000000*C19*365/1000000*D19 -> 2190000000 | M19: =G19/推導鏈!$D$18/H19*(I19/輸入!$D$31)*J19 -> 0.56131011 | N19: =M19/(1/推導鏈!$D$16+(L19/K19)/推導鏈!$D$17) -> 1.1759074e+10 | O19: =N19/K19 -> 3.074107 | P19: =輸入!$D$6*1000000000/(N19*推導鏈!$D$6) -> 0.56688729 | Q19: =輸入!$D$6*1000000000/N19 -> 1.1114821 | R19: =(M19-(輸入!$D$14*1000000000*525600*E19/1000000)/推導鏈!$D$16)/((1-D19)/推導鏈!$D$16+D19/推導鏈!$D$17)*1000000/(F19*1000000000*365) -> 21915.556 | S19: =IF(Q19>=推導鏈!$D$41,"回本","不回本") -> 回本
A20: κ | B20: 低 | C20: =輸入!$D$17 -> 4000 | D20: =輸入!$D$18 -> 0.6 | E20: =輸入!$D$15 -> 0.75 | F20: =輸入!$D$16 -> 2.5 | G20: =輸入!$D$29 -> 12.6 | H20: =輸入!$D$30 -> 2 | I20: =輸入!$D$32 -> 0.35 | J20: =輸入!$I$33 -> 0.65 | K20: =輸入!$D$14*1000000000*525600*E20/1000000+F20*1000000000*C20*365/1000000*(1-D20) -> 3825200000 | L20: =F20*1000000000*C20*365/1000000*D20 -> 2190000000 | M20: =G20/推導鏈!$D$18/H20*(I20/輸入!$D$31)*J20 -> 0.2553961 | N20: =M20/(1/推導鏈!$D$16+(L20/K20)/推導鏈!$D$17) -> 5.3503788e+09 | O20: =N20/K20 -> 1.3987187 | P20: =輸入!$D$6*1000000000/(N20*推導鏈!$D$6) -> 1.2459061 | Q20: =輸入!$D$6*1000000000/N20 -> 2.4428177 | R20: =(M20-(輸入!$D$14*1000000000*525600*E20/1000000)/推導鏈!$D$16)/((1-D20)/推導鏈!$D$16+D20/推導鏈!$D$17)*1000000/(F20*1000000000*365) -> 7444.0205 | S20: =IF(Q20>=推導鏈!$D$41,"回本","不回本") -> 回本 | T20: =ABS(LN(O21/O20)) -> 0.61310447
A21: κ | B21: 高 | C21: =輸入!$D$17 -> 4000 | D21: =輸入!$D$18 -> 0.6 | E21: =輸入!$D$15 -> 0.75 | F21: =輸入!$D$16 -> 2.5 | G21: =輸入!$D$29 -> 12.6 | H21: =輸入!$D$30 -> 2 | I21: =輸入!$D$32 -> 0.35 | J21: =輸入!$J$33 -> 1.2 | K21: =輸入!$D$14*1000000000*525600*E21/1000000+F21*1000000000*C21*365/1000000*(1-D21) -> 3825200000 | L21: =F21*1000000000*C21*365/1000000*D21 -> 2190000000 | M21: =G21/推導鏈!$D$18/H21*(I21/輸入!$D$31)*J21 -> 0.47150049 | N21: =M21/(1/推導鏈!$D$16+(L21/K21)/推導鏈!$D$17) -> 9.8776223e+09 | O21: =N21/K21 -> 2.5822499 | P21: =輸入!$D$6*1000000000/(N21*推導鏈!$D$6) -> 0.67486582 | Q21: =輸入!$D$6*1000000000/N21 -> 1.3231929 | R21: =(M21-(輸入!$D$14*1000000000*525600*E21/1000000)/推導鏈!$D$16)/((1-D21)/推導鏈!$D$16+D21/推導鏈!$D$17)*1000000/(F21*1000000000*365) -> 17667.032 | S21: =IF(Q21>=推導鏈!$D$41,"回本","不回本") -> 回本
A23: 讀法：缺口 ln 寬度最大的輸入，就是最值得先查證的輸入。m_fleet 與實收單價只隨機隊端與營收變動，需求端輸入（τ、免費占比、API 比例、每日訊息）只改變缺口，不改變 m_fleet。

Sheet 四項口徑差
A1: 四項口徑差：模型 L1 的落差分解，以及為何乘積 13.4 會超過 ScaleServe 7.38
A3: # | B3: 項目 | C3: 單位 | D3: 模型 L1 現值 | E3: 本活頁簿重算 | F3: 說明
A4: 1 | B4: GapPrompt：每則 token ÷ 2,000 | C4: x | D4: 2 | E4: =推導鏈!D19/E11 -> 1.3013083 | F4: 模型直接用 τ ÷ 2,000＝2.0。但 API 不隨 τ 變，GW 只增加 1.30 倍（E 欄＝τ 4,000 的 GW ÷ τ 2,000 的 GW）。
A5: 2 | B5: GapSpendBasis：計價倍數 | C5: x | D5: 2 | E5: =輸入!$D$30 -> 2 | F5: 與推導鏈 D2 相同；A 段證據中心 1.5
A6: 3 | B6: GapISL：參考請求 ISL 16K 對 4K | C6: x | D6: 2.307 | E6: =1/輸入!$D$33 -> 1 | F6: 模型取「輸入縮成 4K、輸出仍 2K」的產出比；A 段以實際輸入輸出比重算 κ≈1.0，即本項≈1.0
A7: 4 | B7: GapUtil：IF_Util × δ ÷ 實際利用率 | C7: x | D7: 1.457 | E7: =輸入!$D$31/輸入!$D$32 -> 1.7142857 | F7: 模型乘了 δ 0.85，但機隊路線（推導鏈 D3）只用 IF_Util ÷ 實際利用率＝1.714；兩處口徑不同
A8: 5 | B8: 乘積 | C8: x | D8: =D4*D5*D6*D7 -> 13.445196 | E8: =E4*E5*E6*E7 -> 4.4616284 | F8: 模型 13.44；本活頁簿以有效 τ 倍數與機隊口徑重算
A9: 6 | B9: ScaleServe（τ＝4,000） | C9: x | D9: 7.378 | E9: =推導鏈!D31 -> 7.3778569 | F9: 支出路線 GW ÷ token 路線 GW
A10: 7 | B10: ScaleServe（τ＝2,000；v5.28 基準） | C10: x | E10: =推導鏈!D21/E11 -> 9.6008662 | F10: 乘積應對照的對象是 τ＝2,000 的 ScaleServe
A11: — | B11: （輔助）τ＝2,000 時 token 路線 GW | C11: GW | E11: =(輸入!$D$14*1000000000*525600*輸入!$D$15/1000000+輸入!$D$16*1000000000*2000*365/1000000*(1-輸入!$D$18))/推導鏈!$D$16+(輸入!$D$16*1000000000*2000*365/1000000*輸入!$D$18)/推導鏈!$D$17 -> 0.14031487 | F11: 計算第 1、7 列用
A12: 8 | B12: 只改正 τ 重複計入、其餘維持模型值的乘積 | C12: x | E12: =E4*D5*D6*D7 -> 8.7481724 | F12: 1.30 × 2.0 × 2.307 × 1.457
A13: 9 | B13: 第 8 列對 ScaleServe（τ＝2,000）的解釋比例 | C13: % | E13: =E12/E10 -> 0.91118574 | F13: 第 8 列 ÷ 第 7 列
A14: 10 | B14: 再改用實際流量（κ）與機隊利用率口徑的乘積 | C14: x | E14: =E8 -> 4.4616284 | F14: ＝第 5 列 E 欄
A15: 11 | B15: 第 10 列的解釋比例 | C15: % | E15: =E14/E10 -> 0.46471103 | F15: 第 10 列 ÷ 第 7 列；剩下的部分就是推導鏈 E2 的缺口
A17: 讀法：模型的乘積 13.44 超過 7.38，是因為 (a) τ 的倍數 2.0 被重複計入（ScaleServe 7.38 已經是 τ＝4,000 下的值，應對照 τ＝2,000 的 9.60），(b) GapISL 2.31 用了不符實際流量的假設。只改正 (a) 時乘積可解釋約九成（第 9 列）；再改正 (b) 與利用率口徑後只解釋不到一半（第 11 列），剩下的就是推導鏈 E2 的缺口。
A18: 四項口徑差只是說明工具；本活頁簿以推導鏈 E4 的恆等式為準：缺口＝ScaleServe ÷（計價倍數 × IF_Util ÷（實際利用率 × κ））。

Sheet 價格時間錯配
A1: 價格時間錯配：2025 年實際牌價 ÷ 2026-09 快照（ρ），以及對 m 的影響
A2: 參考請求單價 ref＝[0.45 × 輸入價 × 16,000 ＋ 0.55 × 快取價 × 16,000 ＋ 輸出價 × 2,000] ÷ 18,000（未折扣；兩邊同乘 0.8 約掉）。數值取自 v5.36A 第 3.3 節（Derived；牌價為二手彙整，等級 3）。
A4: 模型 | B4: ref $/M | C4: 2025 月數 | D4: 加權 | E4: 說明
A5: GPT-4o（中階，2025-01～07） | B5: 2.722 | C5: 7 | D5: =B5*C5 -> 19.054
A6: GPT-5（中階，2025-08～11） | B6: 1.672 | C6: 4 | D6: =B6*C6 -> 6.688
A7: GPT-5.2（中階，2025-12） | B7: 2.341 | C7: 1 | D7: =B7*C7 -> 2.341
A8: GPT-4o mini（低階，2025-01～07） | B8: 0.163 | C8: 7 | D8: =B8*C8 -> 1.141
A9: GPT-5 mini（低階，2025-08～12） | B9: 0.334 | C9: 5 | D9: =B9*C9 -> 1.67
A10: 快照 Sol（GPT-6 中階） | B10: 2.009
A11: 快照 Luna（GPT-6 低階） | B11: 0.1
A13: 2025 中階時間加權 ref | B13: =SUM(D5:D7)/SUM(C5:C7) -> 2.34025
A14: 2025 低階時間加權 ref | B14: =SUM(D8:D9)/SUM(C8:C9) -> 0.23425
A15: ρ 情境 1：全用中階 | B15: =B13/B10 -> 1.164883 | E15: 2025 中階 ÷ 快照 Sol；A 段區間 0.83–1.36
A16: ρ 情境 2：中階＋低階各半 | B16: =(0.5*B13+0.5*B14)/(0.5*B10+0.5*B11) -> 1.2207207 | E16: A 段區間 0.82–1.47
A18: 修正後 m（模型現值欄） | B18: ρ 情境 1 | C18: ρ 情境 2
A19: m_fleet ÷ ρ | B19: =推導鏈!D26/B15 -> 0.69521057 | C19: =推導鏈!D26/B16 -> 0.66341054
A20: m_整體 ÷ ρ | B20: =推導鏈!D13/B15 -> 1.4960062 | C20: =推導鏈!D13/B16 -> 1.4275765
A21: 缺口（修正後 m_整體 ÷ 修正後 m_fleet） | B21: =B20/B19 -> 2.1518749 | C21: =C20/C19 -> 2.1518749
A23: 讀法：ρ 讓兩個 m 都下降 14–18%，但缺口不變（第 21 列＝推導鏈 E2）。實收單價（美元）是 2025 營收 ÷ 2025 token 的觀測，也不受 ρ 影響，所以回本判讀不變。ρ 只改變「m 低於 1 是打折還是牌價下降」的解讀。

Sheet 證據
A1: 證據：v5.36A 查證（2026-10-15）的原始紀錄，原樣複製；「已搜尋，未找到」與「不存在」不同
A3: 2.1_A1 新揭露
A4: 搜尋範圍：WebSearch「OpenAI tokens per day ChatGPT messages per day October 2026」「OpenAI API tokens per minute DevDay 2026」「OpenAI announces tokens per day billion token API usage October 2026（extended）」「OpenAI news October 14 2026 weekly active users」「Anthropic Claude tokens per day disclosed run-rate revenue October 2026」「Google Gemini monthly tokens processed quadrillion 2026」「Microsoft FY26 Q4 earnings Nadella tokens processed Foundry」；WebFetch：openai.com DevDay 2026 recap、blog.google I/O 2026、Microsoft FY26 Q4 電話會議逐字稿（.docx 讀出為二進位，未能讀取）、Futurum FY26 Q4 摘要。
A5: 2.1 A1 新揭露（2026-10-12 之後；並補作類比的 token 量）
A6: ID | B6: 項目 | C6: 數值 | D6: 單位／期間 | E6: 來源 | F6: 文件日 | G6: 標記 | H6: 利害關係方與誘因／備註 | I6: 讀取日
A7: A1-1 | B7: 2026-10-12 後 OpenAI 每日訊息、每日／每分鐘 token、API token 量 | C7: 已搜尋，未找到 | D7: — | E7: 上列搜尋；OpenAI DevDay 2026 recap（2026-09-29）只有「ChatGPT 1.2B 週用戶」，無訊息數與 token 量 | F7: 讀取日 2026-10-15 | G7: — | H7: 不等於不存在；最新可查日期為 10-08（OpenRouter）與 10-10（二手摘要） | I7: 2026-10-15
A8: A1-2 | B8: Anthropic token 量 | C8: 已搜尋，未找到；僅有 2026-06-01 機密 S-1 申報與年化營收約 470 億（2026 年 5 月下旬）的二手報導（InterCapital 2026-06-08），無 token、無推論成本、無利用率 | D8: — | E8: https://inter.capital/meet-the-father-of-claude-anthropic-files-for-an-ipo-at-usd-965-billion/；Madrona 2026-04 文章也無 token 量 | F8: 2026-06-08 | G8: Interested-party（二手） | H8: Anthropic：IPO 前敘事 | I8: 2026-10-15
A9: A1-3 | B9: Google 每月處理 token | C9: 3.2 千兆（3.2e15）／月，一年前約 480 兆，兩年前 9.7 兆；Gemini app 月活 >9 億 | D9: 2026-05（I/O） | E9: https://blog.google/innovation-and-ai/sundar-pichai-io-2026/ | F9: 2026-05-19 | G9: Interested-party（Google；誘因：AI 領先敘事，token 量含所有內部表面與快取，並非付費收入口徑） | H9: 換算 1.07e14 tok/日＝107 T/日；對照 Alloc 第 12 列 OpenAI 2025 需求 16.5 T/日（Epoch 區間 10–100 T）。DB_Evidence D180 已登錄同主題，不重複登錄 | I9: 2026-10-15
A10: A1-4 | B10: Microsoft：年化達 1 兆 token 的 Foundry 客戶數較去年 ×4 | C10: 無 token 總量 | D10: FY26 Q4（2026-04～06），電話會議 2026-07-29 | E10: Futurum 2026-07-31 https://futurumgroup.com/insights/microsoft-q4-fy-2026-ai-demand-accelerates-azure-and-enterprise-growth/（二手） | F10: 2026-07-31 | G10: Interested-party（二手） | H10: 該文未提 OpenAI；Microsoft Cloud 毛利 65%（FY26 Q4，cryptobriefing 2026-10-10 摘要）→ 不可比（含軟體） | I10: 2026-10-15
A11: A1-5 | B11: OpenRouter 週 token | C11: 128.4 T／週（2026-09-14 週）；2025-01-13 週約 0.5 T；OpenAI 占 OpenAI＋Anthropic 合計 token 78% | D11: 2026-09 | E11: https://openrouter.ai/data/newsletter/the-token-state-of-play | F11: 2026-09-22 | G11: Analogy（OpenRouter：路由商，樣本偏開發者；無輸入／輸出拆分） | H11: 2025 年 OpenAI 的 OpenRouter 量不等於 OpenAI 全部 API | I11: 2026-10-15
A12: A1-6 | B12: OpenAI 內部：Codex 占 OpenAI 全公司每週輸出 token | C12: 99.8%；平均員工 2025-08 前 Codex 占比 <10%，2026-06 前後 >85% | D12: 2026-06 前後 | E12: https://openai.com/index/how-agents-are-transforming-work/ | F12: 2026-06～08 | G12: Interested-party（OpenAI 自述） | H12: 只涵蓋 OpenAI 內部使用，不是客戶流量；說明 2025 年流量結構仍以對話為主，代理型流量是 2026 年的現象（支持「2025 實際輸入長度較短、較少快取」） | I12: 2026-10-15
A13: A1-7 | B13: OpenRouter 月 token（2026-08）OpenAI 25.6 T、Anthropic 8.8 T | C13: — | D13: 2026-08 | E13: https://sacra.com/research/openai（二手） | F13: 2026-10 讀取 | G13: Analogy（二手） | H13: 僅作量級對照 | I13: 2026-10-15
A15: 2.2_A2 計價倍數
A16: 搜尋範圍：「OpenAI Microsoft Azure inference spend 2025 … leaked documents revenue share」「OpenAI Oracle Stargate compute price per GPU hour per GW」「OpenAI compute margin 2025 The Information」「Oracle AI cloud gross margin 14%」「Microsoft Azure AI infrastructure gross margin」「H100 rental price 2025 Silicon Data」「Azure ND H100 v5 price」「OpenAI Oracle $300 billion 4.5 gigawatts」「CoreWeave revenue per megawatt」；WebFetch 對應原文。
A17: 持有成本對照（Interface／L1，100% 時數、基準成本）：Hopper 1.543 $/GPU-hr（1.08–2.65）；單位 GW：Hopper 9.70、GB200 8.83、GB300 10.89、VR200 12.23 $B/GW/年。
A18: 2.2 A2 計價倍數（Azure 推論計價 ÷ 持有成本；現值 2.0，區間 1.5–3.0，Assumed）
A19: ID | B19: 項目 | C19: 數值 | D19: 期間 | E19: 來源 | F19: 文件日 | G19: 標記 | H19: 利害關係方與誘因／推得倍數 | I19: 讀取日
A20: A2-1 | B20: Oracle 出租 Nvidia 伺服器：營收約 9 億、毛利約 1.25 億 | C20: 毛利率 14% | D20: 2025-06～08 季 | E20: 二手轉述 The Information 報導 https://business.sherbrookerecord.com/sherbrookerecord/article/marketminute-2025-10-7-oracles-ai-cloud-margins-squeezed-by-nvidia-chips-sparking-investor-jitters | F20: 2025-10-07 | G20: Interested-party（洩漏的內部財務，二手；Oracle 曾公開表示合約壽命期毛利更高，該文未載，未驗證） | H20: 價格÷（含折舊與營運成本的成本）＝1÷(1−0.14)＝1.16（Derived）。此處成本含營運費，略大於「持有成本」，故倍數略低估 | I20: 2026-10-15
A21: A2-2 | B21: CoreWeave 2026 Q2：營收 26 億、調整後營業利益率 5%、調整後 EBITDA 率 59%；活躍電力 1.5 GW、合約電力 3.7→4.2 GW | C21: 營業利益率 5% | D21: 2026 Q2 | E21: https://www.marketbeat.com/instant-alerts/coreweave-q2-earnings-call-highlights-2026-08-11/（二手摘要） | F21: 2026-08-11 | G21: Interested-party（CoreWeave；誘因：資本市場） | H21: 價格÷（成本含折舊、未含利息）≈1÷(1−0.05)＝1.05（Derived，下限）。每 MW 營收：未揭露 | I21: 2026-10-15
A22: A2-3 | B22: OpenAI–Oracle 雲端合約：3,000 億美元、5 年、2027 起、約 4.5–5 GW | C22: 約 600 億／年；每 GW 年 12.0–13.3 B | D22: 2027–2031 | E22: WSJ 經 The Register https://www.theregister.com/2025/09/11/openai_reportedly_on_the_hook/ | F22: 2025-09-11 | G22: Interested-party（匿名消息；OpenAI 與 Oracle 皆有誘因渲染規模；GW 口徑未明：IT 或設施） | H22: Derived：對持有成本 GB300 10.89→1.10–1.22；GB200 8.83→1.36–1.51；VR200 12.23→0.98–1.09。若 GW 為設施口徑，每 IT GW 再 ×PUE，倍數上升（口徑未明，不加） | I22: 2026-10-15
A23: A2-4 | B23: H100 租價指數（每 GPU-hr）：2025-01～05 超大雲 8.73–9.30、市集 2.27–2.46、neocloud 3.00–4.19；2025-07～12 超大雲 6.20–6.64、市集 1.92–2.00、neocloud 3.01–3.40 | C23: 超大雲 6.26–8.96、neocloud 3.33–3.50、市集 1.95–2.29 | D23: 2025 | E23: https://www.silicondata.com/blog/h100-rental-price-over-time | F23: 讀取日 2026-10-15 | G23: Interested-party（Silicon Data：賣指數資料；為牌價而非 OpenAI 長約價） | H23: Derived（對 Hopper 持有成本 1.543）：市集 1.3–1.5、neocloud 2.2–2.3、超大雲 4.1–5.8（牌價）。注意：此為「按時數出租」價，持有成本亦為 100% 時數，單位一致 | I23: 2026-10-15
A24: A2-5 | B24: 洩漏的 Microsoft 文件：OpenAI 2025 前三季 Azure 推論支出 8.7B（2024 全年 3.7B）；對 Microsoft 的 20% 分成 2025 H1 4.547 億、Q3 8.659 億 | C24: 8.7B（Q1–Q3）；12.6B 為全年推估 | D24: 2025 | E24: The Register 2025-11-12 https://www.theregister.com/2025/11/12/openai_spending_report/ | F24: 2025-11-12 | G24: Interested-party（洩漏，Zitron 經手；Microsoft 發言人稱「數字不太對」；文中提到雲端抵用金可能未反映） | H24: SRC_DEM_018 12.6B 的出處；基準（Azure 價、單價）文中未載 | I24: 2026-10-15
A25: A2-6 | B25: OpenAI 計算毛利（paying products）：2024-01 約 35%、2024 年底 52%、2025-10 約 70% | C25: 70%（2025-10） | D25: — | E25: The Information 經 Bloomberg／Fortune https://fortune.com/2025/12/21/openai-compute-margins-revenue-chatgpt-earnings-sam-altman/；SaaStr 2025-12-24 | F25: 2025-12-21 | G25: Interested-party（OpenAI 內部指標，洩漏；OpenAI 發言人不予置評；誘因：融資敘事） | H25: Derived 交叉檢查：付費推論成本＝(1−毛利)×營收13.07＝3.9（70%）至 5.1（61%，年內平均）；對照 SRC_DEM_004−005＝8.4−3.9＝4.5，吻合。→ 8.4B 是「OpenAI 自己帳上的推論成本」，與毛利口徑一致；12.6B 是另一來源（Azure 帳單） | I25: 2026-10-15
A26: A2-7 | B26: OpenAI 對 Microsoft／Oracle／CoreWeave 的推論算力單價（每 GPU-hr 或每 GW） | C26: 已搜尋，未找到（只有合約總額與 GW 級別） | D26: — | E26: 同上各搜尋 | F26: — | G26: — | H26: v5.29 E262 已記同一缺口 | I26: 2026-10-15
A27: A2-8 | B27: 營收分成與算力抵扣的會計說明 | C27: 已搜尋，未找到一手說明；僅有「20% 分成」「抵用金可能未反映」二手敘述 | D27: — | E27: A2-5 | F27: — | G27: — | H27: 影響：12.6B 若含抵用金，現金支出被高估 | I27: 2026-10-15
A28: A2 判讀（Derived）： 純 GPU 租賃類觀測的倍數落在 1.05–1.5（毛利、合約、市集）；只有 neocloud 牌價（2.2）與超大雲牌價（4–6）超過 2.0，而 OpenAI 用長約、不是牌價。證據中心 1.5（1.2–2.0），現值 2.0（1.5–3.0）偏高，上緣 3.0 沒有任何支持。但把倍數調低會讓機隊變大、缺口變大（第 1.1 節）。能抵消的只有「推論支出基準」那一項（A2-5 vs A2-6 的兩個來源差 1.5 倍＝12.6÷8.4）。
A30: 2.3_A3 實際利用率 × 生產折減
A31: 搜尋範圍：「average GPU utilization large-scale inference clusters production percent」「Altman compute constrained capacity ChatGPT rate limits GPUs melting」「Alibaba Aegaeon GPU pooling」「ChatGPT traffic diurnal pattern peak hour to average ratio」；WebFetch：DeepSeek 一手文件、Hebbia、BurstGPT、arXiv 2608.13573、arXiv 2609.12923（PDF 讀出為空，未能讀取）。
A32: 2.3 A3 實際利用率 × 生產折減（現值 0.35，區間 0.30–0.40，Assumed）
A33: ID | B33: 項目 | C33: 數值 | D33: 期間 | E33: 來源 | F33: 文件日 | G33: 標記 | H33: 備註 | I33: 讀取日
A34: A3-1 | B34: DeepSeek V3／R1 線上服務：日均占用 226.75 節點（每節點 8×H800），尖峰 278 節點；低負載時段把節點讓給研究與訓練 | C34: 日均÷尖峰＝0.816 | D34: 2025-02 | E34: https://github.com/deepseek-ai/open-infra-index（Open Source Week Day 6 文件） | F34: 2025-02-27 | G34: Verified（一手節點數）／Interested-party（同文件的 545% 成本利潤率是自我宣傳，不引用） | H34: 這是「隨負載調度」後的比值；OpenAI 無夜間釋放（全球時區、免費層全天）。只能當上界參考，不是 token 吞吐利用率 | I34: 2026-10-15
A35: A3-2 | B35: 突發型負載的機隊平均利用率（示意） | C35: 約 12%（尖峰為平均的 8 倍；對照平滑負載 16 GPU vs 125 GPU） | D35: 2026-02 | E35: https://www.hebbia.com/blog/the-hidden-economics-of-llm-inference | F35: 2026-02 | G35: Analogy（廠商內部建模與 Erlang-C，非實測） | H35: 企業單租戶情境，不代表 OpenAI | I35: 2026-10-15
A36: A3-3 | B36: Alibaba Aegaeon：多模型 GPU 池化，1,192→213 張 H20（−82%），數十個至 72B 模型，Model Studio 多月 beta | C36: −82% GPU | D36: 2025-10 | E36: https://tomshardware.com/tech-industry/semiconductors/alibaba-says-new-pooling-system-cut-nvidia-gpu-use-by-82-percent | F36: 2025-10 | G36: Interested-party（Alibaba；誘因：技術宣傳） | H36: 長尾小模型閒置的例子；未載利用率百分比；不適用於旗艦模型 | I36: 2026-10-15
A37: A3-4 | B37: 對話型流量平日／上班時段高峰、週末與夜間低；API 型流量不週期、突發 | C37: 無單一比值 | D37: 2023～24 | E37: BurstGPT arXiv 2401.17644（Azure OpenAI 的區域服務商，213 天 1,031 萬筆） | F37: 2024-01 | G37: Analogy | H37: 方向支持「尖峰高於平均」；數值未載 | I37: 2026-10-15
A38: A3-5 | B38: OpenAI／Anthropic／Google 大規模推論叢集的 token 吞吐÷容量實測 | C38: 已搜尋，未找到 | D38: — | E38: 上列 | F38: — | G38: — | H38: 不是 SM 利用率，也不是 MFU；公開資料只有學術與廠商示意 | I38: 2026-10-15
A39: A3-6 | B39: OpenAI「算力不足」公開說法的時間分布 | C39: 已搜尋，未找到；只找到單一事件（2025-03 Altman 稱圖像生成使 GPU「熔化」並限流）的報導 | D39: 2025-03 | E39: https://fortune.com/2025/03/28/sam-altman-chatgpt-gpus-melting-ai-images | F39: 2025-03-28 | G39: Interested-party | H39: 事件而非分布 | I39: 2026-10-15
A40: A3 判讀： 沒有實測可以支持或推翻 0.30–0.40。DeepSeek 的日均÷尖峰 0.82 是「容量按尖峰配置、再隨負載調度」的上界；乘上批次填充與延遲目標的損失後，0.35 在合理範圍。機隊端只要利用率往高處走（0.40–0.50），缺口擴大至 2.46–3.07，所以 A3 不能用來閉合缺口。
A42: 2.4_A4 實際輸入長度、輸入輸出比、快取
A43: 搜尋範圍：「OpenRouter 2026 prompt tokens completion tokens ratio cache hit rate」「OpenAI prompt caching percent of API input tokens cached Codex agentic」「Codex tokens per week OpenAI」；WebFetch：OpenRouter「Cache is Crucial」「Token State of Play」、OpenAI「Better prompt caching for GPT-6」、arXiv 2608.13573、DeepSeek 一手文件。
A44: 2.4 A4 實際輸入長度、輸入輸出比、快取命中（現值：參考請求 ISL 16K／OSL 2K／χ 0.55；GapISL 2.31）
...
