Workbook

Sheet 說明
A1: 世代間每 MW 簽約收入的產業基準｜A 段查證明細（不改 Excel 模型）
A3: 讀取版本：model/20261014_Tokenomics_v5.35.xlsx（master 9dff7f5）。本檔只新增，不改模型。擷取日 2026-10-15。
A4: 頁籤：價格點_a_同等能力、價格點_b_層級牌價、價格點_c_算力租賃、E338-E341確認、上市間隔、對照計算。
A5: 標記：Verified／Interested-party／Analogy／Assumed／Derived。模型商與雲端商自家牌價一律標 Interested-party（銷售方），價格事實以官方頁確認。
A6: 藍字＝人工輸入的價格或日期（附來源）；黑字＝公式。「對照計算」頁每個結果都是公式，可點格看推導。
A7: Wayback Machine 被工具擋下（SITE_BLOCKED）：歷史牌價改用各模型當時的官方公告頁；上市後 0–6 個月的 GPU 租賃官方價格頁快照取不到。
A8: SemiAnalysis 未單獨引用；同源轉載（例如 spheron 轉述 CoreWeave 牌價）不算獨立來源。

Sheet 價格點_a_同等能力
A1: (a) 同等能力 token 價格（固定能力門檻下的最低價格與下降速率）
A3: 序列 | B3: 模型／門檻 | C3: 時點 | D3: 數值 | E3: 單位 | F3: 說明 | G3: 標記 | H3: 來源 | I3: URL | J3: 文件日期 | K3: 擷取日 | L3: 利害關係說明
A4: a1 MMLU≥GPT-4-0314（86.0）最低價 | B4: GPT-4-0314 | C4: 2023-03-14 | D4: 37.5 | E4: $/M（3:1 混合） | F4: 計算：(3×30+60)/4 | G4: Derived | H4: Epoch AI（Cottier 等）2025-03-12 | I4: https://epoch.ai/data-insights/llm-inference-price-trends | J4: 2025-03-12 | K4: 2026-10-15 | L4: 非銷售方（研究機構）；價格為 3:1 輸入:輸出混合（由 GPT-4 30/60→37.5 驗證）
A5: a1 MMLU≥GPT-4-0314（86.0）最低價 | B5: GPT-4 Turbo | C5: 2023-11-06 | D5: 15 | E5: $/M（3:1 混合） | F5: 計算：(3×10+30)/4 | G5: Derived | H5: Epoch AI（Cottier 等）2025-03-12 | I5: https://epoch.ai/data-insights/llm-inference-price-trends | J5: 2025-03-12 | K5: 2026-10-15 | L5: 非銷售方（研究機構）；價格為 3:1 輸入:輸出混合（由 GPT-4 30/60→37.5 驗證）
A6: a1 MMLU≥GPT-4-0314（86.0）最低價 | B6: GPT-4o-2024-05 | C6: 2024-05-13 | D6: 7.5 | E6: $/M（3:1 混合） | F6: 計算：(3×5+15)/4 | G6: Derived | H6: Epoch AI（Cottier 等）2025-03-12 | I6: https://epoch.ai/data-insights/llm-inference-price-trends | J6: 2025-03-12 | K6: 2026-10-15 | L6: 非銷售方（研究機構）；價格為 3:1 輸入:輸出混合（由 GPT-4 30/60→37.5 驗證）
A7: a1 MMLU≥GPT-4-0314（86.0）最低價 | B7: Gemini-1.5-Pro-2024-05 | C7: 2024-05-23 | D7: 2.19 | E7: $/M（3:1 混合） | F7: 計算：(3×1.25+5)/4；用的是 2024-10 降價後的價格，日期卻是模型發布日；時點與價格不同步 | G7: Derived | H7: Epoch AI（Cottier 等）2025-03-12 | I7: https://epoch.ai/data-insights/llm-inference-price-trends | J7: 2025-03-12 | K7: 2026-10-15 | L7: 非銷售方（研究機構）；價格為 3:1 輸入:輸出混合（由 GPT-4 30/60→37.5 驗證）
A8: a1 MMLU≥GPT-4-0314（86.0）最低價 | B8: Gemini 2.0 Flash | C8: 2025-02-05 | D8: 0.18 | E8: $/M（3:1 混合） | G8: Derived | H8: Epoch AI（Cottier 等）2025-03-12 | I8: https://epoch.ai/data-insights/llm-inference-price-trends | J8: 2025-03-12 | K8: 2026-10-15 | L8: 非銷售方（研究機構）；價格為 3:1 輸入:輸出混合（由 GPT-4 30/60→37.5 驗證）
A9: a2 GPQA Diamond≥33（GPT-4-0314 水準）最低價 | B9: GPT-4-0314 | C9: 2023-03-14 | D9: 37.5 | E9: $/M（3:1 混合） | G9: Derived | H9: Epoch AI（Cottier 等）2025-03-12 | I9: https://epoch.ai/data-insights/llm-inference-price-trends | J9: 2025-03-12 | K9: 2026-10-15 | L9: 非銷售方（研究機構）；價格為 3:1 輸入:輸出混合（由 GPT-4 30/60→37.5 驗證）
A10: a2 GPQA Diamond≥33（GPT-4-0314 水準）最低價 | B10: GPT-4 Turbo | C10: 2023-11-06 | D10: 15 | E10: $/M（3:1 混合） | G10: Derived | H10: Epoch AI（Cottier 等）2025-03-12 | I10: https://epoch.ai/data-insights/llm-inference-price-trends | J10: 2025-03-12 | K10: 2026-10-15 | L10: 非銷售方（研究機構）；價格為 3:1 輸入:輸出混合（由 GPT-4 30/60→37.5 驗證）
A11: a2 GPQA Diamond≥33（GPT-4-0314 水準）最低價 | B11: Mistral-Large-2024-02 | C11: 2024-02-26 | D11: 6 | E11: $/M（3:1 混合） | G11: Derived | H11: Epoch AI（Cottier 等）2025-03-12 | I11: https://epoch.ai/data-insights/llm-inference-price-trends | J11: 2025-03-12 | K11: 2026-10-15 | L11: 非銷售方（研究機構）；價格為 3:1 輸入:輸出混合（由 GPT-4 30/60→37.5 驗證）
A12: a2 GPQA Diamond≥33（GPT-4-0314 水準）最低價 | B12: Claude-3-Haiku | C12: 2024-03-04 | D12: 0.5 | E12: $/M（3:1 混合） | F12: 計算：(3×0.25+1.25)/4 | G12: Derived | H12: Epoch AI（Cottier 等）2025-03-12 | I12: https://epoch.ai/data-insights/llm-inference-price-trends | J12: 2025-03-12 | K12: 2026-10-15 | L12: 非銷售方（研究機構）；價格為 3:1 輸入:輸出混合（由 GPT-4 30/60→37.5 驗證）
A13: a2 GPQA Diamond≥33（GPT-4-0314 水準）最低價 | B13: Gemini-1.5-Flash-2024-05 | C13: 2024-05-10 | D13: 0.13 | E13: $/M（3:1 混合） | F13: 同上，價格可能為降價後 | G13: Derived | H13: Epoch AI（Cottier 等）2025-03-12 | I13: https://epoch.ai/data-insights/llm-inference-price-trends | J13: 2025-03-12 | K13: 2026-10-15 | L13: 非銷售方（研究機構）；價格為 3:1 輸入:輸出混合（由 GPT-4 30/60→37.5 驗證）
A14: a2 GPQA Diamond≥33（GPT-4-0314 水準）最低價 | B14: Phi 4 | C14: 2024-12-13 | D14: 0.12 | E14: $/M（3:1 混合） | G14: Derived | H14: Epoch AI（Cottier 等）2025-03-12 | I14: https://epoch.ai/data-insights/llm-inference-price-trends | J14: 2025-03-12 | K14: 2026-10-15 | L14: 非銷售方（研究機構）；價格為 3:1 輸入:輸出混合（由 GPT-4 30/60→37.5 驗證）
A15: a3 彙總速率（Epoch 2025） | B15: GPQA 達 GPT-4-0314 水準 | C15: 2023-03→2025-02 | D15: 40 | E15: 倍／年 | F15: Epoch：價格每年下降 40 倍；各門檻範圍 9–900 倍／年；「最快的下降發生在最近一年，不確定是否持續」 | G15: Derived | H15: Epoch AI（Cottier 等）2025-03-12 | I15: https://epoch.ai/data-insights/llm-inference-price-trends | J15: 2025-03-12 | K15: 2026-10-15 | L15: 非銷售方（研究機構）；價格為 3:1 輸入:輸出混合（由 GPT-4 30/60→37.5 驗證）
A16: a3 彙總速率（Epoch 2026） | B16: 五個基準平均（AIME、棋題、FrontierMath 1–3、GPQA Diamond、Mystery Game） | C16: 2023→2026 | D16: 13 | E16: 倍／年（≈每季 −47%） | F16: 成本＝達到固定準確度的實際花費（含推理 token，由測試逐題紀錄計算），不是牌價；最前沿 −66%／季（75 倍／年）；SOTA 後兩年 −32%／季（4.7 倍／年）；開源模型以租用硬體計價 | G16: Derived | H16: Epoch AI「The plunging price of thought」（Emberson、Roodman） | I16: https://epoch.ai/publications/the-plunging-price-of-thought | J16: 2026-09-22（2026-09-23 更新） | K16: 2026-10-15 | L16: 研究機構；成本口徑含推理 token
A17: a3 彙總速率（Epoch 2026） | B17: o3（2025-01-31）→ GPT-5.6 Luna（約 18 個月後）達 GPQA Diamond 75% | C17: 2025-01→2026-07 | D17: 725 | E17: 倍（每題成本 $0.30→$0.0004） | F17: Epoch 舉例 | G17: Derived | H17: Epoch AI「The plunging price of thought」 | I17: https://epoch.ai/publications/the-plunging-price-of-thought | J17: 2026-09-22 | K17: 2026-10-15 | L17: 非銷售方（研究機構）；價格為 3:1 輸入:輸出混合（由 GPT-4 30/60→37.5 驗證）
A18: a3 彙總速率（學術） | B18: 前沿模型達固定基準分數的成本（知識、推理、數學、軟體工程基準） | C18: 2022→2025 | D18: 7.5 | E18: 倍／年（5–10 倍） | F18: Gundlach、Lynch、Mertens、Thompson（arXiv 2511.23455v2）：演算法效率約 3 倍／年；前沿模型的執行價格另以每年 3–18 倍上升 | G18: Derived | H18: arXiv 2511.23455v2「The Price of Progress」 | I18: https://arxiv.org/abs/2511.23455v2 | J18: 2026-03-23（v2） | K18: 2026-10-15 | L18: 學術研究
A20: (a′) 同一模型壽命內降價（供 Q2 區分「壽命內衰減」與「世代間價格變化」）
A21: 模型 | B21: 生效日 | C21: 舊價 | D21: 新價 | E21: 幅度 | F21: 說明 | G21: 標記 | H21: 來源 | I21: URL | J21: 文件日期 | K21: 擷取日 | L21: 利害關係說明
A22: o3 | B22: 2025-06-10 | C22: 10/40（圖說） | D22: 2/8 | E22: $/M 輸入／輸出（−80%） | F22: 舊價僅見於圖說（AI 產生圖說），官方文字只給新價 2/8 | G22: Interested-party | H22: OpenAI Developer Community「o3 is 80% cheaper」 | I22: https://community.openai.com/t/o3-is-80-cheaper-and-introducing-o3-pro/1284925 | J22: 2025-06-10 | K22: 2026-10-15 | L22: 賣方（模型商）自家牌價；價格事實以官方頁確認，立場為銷售方
A23: Gemini 1.5 Pro | B23: 2024-10-01 | C23: 3.5/10.5（推算） | D23: 1.25/5（推算） | E23: 輸入 −64%／輸出 −52% | F23: 官方只給降幅 | G23: Interested-party | H23: developers.googleblog.com | I23: https://developers.googleblog.com/en/updated-production-ready-gemini-models-reduced-15-pro-pricing-increased-rate-limits-and-more/ | J23: 2024-09-24 | K23: 2026-10-15 | L23: 賣方（模型商）自家牌價；價格事實以官方頁確認，立場為銷售方
A24: GPT-5.6 Luna | B24: 2026-07-30 | C24: — | D24: — | E24: −80% | F24: 官方只給降幅 | G24: Interested-party | H24: developers.openai.com changelog | I24: https://developers.openai.com/api/docs/changelog | J24: 2026-07-30 | K24: 2026-10-15 | L24: 賣方（模型商）自家牌價；價格事實以官方頁確認，立場為銷售方
A25: GPT-5.6 Terra | B25: 2026-07-30 | C25: 2.5/15 | D25: 2/12（推算） | E25: −20% | G25: Interested-party | H25: openai.com/index/gpt-5-6/ | I25: https://openai.com/index/gpt-5-6/ | J25: 2026-07-30 | K25: 2026-10-15 | L25: 賣方（模型商）自家牌價；價格事實以官方頁確認，立場為銷售方
A26: GPT-5.6 Sol | B26: 2026-08-21 | C26: 5/30 | D26: 4/20 | E26: 輸入 −20%／輸出 −33%（促銷，至少至 2026-11-21） | G26: Interested-party | H26: developers.openai.com changelog | I26: https://developers.openai.com/api/docs/changelog | J26: 2026-08-21 | K26: 2026-10-15 | L26: 賣方（模型商）自家牌價；價格事實以官方頁確認，立場為銷售方
A27: AWS P5（H100）on-demand | B27: 2025-06-01 | C27: ~12.29/GPU-hr（推算：55.04÷0.56÷8） | D27: 6.88/GPU-hr | E27: −44%（Savings Plans −25% 至 −45%） | F27: 此項屬算力租賃，列此供對照 | G27: Derived | H27: AWS 部落格「up to 45% price reduction」；instances.vantage.sh（現價） | I27: https://aws.amazon.com/blogs/aws/announcing-up-to-45-price-reduction-for-amazon-ec2-nvidia-gpu-accelerated-instances/ | J27: 2025-06 | K27: 2026-10-15 | L27: 賣方（雲端商）自家牌價；立場為銷售方
A28: Claude Sonnet 5 | B28: 2026-08-10 | C28: （原訂 9/1 起 3/15） | D28: 2/10 轉為永久 | E28: 未實現的漲價取消 | G28: Interested-party | H28: anthropic.com/news/claude-sonnet-5 | I28: https://www.anthropic.com/news/claude-sonnet-5 | J28: 2026-08-10 | K28: 2026-10-15 | L28: 賣方（模型商）自家牌價；價格事實以官方頁確認，立場為銷售方
A30: 已搜尋，未找到：2025-02 以後、可回溯到原始牌價的逐點「固定能力最低價」序列（Epoch 2025 表止於 2025-02-05；Epoch 2026-09 報告為成本口徑彙總，圖內數值未提供）。已搜尋管道：epoch.ai 兩篇、arXiv 2511.23455。未查：Artificial Analysis。

Sheet 價格點_b_層級牌價
A1: (b) 層級牌價（上市時每 M token；輸入、輸出分開）
A3: 業者 | B3: 層級 | C3: 模型 | D3: 上市／生效日 | E3: 輸入 $/M | F3: 輸出 $/M | G3: 3:1 混合 $/M | H3: 8:1 混合 $/M | I3: 標記 | J3: 來源 | K3: URL | L3: 擷取日 | M3: 利害關係說明 | N3: 備註
A4: OpenAI | B4: 中階 | C4: GPT-4 (8K) | D4: 2023-03-14 | E4: 30 | F4: 60 | G4: =(3*E4+F4)/4 -> 37.5 | H4: =(8*E4+F4)/9 -> 33.333333 | I4: Interested-party | J4: openai.com/index/gpt-4-research/ | K4: https://openai.com/index/gpt-4-research/ | L4: 2026-10-15 | M4: 賣方（模型商）自家牌價；價格事實以官方頁確認，立場為銷售方 | N4: 當時為旗艦
A5: OpenAI | B5: 中階 | C5: GPT-4 Turbo | D5: 2023-11-06 | E5: 10 | F5: 30 | G5: =(3*E5+F5)/4 -> 15 | H5: =(8*E5+F5)/9 -> 12.222222 | I5: Interested-party | J5: openai.com DevDay 公告 | K5: https://openai.com/index/new-models-and-developer-products-announced-at-devday/ | L5: 2026-10-15 | M5: 賣方（模型商）自家牌價；價格事實以官方頁確認，立場為銷售方 | N5: 當時為旗艦
A6: OpenAI | B6: 中階 | C6: GPT-4o | D6: 2024-05-13 | E6: 5 | F6: 15 | G6: =(3*E6+F6)/4 -> 7.5 | H6: =(8*E6+F6)/9 -> 6.1111111 | I6: Interested-party | J6: OpenAI Developer Community 官方公告貼文 | K6: https://community.openai.com/t/announcing-gpt-4o-in-the-api/744700 | L6: 2026-10-15 | M6: 賣方（模型商）自家牌價；價格事實以官方頁確認，立場為銷售方 | N6: 當時為旗艦；openai.com 本站頁無絕對價
A7: OpenAI | B7: 中階 | C7: GPT-4o-2024-08-06 | D7: 2024-08-06 | E7: 2.5 | F7: 10 | G7: =(3*E7+F7)/4 -> 4.375 | H7: =(8*E7+F7)/9 -> 3.3333333 | I7: Interested-party | J7: openai.com structured outputs 公告 | K7: https://openai.com/index/introducing-structured-outputs-in-the-api/ | L7: 2026-10-15 | M7: 賣方（模型商）自家牌價；價格事實以官方頁確認，立場為銷售方 | N7: 新快照降價
A8: OpenAI | B8: 中階 | C8: GPT-4.1 | D8: 2025-04-14 | E8: 2 | F8: 8 | G8: =(3*E8+F8)/4 -> 3.5 | H8: =(8*E8+F8)/9 -> 2.6666667 | I8: Interested-party | J8: openai.com/index/gpt-4-1/ | K8: https://openai.com/index/gpt-4-1/ | L8: 2026-10-15 | M8: 賣方（模型商）自家牌價；價格事實以官方頁確認，立場為銷售方
A9: OpenAI | B9: 中階 | C9: GPT-5 | D9: 2025-08-07 | E9: 1.25 | F9: 10 | G9: =(3*E9+F9)/4 -> 3.4375 | H9: =(8*E9+F9)/9 -> 2.2222222 | I9: Interested-party | J9: openai.com GPT-5 for developers | K9: https://openai.com/index/introducing-gpt-5-for-developers/ | L9: 2026-10-15 | M9: 賣方（模型商）自家牌價；價格事實以官方頁確認，立場為銷售方
A10: OpenAI | B10: 中階 | C10: GPT-5.2 | D10: 2025-12-11 | E10: 1.75 | F10: 14 | G10: =(3*E10+F10)/4 -> 4.8125 | H10: =(8*E10+F10)/9 -> 3.1111111 | I10: Interested-party | J10: openai.com/index/introducing-gpt-5-2/ | K10: https://openai.com/index/introducing-gpt-5-2/ | L10: 2026-10-15 | M10: 賣方（模型商）自家牌價；價格事實以官方頁確認，立場為銷售方
A11: OpenAI | B11: 中階 | C11: GPT-5.4 | D11: 2026-03-05 | E11: 2.5 | F11: 15 | G11: =(3*E11+F11)/4 -> 5.625 | H11: =(8*E11+F11)/9 -> 3.8888889 | I11: Interested-party | J11: openai.com/index/introducing-gpt-5-4/ | K11: https://openai.com/index/introducing-gpt-5-4/ | L11: 2026-10-15 | M11: 賣方（模型商）自家牌價；價格事實以官方頁確認，立場為銷售方
A12: OpenAI | B12: 中階 | C12: GPT-5.6 Terra（上市價） | D12: 2026-07-09 | E12: 2.5 | F12: 15 | G12: =(3*E12+F12)/4 -> 5.625 | H12: =(8*E12+F12)/9 -> 3.8888889 | I12: Interested-party | J12: openai.com/index/gpt-5-6/ | K12: https://openai.com/index/gpt-5-6/ | L12: 2026-10-15 | M12: 賣方（模型商）自家牌價；價格事實以官方頁確認，立場為銷售方 | N12: 2026-07-30 降 20%
A13: OpenAI | B13: 中階 | C13: GPT-5.6 Terra（降價後） | D13: 2026-07-30 | E13: 2 | F13: 12 | G13: =(3*E13+F13)/4 -> 4.5 | H13: =(8*E13+F13)/9 -> 3.1111111 | I13: Derived | J13: openai.com/index/gpt-5-6/ 與 developers.openai.com changelog | K13: https://developers.openai.com/api/docs/changelog | L13: 2026-10-15 | M13: 賣方（模型商）自家牌價；價格事實以官方頁確認，立場為銷售方 | N13: 由 20% 降幅推得（Derived）
A14: OpenAI | B14: 中階 | C14: GPT-6 Sol | D14: 2026-09-22 | E14: 2 | F14: 10 | G14: =(3*E14+F14)/4 -> 4 | H14: =(8*E14+F14)/9 -> 2.8888889 | I14: Interested-party | J14: openai.com/index/introducing-gpt-6-sol-and-luna/；changelog | K14: https://openai.com/index/introducing-gpt-6-sol-and-luna/ | L14: 2026-10-15 | M14: 賣方（模型商）自家牌價；價格事實以官方頁確認，立場為銷售方 | N14: 層級名換位：GPT-6 的 Sol 為中階
A15: OpenAI | B15: 中階 | C15: GPT-6.1 Sol | D15: 2026-09-29 | E15: 2 | F15: 10 | G15: =(3*E15+F15)/4 -> 4 | H15: =(8*E15+F15)/9 -> 2.8888889 | I15: Interested-party | J15: developers.openai.com changelog | K15: https://developers.openai.com/api/docs/changelog | L15: 2026-10-15 | M15: 賣方（模型商）自家牌價；價格事實以官方頁確認，立場為銷售方 | N15: 快取 0.10
A16: OpenAI | B16: 旗艦 | C16: GPT-4 (8K) | D16: 2023-03-14 | E16: 30 | F16: 60 | G16: =(3*E16+F16)/4 -> 37.5 | H16: =(8*E16+F16)/9 -> 33.333333 | I16: Interested-party | J16: openai.com/index/gpt-4-research/ | K16: https://openai.com/index/gpt-4-research/ | L16: 2026-10-15 | M16: 賣方（模型商）自家牌價；價格事實以官方頁確認，立場為銷售方
A17: OpenAI | B17: 旗艦 | C17: GPT-4 Turbo | D17: 2023-11-06 | E17: 10 | F17: 30 | G17: =(3*E17+F17)/4 -> 15 | H17: =(8*E17+F17)/9 -> 12.222222 | I17: Interested-party | J17: openai.com DevDay | K17: https://openai.com/index/new-models-and-developer-products-announced-at-devday/ | L17: 2026-10-15 | M17: 賣方（模型商）自家牌價；價格事實以官方頁確認，立場為銷售方
A18: OpenAI | B18: 旗艦 | C18: GPT-4o | D18: 2024-05-13 | E18: 5 | F18: 15 | G18: =(3*E18+F18)/4 -> 7.5 | H18: =(8*E18+F18)/9 -> 6.1111111 | I18: Interested-party | J18: OpenAI Developer Community 官方公告 | K18: https://community.openai.com/t/announcing-gpt-4o-in-the-api/744700 | L18: 2026-10-15 | M18: 賣方（模型商）自家牌價；價格事實以官方頁確認，立場為銷售方
A19: OpenAI | B19: 旗艦 | C19: GPT-5 | D19: 2025-08-07 | E19: 1.25 | F19: 10 | G19: =(3*E19+F19)/4 -> 3.4375 | H19: =(8*E19+F19)/9 -> 2.2222222 | I19: Interested-party | J19: openai.com GPT-5 for developers | K19: https://openai.com/index/introducing-gpt-5-for-developers/ | L19: 2026-10-15 | M19: 賣方（模型商）自家牌價；價格事實以官方頁確認，立場為銷售方
A20: OpenAI | B20: 旗艦 | C20: GPT-5.2 | D20: 2025-12-11 | E20: 1.75 | F20: 14 | G20: =(3*E20+F20)/4 -> 4.8125 | H20: =(8*E20+F20)/9 -> 3.1111111 | I20: Interested-party | J20: openai.com GPT-5.2 | K20: https://openai.com/index/introducing-gpt-5-2/ | L20: 2026-10-15 | M20: 賣方（模型商）自家牌價；價格事實以官方頁確認，立場為銷售方
A21: OpenAI | B21: 旗艦 | C21: GPT-5.4 | D21: 2026-03-05 | E21: 2.5 | F21: 15 | G21: =(3*E21+F21)/4 -> 5.625 | H21: =(8*E21+F21)/9 -> 3.8888889 | I21: Interested-party | J21: openai.com GPT-5.4 | K21: https://openai.com/index/introducing-gpt-5-4/ | L21: 2026-10-15 | M21: 賣方（模型商）自家牌價；價格事實以官方頁確認，立場為銷售方
A22: OpenAI | B22: 旗艦 | C22: GPT-5.6 Sol（上市價） | D22: 2026-07-09 | E22: 5 | F22: 30 | G22: =(3*E22+F22)/4 -> 11.25 | H22: =(8*E22+F22)/9 -> 7.7777778 | I22: Interested-party | J22: openai.com/index/gpt-5-6/ | K22: https://openai.com/index/gpt-5-6/ | L22: 2026-10-15 | M22: 賣方（模型商）自家牌價；價格事實以官方頁確認，立場為銷售方 | N22: 2026-08-21 起促銷 4/20，至少至 2026-11-21
A23: OpenAI | B23: 旗艦 | C23: GPT-6 Astra | D23: 2026-09-03 | E23: 10 | F23: 50 | G23: =(3*E23+F23)/4 -> 20 | H23: =(8*E23+F23)/9 -> 14.444444 | I23: Interested-party | J23: developers.openai.com changelog（上市日）、openai.com/index/gpt-6-astra/（價格） | K23: https://openai.com/index/gpt-6-astra/ | L23: 2026-10-15 | M23: 賣方（模型商）自家牌價；價格事實以官方頁確認，立場為銷售方
A24: Anthropic | B24: 中階（Sonnet） | C24: Claude 3 Sonnet | D24: 2024-03-04 | E24: 3 | F24: 15 | G24: =(3*E24+F24)/4 -> 6 | H24: =(8*E24+F24)/9 -> 4.3333333 | I24: Interested-party | J24: anthropic.com/news/claude-3-family | K24: https://www.anthropic.com/news/claude-3-family | L24: 2026-10-15 | M24: 賣方（模型商）自家牌價；價格事實以官方頁確認，立場為銷售方
A25: Anthropic | B25: 中階（Sonnet） | C25: Claude 3.5 Sonnet | D25: 2024-06-21 | E25: 3 | F25: 15 | G25: =(3*E25+F25)/4 -> 6 | H25: =(8*E25+F25)/9 -> 4.3333333 | I25: Interested-party | J25: anthropic.com/news/claude-3-5-sonnet | K25: https://www.anthropic.com/news/claude-3-5-sonnet | L25: 2026-10-15 | M25: 賣方（模型商）自家牌價；價格事實以官方頁確認，立場為銷售方
A26: Anthropic | B26: 中階（Sonnet） | C26: Claude 3.7 Sonnet | D26: 2025-02-24 | E26: 3 | F26: 15 | G26: =(3*E26+F26)/4 -> 6 | H26: =(8*E26+F26)/9 -> 4.3333333 | I26: Interested-party | J26: anthropic.com/news/claude-3-7-sonnet | K26: https://www.anthropic.com/news/claude-3-7-sonnet | L26: 2026-10-15 | M26: 賣方（模型商）自家牌價；價格事實以官方頁確認，立場為銷售方
A27: Anthropic | B27: 中階（Sonnet） | C27: Claude Sonnet 4 | D27: 2025-05-22 | E27: 3 | F27: 15 | G27: =(3*E27+F27)/4 -> 6 | H27: =(8*E27+F27)/9 -> 4.3333333 | I27: Interested-party | J27: anthropic.com/news/claude-4 | K27: https://www.anthropic.com/news/claude-4 | L27: 2026-10-15 | M27: 賣方（模型商）自家牌價；價格事實以官方頁確認，立場為銷售方
A28: Anthropic | B28: 中階（Sonnet） | C28: Claude Sonnet 4.5 | D28: 2025-09-29 | E28: 3 | F28: 15 | G28: =(3*E28+F28)/4 -> 6 | H28: =(8*E28+F28)/9 -> 4.3333333 | I28: Interested-party | J28: anthropic.com/news/claude-sonnet-4-5 | K28: https://www.anthropic.com/news/claude-sonnet-4-5 | L28: 2026-10-15 | M28: 賣方（模型商）自家牌價；價格事實以官方頁確認，立場為銷售方
A29: Anthropic | B29: 中階（Sonnet） | C29: Claude Sonnet 4.6 | D29: 2026-02-17 | E29: 3 | F29: 15 | G29: =(3*E29+F29)/4 -> 6 | H29: =(8*E29+F29)/9 -> 4.3333333 | I29: Interested-party | J29: anthropic.com/news/claude-sonnet-4-6 | K29: https://www.anthropic.com/news/claude-sonnet-4-6 | L29: 2026-10-15 | M29: 賣方（模型商）自家牌價；價格事實以官方頁確認，立場為銷售方
A30: Anthropic | B30: 中階（Sonnet） | C30: Claude Sonnet 5 | D30: 2026-06-30 | E30: 2 | F30: 10 | G30: =(3*E30+F30)/4 -> 4 | H30: =(8*E30+F30)/9 -> 2.8888889 | I30: Interested-party | J30: anthropic.com/news/claude-sonnet-5 | K30: https://www.anthropic.com/news/claude-sonnet-5 | L30: 2026-10-15 | M30: 賣方（模型商）自家牌價；價格事實以官方頁確認，立場為銷售方 | N30: 2026-08-10 起「introductory 2/10 變永久」；新 tokenizer（同文字約 1.0–1.35× token）
A31: Anthropic | B31: 中階（Sonnet） | C31: Claude Sonnet 5.5 | D31: 2026-09-28 | E31: 2 | F31: 10 | G31: =(3*E31+F31)/4 -> 4 | H31: =(8*E31+F31)/9 -> 2.8888889 | I31: Interested-party | J31: anthropic.com/news/claude-sonnet-5-5 | K31: https://www.anthropic.com/news/claude-sonnet-5-5 | L31: 2026-10-15 | M31: 賣方（模型商）自家牌價；價格事實以官方頁確認，立場為銷售方
A32: Anthropic | B32: 旗艦（Opus） | C32: Claude 3 Opus | D32: 2024-03-04 | E32: 15 | F32: 75 | G32: =(3*E32+F32)/4 -> 30 | H32: =(8*E32+F32)/9 -> 21.666667 | I32: Interested-party | J32: anthropic.com/news/claude-3-family | K32: https://www.anthropic.com/news/claude-3-family | L32: 2026-10-15 | M32: 賣方（模型商）自家牌價；價格事實以官方頁確認，立場為銷售方
A33: Anthropic | B33: 旗艦（Opus） | C33: Claude Opus 4 | D33: 2025-05-22 | E33: 15 | F33: 75 | G33: =(3*E33+F33)/4 -> 30 | H33: =(8*E33+F33)/9 -> 21.666667 | I33: Interested-party | J33: anthropic.com/news/claude-4 | K33: https://www.anthropic.com/news/claude-4 | L33: 2026-10-15 | M33: 賣方（模型商）自家牌價；價格事實以官方頁確認，立場為銷售方
A34: Anthropic | B34: 旗艦（Opus） | C34: Claude Opus 4.5 | D34: 2025-11-24 | E34: 5 | F34: 25 | G34: =(3*E34+F34)/4 -> 10 | H34: =(8*E34+F34)/9 -> 7.2222222 | I34: Interested-party | J34: anthropic.com/news/claude-opus-4-5 | K34: https://www.anthropic.com/news/claude-opus-4-5 | L34: 2026-10-15 | M34: 賣方（模型商）自家牌價；價格事實以官方頁確認，立場為銷售方 | N34: 頁面未標輸入／輸出，$5/$25 依 platform.claude.com 定價頁
A35: Anthropic | B35: 旗艦（Opus） | C35: Claude Opus 5 | D35: 2026-07-24 | E35: 5 | F35: 25 | G35: =(3*E35+F35)/4 -> 10 | H35: =(8*E35+F35)/9 -> 7.2222222 | I35: Interested-party | J35: anthropic.com/news/claude-opus-5 | K35: https://www.anthropic.com/news/claude-opus-5 | L35: 2026-10-15 | M35: 賣方（模型商）自家牌價；價格事實以官方頁確認，立場為銷售方 | N35: 與 Opus 4.8 同價
A36: Anthropic | B36: 旗艦（Opus） | C36: Claude Opus 5.5 | D36: 2026-09-22 | E36: 4 | F36: 20 | G36: =(3*E36+F36)/4 -> 8 | H36: =(8*E36+F36)/9 -> 5.7777778 | I36: Interested-party | J36: platform.claude.com/docs/en/models/opus-5-5/overview | K36: https://platform.claude.com/docs/en/models/opus-5-5/overview | L36: 2026-10-15 | M36: 賣方（模型商）自家牌價；價格事實以官方頁確認，立場為銷售方
A37: Anthropic | B37: 頂層（Fable） | C37: Claude Fable 5 | D37: 2026-06-09 | E37: 10 | F37: 50 | G37: =(3*E37+F37)/4 -> 20 | H37: =(8*E37+F37)/9 -> 14.444444 | I37: Interested-party | J37: platform.claude.com/docs/en/models/fable-5/overview | K37: https://platform.claude.com/docs/en/models/fable-5/overview | L37: 2026-10-15 | M37: 賣方（模型商）自家牌價；價格事實以官方頁確認，立場為銷售方 | N37: Fable 價高於 Opus 5.5
A38: Google | B38: 旗艦（Pro） | C38: Gemini 1.5 Pro（≤128K） | D38: 2024-05-23 | E38: 3.5 | F38: 10.5 | G38: =(3*E38+F38)/4 -> 5.25 | H38: =(8*E38+F38)/9 -> 4.2777778 | I38: Derived | J38: Google AI Developers Forum 使用者貼文（輸入 3.50）；輸出 10.5 由 2024-09-24 降幅（輸入 −64%、輸出 −52%）與降後 1.25/5 反推 | K38: https://discuss.ai.google.dev/t/pay-as-you-go-plan-of-gemini-pro-1-5-3-5-million-tokens-meaning/3375 | L38: 2026-10-15 | M38: 賣方牌價；官方一手頁缺，輸入來自社群貼文 | N38: 找不到官方頁絕對價；輸出為 Derived
A39: Google | B39: 旗艦（Pro） | C39: Gemini 1.5 Pro（降價後，≤128K） | D39: 2024-10-01 | E39: 1.25 | F39: 5 | G39: =(3*E39+F39)/4 -> 2.1875 | H39: =(8*E39+F39)/9 -> 1.6666667 | I39: Derived | J39: developers.googleblog.com（2024-09-24）降幅 + 反推 | K39: https://developers.googleblog.com/en/updated-production-ready-gemini-models-reduced-15-pro-pricing-increased-rate-limits-and-more/ | L39: 2026-10-15 | M39: 賣方（模型商）自家牌價；價格事實以官方頁確認，立場為銷售方 | N39: 官方只給降幅；1.25/5 為推算相符值
A40: Google | B40: 旗艦（Pro） | C40: Gemini 2.5 Pro（≤200K） | D40: 2025-04-04 | E40: 1.25 | F40: 10 | G40: =(3*E40+F40)/4 -> 3.4375 | H40: =(8*E40+F40)/9 -> 2.2222222 | I40: Interested-party | J40: ai.google.dev 現行定價頁（價）；blog.google 2025-04-04（開始計費日，價為圖片） | K40: https://ai.google.dev/gemini-api/docs/pricing | L40: 2026-10-15 | M40: 賣方（模型商）自家牌價；價格事實以官方頁確認，立場為銷售方 | N40: 日期為首次公開計費日；2025-06-17 GA 同價
A41: Google | B41: 旗艦（Pro） | C41: Gemini 3 Pro（≤200K） | D41: 2025-11-18 | E41: 2 | F41: 12 | G41: =(3*E41+F41)/4 -> 4.5 | H41: =(8*E41+F41)/9 -> 3.1111111 | I41: Interested-party | J41: blog.google/technology/developers/gemini-3-developers/；changelog（上市日） | K41: https://blog.google/technology/developers/gemini-3-developers/ | L41: 2026-10-15 | M41: 賣方（模型商）自家牌價；價格事實以官方頁確認，立場為銷售方
...

Sheet 價格點_c_算力租賃
A1: (c) 算力租賃價格（隨需、預留、長約分開；每 GPU 小時與每 MW 年）
A3: GPU／產品 | B3: 計價層 | C3: 世代 | D3: 時點 | E3: 數值 | F3: 單位 | G3: 業者 | H3: 來源 | I3: URL | J3: 文件日期 | K3: 擷取日 | L3: 標記 | M3: 利害關係說明 | N3: 備註
A4: A100 80GB | B4: 隨需 | C4: Ampere（A100） | D4: 現價（頁面未標日） | E4: 2.79 | F4: $/GPU-hr | G4: Lambda | H4: lambda.ai/pricing | I4: https://lambda.ai/pricing | J4: （無） | K4: 2026-10-15 | L4: Interested-party | M4: 賣方（雲端商）自家牌價；立場為銷售方
A5: A100 80GB | B5: 隨需 | C5: Ampere（A100） | D5: 現價（頁面未標日） | E5: 2.7 | F5: $/GPU-hr | G5: CoreWeave | H5: coreweave.com/pricing（8 卡 $21.60÷8） | I5: https://www.coreweave.com/pricing | J5: （無） | K5: 2026-10-15 | L5: Interested-party | M5: 賣方（雲端商）自家牌價；立場為銷售方
A6: A100 8 卡 p4d | B6: 隨需 | C6: Ampere（A100） | D6: 2025-06 降價後現價 | E6: 2.745 | F6: $/GPU-hr | G6: AWS | H6: instances.vantage.sh（彙整 AWS 牌價 $21.958÷8）；AWS 部落格確認 2025-06-01 降 33% | I6: https://instances.vantage.sh/aws/ec2/p4d.24xlarge | J6: 2026-10-15 | K6: 2026-10-15 | L6: Derived | M6: 賣方（雲端商）自家牌價；立場為銷售方 | N6: 二手彙整站
A7: A100 8 卡 p4d | B7: 預留 1 年 | C7: Ampere（A100） | D7: 2025-06 降價後現價 | E7: 1.74 | F7: $/GPU-hr | G7: AWS | H7: instances.vantage.sh（$13.921÷8） | I7: https://instances.vantage.sh/aws/ec2/p4d.24xlarge | J7: 2026-10-15 | K7: 2026-10-15 | L7: Derived | M7: 賣方（雲端商）自家牌價；立場為銷售方 | N7: 二手彙整站
A8: A100 8 卡 p4d | B8: 預留 3 年 | C8: Ampere（A100） | D8: 2025-06 降價後現價 | E8: 1.172 | F8: $/GPU-hr | G8: AWS | H8: instances.vantage.sh（$9.374÷8） | I8: https://instances.vantage.sh/aws/ec2/p4d.24xlarge | J8: 2026-10-15 | K8: 2026-10-15 | L8: Derived | M8: 賣方（雲端商）自家牌價；立場為銷售方 | N8: 二手彙整站
A9: H100 PCIe | B9: 隨需 | C9: Hopper（H100） | D9: 2023-05-10 | E9: 2.4 | F9: $/GPU-hr | G9: Lambda | H9: lambda.ai/blog/lambda-cloud-deploys-nvidia-h100-tensor-core-gpus（上市後約 1–2 個月） | I9: https://lambda.ai/blog/lambda-cloud-deploys-nvidia-h100-tensor-core-gpus | J9: 2023-05-10 | K9: 2026-10-15 | L9: Interested-party | M9: 賣方（雲端商）自家牌價；立場為銷售方 | N9: 1 卡 PCIe
A10: H100 SXM 8x | B10: 隨需 | C10: Hopper（H100） | D10: 2023-08-02 | E10: 2.59 | F10: $/GPU-hr | G10: Lambda | H10: lambda.ai 部落格（8x H100 SXM 隨需） | I10: https://lambda.ai/blog/lambda-cloud-deploys-on-demand-nvidia-hgx-h100-with-8x-h100-sxm-instances | J10: 2023-08-02 | K10: 2026-10-15 | L10: Interested-party | M10: 賣方（雲端商）自家牌價；立場為銷售方
A11: H100 SXM 8x | B11: 隨需 | C11: Hopper（H100） | D11: 2024-10-07 | E11: 2.99 | F11: $/GPU-hr | G11: Lambda | H11: lambda.ai 部落格（1x $3.29／2x $3.19／4x $3.09／8x $2.99） | I11: https://lambda.ai/blog/creating-more-options-for-ai-developers-new-1x-2x-and-4x-sxm | J11: 2024-10-07 | K11: 2026-10-15 | L11: Interested-party | M11: 賣方（雲端商）自家牌價；立場為銷售方
A12: H100 SXM | B12: 隨需 | C12: Hopper（H100） | D12: 現價（頁面未標日） | E12: 3.99 | F12: $/GPU-hr | G12: Lambda | H12: lambda.ai/pricing | I12: https://lambda.ai/pricing | J12: （無） | K12: 2026-10-15 | L12: Interested-party | M12: 賣方（雲端商）自家牌價；立場為銷售方 | N12: 高於 2024-10 的 2.99
A13: H100 1-Click Cluster | B13: 預留（最短 1 週） | C13: Hopper（H100） | D13: 2024-06-03 | E13: 4.49 | F13: $/GPU-hr | G13: Lambda | H13: lambda.ai 1-Click Clusters 公告 | I13: https://lambda.ai/blog/introducing-lambda-1-click-clusters-a-new-way-to-train-large-ai-models | J13: 2024-06-03（2024-08-16 更新） | K13: 2026-10-15 | L13: Interested-party | M13: 賣方（雲端商）自家牌價；立場為銷售方
A14: H100 8 卡 HGX | B14: 隨需 | C14: Hopper（H100） | D14: 現價（頁面未標日） | E14: 6.16 | F14: $/GPU-hr | G14: CoreWeave | H14: coreweave.com/pricing（$49.24÷8）；另稱預留承諾最高折 60% | I14: https://www.coreweave.com/pricing | J14: （無） | K14: 2026-10-15 | L14: Interested-party | M14: 賣方（雲端商）自家牌價；立場為銷售方
A15: H100 | B15: 隨需 | C15: Hopper（H100） | D15: 現價（頁面頁尾 2026，圖檔 2024-12） | E15: 4.5 | F15: $/GPU-hr | G15: Nebius | H15: nebius.com/prices（可能過時）；稱大型叢集承諾折扣最高約 35% | I15: https://nebius.com/prices | J15: （無） | K15: 2026-10-15 | L15: Interested-party | M15: 賣方（雲端商）自家牌價；立場為銷售方 | N15: 頁面日期不明
A16: H100 p5.48xlarge | B16: 隨需 | C16: Hopper（H100） | D16: 2025-06 降價後現價 | E16: 6.88 | F16: $/GPU-hr | G16: AWS | H16: instances.vantage.sh（$55.04÷8）；降幅出自 AWS 部落格 | I16: https://instances.vantage.sh/aws/ec2/p5.48xlarge | J16: 2026-10-15 | K16: 2026-10-15 | L16: Derived | M16: 賣方（雲端商）自家牌價；立場為銷售方 | N16: 二手彙整站
A17: H100 p5.48xlarge | B17: 隨需（降價前） | C17: Hopper（H100） | D17: 2023-07-26 上市價（推算） | E17: 12.29 | F17: $/GPU-hr | G17: AWS | H17: 由 $55.04÷(1−0.44)÷8 推算；P5 GA 日 2023-07-26 見 AWS What's New；上市原價未直接讀到 | I17: https://aws.amazon.com/about-aws/whats-new/2023/07/amazon-ec2-p5-instances-generative-ai-hpc-generally-available/ | J17: 2023-07-26 | K17: 2026-10-15 | L17: Derived | M17: 賣方（雲端商）自家牌價；立場為銷售方 | N17: 推算值
A18: H100 p5.48xlarge | B18: 預留 3 年 | C18: Hopper（H100） | D18: 2025-06 降價後現價 | E18: 2.972 | F18: $/GPU-hr | G18: AWS | H18: instances.vantage.sh（$23.777÷8） | I18: https://instances.vantage.sh/aws/ec2/p5.48xlarge | J18: 2026-10-15 | K18: 2026-10-15 | L18: Derived | M18: 賣方（雲端商）自家牌價；立場為銷售方 | N18: 二手彙整站
A19: H100（Silicon Data 指數） | B19: 隨需（指數，超大規模雲） | C19: Hopper（H100） | D19: 2023-08～2023-12 | E19: 7.76 | F19: $/GPU-hr（中位） | G19: Silicon Data | H19: Silicon Data 部落格「H100 Rental Price Over Time」 | I19: https://www.silicondata.com/blog/h100-rental-price-over-time | J19: 2025-12-21 | K19: 2026-10-15 | L19: Interested-party | M19: 指數供應商自家文章；方法不透明、與資料來源無法獨立驗證 | N19: 區間 7.62–7.77
A20: H100（Silicon Data 指數） | B20: 隨需（指數，超大規模雲） | C20: Hopper（H100） | D20: 2025-07～2025-12 | E20: 6.26 | F20: $/GPU-hr（中位） | G20: Silicon Data | H20: 同上 | I20: https://www.silicondata.com/blog/h100-rental-price-over-time | J20: 2025-12-21 | K20: 2026-10-15 | L20: Interested-party | M20: 同上
A21: H100（Silicon Data 指數） | B21: 隨需（指數，新雲） | C21: Hopper（H100） | D21: 2024-06～2024-12 | E21: 2.99 | F21: $/GPU-hr（中位） | G21: Silicon Data | H21: 同上 | I21: https://www.silicondata.com/blog/h100-rental-price-over-time | J21: 2025-12-21 | K21: 2026-10-15 | L21: Interested-party | M21: 同上
A22: H100（Silicon Data 指數） | B22: 隨需（指數，新雲） | C22: Hopper（H100） | D22: 2025-07～2025-12 | E22: 3.33 | F22: $/GPU-hr（中位） | G22: Silicon Data | H22: 同上 | I22: https://www.silicondata.com/blog/h100-rental-price-over-time | J22: 2025-12-21 | K22: 2026-10-15 | L22: Interested-party | M22: 同上
A23: H100（Silicon Data 指數） | B23: 隨需（指數，市集） | C23: Hopper（H100） | D23: 2024-06～2024-12 | E23: 2.58 | F23: $/GPU-hr（中位） | G23: Silicon Data | H23: 同上 | I23: https://www.silicondata.com/blog/h100-rental-price-over-time | J23: 2025-12-21 | K23: 2026-10-15 | L23: Interested-party | M23: 同上
A24: H100（Silicon Data 指數） | B24: 隨需（指數，市集） | C24: Hopper（H100） | D24: 2025-07～2025-12 | E24: 1.95 | F24: $/GPU-hr（中位） | G24: Silicon Data | H24: 同上 | I24: https://www.silicondata.com/blog/h100-rental-price-over-time | J24: 2025-12-21 | K24: 2026-10-15 | L24: Interested-party | M24: 同上
A25: H100 SDH100RT 指數 | B25: 隨需（指數，新雲） | C25: Hopper（H100） | D25: 2026-10-14 | E25: 2.85 | F25: $/GPU-hr | G25: Silicon Data | H25: silicondata.com/products/silicon-index/h100 | I25: https://www.silicondata.com/products/silicon-index/h100 | J25: 2026-10-14 | K25: 2026-10-15 | L25: Interested-party | M25: 同上；同頁 FAQ 寫 2.53，頁內不一致 | N25: 頁內兩個數字不一致（2.85／2.53）
A26: B200 SXM6 8x | B26: 隨需 | C26: Blackwell（B200） | D26: 2025-08-12 | E26: 4.99 | F26: $/GPU-hr | G26: Lambda | H26: lambda.ai/blog/nvidia-b200-lambda-on-demand-cloud（頁面 2025-11-05 更新） | I26: https://lambda.ai/blog/nvidia-b200-lambda-on-demand-cloud | J26: 2025-08-12 | K26: 2026-10-15 | L26: Interested-party | M26: 賣方（雲端商）自家牌價；立場為銷售方 | N26: Lambda 的 B200 上市日；CoreWeave 在 2025-02 已上線 GB200
A27: B200 SXM6 | B27: 隨需 | C27: Blackwell（B200） | D27: 現價（頁面未標日） | E27: 6.69 | F27: $/GPU-hr | G27: Lambda | H27: lambda.ai/pricing | I27: https://lambda.ai/pricing | J27: （無） | K27: 2026-10-15 | L27: Interested-party | M27: 賣方（雲端商）自家牌價；立場為銷售方 | N27: 高於 2025-08 的 4.99；getdeploying 稱 B200 中位隨需價 12 個月 +19%
A28: B200 1-Click Cluster | B28: 預留（2 週～1 年，16／64／256+ 卡） | C28: Blackwell（B200） | D28: 現價（頁面未標日） | E28: 9.86／9.36／8.87 | F28: $/GPU-hr | G28: Lambda | H28: lambda.ai/service/gpu-cloud/1-click-clusters | I28: https://lambda.ai/service/gpu-cloud/1-click-clusters | J28: （無） | K28: 2026-10-15 | L28: Interested-party | M28: 賣方（雲端商）自家牌價；立場為銷售方
A29: B200 HGX 8 卡 | B29: 隨需 | C29: Blackwell（B200） | D29: 現價（頁面未標日） | E29: 8.6 | F29: $/GPU-hr | G29: CoreWeave | H29: coreweave.com/pricing（$68.80÷8） | I29: https://www.coreweave.com/pricing | J29: （無） | K29: 2026-10-15 | L29: Interested-party | M29: 賣方（雲端商）自家牌價；立場為銷售方
A30: B200 | B30: 隨需 | C30: Blackwell（B200） | D30: 現價（頁面日期不明） | E30: 8.5 | F30: $/GPU-hr | G30: Nebius | H30: nebius.com/prices | I30: https://nebius.com/prices | J30: （無） | K30: 2026-10-15 | L30: Interested-party | M30: 賣方（雲端商）自家牌價；立場為銷售方
A31: B200 p6-b200.48xlarge | B31: 隨需 | C31: Blackwell（B200） | D31: 現價 | E31: 14.24 | F31: $/GPU-hr | G31: AWS | H31: instances.vantage.sh（$113.933÷8） | I31: https://instances.vantage.sh/aws/ec2/p6-b200.48xlarge | J31: 2026-10-15 | K31: 2026-10-15 | L31: Derived | M31: 賣方（雲端商）自家牌價；立場為銷售方 | N31: 二手彙整站
A32: B200（多家業者中位） | B32: 隨需 | C32: Blackwell（B200） | D32: 2026-10-15 | E32: 7.94 | F32: $/GPU-hr（中位數，67 組） | G32: getdeploying.com 彙整 | H32: getdeploying.com/gpus/nvidia-b200 | I32: https://getdeploying.com/gpus/nvidia-b200 | J32: 2026-10-15 | K32: 2026-10-15 | L32: Analogy | M32: 彙整站含贊助商標示；僅作橫斷面對照 | N32: 預留中位 5.62；隨需中位 90 天 +4%、12 個月 +19%
A33: GB200 NVL72（4 GPU 單位） | B33: 隨需 | C33: GB200 | D33: 現價（頁面未標日） | E33: 10.5 | F33: $/GPU-hr | G33: CoreWeave | H33: coreweave.com/pricing（$42.00÷4）；與 SRC_PRC_001 同一牌價，勿重複計入獨立來源 | I33: https://www.coreweave.com/pricing | J33: （無） | K33: 2026-10-15 | L33: Interested-party | M33: 賣方（雲端商）自家牌價；立場為銷售方 | N33: SRC_PRC_001 經 spheron 轉述 2026-05 為同值 $42/4 GPU
A34: GB300 NVL72（4 GPU 單位） | B34: 隨需 | C34: GB300 | D34: 2026-10-14 | E34: 18 | F34: $/GPU-hr | G34: Oracle Cloud | H34: getdeploying.com 彙整 OCI 公開價（BM.GPU.GB300.42） | I34: https://getdeploying.com/gpus/nvidia-gb300 | J34: 2026-10-14 | K34: 2026-10-15 | L34: Analogy | M34: 賣方（雲端商）自家牌價；立場為銷售方 | N34: OCI 官方頁價格欄未擷取到（頁面更新 2026-08-25）；此值為二手彙整
A35: GB300（1x 配置） | B35: 隨需 | C35: GB300 | D35: 2026-10-14 | E35: 11.28 | F35: $/GPU-hr | G35: Verda | H35: getdeploying.com 彙整 | I35: https://getdeploying.com/gpus/nvidia-gb300 | J35: 2026-10-14 | K35: 2026-10-15 | L35: Analogy | M35: 賣方（雲端商）自家牌價；立場為銷售方 | N35: 標示缺貨
A36: GB300（1x 配置） | B36: 預留 24 個月 | C36: GB300 | D36: 2026-10-14 | E36: 8.46 | F36: $/GPU-hr | G36: Verda | H36: getdeploying.com 彙整 | I36: https://getdeploying.com/gpus/nvidia-gb300 | J36: 2026-10-14 | K36: 2026-10-15 | L36: Analogy | M36: 賣方（雲端商）自家牌價；立場為銷售方 | N36: 標示缺貨
A37: B300 | B37: 隨需 | C37: GB300 世代（單卡 B300） | D37: 現價（頁面日期不明） | E37: 9.5 | F37: $/GPU-hr | G37: Nebius | H37: nebius.com/prices | I37: https://nebius.com/prices | J37: （無） | K37: 2026-10-15 | L37: Interested-party | M37: 賣方（雲端商）自家牌價；立場為銷售方 | N37: B300 單卡，非 NVL72
A38: GB300 NVL72 | B38: 隨需／預留 | C38: GB300 | D38: 2026-10-14 | E38: （聯絡業務） | G38: CoreWeave、Nebius、AWS、Together AI、Gcore | H38: getdeploying.com 彙整與各家定價頁 | I38: https://getdeploying.com/gpus/nvidia-gb300 | J38: 2026-10-14 | K38: 2026-10-15 | L38: Interested-party | M38: 賣方（雲端商）自家牌價；立場為銷售方 | N38: 已搜尋，未找到公開標價
A39: VR200 NVL72 | B39: 隨需／預留 | C39: VR200 | D39: — | E39: （無） | G39: CoreWeave 2026-09-30 宣布供應，未載價格 | H39: coreweave.com/news（Cognition 首位客戶） | I39: https://www.coreweave.com/news/coreweave-delivers-nvidia-vera-rubin-nvl72-performance-at-production-scale-starting-with-cognition | J39: 2026-09-30 | K39: 2026-10-15 | L39: Interested-party | M39: 賣方（雲端商）自家牌價；立場為銷售方 | N39: 已搜尋，未找到公開價格
A40: GB300 長約（IREN—Microsoft，5 年、200 MW 關鍵 IT 負載） | B40: 長約（5 年；含 20% 預付） | C40: GB300 | D40: 2025-11-03 | E40: 9.7 | F40: $M/MW-IT/年（= $9.7B ÷ 5 年 ÷ 200 MW；Derived） | G40: IREN（賣方揭露） | H40: iren.com 公告（合約價值約 $9.7B、五年、200 MW 關鍵 IT 負載、20% 預付） | I40: https://iren.com/resources/blog/iren-signs97-billion-agreement-with-microsoft-to-deploy-ai-cloud-infrastructure | J40: 2025-11-03 | K40: 2026-10-15 | L40: Interested-party | M40: 賣方公司自行揭露；只記單價，不記合約組合、客戶細節或公司指引 | N40: 與 Excel 契約第 4 節對帳提醒 9.70 一致；公告未載 GPU 數
A41: GB300 長約（Nebius—Microsoft，5 年） | B41: 長約（5 年） | C41: GB300 | D41: 2025-09-09 | E41: （無法換算） | G41: Nebius（賣方揭露） | H41: DCD 轉述（合約 $17.4B，至多 $19.4B；公告未載 MW 與 GPU 數） | I41: https://datacenterdynamics.com/en/news/microsoft-to-use-nebius-gpu-data-centers-in-deal-worth-174bn-over-five-years | J41: 2025-09-09 | K41: 2026-10-15 | L41: Interested-party | M41: 賣方揭露；二手轉述 | N41: 缺 MW／GPU 數，無法換算單價；不列入實算
...

Sheet E338-E341確認
A1: E338–E341 一手確認與年變化率重算
A3: 證據 | B3: 項目 | C3: E338–E341 原值 | D3: 一手來源與讀到的值 | E3: 文件日期 | F3: 判定 | G3: URL
A4: E338 | B4: GPT-4 | C4: 30/60（2023-03） | D4: $0.03/$0.06 每 1K | E4: 2023-03-14 | F4: 一致 | G4: https://openai.com/index/gpt-4-research/
A5: E338 | B5: GPT-4 Turbo | C5: 10/30（2023-11） | D5: $0.01/$0.03 每 1K | E5: 2023-11-06 | F5: 一致 | G5: https://openai.com/index/new-models-and-developer-products-announced-at-devday/
A6: E338 | B6: GPT-4o | C6: 5/15（2024-05） | D6: OpenAI 官方社群公告 $5/$15（本站頁無絕對價） | E6: 2024-05-13 | F6: 一致（來源為官方社群公告） | G6: https://community.openai.com/t/announcing-gpt-4o-in-the-api/744700
A7: E338 | B7: GPT-4o-0806 | C7: 2.5/10 | D7: $2.50/$10.00 | E7: 2024-08-06 | F7: 一致 | G7: https://openai.com/index/introducing-structured-outputs-in-the-api/
A8: E338 | B8: GPT-4.1 | C8: 2/8（2025-04） | D8: $2.00/$8.00 | E8: 2025-04-14 | F8: 一致 | G8: https://openai.com/index/gpt-4-1/
A9: E338 | B9: GPT-5 | C9: 1.25/10（2025-08） | D9: $1.25/$10.00 | E9: 2025-08-07 | F9: 一致 | G9: https://openai.com/index/introducing-gpt-5-for-developers/
A10: E338 | B10: GPT-5.2 | C10: 1.75/14（2025-12） | D10: $1.75/$14 | E10: 2025-12-11 | F10: 一致 | G10: https://openai.com/index/introducing-gpt-5-2/
A11: E338 | B11: GPT-5.4 | C11: 2.5/15（2026-03） | D11: $2.50/$15 | E11: 2026-03-05 | F11: 一致 | G11: https://openai.com/index/introducing-gpt-5-4/
A12: E338 | B12: GPT-5.6 Terra | C12: 2/12（2026-07） | D12: 上市價 $2.50/$15（2026-07-09）；2026-07-30 降 20% → 2/12 | E12: 2026-07-09／07-30 | F12: 不一致（時點）：2/12 是降價後價；上市價 2.5/15 | G12: https://openai.com/index/gpt-5-6/
A13: E338 | B13: GPT-6 Sol | C13: 2/10（2026-09） | D13: $2/$10；changelog 2026-09-22 上市 | E13: 2026-09-22 | F13: 一致（SRC_PRC_006–008 記 09-25，差 3 天） | G13: https://openai.com/index/introducing-gpt-6-sol-and-luna/
A14: E338 | B14: GPT-6.1 Sol | C14: 2/10、快取 0.10（2026-09-29） | D14: changelog：2026-09-29「$2 input, $0.10 cached input, $2.50 cache write, $10 output」 | E14: 2026-09-29 | F14: 一致 | G14: https://developers.openai.com/api/docs/changelog
... A23: E341 | B23: 迴歸結果 | C23: 見下表 | D23: 無法由 E338–E340 復現（原始取點與腳本未留存）；重算見下表 | E23: — | F23: 不可復現 | G23: —
A26: E341 重算：對數線性迴歸，年變化率＝EXP(SLOPE(LN(混合價),年))−1；取點＝上市日；混合價＝w×輸入＋(1−w)×輸出
A27: w（8:1，對應參考請求 ISL 16,384／OSL 2,048） | E27: =8/9 -> 0.88888889
A28: w（3:1） | E28: =3/4 -> 0.75
A30: OpenAI 中階（E338 原序列）
A31: 日期 | B31: 輸入 | C31: 輸出 | D31: 年(小數) | E31: LN(8:1) | F31: LN(3:1)
A32: 2023-03-14 | B32: 30 | C32: 60 | D32: =DATE(2023,3,14)/365.25 -> 123.20055 | E32: =LN($E$27*B32+(1-$E$27)*C32) -> 3.5065579 | F32: =LN($E$28*B32+(1-$E$28)*C32) -> 3.6243409
A33: 2023-11-06 | B33: 10 | C33: 30 | D33: =DATE(2023,11,6)/365.25 -> 123.84942 | E33: =LN($E$27*B33+(1-$E$27)*C33) -> 2.5032558 | F33: =LN($E$28*B33+(1-$E$28)*C33) -> 2.7080502
A34: 2024-05-13 | B34: 5 | C34: 15 | D34: =DATE(2024,5,13)/365.25 -> 124.36687 | E34: =LN($E$27*B34+(1-$E$27)*C34) -> 1.8101086 | F34: =LN($E$28*B34+(1-$E$28)*C34) -> 2.014903
A35: 2024-08-06 | B35: 2.5 | C35: 10 | D35: =DATE(2024,8,6)/365.25 -> 124.59959 | E35: =LN($E$27*B35+(1-$E$27)*C35) -> 1.2039728 | F35: =LN($E$28*B35+(1-$E$28)*C35) -> 1.4759065
A36: 2025-04-14 | B36: 2 | C36: 8 | D36: =DATE(2025,4,14)/365.25 -> 125.28679 | E36: =LN($E$27*B36+(1-$E$27)*C36) -> 0.98082925 | F36: =LN($E$28*B36+(1-$E$28)*C36) -> 1.252763
A37: 2025-08-07 | B37: 1.25 | C37: 10 | D37: =DATE(2025,8,7)/365.25 -> 125.60164 | E37: =LN($E$27*B37+(1-$E$27)*C37) -> 0.7985077 | F37: =LN($E$28*B37+(1-$E$28)*C37) -> 1.2347445
A38: 2025-12-11 | B38: 1.75 | C38: 14 | D38: =DATE(2025,12,11)/365.25 -> 125.94661 | E38: =LN($E$27*B38+(1-$E$27)*C38) -> 1.1349799 | F38: =LN($E$28*B38+(1-$E$28)*C38) -> 1.5712167
A39: 2026-03-05 | B39: 2.5 | C39: 15 | D39: =DATE(2026,3,5)/365.25 -> 126.17659 | E39: =LN($E$27*B39+(1-$E$27)*C39) -> 1.3581235 | F39: =LN($E$28*B39+(1-$E$28)*C39) -> 1.7272209
A40: 2026-07-09 | B40: 2 | C40: 12 | D40: =DATE(2026,7,9)/365.25 -> 126.52156 | E40: =LN($E$27*B40+(1-$E$27)*C40) -> 1.1349799 | F40: =LN($E$28*B40+(1-$E$28)*C40) -> 1.5040774
A41: 2026-09-22 | B41: 2 | C41: 10 | D41: =DATE(2026,9,22)/365.25 -> 126.7269 | E41: =LN($E$27*B41+(1-$E$27)*C41) -> 1.060872 | F41: =LN($E$28*B41+(1-$E$28)*C41) -> 1.3862944
A42: 2026-09-29 | B42: 2 | C42: 10 | D42: =DATE(2026,9,29)/365.25 -> 126.74606 | E42: =LN($E$27*B42+(1-$E$27)*C42) -> 1.060872 | F42: =LN($E$28*B42+(1-$E$28)*C42) -> 1.3862944
A43: 窗口 | B43: 點數 | E43: 年變化 8:1 | F43: 年變化 3:1
A44: 2023–2026.8 | B44: 9 | E44: =EXP(SLOPE(E32:E40,D32:D40))-1 -> -0.47560281 | F44: =EXP(SLOPE(F32:F40,D32:D40))-1 -> -0.42691259
A45: 2024.3–2026.8 | B45: 7 | E45: =EXP(SLOPE(E34:E40,D34:D40))-1 -> -0.16130096 | F45: =EXP(SLOPE(F34:F40,D34:D40))-1 -> -0.085989065
A46: 2025–2026.8 | B46: 5 | E46: =EXP(SLOPE(E36:E40,D36:D40))-1 -> 0.32036784 | F46: =EXP(SLOPE(F36:F40,D36:D40))-1 -> 0.38201928
A47: 2024.3–2026.10 | B47: 9 | E47: =EXP(SLOPE(E34:E42,D34:D42))-1 -> -0.1415667 | F47: =EXP(SLOPE(F34:F42,D34:D42))-1 -> -0.097942072
A49: OpenAI 中階（確認序列：Terra 取上市價 2.5/15）
A50: 日期 | B50: 輸入 | C50: 輸出 | D50: 年(小數) | E50: LN(8:1) | F50: LN(3:1)
A51: 2023-03-14 | B51: 30 | C51: 60 | D51: =DATE(2023,3,14)/365.25 -> 123.20055 | E51: =LN($E$27*B51+(1-$E$27)*C51) -> 3.5065579 | F51: =LN($E$28*B51+(1-$E$28)*C51) -> 3.6243409
A52: 2023-11-06 | B52: 10 | C52: 30 | D52: =DATE(2023,11,6)/365.25 -> 123.84942 | E52: =LN($E$27*B52+(1-$E$27)*C52) -> 2.5032558 | F52: =LN($E$28*B52+(1-$E$28)*C52) -> 2.7080502
A53: 2024-05-13 | B53: 5 | C53: 15 | D53: =DATE(2024,5,13)/365.25 -> 124.36687 | E53: =LN($E$27*B53+(1-$E$27)*C53) -> 1.8101086 | F53: =LN($E$28*B53+(1-$E$28)*C53) -> 2.014903
...

Sheet 上市間隔
A1: 世代上市間隔（步驟 4）：發表會日期與「量產出貨／雲端開始供應」日期分開記
A3: 世代 | B3: 事件 | C3: 日期 | D3: 事件類型 | E3: 來源 | F3: URL | G3: 標記 | H3: 備註
A4: Hopper H100 | B4: GTC 發表 | C4: 44642 | D4: 發表會 | E4: （常識；本次未取一手頁） | F4: — | G4: 未驗證 | H4: 未逐筆取一手頁
A5: Hopper H100 | B5: NVIDIA 宣布 H100 全面量產 | C5: 44824 | D5: 量產 | E5: NVIDIA 新聞稿「Hopper in Full Production」 | F5: https://nvidianews.nvidia.com/news/nvidia-hopper-in-full-production | G5: Interested-party | H5: 系統預計 2022-10 起出貨
A6: Hopper H100 | B6: CoreWeave、Cirrascale 雲端 GA | C6: 45006 | D6: 雲端開始供應（基準） | E6: NVIDIA 新聞稿「Hopper GPUs Expand Reach」 | F6: https://nvidianews.nvidia.com/news/nvidia-hopper-gpus-expand-reach-as-demand-for-ai-grows | G6: Interested-party | H6: 同稿：OCI 限量、AWS 與 Azure 預覽
A7: Hopper H100 | B7: Lambda H100 隨需上線 | C7: 45056 | D7: 雲端開始供應 | E7: Lambda 部落格 | F7: https://lambda.ai/blog/lambda-cloud-deploys-nvidia-h100-tensor-core-gpus | G7: Interested-party
A8: Hopper H100 | B8: AWS P5 GA | C8: 45133 | D8: 雲端開始供應（超大規模雲） | E8: AWS What's New | F8: https://aws.amazon.com/about-aws/whats-new/2023/07/amazon-ec2-p5-instances-generative-ai-hpc-generally-available/ | G8: Interested-party
A9: GB200 NVL72 | B9: GTC 發表 | C9: 45369 | D9: 發表會 | E9: （常識；本次未取一手頁） | F9: — | G9: 未驗證
A10: GB200 NVL72 | B10: NVIDIA：Blackwell「in full production」 | C10: 45616 | D10: 量產 | E10: NVIDIA 第三季 FY2025 財報新聞稿 | F10: https://nvidianews.nvidia.com/news/nvidia-announces-financial-results-for-third-quarter-fiscal-2025 | G10: Interested-party | H10: 未載出貨起日
A11: GB200 NVL72 | B11: CoreWeave GB200 NVL72 GA（首家） | C11: 45692 | D11: 雲端開始供應（基準） | E11: NVIDIA 部落格 | F11: https://blogs.nvidia.com/blog/blackwell-coreweave-gb200-nvl72-instances-cloud/ | G11: Interested-party | H11: CoreWeave 文件稱 2025-02-03 實例上線
A12: GB300 NVL72 | B12: GTC 發表 | C12: 45734 | D12: 發表會 | E12: （常識；本次未取一手頁） | F12: — | G12: 未驗證
A13: GB300 NVL72 | B13: CoreWeave 首家部署 GB300 NVL72（Dell 出貨） | C13: 45841 | D13: 出貨／部署（基準） | E13: CoreWeave 新聞稿 | F13: https://www.coreweave.com/news/coreweave-becomes-first-cloud-provider-to-deploy-nvidia-gb300-nvl72-platform | G13: Interested-party
A14: GB300 NVL72 | B14: CoreWeave GB300 實例上線 | C14: 45888 | D14: 雲端開始供應（替代） | E14: CoreWeave 文件標題（搜尋結果標題，未開頁） | F14: https://docs.coreweave.com/release-notes/gb300-nvl72 | G14: Interested-party | H14: 僅見搜尋結果標題
A15: VR200 NVL72 | B15: NVIDIA：Rubin「in full production」 | C15: 46027 | D15: 量產 | E15: NVIDIA CES 新聞稿 | F15: https://nvidianews.nvidia.com/news/rubin-platform-ai-supercomputer | G15: Interested-party | H15: 合作夥伴 2026 下半年供應
A16: VR200 NVL72 | B16: CoreWeave 宣布 VR NVL72 供應，首位客戶 Cognition 正式上線 | C16: 46295 | D16: 雲端開始供應（基準） | E16: CoreWeave 新聞稿 | F16: https://www.coreweave.com/news/coreweave-delivers-nvidia-vera-rubin-nvl72-performance-at-production-scale-starting-with-cognition | G16: Interested-party | H16: 頁面未稱 GA；Cognition 叢集 2026-09 初建置
A19: 相鄰世代間隔（年）
A20: 世代對 | B20: 基準（雲端開始供應→雲端開始供應） | C20: 低 | D20: 高 | E20: 基準天數 | F20: 低天數 | G20: 高天數 | H20: 說明
A21: Hopper→GB200 | B21: =E21/365.25 -> 1.8781656 | C21: =MIN(F21,G21)/365.25 -> 1.8781656 | D21: =MAX(F21,G21)/365.25 -> 2.1683778 | E21: =C11-C6 -> 686 | F21: =C11-C6 -> 686 | G21: =C10-C5 -> 792 | H21: 低＝雲端對雲端；高＝量產宣布對量產宣布（2022-09-20→2024-11-20）
A22: GB200→GB300 | B22: =E22/365.25 -> 0.40793977 | C22: =MIN(F22,G22)/365.25 -> 0.40793977 | D22: =MAX(F22,G22)/365.25 -> 0.53661875 | E22: =C13-C11 -> 149 | F22: =C13-C11 -> 149 | G22: =C14-C11 -> 196 | H22: 低＝GB200 雲端 GA→GB300 首家部署；高＝→GB300 實例上線（2025-08-19）
A23: GB300→VR200 | B23: =E23/365.25 -> 1.1786448 | C23: =MIN(F23,G23)/365.25 -> 1.1143053 | D23: =MAX(F23,G23)/365.25 -> 1.2429843 | E23: =AVERAGE(F23,G23) -> 430.5 | F23: =C16-C14 -> 407 | G23: =C16-C13 -> 454 | H23: 低＝GB300 實例上線→VR200 首位客戶上線；高＝GB300 首家部署→VR200（基準取中點）
A25: 發表會對發表會（參考，不作基準）：Hopper→Blackwell 2022-03-22→2024-03-18＝約 2.0 年；Blackwell→Blackwell Ultra 2024-03-18→2025-03-18＝1.0 年；發表會日期未逐筆取一手頁。
A26: 標記：區間為 Analogy（三對世代各 1 個樣本，無統計意義）；日期本身為 Interested-party（業者新聞稿）。

Sheet 對照計算
A1: 步驟 5 實算對照：世代每 MW 收入指數（上市對上市）與回本餘裕
A2: q、持有成本、每 MW GPU 數取自 model/20261014_Tokenomics_v5.35.xlsx（括號為原格）；Δ 取自「上市間隔」頁；藍字為人工輸入價格
A4: A. 輸入（Excel v5.35） | B4: Hopper→GB200 | C4: GB200→GB300 | D4: GB300→VR200 | G4: 來源格
A5: q 基準（新世代÷舊世代 每 MW 總產出，Sol） | B5: 4.8451987 | C5: 1.455876 | D5: 1.5652852 | G5: L1!D58、D59、D60
A6: q 低（VR200 為 Sens_Perf η_d×0.5） | B6: 4.8451987 | C6: 1.455876 | D6: 0.91533489 | G6: L1!E58、E59、E60
A7: q 高（VR200 為 η_d×1.5） | B7: 4.8451987 | C7: 1.455876 | D7: 2.0506532 | G7: L1!F58、F59、F60
A8: 每 MW 年持有成本 舊世代 $M/MW/年 | B8: 9.7030873 | C8: 8.8281656 | D8: 10.886411 | G8: L1!D54、D55、D56（L1_HoldEconMW_*）
A9: 每 MW 年持有成本 新世代 $M/MW/年 | B9: 8.8281656 | C9: 10.886411 | D9: 12.225471 | G9: L1!D55、D56、D57
A10: 持有成本比（新÷舊） | B10: =B9/B8 -> 0.90983058 | C10: =C9/C8 -> 1.2331453 | D10: =D9/D8 -> 1.1230029 | G10: 公式
A11: 每 MW GPU 數 舊世代（顆） | B11: 718.048 | C11: 501.768 | D11: 487.008 | G11: Interface!D7、G7、J7（每 GW GPU 數基準欄）÷1000
A12: 每 MW GPU 數 新世代（顆） | B12: 501.768 | C12: 487.008 | D12: 291.744 | G12: Interface!G7、J7、M7 ÷1000
A13: Δ 基準（年；「上市間隔」頁） | B13: =上市間隔!B21 -> 1.8781656 | C13: =上市間隔!B22 -> 0.40793977 | D13: =上市間隔!B23 -> 1.1786448
A14: Δ 低（年） | B14: =上市間隔!C21 -> 1.8781656 | C14: =上市間隔!C22 -> 0.40793977 | D14: =上市間隔!C23 -> 1.1143053
A15: Δ 高（年） | B15: =上市間隔!D21 -> 2.1683778 | C15: =上市間隔!D22 -> 0.53661875 | D15: =上市間隔!D23 -> 1.2429843
A17: B. 兩個門檻（年價格變化率 g；價格每年變化 g，持續 Δ 年） | B17: Hopper→GB200 | C17: GB200→GB300 | D17: GB300→VR200 | G17: 公式
A18: g*（收入指數＝1）：Δ 基準、q 基準 | B18: =B5^(-1/B13)-1 -> -0.56836512 | C18: =C5^(-1/C13)-1 -> -0.60177706 | D18: =D5^(-1/D13)-1 -> -0.31624479 | G18: q×(1+g)^Δ＝1 → g＝q^(−1/Δ)−1；實際年價格變化率高於此值，世代每 MW 收入指數＞1
A19: g*（收入指數＝1）：Δ 低 | B19: =B5^(-1/B14)-1 -> -0.56836512 | C19: =C5^(-1/C14)-1 -> -0.60177706 | D19: =D5^(-1/D14)-1 -> -0.3310897
A20: g*（收入指數＝1）：Δ 高 | B20: =B5^(-1/B15)-1 -> -0.51699464 | C20: =C5^(-1/C15)-1 -> -0.50339125 | D20: =D5^(-1/D15)-1 -> -0.30265685
A21: g*（回本餘裕＝1）：Δ 基準、q 基準 | B21: =(B10/B5)^(1/B13)-1 -> -0.58954485 | C21: =(C10/C5)^(1/C13)-1 -> -0.33436925 | D21: =(D10/D5)^(1/D13)-1 -> -0.24552406 | G21: q×(1+g)^Δ÷成本比＝1 → g＝(成本比÷q)^(1/Δ)−1；高於此值，回本餘裕＞1
A22: g*（回本餘裕＝1）：Δ 低 | B22: =(B10/B5)^(1/B14)-1 -> -0.58954485 | C22: =(C10/C5)^(1/C14)-1 -> -0.33436925 | D22: =(D10/D5)^(1/D14)-1 -> -0.25769789
A23: g*（回本餘裕＝1）：Δ 高 | B23: =(B10/B5)^(1/B15)-1 -> -0.53759172 | C23: =(C10/C5)^(1/C15)-1 -> -0.26612636 | D23: =(D10/D5)^(1/D15)-1 -> -0.23444089
A24: g*（收入指數＝1）：q 低、Δ 基準（VR200 區間低端） | B24: =B6^(-1/B13)-1 -> -0.56836512 | C24: =C6^(-1/C13)-1 -> -0.60177706 | D24: =D6^(-1/D13)-1 -> 0.077945355
A25: g*（收入指數＝1）：q 高、Δ 基準 | B25: =B7^(-1/B13)-1 -> -0.56836512 | C25: =C7^(-1/C13)-1 -> -0.60177706 | D25: =D7^(-1/D13)-1 -> -0.45627332
A27: C. 推算值 q×(1+g)^Δ（Δ 基準） | B27: Hopper→GB200 | C27: GB200→GB300 | D27: GB300→VR200 | G27: 說明
A28: 收入指數：g＝−25% | B28: =B$5*(1+(-0.25))^B$13 -> 2.822643 | C28: =C$5*(1+(-0.25))^C$13 -> 1.2946635 | D28: =D$5*(1+(-0.25))^D$13 -> 1.1151546 | G28: 與 Cap_In I-1 的 g 基準／區間（−0.10；−0.25～+0.05）並列
A29: 收入指數：g＝−10% | B29: =B$5*(1+(-0.1))^B$13 -> 3.975314 | C29: =C$5*(1+(-0.1))^C$13 -> 1.3946271 | D29: =D$5*(1+(-0.1))^D$13 -> 1.3824889
A30: 收入指數：g＝+5% | B30: =B$5*(1+(0.05))^B$13 -> 5.3101722 | C30: =C$5*(1+(0.05))^C$13 -> 1.4851433 | D30: =D$5*(1+(0.05))^D$13 -> 1.6579374
A31: 回本餘裕（指數÷成本比）：g＝−25% | B31: =B28/B$10 -> 3.102383 | C31: =C28/C$10 -> 1.0498872 | D31: =D28/D$10 -> 0.99301138
A32: 回本餘裕（指數÷成本比）：g＝−10% | B32: =B29/B$10 -> 4.3692904 | C32: =C29/C$10 -> 1.1309511 | D32: =D29/D$10 -> 1.2310644
A33: 回本餘裕（指數÷成本比）：g＝+5% | B33: =B30/B$10 -> 5.8364406 | C33: =C30/C$10 -> 1.2043538 | D33: =D30/D$10 -> 1.476343
A35: D. 實證價格 → 上市對上市因子與指數 | B35: Hopper→GB200 | C35: GB200→GB300 | D35: GB300→VR200 | G35: 價格點與備註
A36: 混合權重 w（輸入占比；0.75＝3:1，8/9＝8:1） | B36: 0.75
A37: b1 OpenAI 中階牌價（GPT-4 → 4o-0806 → 4.1 → 6.1 Sol） | G37: 時點：2023-03-21 最新＝GPT-4（當時為旗艦）；2025-02-04＝GPT-4o-0806；2025-07-03＝GPT-4.1；2026-09-30＝GPT-6.1 Sol。第一對的「中階」其實是旗艦；層級口徑不連續。
A38: 舊世代時點混合價 $/M | B38: =$B$36*30+(1-$B$36)*60 -> 37.5 | C38: =$B$36*2.5+(1-$B$36)*10 -> 4.375 | D38: =$B$36*2+(1-$B$36)*8 -> 3.5
A39: 新世代時點混合價 $/M | B39: =$B$36*2.5+(1-$B$36)*10 -> 4.375 | C39: =$B$36*2+(1-$B$36)*8 -> 3.5 | D39: =$B$36*2+(1-$B$36)*10 -> 4
A40: 價格因子（新÷舊） | B40: =B39/B38 -> 0.11666667 | C40: =C39/C38 -> 0.8 | D40: =D39/D38 -> 1.1428571
A41: 收入指數＝q×因子 | B41: =B$5*B40 -> 0.56527318 | C41: =C$5*C40 -> 1.1647008 | D41: =D$5*D40 -> 1.7888974
A42: 年化價格變化率 | B42: =B40^(1/B$13)-1 -> -0.68142597 | C42: =C40^(1/C$13)-1 -> -0.42131745 | D42: =D40^(1/D$13)-1 -> 0.11995926
A43: 回本餘裕＝指數÷成本比 | B43: =B41/B$10 -> 0.62129498 | C43: =C41/C$10 -> 0.944496 | D43: =D41/D$10 -> 1.5929589
A44: 收入指數＝1 門檻：實證在門檻哪一側 | B44: =IF(B42>=B$18,"高於門檻（指數≥1）","低於門檻（指數<1）") -> 低於門檻（指數<1） | C44: =IF(C42>=C$18,"高於門檻（指數≥1）","低於門檻（指數<1）") -> 高於門檻（指數≥1） | D44: =IF(D42>=D$18,"高於門檻（指數≥1）","低於門檻（指數<1）") -> 高於門檻（指數≥1）
...
