Workbook

Sheet 說明
A1: Tokenomics Stage 0 審閱檔（chat 端）
A3: 日期 | B3: 2026-10-02
A4: 基準 | B4: 20261002_Tokenomics_v5.10.xlsx（master；唯讀，未修改）
A5: 用途 | B5: Stage 0 第 2 步：拆解 Sources 61 筆為候選 SRC 數值紀錄、判定等級與立場；複核藍字 324 列分類，判定「待分類」。供 Gate 0 核准。
A6: 與 CC 第 10 輪的關係 | B6: INV_ID 編號規則與 CC 指令相同（工作表順序＋列號），CC 盤點檔回來後可逐列合併；CC 提供的敏感度排序屬另一份資料，本檔未含。
A7: 請 Andy 看的地方 | B7: 「Gate0_決策」黃底欄：6 項標「待 Andy」（G0-2、3、4、6、7、8）。其餘頁為依據，可抽看。
A8: 閱讀順序 | B8: Gate0_決策 → 發現 → 盤點複核（篩選「Gate 0 爭議＝是」）→ SRC_候選 → Sources_拆解 → 格對照
A9: 涵蓋範圍（限制） | B9: Assumed、Analogy、Decision、情境選擇共約 180 列只做規則檢查，未逐列判讀；原始、待分類、Derived、多標記與相關列（共 126 列）逐列判讀。SRC 候選紀錄的數值取自 Sources 文字與模型格，未重新查核原文。
A11: 統計（公式，連動各頁）
A12: SRC 候選紀錄數 | B12: =COUNTA(SRC_候選!A2:A243) -> 242
A13: 其中 Active | B13: =COUNTIF(SRC_候選!P2:P243,"Active") -> 233
A14: 其中 Alt | B14: =COUNTIF(SRC_候選!P2:P243,"Alt") -> 8
A15: 其中 Superseded | B15: =COUNTIF(SRC_候選!P2:P243,"Superseded") -> 1
A16: 來源等級 1 | B16: =COUNTIF(SRC_候選!L2:L243,1) -> 65
A17: 來源等級 2 | B17: =COUNTIF(SRC_候選!L2:L243,2) -> 78
A18: 來源等級 3 | B18: =COUNTIF(SRC_候選!L2:L243,3) -> 99
A19: 立場：利害關係方 | B19: =COUNTIF(SRC_候選!M2:M243,"利害關係方") -> 189
A20: 立場：中立 | B20: =COUNTIF(SRC_候選!M2:M243,"中立") -> 53
A21: 模型使用中的紀錄（含對照） | B21: =COUNTIF(SRC_候選!R2:R243,"<>未使用") -> 199
A22: 直接引用且數值一致的紀錄 | B22: =COUNTIF(SRC_候選!R2:R243,"一致") -> 145
A23: 直接引用但數值不一致的紀錄（應為 0） | B23: =COUNTIF(SRC_候選!R2:R243,"不一致") -> 0
A24: 藍字列總數 | B24: =COUNTA(盤點複核!A2:A325) -> 324
A25: chat 分類與 CC 規則不同的列 | B25: =COUNTIF(盤點複核!N2:N325,"否") -> 128
A26: Gate 0 爭議列 | B26: =COUNTIF(盤點複核!T2:T325,"是") -> 21
A27: 可直接連結 SRC 的藍字格（Stage 1 改連結、數值不變） | B27: =SUM(盤點複核!Q2:Q325) -> 177
A28: 與 SRC 相關但值不相等的藍字格（換算／取整／選取） | B28: =SUM(盤點複核!R2:R325) -> 38
A30: chat 複核分類（列數）
A31: 原始數據→SRC | B31: =COUNTIF(盤點複核!M2:M325,"原始數據→SRC") -> 38
A32: 混合（逐格） | B32: =COUNTIF(盤點複核!M2:M325,"混合（逐格）") -> 45
A33: Derived→改公式 | B33: =COUNTIF(盤點複核!M2:M325,"Derived→改公式") -> 10
A34: Analogy | B34: =COUNTIF(盤點複核!M2:M325,"Analogy") -> 36
A35: Assumed | B35: =COUNTIF(盤點複核!M2:M325,"Assumed") -> 96
A36: Decision | B36: =COUNTIF(盤點複核!M2:M325,"Decision") -> 18
A37: 情境選擇 | B37: =COUNTIF(盤點複核!M2:M325,"情境選擇") -> 13
A38: 情境值 | B38: =COUNTIF(盤點複核!M2:M325,"情境值") -> 29
A39: Tech_Registry 登錄 | B39: =COUNTIF(盤點複核!M2:M325,"Tech_Registry 登錄") -> 8
A40: Checks→L1 對照 | B40: =COUNTIF(盤點複核!M2:M325,"Checks→L1 對照") -> 11
A41: Evidence（不遷移） | B41: =COUNTIF(盤點複核!M2:M325,"Evidence（不遷移）") -> 20
A42: 合計 | B42: =SUM(B31:B41) -> 324
A44: SRC 分頁（紀錄數）
...

Sheet Gate0_決策
A1: 編號 | B1: 議題 | C1: 建議 | D1: 理由與影響 | E1: 性質 | F1: 狀態 | G1: Andy 決定
A2: G0-1 | B2: 遷移粒度 | C2: 逐格遷移（不是逐列） | D2: F01、F02：71 列原始或混合列中，大量列內各格來源不同（見說明頁統計）。 | E2: 工程類：chat 直接定案 | F2: 已定
A3: G0-2 | B3: Stage 1 數值不變與「值不等於來源」的格 | C3: 模型格值等於 SRC 值者改連結；取整、區間中點、選取值、改公式會變值者，Stage 1 保留藍字並補標記（Analogy／Decision）與 SRC_ID；Stage 2 再逐筆決定是否改連結（改值即升次版） | D3: Gate 1 要求逐格一致；強行連結會讓 VR200 價格高值 9.1→9.09、服務占比 0.41→0.4118 等變動，混入遷移版本後無法區分「遷移」與「改值」。 | E3: 判斷類：請 Andy 核准 | F3: 待 Andy
A4: G0-3 | B4: J3 Sol SLO 65 對來源 68 | C4: Stage 1 維持 65（Decision）；Stage 2 重讀 Artificial Analysis 頁後由 Andy 決定是否改 68 | D4: 差異 4.6%；SLO 是 Block 2 每 GW 產出的主要驅動之一，改值會連動下游。 | E4: 判斷類 | F4: 待 Andy
A5: G0-4 | B5: 能力指數版本 | C5: 建議統一用 v4.3.2（較新）；Stage 2 重抓 v4.3 的七個值。統一前，K2 前緣判定附註「版本混用」 | D5: F08；G4 只比同口徑。 | E5: 判斷類 | F5: 待 Andy
A6: G0-5 | B6: 公式內嵌原始數據納入 Stage 1 範圍 | C6: 納入；CC 第 11 輪加一項「公式內數值常數掃描」（排除單位換算常數），清單由 chat 端判定 | D6: F03；不納入則 Gate 1「寫死 0 格」只對藍字成立。 | E6: 工程類：chat 直接定案 | F6: 已定
A7: G0-6 | B7: Tech_Registry 採用數 | C7: T10 的公開採用實驗室數改由 SRC_Model 採用紀錄計數（已建 4 筆）；T01–T05 等待 Stage 2 補採用紀錄後再改 | D7: J14 的主流判定依「至少兩家公開採用」，計數改為公式後，新增一筆採用紀錄即可自動更新判定。 | E7: 判斷類（改變 J14 的維護方式） | F7: 待 Andy
A8: G0-7 | B8: 來源等級對應規則 | C8: 1＝一手且已讀原文；2＝二手且已讀，或一手文件轉載；3＝模型內建知識、只見搜尋摘錄、或查核狀態為「待查核」 | D8: 「待查核」無法確認讀過全文，從嚴歸 3。結果見說明頁：多數 Block 1 硬體數據為 3 級，Stage 2 查核量會比交接文件估計的多。 | E8: 判斷類（G3 的細則） | F8: 待 Andy
A9: G0-8 | B9: 同指標的多家分析師估計（S9：MS 7.8 對 Bernstein 9.09） | C9: 不套用 G4「日期較新者勝」：不同分析師的獨立估計屬並列（Alt），基準值由 Decision 選取並記決策 ID；低／高沿用各家估計 | D9: G4 的比較規則是為「同一事實的多個報導」設計；照字面套用，Bernstein（2026-06）會取代 MS（2026-05），VR200 機架價格基準上升 16.5%，每 GW 資本支出連動上升。 | E9: 判斷類（G4 的例外） | F9: 待 Andy
A10: G0-9 | B10: 不遷入 Source 的 Sources 條目 | C10: S14（PUE，v4 假設）、S34（AMD 定性提醒）、S43（verl 定性設定）不遷入；S14 對應的 PUE 維持 Analogy，Stage 2 另找來源 | D10: G1：Source 只存已取得的原始訊息。 | E10: 依 G1 直接定案 | F10: 已定
A11: G0-10 | B11: 未登錄來源 | C11: 以 U-NV、U-PR、U-DS 新增 3 級候選紀錄（F06） | D11: G2：所有用到的數據都要有 Source；不新增則 Gate 1「每筆 Active SRC 有 Evidence ID」以外，這些格會變成無來源的原始數據。 | E11: 依 G2 直接定案 | F11: 已定

Sheet SRC_候選
A1: SRC_ID（候選） | B1: 分頁 | C1: 原 S 編號 | D1: 指標 | E1: 數值 | F1: 低 | G1: 高 | H1: 單位 | I1: 口徑 | J1: 適用對象 | K1: 日期 | L1: 來源等級 | M1: 立場 | N1: 立場說明（哪一方、誘因） | O1: 一手／二手 | P1: 狀態 | Q1: 模型使用位置（格｜關係） | R1: 與模型格一致性 | S1: 備註
A2: SRC_HW_001 | B2: SRC_HW | C2: S1 | D2: DGX H100 最大系統功率 | E2: 10.2 | H2: kW／8 GPU | I2: 系統最大功率 | J2: Hopper H100（DGX） | K2: 2023 | L2: 3 | M2: 利害關係方 | N2: NVIDIA：產品規格 | O2: 一手（未讀） | P2: Active | Q2: Spec_Rack!C9｜取整 | R2: — | S2: ×4 台＝40.8 kW，模型取 41
A3: SRC_HW_002 | B3: SRC_HW | C3: S2 | D3: HGX H100 單 GPU 價格 | E3: 30000 | H3: $/GPU | I3: 取得價 | J3: Hopper H100 | K3: 2026 | L3: 3 | M3: 利害關係方 | N3: clusterbid：硬體交易平台，報價有成交誘因；低品質 | O3: 二手 | P3: Active | R3: 未使用
A4: SRC_HW_003 | B4: SRC_HW | C4: S2 | D4: HGX H100 8 GPU 伺服器價格 | F4: 220000 | G4: 320000 | H4: $/台 | I4: 取得價區間 | J4: Hopper H100 | K4: 2026 | L4: 3 | M4: 利害關係方 | N4: clusterbid：硬體交易平台，報價有成交誘因；低品質 | O4: 二手 | P4: Active | Q4: Spec_Rack!C11｜取整；Spec_Rack!C13｜取整 | R4: — | S4: ×4 台＝0.88–1.28 $M；模型 0.9／1.1／1.3
A5: SRC_HW_004 | B5: SRC_HW | C5: S3 | D5: GB200 NVL72 機架功率 | F5: 120 | G5: 130 | H5: kW/架 | I5: 未明（設計或最大） | J5: GB200 NVL72 | K5: 2026-06 | L5: 3 | M5: 利害關係方 | N5: moduledge、hashrateindex：零組件／挖礦業者 | O5: 二手 | P5: Active | Q5: Spec_Rack!D8｜直接；Spec_Rack!D9｜選取 | R5: 一致 | S5: 模型高值 140 無對應來源（v4＝139）
A6: SRC_HW_005 | B6: SRC_HW | C6: S3 | D6: GB300 NVL72 機架功率 | F6: 132 | G6: 142 | H6: kW/架 | I6: 未明 | J6: GB300 NVL72 | K6: 2026-06 | L6: 3 | M6: 利害關係方 | N6: moduledge、hashrateindex：零組件／挖礦業者 | O6: 二手 | P6: Active | Q6: Spec_Rack!E8｜直接；Spec_Rack!E10｜直接；Spec_Rack!E9｜換算 | R6: 一致 | S6: 模型基準 137＝區間中點
A7: SRC_HW_006 | B7: SRC_HW | C7: S4 | D7: GB200 NVL72 機架價格 | F7: 2.8 | G7: 3.4 | H7: $M/架 | I7: 媒體報價 | J7: GB200 NVL72 | K7: 2026-03 | L7: 3 | M7: 利害關係方 | N7: 供應鏈消息經媒體轉述（Tom's Hardware） | O7: 二手 | P7: Active | Q7: Spec_Rack!D11｜直接；Spec_Rack!D13｜直接；Spec_Rack!D12｜換算 | R7: 一致 | S7: 模型基準 3.1＝中點（另載 Barron's 約 3）
A8: SRC_HW_007 | B8: SRC_HW | C8: S4 | D8: GB300 NVL72 機架價格 | F8: 6 | G8: 6.5 | H8: $M/架 | I8: 媒體報價 | J8: GB300 NVL72 | K8: 2026-03 | L8: 3 | M8: 利害關係方 | N8: 供應鏈消息經媒體轉述（Tom's Hardware） | O8: 二手 | P8: Active | Q8: Spec_Rack!E13｜直接 | R8: 一致
A9: SRC_HW_008 | B9: SRC_HW | C9: S4 | D9: VR200 NVL72 機架價格（含約 $1M NAND） | F9: 5 | G9: 7 | H9: $M/架 | I9: 媒體報價 | J9: VR200 NVL72 | K9: 2026-03 | L9: 3 | M9: 利害關係方 | N9: 供應鏈消息經媒體轉述（Tom's Hardware） | O9: 二手 | P9: Alt | R9: 未使用 | S9: 與 S9 同指標但含 NAND 口徑不同 → Alt
A10: SRC_HW_009 | B10: SRC_HW | C10: S5 | D10: Supermicro GB300 NVL72 機架功率 | F10: 132 | G10: 140 | H10: kW/架 | I10: 廠商規格 | J10: GB300 NVL72 | K10: 2026-08 | L10: 3 | M10: 利害關係方 | N10: Supermicro：系統廠產品規格 | O10: 二手 | P10: Active | Q10: Spec_Rack!E8｜直接 | R10: 一致
A11: SRC_HW_010 | B11: SRC_HW | C11: S6 | D11: GB300 NVL72 採購單價 | E11: 5 | H11: $M/架 | I11: 採購單 | J11: GB300 NVL72 | K11: 2026-08 | L11: 3 | M11: 利害關係方 | N11: 未具名交易方（Data Gravity 經 wing.vc） | O11: 二手 | P11: Active | Q11: Spec_Rack!E12｜直接 | R11: 一致
A12: SRC_HW_011 | B12: SRC_HW | C12: S7 | D12: VR200 NVL72 機架功率 Max-Q | E12: 190 | H12: kW/架 | I12: 運轉模式 Max-Q | J12: VR200 NVL72 | K12: 2026 | L12: 3 | M12: 利害關係方 | N12: 郭明錤（供應鏈分析師）；spheron、thundercompute 為 GPU 雲業者 | O12: 二手 | P12: Active | Q12: Spec_Rack!F8｜直接 | R12: 一致 | S12: D3
A13: SRC_HW_012 | B13: SRC_HW | C13: S7 | D13: VR200 NVL72 機架功率 Max-P | E13: 230 | H13: kW/架 | I13: 運轉模式 Max-P | J13: VR200 NVL72 | K13: 2026 | L13: 3 | M13: 利害關係方 | N13: 郭明錤（供應鏈分析師）；spheron、thundercompute 為 GPU 雲業者 | O13: 二手 | P13: Active | Q13: Spec_Rack!F10｜直接 | R13: 一致 | S13: D3
A14: SRC_HW_013 | B14: SRC_HW | C14: S7 | D14: Rubin Ultra NVL576 機架功率 | E14: 600 | H14: kW/架 | I14: 約值 | J14: Rubin Ultra NVL576 | K14: 2026 | L14: 3 | M14: 利害關係方 | N14: 郭明錤（供應鏈分析師）；spheron、thundercompute 為 GPU 雲業者 | O14: 二手 | P14: Active | Q14: Spec_Rack!G9｜直接 | R14: 一致 | S14: 模型低／高 550／650 為 Assumed ±50
A15: SRC_HW_014 | B15: SRC_HW | C15: S8 | D15: Supermicro VR NVL72 散熱設計點 | E15: 227 | H15: kW/架 | I15: DLC-2 設計點 | J15: VR200 NVL72 | K15: 2026-09 | L15: 3 | M15: 利害關係方 | N15: Supermicro：系統廠（論壇轉述） | O15: 二手 | P15: Active | Q15: Spec_Rack!F9｜直接 | R15: 一致 | S15: D3 基準
A16: SRC_HW_015 | B16: SRC_HW | C16: S9 | D16: VR200 NVL72 機架成本（Morgan Stanley） | E16: 7.8 | H16: $M/架 | I16: 分析師估計 | J16: VR200 NVL72 | K16: 2026-05 | L16: 3 | M16: 中立 | N16: Morgan Stanley、Bernstein 賣方研究（推估方法未公開）；現行標記為 IP | O16: 二手 | P16: Active | Q16: Spec_Rack!F12｜直接 | R16: 一致
A17: SRC_HW_016 | B17: SRC_HW | C17: S9 | D17: VR200 NVL72 機架成本，自購記憶體（Morgan Stanley） | E17: 6.7 | H17: $M/架 | I17: 分析師估計，不含記憶體加價 | J17: VR200 NVL72 | K17: 2026-05 | L17: 3 | M17: 中立 | N17: Morgan Stanley、Bernstein 賣方研究（推估方法未公開）；現行標記為 IP | O17: 二手 | P17: Alt | Q17: Spec_Rack!F11｜直接 | R17: 一致 | S17: 口徑不同（自購記憶體）→ Alt
A18: SRC_HW_017 | B18: SRC_HW | C18: S9 | D18: VR200 NVL72 機架成本（Bernstein） | E18: 9.09 | H18: $M/架 | I18: 分析師估計 | J18: VR200 NVL72 | K18: 2026-06 | L18: 3 | M18: 中立 | N18: Morgan Stanley、Bernstein 賣方研究（推估方法未公開）；現行標記為 IP | O18: 二手 | P18: Alt | Q18: Spec_Rack!F13｜取整 | R18: — | S18: 模型取 9.1；與 MS 同口徑，依 G4 日期較新者勝 → 需 chat 判定（見 Gate 0）
A19: SRC_HW_018 | B19: SRC_HW | C19: S11 | D19: VR200 報價中與網路設備相關金額 | E19: 1 | H19: $M/架 | I19: 約值 | J19: VR200 NVL72 | K19: 2026 | L19: 3 | M19: 利害關係方 | N19: originalpricing.com：未知立場；未解（可能與 S4 重複計算） | O19: 二手 | P19: Alt | R19: 未使用 | S19: 可能與 S4 NAND 重複；未解
A20: SRC_HW_019 | B20: SRC_HW | C20: S28 | D20: H100 BF16 dense 峰值 | E20: 0.989 | H20: PF/GPU | I20: dense | J20: Hopper H100 | K20: 2025–26 | L20: 3 | M20: 利害關係方 | N20: NVIDIA 規格；模型內建知識 | O20: 一手（未讀） | P20: Active | Q20: Spec_Rack!C39｜直接 | R20: 一致 | S20: S28 原記為「FP8 989 TF」，實為 BF16（E001）
A21: SRC_HW_020 | B21: SRC_HW | C21: S28 | D21: H100 HBM 容量 | E21: 80 | H21: GB/GPU | J21: Hopper H100 | K21: 2025–26 | L21: 3 | M21: 利害關係方 | N21: NVIDIA 規格；模型內建知識 | O21: 一手（未讀） | P21: Active | Q21: Spec_Rack!C25｜直接 | R21: 一致
A22: SRC_HW_021 | B22: SRC_HW | C22: S28 | D22: H100 HBM 頻寬 | E22: 3.35 | H22: TB/s/GPU | J22: Hopper H100 | K22: 2025–26 | L22: 3 | M22: 利害關係方 | N22: NVIDIA 規格；模型內建知識 | O22: 一手（未讀） | P22: Active | Q22: Spec_Rack!C26｜直接 | R22: 一致
A23: SRC_HW_022 | B23: SRC_HW | C23: S28 | D23: GB200 FP4 dense 峰值 | E23: 10 | H23: PF/GPU | I23: dense | J23: GB200 NVL72 | K23: 2025–26 | L23: 3 | M23: 利害關係方 | N23: NVIDIA 規格；模型內建知識 | O23: 一手（未讀） | P23: Active | Q23: Spec_Rack!D23｜直接；Spec_Rack!D24｜直接 | R23: 一致 | S23: 另載 HGX B200 為 9
A24: SRC_HW_023 | B24: SRC_HW | C24: S28 | D24: GB200 HBM 頻寬 | E24: 8 | H24: TB/s/GPU | J24: GB200 NVL72 | K24: 2025–26 | L24: 3 | M24: 利害關係方 | N24: NVIDIA 規格；模型內建知識 | O24: 一手（未讀） | P24: Active | Q24: Spec_Rack!D26｜直接 | R24: 一致
A25: SRC_HW_024 | B25: SRC_HW | C25: S28 | D25: GB200 HBM 容量（每 GPU，模型內建知識） | E25: 186 | H25: GB/GPU | J25: GB200 NVL72 | K25: 2025–26 | L25: 3 | M25: 利害關係方 | N25: NVIDIA 規格；模型內建知識 | O25: 一手（未讀） | P25: Alt | R25: 未使用 | S25: 模型 186 由 13.4 TB ÷ 72 換算（見 U-NV）；InferenceX 以 192 計 → 口徑不同
A26: SRC_HW_025 | B26: SRC_HW | C26: S28 | D26: B300 FP4 dense 峰值 | E26: 15 | H26: PF/GPU | I26: dense | J26: GB300 NVL72 | K26: 2025–26 | L26: 3 | M26: 利害關係方 | N26: NVIDIA 規格；模型內建知識 | O26: 一手（未讀） | P26: Active | Q26: Spec_Rack!E23｜直接；Spec_Rack!E24｜直接 | R26: 一致
A27: SRC_HW_026 | B27: SRC_HW | C27: S28 | D27: B300 HBM 容量 | E27: 288 | H27: GB/GPU | J27: GB300 NVL72 | K27: 2025–26 | L27: 3 | M27: 利害關係方 | N27: NVIDIA 規格；模型內建知識 | O27: 一手（未讀） | P27: Active | Q27: Spec_Rack!E25｜直接 | R27: 一致
A28: SRC_HW_027 | B28: SRC_HW | C28: S28 | D28: Rubin NVFP4 推論峰值 | E28: 50 | H28: PF/GPU | I28: 含自適應壓縮 | J28: VR200 NVL72 | K28: 2025–26 | L28: 3 | M28: 利害關係方 | N28: NVIDIA 規格；模型內建知識 | O28: 一手（未讀） | P28: Active | Q28: Spec_Rack!F24｜直接 | R28: 一致 | S28: J2：只作高情境；與 S36 換算值一致
A29: SRC_HW_028 | B29: SRC_HW | C29: S28 | D29: Rubin NVFP4 訓練峰值 | E29: 35 | H29: PF/GPU | I29: dense | J29: VR200 NVL72 | K29: 2025–26 | L29: 3 | M29: 利害關係方 | N29: NVIDIA 規格；模型內建知識 | O29: 一手（未讀） | P29: Active | Q29: Spec_Rack!F23｜直接 | R29: 一致 | S29: 與 S36 換算值一致
A30: SRC_HW_029 | B30: SRC_HW | C30: S28 | D30: Rubin HBM 容量 | E30: 288 | H30: GB/GPU | J30: VR200 NVL72 | K30: 2025–26 | L30: 3 | M30: 利害關係方 | N30: NVIDIA 規格；模型內建知識 | O30: 一手（未讀） | P30: Active | Q30: Spec_Rack!F25｜直接 | R30: 一致
A31: SRC_HW_030 | B31: SRC_HW | C31: S28 | D31: Rubin HBM 頻寬 | E31: 22 | H31: TB/s/GPU | I31: NVIDIA 2026 上修 | J31: VR200 NVL72 | K31: 2025–26 | L31: 3 | M31: 利害關係方 | N31: NVIDIA 規格；模型內建知識 | O31: 一手（未讀） | P31: Active | Q31: Spec_Rack!F26｜直接 | R31: 一致
A32: SRC_HW_031 | B32: SRC_HW | C32: S28 | D32: Rubin Ultra NVL576 FP4 峰值（全架） | E32: 15000 | H32: PF/架 | I32: 144 封裝 | J32: Rubin Ultra NVL576 | K32: 2025–26 | L32: 3 | M32: 利害關係方 | N32: NVIDIA 規格；模型內建知識 | O32: 一手（未讀） | P32: Active | Q32: Spec_Rack!G24｜取整 | R32: — | S32: ÷144＝104.2，模型取 104
A33: SRC_HW_032 | B33: SRC_HW | C33: S29 | D33: HBM3 存取能量 | E33: 3.9 | H33: pJ/bit | I33: 文獻常見值 | J33: HBM3 | K33: — | L33: 3 | M33: 中立 | N33: 文獻常見值；模型內建知識 | O33: — | P33: Active | Q33: Spec_Rack!C34｜取整 | R33: — | S33: ×8 bit＝31.2 pJ/byte，模型 31
A34: SRC_HW_033 | B34: SRC_HW | C34: S29 | D34: HBM3e 存取能量 | E34: 3 | H34: pJ/bit | I34: 文獻常見值 | J34: HBM3e | K34: — | L34: 3 | M34: 中立 | N34: 文獻常見值；模型內建知識 | O34: — | P34: Active | Q34: Spec_Rack!D34｜換算；Spec_Rack!E34｜換算 | R34: — | S34: ×8＝24，模型 25
A35: SRC_HW_034 | B35: SRC_HW | C35: S29 | D35: HBM4 存取能量 | E35: 2.5 | H35: pJ/bit | I35: 文獻常見值 | J35: HBM4 | K35: — | L35: 3 | M35: 中立 | N35: 文獻常見值；模型內建知識 | O35: — | P35: Active | Q35: Spec_Rack!F34｜換算 | R35: — | S35: ×8＝20
A36: SRC_HW_035 | B36: SRC_HW | C36: S29 | D36: SerDes 能量 | F36: 1 | G36: 2 | H36: pJ/bit | I36: 文獻常見值 | J36: — | K36: — | L36: 3 | M36: 中立 | N36: 文獻常見值；模型內建知識 | O36: — | P36: Active | R36: 未使用
A37: SRC_HW_036 | B37: SRC_HW | C37: S36 | D37: Vera Rubin NVL72 NVFP4 推論峰值（全架） | E37: 3600 | H37: PF/架 | I37: 72 GPU | J37: VR200 NVL72 | K37: 2026 | L37: 2 | M37: 利害關係方 | N37: NVIDIA 規格表（Gigabyte 轉載 PDF）；若確認為原文件影本可升 1 | O37: 一手文件之轉載 | P37: Active | Q37: Spec_Rack!F24｜換算 | R37: — | S37: ÷72＝50
A38: SRC_HW_037 | B38: SRC_HW | C38: S36 | D38: Vera Rubin NVL72 NVFP4 訓練峰值（全架） | E38: 2520 | H38: PF/架 | I38: 72 GPU | J38: VR200 NVL72 | K38: 2026 | L38: 2 | M38: 利害關係方 | N38: NVIDIA 規格表（Gigabyte 轉載 PDF）；若確認為原文件影本可升 1 | O38: 一手文件之轉載 | P38: Active | Q38: Spec_Rack!F41｜換算 | R38: — | S38: ÷72＝35
A39: SRC_HW_038 | B39: SRC_HW | C39: S36 | D39: Vera Rubin NVL72 FP8／FP6 訓練峰值（全架） | E39: 1260 | H39: PF/架 | I39: 72 GPU | J39: VR200 NVL72 | K39: 2026 | L39: 2 | M39: 利害關係方 | N39: NVIDIA 規格表（Gigabyte 轉載 PDF）；若確認為原文件影本可升 1 | O39: 一手文件之轉載 | P39: Active | Q39: Spec_Rack!F40｜換算 | R39: — | S39: ÷72＝17.5
A40: SRC_HW_039 | B40: SRC_HW | C40: S36 | D40: Vera Rubin NVL72 BF16 峰值（全架） | E40: 288 | H40: PF/架 | I40: 72 GPU | J40: VR200 NVL72 | K40: 2026 | L40: 2 | M40: 利害關係方 | N40: NVIDIA 規格表（Gigabyte 轉載 PDF）；若確認為原文件影本可升 1 | O40: 一手文件之轉載 | P40: Active | Q40: Spec_Rack!F39｜換算 | R40: — | S40: ÷72＝4
...

Sheet Sources_拆解
A1: S 編號 | B1: 項目（Sources） | C1: 原標記 | D1: 原查核狀態 | E1: 擬分頁 | F1: 來源等級 | G1: 立場 | H1: 立場說明 | I1: 一手／二手 | J1: 處置 | K1: 候選紀錄數 | L1: 候選 SRC_ID
A2: S1 | B2: DGX H100 功率 | C2: Verified | D2: 待查核 | E2: SRC_HW | F2: 3 | G2: 利害關係方 | H2: NVIDIA：產品規格 | I2: 一手（未讀） | J2: 遷入 | K2: 1 | L2: SRC_HW_001
A3: S2 | B3: HGX H100 價格 | C3: Analogy | D3: 待查核 | E3: SRC_HW | F3: 3 | G3: 利害關係方 | H3: clusterbid：硬體交易平台，報價有成交誘因；低品質 | I3: 二手 | J3: 遷入 | K3: 2 | L3: SRC_HW_002、SRC_HW_003
A4: S3 | B4: GB200／GB300 機架功率 | C4: Interested-party | D4: 待查核 | E4: SRC_HW | F4: 3 | G4: 利害關係方 | H4: moduledge、hashrateindex：零組件／挖礦業者 | I4: 二手 | J4: 遷入 | K4: 2 | L4: SRC_HW_004、SRC_HW_005
A5: S4 | B5: GB200／GB300／VR200 價格 | C5: Interested-party | D5: 待查核 | E5: SRC_HW | F5: 3 | G5: 利害關係方 | H5: 供應鏈消息經媒體轉述（Tom's Hardware） | I5: 二手 | J5: 遷入 | K5: 3 | L5: SRC_HW_006、SRC_HW_007、SRC_HW_008
A6: S5 | B6: GB300 機架功率 | C6: Interested-party | D6: 待查核 | E6: SRC_HW | F6: 3 | G6: 利害關係方 | H6: Supermicro：系統廠產品規格 | I6: 二手 | J6: 遷入 | K6: 1 | L6: SRC_HW_009
A7: S6 | B7: GB300 採購單價 | C7: Interested-party | D7: 待查核 | E7: SRC_HW | F7: 3 | G7: 利害關係方 | H7: 未具名交易方（Data Gravity 經 wing.vc） | I7: 二手 | J7: 遷入 | K7: 1 | L7: SRC_HW_010
A8: S7 | B8: VR200 與 Rubin Ultra 功率 | C8: Interested-party | D8: 待查核 | E8: SRC_HW | F8: 3 | G8: 利害關係方 | H8: 郭明錤（供應鏈分析師）；spheron、thundercompute 為 GPU 雲業者 | I8: 二手 | J8: 遷入 | K8: 3 | L8: SRC_HW_011、SRC_HW_012、SRC_HW_013
A9: S8 | B9: Supermicro VR NVL72 散熱設計點 | C9: Interested-party | D9: 待查核 | E9: SRC_HW | F9: 3 | G9: 利害關係方 | H9: Supermicro：系統廠（論壇轉述） | I9: 二手 | J9: 遷入 | K9: 1 | L9: SRC_HW_014
A10: S9 | B10: VR200 機架成本估計 | C10: Interested-party | D10: 待查核 | E10: SRC_HW | F10: 3 | G10: 中立 | H10: Morgan Stanley、Bernstein 賣方研究（推估方法未公開）；現行標記為 IP | I10: 二手 | J10: 遷入 | K10: 3 | L10: SRC_HW_015、SRC_HW_016、SRC_HW_017
A11: S10 | B11: 網路資本支出占比 | C11: Analogy | D11: 待查核 | E11: SRC_DC | F11: 3 | G11: 利害關係方 | H11: hedgehog.cloud：網路業者；J.P. Morgan AM 為中立方 | I11: 二手 | J11: 遷入 | K11: 2 | L11: SRC_DC_001、SRC_DC_002
A12: S11 | B12: VR200 報價是否含網路 | C12: Interested-party | D12: 未解：可能重複計算 | E12: SRC_HW | F12: 3 | G12: 利害關係方 | H12: originalpricing.com：未知立場；未解（可能與 S4 重複計算） | I12: 二手 | J12: 遷入（Alt，未解） | K12: 1 | L12: SRC_HW_018
A13: S12 | B13: 廠房建造成本 | C13: Analogy | D13: 待查核 | E13: SRC_DC | F13: 3 | G13: 中立 | H13: JLL、Turner & Townsend：不動產與工程顧問（產業研究） | I13: 二手 | J13: 遷入 | K13: 2 | L13: SRC_DC_003、SRC_DC_004
A14: S13 | B14: 美國工業電價 | C14: Verified | D14: 已核對二手轉載 | E14: SRC_DC | F14: 2 | G14: 中立 | H14: EIA：政府統計 | I14: 二手（轉載） | J14: 遷入 | K14: 2 | L14: SRC_DC_005、SRC_DC_006
A15: S14 | B15: PUE | C15: Analogy | D15: 待查核 | E15: — | F15: — | G15: — | H15: v4 假設，非已取得訊息 | I15: — | J15: 不遷入：非原始訊息（G1），模型頁 PUE 維持 Analogy；Stage 2 另找來源 | K15: 0
A16: S15 | B16: GPU 折舊年限 | C16: Verified | D16: 待以 10-K 原文核對 | E16: SRC_DC | F16: 2 | G16: 利害關係方 | H16: 公司自定會計政策：延長年限可提高帳面獲利 | I16: 二手 | J16: 遷入 | K16: 3 | L16: SRC_DC_007、SRC_DC_008、SRC_DC_009
A17: S16 | B17: 每 GW 建置成本 | C17: Interested-party | D17: 待查核；口徑（IT／設施）未明 | E17: SRC_DC | F17: 3 | G17: 利害關係方 | H17: NVIDIA 執行長：有放大市場規模的誘因；GW 口徑未明 | I17: 二手 | J17: 遷入 | K17: 2 | L17: SRC_DC_010、SRC_DC_011
A18: S17 | B18: GPU 每小時 TCO | C18: Interested-party | D18: 假設未公開 | E18: SRC_DC | F18: 2 | G18: 利害關係方 | H18: SemiAnalysis：販售 TCO 模型、平台受晶片商贊助；須第二來源 | I18: 一手（SA 自家部落格） | J18: 遷入 | K18: 2 | L18: SRC_DC_012、SRC_DC_013
A19: S18 | B19: CoreWeave GB200 牌價 | C19: Verified | D19: 待查核 | E19: SRC_Price | F19: 3 | G19: 利害關係方 | H19: CoreWeave 牌價（經 spheron 轉述；spheron 為競爭 GPU 雲） | I19: 二手 | J19: 遷入 | K19: 1 | L19: SRC_PRC_001
A20: S19 | B20: 新雲損益兩平租金 | C20: Derived | D20: 機型未明 | E20: SRC_Price | F20: 2 | G20: 中立 | H20: 獨立部落客推算（第三方推算值，非實測）；機型未明 | I20: 一手（作者自算） | J20: 遷入 | K20: 1 | L20: SRC_PRC_002
A21: S20 | B21: InferenceX GB300 對 GB200（V4-Pro） | C21: Interested-party（SemiAnalysis：平台受晶片商贊助、另售 TCO 模型）；單一來源須佐證 | D21: 已核對原文（交接錨點即此，屬舊軟體） | E21: SRC_Perf | F21: 1 | G21: 利害關係方 | H21: SemiAnalysis InferenceX；須第二來源 | I21: 一手 | J21: 遷入 | K21: 3 | L21: SRC_PERF_001、SRC_PERF_002、SRC_PERF_003
A22: S21 | B22: SGLang／NVIDIA：V4 on GB300 | C22: Interested-party（SGLang、NVIDIA 作者） | D22: 已核對原文 | E22: SRC_Perf | F22: 1 | G22: 利害關係方 | H22: SGLang、NVIDIA 作者 | I22: 一手 | J22: 遷入 | K22: 5 | L22: SRC_PERF_004、SRC_PERF_005、SRC_PERF_006、SRC_PERF_007、SRC_PERF_008
A23: S22 | B23: InferenceX 每美元比較（B300 對 GB300，V4-Pro） | C23: Interested-party（SemiAnalysis）；擬合所用，第二來源見 S31、S32 | D23: 已核對搜尋摘錄；軟體與日期待確認 | E23: SRC_Perf | F23: 3 | G23: 利害關係方 | H23: SemiAnalysis InferenceX；須第二來源（S31、S32） | I23: 一手（只見摘錄） | J23: 遷入 | K23: 5 | L23: SRC_PERF_009、SRC_PERF_010、SRC_PERF_011、SRC_PERF_012、SRC_PERF_013
A24: S23 | B24: InferenceX 比較（GB200 對 GB300，V4-Pro 0813） | C24: Interested-party（SemiAnalysis） | D24: 口徑待查：頁面預設為 agentic traces | E24: SRC_Perf | F24: 1 | G24: 利害關係方 | H24: SemiAnalysis InferenceX；工作負載口徑待查 | I24: 一手 | J24: 遷入 | K24: 2 | L24: SRC_PERF_014、SRC_PERF_015
A25: S24 | B25: InferenceX H200（V4-Pro，FP8） | C25: Interested-party（SemiAnalysis） | D25: 口徑待查；未入驗證 | E25: SRC_Perf | F25: 1 | G25: 利害關係方 | H25: SemiAnalysis InferenceX；口徑待查；模型未使用 | I25: 一手 | J25: 遷入 | K25: 2 | L25: SRC_PERF_016、SRC_PERF_017
A26: S25 | B26: Anthropic 多代理研究系統 | C26: Interested-party（Anthropic） | D26: 已核對二手 | E26: SRC_Harness | F26: 2 | G26: 利害關係方 | H26: Anthropic：自家產品宣傳 | I26: 二手 | J26: 遷入 | K26: 2 | L26: SRC_HAR_001、SRC_HAR_002
A27: S26 | B27: Artificial Analysis 輸出速度 | C27: Verified-measured（反映供應商自身服務選擇） | D27: 已核對 | E27: SRC_Perf | F27: 1 | G27: 中立 | H27: Artificial Analysis：獨立評測（反映供應商自身服務設定） | I27: 一手 | J27: 遷入 | K27: 5 | L27: SRC_PERF_018、SRC_PERF_019、SRC_PERF_020、SRC_PERF_021、SRC_PERF_022
... A34: S33 | B34: MLCommons DeepSeek-R1 基準規格 | C34: Verified | D34: 已核對 | E34: SRC_Perf | F34: 1 | G34: 中立 | H34: MLCommons：基準規則 | I34: 一手 | J34: 遷入 | K34: 7 | L34: SRC_PERF_029、SRC_PERF_030、SRC_PERF_031、SRC_PERF_032、SRC_PERF_033、SRC_PERF_034、SRC_PERF_035
A35: S34 | B35: AMD：InferenceX 資料的選擇性使用 | C35: Interested-party（AMD） | D35: 提醒：同一平台資料可因設定選擇而偏向 | E35: — | F35: — | G35: — | H35: 定性提醒，無數值 | I35: — | J35: 不遷入：無數值；轉為 DB_Evidence 備註（SemiAnalysis 資料使用規則的佐證） | K35: 0
A36: S35 | B36: DeepSeek-V4 技術報告（arXiv 2606.19348） | C36: Interested-party（DeepSeek） | D36: 已核對原文摘錄 | E36: SRC_Model | F36: 1 | G36: 利害關係方 | H36: DeepSeek 技術報告 | I36: 一手 | J36: 遷入（精度做法為定性，不建數值） | K36: 4 | L36: SRC_MOD_029、SRC_MOD_030、SRC_MOD_031、SRC_MOD_032
A37: S36 | B37: NVIDIA Vera Rubin NVL72 規格表 | C37: Interested-party（NVIDIA） | D37: 已核對兩處轉載 | E37: SRC_HW | F37: 2 | G37: 利害關係方 | H37: NVIDIA 規格表（Gigabyte 轉載 PDF）；若確認為原文件影本可升 1 | I37: 一手文件之轉載 | J37: 遷入 | K37: 4 | L37: SRC_HW_036、SRC_HW_037、SRC_HW_038、SRC_HW_039
A38: S37 | B38: Meta Llama 3 技術報告 | C38: Interested-party（Meta） | D38: 待查核 | E38: SRC_Perf | F38: 3 | G38: 利害關係方 | H38: Meta 技術報告；模型內建知識 | I38: 一手（未讀） | J38: 遷入 | K38: 2 | L38: SRC_PERF_036、SRC_PERF_037
A39: S38 | B39: Epoch：最終訓練占研發算力少數 | C39: Analogy（Epoch 推估；資料源為 The Information 等報導） | D39: 已核對 | E39: SRC_Demand | F39: 1 | G39: 中立 | H39: Epoch：獨立研究（底層資料為 The Information 等報導） | I39: 一手（Epoch 推估） | J39: 遷入 | K39: 3 | L39: SRC_DEM_001、SRC_DEM_002、SRC_DEM_003
A40: S39 | B40: Epoch：超過 1e25 FLOP 的模型 | C40: Analogy（Epoch 推估） | D40: 已核對 | E40: SRC_Model | F40: 1 | G40: 中立 | H40: Epoch：獨立研究；估計誤差 2–5 倍 | I40: 一手（Epoch 推估） | J40: 遷入 | K40: 1 | L40: SRC_MOD_033
A41: S40 | B41: R1 RL 算力（Lambert《RLHF》書） | C41: Interested-party（DeepSeek，經轉述） | D41: 已核對轉述 | E41: SRC_Model | F41: 2 | G41: 利害關係方 | H41: DeepSeek 揭露，經 Lambert 轉述 | I41: 二手 | J41: 遷入 | K41: 1 | L41: SRC_MOD_034
A42: S41 | B42: Epoch：推理模型能擴展多遠 | C42: Analogy（Epoch 轉述 NVIDIA） | D42: 已核對 | E42: SRC_Model | F42: 2 | G42: 利害關係方 | H42: NVIDIA 揭露，經 Epoch 轉述 | I42: 二手 | J42: 遷入 | K42: 1 | L42: SRC_MOD_035
A43: S42 | B43: xAI Grok 4 發表 | C43: Interested-party（xAI，宣傳誘因） | D43: 已核對原文；口徑不明 | E43: SRC_Model | F43: 1 | G43: 利害關係方 | H43: xAI：產品發表，有宣傳誘因；口徑不明 | I43: 一手 | J43: 遷入 | K43: 3 | L43: SRC_MOD_036、SRC_MOD_037、SRC_MOD_038
A44: S43 | B44: verl DeepSeek V4 RL 配方（PR #7895） | C44: Verified（開源程式碼） | D44: 已核對；J12 替代情境依據 | E44: — | F44: — | G44: — | H44: 開源程式碼設定（定性） | I44: — | J44: 不遷入：定性；保留於 DB_Evidence E008 | K44: 0
A45: S44 | B45: DeepSeek-V3 技術報告 | C45: Interested-party（DeepSeek） | D45: GPU 小時為模型內建知識，待以原文核對 | E45: SRC_Model | F45: 3 | G45: 利害關係方 | H45: DeepSeek 技術報告；GPU 小時為模型內建知識 | I45: 一手（未讀） | J45: 遷入 | K45: 4 | L45: SRC_MOD_039、SRC_MOD_040、SRC_MOD_041、SRC_MOD_042
A46: S45 | B46: DeepSeek-V4.1-Flash 技術報告（arXiv 2609.19969） | C46: Interested-party（DeepSeek） | D46: 已核對原文摘錄 | E46: SRC_Model | F46: 1 | G46: 利害關係方 | H46: DeepSeek 技術報告 | I46: 一手 | J46: 遷入（採用紀錄） | K46: 1 | L46: SRC_MOD_043
...

Sheet 盤點複核
A1: INV_ID | B1: 工作表 | C1: 列 | D1: 標籤 | E1: 單位 | F1: 藍字格 | G1: 藍字格數 | H1: 全部標記 | I1: 主標記 | J1: 多標記 | K1: 來源編號 | L1: CC 規則初步分類 | M1: chat 複核分類 | N1: 與初步分類相同 | O1: 擬 SRC 分頁 | P1: 理由 | Q1: 直接連結 SRC 的格數 | R1: 換算／取整／選取格數 | S1: 相關 SRC_ID | T1: Gate 0 爭議
A2: INV-001 | B2: Inputs | C2: 5 | D2: IT 電力規模 | E2: GW | F2: E5 | G2: 1 | H2: Decision | I2: Decision | L2: Decision | M2: Decision | N2: 是 | O2: — | P2: 同意規則分類（未逐列判讀） | Q2: 0 | R2: 0
A3: INV-002 | B3: Inputs | C3: 6 | D3: 功率情境（1 低／2 基準／3 高） | E3: 選擇 | F3: E6 | G3: 1 | H3: Decision | I3: Decision | L3: Decision | M3: Decision | N3: 是 | O3: — | P3: 同意規則分類（未逐列判讀） | Q3: 0 | R3: 0
A4: INV-003 | B4: Inputs | C4: 8 | D4: 機架外 IT 電力占比 | E4: % | F4: E8 | G4: 1 | H4: Assumed | I4: Assumed | L4: Assumed | M4: Assumed | N4: 是 | O4: — | P4: 同意規則分類（未逐列判讀） | Q4: 0 | R4: 0
A5: INV-004 | B5: Inputs | C5: 9 | D5: PUE | E5: x | F5: D9、E9、F9 | G5: 3 | H5: Analogy | I5: Analogy | K5: S14 | L5: Analogy | M5: Analogy | N5: 是 | O5: — | P5: 同意規則分類（未逐列判讀）；說明文字引 S14，Stage 1 補可比對象 SRC_ID | Q5: 0 | R5: 0
A6: INV-005 | B6: Inputs | C6: 10 | D6: 平均用電 ÷ 配電設計功率 | E6: % | F6: D10、E10、F10 | G6: 3 | H6: Assumed | I6: Assumed | L6: Assumed | M6: Assumed | N6: 是 | O6: — | P6: 同意規則分類（未逐列判讀） | Q6: 0 | R6: 0
A7: INV-006 | B7: Inputs | C7: 11 | D7: 電價 | E7: $/kWh | F7: D11、E11、F11 | G7: 3 | H7: Verified、Analogy | I7: Verified | J7: 是 | K7: S13 | L7: 原始數據（候選） | M7: Analogy | N7: 否 | O7: SRC_DC | P7: 基準 0.08 低於 EIA 2026-05 的 0.0871（S13）；低值 0.06 為 v4 PPA 假設。模型格非原始值，留模型頁並附可比對象 SRC | Q7: 0 | R7: 1 | S7: SRC_DC_006
A8: INV-007 | B8: Inputs | C8: 13 | D8: Scale-out 網路 ÷ 機架價格 | E8: % | F8: D13、E13、F13 | G8: 3 | H8: Analogy | I8: Analogy | K8: S10 | L8: Analogy | M8: Analogy | N8: 是 | O8: — | P8: 同意規則分類（未逐列判讀）；說明文字引 S10，Stage 1 補可比對象 SRC_ID | Q8: 1 | R8: 1 | S8: SRC_DC_001、SRC_DC_002
A9: INV-008 | B9: Inputs | C9: 14 | D9: 儲存與管理設備 | E9: $/GPU | F9: D14、E14、F14 | G9: 3 | H9: Assumed | I9: Assumed | L9: Assumed | M9: Assumed | N9: 是 | O9: — | P9: 同意規則分類（未逐列判讀） | Q9: 0 | R9: 0
A10: INV-009 | B10: Inputs | C10: 16 | D10: 土地 | E10: $M/MW | F10: D16、E16、F16 | G10: 3 | H10: Assumed | I10: Assumed | L10: Assumed | M10: Assumed | N10: 是 | O10: — | P10: 同意規則分類（未逐列判讀） | Q10: 0 | R10: 0
A11: INV-010 | B11: Inputs | C11: 17 | D11: 建物與基地工程 | E11: $M/MW | F11: D17、E17、F17 | G11: 3 | H11: Assumed | I11: Assumed | K11: S12 | L11: Assumed | M11: Assumed | N11: 是 | O11: — | P11: 同意規則分類（未逐列判讀）；說明文字引 S12，Stage 1 補可比對象 SRC_ID | Q11: 0 | R11: 0
A12: INV-011 | B12: Inputs | C12: 18 | D12: 電力設施（變電、中壓、發電機、UPS） | E12: $M/MW | F12: D18、E18、F18 | G12: 3 | H12: Assumed | I12: Assumed | L12: Assumed | M12: Assumed | N12: 是 | O12: — | P12: 同意規則分類（未逐列判讀） | Q12: 0 | R12: 0
A13: INV-012 | B13: Inputs | C13: 19 | D13: 機械與散熱（液冷迴路、散熱設備） | E13: $M/MW | F13: D19、E19、F19 | G13: 3 | H13: Assumed | I13: Assumed | L13: Assumed | M13: Assumed | N13: 是 | O13: — | P13: 同意規則分類（未逐列判讀） | Q13: 0 | R13: 0
A14: INV-013 | B14: Inputs | C14: 20 | D14: 光纖、佈線、保全、BMS | E14: $M/MW | F14: D20、E20、F20 | G14: 3 | H14: Assumed | I14: Assumed | L14: Assumed | M14: Assumed | N14: 是 | O14: — | P14: 同意規則分類（未逐列判讀） | Q14: 0 | R14: 0
A15: INV-014 | B15: Inputs | C15: 21 | D15: 設計、管理與預備費 | E15: % 廠房 | F15: D21、E21、F21 | G15: 3 | H15: Assumed | I15: Assumed | L15: Assumed | M15: Assumed | N15: 是 | O15: — | P15: 同意規則分類（未逐列判讀） | Q15: 0 | R15: 0
A16: INV-015 | B16: Inputs | C16: 23 | D16: IT 設備折舊年限 | E16: 年 | F16: D23、E23、F23 | G16: 3 | H16: Verified | I16: Verified | K16: S15 | L16: 原始數據（候選） | M16: Decision | N16: 否 | O16: SRC_DC | P16: D4：基準 6 年須與 CRWV 一致；CoreWeave 6、Nebius 4 為可比 SRC（高成本情境 4 直接等於 Nebius） | Q16: 2 | R16: 0 | S16: SRC_DC_007、SRC_DC_008
A17: INV-016 | B17: Inputs | C17: 24 | D17: 建物年限 | E17: 年 | F17: E24 | G17: 1 | H17: Analogy | I17: Analogy | L17: Analogy | M17: Analogy | N17: 是 | O17: — | P17: 同意規則分類（未逐列判讀） | Q17: 0 | R17: 0
A18: INV-017 | B18: Inputs | C18: 25 | D18: 電力設施年限 | E18: 年 | F18: E25 | G18: 1 | H18: Analogy | I18: Analogy | L18: Analogy | M18: Analogy | N18: 是 | O18: — | P18: 同意規則分類（未逐列判讀） | Q18: 0 | R18: 0
A19: INV-018 | B19: Inputs | C19: 26 | D19: 機械與散熱年限 | E19: 年 | F19: E26 | G19: 1 | H19: Analogy | I19: Analogy | L19: Analogy | M19: Analogy | N19: 是 | O19: — | P19: 同意規則分類（未逐列判讀） | Q19: 0 | R19: 0
A20: INV-019 | B20: Inputs | C20: 27 | D20: 光纖與保全年限 | E20: 年 | F20: E27 | G20: 1 | H20: Analogy | I20: Analogy | L20: Analogy | M20: Analogy | N20: 是 | O20: — | P20: 同意規則分類（未逐列判讀） | Q20: 0 | R20: 0
A21: INV-020 | B21: Inputs | C21: 28 | D21: WACC（經濟口徑） | E21: % | F21: D28、E28、F28 | G21: 3 | H21: Assumed | I21: Assumed | L21: Assumed | M21: Assumed | N21: 是 | O21: — | P21: 同意規則分類（未逐列判讀） | Q21: 0 | R21: 0
A22: INV-021 | B22: Inputs | C22: 30 | D22: IT 維護 | E22: % IT 資本/年 | F22: D30、E30、F30 | G22: 3 | H22: Analogy | I22: Analogy | L22: Analogy | M22: Analogy | N22: 是 | O22: — | P22: 同意規則分類（未逐列判讀） | Q22: 0 | R22: 0
A23: INV-022 | B23: Inputs | C23: 31 | D23: 廠房維護 | E23: % 廠房資本/年 | F23: D31、E31、F31 | G23: 3 | H23: Analogy | I23: Analogy | L23: Analogy | M23: Analogy | N23: 是 | O23: — | P23: 同意規則分類（未逐列判讀） | Q23: 0 | R23: 0
A24: INV-023 | B24: Inputs | C24: 32 | D24: 人員 | E24: $M/GW/年 | F24: D32、E32、F32 | G24: 3 | H24: Assumed | I24: Assumed | L24: Assumed | M24: Assumed | N24: 是 | O24: — | P24: 同意規則分類（未逐列判讀） | Q24: 0 | R24: 0
A25: INV-024 | B25: Inputs | C25: 33 | D25: 軟體授權與連線 | E25: $M/GW/年 | F25: D33、E33、F33 | G25: 3 | H25: Assumed | I25: Assumed | L25: Assumed | M25: Assumed | N25: 是 | O25: — | P25: 同意規則分類（未逐列判讀） | Q25: 0 | R25: 0
A26: INV-025 | B26: Inputs | C26: 34 | D26: 水與耗材 | E26: $M/MW/年 | F26: D34、E34、F34 | G26: 3 | H26: Assumed | I26: Assumed | L26: Assumed | M26: Assumed | N26: 是 | O26: — | P26: 同意規則分類（未逐列判讀） | Q26: 0 | R26: 0
A27: INV-026 | B27: Inputs | C27: 35 | D27: 財產稅與保險 | E27: % 總資本/年 | F27: D35、E35、F35 | G27: 3 | H27: Analogy | I27: Analogy | L27: Analogy | M27: Analogy | N27: 是 | O27: — | P27: 同意規則分類（未逐列判讀） | Q27: 0 | R27: 0
A28: INV-027 | B28: Spec_Rack | C28: 6 | D28: GPU 封裝／架 | F28: C6、D6、E6、F6、G6 | G28: 5 | L28: 待分類 | M28: 混合（逐格） | N28: 否 | O28: SRC_HW | P28: GB200／GB300／VR200 的 72、RU 的 144 為產品規格（SRC）；Hopper 32＝HGX ×4 為機架配置選擇（Assumed） | Q28: 3 | R28: 0 | S28: SRC_HW_047
A29: INV-028 | B29: Spec_Rack | C29: 8 | D29: 配電設計功率 低（kW） | F29: C8、D8、E8、F8、G8 | G29: 5 | L29: 待分類 | M29: 混合（逐格） | N29: 否 | O29: SRC_HW | P29: GB200 120、GB300 132、VR200 190 等於來源值；Hopper 38、RU 550 為 Assumed 區間 | Q29: 3 | R29: 0 | S29: SRC_HW_004、SRC_HW_005、SRC_HW_009、SRC_HW_011 | T29: 是
A30: INV-029 | B30: Spec_Rack | C30: 9 | D30: 配電設計功率 基準（kW） | F30: C9、D9、E9、F9、G9 | G30: 5 | L30: 待分類 | M30: 混合（逐格） | N30: 否 | O30: SRC_HW | P30: VR200 227（S8）、RU 600（S7）等於來源；Hopper 41＝10.2×4 取整、GB200 130 為區間上緣、GB300 137 為中點 → 留藍字附 SRC | Q30: 2 | R30: 3 | S30: SRC_HW_001、SRC_HW_004、SRC_HW_005、SRC_HW_013、SRC_HW_014 | T30: 是
A31: INV-030 | B31: Spec_Rack | C31: 10 | D31: 配電設計功率 高（kW） | F31: C10、D10、E10、F10、G10 | G31: 5 | L31: 待分類 | M31: 混合（逐格） | N31: 否 | O31: SRC_HW | P31: GB300 142、VR200 230 等於來源；GB200 140 無來源（v4＝139）、Hopper 44、RU 650 為 Assumed | Q31: 2 | R31: 0 | S31: SRC_HW_005、SRC_HW_012 | T31: 是
A32: INV-031 | B32: Spec_Rack | C32: 11 | D32: 機架價格 低（$M） | F32: C11、D11、E11、F11、G11 | G32: 5 | L32: 待分類 | M32: 混合（逐格） | N32: 否 | O32: SRC_HW | P32: GB200 2.8（S4）、GB300 4.0（MS，未登錄）、VR200 6.7（S9，自購記憶體口徑）等於來源；Hopper 0.9 由 S2 換算取整；RU 為 VR × 倍數的 Assumed | Q32: 3 | R32: 1 | S32: SRC_HW_003、SRC_HW_006、SRC_HW_016、SRC_HW_052 | T32: 是
A33: INV-032 | B33: Spec_Rack | C33: 12 | D33: 機架價格 基準（$M） | F33: C12、D12、E12、F12、G12 | G33: 5 | L33: 待分類 | M33: 混合（逐格） | N33: 否 | O33: SRC_HW | P33: GB300 5.0（S6）、VR200 7.8（S9 MS）等於來源；GB200 3.1 為 S4 區間中點；Hopper 1.1 換算；RU 31.2＝VR 7.8 × 4（Assumed 倍數，應改公式） | Q33: 2 | R33: 1 | S33: SRC_HW_006、SRC_HW_010、SRC_HW_015 | T33: 是
A34: INV-033 | B34: Spec_Rack | C34: 13 | D34: 機架價格 高（$M） | F34: C13、D13、E13、F13、G13 | G34: 5 | L34: 待分類 | M34: 混合（逐格） | N34: 否 | O34: SRC_HW | P34: GB200 3.4、GB300 6.5（S4）等於來源；VR200 9.1 為 Bernstein 9.09 取整；Hopper 1.3 換算；RU 39＝7.8 × 5 | Q34: 2 | R34: 2 | S34: SRC_HW_003、SRC_HW_006、SRC_HW_007、SRC_HW_017 | T34: 是
A35: INV-034 | B35: Spec_Rack | C35: 23 | D35: 峰值 dense（基準）PF/GPU | F35: C23、D23、E23、F23、G23 | G35: 5 | H35: Interested-party、Derived | I35: Interested-party | J35: 是 | K35: S28 | L35: 原始數據（候選） | M35: 混合（逐格） | N35: 否 | O35: SRC_HW | P35: Hopper 1.979（E001）、GB200 10、GB300 15、VR200 35 等於 NVIDIA 規格；RU 73＝104 × 35/50 推估 → Derived 改公式 | Q35: 4 | R35: 0 | S35: SRC_HW_022、SRC_HW_025、SRC_HW_028、SRC_HW_040
A36: INV-035 | B36: Spec_Rack | C36: 24 | D36: 峰值（高情境：NVFP4 推論口徑）PF/GPU | F36: C24、D24、E24、F24、G24 | G36: 5 | L36: 待分類 | M36: 混合（逐格） | N36: 否 | O36: SRC_HW | P36: GB200 10、GB300 15、VR200 50 等於規格（VR 也可由 S36 3,600 ÷ 72 換算）；Hopper 1.979 複製 FP8 值（應連結第 23 列）；RU 104＝15 EF ÷ 144 取整 | Q36: 3 | R36: 1 | S36: SRC_HW_022、SRC_HW_025、SRC_HW_027、SRC_HW_031、SRC_HW_036
A37: INV-036 | B37: Spec_Rack | C37: 25 | D37: HBM 容量 GB/GPU | F37: C25、D25、E25、F25、G25 | G37: 5 | K37: S28 | L37: 待分類 | M37: 混合（逐格） | N37: 否 | O37: SRC_HW | P37: Hopper 80、GB300 288、VR200 288 等於規格；GB200 186＝13.4 TB ÷ 72（換算，InferenceX 以 192 計）；RU 1,024 為約值（Analogy） | Q37: 3 | R37: 1 | S37: SRC_HW_020、SRC_HW_026、SRC_HW_029、SRC_HW_041
A38: INV-037 | B38: Spec_Rack | C38: 26 | D38: HBM 頻寬 TB/s/GPU | F38: C26、D26、E26、F26、G26 | G38: 5 | K38: S28 | L38: 待分類 | M38: 混合（逐格） | N38: 否 | O38: SRC_HW | P38: Hopper 3.35、GB200／GB300 8、VR200 22 等於規格；RU 32＝4.6 PB/s ÷ 144 取整 | Q38: 3 | R38: 1 | S38: SRC_HW_021、SRC_HW_023、SRC_HW_030、SRC_HW_044
A39: INV-038 | B39: Spec_Rack | C39: 27 | D39: EP 通訊頻寬 TB/s/GPU（單向） | F39: C27、D27、E27、F27、G27 | G39: 5 | H39: Assumed | I39: Assumed | K39: S20 | L39: Assumed | M39: 混合（逐格） | N39: 否 | O39: SRC_HW | P39: GB200／GB300 0.9、VR200 1.8 為 NVLink 規格；Hopper 0.05＝400G IB（換算）；RU 取同 VR（Assumed） | Q39: 3 | R39: 0 | S39: SRC_HW_048、SRC_HW_049
A40: INV-039 | B40: Spec_Rack | C40: 28 | D40: Scale-up 域 GPU 數 | F40: C28、D28、E28、F28、G28 | G40: 5 | L40: 待分類 | M40: 原始數據→SRC | N40: 否 | O40: SRC_HW | P40: NVLink 域大小為產品規格（Hopper 8＝HGX 8 GPU；NVL72；NVL576 為 144 封裝）；目前無登錄來源，Stage 2 補 | Q40: 3 | R40: 0 | S40: SRC_HW_047
...

Sheet 格對照
A1: 模型格 | B1: 模型格值 | C1: SRC_ID | D1: 關係 | E1: SRC 數值 | F1: SRC 低 | G1: SRC 高 | H1: SRC 狀態 | I1: 一致性 | J1: 指標
A2: Arch!C11 | B2: 512 | C2: SRC_MOD_009 | D2: 直接 | E2: 512 | H2: Active | I2: 一致 | J2: DeepSeek V4 KV head 維度
A3: Arch!C12 | B3: 256 | C3: SRC_MOD_010 | D3: 直接 | E3: 256 | H3: Active | I3: 一致 | J3: DeepSeek V4-Flash routed experts
A4: Arch!C13 | B4: 6 | C4: SRC_MOD_012 | D4: 直接 | E4: 6 | H4: Active | I4: 一致 | J4: DeepSeek V4 每 token 啟用 routed experts
A5: Arch!C14 | B5: 1 | C5: SRC_MOD_013 | D5: 直接 | E5: 1 | H5: Active | I5: 一致 | J5: DeepSeek V4 shared experts
A6: Arch!C15 | B6: 129280 | C6: SRC_MOD_014 | D6: 直接 | E6: 129280 | H6: Active | I6: 一致 | J6: DeepSeek V4 vocab
A7: Arch!C16 | B7: 0.5 | C7: SRC_MOD_015 | D7: 直接 | E7: 0.5 | H7: Active | I7: 一致 | J7: DeepSeek V4 全注意力層比例（CSA／HCA 約各半）
A8: Arch!C17 | B8: 4224 | C8: SRC_MOD_018 | D8: 換算 | E8: 1024 | H8: Active | I8: — | J8: DeepSeek V4 CSA top-k 壓縮塊數
A9: Arch!C17 | B9: 4224 | C9: SRC_MOD_019 | D9: 換算 | E9: 4 | H9: Active | I9: — | J9: DeepSeek V4 CSA 壓縮塊長度
A10: Arch!C18 | B10: 128 | C10: SRC_MOD_016 | D10: 直接 | E10: 128 | H10: Active | I10: 一致 | J10: DeepSeek V4 HCA 壓縮比
A11: Arch!C19 | B11: 128 | C11: SRC_MOD_017 | D11: 直接 | E11: 128 | H11: Active | I11: 一致 | J11: DeepSeek V4 滑動窗
A12: Arch!C6 | B12: 284 | C12: SRC_MOD_005 | D12: 直接 | E12: 284 | H12: Active | I12: 一致 | J12: DeepSeek V4-Flash 總參數
A13: Arch!C7 | B13: 13 | C13: SRC_MOD_006 | D13: 直接 | E13: 13 | H13: Active | I13: 一致 | J13: DeepSeek V4-Flash 啟用參數
... A113: Checks!C10 | B113: 3.57 | C113: SRC_PRC_002 | D113: 對照 | E113: 3.57 | H113: Active | I113: — | J113: 新雲損益兩平租金（Cape Fear）
A114: Checks!C19 | B114: 0.078 | C114: SRC_PERF_011 | D114: 對照 | E114: 0.078 | H114: Active | I114: — | J114: InferenceX GB300 每 M token 成本 @72 tok/s
A115: Checks!C37 | B115: 9.6%–22.6% | C115: SRC_DEM_001 | D115: 對照 | E115: 0.096 | H115: Active | I115: — | J115: 最終訓練占研發支出：OpenAI
A116: Checks!C37 | B116: 9.6%–22.6% | C116: SRC_DEM_002 | D116: 對照 | E116: 0.226 | H116: Active | I116: — | J116: 最終訓練占研發支出：MiniMax
A117: Checks!C4 | B117: 50–60 | C117: SRC_DC_010 | D117: 對照 | F117: 50 | G117: 60 | H117: Active | I117: — | J117: 每 GW 建置成本（黃仁勳）
A118: Checks!C43 | B118: 10.456 | C118: SRC_DEM_007 | D118: 換算 | E118: 13.07 | H118: Active | I118: — | J118: OpenAI 2025 營收
A119: Checks!C43 | B119: 10.456 | C119: SRC_DEM_008 | D119: 換算 | E119: 0.6 | H119: Active | I119: — | J119: OpenAI 算力規模 2024 年底
A120: Checks!C43 | B120: 10.456 | C120: SRC_DEM_009 | D120: 換算 | E120: 1.9 | H120: Active | I120: — | J120: OpenAI 算力規模 2025 年底
A121: Checks!C5 | B121: 35 | C121: SRC_DC_011 | D121: 對照 | E121: 35 | H121: Active | I121: — | J121: 每 GW 中 NVIDIA 晶片與系統
A122: Checks!C6 | B122: 11.3 × 1.07–1.10 | C122: SRC_DC_003 | D122: 對照 | E122: 11.3 | H122: Active | I122: — | J122: 全球平均資料中心建造成本（JLL 2026）
A123: Checks!C6 | B123: 11.3 × 1.07–1.10 | C123: SRC_DC_004 | D123: 對照 | F123: 0.07 | G123: 0.1 | H123: Active | I123: — | J123: 液冷溢價（Turner & Townsend）
A124: Checks!C62 | B124: 0.51 | C124: SRC_HAR_010 | D124: 對照 | E124: 0.51 | H124: Active | I124: — | J124: ARC-AGI-3：Adapter token ÷ 標準
A125: Checks!C7 | B125: 2.21 | C125: SRC_DC_012 | D125: 對照 | E125: 2.21 | H125: Active | I125: — | J125: GB200 NVL72 每 GPU 小時 TCO（SemiAnalysis）
A126: Checks!C8 | B126: 2.65 | C126: SRC_DC_013 | D126: 對照 | E126: 2.65 | H126: Active | I126: — | J126: GB300 NVL72 每 GPU 小時 TCO（SemiAnalysis）
A127: Checks!C9 | B127: 10.5 | C127: SRC_PRC_001 | D127: 換算 | E127: 42 | H127: Active | I127: — | J127: CoreWeave GB200 4-GPU 執行個體牌價
A128: Har_In!C70 | B128: 0.627 | C128: SRC_HAR_003 | D128: 直接 | E128: 0.627 | H128: Active | I128: 一致 | J128: ARC-AGI-3：GPT-6 Astra 標準 harness 成功率（最高推理）
A129: Har_In!C71 | B129: 0.986 | C129: SRC_HAR_005 | D129: 直接 | E129: 0.986 | H129: Active | I129: 一致 | J129: ARC-AGI-3：Provider Adapter 最高推理成功率
A130: Har_In!C72 | B130: 0.999 | C130: SRC_HAR_007 | D130: 直接 | E130: 0.999 | H130: Active | I130: 一致 | J130: ARC-AGI-3：Provider Adapter 高推理成功率
A131: Har_In!C73 | B131: 0.302 | C131: SRC_HAR_012 | D131: 直接 | E131: 0.302 | H131: Active | I131: 一致 | J131: ARC-AGI-3：Claude Opus 5 標準 harness 成功率
A132: Har_In!C74 | B132: 1 | C132: SRC_HAR_015 | D132: 直接 | E132: 1 | H132: Active | I132: 一致 | J132: ARC-AGI-3：Opus 5＋Nvidia harness 成功率
A133: Har_In!C77 | B133: 3.5667 | C133: SRC_CAP_012 | D133: 直接 | E133: 3.5667 | H133: Active | I133: 一致 | J133: METR 50% 時間範圍：GPT-5
A134: Har_In!C78 | B134: 6.5667 | C134: SRC_CAP_014 | D134: 直接 | E134: 6.5667 | H134: Active | I134: 一致 | J134: METR 50% 時間範圍：GPT-5.2（high）
A135: Har_In!C79 | B135: 5.7 | C135: SRC_CAP_016 | D135: 直接 | E135: 5.7 | H135: Active | I135: 一致 | J135: METR 50% 時間範圍：GPT-5.4（xhigh）
... A146: Inputs!E11 | B146: 0.08 | C146: SRC_DC_006 | D146: 選取 | E146: 0.0871 | H146: Active | I146: — | J146: 美國工業電價 2026-05
A147: Inputs!E13 | B147: 0.1 | C147: SRC_DC_001 | D147: 選取 | F147: 0.04 | G147: 0.08 | H147: Active | I147: — | J147: 1,024 GPU 叢集網路 ÷ GPU BOM
A148: Inputs!E23 | B148: 6 | C148: SRC_DC_007 | D148: 直接 | E148: 6 | H148: Active | I148: 一致 | J148: CoreWeave GPU 折舊年限
A149: Inputs!F13 | B149: 0.15 | C149: SRC_DC_002 | D149: 直接 | E149: 0.15 | H149: Active | I149: 一致 | J149: 網路占 AI 支出（J.P. Morgan AM 假設）
...

Sheet 發現
A1: 編號 | B1: 主題 | C1: 內容 | D1: 位置 | E1: 對應 Gate 0
A2: F01 | B2: 標記位置 | C2: Spec_Rack 的來源標記是「逐欄」寫在第 17 列（Analogy／IP／IP／IP／Assumed），不是逐列；列層級分類因此把第 8–13 列判為「待分類」。Stage 1 必須逐格處理。 | D2: Spec_Rack 第 8–13、17 列 | E2: G0-1
A3: F02 | B3: 一列多類 | C3: Arch（Luna、Sol＝真實模型的原始參數；Astra＝Assumed）、Spec_Rack（各世代來源不同）、Cap_In 市場表（價格、指數為原始；屬性欄非數值）都是同一列內混合不同類別。 | D3: 見盤點複核「混合（逐格）」 | E3: G0-1
A4: F03 | B4: 公式內嵌原始數據 | C4: Calib C118:F118（=1000/15、=1000/80，TPOT 上限）、Calib C120:E120（=253506/72 等，MLPerf 總量）把原始數據寫在公式裡；Checks 判讀公式含 11.3、1.07、50、60 等外部參照常數；Sensitivity X8:Y8 為 =0.05、=0.12。這些不是藍字，CC 盤點不會列入，但 Gate 1「原始數據寫死在模型頁 0 格」必須涵蓋。 | D4: Calib、Checks、Sensitivity | E4: G0-5
A5: F04 | B5: 藍字但其實是推導值 | C5: Arch 17、Arch 21–23、Calib 108–109、Har_In 75、Train_In 44、Cap_In 28–29、Spec_Rack G 欄（RU）多格，數值是由其他數字算出後手填。前五者改公式後數值不變；Train_In 44（0.055→0.0552）、Cap_In 28（0.41→0.4118）、Cap_In 29（0.46→0.4643）改公式會改變數值。 | D5: 見盤點複核「Derived→改公式」 | E5: G0-2
A6: F05 | B6: Tech_Registry 的標記意義不同 | C6: Tech_Registry 列內的 Verified／IP 指「採用證據」的性質，不是該列倍數的性質；CC 規則會把 T01–T06、T10 判成原始數據。chat 改判為「Tech_Registry 登錄」。 | D6: Tech_Registry 第 5–14 列 | E6: G0-6
A7: F06 | B7: 未登錄來源 | C7: 模型頁說明文字引用、但 Sources 沒有的數值出處：Barron's GB200 約 $3M、Morgan Stanley GB300 約 $4M、GB200 NVL72 13.4 TB、RU 4.6 PB/s 與 5 EF、Rubin 1.8 kW、NVLink 頻寬、DeepSeek V3／V4 架構參數（Arch、Calib H 節，標 Verified 但無 S 編號）。已以 U-NV、U-PR、U-DS 新增候選紀錄，等級 3。 | D7: SRC_候選 原 S 編號＝U-* | E7: —
A8: F07 | B8: S28 的錯誤標示 | C8: S28 寫「H100 FP8 989 TF」，989 實為 BF16 dense（E001 已更正 FP8 為 1,979）。拆成兩筆：H100 BF16 0.989（S28）與 H100 FP8 1.979（E001），兩者皆 Active，無取代關係。 | D8: SRC_HW | E8: —
A9: F08 | B9: 能力指數版本混用 | C9: Cap_In 市場表同時使用 AA Index v4.3（Astra、Anthropic、V4-Pro、GLM-Flash、Qwen）與 v4.3.2（Luna、Sol、V4.1-Flash、GLM-5.3）。K3 寫「全表固定同一版本」，G4 規定只比同口徑；兩版混用會影響 K2 前緣判定。 | D9: Cap_In I 欄 | E9: G0-4
A10: F09 | B10: 模型名稱對應待查 | C10: 指數 40 來自「Qwen3.8 2.4T」，模型用於 Qwen3.8-Max；指數 36 來自「DeepSeek V4 Pro」，模型用於 V4-Pro-0813。是否同一模型、同一版本未確認。 | D10: Cap_In 53、56 | E10: —
A11: F10 | B11: J3 與來源不一致 | C11: S26 記 GPT-5.6 Sol 約 68 tok/s，J3 與 Serving!D21 用 65。可能是刻意取整或筆誤。 | D11: Serving 21 | E11: G0-3
A12: F11 | B12: InferenceX 單一平台 | C12: Calib 七個錨點全部來自 InferenceX（SemiAnalysis），S22 兩個擬合點只見搜尋摘錄（3 級）。依 Andy 的 SemiAnalysis 規則須第二來源；MLPerf（S31、S32）是現有的第二來源，但量測口徑不同。 | D12: Calib 第 17 列 | E12: —
A13: F12 | B13: 來源等級分布偏低 | C13: 見說明頁統計。Block 1 的機架功率與價格（模型中影響每 GW 成本最大的輸入）全部為 3 級：皆來自轉述或只見摘要。Stage 2 依 CC 敏感度排序，這一組很可能排在最前面。 | D13: Spec_Rack | E13: —
