Workbook

Sheet 逐列檢查
A1: 規則：第 0 段「C3_核心推導列」扣除「C7_m路徑」後屬 3A 工作表的 510 個頁＋列，逐列檢查 L1–L9。「—」＝沒有發現問題（不等於已證明正確）。L3 以 10_mech.py 機械檢查（世代×層級／成本頁之間同欄對位 0 處不符；Interface 層級常數 3*(世代−1)+k 對列標籤 0 處不符）；L7 以 20_l7_closure.py 在 4 個端點情境重算（文字或 0）；L8「直接」＝本列公式直接引用第 1 段 Y1–Y9 輸入格，「上游」＝依賴圖上游任一處含 Y 類輸入。G 編號對應報告第 3 節。嚴重度：高＝直接作用在下游契約名稱的口徑或閉合問題；中＝其他 L1–L9；低＝結構或顯示；資訊＝只有 L8。只標問題，不判定對錯、不提修法。
A2: 頁 | B2: 列 | C2: 列標籤 | D2: 單位 | E2: 公式格數 | F2: 同列公式結構數（R1C1） | G2: 代表格 | H2: 代表公式 | I2: 代表值 | J2: L1 量綱 | K2: L2 口徑 | L2: L3 引用對位 | M2: L4 重複／漏算 | N2: L5 恆等式與閉合 | O2: L6 倒推 | P2: L7 條件分支 | Q2: L8 與 Y1–Y9 的連結 | R2: L9 物理合理性 | S2: 上游 Y 類 | T2: 直接 Y 類 | U2: 非治理頁下游格數 | V2: G 編號 | W2: 嚴重度
A3: Spec_Rack | B3: 33 | C3: GPU 功率 W/封裝（能量用） | E3: 4 | F3: 4 | G3: C33 | H3: =SRC_HW_056 | I3: 700 | J3: — | K3: — | L3: — | M3: — | N3: — | O3: — | P3: — | Q3: — | R3: [G23] RU 3,600 W／封裝為推估（Interested-party；只進能量下限）；F 欄以 SRC_HW_046×1000，其他欄為單一 SRC | U3: 64 | V3: G23 | W3: 低
A4: Spec_Rack | B4: 34 | C4: HBM 存取能量 pJ/byte | E4: 1 | F4: 1 | G4: F34 | H4: =SRC_HW_034*8 | I4: 20 | J4: — | K4: — | L4: — | M4: — | N4: — | O4: — | P4: — | Q4: — | R4: — | U4: 64 | W4: —
A5: Spec_Rack | B5: 40 | C5: FP8 dense PF/GPU（訓練基準，J7） | E5: 4 | F5: 3 | G5: C40 | H5: =SRC_HW_040 | I5: 1.979 | J5: — | K5: — | L5: — | M5: — | N5: — | O5: — | P5: — | Q5: — | R5: — | U5: 65 | W5: —
A6: Serving | B6: 15 | C6: 快取命中 KV 載入頻寬 | D6: TB/s/GPU | E6: 0 | F6: 0 | J6: — | K6: — | L6: — | M6: — | N6: — | O6: — | P6: — | Q6: — | R6: — | U6: 64 | W6: —
A7: Workload | B7: 5 | C7: 輪數 T | D7: 輪 | E7: 0 | F7: 0 | J7: — | K7: — | L7: — | M7: — | N7: — | O7: — | P7: — | Q7: — | R7: — | U7: 32 | W7: —
A8: Workload | B8: 6 | C8: 初始上下文 S（系統提示、歷史、工具定義） | D8: tok | E8: 0 | F8: 0 | J8: — | K8: — | L8: — | M8: — | N8: — | O8: — | P8: — | Q8: — | R8: — | U8: 69 | W8: —
A9: Workload | B9: 7 | C9: 每輪新輸入 u（使用者或工具結果） | D9: tok | E9: 0 | F9: 0 | J9: — | K9: — | L9: — | M9: — | N9: — | O9: — | P9: — | Q9: — | R9: — | U9: 69 | W9: —
A10: Workload | B10: 8 | C10: 每輪思考 token h | D10: tok | E10: 0 | F10: 0 | J10: — | K10: — | L10: — | M10: — | N10: — | O10: — | P10: — | Q10: 直接引用 Y5 類輸入 | R10: — | S10: Y5 | T10: Y5 | U10: 32 | W10: 資訊（只有 L8）
A11: Workload | B11: 9 | C11: 每輪可見輸出 o | D11: tok | E11: 0 | F11: 0 | J11: — | K11: — | L11: — | M11: — | N11: — | O11: — | P11: — | Q11: — | R11: — | U11: 74 | W11: —
A12: Workload | B12: 10 | C12: 思考保留於上下文比例 ρ | D12: % | E12: 0 | F12: 0 | J12: — | K12: — | L12: — | M12: — | N12: — | O12: — | P12: — | Q12: — | R12: — | U12: 10 | W12: —
A13: Workload | B13: 11 | C13: 歷史快取命中率 χ | D13: % | E13: 0 | F13: 0 | J13: — | K13: — | L13: — | M13: — | N13: — | O13: — | P13: — | Q13: — | R13: — | U13: 32 | W13: —
A14: Workload | B14: 12 | C14: 並行子代理數 m | D14: 個 | E14: 0 | F14: 0 | J14: — | K14: — | L14: — | M14: — | N14: — | O14: — | P14: — | Q14: — | R14: — | U14: 66 | W14: —
A15: Workload | B15: 13 | C15: harness token 倍數 | D15: x | E15: 0 | F15: 0 | J15: — | K15: — | L15: — | M15: — | N15: [G16] harness token 倍數標為「殘差倍數」（基準 1） | O15: — | P15: — | Q15: — | R15: — | U15: 66 | V15: G16 | W15: 低
A16: Workload | B16: 14 | C16: 歷史保留比 c（壓縮後保留的歷史比例；1＝不壓縮） | D16: x | E16: 0 | F16: 0 | J16: — | K16: — | L16: — | M16: — | N16: — | O16: — | P16: — | Q16: — | R16: — | U16: 10 | W16: —
A17: Workload | B17: 18 | C17: 有效輪數 T | D17: 輪 | E17: 5 | F17: 5 | G17: C18 | H17: =C5*(1+B5_W*(INDEX(B5_SelT,1,1)-1)) | I17: 1 | J17: — | K17: — | L17: — | M17: — | N17: — | O17: — | P17: — | Q17: — | R17: — | U17: 20 | W17: —
A18: Workload | B18: 19 | C18: 有效每輪思考 h | D18: tok | E18: 5 | F18: 5 | G18: C19 | H18: =C8*(1+B5_W*(INDEX(B5_SelH,1,1)-1)) | I18: 0 | J18: — | K18: — | L18: — | M18: — | N18: — | O18: — | P18: — | Q18: 直接引用 Y5 類輸入 | R18: — | S18: Y5 | T18: Y5 | U18: 20 | W18: 資訊（只有 L8）
A19: Workload | B19: 20 | C19: 有效思考保留 ρ | D19: % | E19: 5 | F19: 5 | G19: C20 | H19: =C10+B5_W*(INDEX(B5_Selrho,1,1)-C10) | I19: 0 | J19: — | K19: — | L19: — | M19: — | N19: — | O19: — | P19: — | Q19: — | R19: — | U19: 5 | W19: —
A20: Workload | B20: 21 | C20: 有效快取命中 χ | D20: % | E20: 5 | F20: 5 | G20: C21 | H20: =MIN(1,MAX(0,C11+B5_W*INDEX(B5_SelDChi,1,1))) | I20: 0.5 | J20: — | K20: — | L20: — | M20: — | N20: — | O20: — | P20: [G16] MIN(1,MAX(0,…)) 截斷：harness 檔案 Δχ 使 χ 超出 0–1 時無提示 | Q20: — | R20: — | U20: 5 | V20: G16 | W20: 低
A21: Workload | B21: 22 | C21: 有效子代理數 m | D21: 個 | E21: 5 | F21: 5 | G21: C22 | H21: =C12+B5_W*INDEX(B5_SelDM,1,1) | I21: 0 | J21: — | K21: — | L21: — | M21: — | N21: — | O21: — | P21: — | Q21: — | R21: — | U21: 5 | W21: —
A22: Workload | B22: 23 | C22: 有效歷史保留比 c | D22: x | E22: 5 | F22: 5 | G22: C23 | H22: =C14+B5_W*(INDEX(B5_SelC,1,1)-C14) | I22: 1 | J22: — | K22: — | L22: — | M22: — | N22: — | O22: — | P22: — | Q22: — | R22: — | U22: 15 | W22: —
A23: Workload | B23: 26 | C23: 每輪上下文增量 u＋o＋ρh | D23: tok | E23: 5 | F23: 1 | G23: C26 | H23: =C7+C9+C20*C19 | I23: 1000 | J23: — | K23: [G16] 任務 token 結構（例：一般聊天輸入 2,500、輸出 500、思考 0）與 Serving 參考請求（Luna ISL 8,192／OSL 1,024 含思考）是兩套獨立定義，分別進每成功任務成本與每 M token 單價（與 Y6 同類） | L23: — | M23: — | N23: — | O23: — | P23: — | Q23: 上游含 Y5 | R23: — | S23: Y5 | U23: 15 | V23: G16 | W23: 中
A24: Workload | B24: 27 | C24: 單代理輸入總量 | D24: tok | E24: 5 | F24: 1 | G24: C27 | H24: =C18*(C6+C7)+C23*C26*C18*(C18-1)/2 | I24: 2500 | J24: — | K24: [G16] 任務 token 結構（例：一般聊天輸入 2,500、輸出 500、思考 0）與 Serving 參考請求（Luna ISL 8,192／OSL 1,024 含思考）是兩套獨立定義，分別進每成功任務成本與每 M token 單價（與 Y6 同類） | L24: — | M24: — | N24: — | O24: — | P24: — | Q24: 上游含 Y5 | R24: — | S24: Y5 | U24: 5 | V24: G16 | W24: 中
A25: Workload | B25: 28 | C25: 其中可快取（前綴） | D25: tok | E25: 5 | F25: 1 | G25: C28 | H25: =C21*(C18*C6+C23*C26*C18*(C18-1)/2) | I25: 1000 | J25: — | K25: [G16] 任務 token 結構（例：一般聊天輸入 2,500、輸出 500、思考 0）與 Serving 參考請求（Luna ISL 8,192／OSL 1,024 含思考）是兩套獨立定義，分別進每成功任務成本與每 M token 單價（與 Y6 同類） | L25: — | M25: — | N25: — | O25: — | P25: — | Q25: 上游含 Y5 | R25: — | S25: Y5 | U25: 10 | V25: G16 | W25: 中
A26: Workload | B26: 29 | C26: 其中新鮮 | D26: tok | E26: 5 | F26: 1 | G26: C29 | H26: =C27-C28 | I26: 1500 | J26: — | K26: [G16] 任務 token 結構（例：一般聊天輸入 2,500、輸出 500、思考 0）與 Serving 參考請求（Luna ISL 8,192／OSL 1,024 含思考）是兩套獨立定義，分別進每成功任務成本與每 M token 單價（與 Y6 同類） | L26: — | M26: — | N26: — | O26: — | P26: — | Q26: 上游含 Y5 | R26: — | S26: Y5 | U26: 5 | V26: G16 | W26: 中
A27: Workload | B27: 30 | C27: 單代理 decode（思考＋可見） | D27: tok | E27: 5 | F27: 1 | G27: C30 | H27: =C18*(C19+C9) | I27: 500 | J27: — | K27: [G16] 任務 token 結構（例：一般聊天輸入 2,500、輸出 500、思考 0）與 Serving 參考請求（Luna ISL 8,192／OSL 1,024 含思考）是兩套獨立定義，分別進每成功任務成本與每 M token 單價（與 Y6 同類） | L27: — | M27: — | N27: — | O27: — | P27: — | Q27: 上游含 Y5 | R27: — | S27: Y5 | U27: 5 | V27: G16 | W27: 中
A28: Workload | B28: 31 | C28: 系統倍數（1＋m）× harness 殘差倍數 | D28: x | E28: 5 | F28: 1 | G28: C31 | H28: =(1+C22)*C13 | I28: 1 | J28: — | K28: — | L28: — | M28: — | N28: — | O28: — | P28: — | Q28: — | R28: — | U28: 15 | W28: —
A29: Workload | B29: 32 | C29: 任務新鮮 prefill | D29: tok | E29: 5 | F29: 1 | G29: C32 | H29: =C29*C31 | I29: 1500 | J29: — | K29: — | L29: — | M29: — | N29: — | O29: — | P29: — | Q29: 上游含 Y5 | R29: — | S29: Y5 | U29: 55 | W29: 資訊（只有 L8）
A30: Workload | B30: 33 | C30: 任務快取 prefill | D30: tok | E30: 5 | F30: 1 | G30: C33 | H30: =C28*C31 | I30: 1000 | J30: — | K30: — | L30: — | M30: — | N30: — | O30: — | P30: — | Q30: 上游含 Y5 | R30: — | S30: Y5 | U30: 55 | W30: 資訊（只有 L8）
A31: Workload | B31: 34 | C31: 任務 decode | D31: tok | E31: 5 | F31: 1 | G31: C34 | H31: =C30*C31 | I31: 500 | J31: — | K31: — | L31: — | M31: — | N31: — | O31: — | P31: — | Q31: 上游含 Y5 | R31: — | S31: Y5 | U31: 55 | W31: 資訊（只有 L8）
A32: Workload | B32: 35 | C32: 任務總 token | D32: tok | E32: 5 | F32: 1 | G32: C35 | H32: =C32+C33+C34 | I32: 3000 | J32: — | K32: [G16] 任務 token 結構（例：一般聊天輸入 2,500、輸出 500、思考 0）與 Serving 參考請求（Luna ISL 8,192／OSL 1,024 含思考）是兩套獨立定義，分別進每成功任務成本與每 M token 單價（與 Y6 同類） | L32: — | M32: — | N32: — | O32: — | P32: — | Q32: 上游含 Y5 | R32: — | S32: Y5 | U32: 15 | V32: G16 | W32: 中
A33: Calib | B33: 26 | C33: EP 通訊頻寬 | D33: TB/s | E33: 7 | F33: 1 | G33: C26 | H33: =INDEX(Spec_Rack!$C$27:$G$27,C10) | I33: 0.9 | J33: — | K33: — | L33: — | M33: — | N33: — | O33: — | P33: — | Q33: — | R33: — | U33: 8 | W33: —
A34: Calib | B34: 32 | C34: d_model | E34: 7 | F34: 1 | G34: C32 | H34: =Arch!$D$9 | I34: 7168 | J34: — | K34: — | L34: — | M34: — | N34: — | O34: — | P34: — | Q34: — | R34: — | U34: 8 | W34: —
A35: Calib | B35: 33 | C35: 啟用專家 | E35: 7 | F35: 1 | G35: C33 | H35: =Arch!$D$13 | I35: 6 | J35: — | K35: — | L35: — | M35: — | N35: — | O35: — | P35: — | Q35: — | R35: — | U35: 8 | W35: —
A36: Calib | B36: 36 | C36: KV bytes/token | D36: B | E36: 7 | F36: 1 | G36: C36 | H36: =Arch!$D$25 | I36: 3965 | J36: — | K36: — | L36: — | M36: — | N36: — | O36: — | P36: — | Q36: 上游含 Y1 | R36: — | S36: Y1 | U36: 15 | W36: 資訊（只有 L8）
A37: Calib | B37: 75 | C37: η_d（該世代） | D37: % | E37: 7 | F37: 1 | G37: C75 | H37: =INDEX($C$70:$G$70,C10) | I37: 0.035755 | J37: — | K37: — | L37: — | M37: — | N37: — | O37: [G05] 驗證點以擬合值重算；擬合點本身恆等，樣本外點 E／H／I 為 0.99／1.00／0.88，F／G（舊軟體）2.18／4.11；七點全部同一平台（J19） | P37: — | Q37: 上游含 Y5,Y8 | R37: — | S37: Y5,Y8 | U37: 7 | V37: G05 | W37: 中
A38: Calib | B38: 76 | C38: 每層延遲（該世代） | D38: µs | E38: 7 | F38: 1 | G38: C76 | H38: =INDEX($C$71:$G$71,C10) | I38: 161.18534 | J38: — | K38: — | L38: — | M38: — | N38: — | O38: [G05] 驗證點以擬合值重算；擬合點本身恆等，樣本外點 E／H／I 為 0.99／1.00／0.88，F／G（舊軟體）2.18／4.11；七點全部同一平台（J19） | P38: — | Q38: 上游含 Y5,Y8 | R38: — | S38: Y5,Y8 | U38: 7 | V38: G05 | W38: 中
A39: Calib | B39: 77 | C39: η_p（該世代） | D39: % | E39: 7 | F39: 1 | G39: C77 | H39: =INDEX($C$72:$G$72,C10) | I39: 0.3 | J39: — | K39: — | L39: — | M39: — | N39: — | O39: [G05] 驗證點以擬合值重算；擬合點本身恆等，樣本外點 E／H／I 為 0.99／1.00／0.88，F／G（舊軟體）2.18／4.11；七點全部同一平台（J19） | P39: — | Q39: 上游含 Y5,Y8 | R39: — | S39: Y5,Y8 | U39: 7 | V39: G05 | W39: 中
A40: Calib | B40: 78 | C40: prefill tok/s/GPU | D40: tok/s | E40: 7 | F40: 1 | G40: C78 | H40: =C77*C23*1000000000000000/(C47*1000000000) | I40: 34214.061 | J40: — | K40: — | L40: — | M40: — | N40: — | O40: [G05] 驗證點以擬合值重算；擬合點本身恆等，樣本外點 E／H／I 為 0.99／1.00／0.88，F／G（舊軟體）2.18／4.11；七點全部同一平台（J19） | P40: — | Q40: 上游含 Y5,Y8 | R40: — | S40: Y5,Y8 | U40: 7 | V40: G05 | W40: 中
...

Sheet 傳遞強度
A1: 規則：嚴重度「高」的問題（G01–G06、G14、G15），估計對下游契約名稱（docs/plan/Tokenomics_downstream_contract.md：IF_／IFW_／L1_）的影響方向與大小。結構量直接由工作簿數值計算；端點擾動以第 2 段 20_eval.py（工作簿公式原文求值；3A 5,628 格對快取值 0 不符；LibreOffice 1 次 27 格 0 不符）單一輸入取 Gov_Map 區間端點、其他不變重算。「替代讀法」只重組工作簿數值，不是活頁簿機制，只用來顯示大小。G05（η_p）、G15（B4_Serve、B4_Free）的大小見端點列。
A2: G 編號 | B2: 問題 | C2: 受影響的契約名稱 | D2: 方向 | E2: 大小 | F2: 方法
A3: G01 | B3: 由上而下攤提閉合 0.82–0.88（Amortize 39） | C3: IF_AmortTD_*、IF_AmortDefault_*、IF_AmortRev_*、IF_FullCostDefault_* | D3: 偏低 | E3: Hopper 閉合 0.820（閉合到訓練 GW × 持有成本時攤提 +22%）；GB200 閉合 0.874（閉合到訓練 GW × 持有成本時攤提 +14%）；GB300 閉合 0.881（閉合到訓練 GW × 持有成本時攤提 +14%）；VR200 閉合 0.859（閉合到訓練 GW × 持有成本時攤提 +16%）；Rubin 閉合 0.855（閉合到訓練 GW × 持有成本時攤提 +17%） | F3: 結構量（不擾動）；χ＝0 時閉合 1.00（Python 與 LibreOffice 各 1 次）
A4: G02 | B4: 自下而上攤提分母含免費 token（Amortize 13／22／32） | C4: IF_AmortBU_*、IF_FullCost_*、IF_AmortDefault_*、IF_FullCostDefault_* | D4: 偏低（以付費 token 為分母時） | E4: Hopper Luna：分母比 8.42，IF_FullCost +46%、IF_FullCostDefault +94%；Hopper Sol：分母比 1.73，IF_FullCost +14%、IF_FullCostDefault +25%；Hopper Astra：分母比 1.00，IF_FullCost +0%、IF_FullCostDefault +0%；VR200 Luna：分母比 7.46，IF_FullCost +10%、IF_FullCostDefault +75%；VR200 Sol：分母比 1.64，IF_FullCost +4%、IF_FullCostDefault +21%；VR200 Astra：分母比 1.00，IF_FullCost +0%、IF_FullCostDefault +0% | F4: 替代讀法（只重組工作簿數值；33_alt.py）
A5: G03 | B5: _Prod 層 token 線性 0.85、營收重解 SLO | C5: IFW_TokGW_*_Prod、IFW_RevGW*_Prod | D5: token 層偏高（相對營收層） | E5: IFW_RevGW_Sol：Hopper 0.730、GB200 0.798、GB300 0.798、VR200 0.808、Rubin 0.810；IFW_RevGW_Astra：Hopper 0.486、GB200 0.733、GB300 0.699、VR200 0.766、Rubin 0.776；IFW_RevGWFleet：Hopper 0.560、GB200 0.758、GB300 0.732、VR200 0.782、Rubin 0.789；IFW_TokGW_Sol：Hopper 0.850、GB200 0.850、GB300 0.850、VR200 0.850、Rubin 0.850 | F5: 結構量（_Prod ÷ _Util）
A6: G04 | B6: 兩組 _Life（IF_ 不含折減、IFW_ 含重解折減） | C6: IF_RevGW_*_Life、IF_RevGWFleet_Life 對 IFW_*_Life | D6: IF_ 組偏高 | E6: IFW_RevGW_Luna_Life：Hopper 0.685、GB200 0.782、GB300 0.782、VR200 0.787、Rubin 0.788；IFW_RevGW_Sol_Life：Hopper 0.730、GB200 0.798、GB300 0.798、VR200 0.808、Rubin 0.810；IFW_RevGW_Astra_Life：Hopper 0.486、GB200 0.733、GB300 0.699、VR200 0.766、Rubin 0.776；IFW_RevGWFleet_Life：Hopper 0.560、GB200 0.758、GB300 0.732、VR200 0.782、Rubin 0.789 | F6: 結構量（IFW ÷ IF）
A7: G06 | B7: 組合旗標使可達層級也變文字；單一層級列變 0 | C7: IF_AmortBU_*、IF_AmortDefault_*、IF_FullCost*、IFW_RevGWFleet*；IFW_TokGW_Astra_*、IFW_RevGW_Astra_* 等 | D7: 文字／0 | E7: Serving!C18=0.7：變文字 28 個名稱、變 0 13 個名稱；Arch!E8=160：變文字 31 個名稱、變 0 13 個名稱；Calib!C68=3：變文字 37 個名稱、變 0 39 個名稱；Serving!D21,E21=100：變文字 34 個名稱、變 0 26 個名稱 | F7: 4 個 L7 情境（20_l7_closure.py）
A8: G14 | B8: 縮放倍數 2.2–12.0；預設攤提總額由 B4_Serve 決定 | C8: IF_AmortDefault_*、IF_FullCostDefault_* | D8: 視 B4_Serve | E8: 見下方 A02 列（B4_Serve 0.3／0.6） | F8: 端點擾動
A9: 端點 | B9: A01／Y11 快取命中 χ（Cap_In C13） | C9: IF_AmortTD_Sol（VR200 基準）、IF_FullCost_Sol（VR200 基準）、IF_AmortDefault_Sol（VR200 基準）、IF_FullCostDefault_Sol（VR200 基準）、IF_FullCostDefault_Luna（Hopper 基準）、IFW_RevGW_Sol_Prod（VR200）、IFW_RevGWFleet_Prod（Hopper 基準）、IFW_RevGWFleet_Prod（VR200 基準）、縮放倍數 Amortize!M41 | D9: 低端／高端 | E9: IF_AmortTD_Sol（VR200 基準） +8.6%／-6.9%；IF_FullCost_Sol（VR200 基準） +8.1%／-6.5%；IF_AmortDefault_Sol（VR200 基準） +7.4%／-6.0%；IF_FullCostDefault_Sol（VR200 基準） +8.2%／-6.6%；IF_FullCostDefault_Luna（Hopper 基準） +11.6%／-9.3%；IFW_RevGW_Sol_Prod（VR200） +19.9%／-15.9%；IFW_RevGWFleet_Prod（Hopper 基準） +19.9%／-15.9%；IFW_RevGWFleet_Prod（VR200 基準） +19.9%／-15.9%；縮放倍數 Amortize!M41 +7.4%／-6.0% | F9: 單一輸入端點 0.3／0.75；20_eval.py
A10: 端點 | B10: A02／Y11 對外服務占機隊（Cap_In C28） | C10: IF_AmortBU_Sol（VR200 基準）、IF_AmortTD_Sol（VR200 基準）、IF_FullCost_Sol（VR200 基準）、IF_AmortDefault_Sol（VR200 基準）、IF_FullCostDefault_Sol（VR200 基準）、IF_AmortBU_Luna（Hopper 基準）、IF_FullCostDefault_Luna（Hopper 基準）、IFW_RevGWFleet_Prod（Hopper 基準）、IFW_RevGWFleet_Prod（VR200 基準）、縮放倍數 Amortize!M41 | D10: 低端／高端 | E10: IF_AmortBU_Sol（VR200 基準） +36.7%／-31.7%；IF_AmortTD_Sol（VR200 基準） +62.1%／-53.7%；IF_FullCost_Sol（VR200 基準） +2.1%／-1.8%；IF_AmortDefault_Sol（VR200 基準） +62.1%／-53.7%；IF_FullCostDefault_Sol（VR200 基準） +20.3%／-17.5%；IF_AmortBU_Luna（Hopper 基準） +36.7%／-31.7%；IF_FullCostDefault_Luna（Hopper 基準） +7.8%／-6.8%；IFW_RevGWFleet_Prod（Hopper 基準） -26.8%／+46.3%；IFW_RevGWFleet_Prod（VR200 基準） -26.8%／+46.3%；縮放倍數 Amortize!M41 +18.6%／-32.2% | F10: 單一輸入端點 0.3／0.6；20_eval.py
A11: 端點 | B11: A03／Y11 免費占服務（Cap_In C29） | C11: IF_AmortBU_Sol（VR200 基準）、IF_FullCost_Sol（VR200 基準）、IF_AmortDefault_Sol（VR200 基準）、IF_FullCostDefault_Sol（VR200 基準）、IF_AmortBU_Luna（Hopper 基準）、IF_FullCostDefault_Luna（Hopper 基準）、IFW_RevGWFleet_Prod（Hopper 基準）、IFW_RevGWFleet_Prod（VR200 基準）、縮放倍數 Amortize!M41 | D11: 低端／高端 | E11: IF_AmortBU_Sol（VR200 基準） -3.0%／+4.1%；IF_FullCost_Sol（VR200 基準） -0.2%／+0.2%；IF_AmortDefault_Sol（VR200 基準） -2.8%／+3.8%；IF_FullCostDefault_Sol（VR200 基準） -0.9%／+1.2%；IF_AmortBU_Luna（Hopper 基準） +22.9%／-19.2%；IF_FullCostDefault_Luna（Hopper 基準） +3.0%／-2.5%；IFW_RevGWFleet_Prod（Hopper 基準） +20.4%／-25.9%；IFW_RevGWFleet_Prod（VR200 基準） +20.4%／-25.9%；縮放倍數 Amortize!M41 +0.2%／-0.3% | F11: 單一輸入端點 0.35／0.6；20_eval.py
A12: 端點 | B12: A02 研發倍數（Train_In C13） | C12: IF_AmortBU_Sol（VR200 基準）、IF_FullCost_Sol（VR200 基準）、IF_AmortBU_Luna（Hopper 基準）、IF_ProgCost_Sol（VR200 基準）、縮放倍數 Amortize!M41 | D12: 低端／高端 | E12: IF_AmortBU_Sol（VR200 基準） -45.0%／+30.0%；IF_FullCost_Sol（VR200 基準） -2.5%／+1.7%；IF_AmortBU_Luna（Hopper 基準） -45.0%／+30.0%；IF_ProgCost_Sol（VR200 基準） -45.0%／+30.0%；縮放倍數 Amortize!M41 +81.8%／-23.1% | F12: 單一輸入端點 4.4／10.4；20_eval.py
A13: 端點 | B13: A04／Y10 生產折減（Serving C28） | C13: IFW_TokGW_Sol_Prod（VR200）、IFW_RevGW_Sol_Prod（VR200）、IFW_RevGWFleet_Prod（Hopper 基準）、IFW_RevGWFleet_Prod（VR200 基準） | D13: 低端／高端 | E13: IFW_TokGW_Sol_Prod（VR200） -17.6%／+17.6%；IFW_RevGW_Sol_Prod（VR200） -24.1%／+23.8%；IFW_RevGWFleet_Prod（Hopper 基準） —／+78.6%；IFW_RevGWFleet_Prod（VR200 基準） -28.7%／+27.8% | F13: 單一輸入端點 0.7／1.0；20_eval.py
... A18: 端點 | B18: A07 平均用電 ÷ 設計功率（Inputs E10） | C18: IF_CostDec_Sol（VR200 基準）、IF_CostPre_Sol（VR200 基準）、IF_AmortBU_Sol（VR200 基準）、IF_AmortTD_Sol（VR200 基準）、IF_FullCost_Sol（VR200 基準）、IF_AmortDefault_Sol（VR200 基準）、IF_FullCostDefault_Sol（VR200 基準）、IF_AmortBU_Luna（Hopper 基準）、IF_FullCostDefault_Luna（Hopper 基準）、IF_ProgCost_Sol（VR200 基準）、IF_TokPerJ_Sol（VR200） | D18: 低端／高端 | E18: IF_CostDec_Sol（VR200 基準） -0.7%／+0.7%；IF_CostPre_Sol（VR200 基準） -0.7%／+0.7%；IF_AmortBU_Sol（VR200 基準） -0.7%／+0.7%；IF_AmortTD_Sol（VR200 基準） -0.7%／+0.7%；IF_FullCost_Sol（VR200 基準） -0.7%／+0.7%；IF_AmortDefault_Sol（VR200 基準） -0.7%／+0.7%；IF_FullCostDefault_Sol（VR200 基準） -0.7%／+0.7%；IF_AmortBU_Luna（Hopper 基準） -0.9%／+0.9%；IF_FullCostDefault_Luna（Hopper 基準） -0.9%／+0.9%；IF_ProgCost_Sol（VR200 基準） -0.7%／+0.7%；IF_TokPerJ_Sol（VR200） +14.3%／-11.1% | F18: 單一輸入端點 0.7／0.9；20_eval.py

Sheet 高嚴重度
A1: 規則：「逐列檢查」頁嚴重度＝高的列（直接作用在下游契約名稱的口徑或閉合問題）。只標問題，不判定對錯、不提修法。
A2: 頁 | B2: 列 | C2: 列標籤 | D2: G 編號 | E2: L2 | F2: L4 | G2: L5 | H2: L6 | I2: L7 | J2: L9 | K2: L8
A3: Calib | B3: 86 | C3: 模型 ÷ 實測 | D3: G05 | E3: — | F3: — | G3: [G05] Calib D 節以兩個擬合點聯立解兩個未知數（η_d、每層延遲），F 節擬合點「模型 ÷ 實測」恆為 1.00（Checks B14），是代數恆等，不是驗證。η_d＝3.58% 是吸收未建模開銷的擬合係數，比一般 GEMM 達成率低一個數量級以上（L9）。J5 說明「擬合結果對 η_p 不敏感」，但 G 節顯示 η_p 0.15／0.3／0.45 → η_d 0.055／0.036／0.032、每層延遲 175／161／157 µs；S3：η_p 端點 → IF_CostPre_Sol（VR200）+100%／−33%、IF_CostDec_Sol −33%／+11%、IFW_RevGWFleet_Prod（Hopper）−30%／+8% | H3: — | I3: — | J3: [G05] 擬合 η_d 3.58%（GB300、Sol）；Perf 推出的 decode 有效 MFU（含草稿驗證）全部 15 欄 1.0–2.5% | K3: 上游含 Y1,Y5,Y8
A4: Fleet_1GW | B4: 10 | C4: 對外服務 | D4: G15 | E4: [G15] 1 GW 參考機隊的服務／免費／訓練占比＝2025 OpenAI 支出比（B4_Serve 0.41、B4_Free 0.46），全部世代同值（Y11；與第 1 段 Y3 同源） | F4: — | G4: — | H4: — | I4: — | J4: — | K4: 直接引用 Y3 類輸入
A5: Fleet_1GW | B5: 12 | C5: 免費服務 | D5: G15 | E5: [G15] 1 GW 參考機隊的服務／免費／訓練占比＝2025 OpenAI 支出比（B4_Serve 0.41、B4_Free 0.46），全部世代同值（Y11；與第 1 段 Y3 同源） | F5: — | G5: — | H5: — | I5: — | J5: — | K5: 直接引用 Y3 類輸入
A6: Fleet_1GW | B6: 13 | C6: 訓練＋研發 | D6: G15 | E6: [G15] 1 GW 參考機隊的服務／免費／訓練占比＝2025 OpenAI 支出比（B4_Serve 0.41、B4_Free 0.46），全部世代同值（Y11；與第 1 段 Y3 同源） | F6: — | G6: — | H6: — | I6: — | J6: — | K6: 直接引用 Y3 類輸入
A7: Fleet_1GW | B7: 33 | C7: 家族研發計畫占 1 GW 年（三層級合計） | D7: G14 | E7: — | F7: — | G7: — | H7: — | I7: — | J7: [G14] 隱含每 GW 年家族研發計畫 3.4（Hopper）–12.1（VR200），活頁簿自己的參考範圍 1–3（Checks B51，只顯示） | K7: 上游含 Y1,Y5,Y8
A8: Fleet_1GW | B8: 34 | C8: 隱含每 GW 年可容納的家族研發計畫數（訓練＋研發 ÷ 家族計畫） | D8: G14 | E8: — | F8: — | G8: — | H8: — | I8: — | J8: [G14] 隱含每 GW 年家族研發計畫 3.4（Hopper）–12.1（VR200），活頁簿自己的參考範圍 1–3（Checks B51，只顯示） | K8: 上游含 Y1,Y3,Y5,Y8
A9: Amortize | B9: 13 | C9: 自下而上攤提＝回本所需單價溢價 [IF_AmortBU_Luna] | D9: G02,G06 | E9: [G02] 自下而上攤提＝研發計畫成本 ÷ 壽命內「付費＋免費」token，列標籤卻是「回本所需單價溢價」：免費 token 不付費，以付費 token 為分母時 Luna 溢價為 8.4 倍（Hopper）／7.5 倍（VR200）、Sol 1.6–1.8 倍、Astra 1.0 倍（免費組合 Astra 0%）（30_s3.json BU_denominator_ratio） | F9: — | G9: — | H9: — | I9: [G06] 組合旗標使本列在任一層級不可達時變文字，包括可達層級（20_l7_closure.json） | J9: — | K9: 上游含 Y1,Y2,Y3,Y4,Y5,Y6,Y7,Y8
A10: Amortize | B10: 15 | C10: 由上而下攤提 [IF_AmortTD_Luna] | D10: G01,G06 | E10: — | F10: [G01] 由上而下溢價＝訓練占比 ÷（1 − 訓練占比）× 服務成本（快取混合）；因服務成本 × 服務 token ≠ 服務 GW × 持有成本，攤提總額少計 12–18%（見 Amortize 第 39 列） | G10: — | H10: — | I10: [G06] 組合旗標使本列在任一層級不可達時變文字，包括可達層級（20_l7_closure.json） | J10: — | K10: 上游含 Y1,Y2,Y3,Y4,Y5,Y6,Y7,Y8
A11: Amortize | B11: 22 | C11: 自下而上攤提＝回本所需單價溢價 [IF_AmortBU_Sol] | D11: G02,G06 | E11: [G02] 自下而上攤提＝研發計畫成本 ÷ 壽命內「付費＋免費」token，列標籤卻是「回本所需單價溢價」：免費 token 不付費，以付費 token 為分母時 Luna 溢價為 8.4 倍（Hopper）／7.5 倍（VR200）、Sol 1.6–1.8 倍、Astra 1.0 倍（免費組合 Astra 0%）（30_s3.json BU_denominator_ratio） | F11: — | G11: — | H11: — | I11: [G06] 組合旗標使本列在任一層級不可達時變文字，包括可達層級（20_l7_closure.json） | J11: — | K11: 上游含 Y1,Y2,Y3,Y4,Y5,Y6,Y7,Y8
A12: Amortize | B12: 24 | C12: 由上而下攤提 [IF_AmortTD_Sol] | D12: G01,G06 | E12: — | F12: [G01] 由上而下溢價＝訓練占比 ÷（1 − 訓練占比）× 服務成本（快取混合）；因服務成本 × 服務 token ≠ 服務 GW × 持有成本，攤提總額少計 12–18%（見 Amortize 第 39 列） | G12: — | H12: — | I12: [G06] 組合旗標使本列在任一層級不可達時變文字，包括可達層級（20_l7_closure.json） | J12: — | K12: 上游含 Y1,Y2,Y3,Y4,Y5,Y6,Y7,Y8
A13: Amortize | B13: 32 | C13: 自下而上攤提＝回本所需單價溢價 [IF_AmortBU_Astra] | D13: G02,G06 | E13: [G02] 自下而上攤提＝研發計畫成本 ÷ 壽命內「付費＋免費」token，列標籤卻是「回本所需單價溢價」：免費 token 不付費，以付費 token 為分母時 Luna 溢價為 8.4 倍（Hopper）／7.5 倍（VR200）、Sol 1.6–1.8 倍、Astra 1.0 倍（免費組合 Astra 0%）（30_s3.json BU_denominator_ratio） | F13: — | G13: — | H13: — | I13: [G06] 組合旗標使本列在任一層級不可達時變文字，包括可達層級（20_l7_closure.json） | J13: — | K13: 上游含 Y1,Y2,Y3,Y4,Y5,Y6,Y7,Y8
A14: Amortize | B14: 34 | C14: 由上而下攤提 [IF_AmortTD_Astra] | D14: G01,G06 | E14: — | F14: [G01] 由上而下溢價＝訓練占比 ÷（1 − 訓練占比）× 服務成本（快取混合）；因服務成本 × 服務 token ≠ 服務 GW × 持有成本，攤提總額少計 12–18%（見 Amortize 第 39 列） | G14: — | H14: — | I14: [G06] 組合旗標使本列在任一層級不可達時變文字，包括可達層級（20_l7_closure.json） | J14: — | K14: 上游含 Y1,Y2,Y3,Y4,Y5,Y6,Y7,Y8
... A53: Interface | B53: 285 | C53: 每 GW 總產出（100%）｜× CTL_ProdDerate（＝Util 列 × CTL_ProdDerate，線性；Interface_Prod 同列為 100% 口徑重解值，保留原處作對照） [IFW_TokGW_Astra_Prod] | D53: G03,G06 | E53: [G03] 每 GW 產出的 _Prod 層＝Util 列 × CTL_ProdDerate（線性 0.85），同一瀑布的營收 _Prod 層（第 235／240／245／250 列）＝重解 SLO 後的值，比 Util 低 0.49–0.81 倍（Hopper Astra 0.486、VR200 Sol 0.808）。同一層名稱，token 與營收的折減方式不同，_Prod 層的營收 ÷ token 不再等於單價。契約第 2 條寫「_Prod＝_Util × CTL_ProdDerate」（線性） | F53: — | G53: — | H53: — | I53: [G06] 單一層級列不可達時輸出 0（數值）而非文字；與組合列的文字處理方式相反（第 2 段 F09） | J53: — | K53: 直接引用 Y5 類輸入

Sheet L9 物理量
A1: 規則：Perf 15 欄（世代 × 成本情境欄依層級）在基準下的中間物理量。decode 有效 MFU＝每 GPU decode tok/s × decode FLOPs/token ×（草稿數＋1）÷ 每步接受 token ÷ 計算用峰值（含草稿驗證）；prefill MFU＝prefill tok/s × prefill FLOPs/token ÷ 峰值；decode HBM 頻寬利用率＝每 GPU decode tok/s × 每接受 token HBM 讀取 ÷ HBM 頻寬。全部由工作簿數值計算（31_l9_closure_cause.py），不新增機制。只顯示，不判定。
A2: 世代 | B2: 層級 | C2: B*（序列/GPU） | D2: decode tok/s/GPU | E2: 每用戶速度 | F2: decode 有效 MFU | G2: prefill MFU | H2: decode HBM 頻寬利用率 | I2: TTFT 計算（s） | J2: TTFT 符合 | K2: tok/J | L2: J/decode token | M2: 能量閉合比 | N2: 權重占可用 HBM
A3: Hopper H100 | B3: Luna | C3: 4.85 | D3: 581.4 | E3: 120 | F3: 0.018 | G3: 0.15 | H3: 0.14 | I3: 0.132 | J3: 是 | K3: 3.19 | L3: 1.763 | M3: 0.037 | N3: 0.136
A4: Hopper H100 | B4: Sol | C4: 2.61 | D4: 169.4 | E4: 65 | F4: 0.018 | G4: 0.15 | H4: 0.268 | I4: 0.917 | J4: 是 | K4: 0.93 | L4: 6.05 | M4: 0.045 | N4: 0.484
A5: Hopper H100 | B5: Astra | C5: 0.45 | D5: 24.6 | E5: 55 | F5: 0.0104 | G5: 0.15 | H5: 0.271 | I5: 6.082 | J5: 否 | K5: 0.17 | L5: 41.712 | M5: 0.038 | N5: 0.568
A6: GB200 NVL72 | B6: Luna | C6: 28.63 | D6: 3435.8 | E6: 120 | F6: 0.021 | G6: 0.3 | H6: 0.065 | I6: 0.026 | J6: 是 | K6: 15.61 | L6: 0.427 | M6: 0.053 | N6: 0.062
A7: GB200 NVL72 | B7: Sol | C7: 15.18 | D7: 986.6 | E7: 65 | F7: 0.0208 | G7: 0.3 | H7: 0.157 | I7: 0.181 | J7: 是 | K7: 4.49 | L7: 1.487 | M7: 0.062 | N7: 0.287
A8: GB200 NVL72 | B8: Astra | C8: 3.07 | D8: 168.6 | E8: 55 | F8: 0.0141 | G8: 0.3 | H8: 0.261 | I8: 1.203 | J8: 是 | K8: 0.86 | L8: 8.699 | M8: 0.06 | N8: 0.537
A9: GB300 NVL72 | B9: Luna | C9: 42.95 | D9: 5153.8 | E9: 120 | F9: 0.021 | G9: 0.3 | H9: 0.067 | I9: 0.017 | J9: 是 | K9: 22.73 | L9: 0.293 | M9: 0.059 | N9: 0.04
A10: GB300 NVL72 | B10: Sol | C10: 22.77 | D10: 1479.9 | E10: 65 | F10: 0.0208 | G10: 0.3 | H10: 0.159 | I10: 0.121 | J10: 是 | K10: 6.53 | L10: 1.021 | M10: 0.067 | N10: 0.185
A11: GB300 NVL72 | B11: Astra | C11: 3.7 | D11: 203.2 | E11: 55 | F11: 0.0114 | G11: 0.3 | H11: 0.342 | I11: 0.802 | J11: 是 | K11: 1.04 | L11: 7.435 | M11: 0.067 | N11: 0.457
A12: VR200 NVL72 | B12: Luna | C12: 106.84 | D12: 12820.4 | E12: 120 | F12: 0.0224 | G12: 0.3 | H12: 0.028 | I12: 0.007 | J12: 是 | K12: 33.3 | L12: 0.197 | M12: 0.046 | N12: 0.04
A13: VR200 NVL72 | B13: Sol | C13: 62.09 | D13: 4035.7 | E13: 65 | F13: 0.0243 | G13: 0.3 | H13: 0.061 | I13: 0.052 | J13: 是 | K13: 10.23 | L13: 0.625 | M13: 0.052 | N13: 0.185
A14: VR200 NVL72 | B14: Astra | C14: 14.18 | D14: 779.6 | E14: 55 | F14: 0.0187 | G14: 0.3 | H14: 0.145 | I14: 0.344 | J14: 是 | K14: 2.2 | L14: 3.235 | M14: 0.053 | N14: 0.457
... A17: Rubin Ultra | B17: Astra | C17: 31.61 | D17: 1738.7 | E17: 55 | F17: 0.0208 | G17: 0.3 | H17: 0.1 | I17: 0.086 | J17: 是 | K17: 3.21 | L17: 2.173 | M17: 0.06 | N17: 0.091
