Workbook

Sheet README
A1: Stage 0 盤點（唯讀）— 20261002_Tokenomics_v5.10.xlsx
A2: 產生程式 | B2: tools/stage0_inventory.py（輸入 xlsx 路徑，輸出本檔；可重跑，不在 CI）
A3: 活頁簿 SHA-256 | B3: d7d59ab8a9c965e9c9a0ed96d7e5a6ba820fbb90adedd146a3542b0ba979497f | F3: 前後一致：是
A5: 目的 | B5: 盤點藍字輸入：依既有標記機械分類、建立靜態依賴圖、以擾動求 load-bearing 排序。分類只是『初步』；待分類與爭議列由 chat 端複核，Andy 核准遷移範圍（Gate 0）。
A6: 母體 | B6: 藍字格＝字型色 RGB 結尾 0000FF、值非空、非公式；盤點單位＝工作表 × 列。藍字但為公式者另列（藍字公式格）。
A8: 初步分類規則（依序，先符合者為準）
A9: R1 | B9: 工作表＝DB_Evidence | C9: Evidence 登錄（非輸入）
A10: R2 | B10: 工作表＝Checks | C10: Checks 外部參照
A11: R3 | B11: 主標記＝Verified 或 Interested-party | C11: 原始數據（候選）
A12: R4 | B12: 主標記＝Analogy／Assumed／Decision | C12: 同主標記
A13: R5 | B13: 主標記＝Derived | C13: Derived 藍字（異常）
A14: R6 | B14: 無標記，且工作表以 Sens_ 開頭、或單位＝「選擇」、或標籤含「索引」 | C14: 情境選擇
A15: R7 | B15: 其餘 | C15: 待分類
A16: 標記擷取 | B16: 標記＝該列所有非公式文字格（含 A、B 欄與藍字文字格）的子字串比對（區分大小寫）：Verified、Interested-party、Analogy、Assumed、Decision、Derived；主標記依序取第一個；兩個以上者標『多標記』。
A17: 擾動方法 | B17: engine（pycel）重算；每列所有數值藍字格同時 ×1.1 與 ×0.9，之後還原；ε₊＝(y₊/y₀−1)/0.1、ε₋＝(1−y₋/y₀)/0.1、ε＝(y₊−y₋)/(y₀×0.2)；單位 % 且 ×1.1>1 者只做 −10%（單邊）。
A18: 整數選擇格（本工具的解讀） | B18: 列屬『情境選擇』、或單位＝選擇、或標籤含『索引』、或標籤含『（1／2／3）』類選項說明，或標籤含『（1＝有）』『（1＝是）』類 0／1 旗標說明時，其中值為整數的藍字格不擾動；同列非整數數值格仍擾動。X2＝該列沒有任何可擾動格。
A19: 不擾動原因代碼 | B19: X1 文字值（列內無數值格）；X2 整數選擇格；X3 基準值為 0；X4 Evidence／Checks 列；X5a 靜態不可達任何 IF_；X5b 可達 IF_ 但未達 O01–O14（彈性記 0）。
A20: 分段（僅供排序閱讀） | B20: 高 ≥ 0.5；中 0.1–0.5；低 < 0.1；無＝0（含未擾動）。分數＝O01–O13 的 |ε| 最大值。門檻由 chat 端日後判斷是否調整。
A22: 期望值核對表（第 2、3.3 節）
A23: 類別 | B23: 項目 | C23: 期望 | D23: 實得 | E23: 差異
A24: 總計 | B24: 藍字列 | C24: 324 | D24: 324 | E24: 0
A25: 總計 | B25: 藍字格 | C25: 1491 | D25: 1491 | E25: 0
A26: 總計 | B26: 藍字公式格 | C26: 31 | D26: 31 | E26: 0
A27: 工作表列數 | B27: Inputs | C27: 26 | D27: 26 | E27: 0
A28: 工作表列數 | B28: Spec_Rack | C28: 22 | D28: 22 | E28: 0
A29: 工作表列數 | B29: Arch | C29: 18 | D29: 18 | E29: 0
A30: 工作表列數 | B30: Serving | C30: 16 | D30: 16 | E30: 0
A31: 工作表列數 | B31: Workload | C31: 11 | D31: 11 | E31: 0
A32: 工作表列數 | B32: Calib | C32: 26 | D32: 26 | E32: 0
A33: 工作表列數 | B33: Tech_Registry | C33: 12 | D33: 12 | E33: 0
A34: 工作表列數 | B34: Perf | C34: 2 | D34: 2 | E34: 0
A35: 工作表列數 | B35: Sens_Perf | C35: 9 | D35: 9 | E35: 0
... A68: 動態引用 | B68: OFFSET／INDIRECT 公式數 | C68: 0 | D68: 0 | E68: 0
A70: 與 builder restore_log 口徑的差異（依工作表）
A71: 工作表 | B71: builder 是否重建 | C71: 本母體藍字格 | D71: restore 快照格 | E71: 差異 | F71: 差異來源
A72: Inputs | B72: 否 | C72: 64 | D72: 0 | E72: 64 | F72: builder 不重建此頁（輸入頁或登錄頁）
A73: Spec_Rack | B73: 是 | C73: 110 | D73: 75 | E73: 35 | F73: 重建頁內不在快照：A 欄藍字（如 Cap_In 模型名稱列）或 Spec_Rack 第 20 列以前（Block 1 區，由 Excel 擁有）
A74: Arch | B74: 是 | C74: 52 | D74: 52 | E74: 0
A75: Serving | B75: 是 | C75: 24 | D75: 24 | E75: 0
A76: Workload | B76: 是 | C76: 53 | D76: 53 | E76: 0
...

Sheet 盤點
A1: INV_ID | B1: 工作表 | C1: 列 | D1: 標籤 | E1: 單位 | F1: 藍字格位址 | G1: 藍字格數 | H1: 基準值 | I1: 全部標記 | J1: 主標記 | K1: 多標記 | L1: 來源編號（S） | M1: 證據編號（E） | N1: 說明原文 | O1: 初步分類 | P1: 分類依據 | Q1: 可達 IF_ 數 | R1: 可達主要輸出 | S1: 最大 |ε| | T1: 分段 | U1: 排名 | V1: 可達公式格數 | W1: 可達工作表 | X1: 不擾動原因 | Y1: chat 複核分類 | Z1: SRC 分頁候選 | AA1: 理由 | AB1: Gate 0 爭議
A2: INV-001 | B2: Inputs | C2: 5 | D2: IT 電力規模 | E2: GW | F2: E5 | G2: 1 | H2: 1 | I2: Decision | J2: Decision | N2: G5: Decision ｜ H5: 口徑：IT 關鍵電力 | O2: Decision | P2: R4 | Q2: 87 | R2: O01、O02、O03、O04、O05、O06、O08、O10、O11、O12、O13、O14 | S2: 1.0007404 | T2: 高 | U2: 10 | V2: 6128 | W2: Amortize、Cache_Store、Capability、Checks、DC_Cost、Fleet_1GW、Harness、Inputs、Interface、Perf、Perf_Batch、Sens_Har、Sens_Perf、Sens_Rev、Sens_Train、Sensitivity、Theory_Rev、Training、Unit_Cost、Workload
A3: INV-002 | B3: Inputs | C3: 6 | D3: 功率情境（1 低／2 基準／3 高） | E3: 選擇 | F3: E6 | G3: 1 | H3: 2 | I3: Decision | J3: Decision | N3: G6: Decision ｜ H6: 決定每架配電設計功率；見 Spec_Rack 第 9–11 列 | O3: Decision | P3: R4 | Q3: 87 | R3: O01、O02、O03、O04、O05、O06、O08、O10、O11、O12、O13、O14 | T3: 無 | V3: 5243 | W3: Amortize、Cache_Store、Capability、Checks、DC_Cost、Fleet_1GW、Harness、Inputs、Interface、Perf、Perf_Batch、Sens_Har、Sens_Perf、Sens_Rev、Sens_Train、Theory_Rev、Training、Unit_Cost、Workload | X3: X2
A4: INV-003 | B4: Inputs | C4: 8 | D4: 機架外 IT 電力占比 | E4: % | F4: E8 | G4: 1 | H4: 0.08 | I4: Assumed | J4: Assumed | N4: G8: Assumed ｜ H8: 管理、儲存、網路機櫃等；區間 5–12%（見 Sensitivity）。v4 未計 | O4: Assumed | P4: R4 | Q4: 84 | R4: O01、O02、O03、O04、O05、O06、O08、O10、O11、O12、O13、O14 | S4: 0.087611056 | T4: 低 | U4: 66 | V4: 5457 | W4: Amortize、Cache_Store、Capability、Checks、DC_Cost、Fleet_1GW、Harness、Inputs、Interface、Perf、Perf_Batch、Sens_Har、Sens_Perf、Sens_Rev、Sens_Train、Sensitivity、Theory_Rev、Training、Unit_Cost、Workload
A5: INV-004 | B5: Inputs | C5: 9 | D5: PUE | E5: x | F5: D9、E9、F9 | G5: 3 | H5: 1.1；1.2；1.3 | I5: Analogy | J5: Analogy | L5: S14 | N5: G9: Analogy ｜ H9: 液冷 AI 設施；v4＝1.2。S14 | O5: Analogy | P5: R4 | Q5: 59 | R5: O02、O04、O05、O06、O08、O10、O13、O14 | S5: 0.055811125 | T5: 低 | U5: 74 | V5: 3647 | W5: Amortize、Cache_Store、Capability、Checks、DC_Cost、Harness、Interface、Perf、Perf_Batch、Sens_Har、Sens_Perf、Sens_Rev、Sens_Train、Sensitivity、Theory_Rev、Training、Unit_Cost、Workload
A6: INV-005 | B6: Inputs | C6: 10 | D6: 平均用電 ÷ 配電設計功率 | E6: % | F6: D10、E10、F10 | G6: 3 | H6: 0.7；0.8；0.9 | I6: Assumed | J6: Assumed | N6: G10: Assumed ｜ H10: Block 2 以逐步能量模型閉合檢查 | O6: Assumed | P6: R4 | Q6: 61 | R6: O02、O04、O05、O06、O08、O10、O13、O14 | S6: 0.055811125 | T6: 低 | U6: 73 | V6: 3897 | W6: Amortize、Cache_Store、Capability、Checks、DC_Cost、Harness、Interface、Perf、Perf_Batch、Sens_Har、Sens_Perf、Sens_Rev、Sens_Train、Sensitivity、Theory_Rev、Training、Unit_Cost、Workload
A7: INV-006 | B7: Inputs | C7: 11 | D7: 電價 | E7: $/kWh | F7: D11、E11、F11 | G7: 3 | H7: 0.06；0.08；0.1 | I7: Verified、Analogy | J7: Verified | K7: 多標記 | L7: S13 | N7: G11: Verified/Analogy ｜ H11: EIA 美國工業電價 2026 年約 8.6–8.7¢（S13）；低端為 PPA（v4＝0.06） | O7: 原始數據（候選） | P7: R3 | Q7: 58 | R7: O02、O04、O05、O06、O08、O10、O13、O14 | S7: 0.055811125 | T7: 低 | U7: 75 | V7: 3556 | W7: Amortize、Cache_Store、Capability、Checks、DC_Cost、Harness、Interface、Perf、Perf_Batch、Sens_Har、Sens_Perf、Sens_Rev、Sens_Train、Sensitivity、Theory_Rev、Training、Unit_Cost、Workload
A8: INV-007 | B8: Inputs | C8: 13 | D8: Scale-out 網路 ÷ 機架價格 | E8: % | F8: D13、E13、F13 | G8: 3 | H8: 0.05；0.1；0.15 | I8: Analogy | J8: Analogy | L8: S10 | N8: G13: Analogy ｜ H13: 1,024 GPU 叢集網路約為 GPU BOM 4–8%（S10）；GW 級多一層以上交換，取 5–15% | O8: Analogy | P8: R4 | Q8: 59 | R8: O01、O02、O04、O05、O06、O08、O10、O13、O14 | S8: 0.0702143 | T8: 低 | U8: 68 | V8: 3911 | W8: Amortize、Cache_Store、Capability、Checks、DC_Cost、Harness、Interface、Perf、Perf_Batch、Sens_Har、Sens_Perf、Sens_Rev、Sens_Train、Sensitivity、Theory_Rev、Training、Unit_Cost、Workload
A9: INV-008 | B9: Inputs | C9: 14 | D9: 儲存與管理設備 | E9: $/GPU | F9: D14、E14、F14 | G9: 3 | H9: 300；500；800 | I9: Assumed | J9: Assumed | N9: G14: Assumed ｜ H14: v4 約 $350/GPU（$25K/架） | O9: Assumed | P9: R4 | Q9: 59 | R9: O01、O02、O04、O05、O06、O08、O10、O13、O14 | S9: 0.0050554296 | T9: 低 | U9: 94 | V9: 3911 | W9: Amortize、Cache_Store、Capability、Checks、DC_Cost、Harness、Interface、Perf、Perf_Batch、Sens_Har、Sens_Perf、Sens_Rev、Sens_Train、Sensitivity、Theory_Rev、Training、Unit_Cost、Workload
A10: INV-009 | B10: Inputs | C10: 16 | D10: 土地 | E10: $M/MW | F10: D16、E16、F16 | G10: 3 | H10: 0.02；0.02；0.02 | I10: Assumed | J10: Assumed | N10: G16: Assumed ｜ H16: v4：100 英畝 × $200K／GW | O10: Assumed | P10: R4 | Q10: 59 | R10: O01、O02、O04、O05、O06、O08、O10、O13、O14 | S10: 0.00042032673 | T10: 低 | U10: 106 | V10: 3875 | W10: Amortize、Cache_Store、Capability、Checks、DC_Cost、Harness、Interface、Perf、Perf_Batch、Sens_Har、Sens_Perf、Sens_Rev、Sens_Train、Sensitivity、Theory_Rev、Training、Unit_Cost、Workload
A11: INV-010 | B11: Inputs | C11: 17 | D11: 建物與基地工程 | E11: $M/MW | F11: D17、E17、F17 | G11: 3 | H11: 3；3.6；4.5 | I11: Assumed | J11: Assumed | L11: S12 | N11: G17: Assumed ｜ H17: 分項為假設；總額以 JLL 校準（S12） | O11: Assumed | P11: R4 | Q11: 59 | R11: O01、O02、O04、O05、O06、O08、O10、O13、O14 | S11: 0.087007633 | T11: 低 | U11: 67 | V11: 3951 | W11: Amortize、Cache_Store、Capability、Checks、DC_Cost、Harness、Interface、Perf、Perf_Batch、Sens_Har、Sens_Perf、Sens_Rev、Sens_Train、Sensitivity、Theory_Rev、Training、Unit_Cost、Workload
A12: INV-011 | B12: Inputs | C12: 18 | D12: 電力設施（變電、中壓、發電機、UPS） | E12: $M/MW | F12: D18、E18、F18 | G12: 3 | H12: 3.8；4.5；5.5 | I12: Assumed | J12: Assumed | N12: G18: Assumed ｜ H18: 同上 | O12: Assumed | P12: R4 | Q12: 59 | R12: O01、O02、O04、O05、O06、O08、O10、O13、O14 | S12: 0.10875954 | T12: 中 | U12: 59 | V12: 3951 | W12: Amortize、Cache_Store、Capability、Checks、DC_Cost、Harness、Interface、Perf、Perf_Batch、Sens_Har、Sens_Perf、Sens_Rev、Sens_Train、Sensitivity、Theory_Rev、Training、Unit_Cost、Workload
A13: INV-012 | B13: Inputs | C13: 19 | D13: 機械與散熱（液冷迴路、散熱設備） | E13: $M/MW | F13: D19、E19、F19 | G13: 3 | H13: 2；2.5；3.2 | I13: Assumed | J13: Assumed | N13: G19: Assumed ｜ H19: 機架內冷板與 manifold 含在機架價格 | O13: Assumed | P13: R4 | Q13: 59 | R13: O01、O02、O04、O05、O06、O08、O10、O13、O14 | S13: 0.060421968 | T13: 低 | U13: 69 | V13: 3951 | W13: Amortize、Cache_Store、Capability、Checks、DC_Cost、Harness、Interface、Perf、Perf_Batch、Sens_Har、Sens_Perf、Sens_Rev、Sens_Train、Sensitivity、Theory_Rev、Training、Unit_Cost、Workload
A14: INV-013 | B14: Inputs | C14: 20 | D14: 光纖、佈線、保全、BMS | E14: $M/MW | F14: D20、E20、F20 | G14: 3 | H14: 0.3；0.4；0.5 | I14: Assumed | J14: Assumed | N14: G20: Assumed ｜ H20: 同上 | O14: Assumed | P14: R4 | Q14: 59 | R14: O01、O02、O04、O05、O06、O08、O10、O13、O14 | S14: 0.0096675148 | T14: 低 | U14: 89 | V14: 3951 | W14: Amortize、Cache_Store、Capability、Checks、DC_Cost、Harness、Interface、Perf、Perf_Batch、Sens_Har、Sens_Perf、Sens_Rev、Sens_Train、Sensitivity、Theory_Rev、Training、Unit_Cost、Workload
A15: INV-014 | B15: Inputs | C15: 21 | D15: 設計、管理與預備費 | E15: % 廠房 | F15: D21、E21、F21 | G15: 3 | H15: 0.12；0.15；0.18 | I15: Assumed | J15: Assumed | N15: G21: Assumed ｜ H21: v4＝15% | O15: Assumed | P15: R4 | Q15: 59 | R15: O01、O02、O04、O05、O06、O08、O10、O13、O14 | S15: 0.034676955 | T15: 低 | U15: 79 | V15: 3951 | W15: Amortize、Cache_Store、Capability、Checks、DC_Cost、Harness、Interface、Perf、Perf_Batch、Sens_Har、Sens_Perf、Sens_Rev、Sens_Train、Sensitivity、Theory_Rev、Training、Unit_Cost、Workload
A16: INV-015 | B16: Inputs | C16: 23 | D16: IT 設備折舊年限 | E16: 年 | F16: D23、E23、F23 | G16: 3 | H16: 6；6；4 | I16: Verified | J16: Verified | L16: S15 | N16: G23: Verified ｜ H23: CoreWeave 與主要 hyperscaler 6 年；Nebius 4 年、Lambda 5 年（S15）。高成本情境取 4 | O16: 原始數據（候選） | P16: R3 | Q16: 57 | R16: O02、O04、O05、O06、O08、O10、O13、O14 | S16: 0.50517384 | T16: 高 | U16: 30 | V16: 3566 | W16: Amortize、Cache_Store、Capability、Checks、DC_Cost、Harness、Interface、Perf、Perf_Batch、Sens_Har、Sens_Perf、Sens_Rev、Sens_Train、Sensitivity、Theory_Rev、Training、Unit_Cost、Workload
A17: INV-016 | B17: Inputs | C17: 24 | D17: 建物年限 | E17: 年 | F17: E24 | G17: 1 | H17: 30 | I17: Analogy | J17: Analogy | N17: G24: Analogy ｜ H24: v4 | O17: Analogy | P17: R4 | Q17: 57 | R17: O02、O04、O05、O06、O08、O10、O13、O14 | S17: 0.0064537158 | T17: 低 | U17: 90 | V17: 3505 | W17: Amortize、Cache_Store、Capability、Checks、DC_Cost、Harness、Inputs、Interface、Perf、Perf_Batch、Sens_Har、Sens_Perf、Sens_Rev、Sens_Train、Sensitivity、Theory_Rev、Training、Unit_Cost、Workload
A18: INV-017 | B18: Inputs | C18: 25 | D18: 電力設施年限 | E18: 年 | F18: E25 | G18: 1 | H18: 20 | I18: Analogy | J18: Analogy | N18: G25: Analogy ｜ H25: v4 | O18: Analogy | P18: R4 | Q18: 57 | R18: O02、O04、O05、O06、O08、O10、O13、O14 | S18: 0.017011547 | T18: 低 | U18: 84 | V18: 3505 | W18: Amortize、Cache_Store、Capability、Checks、DC_Cost、Harness、Inputs、Interface、Perf、Perf_Batch、Sens_Har、Sens_Perf、Sens_Rev、Sens_Train、Sensitivity、Theory_Rev、Training、Unit_Cost、Workload
A19: INV-018 | B19: Inputs | C19: 26 | D19: 機械與散熱年限 | E19: 年 | F19: E26 | G19: 1 | H19: 15 | I19: Analogy | J19: Analogy | N19: G26: Analogy ｜ H26: v4 | O19: Analogy | P19: R4 | Q19: 57 | R19: O02、O04、O05、O06、O08、O10、O13、O14 | S19: 0.01427859 | T19: 低 | U19: 86 | V19: 3505 | W19: Amortize、Cache_Store、Capability、Checks、DC_Cost、Harness、Inputs、Interface、Perf、Perf_Batch、Sens_Har、Sens_Perf、Sens_Rev、Sens_Train、Sensitivity、Theory_Rev、Training、Unit_Cost、Workload
A20: INV-019 | B20: Inputs | C20: 27 | D20: 光纖與保全年限 | E20: 年 | F20: E27 | G20: 1 | H20: 10 | I20: Analogy | J20: Analogy | N20: G27: Analogy ｜ H27: v4 | O20: Analogy | P20: R4 | Q20: 57 | R20: O02、O04、O05、O06、O08、O10、O13、O14 | S20: 0.0037544898 | T20: 低 | U20: 99 | V20: 3505 | W20: Amortize、Cache_Store、Capability、Checks、DC_Cost、Harness、Inputs、Interface、Perf、Perf_Batch、Sens_Har、Sens_Perf、Sens_Rev、Sens_Train、Sensitivity、Theory_Rev、Training、Unit_Cost、Workload
A21: INV-020 | B21: Inputs | C21: 28 | D21: WACC（經濟口徑） | E21: % | F21: D28、E28、F28 | G21: 3 | H21: 0.08；0.1；0.13 | I21: Assumed | J21: Assumed | N21: G28: Assumed ｜ H28: 與擁有者無關的單一假設；下游公司模型以自身 WACC 覆寫（Andy 2026-09-30 決定） | O21: Assumed | P21: R4 | Q21: 53 | R21: O02、O04、O05、O06、O08、O10、O13、O14 | S21: 0.280379 | T21: 中 | U21: 45 | V21: 3289 | W21: Amortize、Cache_Store、Capability、Checks、DC_Cost、Harness、Interface、Perf、Perf_Batch、Sens_Har、Sens_Perf、Sens_Rev、Sens_Train、Sensitivity、Theory_Rev、Training、Unit_Cost、Workload
A22: INV-021 | B22: Inputs | C22: 30 | D22: IT 維護 | E22: % IT 資本/年 | F22: D30、E30、F30 | G22: 3 | H22: 0.02；0.03；0.04 | I22: Analogy | J22: Analogy | N22: G30: Analogy ｜ H30: v4＝3% | O22: Analogy | P22: R4 | Q22: 57 | R22: O02、O04、O05、O06、O08、O10、O13、O14 | S22: 0.088139574 | T22: 低 | U22: 65 | V22: 3503 | W22: Amortize、Cache_Store、Capability、Checks、DC_Cost、Harness、Interface、Perf、Perf_Batch、Sens_Har、Sens_Perf、Sens_Rev、Sens_Train、Sensitivity、Theory_Rev、Training、Unit_Cost、Workload
A23: INV-022 | B23: Inputs | C23: 31 | D23: 廠房維護 | E23: % 廠房資本/年 | F23: D31、E31、F31 | G23: 3 | H23: 0.015；0.02；0.025 | I23: Analogy | J23: Analogy | N23: G31: Analogy ｜ H31: v4＝2% | O23: Analogy | P23: R4 | Q23: 57 | R23: O02、O04、O05、O06、O08、O10、O13、O14 | S23: 0.02102142 | T23: 低 | U23: 81 | V23: 3503 | W23: Amortize、Cache_Store、Capability、Checks、DC_Cost、Harness、Interface、Perf、Perf_Batch、Sens_Har、Sens_Perf、Sens_Rev、Sens_Train、Sensitivity、Theory_Rev、Training、Unit_Cost、Workload
A24: INV-023 | B24: Inputs | C24: 32 | D24: 人員 | E24: $M/GW/年 | F24: D32、E32、F32 | G24: 3 | H24: 50；75；100 | I24: Assumed | J24: Assumed | N24: G32: Assumed ｜ H32: v4：500 FTE × $150K | O24: Assumed | P24: R4 | Q24: 57 | R24: O02、O04、O05、O06、O08、O10、O13、O14 | S24: 0.0062218095 | T24: 低 | U24: 91 | V24: 3503 | W24: Amortize、Cache_Store、Capability、Checks、DC_Cost、Harness、Interface、Perf、Perf_Batch、Sens_Har、Sens_Perf、Sens_Rev、Sens_Train、Sensitivity、Theory_Rev、Training、Unit_Cost、Workload
A25: INV-024 | B25: Inputs | C25: 33 | D25: 軟體授權與連線 | E25: $M/GW/年 | F25: D33、E33、F33 | G25: 3 | H25: 150；200；250 | I25: Assumed | J25: Assumed | N25: G33: Assumed ｜ H33: v4＝$200M | O25: Assumed | P25: R4 | Q25: 57 | R25: O02、O04、O05、O06、O08、O10、O13、O14 | S25: 0.016591492 | T25: 低 | U25: 85 | V25: 3503 | W25: Amortize、Cache_Store、Capability、Checks、DC_Cost、Harness、Interface、Perf、Perf_Batch、Sens_Har、Sens_Perf、Sens_Rev、Sens_Train、Sensitivity、Theory_Rev、Training、Unit_Cost、Workload
A26: INV-025 | B26: Inputs | C26: 34 | D26: 水與耗材 | E26: $M/MW/年 | F26: D34、E34、F34 | G26: 3 | H26: 0.04；0.05；0.06 | I26: Assumed | J26: Assumed | N26: G34: Assumed ｜ H34: v4＝$50K/MW | O26: Assumed | P26: R4 | Q26: 57 | R26: O02、O04、O05、O06、O08、O10、O13、O14 | S26: 0.004147873 | T26: 低 | U26: 96 | V26: 3503 | W26: Amortize、Cache_Store、Capability、Checks、DC_Cost、Harness、Interface、Perf、Perf_Batch、Sens_Har、Sens_Perf、Sens_Rev、Sens_Train、Sensitivity、Theory_Rev、Training、Unit_Cost、Workload
A27: INV-026 | B27: Inputs | C27: 35 | D27: 財產稅與保險 | E27: % 總資本/年 | F27: D35、E35、F35 | G27: 3 | H27: 0.003；0.005；0.008 | I27: Analogy | J27: Analogy | N27: G35: Analogy ｜ H35: v4＝0.5% | O27: Analogy | P27: R4 | Q27: 57 | R27: O02、O04、O05、O06、O08、O10、O13、O14 | S27: 0.019736423 | T27: 低 | U27: 82 | V27: 3503 | W27: Amortize、Cache_Store、Capability、Checks、DC_Cost、Harness、Interface、Perf、Perf_Batch、Sens_Har、Sens_Perf、Sens_Rev、Sens_Train、Sensitivity、Theory_Rev、Training、Unit_Cost、Workload
A28: INV-027 | B28: Spec_Rack | C28: 6 | D28: GPU 封裝／架 | F28: C6、D6、E6、F6、G6 | G28: 5 | H28: 32；72；72；72；144 | O28: 待分類 | P28: R7 | Q28: 92 | R28: O01、O02、O03、O04、O05、O06、O08、O10、O11、O12、O13、O14 | S28: 1.0068666 | T28: 高 | U28: 9 | V28: 5924 | W28: Amortize、Cache_Store、Capability、Checks、DC_Cost、Fleet_1GW、Harness、Interface、Perf、Perf_Batch、Sens_Har、Sens_Perf、Sens_Rev、Sens_Train、Sensitivity、Theory_Rev、Training、Unit_Cost、Workload
A29: INV-028 | B29: Spec_Rack | C29: 8 | D29: 配電設計功率 低（kW） | F29: C8、D8、E8、F8、G8 | G29: 5 | H29: 38；120；132；190；550 | O29: 待分類 | P29: R7 | Q29: 87 | R29: O01、O02、O03、O04、O05、O06、O08、O10、O11、O12、O13、O14 | S29: 0 | T29: 無 | U29: 123 | V29: 5268 | W29: Amortize、Cache_Store、Capability、Checks、DC_Cost、Fleet_1GW、Harness、Interface、Perf、Perf_Batch、Sens_Har、Sens_Perf、Sens_Rev、Sens_Train、Sensitivity、Theory_Rev、Training、Unit_Cost、Workload
A30: INV-029 | B30: Spec_Rack | C30: 9 | D30: 配電設計功率 基準（kW） | F30: C9、D9、E9、F9、G9 | G30: 5 | H30: 41；130；137；227；600 | O30: 待分類 | P30: R7 | Q30: 87 | R30: O01、O02、O03、O04、O05、O06、O08、O10、O11、O12、O13、O14 | S30: 1.010612 | T30: 高 | U30: 6 | V30: 5786 | W30: Amortize、Cache_Store、Capability、Checks、DC_Cost、Fleet_1GW、Harness、Interface、Perf、Perf_Batch、Sens_Har、Sens_Perf、Sens_Rev、Sens_Train、Sensitivity、Theory_Rev、Training、Unit_Cost、Workload
A31: INV-030 | B31: Spec_Rack | C31: 10 | D31: 配電設計功率 高（kW） | F31: C10、D10、E10、F10、G10 | G31: 5 | H31: 44；140；142；230；650 | O31: 待分類 | P31: R7 | Q31: 87 | R31: O01、O02、O03、O04、O05、O06、O08、O10、O11、O12、O13、O14 | S31: 0 | T31: 無 | U31: 124 | V31: 5268 | W31: Amortize、Cache_Store、Capability、Checks、DC_Cost、Fleet_1GW、Harness、Interface、Perf、Perf_Batch、Sens_Har、Sens_Perf、Sens_Rev、Sens_Train、Sensitivity、Theory_Rev、Training、Unit_Cost、Workload
A32: INV-031 | B32: Spec_Rack | C32: 11 | D32: 機架價格 低（$M） | F32: C11、D11、E11、F11、G11 | G32: 5 | H32: 0.9；2.8；4；6.7；23.4 | O32: 待分類 | P32: R7 | Q32: 44 | R32: O10 | S32: 0 | T32: 無 | U32: 111 | V32: 2136 | W32: Amortize、Cache_Store、Capability、Checks、DC_Cost、Interface、Perf、Perf_Batch、Sens_Perf、Sens_Rev、Sens_Train、Sensitivity、Theory_Rev、Training、Unit_Cost
A33: INV-032 | B33: Spec_Rack | C33: 12 | D33: 機架價格 基準（$M） | F33: C12、D12、E12、F12、G12 | G33: 5 | H33: 1.1；3.1；5；7.8；31.2 | O33: 待分類 | P33: R7 | Q33: 59 | R33: O01、O02、O04、O05、O06、O08、O10、O13、O14 | S33: 0.7723573 | T33: 高 | U33: 18 | V33: 3115 | W33: Amortize、Cache_Store、Capability、Checks、DC_Cost、Harness、Interface、Perf、Perf_Batch、Sens_Har、Sens_Perf、Sens_Rev、Sens_Train、Sensitivity、Theory_Rev、Training、Unit_Cost、Workload
A34: INV-033 | B34: Spec_Rack | C34: 13 | D34: 機架價格 高（$M） | F34: C13、D13、E13、F13、G13 | G34: 5 | H34: 1.3；3.4；6.5；9.1；39 | O34: 待分類 | P34: R7 | Q34: 44 | R34: O10 | S34: 0 | T34: 無 | U34: 112 | V34: 2136 | W34: Amortize、Cache_Store、Capability、Checks、DC_Cost、Interface、Perf、Perf_Batch、Sens_Perf、Sens_Rev、Sens_Train、Sensitivity、Theory_Rev、Training、Unit_Cost
A35: INV-034 | B35: Spec_Rack | C35: 23 | D35: 峰值 dense（基準）PF/GPU | F35: C23、D23、E23、F23、G23 | G35: 5 | H35: 1.979；10；15；35；73 | I35: Interested-party、Derived | J35: Interested-party | K35: 多標記 | L35: S28 | N35: H23: Interested-party（NVIDIA 規格）：H100 FP8 dense 1,979 TF（v5.5 更正；v5.4 誤填 BF16 的 989）；GB200 FP4 10 PF（HGX B200 為 9）；B300 15；Rubin NVFP4 訓練 35；RU＝104×35/50 推估 [Derived]。S28 | O35: 原始數據（候選） | P35: R3 | Q35: 92 | R35: O03、O04、O05、O06、O07、O08、O09、O10、O11、O12、O13、O14 | S35: 0.34060378 | T35: 中 | U35: 37 | V35: 7639 | W35: Amortize、Calib、Capability、Checks、Fleet_1GW、Harness、Interface、Perf、Perf_Batch、Sens_Har、Sens_Perf、Sens_Rev、Sens_Train、Spec_Rack、Theory_Rev、Training、Unit_Cost、Workload
A36: INV-035 | B36: Spec_Rack | C36: 24 | D36: 峰值（高情境：NVFP4 推論口徑）PF/GPU | F36: C24、D24、E24、F24、G24 | G36: 5 | H36: 1.979；10；15；50；104 | N36: H24: Rubin 50 PF 含自適應壓縮；RU NVL576 15 EF ÷ 144。J2：只作高情境 | O36: 待分類 | P36: R7 | Q36: 92 | R36: O03、O04、O05、O06、O07、O08、O09、O10、O11、O12、O13、O14 | S36: 0 | T36: 無 | U36: 125 | V36: 7639 | W36: Amortize、Calib、Capability、Checks、Fleet_1GW、Harness、Interface、Perf、Perf_Batch、Sens_Har、Sens_Perf、Sens_Rev、Sens_Train、Spec_Rack、Theory_Rev、Training、Unit_Cost、Workload
A37: INV-036 | B37: Spec_Rack | C37: 25 | D37: HBM 容量 GB/GPU | F37: C25、D25、E25、F25、G25 | G37: 5 | H37: 80；186；288；288；1024 | L37: S28 | N37: H25: GB200 NVL72 13.4 TB ÷ 72；InferenceX 以 192 計。RU HBM4e 約 1 TB/封裝。S28 | O37: 待分類 | P37: R7 | Q37: 92 | R37: O03、O04、O05、O06、O07、O08、O09、O10、O11、O12、O13、O14 | S37: 0.22064113 | T37: 中 | U37: 49 | V37: 7394 | W37: Amortize、Cache_Store、Calib、Capability、Checks、Fleet_1GW、Harness、Interface、Perf、Perf_Batch、Sens_Har、Sens_Perf、Sens_Rev、Sens_Train、Theory_Rev、Training、Unit_Cost、Workload
A38: INV-037 | B38: Spec_Rack | C38: 26 | D38: HBM 頻寬 TB/s/GPU | F38: C26、D26、E26、F26、G26 | G38: 5 | H38: 3.35；8；8；22；32 | L38: S28 | N38: H26: Rubin 22 TB/s（NVIDIA 2026 上修）；RU 4.6 PB/s ÷ 144。S28 | O38: 待分類 | P38: R7 | Q38: 89 | R38: O03、O04、O05、O06、O07、O08、O09、O10、O11、O12、O13、O14 | S38: 0.17829583 | T38: 中 | U38: 54 | V38: 6755 | W38: Amortize、Calib、Capability、Checks、Fleet_1GW、Harness、Interface、Perf、Perf_Batch、Sens_Har、Sens_Perf、Sens_Rev、Sens_Train、Spec_Rack、Theory_Rev、Training、Unit_Cost、Workload
A39: INV-038 | B39: Spec_Rack | C39: 27 | D39: EP 通訊頻寬 TB/s/GPU（單向） | F39: C27、D27、E27、F27、G27 | G39: 5 | H39: 0.05；0.9；0.9；1.8；1.8 | I39: Assumed | J39: Assumed | L39: S20 | N39: H27: Hopper EP 跨節點走 400G IB；NVLink 5＝900 GB/s；NVLink 6＝1.8 TB/s（InferenceX 規格表 S20）；RU 取同 VR [Assumed] | O39: Assumed | P39: R4 | Q39: 89 | R39: O03、O04、O05、O06、O07、O08、O09、O10、O11、O12、O13、O14 | S39: 0 | T39: 無 | U39: 126 | V39: 6591 | W39: Amortize、Calib、Capability、Checks、Fleet_1GW、Harness、Interface、Perf、Perf_Batch、Sens_Har、Sens_Perf、Sens_Rev、Sens_Train、Theory_Rev、Training、Unit_Cost、Workload
A40: INV-039 | B40: Spec_Rack | C40: 28 | D40: Scale-up 域 GPU 數 | F40: C28、D28、E28、F28、G28 | G40: 5 | H40: 8；72；72；72；144 | O40: 待分類 | P40: R7 | Q40: 0 | T40: 無 | V40: 0 | X40: X5a
...

Sheet 藍字格
A1: INV_ID | B1: 工作表 | C1: 格位址 | D1: 值 | E1: 型別 | F1: 欄表頭
A2: INV-001 | B2: Inputs | C2: E5 | D2: 1 | E2: 數值 | F2: 基準
A3: INV-002 | B3: Inputs | C3: E6 | D3: 2 | E3: 數值 | F3: 基準
A4: INV-003 | B4: Inputs | C4: E8 | D4: 0.08 | E4: 數值 | F4: 基準
A5: INV-004 | B5: Inputs | C5: D9 | D5: 1.1 | E5: 數值 | F5: 低成本
A6: INV-004 | B6: Inputs | C6: E9 | D6: 1.2 | E6: 數值 | F6: 基準
A7: INV-004 | B7: Inputs | C7: F9 | D7: 1.3 | E7: 數值 | F7: 高成本
A8: INV-005 | B8: Inputs | C8: D10 | D8: 0.7 | E8: 數值 | F8: 低成本
A9: INV-005 | B9: Inputs | C9: E10 | D9: 0.8 | E9: 數值 | F9: 基準
A10: INV-005 | B10: Inputs | C10: F10 | D10: 0.9 | E10: 數值 | F10: 高成本
A11: INV-006 | B11: Inputs | C11: D11 | D11: 0.06 | E11: 數值 | F11: 低成本
A12: INV-006 | B12: Inputs | C12: E11 | D12: 0.08 | E12: 數值 | F12: 基準
A13: INV-006 | B13: Inputs | C13: F11 | D13: 0.1 | E13: 數值 | F13: 高成本
... A241: INV-079 | B241: Serving | C241: D21 | D241: 65 | E241: 數值 | F241: 標記
A242: INV-079 | B242: Serving | C242: E21 | D242: 55 | E242: 數值
A243: INV-080 | B243: Serving | C243: C22 | D243: 2 | E243: 數值 | F243: 值
A244: INV-080 | B244: Serving | C244: D22 | D244: 3 | E244: 數值 | F244: 標記
A245: INV-080 | B245: Serving | C245: E22 | D245: 5 | E245: 數值
A246: INV-081 | B246: Serving | C246: C23 | D246: 8192 | E246: 數值 | F246: 值
A247: INV-081 | B247: Serving | C247: D23 | D247: 16384 | E247: 數值 | F247: 標記
A248: INV-081 | B248: Serving | C248: E23 | D248: 32768 | E248: 數值
A249: INV-082 | B249: Serving | C249: C24 | D249: 1024 | E249: 數值 | F249: 值
A250: INV-082 | B250: Serving | C250: D24 | D250: 2048 | E250: 數值 | F250: 標記
A251: INV-082 | B251: Serving | C251: E24 | D251: 4096 | E251: 數值
A252: INV-083 | B252: Workload | C252: C5 | D252: 1 | E252: 數值 | F252: 一般聊天
A253: INV-083 | B253: Workload | C253: D5 | D253: 1 | E253: 數值 | F253: 推理聊天
A254: INV-083 | B254: Workload | C254: E5 | D254: 4 | E254: 數值 | F254: 單代理（工具迴圈）
A255: INV-083 | B255: Workload | C255: F5 | D255: 4 | E255: 數值 | F255: 多代理研究
A256: INV-083 | B256: Workload | C256: G5 | D256: 30 | E256: 數值 | F256: Coding agent（長程）
A257: INV-084 | B257: Workload | C257: C6 | D257: 2000 | E257: 數值 | F257: 一般聊天
A258: INV-084 | B258: Workload | C258: D6 | D258: 2000 | E258: 數值 | F258: 推理聊天
A259: INV-084 | B259: Workload | C259: E6 | D259: 3000 | E259: 數值 | F259: 單代理（工具迴圈）
A260: INV-084 | B260: Workload | C260: F6 | D260: 3000 | E260: 數值 | F260: 多代理研究
A261: INV-084 | B261: Workload | C261: G6 | D261: 12000 | E261: 數值 | F261: Coding agent（長程）
A262: INV-085 | B262: Workload | C262: C7 | D262: 500 | E262: 數值 | F262: 一般聊天
A263: INV-085 | B263: Workload | C263: D7 | D263: 500 | E263: 數值 | F263: 推理聊天
... A304: INV-093 | B304: Workload | C304: F40 | D304: 15 | E304: 數值 | F304: 多代理研究
A305: INV-094 | B305: Calib | C305: C5 | D305: 0.3 | E305: 數值
A306: INV-095 | B306: Calib | C306: C10 | D306: 3 | E306: 數值 | F306: 擬合點 1
A307: INV-095 | B307: Calib | C307: D10 | D307: 3 | E307: 數值 | F307: 擬合點 2
...

Sheet 藍字公式格
A1: 工作表 | B1: 格位址 | C1: 公式 | D1: 該列標籤
A2: Calib | B2: C118 | C2: =1000/15 | D2: 每用戶速度下限（1000 ÷ TPOT）
A3: Calib | B3: D118 | C3: =1000/15 | D3: 每用戶速度下限（1000 ÷ TPOT）
A4: Calib | B4: E118 | C4: =1000/15 | D4: 每用戶速度下限（1000 ÷ TPOT）
A5: Calib | B5: F118 | C5: =1000/80 | D5: 每用戶速度下限（1000 ÷ TPOT）
A6: Calib | B6: C120 | C6: =253506/72 | D6: MLPerf 實測輸出 tok/s/GPU（總量 ÷ 72）
A7: Calib | B7: D120 | C7: =240318/72 | D7: MLPerf 實測輸出 tok/s/GPU（總量 ÷ 72）
A8: Calib | B8: E120 | C8: =652750/72 | D8: MLPerf 實測輸出 tok/s/GPU（總量 ÷ 72）
A9: Sens_Perf | B9: AC34 | C9: =Arch!$E$21 | D9: KV bytes/token（含 H_KV）
A10: Sens_Perf | B10: AD34 | C10: =Arch!$E$21 | D10: KV bytes/token（含 H_KV）
A11: Sens_Perf | B11: AE34 | C11: =Arch!$E$22 | D11: KV bytes/token（含 H_KV）
A12: Sens_Perf | B12: AF34 | C12: =Arch!$E$22 | D12: KV bytes/token（含 H_KV）
A13: Sens_Perf | B13: AG34 | C13: =Arch!$E$23 | D13: KV bytes/token（含 H_KV）
A14: Sens_Perf | B14: AH34 | C14: =Arch!$E$23 | D14: KV bytes/token（含 H_KV）
A15: Perf_Batch | B15: R14 | C15: =Spec_Rack!$F$40 | D15: 計算用峰值
A16: Perf_Batch | B16: S14 | C16: =Spec_Rack!$F$40 | D16: 計算用峰值
A17: Sens_Train | B17: I10 | C17: =INDEX(Spec_Rack!$C$41:$G$41,I$6) | D17: FP8 dense 峰值
A18: Sens_Train | B18: J10 | C18: =INDEX(Spec_Rack!$C$41:$G$41,J$6) | D18: FP8 dense 峰值
A19: Sens_Train | B19: O53 | C19: =INDEX(Train_In!$C$34:$E$34,O$7)*0.3 | D19: rollout 輸出 token
A20: Sens_Train | B20: P53 | C20: =INDEX(Train_In!$C$34:$E$34,P$7)*0.3 | D20: rollout 輸出 token
A21: Sens_Train | B21: Q53 | C21: =INDEX(Train_In!$C$34:$E$34,Q$7)*3 | D21: rollout 輸出 token
A22: Sens_Train | B22: R53 | C22: =INDEX(Train_In!$C$34:$E$34,R$7)*3 | D22: rollout 輸出 token
A23: Sens_Train | B23: W59 | C23: =Perf_Batch!R103 | D23: rollout decode GPU 秒／M（Perf_Batch 本層級）
A24: Sens_Train | B24: X59 | C24: =Perf_Batch!S103 | D24: rollout decode GPU 秒／M（Perf_Batch 本層級）
A25: Sens_Train | B25: W60 | C25: =Perf_Batch!R101 | D25: rollout prefill GPU 秒／M
A26: Sens_Train | B26: X60 | C26: =Perf_Batch!S101 | D26: rollout prefill GPU 秒／M
A27: Sens_Train | B27: W61 | C27: =Perf_Batch!R65 | D27: rollout decode FLOPs/token
A28: Sens_Train | B28: X61 | C28: =Perf_Batch!S65 | D28: rollout decode FLOPs/token
A29: Sens_Train | B29: W62 | C29: =Perf_Batch!R67 | D29: rollout prefill FLOPs/token
A30: Sens_Train | B30: X62 | C30: =Perf_Batch!S67 | D30: rollout prefill FLOPs/token
A31: Sens_Train | B31: AA93 | C31: =INDEX(Train_In!$C$37:$E$37,AA$7)*3 | D31: 合成資料 token
A32: Sens_Train | B32: AB93 | C32: =INDEX(Train_In!$C$37:$E$37,AB$7)*3 | D32: 合成資料 token

Sheet 依賴
A1: INV_ID | B1: IF_ 名稱 | C1: 名稱內可達格數 | D1: 擾動是否觀測到改變（空白＝未擾動）
A2: INV-001 | B2: IF_AmortBU_Astra | C2: 15 | D2: 是
A3: INV-001 | B3: IF_AmortBU_Luna | C3: 15 | D3: 是
A4: INV-001 | B4: IF_AmortBU_Sol | C4: 15 | D4: 是
A5: INV-001 | B5: IF_AmortDefault_Astra | C5: 15 | D5: 是
A6: INV-001 | B6: IF_AmortDefault_Luna | C6: 15 | D6: 是
A7: INV-001 | B7: IF_AmortDefault_Sol | C7: 15 | D7: 是
A8: INV-001 | B8: IF_AmortRev_Astra | C8: 15 | D8: 是
A9: INV-001 | B9: IF_AmortRev_Luna | C9: 15 | D9: 是
A10: INV-001 | B10: IF_AmortRev_Sol | C10: 15 | D10: 是
A11: INV-001 | B11: IF_AmortTD_Astra | C11: 15 | D11: 是
A12: INV-001 | B12: IF_AmortTD_Luna | C12: 15 | D12: 是
A13: INV-001 | B13: IF_AmortTD_Sol | C13: 15 | D13: 是
... A88: INV-001 | B88: IF_VReq_Sol | C88: 15 | D88: 是
A89: INV-002 | B89: IF_AmortBU_Astra | C89: 15
A90: INV-002 | B90: IF_AmortBU_Luna | C90: 15
A91: INV-002 | B91: IF_AmortBU_Sol | C91: 15
A92: INV-002 | B92: IF_AmortDefault_Astra | C92: 15
A93: INV-002 | B93: IF_AmortDefault_Luna | C93: 15
A94: INV-002 | B94: IF_AmortDefault_Sol | C94: 15
A95: INV-002 | B95: IF_AmortRev_Astra | C95: 15
A96: INV-002 | B96: IF_AmortRev_Luna | C96: 15
A97: INV-002 | B97: IF_AmortRev_Sol | C97: 15
A98: INV-002 | B98: IF_AmortTD_Astra | C98: 15
A99: INV-002 | B99: IF_AmortTD_Luna | C99: 15
A100: INV-002 | B100: IF_AmortTD_Sol | C100: 15
... A175: INV-002 | B175: IF_VReq_Sol | C175: 15
A176: INV-003 | B176: IF_AmortBU_Astra | C176: 15 | D176: 是
A177: INV-003 | B177: IF_AmortBU_Luna | C177: 15 | D177: 是
A178: INV-003 | B178: IF_AmortBU_Sol | C178: 15 | D178: 是
A179: INV-003 | B179: IF_AmortDefault_Astra | C179: 15 | D179: 是
A180: INV-003 | B180: IF_AmortDefault_Luna | C180: 15 | D180: 是
A181: INV-003 | B181: IF_AmortDefault_Sol | C181: 15 | D181: 是
A182: INV-003 | B182: IF_AmortRev_Astra | C182: 15 | D182: 是
A183: INV-003 | B183: IF_AmortRev_Luna | C183: 15 | D183: 是
A184: INV-003 | B184: IF_AmortRev_Sol | C184: 15 | D184: 是
A185: INV-003 | B185: IF_AmortTD_Astra | C185: 15 | D185: 是
A186: INV-003 | B186: IF_AmortTD_Luna | C186: 15 | D186: 是
A187: INV-003 | B187: IF_AmortTD_Sol | C187: 15 | D187: 是
... A4048: INV-062 | B4048: IF_VReq_Sol | C4048: 15 | D4048: 是
...

Sheet 敏感度
A1: INV_ID | B1: 輸出 ID | C1: y₀ | D1: y₊ | E1: y₋ | F1: ε₊ | G1: ε₋ | H1: ε | I1: 單邊 | J1: 錯誤／文字結果
A2: INV-001 | B2: O01 | C2: 47.582032 | D2: 52.347128 | E2: 42.825552 | F2: 1.0014486 | G2: 0.99963785 | H2: 1.0005432
A3: INV-001 | B3: O02 | C3: 12.054371 | D3: 13.261632 | E3: 10.84939 | F3: 1.001513 | G3: 0.99962174 | H3: 1.0005674
A4: INV-001 | B4: O03 | C4: 2.3809835e+11 | D4: 2.619552e+11 | E4: 2.1430027e+11 | F4: 1.0019743 | G4: 0.99950642 | H4: 1.0007404
A5: INV-001 | B5: O04 | C5: 0.3225757 | D5: 0.32256217 | E5: 0.32257156 | F5: -0.00041927417 | G5: 0.00012812752 | H5: -0.00014557333
A6: INV-001 | B6: O05 | C6: 1.6606622 | D6: 1.6605925 | E6: 1.6606409 | F6: -0.00041927417 | G6: 0.00012812752 | H6: -0.00014557333
A7: INV-001 | B7: O06 | C7: 0.55698369 | D7: 0.55699208 | E7: 0.55699395 | F7: 0.00015068188 | G7: -0.00018416951 | H7: -1.6743816e-05
A8: INV-001 | B8: O07 | C8: 11677661 | D8: 11677661 | E8: 11677661 | F8: 0 | G8: 0 | H8: 0
A9: INV-001 | B9: O08 | C9: 440.64044 | D9: 440.62197 | E9: 440.6348 | F9: -0.00041927417 | G9: 0.00012812752 | H9: -0.00014557333
A10: INV-001 | B10: O09 | C10: 0.25575637 | D10: 0.25575637 | E10: 0.25575637 | F10: 0 | G10: 0 | H10: 0
A11: INV-001 | B11: O10 | C11: 0.10469626 | D11: 0.10469187 | E11: 0.10469492 | F11: -0.00041915084 | G11: 0.00012808983 | H11: -0.0001455305
A12: INV-001 | B12: O11 | C12: 229.59031 | D12: 252.59467 | E12: 206.64261 | F12: 1.0019743 | G12: 0.99950642 | H12: 1.0007404
A13: INV-001 | B13: O12 | C13: 49.106545 | D13: 54.026895 | E13: 44.198314 | F13: 1.0019743 | G13: 0.99950642 | H13: 1.0007404
... A701: INV-057 | B701: O14 | C701: 0.020916193 | D701: 0.020935366 | E701: 0.020897066 | F701: 0.0091667447 | G701: 0.0091446108 | H701: 0.0091556778
A702: INV-059 | B702: O01 | C702: 47.582032 | E702: 47.582032 | G702: 0 | H702: 0 | I702: 單邊
A703: INV-059 | B703: O02 | C703: 12.054371 | E703: 12.054371 | G703: 0 | H703: 0 | I703: 單邊
A704: INV-059 | B704: O03 | C704: 2.3809835e+11 | E704: 2.3833706e+11 | G704: -0.010025382 | H704: -0.010025382 | I704: 單邊
A705: INV-059 | B705: O04 | C705: 0.3225757 | E705: 0.32533743 | G705: -0.08561503 | H705: -0.08561503 | I705: 單邊
A706: INV-059 | B706: O05 | C706: 1.6606622 | E706: 1.7144206 | G706: -0.32371713 | H706: -0.32371713 | I706: 單邊
A707: INV-059 | B707: O06 | C707: 0.55698369 | E707: 0.56167845 | G707: -0.084288996 | H707: -0.084288996 | I707: 單邊
A708: INV-059 | B708: O07 | C708: 11677661 | E708: 11784919 | G708: -0.091849169 | H708: -0.091849169 | I708: 單邊
A709: INV-059 | B709: O08 | C709: 440.64044 | E709: 444.68769 | G709: -0.091849169 | H709: -0.091849169 | I709: 單邊
A710: INV-059 | B710: O09 | C710: 0.25575637 | E710: 0.25403371 | G710: 0.067355778 | H710: 0.067355778 | I710: 單邊
A711: INV-059 | B711: O10 | C711: 0.10469626 | E711: 0.10517341 | G711: -0.045575039 | H711: -0.045575039 | I711: 單邊
A712: INV-059 | B712: O11 | C712: 229.59031 | E712: 229.82048 | G712: -0.010025382 | H712: -0.010025382 | I712: 單邊
A713: INV-059 | B713: O12 | C713: 49.106545 | E713: 48.474548 | G713: 0.1286991 | H713: 0.1286991 | I713: 單邊
... A715: INV-059 | B715: O14 | C715: 0.020916193 | E715: 0.02093473 | G715: -0.0088624555 | H715: -0.0088624555 | I715: 單邊
A716: INV-060 | B716: O01 | C716: 47.582032 | D716: 47.582032 | E716: 47.582032 | F716: 0 | G716: 0 | H716: 0
A717: INV-060 | B717: O02 | C717: 12.054371 | D717: 12.054371 | E717: 12.054371 | F717: 0 | G717: 0 | H717: 0
A718: INV-060 | B718: O03 | C718: 2.3809835e+11 | D718: 2.3636628e+11 | E718: 2.3883068e+11 | F718: -0.072746181 | G718: -0.030757309 | H718: -0.051751745
A719: INV-060 | B719: O04 | C719: 0.3225757 | D719: 0.32254334 | E719: 0.32454986 | F719: -0.001003145 | G719: -0.06120008 | H719: -0.031101612
A720: INV-060 | B720: O05 | C720: 1.6606622 | D720: 1.6196396 | E720: 1.7132948 | F720: -0.24702534 | G720: -0.31693785 | H720: -0.2819816
A721: INV-060 | B721: O06 | C721: 0.55698369 | D721: 0.55692782 | E721: 0.5603373 | F721: -0.001003145 | G721: -0.060210105 | H721: -0.030606625
A722: INV-060 | B722: O07 | C722: 11677661 | D722: 11598496 | E722: 11781860 | F722: -0.067791777 | G722: -0.089229351 | H722: -0.078510564
A723: INV-060 | B723: O08 | C723: 440.64044 | D723: 437.65326 | E723: 444.57225 | F723: -0.067791777 | G723: -0.089229351 | H723: -0.078510564
A724: INV-060 | B724: O09 | C724: 0.25575637 | D724: 0.25830962 | E724: 0.25370456 | F724: 0.099831318 | G724: 0.080225107 | H724: 0.090028213
A725: INV-060 | B725: O10 | C725: 0.10469626 | D725: 0.10493973 | E725: 0.10496179 | F725: 0.023255413 | G725: -0.025361892 | H725: -0.0010532394
A726: INV-060 | B726: O11 | C726: 229.59031 | D726: 227.92013 | E726: 230.29647 | F726: -0.072746181 | G726: -0.030757309 | H726: -0.051751745
A727: INV-060 | B727: O12 | C727: 49.106545 | D727: 49.487592 | E727: 48.521922 | F727: 0.077596021 | G727: 0.11905195 | H727: 0.098323983
... A1975: INV-246 | B1975: O14 | C1975: 0.020916193 | D1975: 0.023240699 | E1975: 0.01863403 | F1975: 1.1113427 | G1975: 1.0910986 | H1975: 1.1012206
...

Sheet 排序
A1: 排名 | B1: INV_ID | C1: 工作表 | D1: 列 | E1: 標籤 | F1: 初步分類 | G1: 主標記 | H1: 最大 |ε|（O01–O13） | I1: 所屬輸出 | J1: 分段 | K1: Interface 改變格數 | L1: 離散事件（前緣翻轉） | M1: 擾動格數 | N1: 單邊 | O1: O14 |ε|（另列）
A2: 1 | B2: INV-078 | C2: Serving | D2: 18 | E2: 實測→生產效率折減 | F2: Assumed | G2: Assumed | H2: 1.7324417 | I2: O05 | J2: 高 | K2: 1205 | M2: 1 | O2: 1.304788
A3: 2 | B3: INV-089 | C3: Workload | D3: 11 | E3: 歷史快取命中率 χ | F3: Assumed | G3: Assumed | H3: 1.599534 | I3: O13 | J3: 高 | K3: 84 | M3: 5 | O3: 1.2736519
A4: 3 | B4: INV-100 | C4: Calib | D4: 17 | E4: 實測 tok/s/GPU（總 token） | F4: 待分類 | H4: 1.3508007 | I4: O04 | J4: 高 | K4: 1160 | M4: 7 | O4: 1.0231604
A5: 4 | B5: INV-083 | C5: Workload | D5: 5 | E5: 輪數 T | F5: Assumed | G5: Assumed | H5: 1.1419317 | I5: O13 | J5: 高 | K5: 97 | M5: 5 | O5: 1.1012206
A6: 5 | B6: INV-097 | C6: Calib | D6: 14 | E6: 每用戶速度 | F6: 待分類 | H6: 1.1326037 | I6: O05 | J6: 高 | K6: 1160 | M6: 7 | O6: 0.47678638
A7: 6 | B7: INV-029 | C7: Spec_Rack | D7: 9 | E7: 配電設計功率 基準（kW） | F7: 待分類 | H7: 1.010612 | I7: O11 | J7: 高 | K7: 1085 | M7: 5 | O7: 0.23205326
A8: 7 | B8: INV-101 | C8: Calib | D8: 67 | E8: η_d 倍數 | F8: Analogy | G8: Analogy | H8: 1.010101 | I8: O04 | J8: 高 | K8: 1160 | M8: 5 | O8: 0.76509833
A9: 8 | B9: INV-077 | C9: Serving | D9: 17 | E9: 基準利用率（第 0 層） | F9: Assumed | G9: Assumed | H9: 1.010101 | I9: O10 | J9: 高 | K9: 540 | M9: 1 | O9: 1.0030037
A10: 9 | B10: INV-027 | C10: Spec_Rack | D10: 6 | E10: GPU 封裝／架 | F10: 待分類 | H10: 1.0068666 | I10: O08 | J10: 高 | K10: 1124 | M10: 5 | O10: 0.99979198
A11: 10 | B11: INV-001 | C11: Inputs | D11: 5 | E11: IT 電力規模 | F11: Decision | G11: Decision | H11: 1.0007404 | I11: O11 | J11: 高 | K11: 1085 | M11: 1 | O11: 0.00014455047
A12: 11 | B12: INV-152 | C12: Train_In | D12: 13 | E12: 研發倍數（研發總 GPU 小時 ÷ 最終訓練） | F12: Analogy | G12: Analogy | H12: 1 | I12: O08 | J12: 高 | K12: 226 | M12: 1 | O12: 0
A13: 12 | B13: INV-207 | C13: Cap_In | D13: 28 | E13: 對外服務占機隊 | F13: 原始數據（候選） | G13: Interested-party | H13: 1 | I13: O12 | J13: 高 | K13: 391 | M13: 3 | O13: 0
A14: 13 | B14: INV-091 | C14: Workload | D14: 13 | E14: harness token 倍數 | F14: 待分類 | H14: 1 | I14: O13 | J14: 高 | K14: 85 | M14: 5 | O14: 1
A15: 14 | B15: INV-079 | C15: Serving | D15: 21 | E15: SLO：每用戶 decode 速度下限 | F15: 原始數據（候選） | G15: Verified | H15: 0.91385915 | I15: O05 | J15: 高 | K15: 845 | M15: 3 | O15: 0.3560364
A16: 15 | B16: INV-099 | C16: Calib | D16: 16 | E16: OSL | F16: 待分類 | H16: 0.86308469 | I16: O05 | J16: 高 | K16: 1160 | M16: 7 | O16: 0.65159985
A17: 16 | B17: INV-208 | C17: Cap_In | D17: 29 | E17: 其中免費服務占服務 | F17: 原始數據（候選） | G17: Interested-party | H17: 0.85185185 | I17: O12 | J17: 高 | K17: 346 | M17: 3 | O17: 0
A18: 17 | B18: INV-098 | C18: Calib | D18: 15 | E18: ISL | F18: 待分類 | H18: 0.80163775 | I18: O05 | J18: 高 | K18: 1160 | M18: 7 | O18: 0.60207763
A19: 18 | B19: INV-032 | C19: Spec_Rack | D19: 12 | E19: 機架價格 基準（$M） | F19: 待分類 | H19: 0.7723573 | I19: O06 | J19: 高 | K19: 264 | M19: 5 | O19: 0.75779517
A20: 19 | B20: INV-082 | C20: Serving | D20: 24 | E20: 參考 OSL（含思考） | F20: Assumed | G20: Assumed | H20: 0.74068027 | I20: O10 | J20: 高 | K20: 851 | M20: 3 | O20: 0.00036187262
A21: 20 | B21: INV-047 | C21: Spec_Rack | D21: 40 | E21: FP8 dense PF/GPU（訓練基準，J7） | F21: 原始數據（候選） | G21: Interested-party | H21: 0.73229843 | I21: O07 | J21: 高 | K21: 495 | M21: 5 | O21: 0
A22: 21 | B22: INV-145 | C22: Train_In | D22: 6 | E22: 預訓練 MFU 基準（FP8 分母；GB200／GB300） | F22: Analogy | G22: Analogy | H22: 0.73229843 | I22: O07 | J22: 高 | K22: 495 | M22: 1 | O22: 0
A23: 22 | B23: INV-157 | C23: Train_In | D23: 21 | E23: 預訓練 MFU 世代倍數 | F23: Assumed | G23: Assumed | H23: 0.73229843 | I23: O07 | J23: 高 | K23: 495 | M23: 5 | O23: 0
A24: 23 | B24: INV-146 | C24: Train_In | D24: 7 | E24: goodput（扣除故障、重啟、checkpoint 的有效時間比） | F24: Analogy | G24: Analogy | H24: 0.73229843 | I24: O07 | J24: 高 | K24: 495 | M24: 1 | O24: 0
A25: 24 | B25: INV-158 | C25: Train_In | D25: 25 | E25: 預訓練 token | F25: 原始數據（候選） | G25: Verified | H25: 0.72513098 | I25: O09 | J25: 高 | K25: 495 | M25: 3 | O25: 0
A26: 25 | B26: INV-081 | C26: Serving | D26: 23 | E26: 參考 ISL（每次請求輸入） | F26: Assumed | G26: Assumed | H26: 0.70345561 | I26: O10 | J26: 高 | K26: 896 | M26: 3 | O26: 0.0066786353
A27: 26 | B27: INV-102 | C27: Calib | D27: 68 | E27: 每層延遲倍數 | F27: Assumed | G27: Assumed | H27: 0.68655609 | I27: O05 | J27: 高 | K27: 1160 | M27: 5 | O27: 0.29333356
A28: 27 | B28: INV-167 | C28: Train_In | D28: 34 | E28: RL rollout 輸出 token（含各領域專家） | F28: 待分類 | H28: 0.68078555 | I28: O09 | J28: 高 | K28: 495 | M28: 3 | O28: 0
A29: 28 | B29: INV-050 | C29: Arch | D29: 7 | E29: 啟用參數 | F29: 原始數據（候選） | G29: Verified | H29: 0.64181863 | I29: O05 | J29: 高 | K29: 1250 | M29: 3 | O29: 0.13311852
A30: 29 | B30: INV-196 | C30: Cap_In | D30: 8 | E30: 輸出（含思考 token） | F30: 原始數據（候選） | G30: Verified | H30: 0.55309735 | I30: O12 | J30: 高 | K30: 129 | M30: 3 | O30: 0
A31: 30 | B31: INV-015 | C31: Inputs | D31: 23 | E31: IT 設備折舊年限 | F31: 原始數據（候選） | G31: Verified | H31: 0.50517384 | I31: O06 | J31: 高 | K31: 644 | M31: 3 | O31: 0.4944922
A32: 31 | B32: INV-086 | C32: Workload | D32: 8 | E32: 每輪思考 token h | F32: Assumed | G32: Assumed | H32: 0.4435485 | I32: O13 | J32: 中 | K32: 72 | M32: 4 | O32: 0.42921986
A33: 32 | B33: INV-198 | C33: Cap_In | D33: 13 | E33: 參考請求快取命中率 χ（輸入中屬快取命中的比例） | F33: Assumed | G33: Assumed | H33: 0.4380531 | I33: O12 | J33: 中 | K33: 441 | M33: 3 | O33: 0
A34: 33 | B34: INV-148 | C34: Train_In | D34: 9 | E34: RL trainer MFU 係數（× 預訓練 MFU） | F34: Assumed | G34: Assumed | H34: 0.4189445 | I34: O09 | J34: 中 | K34: 495 | M34: 1 | O34: 0
A35: 34 | B35: INV-194 | C35: Cap_In | D35: 6 | E35: 新鮮輸入 | F35: 原始數據（候選） | G35: Verified | H35: 0.39823009 | I35: O12 | J35: 中 | K35: 126 | M35: 3 | O35: 0
A36: 35 | B36: INV-264 | C36: Har_In | D36: 48 | E36: 50% 時間範圍 基準 | F36: Analogy | G36: Analogy | H36: 0.37803485 | I36: O13 | J36: 中 | K36: 109 | M36: 3 | O36: 0.28192696
A37: 36 | B37: INV-268 | C37: Har_In | D37: 53 | E37: 任務長度（人類完成時間） | F37: Assumed | G37: Assumed | H37: 0.37519603 | I37: O13 | J37: 中 | K37: 99 | M37: 5 | O37: 0.27980985
A38: 37 | B38: INV-034 | C38: Spec_Rack | D38: 23 | E38: 峰值 dense（基準）PF/GPU | F38: 原始數據（候選） | G38: Interested-party | H38: 0.34060378 | I38: O04 | J38: 中 | K38: 1205 | M38: 5 | O38: 0.024136772
A39: 38 | B39: INV-094 | C39: Calib | D39: 5 | E39: η_p：prefill 達成峰值比例 | F39: Analogy | G39: Analogy | H39: 0.34060378 | I39: O04 | J39: 中 | K39: 1205 | M39: 1 | O39: 0.024136772
A40: 39 | B40: INV-150 | C40: Train_In | D40: 11 | E40: rollout 效率（長尾等待、權重同步、閒置） | F40: Analogy | G40: Analogy | H40: 0.32472349 | I40: O09 | J40: 中 | K40: 495 | M40: 1 | O40: 0
...

Sheet 各輸出前5
A1: 輸出 ID | B1: 名次 | C1: INV_ID | D1: 工作表 | E1: 列 | F1: 標籤 | G1: 初步分類 | H1: 主標記 | I1: |ε|
A2: O01 | B2: 1 | C2: INV-001 | D2: Inputs | E2: 5 | F2: IT 電力規模 | G2: Decision | H2: Decision | I2: 1.0005432
A3: O01 | B3: 2 | C3: INV-029 | D3: Spec_Rack | E3: 9 | F3: 配電設計功率 基準（kW） | G3: 待分類 | I3: 0.74150932
A4: O01 | B4: 3 | C4: INV-032 | D4: Spec_Rack | E4: 12 | F4: 機架價格 基準（$M） | G4: 待分類 | I4: 0.73065732
A5: O01 | B5: 4 | C5: INV-011 | D5: Inputs | E5: 18 | F5: 電力設施（變電、中壓、發電機、UPS） | G5: Assumed | H5: Assumed | I5: 0.10875954
A6: O01 | B6: 5 | C6: INV-010 | D6: Inputs | E6: 17 | F6: 建物與基地工程 | G6: Assumed | H6: Assumed | I6: 0.087007633
A7: O02 | B7: 1 | C7: INV-001 | D7: Inputs | E7: 5 | F7: IT 電力規模 | G7: Decision | H7: Decision | I7: 1.0005674
A8: O02 | B8: 2 | C8: INV-029 | D8: Spec_Rack | E8: 9 | F8: 配電設計功率 基準（kW） | G8: 待分類 | I8: 0.77449211
A9: O02 | B9: 3 | C9: INV-032 | D9: Spec_Rack | E9: 12 | F9: 機架價格 基準（$M） | G9: 待分類 | I9: 0.76315741
A10: O02 | B10: 4 | C10: INV-015 | D10: Inputs | E10: 23 | F10: IT 設備折舊年限 | G10: 原始數據（候選） | H10: Verified | I10: 0.49799128
A11: O02 | B11: 5 | C11: INV-020 | D11: Inputs | E11: 28 | F11: WACC（經濟口徑） | G11: Assumed | H11: Assumed | I11: 0.280379
A12: O03 | B12: 1 | C12: INV-078 | D12: Serving | E12: 18 | F12: 實測→生產效率折減 | G12: Assumed | H12: Assumed | I12: 1.2741023
A13: O03 | B13: 2 | C13: INV-029 | D13: Spec_Rack | E13: 9 | F13: 配電設計功率 基準（kW） | G13: 待分類 | I13: 1.010612
A14: O03 | B14: 3 | C14: INV-001 | D14: Inputs | E14: 5 | F14: IT 電力規模 | G14: Decision | H14: Decision | I14: 1.0007404
A15: O03 | B15: 4 | C15: INV-027 | D15: Spec_Rack | E15: 6 | F15: GPU 封裝／架 | G15: 待分類 | I15: 1
A16: O03 | B16: 5 | C16: INV-100 | D16: Calib | E16: 17 | F16: 實測 tok/s/GPU（總 token） | G16: 待分類 | I16: 0.94671767
A17: O04 | B17: 1 | C17: INV-078 | D17: Serving | E17: 18 | F17: 實測→生產效率折減 | G17: Assumed | H17: Assumed | I17: 1.4138743
A18: O04 | B18: 2 | C18: INV-100 | D18: Calib | E18: 17 | F18: 實測 tok/s/GPU（總 token） | G18: 待分類 | I18: 1.3508007
A19: O04 | B19: 3 | C19: INV-101 | D19: Calib | E19: 67 | F19: η_d 倍數 | G19: Analogy | H19: Analogy | I19: 1.010101
A20: O04 | B20: 4 | C20: INV-027 | D20: Spec_Rack | E20: 6 | F20: GPU 封裝／架 | G20: 待分類 | I20: 1.0068666
A21: O04 | B21: 5 | C21: INV-099 | D21: Calib | E21: 16 | F21: OSL | G21: 待分類 | I21: 0.86025761
A22: O05 | B22: 1 | C22: INV-078 | D22: Serving | E22: 18 | F22: 實測→生產效率折減 | G22: Assumed | H22: Assumed | I22: 1.7324417
A23: O05 | B23: 2 | C23: INV-100 | D23: Calib | E23: 17 | F23: 實測 tok/s/GPU（總 token） | G23: 待分類 | I23: 1.3252981
A24: O05 | B24: 3 | C24: INV-097 | D24: Calib | E24: 14 | F24: 每用戶速度 | G24: 待分類 | I24: 1.1326037
A25: O05 | B25: 4 | C25: INV-101 | D25: Calib | E25: 67 | F25: η_d 倍數 | G25: Analogy | H25: Analogy | I25: 1.010101
A26: O05 | B26: 5 | C26: INV-027 | D26: Spec_Rack | E26: 6 | F26: GPU 封裝／架 | G26: 待分類 | I26: 1.0068666
A27: O06 | B27: 1 | C27: INV-078 | D27: Serving | E27: 18 | F27: 實測→生產效率折減 | G27: Assumed | H27: Assumed | I27: 1.4830322
A28: O06 | B28: 2 | C28: INV-100 | D28: Calib | E28: 17 | F28: 實測 tok/s/GPU（總 token） | G28: 待分類 | I28: 1.3452042
A29: O06 | B29: 3 | C29: INV-101 | D29: Calib | E29: 67 | F29: η_d 倍數 | G29: Analogy | H29: Analogy | I29: 1.010101
A30: O06 | B30: 4 | C30: INV-027 | D30: Spec_Rack | E30: 6 | F30: GPU 封裝／架 | G30: 待分類 | I30: 1.0049945
A31: O06 | B31: 5 | C31: INV-099 | D31: Calib | E31: 16 | F31: OSL | G31: 待分類 | I31: 0.86087786
A32: O07 | B32: 1 | C32: INV-047 | D32: Spec_Rack | E32: 40 | F32: FP8 dense PF/GPU（訓練基準，J7） | G32: 原始數據（候選） | H32: Interested-party | I32: 0.73229843
A33: O07 | B33: 2 | C33: INV-145 | D33: Train_In | E33: 6 | F33: 預訓練 MFU 基準（FP8 分母；GB200／GB300） | G33: Analogy | H33: Analogy | I33: 0.73229843
A34: O07 | B34: 3 | C34: INV-157 | D34: Train_In | E34: 21 | F34: 預訓練 MFU 世代倍數 | G34: Assumed | H34: Assumed | I34: 0.73229843
A35: O07 | B35: 4 | C35: INV-146 | D35: Train_In | E35: 7 | F35: goodput（扣除故障、重啟、checkpoint 的有效時間比） | G35: Analogy | H35: Analogy | I35: 0.73229843
A36: O07 | B36: 5 | C36: INV-050 | D36: Arch | E36: 7 | F36: 啟用參數 | G36: 原始數據（候選） | H36: Verified | I36: 0.52038413
A37: O08 | B37: 1 | C37: INV-027 | D37: Spec_Rack | E37: 6 | F37: GPU 封裝／架 | G37: 待分類 | I37: 1.0068666
A38: O08 | B38: 2 | C38: INV-152 | D38: Train_In | E38: 13 | F38: 研發倍數（研發總 GPU 小時 ÷ 最終訓練） | G38: Analogy | H38: Analogy | I38: 1
A39: O08 | B39: 3 | C39: INV-032 | D39: Spec_Rack | E39: 12 | F39: 機架價格 基準（$M） | G39: 待分類 | I39: 0.76315741
A40: O08 | B40: 4 | C40: INV-047 | D40: Spec_Rack | E40: 40 | F40: FP8 dense PF/GPU（訓練基準，J7） | G40: 原始數據（候選） | H40: Interested-party | I40: 0.73229843
...

Sheet 不擾動
A1: INV_ID | B1: 工作表 | C1: 列 | D1: 標籤 | E1: 初步分類 | F1: 原因代碼 | G1: 靜態可達主要輸出 | H1: 可達 IF_ 數
A2: INV-002 | B2: Inputs | C2: 6 | D2: 功率情境（1 低／2 基準／3 高） | E2: Decision | F2: X2 | G2: O01、O02、O03、O04、O05、O06、O08、O10、O11、O12、O13、O14 | H2: 87
A3: INV-039 | B3: Spec_Rack | C3: 28 | D3: Scale-up 域 GPU 數 | E3: 待分類 | F3: X5a | H3: 0
A4: INV-043 | B4: Spec_Rack | C4: 32 | D4: 每 prefill 實例 GPU 數（算 TTFT） | E4: 待分類 | F4: X5a | H4: 0
A5: INV-044 | B5: Spec_Rack | C5: 33 | D5: GPU 功率 W/封裝（能量用） | E5: 原始數據（候選） | F5: X5a | H5: 0
A6: INV-045 | B6: Spec_Rack | C6: 34 | D6: HBM 存取能量 pJ/byte | E6: Analogy | F6: X5a | H6: 0
A7: INV-046 | B7: Spec_Rack | C7: 39 | D7: BF16 dense PF/GPU | E7: 原始數據（候選） | F7: X5a | H7: 0
A8: INV-048 | B8: Spec_Rack | C8: 41 | D8: NVFP4 訓練 dense PF/GPU（Tech_Registry 情境） | E8: Assumed | F8: X5a | H8: 0
A9: INV-058 | B9: Arch | C9: 15 | D9: vocab | E9: 原始數據（候選） | F9: X5a | H9: 0
A10: INV-063 | B10: Arch | C10: 20 | D10: Astra KV 情境（1 混合／2 全層 MLA／3 GQA-8） | E10: Decision | F10: X2 | G10: O03、O04、O05、O06、O07、O08、O09、O10、O11、O12、O13、O14 | H10: 93
A11: INV-076 | B11: Serving | C11: 16 | D11: 峰值情境（1＝dense 基準／2＝NVFP4 推論高） | E11: Decision | F11: X2 | G11: O03、O04、O05、O06、O07、O08、O09、O10、O11、O12、O13、O14 | H11: 92
A12: INV-080 | B12: Serving | C12: 22 | D12: TTFT 上限（只作檢查） | E12: Assumed | F12: X5a | H12: 0
A13: INV-088 | B13: Workload | C13: 10 | D13: 思考保留於上下文比例 ρ | E13: Assumed | F13: X3 | G13: O13、O14 | H13: 21
A14: INV-093 | B14: Workload | C14: 40 | D14: 參照：Anthropic 揭露倍數（相對聊天） | E14: 原始數據（候選） | F14: X5a | H14: 0
A15: INV-095 | B15: Calib | C15: 10 | D15: 世代索引 | E15: 情境選擇 | F15: X2 | G15: O03、O04、O05、O06、O07、O08、O09、O10、O11、O12、O13、O14 | H15: 89
A16: INV-096 | B16: Calib | C16: 13 | D16: MTP（1＝有） | E16: 待分類 | F16: X2 | G16: O03、O04、O05、O06、O07、O08、O09、O10、O11、O12、O13、O14 | H16: 89
A17: INV-104 | B17: Calib | C17: 90 | D17: η_p | E17: 待分類 | F17: X5a | H17: 0
A18: INV-105 | B18: Calib | C18: 100 | D18: 總參數 | E18: 原始數據（候選） | F18: X5a | H18: 0
A19: INV-106 | B19: Calib | C19: 101 | D19: 啟用參數 | E19: 待分類 | F19: X5a | H19: 0
A20: INV-107 | B20: Calib | C20: 102 | D20: 層數 | E20: 待分類 | F20: X5a | H20: 0
A21: INV-108 | B21: Calib | C21: 103 | D21: d_model | E21: 待分類 | F21: X5a | H21: 0
A22: INV-109 | B22: Calib | C22: 104 | D22: routed experts | E22: 待分類 | F22: X5a | H22: 0
A23: INV-110 | B23: Calib | C23: 105 | D23: 啟用 experts | E23: 待分類 | F23: X5a | H23: 0
A24: INV-111 | B24: Calib | C24: 106 | D24: shared experts | E24: 待分類 | F24: X5a | H24: 0
A25: INV-112 | B25: Calib | C25: 107 | D25: vocab | E25: 待分類 | F25: X5a | H25: 0
A26: INV-113 | B26: Calib | C26: 108 | D26: KV bytes/token（MLA 576 × 61 層，FP8） | E26: 待分類 | F26: X5a | H26: 0
A27: INV-114 | B27: Calib | C27: 109 | D27: 注意力 FLOPs／被注意 token（MLA：2×128×192＋2×128×128，× 61） | E27: 待分類 | F27: X5a | H27: 0
A28: INV-115 | B28: Calib | C28: 110 | D28: 平均 ISL（MLCommons 資料集） | E28: 待分類 | F28: X5a | H28: 0
... A32: INV-119 | B32: Calib | C32: 120 | D32: MLPerf 實測輸出 tok/s/GPU（總量 ÷ 72） | E32: 待分類 | F32: X5a | H32: 0
A33: INV-132 | B33: Perf | C33: 6 | D33: 世代索引 | E33: 情境選擇 | F33: X2 | G33: O03、O04、O05、O06、O10、O11、O12、O13、O14 | H33: 71
A34: INV-133 | B34: Perf | C34: 7 | D34: 層級索引 | E34: 情境選擇 | F34: X2 | G34: O03、O04、O05、O06、O10、O11、O12、O13、O14 | H34: 74
A35: INV-134 | B35: Sens_Perf | C35: 6 | D35: 世代索引 | E35: 情境選擇 | F35: X2 | H35: 0
A36: INV-135 | B36: Sens_Perf | C36: 7 | D36: 層級索引 | E36: 情境選擇 | F36: X2 | H36: 0
A37: INV-136 | B37: Sens_Perf | C37: 14 | D37: 計算用峰值 | E37: 情境選擇 | F37: X2 | H37: 0
A38: INV-137 | B38: Sens_Perf | C38: 41 | D38: SLO：每用戶 decode 速度下限 | E38: 情境選擇 | F38: X2 | H38: 0
A39: INV-138 | B39: Sens_Perf | C39: 43 | D39: 參考 ISL | E39: 情境選擇 | F39: X2 | H39: 0
A40: INV-139 | B40: Sens_Perf | C40: 48 | D40: 草稿接受率 | E40: 情境選擇 | F40: X5a | H40: 0
A41: INV-140 | B41: Sens_Perf | C41: 50 | D41: 實測→生產效率折減 | E41: 情境選擇 | F41: X5a | H41: 0
A42: INV-141 | B42: Sens_Perf | C42: 52 | D42: η_d 倍數（Tech_Registry H_ETAD；Sens_Perf 情境覆寫） | E42: 情境選擇 | F42: X5a | H42: 0
A43: INV-142 | B43: Sens_Perf | C43: 54 | D43: 每層延遲倍數（Tech_Registry H_TL；Sens_Perf 情境覆寫） | E43: 情境選擇 | F43: X5a | H43: 0
...

Sheet 主要輸出
A1: ID | B1: 具名範圍 | C1: 欄 | D1: 儲存格 | E1: 內容 | F1: 單位 | G1: 指令表基準值（6 位有效） | H1: 活頁簿快取值（LibreOffice） | I1: engine 基準值 | J1: engine vs 快取 相對誤差 | K1: engine vs 指令表 相對誤差
A2: O01 | B2: IF_CapexTotal | C2: 11 | D2: Interface!M11 | E2: VR200 每 GW 資本支出合計 | F2: $B | G2: 47.582 | H2: 47.582032 | I2: 47.582032 | J2: 0 | K2: 6.7252322e-07
A3: O02 | B3: IF_HoldEcon | C3: 11 | D3: Interface!M13 | E3: VR200 每 GW 年持有成本（經濟） | F3: $B/年 | G3: 12.0544 | H3: 12.054371 | I3: 12.054371 | J3: 1.0315344e-15 | K3: 2.4085132e-06
A4: O03 | B4: IF_TokGW_Sol | C4: 11 | D4: Interface!M31 | E4: VR200 Sol 每 GW 總產出（100%） | F4: M tok/年 | G4: 238098000000 | H4: 2.3809835e+11 | I4: 2.3809835e+11 | J4: 1.666238e-15 | K4: 1.4909218e-06
A5: O04 | B5: IF_CostDec_Sol | C5: 11 | D5: Interface!M35 | E5: VR200 Sol decode $/M（經濟、100%） | F5: $/M | G5: 0.322576 | H5: 0.3225757 | I5: 0.3225757 | J5: 1.7208721e-16 | K5: 9.3830269e-07
A6: O05 | B6: IF_CostDec_Astra | C6: 11 | D6: Interface!M45 | E6: VR200 Astra decode $/M | F6: $/M | G6: 1.66066 | H6: 1.6606622 | I6: 1.6606622 | J6: 1.8719186e-15 | K6: 1.3022356e-06
A7: O06 | B7: IF_CostDec_Sol | C7: 8 | D7: Interface!J35 | E7: GB300 Sol decode $/M | F7: $/M | G7: 0.556984 | H7: 0.55698369 | I7: 0.55698369 | J7: 7.9731098e-16 | K7: 5.5581488e-07
A8: O07 | B8: IF_TrainGPUh_Astra | C8: 11 | D8: Interface!M72 | E8: VR200 Astra 最終訓練 GPU 小時 | F8: GPU-hr | G8: 11677700 | H8: 11677661 | I8: 11677661 | J8: 1.5950499e-15 | K8: 3.3640749e-06
A9: O08 | B9: IF_ProgCost_Astra | C9: 11 | D9: Interface!M78 | E9: VR200 Astra 研發計畫成本（經濟） | F9: $M | G9: 440.64 | H9: 440.64044 | I9: 440.64044 | J9: 0 | K9: 1.0008913e-06
A10: O09 | B10: IF_PostShareGPUh_Sol | C10: 11 | D10: Interface!M66 | E10: VR200 Sol 後訓練占比（GPU 小時） | F10: % | G10: 0.255756 | H10: 0.25575637 | I10: 0.25575637 | J10: 1.085235e-15 | K10: 1.4588592e-06
A11: O10 | B11: IF_FullCostDefault_Sol | C11: 11 | D11: Interface!M118 | E11: VR200 Sol 全成本 $/M（下游預設） | F11: $/M | G11: 0.104696 | H11: 0.10469626 | I11: 0.10469626 | J11: 1.5906342e-15 | K11: 2.4765646e-06
A12: O11 | B12: IF_RevGW_Sol | C12: 11 | D12: Interface!M119 | E12: VR200 Sol 每 GW 理論營收 | F12: $B/年 | G12: 229.59 | H12: 229.59031 | I12: 229.59031 | J12: 4.9517264e-16 | K12: 1.3376048e-06
A13: O12 | B13: IF_RevGWFleet | C13: 11 | D13: Interface!M143 | E13: VR200 1 GW 參考機隊付費服務營收 | F13: $B/年 | G13: 49.1065 | H13: 49.106545 | I13: 49.106545 | J13: 8.681646e-16 | K13: 9.1685556e-07
... A15: O14 | B15: IF_FrontSuccVR | C15: 5 | D15: Interface!G190 | E15: Coding agent 成功任務成本前緣 | F15: $（或文字「無合格」） | G15: 0.0209162 | H15: 0.020916193 | I15: 0.020916193 | J15: 8.2936865e-16 | K15: 3.3413376e-07

Sheet 異常
A1: 類型 | B1: INV_ID | C1: 工作表 | D1: 列／格 | E1: 標籤／輸出 | F1: 內容 | G1: 初步分類
A2: 多標記 | B2: INV-006 | C2: Inputs | D2: 11 | E2: 電價 | F2: Verified、Analogy | G2: 原始數據（候選）
A3: 多標記 | B3: INV-034 | C3: Spec_Rack | D3: 23 | E3: 峰值 dense（基準）PF/GPU | F3: Interested-party、Derived | G3: 原始數據（候選）
A4: 多標記 | B4: INV-040 | C4: Spec_Rack | D4: 29 | E4: decode EP 基準寬度 | F4: Analogy、Assumed | G4: Analogy
A5: 多標記 | B5: INV-046 | C5: Spec_Rack | D5: 39 | E5: BF16 dense PF/GPU | F5: Interested-party、Assumed | G5: 原始數據（候選）
A6: 多標記 | B6: INV-048 | C6: Spec_Rack | D6: 41 | E6: NVFP4 訓練 dense PF/GPU（Tech_Registry 情境） | F6: Assumed、Derived | G6: Assumed
A7: 多標記 | B7: INV-049 | C7: Arch | D7: 6 | E7: 總參數 | F7: Verified、Assumed | G7: 原始數據（候選）
A8: 多標記 | B8: INV-050 | C8: Arch | D8: 7 | E8: 啟用參數 | F8: Verified、Assumed | G8: 原始數據（候選）
A9: 多標記 | B9: INV-051 | C9: Arch | D9: 8 | E9: 層數 | F9: Verified、Assumed | G9: 原始數據（候選）
A10: 多標記 | B10: INV-052 | C10: Arch | D10: 9 | E10: d_model | F10: Verified、Assumed、Derived | G10: 原始數據（候選）
A11: 多標記 | B11: INV-053 | C11: Arch | D11: 10 | E11: query heads | F11: Verified、Analogy | G11: 原始數據（候選）
A12: 多標記 | B12: INV-054 | C12: Arch | D12: 11 | E12: head_dim | F12: Verified、Assumed | G12: 原始數據（候選）
A13: 多標記 | B13: INV-055 | C13: Arch | D13: 12 | E13: routed experts | F13: Verified、Assumed | G13: 原始數據（候選）
... A30: Derived 藍字 | B30: INV-267 | C30: Har_In | D30: 51 | E30: 斜率 β（C＝基準、D＝低、E＝高） | F30: Derived | G30: Derived 藍字（異常）
A31: 藍字公式格 | C31: Calib | D31: C118 | E31: 每用戶速度下限（1000 ÷ TPOT） | F31: =1000/15
A32: 藍字公式格 | C32: Calib | D32: D118 | E32: 每用戶速度下限（1000 ÷ TPOT） | F32: =1000/15
A33: 藍字公式格 | C33: Calib | D33: E118 | E33: 每用戶速度下限（1000 ÷ TPOT） | F33: =1000/15
A34: 藍字公式格 | C34: Calib | D34: F118 | E34: 每用戶速度下限（1000 ÷ TPOT） | F34: =1000/80
A35: 藍字公式格 | C35: Calib | D35: C120 | E35: MLPerf 實測輸出 tok/s/GPU（總量 ÷ 72） | F35: =253506/72
A36: 藍字公式格 | C36: Calib | D36: D120 | E36: MLPerf 實測輸出 tok/s/GPU（總量 ÷ 72） | F36: =240318/72
A37: 藍字公式格 | C37: Calib | D37: E120 | E37: MLPerf 實測輸出 tok/s/GPU（總量 ÷ 72） | F37: =652750/72
A38: 藍字公式格 | C38: Sens_Perf | D38: AC34 | E38: KV bytes/token（含 H_KV） | F38: =Arch!$E$21
A39: 藍字公式格 | C39: Sens_Perf | D39: AD34 | E39: KV bytes/token（含 H_KV） | F39: =Arch!$E$21
A40: 藍字公式格 | C40: Sens_Perf | D40: AE34 | E40: KV bytes/token（含 H_KV） | F40: =Arch!$E$22
A41: 藍字公式格 | C41: Sens_Perf | D41: AF34 | E41: KV bytes/token（含 H_KV） | F41: =Arch!$E$22
A42: 藍字公式格 | C42: Sens_Perf | D42: AG34 | E42: KV bytes/token（含 H_KV） | F42: =Arch!$E$23
A43: 藍字公式格 | C43: Sens_Perf | D43: AH34 | E43: KV bytes/token（含 H_KV） | F43: =Arch!$E$23
A44: 藍字公式格 | C44: Perf_Batch | D44: R14 | E44: 計算用峰值 | F44: =Spec_Rack!$F$40
A45: 藍字公式格 | C45: Perf_Batch | D45: S14 | E45: 計算用峰值 | F45: =Spec_Rack!$F$40
A46: 藍字公式格 | C46: Sens_Train | D46: I10 | E46: FP8 dense 峰值 | F46: =INDEX(Spec_Rack!$C$41:$G$41,I$6)
A47: 藍字公式格 | C47: Sens_Train | D47: J10 | E47: FP8 dense 峰值 | F47: =INDEX(Spec_Rack!$C$41:$G$41,J$6)
A48: 藍字公式格 | C48: Sens_Train | D48: O53 | E48: rollout 輸出 token | F48: =INDEX(Train_In!$C$34:$E$34,O$7)*0.3
A49: 藍字公式格 | C49: Sens_Train | D49: P53 | E49: rollout 輸出 token | F49: =INDEX(Train_In!$C$34:$E$34,P$7)*0.3
A50: 藍字公式格 | C50: Sens_Train | D50: Q53 | E50: rollout 輸出 token | F50: =INDEX(Train_In!$C$34:$E$34,Q$7)*3
A51: 藍字公式格 | C51: Sens_Train | D51: R53 | E51: rollout 輸出 token | F51: =INDEX(Train_In!$C$34:$E$34,R$7)*3
A52: 藍字公式格 | C52: Sens_Train | D52: W59 | E52: rollout decode GPU 秒／M（Perf_Batch 本層級） | F52: =Perf_Batch!R103
A53: 藍字公式格 | C53: Sens_Train | D53: X59 | E53: rollout decode GPU 秒／M（Perf_Batch 本層級） | F53: =Perf_Batch!S103
A54: 藍字公式格 | C54: Sens_Train | D54: W60 | E54: rollout prefill GPU 秒／M | F54: =Perf_Batch!R101
A55: 藍字公式格 | C55: Sens_Train | D55: X60 | E55: rollout prefill GPU 秒／M | F55: =Perf_Batch!S101
A56: 藍字公式格 | C56: Sens_Train | D56: W61 | E56: rollout decode FLOPs/token | F56: =Perf_Batch!R65
...
