Workbook

Sheet 結果
A1: J7 結果：僅 Epoch 追蹤之 OpenAI 相關站點的 2026 增量（IT 電力），加到 2025 年底 1.9 GW；Epoch 未涵蓋的增量（Azure 其他、Oracle 其他、Google、AWS、AMD、Cerebras）只會使 GW 更高、倍數更低
A3: 持平門檻 GW（2026 比值＝2025 比值） | B3: 值 | C3: 公式說明
A4: Q2 年化 ÷ Q2 季平均 | B4: =參數!B14/(參數!B12*參數!B13) -> 2.166884 | C4: 營收 ÷（2025 比值 × h）
A5: FY2026 ÷ 全年平均 | B5: =參數!B15/(參數!B12*參數!B13) -> 2.883686
A6: 9 月底 run-rate ÷ 2026 年底 GW（時點不一致：run-rate 為 9 月底；年底 run-rate 若更高，倍數更高） | B6: =參數!B16/(參數!B12*參數!B13) -> 4.1195514
A8: 情境（占比／上線時點；早＝證據未排除的最早日期） | B8: Q2 季平均 GW | C8: Q2 倍數 | D8: 全年平均 GW | E8: 全年倍數 | F8: 2026 年底 GW | G8: 年底倍數 | H8: Q2 倍數（營收 268 億）
A9: 低占比＋晚（Epoch 日期） | B9: =參數!$B$2+SUMPRODUCT(站點彙總!$D$2:$D$22,(站點彙總!$B$2:$B$22="confident")*參數!$B$24+(站點彙總!$B$2:$B$22="likely")*參數!$C$24+(站點彙總!$B$2:$B$22="speculative")*參數!$D$24)/1000 -> 2.205511 | C9: =$B$4/B9 -> 0.98248616 | D9: =參數!$B$2+SUMPRODUCT(站點彙總!$F$2:$F$22,(站點彙總!$B$2:$B$22="confident")*參數!$B$24+(站點彙總!$B$2:$B$22="likely")*參數!$C$24+(站點彙總!$B$2:$B$22="speculative")*參數!$D$24)/1000 -> 2.3939849 | E9: =$B$5/D9 -> 1.2045548 | F9: =參數!$B$2+SUMPRODUCT(站點彙總!$H$2:$H$22,(站點彙總!$B$2:$B$22="confident")*參數!$B$24+(站點彙總!$B$2:$B$22="likely")*參數!$C$24+(站點彙總!$B$2:$B$22="speculative")*參數!$D$24)/1000 -> 3.1715 | G9: =$B$6/F9 -> 1.2989284 | H9: =參數!$B$17/(參數!$B$12*參數!$B$13*B9) -> 1.0011646
A10: 低占比＋早（證據下限日期） | B10: =參數!$B$2+SUMPRODUCT(站點彙總!$E$2:$E$22,(站點彙總!$B$2:$B$22="confident")*參數!$B$24+(站點彙總!$B$2:$B$22="likely")*參數!$C$24+(站點彙總!$B$2:$B$22="speculative")*參數!$D$24)/1000 -> 2.3904341 | C10: =$B$4/B10 -> 0.9064814 | D10: =參數!$B$2+SUMPRODUCT(站點彙總!$G$2:$G$22,(站點彙總!$B$2:$B$22="confident")*參數!$B$24+(站點彙總!$B$2:$B$22="likely")*參數!$C$24+(站點彙總!$B$2:$B$22="speculative")*參數!$D$24)/1000 -> 2.4502986 | E10: =$B$5/D10 -> 1.1768712 | F10: =參數!$B$2+SUMPRODUCT(站點彙總!$I$2:$I$22,(站點彙總!$B$2:$B$22="confident")*參數!$B$24+(站點彙總!$B$2:$B$22="likely")*參數!$C$24+(站點彙總!$B$2:$B$22="speculative")*參數!$D$24)/1000 -> 3.1715 | G10: =$B$6/F10 -> 1.2989284 | H10: =參數!$B$17/(參數!$B$12*參數!$B$13*B10) -> 0.92371488
A11: 中占比＋晚（Epoch 日期） | B11: =參數!$B$2+SUMPRODUCT(站點彙總!$D$2:$D$22,(站點彙總!$B$2:$B$22="confident")*參數!$B$25+(站點彙總!$B$2:$B$22="likely")*參數!$C$25+(站點彙總!$B$2:$B$22="speculative")*參數!$D$25)/1000 -> 2.3400742 | C11: =$B$4/B11 -> 0.92598946 | D11: =參數!$B$2+SUMPRODUCT(站點彙總!$F$2:$F$22,(站點彙總!$B$2:$B$22="confident")*參數!$B$25+(站點彙總!$B$2:$B$22="likely")*參數!$C$25+(站點彙總!$B$2:$B$22="speculative")*參數!$D$25)/1000 -> 2.5709144 | E11: =$B$5/D11 -> 1.1216577 | F11: =參數!$B$2+SUMPRODUCT(站點彙總!$H$2:$H$22,(站點彙總!$B$2:$B$22="confident")*參數!$B$25+(站點彙總!$B$2:$B$22="likely")*參數!$C$25+(站點彙總!$B$2:$B$22="speculative")*參數!$D$25)/1000 -> 3.48375 | G11: =$B$6/F11 -> 1.1825049 | H11: =參數!$B$17/(參數!$B$12*參數!$B$13*B11) -> 0.94359382
A12: 中占比＋早（證據下限日期） | B12: =參數!$B$2+SUMPRODUCT(站點彙總!$E$2:$E$22,(站點彙總!$B$2:$B$22="confident")*參數!$B$25+(站點彙總!$B$2:$B$22="likely")*參數!$C$25+(站點彙總!$B$2:$B$22="speculative")*參數!$D$25)/1000 -> 2.5875577 | C12: =$B$4/B12 -> 0.83742443 | D12: =參數!$B$2+SUMPRODUCT(站點彙總!$G$2:$G$22,(站點彙總!$B$2:$B$22="confident")*參數!$B$25+(站點彙總!$B$2:$B$22="likely")*參數!$C$25+(站點彙總!$B$2:$B$22="speculative")*參數!$D$25)/1000 -> 2.6533548 | E12: =$B$5/D12 -> 1.0868075 | F12: =參數!$B$2+SUMPRODUCT(站點彙總!$I$2:$I$22,(站點彙總!$B$2:$B$22="confident")*參數!$B$25+(站點彙總!$B$2:$B$22="likely")*參數!$C$25+(站點彙總!$B$2:$B$22="speculative")*參數!$D$25)/1000 -> 3.48375 | G12: =$B$6/F12 -> 1.1825049 | H12: =參數!$B$17/(參數!$B$12*參數!$B$13*B12) -> 0.85334504
A13: 高占比＋晚（Epoch 日期） | B13: =參數!$B$2+SUMPRODUCT(站點彙總!$D$2:$D$22,(站點彙總!$B$2:$B$22="confident")*參數!$B$26+(站點彙總!$B$2:$B$22="likely")*參數!$C$26+(站點彙總!$B$2:$B$22="speculative")*參數!$D$26)/1000 -> 2.5282527 | C13: =$B$4/B13 -> 0.8570678 | D13: =參數!$B$2+SUMPRODUCT(站點彙總!$F$2:$F$22,(站點彙總!$B$2:$B$22="confident")*參數!$B$26+(站點彙總!$B$2:$B$22="likely")*參數!$C$26+(站點彙總!$B$2:$B$22="speculative")*參數!$D$26)/1000 -> 2.8235315 | E13: =$B$5/D13 -> 1.0213047 | F13: =參數!$B$2+SUMPRODUCT(站點彙總!$H$2:$H$22,(站點彙總!$B$2:$B$22="confident")*參數!$B$26+(站點彙總!$B$2:$B$22="likely")*參數!$C$26+(站點彙總!$B$2:$B$22="speculative")*參數!$D$26)/1000 -> 3.981 | G13: =$B$6/F13 -> 1.0348032 | H13: =參數!$B$17/(參數!$B$12*參數!$B$13*B13) -> 0.87336186
A14: 高占比＋早（證據下限日期） | B14: =參數!$B$2+SUMPRODUCT(站點彙總!$E$2:$E$22,(站點彙總!$B$2:$B$22="confident")*參數!$B$26+(站點彙總!$B$2:$B$22="likely")*參數!$C$26+(站點彙總!$B$2:$B$22="speculative")*參數!$D$26)/1000 -> 2.8477253 | C14: =$B$4/B14 -> 0.76091751 | D14: =參數!$B$2+SUMPRODUCT(站點彙總!$G$2:$G$22,(站點彙總!$B$2:$B$22="confident")*參數!$B$26+(站點彙總!$B$2:$B$22="likely")*參數!$C$26+(站點彙總!$B$2:$B$22="speculative")*參數!$D$26)/1000 -> 2.9452986 | E14: =$B$5/D14 -> 0.97908101 | F14: =參數!$B$2+SUMPRODUCT(站點彙總!$I$2:$I$22,(站點彙總!$B$2:$B$22="confident")*參數!$B$26+(站點彙總!$B$2:$B$22="likely")*參數!$C$26+(站點彙總!$B$2:$B$22="speculative")*參數!$D$26)/1000 -> 3.981 | G14: =$B$6/F14 -> 1.0348032 | H14: =參數!$B$17/(參數!$B$12*參數!$B$13*B14) -> 0.77538362
A15: 最小 | B15: =MIN(B9:B14) -> 2.205511 | C15: =MIN(C9:C14) -> 0.76091751 | D15: =MIN(D9:D14) -> 2.3939849 | E15: =MIN(E9:E14) -> 0.97908101 | F15: =MIN(F9:F14) -> 3.1715 | G15: =MIN(G9:G14) -> 1.0348032 | H15: =MIN(H9:H14) -> 0.77538362
A16: 最大 | B16: =MAX(B9:B14) -> 2.8477253 | C16: =MAX(C9:C14) -> 0.98248616 | D16: =MAX(D9:D14) -> 2.9452986 | E16: =MAX(E9:E14) -> 1.2045548 | F16: =MAX(F9:F14) -> 3.981 | G16: =MAX(G9:G14) -> 1.2989284 | H16: =MAX(H9:H14) -> 1.0011646
A18: 2025 基準檢查：用同一批站點的 2025 時間分布估 2025 平均 GW（其餘增量線性） | B18: 2025 平均 GW | C18: 2025 比值 | D18: Epoch 站 2025 增量 GW | E18: 其餘增量 GW
A19: 低占比 | B19: =參數!$B$18+SUMPRODUCT(站點彙總!$K$2:$K$22,(站點彙總!$B$2:$B$22="confident")*參數!$B$24+(站點彙總!$B$2:$B$22="likely")*參數!$C$24+(站點彙總!$B$2:$B$22="speculative")*參數!$D$24)/1000+0.5*E19 -> 1.1142822 | C19: =參數!$B$19/(B19*參數!$B$20) -> 1.2540922 | D19: =(SUMPRODUCT(站點彙總!$C$2:$C$22,(站點彙總!$B$2:$B$22="confident")*參數!$B$24+(站點彙總!$B$2:$B$22="likely")*參數!$C$24+(站點彙總!$B$2:$B$22="speculative")*參數!$D$24)-SUMPRODUCT(站點彙總!$J$2:$J$22,(站點彙總!$B$2:$B$22="confident")*參數!$B$24+(站點彙總!$B$2:$B$22="likely")*參數!$C$24+(站點彙總!$B$2:$B$22="speculative")*參數!$D$24))/1000 -> 0.486 | E19: =(參數!$B$2-參數!$B$18)-D19 -> 0.814
A20: 中占比 | B20: =參數!$B$18+SUMPRODUCT(站點彙總!$K$2:$K$22,(站點彙總!$B$2:$B$22="confident")*參數!$B$25+(站點彙總!$B$2:$B$22="likely")*參數!$C$25+(站點彙總!$B$2:$B$22="speculative")*參數!$D$25)/1000+0.5*E20 -> 1.0856195 | C20: =參數!$B$19/(B20*參數!$B$20) -> 1.2872029 | D20: =(SUMPRODUCT(站點彙總!$C$2:$C$22,(站點彙總!$B$2:$B$22="confident")*參數!$B$25+(站點彙總!$B$2:$B$22="likely")*參數!$C$25+(站點彙總!$B$2:$B$22="speculative")*參數!$D$25)-SUMPRODUCT(站點彙總!$J$2:$J$22,(站點彙總!$B$2:$B$22="confident")*參數!$B$25+(站點彙總!$B$2:$B$22="likely")*參數!$C$25+(站點彙總!$B$2:$B$22="speculative")*參數!$D$25))/1000 -> 0.67475 | E20: =(參數!$B$2-參數!$B$18)-D20 -> 0.62525
A21: 高占比 | B21: =參數!$B$18+SUMPRODUCT(站點彙總!$K$2:$K$22,(站點彙總!$B$2:$B$22="confident")*參數!$B$26+(站點彙總!$B$2:$B$22="likely")*參數!$C$26+(站點彙總!$B$2:$B$22="speculative")*參數!$D$26)/1000+0.5*E21 -> 1.0600767 | C21: =參數!$B$19/(B21*參數!$B$20) -> 1.3182184 | D21: =(SUMPRODUCT(站點彙總!$C$2:$C$22,(站點彙總!$B$2:$B$22="confident")*參數!$B$26+(站點彙總!$B$2:$B$22="likely")*參數!$C$26+(站點彙總!$B$2:$B$22="speculative")*參數!$D$26)-SUMPRODUCT(站點彙總!$J$2:$J$22,(站點彙總!$B$2:$B$22="confident")*參數!$B$26+(站點彙總!$B$2:$B$22="likely")*參數!$C$26+(站點彙總!$B$2:$B$22="speculative")*參數!$D$26))/1000 -> 0.966 | E21: =(參數!$B$2-參數!$B$18)-D21 -> 0.334
A22: 對照：TK 內插 1.128 GW 時（實算 1.2388；主表用取整 1.239，k 表 k=1 列因此差 <0.001） | B22: =參數!B21 -> 1.128 | C22: =參數!B19/(B22*參數!B20) -> 1.238841
A24: 敏感度：Q2 倍數對 2025 比值（低占比＋晚，最保守 GW） | B24: 2025 比值 | C24: Q2 門檻 GW | D24: Q2 倍數
B25: 1.118 | C25: =參數!$B$14/(B25*參數!$B$13) -> 2.4014037 | D25: =C25/$B$9 -> 1.0888196
B26: 1.18 | C26: =參數!$B$14/(B26*參數!$B$13) -> 2.2752282 | D26: =C26/$B$9 -> 1.0316105
B27: 1.239 | C27: =參數!$B$14/(B27*參數!$B$13) -> 2.166884 | D27: =C27/$B$9 -> 0.98248616
B28: 1.254 | C28: =參數!$B$14/(B28*參數!$B$13) -> 2.1409643 | D28: =C28/$B$9 -> 0.97073393
B29: 1.287 | C29: =參數!$B$14/(B29*參數!$B$13) -> 2.0860678 | D29: =C29/$B$9 -> 0.94584332
B30: 1.318 | C30: =參數!$B$14/(B30*參數!$B$13) -> 2.0370025 | D30: =C30/$B$9 -> 0.92359662
B31: 1.397 | C31: =參數!$B$14/(B31*參數!$B$13) -> 1.9218105 | D31: =C31/$B$9 -> 0.87136746
A33: 敏感度：Friar 1.9 GW 的縮放係數 k（2024、2025 年底與 2025 平均 GW 同乘 k；Epoch 站增量不變） | B33: k | C33: 2025 比值 | D33: Q2 門檻 GW | E33: Q2 GW（低＋晚） | F33: Q2 倍數（低＋晚） | G33: Q2 GW（中＋晚） | H33: Q2 倍數（中＋晚）
B34: 0.9 | C34: =參數!$B$19/(B34*參數!$B$21*參數!$B$20) -> 1.3764899 | D34: =參數!$B$14/(C34*參數!$B$13) -> 1.950446 | E34: =B34*參數!$B$2+($B$9-參數!$B$2) -> 2.015511 | F34: =D34/E34 -> 0.96771786 | G34: =B34*參數!$B$2+($B$11-參數!$B$2) -> 2.1500742 | H34: =D34/G34 -> 0.90715288
B35: 1 | C35: =參數!$B$19/(B35*參數!$B$21*參數!$B$20) -> 1.238841 | D35: =參數!$B$14/(C35*參數!$B$13) -> 2.1671622 | E35: =B35*參數!$B$2+($B$9-參數!$B$2) -> 2.205511 | F35: =D35/E35 -> 0.98261229 | G35: =B35*參數!$B$2+($B$11-參數!$B$2) -> 2.3400742 | H35: =D35/G35 -> 0.92610834
B36: 1.04 | C36: =參數!$B$19/(B36*參數!$B$21*參數!$B$20) -> 1.1911932 | D36: =參數!$B$14/(C36*參數!$B$13) -> 2.2538487 | E36: =B36*參數!$B$2+($B$9-參數!$B$2) -> 2.281511 | F36: =D36/E36 -> 0.98787545 | G36: =B36*參數!$B$2+($B$11-參數!$B$2) -> 2.4160742 | H36: =D36/G36 -> 0.93285575
B37: 1.1 | C37: =參數!$B$19/(B37*參數!$B$21*參數!$B$20) -> 1.126219 | D37: =參數!$B$14/(C37*參數!$B$13) -> 2.3838784 | E37: =B37*參數!$B$2+($B$9-參數!$B$2) -> 2.395511 | F37: =D37/E37 -> 0.99514402 | G37: =B37*參數!$B$2+($B$11-參數!$B$2) -> 2.5300742 | H37: =D37/G37 -> 0.94221681
B38: 1.2 | C38: =參數!$B$19/(B38*參數!$B$21*參數!$B$20) -> 1.0323675 | D38: =參數!$B$14/(C38*參數!$B$13) -> 2.6005946 | E38: =B38*參數!$B$2+($B$9-參數!$B$2) -> 2.585511 | F38: =D38/E38 -> 1.0058339 | G38: =B38*參數!$B$2+($B$11-參數!$B$2) -> 2.7200742 | H38: =D38/G38 -> 0.9560749
A40: 敏感度：OpenAI 在 Fairwater 兩站的占比 f（其他站維持「低」占比；核對 C1） | B40: f | C40: Q2 GW（晚） | D40: Q2 倍數（晚） | E40: Q2 倍數（晚，268 億） | F40: Q2 GW（早） | G40: Q2 倍數（早） | H40: Q2 倍數（早，268 億）
B41: 0 | C41: =$B$9+(B41-參數!$C$24)*SUMIF(站點彙總!$A$2:$A$22,"Microsoft Fairwater*",站點彙總!$D$2:$D$22)/1000 -> 2.022 | D41: =$B$4/C41 -> 1.0716538 | E41: =參數!$B$17/(參數!$B$12*參數!$B$13*C41) -> 1.0920275 | F41: =$B$10+(B41-參數!$C$24)*SUMIF(站點彙總!$A$2:$A$22,"Microsoft Fairwater*",站點彙總!$E$2:$E$22)/1000 -> 2.1567308 | G41: =$B$4/F41 -> 1.0047077 | H41: =參數!$B$17/(參數!$B$12*參數!$B$13*F41) -> 1.0238086
B42: 0.25 | C42: =$B$9+(B42-參數!$C$24)*SUMIF(站點彙總!$A$2:$A$22,"Microsoft Fairwater*",站點彙總!$D$2:$D$22)/1000 -> 2.1137555 | D42: =$B$4/C42 -> 1.0251347 | E42: =參數!$B$17/(參數!$B$12*參數!$B$13*C42) -> 1.0446239 | F42: =$B$10+(B42-參數!$C$24)*SUMIF(站點彙總!$A$2:$A$22,"Microsoft Fairwater*",站點彙總!$E$2:$E$22)/1000 -> 2.2735824 | G42: =$B$4/F42 -> 0.95307036 | H42: =參數!$B$17/(參數!$B$12*參數!$B$13*F42) -> 0.97118957
B43: 0.4 | C43: =$B$9+(B43-參數!$C$24)*SUMIF(站點彙總!$A$2:$A$22,"Microsoft Fairwater*",站點彙總!$D$2:$D$22)/1000 -> 2.1688088 | D43: =$B$4/C43 -> 0.99911252 | E43: =參數!$B$17/(參數!$B$12*參數!$B$13*C43) -> 1.0181071 | F43: =$B$10+(B43-參數!$C$24)*SUMIF(站點彙總!$A$2:$A$22,"Microsoft Fairwater*",站點彙總!$E$2:$E$22)/1000 -> 2.3436934 | G43: =$B$4/F43 -> 0.9245595 | H43: =參數!$B$17/(參數!$B$12*參數!$B$13*F43) -> 0.94213668
B44: 0.5 | C44: =$B$9+(B44-參數!$C$24)*SUMIF(站點彙總!$A$2:$A$22,"Microsoft Fairwater*",站點彙總!$D$2:$D$22)/1000 -> 2.205511 | D44: =$B$4/C44 -> 0.98248616 | E44: =參數!$B$17/(參數!$B$12*參數!$B$13*C44) -> 1.0011646 | F44: =$B$10+(B44-參數!$C$24)*SUMIF(站點彙總!$A$2:$A$22,"Microsoft Fairwater*",站點彙總!$E$2:$E$22)/1000 -> 2.3904341 | G44: =$B$4/F44 -> 0.9064814 | H44: =參數!$B$17/(參數!$B$12*參數!$B$13*F44) -> 0.92371488
B45: 0.75 | C45: =$B$9+(B45-參數!$C$24)*SUMIF(站點彙總!$A$2:$A$22,"Microsoft Fairwater*",站點彙總!$D$2:$D$22)/1000 -> 2.2972665 | D45: =$B$4/C45 -> 0.94324452 | E45: =參數!$B$17/(參數!$B$12*參數!$B$13*C45) -> 0.96117692 | F45: =$B$10+(B45-參數!$C$24)*SUMIF(站點彙總!$A$2:$A$22,"Microsoft Fairwater*",站點彙總!$E$2:$E$22)/1000 -> 2.5072857 | G45: =$B$4/F45 -> 0.86423498 | H45: =參數!$B$17/(參數!$B$12*參數!$B$13*F45) -> 0.8806653
B46: 1 | C46: =$B$9+(B46-參數!$C$24)*SUMIF(站點彙總!$A$2:$A$22,"Microsoft Fairwater*",站點彙總!$D$2:$D$22)/1000 -> 2.389022 | D46: =$B$4/C46 -> 0.9070172 | E46: =參數!$B$17/(參數!$B$12*參數!$B$13*C46) -> 0.92426087 | F46: =$B$10+(B46-參數!$C$24)*SUMIF(站點彙總!$A$2:$A$22,"Microsoft Fairwater*",站點彙總!$E$2:$E$22)/1000 -> 2.6241374 | G46: =$B$4/F46 -> 0.82575099 | H46: =參數!$B$17/(參數!$B$12*參數!$B$13*F46) -> 0.84144967
...

Sheet 參數
A1: 項目 | B1: 值 | C1: 單位 | D1: 標記 | E1: 依據
A2: E0：2025 年底 OpenAI 上線 GW | B2: 1.9 | C2: GW | D2: Interested-party：OpenAI CFO（募資／IPO 誘因） | E2: Friar（DCD 2026-01-21）；Epoch 視為約 IT 電力（電力定義係數中位 0.99）
A3: Q2 視窗起 | B3: 46113 | C3: 日 | D3: — | E3: 2026 Q2
A4: Q2 視窗迄（不含） | B4: 46204 | C4: 日 | D4: —
A5: 全年視窗起 | B5: 46023 | C5: 日 | D5: —
A6: 全年視窗迄（不含） | B6: 46388 | C6: 日 | D6: —
A7: 年底時點 | B7: 46387 | C7: 日 | D7: —
A8: 2025 年底時點 | B8: 46022 | C8: 日 | D8: — | E8: E0 對應時點
A9: 2024 年底時點 | B9: 45657 | C9: 日 | D9: — | E9: 2025 基準檢查用
A10: 2025 視窗起 | B10: 45658 | C10: 日 | D10: —
A11: 2025 視窗迄（不含） | B11: 46023 | C11: 日 | D11: —
A12: 2025 回本比值（基準） | B12: 1.239 | C12: 倍 | D12: Derived | E12: 交接檔第 4 節 A2：130.7 億 ÷（1.128 GW × 93.5 億）
A13: h 2026：每 GW 持有成本 | B13: 9.796 | C13: $B／GW·年 | D13: Derived | E13: A 段（PR #160）OpenAI 模型世代組合
A14: 營收：Q2 年化 | B14: 26.3 | C14: $B | D14: Derived | E14: 交接檔 A2
A15: 營收：FY2026（不含廣告） | B15: 35 | C15: $B | D15: Derived | E15: 交接檔 A2
A16: 營收：9 月底 run-rate | B16: 50 | C16: $B | D16: 報導（FT，二手） | E16: A 段 R01
A17: 營收：Q2 年化（WSJ 67 億×4） | B17: 26.8 | C17: $B | D17: 報導（WSJ，二手） | E17: A 段 R01，對照
A18: 2024 年底 OpenAI 上線 GW | B18: 0.6 | C18: GW | D18: Interested-party | E18: Friar
A19: 2025 營收 | B19: 13.07 | C19: $B | D19: Verified／報導 | E19: 交接檔 A2 之 130.7 億
A20: h 2025 | B20: 9.353 | C20: $B／GW·年 | D20: Derived | E20: TK 2025 機隊持有成本
A21: 2025 平均 GW（TK 內插） | B21: 1.128 | C21: GW | D21: Derived | E21: AL_FleetGW25
A23: OpenAI 使用占比情境（Assumed；依 Epoch 使用者標記） | B23: confident | C23: likely | D23: speculative | E23: 說明
A24: 低 | B24: 1 | C24: 0.5 | D24: 0 | E24: likely 站多與 Microsoft 共用（Fairwater）；speculative 為 Epoch 推測
A25: 中 | B25: 1 | C25: 0.75 | D25: 0.25 | E25: likely 站多與 Microsoft 共用（Fairwater）；speculative 為 Epoch 推測
A26: 高 | B26: 1 | C26: 1 | D26: 1 | E26: likely 站多與 Microsoft 共用（Fairwater）；speculative 為 Epoch 推測

Sheet 站點時間表
A1: 站點 | B1: OpenAI 標記 | C1: 日期（Epoch，晚） | D1: 棟數 | E1: IT 電力 MW | F1: 設施電力 MW | G1: H100e | H1: 日期（早，藍字為改寫） | I1: 早日期依據 | J1: 下一日（晚） | K1: 下一日（早） | L1: Q2 MW·日（晚） | M1: Q2 MW·日（早） | N1: 全年 MW·日（晚） | O1: 全年 MW·日（早） | P1: 2025 年底水準 | Q1: 2026 年底水準（晚） | R1: 2026 年底水準（早） | S1: 2024 年底水準 | T1: 2025 MW·日 | U1: 2026 Q1 記錄之新增 MW（晚）
A2: Microsoft Fairwater Atlanta | B2: likely | C2: 45025 | D2: 0 | E2: 0 | F2: 0 | G2: 0 | H2: =C2 -> 45025 | J2: =IF(AND(2<122,A3=A2),C3,DATE(2100,1,1)) -> 45944 | K2: =IF(AND(2<122,A3=A2),H3,DATE(2100,1,1)) -> 45944 | L2: =E2*MAX(0,MIN(J2,參數!$B$4)-MAX(C2,參數!$B$3)) -> 0 | M2: =E2*MAX(0,MIN(K2,參數!$B$4)-MAX(H2,參數!$B$3)) -> 0 | N2: =E2*MAX(0,MIN(J2,參數!$B$6)-MAX(C2,參數!$B$5)) -> 0 | O2: =E2*MAX(0,MIN(K2,參數!$B$6)-MAX(H2,參數!$B$5)) -> 0 | P2: =E2*(C2<=參數!$B$8)*(J2>參數!$B$8) -> 0 | Q2: =E2*(C2<=參數!$B$7)*(J2>參數!$B$7) -> 0 | R2: =E2*(H2<=參數!$B$7)*(K2>參數!$B$7) -> 0 | S2: =E2*(C2<=參數!$B$9)*(J2>參數!$B$9) -> 0 | T2: =E2*MAX(0,MIN(J2,參數!$B$11)-MAX(C2,參數!$B$10)) -> 0 | U2: =0 -> 0
A3: Microsoft Fairwater Atlanta | B3: likely | C3: 45944 | D3: 2 | E3: 321 | F3: 433 | G3: 387981.94 | H3: =C3 -> 45944 | J3: =IF(AND(3<122,A4=A3),C4,DATE(2100,1,1)) -> 46066 | K3: =IF(AND(3<122,A4=A3),H4,DATE(2100,1,1)) -> 46066 | L3: =E3*MAX(0,MIN(J3,參數!$B$4)-MAX(C3,參數!$B$3)) -> 0 | M3: =E3*MAX(0,MIN(K3,參數!$B$4)-MAX(H3,參數!$B$3)) -> 0 | N3: =E3*MAX(0,MIN(J3,參數!$B$6)-MAX(C3,參數!$B$5)) -> 13803 | O3: =E3*MAX(0,MIN(K3,參數!$B$6)-MAX(H3,參數!$B$5)) -> 13803 | P3: =E3*(C3<=參數!$B$8)*(J3>參數!$B$8) -> 321 | Q3: =E3*(C3<=參數!$B$7)*(J3>參數!$B$7) -> 0 | R3: =E3*(H3<=參數!$B$7)*(K3>參數!$B$7) -> 0 | S3: =E3*(C3<=參數!$B$9)*(J3>參數!$B$9) -> 0 | T3: =E3*MAX(0,MIN(J3,參數!$B$11)-MAX(C3,參數!$B$10)) -> 25359 | U3: =IF(AND(3>2,A2=A3,C3>=參數!$B$5,C3<參數!$B$3),E3-E2,0) -> 0
A4: Microsoft Fairwater Atlanta | B4: likely | C4: 46066 | D4: 2 | E4: 321 | F4: 433 | G4: 387981.94 | H4: =C4 -> 46066 | J4: =IF(AND(4<122,A5=A4),C5,DATE(2100,1,1)) -> 46157 | K4: =IF(AND(4<122,A5=A4),H5,DATE(2100,1,1)) -> 46157 | L4: =E4*MAX(0,MIN(J4,參數!$B$4)-MAX(C4,參數!$B$3)) -> 14124 | M4: =E4*MAX(0,MIN(K4,參數!$B$4)-MAX(H4,參數!$B$3)) -> 14124 | N4: =E4*MAX(0,MIN(J4,參數!$B$6)-MAX(C4,參數!$B$5)) -> 29211 | O4: =E4*MAX(0,MIN(K4,參數!$B$6)-MAX(H4,參數!$B$5)) -> 29211 | P4: =E4*(C4<=參數!$B$8)*(J4>參數!$B$8) -> 0 | Q4: =E4*(C4<=參數!$B$7)*(J4>參數!$B$7) -> 0 | R4: =E4*(H4<=參數!$B$7)*(K4>參數!$B$7) -> 0 | S4: =E4*(C4<=參數!$B$9)*(J4>參數!$B$9) -> 0 | T4: =E4*MAX(0,MIN(J4,參數!$B$11)-MAX(C4,參數!$B$10)) -> 0 | U4: =IF(AND(4>2,A3=A4,C4>=參數!$B$5,C4<參數!$B$3),E4-E3,0) -> 0
A5: Microsoft Fairwater Atlanta | B5: likely | C5: 46157 | D5: 2 | E5: 321 | F5: 433 | G5: 387981.94 | H5: =C5 -> 46157 | J5: =IF(AND(5<122,A6=A5),C6,DATE(2100,1,1)) -> 46187 | K5: =IF(AND(5<122,A6=A5),H6,DATE(2100,1,1)) -> 46158 | L5: =E5*MAX(0,MIN(J5,參數!$B$4)-MAX(C5,參數!$B$3)) -> 9630 | M5: =E5*MAX(0,MIN(K5,參數!$B$4)-MAX(H5,參數!$B$3)) -> 321 | N5: =E5*MAX(0,MIN(J5,參數!$B$6)-MAX(C5,參數!$B$5)) -> 9630 | O5: =E5*MAX(0,MIN(K5,參數!$B$6)-MAX(H5,參數!$B$5)) -> 321 | P5: =E5*(C5<=參數!$B$8)*(J5>參數!$B$8) -> 0 | Q5: =E5*(C5<=參數!$B$7)*(J5>參數!$B$7) -> 0 | R5: =E5*(H5<=參數!$B$7)*(K5>參數!$B$7) -> 0 | S5: =E5*(C5<=參數!$B$9)*(J5>參數!$B$9) -> 0 | T5: =E5*MAX(0,MIN(J5,參數!$B$11)-MAX(C5,參數!$B$10)) -> 0 | U5: =IF(AND(5>2,A4=A5,C5>=參數!$B$5,C5<參數!$B$3),E5-E4,0) -> 0
A6: Microsoft Fairwater Atlanta | B6: likely | C6: 46187 | D6: 4 | E6: 636 | F6: 859 | G6: 768768.72 | H6: 46158 | I6: 2026-05-15 快照仍在試運轉；最早為次日 | J6: =IF(AND(6<122,A7=A6),C7,DATE(2100,1,1)) -> 73051 | K6: =IF(AND(6<122,A7=A6),H7,DATE(2100,1,1)) -> 73051 | L6: =E6*MAX(0,MIN(J6,參數!$B$4)-MAX(C6,參數!$B$3)) -> 10812 | M6: =E6*MAX(0,MIN(K6,參數!$B$4)-MAX(H6,參數!$B$3)) -> 29256 | N6: =E6*MAX(0,MIN(J6,參數!$B$6)-MAX(C6,參數!$B$5)) -> 127836 | O6: =E6*MAX(0,MIN(K6,參數!$B$6)-MAX(H6,參數!$B$5)) -> 146280 | P6: =E6*(C6<=參數!$B$8)*(J6>參數!$B$8) -> 0 | Q6: =E6*(C6<=參數!$B$7)*(J6>參數!$B$7) -> 636 | R6: =E6*(H6<=參數!$B$7)*(K6>參數!$B$7) -> 636 | S6: =E6*(C6<=參數!$B$9)*(J6>參數!$B$9) -> 0 | T6: =E6*MAX(0,MIN(J6,參數!$B$11)-MAX(C6,參數!$B$10)) -> 0 | U6: =IF(AND(6>2,A5=A6,C6>=參數!$B$5,C6<參數!$B$3),E6-E5,0) -> 0
A7: OpenAI Stargate Abilene | B7: confident | C7: 45443 | D7: 0 | E7: 0 | F7: 0 | G7: 0 | H7: =C7 -> 45443 | J7: =IF(AND(7<122,A8=A7),C8,DATE(2100,1,1)) -> 45836 | K7: =IF(AND(7<122,A8=A7),H8,DATE(2100,1,1)) -> 45836 | L7: =E7*MAX(0,MIN(J7,參數!$B$4)-MAX(C7,參數!$B$3)) -> 0 | M7: =E7*MAX(0,MIN(K7,參數!$B$4)-MAX(H7,參數!$B$3)) -> 0 | N7: =E7*MAX(0,MIN(J7,參數!$B$6)-MAX(C7,參數!$B$5)) -> 0 | O7: =E7*MAX(0,MIN(K7,參數!$B$6)-MAX(H7,參數!$B$5)) -> 0 | P7: =E7*(C7<=參數!$B$8)*(J7>參數!$B$8) -> 0 | Q7: =E7*(C7<=參數!$B$7)*(J7>參數!$B$7) -> 0 | R7: =E7*(H7<=參數!$B$7)*(K7>參數!$B$7) -> 0 | S7: =E7*(C7<=參數!$B$9)*(J7>參數!$B$9) -> 0 | T7: =E7*MAX(0,MIN(J7,參數!$B$11)-MAX(C7,參數!$B$10)) -> 0 | U7: =IF(AND(7>2,A6=A7,C7>=參數!$B$5,C7<參數!$B$3),E7-E6,0) -> 0
A8: OpenAI Stargate Abilene | B8: confident | C8: 45836 | D8: 0 | E8: 0 | F8: 0 | G8: 0 | H8: =C8 -> 45836 | J8: =IF(AND(8<122,A9=A8),C9,DATE(2100,1,1)) -> 45926 | K8: =IF(AND(8<122,A9=A8),H9,DATE(2100,1,1)) -> 45926 | L8: =E8*MAX(0,MIN(J8,參數!$B$4)-MAX(C8,參數!$B$3)) -> 0 | M8: =E8*MAX(0,MIN(K8,參數!$B$4)-MAX(H8,參數!$B$3)) -> 0 | N8: =E8*MAX(0,MIN(J8,參數!$B$6)-MAX(C8,參數!$B$5)) -> 0 | O8: =E8*MAX(0,MIN(K8,參數!$B$6)-MAX(H8,參數!$B$5)) -> 0 | P8: =E8*(C8<=參數!$B$8)*(J8>參數!$B$8) -> 0 | Q8: =E8*(C8<=參數!$B$7)*(J8>參數!$B$7) -> 0 | R8: =E8*(H8<=參數!$B$7)*(K8>參數!$B$7) -> 0 | S8: =E8*(C8<=參數!$B$9)*(J8>參數!$B$9) -> 0 | T8: =E8*MAX(0,MIN(J8,參數!$B$11)-MAX(C8,參數!$B$10)) -> 0 | U8: =IF(AND(8>2,A7=A8,C8>=參數!$B$5,C8<參數!$B$3),E8-E7,0) -> 0
A9: OpenAI Stargate Abilene | B9: confident | C9: 45926 | D9: 1 | E9: 105 | F9: 147 | G9: 127337.04 | H9: =C9 -> 45926 | J9: =IF(AND(9<122,A10=A9),C10,DATE(2100,1,1)) -> 46015 | K9: =IF(AND(9<122,A10=A9),H10,DATE(2100,1,1)) -> 46015 | L9: =E9*MAX(0,MIN(J9,參數!$B$4)-MAX(C9,參數!$B$3)) -> 0 | M9: =E9*MAX(0,MIN(K9,參數!$B$4)-MAX(H9,參數!$B$3)) -> 0 | N9: =E9*MAX(0,MIN(J9,參數!$B$6)-MAX(C9,參數!$B$5)) -> 0 | O9: =E9*MAX(0,MIN(K9,參數!$B$6)-MAX(H9,參數!$B$5)) -> 0 | P9: =E9*(C9<=參數!$B$8)*(J9>參數!$B$8) -> 0 | Q9: =E9*(C9<=參數!$B$7)*(J9>參數!$B$7) -> 0 | R9: =E9*(H9<=參數!$B$7)*(K9>參數!$B$7) -> 0 | S9: =E9*(C9<=參數!$B$9)*(J9>參數!$B$9) -> 0 | T9: =E9*MAX(0,MIN(J9,參數!$B$11)-MAX(C9,參數!$B$10)) -> 9345 | U9: =IF(AND(9>2,A8=A9,C9>=參數!$B$5,C9<參數!$B$3),E9-E8,0) -> 0
A10: OpenAI Stargate Abilene | B10: confident | C10: 46015 | D10: 2 | E10: 211 | F10: 295 | G10: 254674.08 | H10: =C10 -> 46015 | J10: =IF(AND(10<122,A11=A10),C11,DATE(2100,1,1)) -> 46037 | K10: =IF(AND(10<122,A11=A10),H11,DATE(2100,1,1)) -> 46037 | L10: =E10*MAX(0,MIN(J10,參數!$B$4)-MAX(C10,參數!$B$3)) -> 0 | M10: =E10*MAX(0,MIN(K10,參數!$B$4)-MAX(H10,參數!$B$3)) -> 0 | N10: =E10*MAX(0,MIN(J10,參數!$B$6)-MAX(C10,參數!$B$5)) -> 2954 | O10: =E10*MAX(0,MIN(K10,參數!$B$6)-MAX(H10,參數!$B$5)) -> 2954 | P10: =E10*(C10<=參數!$B$8)*(J10>參數!$B$8) -> 211 | Q10: =E10*(C10<=參數!$B$7)*(J10>參數!$B$7) -> 0 | R10: =E10*(H10<=參數!$B$7)*(K10>參數!$B$7) -> 0 | S10: =E10*(C10<=參數!$B$9)*(J10>參數!$B$9) -> 0 | T10: =E10*MAX(0,MIN(J10,參數!$B$11)-MAX(C10,參數!$B$10)) -> 1688 | U10: =IF(AND(10>2,A9=A10,C10>=參數!$B$5,C10<參數!$B$3),E10-E9,0) -> 0
A11: OpenAI Stargate Abilene | B11: confident | C11: 46037 | D11: 2 | E11: 211 | F11: 295 | G11: 254674.08 | H11: =C11 -> 46037 | J11: =IF(AND(11<122,A12=A11),C12,DATE(2100,1,1)) -> 46105 | K11: =IF(AND(11<122,A12=A11),H12,DATE(2100,1,1)) -> 46105 | L11: =E11*MAX(0,MIN(J11,參數!$B$4)-MAX(C11,參數!$B$3)) -> 0 | M11: =E11*MAX(0,MIN(K11,參數!$B$4)-MAX(H11,參數!$B$3)) -> 0 | N11: =E11*MAX(0,MIN(J11,參數!$B$6)-MAX(C11,參數!$B$5)) -> 14348 | O11: =E11*MAX(0,MIN(K11,參數!$B$6)-MAX(H11,參數!$B$5)) -> 14348 | P11: =E11*(C11<=參數!$B$8)*(J11>參數!$B$8) -> 0 | Q11: =E11*(C11<=參數!$B$7)*(J11>參數!$B$7) -> 0 | R11: =E11*(H11<=參數!$B$7)*(K11>參數!$B$7) -> 0 | S11: =E11*(C11<=參數!$B$9)*(J11>參數!$B$9) -> 0 | T11: =E11*MAX(0,MIN(J11,參數!$B$11)-MAX(C11,參數!$B$10)) -> 0 | U11: =IF(AND(11>2,A10=A11,C11>=參數!$B$5,C11<參數!$B$3),E11-E10,0) -> 0
A12: OpenAI Stargate Abilene | B12: confident | C12: 46105 | D12: 2 | E12: 211 | F12: 295 | G12: 254674.08 | H12: =C12 -> 46105 | J12: =IF(AND(12<122,A13=A12),C13,DATE(2100,1,1)) -> 46165 | K12: =IF(AND(12<122,A13=A12),H13,DATE(2100,1,1)) -> 46135 | L12: =E12*MAX(0,MIN(J12,參數!$B$4)-MAX(C12,參數!$B$3)) -> 10972 | M12: =E12*MAX(0,MIN(K12,參數!$B$4)-MAX(H12,參數!$B$3)) -> 4642 | N12: =E12*MAX(0,MIN(J12,參數!$B$6)-MAX(C12,參數!$B$5)) -> 12660 | O12: =E12*MAX(0,MIN(K12,參數!$B$6)-MAX(H12,參數!$B$5)) -> 6330 | P12: =E12*(C12<=參數!$B$8)*(J12>參數!$B$8) -> 0 | Q12: =E12*(C12<=參數!$B$7)*(J12>參數!$B$7) -> 0 | R12: =E12*(H12<=參數!$B$7)*(K12>參數!$B$7) -> 0 | S12: =E12*(C12<=參數!$B$9)*(J12>參數!$B$9) -> 0 | T12: =E12*MAX(0,MIN(J12,參數!$B$11)-MAX(C12,參數!$B$10)) -> 0 | U12: =IF(AND(12>2,A11=A12,C12>=參數!$B$5,C12<參數!$B$3),E12-E11,0) -> 0
A13: OpenAI Stargate Abilene | B13: confident | C13: 46165 | D13: 4 | E13: 421 | F13: 590 | G13: 509348.16 | H13: 46135 | I13: Oracle 2026-04-22 貼文「200MW is already operational」＝1–2 棟；最早為次日 | J13: =IF(AND(13<122,A14=A13),C14,DATE(2100,1,1)) -> 46231 | K13: =IF(AND(13<122,A14=A13),H14,DATE(2100,1,1)) -> 46231 | L13: =E13*MAX(0,MIN(J13,參數!$B$4)-MAX(C13,參數!$B$3)) -> 16419 | M13: =E13*MAX(0,MIN(K13,參數!$B$4)-MAX(H13,參數!$B$3)) -> 29049 | N13: =E13*MAX(0,MIN(J13,參數!$B$6)-MAX(C13,參數!$B$5)) -> 27786 | O13: =E13*MAX(0,MIN(K13,參數!$B$6)-MAX(H13,參數!$B$5)) -> 40416 | P13: =E13*(C13<=參數!$B$8)*(J13>參數!$B$8) -> 0 | Q13: =E13*(C13<=參數!$B$7)*(J13>參數!$B$7) -> 0 | R13: =E13*(H13<=參數!$B$7)*(K13>參數!$B$7) -> 0 | S13: =E13*(C13<=參數!$B$9)*(J13>參數!$B$9) -> 0 | T13: =E13*MAX(0,MIN(J13,參數!$B$11)-MAX(C13,參數!$B$10)) -> 0 | U13: =IF(AND(13>2,A12=A13,C13>=參數!$B$5,C13<參數!$B$3),E13-E12,0) -> 0
A14: OpenAI Stargate Abilene | B14: confident | C14: 46231 | D14: 4 | E14: 421 | F14: 590 | G14: 509348.16 | H14: =C14 -> 46231 | J14: =IF(AND(14<122,A15=A14),C15,DATE(2100,1,1)) -> 46327 | K14: =IF(AND(14<122,A15=A14),H15,DATE(2100,1,1)) -> 46327 | L14: =E14*MAX(0,MIN(J14,參數!$B$4)-MAX(C14,參數!$B$3)) -> 0 | M14: =E14*MAX(0,MIN(K14,參數!$B$4)-MAX(H14,參數!$B$3)) -> 0 | N14: =E14*MAX(0,MIN(J14,參數!$B$6)-MAX(C14,參數!$B$5)) -> 40416 | O14: =E14*MAX(0,MIN(K14,參數!$B$6)-MAX(H14,參數!$B$5)) -> 40416 | P14: =E14*(C14<=參數!$B$8)*(J14>參數!$B$8) -> 0 | Q14: =E14*(C14<=參數!$B$7)*(J14>參數!$B$7) -> 0 | R14: =E14*(H14<=參數!$B$7)*(K14>參數!$B$7) -> 0 | S14: =E14*(C14<=參數!$B$9)*(J14>參數!$B$9) -> 0 | T14: =E14*MAX(0,MIN(J14,參數!$B$11)-MAX(C14,參數!$B$10)) -> 0 | U14: =IF(AND(14>2,A13=A14,C14>=參數!$B$5,C14<參數!$B$3),E14-E13,0) -> 0
A15: OpenAI Stargate Abilene | B15: confident | C15: 46327 | D15: 8 | E15: 843 | F15: 1180 | G15: 1018696.3 | H15: =C15 -> 46327 | J15: =IF(AND(15<122,A16=A15),C16,DATE(2100,1,1)) -> 73051 | K15: =IF(AND(15<122,A16=A15),H16,DATE(2100,1,1)) -> 73051 | L15: =E15*MAX(0,MIN(J15,參數!$B$4)-MAX(C15,參數!$B$3)) -> 0 | M15: =E15*MAX(0,MIN(K15,參數!$B$4)-MAX(H15,參數!$B$3)) -> 0 | N15: =E15*MAX(0,MIN(J15,參數!$B$6)-MAX(C15,參數!$B$5)) -> 51423 | O15: =E15*MAX(0,MIN(K15,參數!$B$6)-MAX(H15,參數!$B$5)) -> 51423 | P15: =E15*(C15<=參數!$B$8)*(J15>參數!$B$8) -> 0 | Q15: =E15*(C15<=參數!$B$7)*(J15>參數!$B$7) -> 843 | R15: =E15*(H15<=參數!$B$7)*(K15>參數!$B$7) -> 843 | S15: =E15*(C15<=參數!$B$9)*(J15>參數!$B$9) -> 0 | T15: =E15*MAX(0,MIN(J15,參數!$B$11)-MAX(C15,參數!$B$10)) -> 0 | U15: =IF(AND(15>2,A14=A15,C15>=參數!$B$5,C15<參數!$B$3),E15-E14,0) -> 0
A16: Microsoft Fairwater Wisconsin | B16: likely | C16: 45121 | D16: 0 | E16: 0 | F16: 0 | G16: 0 | H16: =C16 -> 45121 | J16: =IF(AND(16<122,A17=A16),C17,DATE(2100,1,1)) -> 45926 | K16: =IF(AND(16<122,A17=A16),H17,DATE(2100,1,1)) -> 45926 | L16: =E16*MAX(0,MIN(J16,參數!$B$4)-MAX(C16,參數!$B$3)) -> 0 | M16: =E16*MAX(0,MIN(K16,參數!$B$4)-MAX(H16,參數!$B$3)) -> 0 | N16: =E16*MAX(0,MIN(J16,參數!$B$6)-MAX(C16,參數!$B$5)) -> 0 | O16: =E16*MAX(0,MIN(K16,參數!$B$6)-MAX(H16,參數!$B$5)) -> 0 | P16: =E16*(C16<=參數!$B$8)*(J16>參數!$B$8) -> 0 | Q16: =E16*(C16<=參數!$B$7)*(J16>參數!$B$7) -> 0 | R16: =E16*(H16<=參數!$B$7)*(K16>參數!$B$7) -> 0 | S16: =E16*(C16<=參數!$B$9)*(J16>參數!$B$9) -> 0 | T16: =E16*MAX(0,MIN(J16,參數!$B$11)-MAX(C16,參數!$B$10)) -> 0 | U16: =IF(AND(16>2,A15=A16,C16>=參數!$B$5,C16<參數!$B$3),E16-E15,0) -> 0
A17: Microsoft Fairwater Wisconsin | B17: likely | C17: 45926 | D17: 0 | E17: 0 | F17: 0 | G17: 0 | H17: =C17 -> 45926 | J17: =IF(AND(17<122,A18=A17),C18,DATE(2100,1,1)) -> 46050 | K17: =IF(AND(17<122,A18=A17),H18,DATE(2100,1,1)) -> 46050 | L17: =E17*MAX(0,MIN(J17,參數!$B$4)-MAX(C17,參數!$B$3)) -> 0 | M17: =E17*MAX(0,MIN(K17,參數!$B$4)-MAX(H17,參數!$B$3)) -> 0 | N17: =E17*MAX(0,MIN(J17,參數!$B$6)-MAX(C17,參數!$B$5)) -> 0 | O17: =E17*MAX(0,MIN(K17,參數!$B$6)-MAX(H17,參數!$B$5)) -> 0 | P17: =E17*(C17<=參數!$B$8)*(J17>參數!$B$8) -> 0 | Q17: =E17*(C17<=參數!$B$7)*(J17>參數!$B$7) -> 0 | R17: =E17*(H17<=參數!$B$7)*(K17>參數!$B$7) -> 0 | S17: =E17*(C17<=參數!$B$9)*(J17>參數!$B$9) -> 0 | T17: =E17*MAX(0,MIN(J17,參數!$B$11)-MAX(C17,參數!$B$10)) -> 0 | U17: =IF(AND(17>2,A16=A17,C17>=參數!$B$5,C17<參數!$B$3),E17-E16,0) -> 0
A18: Microsoft Fairwater Wisconsin | B18: likely | C18: 46050 | D18: 0 | E18: 0 | F18: 0 | G18: 0 | H18: =C18 -> 46050 | J18: =IF(AND(18<122,A19=A18),C19,DATE(2100,1,1)) -> 46128 | K18: =IF(AND(18<122,A19=A18),H19,DATE(2100,1,1)) -> 46128 | L18: =E18*MAX(0,MIN(J18,參數!$B$4)-MAX(C18,參數!$B$3)) -> 0 | M18: =E18*MAX(0,MIN(K18,參數!$B$4)-MAX(H18,參數!$B$3)) -> 0 | N18: =E18*MAX(0,MIN(J18,參數!$B$6)-MAX(C18,參數!$B$5)) -> 0 | O18: =E18*MAX(0,MIN(K18,參數!$B$6)-MAX(H18,參數!$B$5)) -> 0 | P18: =E18*(C18<=參數!$B$8)*(J18>參數!$B$8) -> 0 | Q18: =E18*(C18<=參數!$B$7)*(J18>參數!$B$7) -> 0 | R18: =E18*(H18<=參數!$B$7)*(K18>參數!$B$7) -> 0 | S18: =E18*(C18<=參數!$B$9)*(J18>參數!$B$9) -> 0 | T18: =E18*MAX(0,MIN(J18,參數!$B$11)-MAX(C18,參數!$B$10)) -> 0 | U18: =IF(AND(18>2,A17=A18,C18>=參數!$B$5,C18<參數!$B$3),E18-E17,0) -> 0
A19: Microsoft Fairwater Wisconsin | B19: likely | C19: 46128 | D19: 1 | E19: 369 | F19: 442 | G19: 445679.64 | H19: =C19 -> 46128 | J19: =IF(AND(19<122,A20=A19),C20,DATE(2100,1,1)) -> 46157 | K19: =IF(AND(19<122,A20=A19),H20,DATE(2100,1,1)) -> 46157 | L19: =E19*MAX(0,MIN(J19,參數!$B$4)-MAX(C19,參數!$B$3)) -> 10701 | M19: =E19*MAX(0,MIN(K19,參數!$B$4)-MAX(H19,參數!$B$3)) -> 10701 | N19: =E19*MAX(0,MIN(J19,參數!$B$6)-MAX(C19,參數!$B$5)) -> 10701 | O19: =E19*MAX(0,MIN(K19,參數!$B$6)-MAX(H19,參數!$B$5)) -> 10701 | P19: =E19*(C19<=參數!$B$8)*(J19>參數!$B$8) -> 0 | Q19: =E19*(C19<=參數!$B$7)*(J19>參數!$B$7) -> 0 | R19: =E19*(H19<=參數!$B$7)*(K19>參數!$B$7) -> 0 | S19: =E19*(C19<=參數!$B$9)*(J19>參數!$B$9) -> 0 | T19: =E19*MAX(0,MIN(J19,參數!$B$11)-MAX(C19,參數!$B$10)) -> 0 | U19: =IF(AND(19>2,A18=A19,C19>=參數!$B$5,C19<參數!$B$3),E19-E18,0) -> 0
A20: Microsoft Fairwater Wisconsin | B20: likely | C20: 46157 | D20: 1 | E20: 369 | F20: 442 | G20: 445679.64 | H20: =C20 -> 46157 | J20: =IF(AND(20<122,A21=A20),C21,DATE(2100,1,1)) -> 46438 | K20: =IF(AND(20<122,A21=A20),H21,DATE(2100,1,1)) -> 46438 | L20: =E20*MAX(0,MIN(J20,參數!$B$4)-MAX(C20,參數!$B$3)) -> 17343 | M20: =E20*MAX(0,MIN(K20,參數!$B$4)-MAX(H20,參數!$B$3)) -> 17343 | N20: =E20*MAX(0,MIN(J20,參數!$B$6)-MAX(C20,參數!$B$5)) -> 85239 | O20: =E20*MAX(0,MIN(K20,參數!$B$6)-MAX(H20,參數!$B$5)) -> 85239 | P20: =E20*(C20<=參數!$B$8)*(J20>參數!$B$8) -> 0 | Q20: =E20*(C20<=參數!$B$7)*(J20>參數!$B$7) -> 369 | R20: =E20*(H20<=參數!$B$7)*(K20>參數!$B$7) -> 369 | S20: =E20*(C20<=參數!$B$9)*(J20>參數!$B$9) -> 0 | T20: =E20*MAX(0,MIN(J20,參數!$B$11)-MAX(C20,參數!$B$10)) -> 0 | U20: =IF(AND(20>2,A19=A20,C20>=參數!$B$5,C20<參數!$B$3),E20-E19,0) -> 0
A21: Microsoft Fairwater Wisconsin | B21: likely | C21: 46438 | D21: 2 | E21: 737 | F21: 885 | G21: 889338.05 | H21: =C21 -> 46438 | J21: =IF(AND(21<122,A22=A21),C22,DATE(2100,1,1)) -> 46886 | K21: =IF(AND(21<122,A22=A21),H22,DATE(2100,1,1)) -> 46886 | L21: =E21*MAX(0,MIN(J21,參數!$B$4)-MAX(C21,參數!$B$3)) -> 0 | M21: =E21*MAX(0,MIN(K21,參數!$B$4)-MAX(H21,參數!$B$3)) -> 0 | N21: =E21*MAX(0,MIN(J21,參數!$B$6)-MAX(C21,參數!$B$5)) -> 0 | O21: =E21*MAX(0,MIN(K21,參數!$B$6)-MAX(H21,參數!$B$5)) -> 0 | P21: =E21*(C21<=參數!$B$8)*(J21>參數!$B$8) -> 0 | Q21: =E21*(C21<=參數!$B$7)*(J21>參數!$B$7) -> 0 | R21: =E21*(H21<=參數!$B$7)*(K21>參數!$B$7) -> 0 | S21: =E21*(C21<=參數!$B$9)*(J21>參數!$B$9) -> 0 | T21: =E21*MAX(0,MIN(J21,參數!$B$11)-MAX(C21,參數!$B$10)) -> 0 | U21: =IF(AND(21>2,A20=A21,C21>=參數!$B$5,C21<參數!$B$3),E21-E20,0) -> 0
A22: Microsoft Fairwater Wisconsin | B22: likely | C22: 46886 | D22: 11 | E22: 2263 | F22: 2715 | G22: 4527539.2 | H22: =C22 -> 46886 | J22: =IF(AND(22<122,A23=A22),C23,DATE(2100,1,1)) -> 73051 | K22: =IF(AND(22<122,A23=A22),H23,DATE(2100,1,1)) -> 73051 | L22: =E22*MAX(0,MIN(J22,參數!$B$4)-MAX(C22,參數!$B$3)) -> 0 | M22: =E22*MAX(0,MIN(K22,參數!$B$4)-MAX(H22,參數!$B$3)) -> 0 | N22: =E22*MAX(0,MIN(J22,參數!$B$6)-MAX(C22,參數!$B$5)) -> 0 | O22: =E22*MAX(0,MIN(K22,參數!$B$6)-MAX(H22,參數!$B$5)) -> 0 | P22: =E22*(C22<=參數!$B$8)*(J22>參數!$B$8) -> 0 | Q22: =E22*(C22<=參數!$B$7)*(J22>參數!$B$7) -> 0 | R22: =E22*(H22<=參數!$B$7)*(K22>參數!$B$7) -> 0 | S22: =E22*(C22<=參數!$B$9)*(J22>參數!$B$9) -> 0 | T22: =E22*MAX(0,MIN(J22,參數!$B$11)-MAX(C22,參數!$B$10)) -> 0 | U22: =IF(AND(22>2,A21=A22,C22>=參數!$B$5,C22<參數!$B$3),E22-E21,0) -> 0
A23: CoreWeave Denton TX | B23: likely | C23: 45597 | D23: 0 | E23: 0 | F23: 0 | G23: 0 | H23: =C23 -> 45597 | J23: =IF(AND(23<122,A24=A23),C24,DATE(2100,1,1)) -> 45808 | K23: =IF(AND(23<122,A24=A23),H24,DATE(2100,1,1)) -> 45808 | L23: =E23*MAX(0,MIN(J23,參數!$B$4)-MAX(C23,參數!$B$3)) -> 0 | M23: =E23*MAX(0,MIN(K23,參數!$B$4)-MAX(H23,參數!$B$3)) -> 0 | N23: =E23*MAX(0,MIN(J23,參數!$B$6)-MAX(C23,參數!$B$5)) -> 0 | O23: =E23*MAX(0,MIN(K23,參數!$B$6)-MAX(H23,參數!$B$5)) -> 0 | P23: =E23*(C23<=參數!$B$8)*(J23>參數!$B$8) -> 0 | Q23: =E23*(C23<=參數!$B$7)*(J23>參數!$B$7) -> 0 | R23: =E23*(H23<=參數!$B$7)*(K23>參數!$B$7) -> 0 | S23: =E23*(C23<=參數!$B$9)*(J23>參數!$B$9) -> 0 | T23: =E23*MAX(0,MIN(J23,參數!$B$11)-MAX(C23,參數!$B$10)) -> 0 | U23: =IF(AND(23>2,A22=A23,C23>=參數!$B$5,C23<參數!$B$3),E23-E22,0) -> 0
A24: CoreWeave Denton TX | B24: likely | C24: 45808 | D24: 1 | E24: 8 | F24: 11 | G24: 7781.7079 | H24: =C24 -> 45808 | J24: =IF(AND(24<122,A25=A24),C25,DATE(2100,1,1)) -> 46022 | K24: =IF(AND(24<122,A25=A24),H25,DATE(2100,1,1)) -> 46022 | L24: =E24*MAX(0,MIN(J24,參數!$B$4)-MAX(C24,參數!$B$3)) -> 0 | M24: =E24*MAX(0,MIN(K24,參數!$B$4)-MAX(H24,參數!$B$3)) -> 0 | N24: =E24*MAX(0,MIN(J24,參數!$B$6)-MAX(C24,參數!$B$5)) -> 0 | O24: =E24*MAX(0,MIN(K24,參數!$B$6)-MAX(H24,參數!$B$5)) -> 0 | P24: =E24*(C24<=參數!$B$8)*(J24>參數!$B$8) -> 0 | Q24: =E24*(C24<=參數!$B$7)*(J24>參數!$B$7) -> 0 | R24: =E24*(H24<=參數!$B$7)*(K24>參數!$B$7) -> 0 | S24: =E24*(C24<=參數!$B$9)*(J24>參數!$B$9) -> 0 | T24: =E24*MAX(0,MIN(J24,參數!$B$11)-MAX(C24,參數!$B$10)) -> 1712 | U24: =IF(AND(24>2,A23=A24,C24>=參數!$B$5,C24<參數!$B$3),E24-E23,0) -> 0
A25: CoreWeave Denton TX | B25: likely | C25: 46022 | D25: 3 | E25: 67 | F25: 94 | G25: 64679.131 | H25: =C25 -> 46022 | J25: =IF(AND(25<122,A26=A25),C26,DATE(2100,1,1)) -> 46076 | K25: =IF(AND(25<122,A26=A25),H26,DATE(2100,1,1)) -> 46023 | L25: =E25*MAX(0,MIN(J25,參數!$B$4)-MAX(C25,參數!$B$3)) -> 0 | M25: =E25*MAX(0,MIN(K25,參數!$B$4)-MAX(H25,參數!$B$3)) -> 0 | N25: =E25*MAX(0,MIN(J25,參數!$B$6)-MAX(C25,參數!$B$5)) -> 3551 | O25: =E25*MAX(0,MIN(K25,參數!$B$6)-MAX(H25,參數!$B$5)) -> 0 | P25: =E25*(C25<=參數!$B$8)*(J25>參數!$B$8) -> 67 | Q25: =E25*(C25<=參數!$B$7)*(J25>參數!$B$7) -> 0 | R25: =E25*(H25<=參數!$B$7)*(K25>參數!$B$7) -> 0 | S25: =E25*(C25<=參數!$B$9)*(J25>參數!$B$9) -> 0 | T25: =E25*MAX(0,MIN(J25,參數!$B$11)-MAX(C25,參數!$B$10)) -> 67 | U25: =IF(AND(25>2,A24=A25,C25>=參數!$B$5,C25<參數!$B$3),E25-E24,0) -> 0
A26: CoreWeave Denton TX | B26: likely | C26: 46076 | D26: 4 | E26: 131 | F26: 183 | G26: 126326.43 | H26: 46023 | I26: 上一快照 2025-12-31 | J26: =IF(AND(26<122,A27=A26),C27,DATE(2100,1,1)) -> 46083 | K26: =IF(AND(26<122,A27=A26),H27,DATE(2100,1,1)) -> 46083 | L26: =E26*MAX(0,MIN(J26,參數!$B$4)-MAX(C26,參數!$B$3)) -> 0 | M26: =E26*MAX(0,MIN(K26,參數!$B$4)-MAX(H26,參數!$B$3)) -> 0 | N26: =E26*MAX(0,MIN(J26,參數!$B$6)-MAX(C26,參數!$B$5)) -> 917 | O26: =E26*MAX(0,MIN(K26,參數!$B$6)-MAX(H26,參數!$B$5)) -> 7860 | P26: =E26*(C26<=參數!$B$8)*(J26>參數!$B$8) -> 0 | Q26: =E26*(C26<=參數!$B$7)*(J26>參數!$B$7) -> 0 | R26: =E26*(H26<=參數!$B$7)*(K26>參數!$B$7) -> 0 | S26: =E26*(C26<=參數!$B$9)*(J26>參數!$B$9) -> 0 | T26: =E26*MAX(0,MIN(J26,參數!$B$11)-MAX(C26,參數!$B$10)) -> 0 | U26: =IF(AND(26>2,A25=A26,C26>=參數!$B$5,C26<參數!$B$3),E26-E25,0) -> 64
A27: CoreWeave Denton TX | B27: likely | C27: 46083 | D27: 4 | E27: 131 | F27: 183 | G27: 126326.43 | H27: =C27 -> 46083 | J27: =IF(AND(27<122,A28=A27),C28,DATE(2100,1,1)) -> 46206 | K27: =IF(AND(27<122,A28=A27),H28,DATE(2100,1,1)) -> 46084 | L27: =E27*MAX(0,MIN(J27,參數!$B$4)-MAX(C27,參數!$B$3)) -> 11921 | M27: =E27*MAX(0,MIN(K27,參數!$B$4)-MAX(H27,參數!$B$3)) -> 0 | N27: =E27*MAX(0,MIN(J27,參數!$B$6)-MAX(C27,參數!$B$5)) -> 16113 | O27: =E27*MAX(0,MIN(K27,參數!$B$6)-MAX(H27,參數!$B$5)) -> 131 | P27: =E27*(C27<=參數!$B$8)*(J27>參數!$B$8) -> 0 | Q27: =E27*(C27<=參數!$B$7)*(J27>參數!$B$7) -> 0 | R27: =E27*(H27<=參數!$B$7)*(K27>參數!$B$7) -> 0 | S27: =E27*(C27<=參數!$B$9)*(J27>參數!$B$9) -> 0 | T27: =E27*MAX(0,MIN(J27,參數!$B$11)-MAX(C27,參數!$B$10)) -> 0 | U27: =IF(AND(27>2,A26=A27,C27>=參數!$B$5,C27<參數!$B$3),E27-E26,0) -> 0
A28: CoreWeave Denton TX | B28: likely | C28: 46206 | D28: 7 | E28: 262 | F28: 367 | G28: 252652.85 | H28: 46084 | I28: 2026-03-02 法說「Denton South partially running」；Q2 deck「operational by midyear」 | J28: =IF(AND(28<122,A29=A28),C29,DATE(2100,1,1)) -> 46266 | K28: =IF(AND(28<122,A29=A28),H29,DATE(2100,1,1)) -> 46266 | L28: =E28*MAX(0,MIN(J28,參數!$B$4)-MAX(C28,參數!$B$3)) -> 0 | M28: =E28*MAX(0,MIN(K28,參數!$B$4)-MAX(H28,參數!$B$3)) -> 23842 | N28: =E28*MAX(0,MIN(J28,參數!$B$6)-MAX(C28,參數!$B$5)) -> 15720 | O28: =E28*MAX(0,MIN(K28,參數!$B$6)-MAX(H28,參數!$B$5)) -> 47684 | P28: =E28*(C28<=參數!$B$8)*(J28>參數!$B$8) -> 0 | Q28: =E28*(C28<=參數!$B$7)*(J28>參數!$B$7) -> 0 | R28: =E28*(H28<=參數!$B$7)*(K28>參數!$B$7) -> 0 | S28: =E28*(C28<=參數!$B$9)*(J28>參數!$B$9) -> 0 | T28: =E28*MAX(0,MIN(J28,參數!$B$11)-MAX(C28,參數!$B$10)) -> 0 | U28: =IF(AND(28>2,A27=A28,C28>=參數!$B$5,C28<參數!$B$3),E28-E27,0) -> 0
A29: CoreWeave Denton TX | B29: likely | C29: 46266 | D29: 7 | E29: 262 | F29: 367 | G29: 252652.85 | H29: =C29 -> 46266 | J29: =IF(AND(29<122,A30=A29),C30,DATE(2100,1,1)) -> 46538 | K29: =IF(AND(29<122,A30=A29),H30,DATE(2100,1,1)) -> 46538 | L29: =E29*MAX(0,MIN(J29,參數!$B$4)-MAX(C29,參數!$B$3)) -> 0 | M29: =E29*MAX(0,MIN(K29,參數!$B$4)-MAX(H29,參數!$B$3)) -> 0 | N29: =E29*MAX(0,MIN(J29,參數!$B$6)-MAX(C29,參數!$B$5)) -> 31964 | O29: =E29*MAX(0,MIN(K29,參數!$B$6)-MAX(H29,參數!$B$5)) -> 31964 | P29: =E29*(C29<=參數!$B$8)*(J29>參數!$B$8) -> 0 | Q29: =E29*(C29<=參數!$B$7)*(J29>參數!$B$7) -> 262 | R29: =E29*(H29<=參數!$B$7)*(K29>參數!$B$7) -> 262 | S29: =E29*(C29<=參數!$B$9)*(J29>參數!$B$9) -> 0 | T29: =E29*MAX(0,MIN(J29,參數!$B$11)-MAX(C29,參數!$B$10)) -> 0 | U29: =IF(AND(29>2,A28=A29,C29>=參數!$B$5,C29<參數!$B$3),E29-E28,0) -> 0
A30: CoreWeave Denton TX | B30: likely | C30: 46538 | D30: 8 | E30: 282 | F30: 395 | G30: 271854.47 | H30: =C30 -> 46538 | J30: =IF(AND(30<122,A31=A30),C31,DATE(2100,1,1)) -> 73051 | K30: =IF(AND(30<122,A31=A30),H31,DATE(2100,1,1)) -> 73051 | L30: =E30*MAX(0,MIN(J30,參數!$B$4)-MAX(C30,參數!$B$3)) -> 0 | M30: =E30*MAX(0,MIN(K30,參數!$B$4)-MAX(H30,參數!$B$3)) -> 0 | N30: =E30*MAX(0,MIN(J30,參數!$B$6)-MAX(C30,參數!$B$5)) -> 0 | O30: =E30*MAX(0,MIN(K30,參數!$B$6)-MAX(H30,參數!$B$5)) -> 0 | P30: =E30*(C30<=參數!$B$8)*(J30>參數!$B$8) -> 0 | Q30: =E30*(C30<=參數!$B$7)*(J30>參數!$B$7) -> 0 | R30: =E30*(H30<=參數!$B$7)*(K30>參數!$B$7) -> 0 | S30: =E30*(C30<=參數!$B$9)*(J30>參數!$B$9) -> 0 | T30: =E30*MAX(0,MIN(J30,參數!$B$11)-MAX(C30,參數!$B$10)) -> 0 | U30: =IF(AND(30>2,A29=A30,C30>=參數!$B$5,C30<參數!$B$3),E30-E29,0) -> 0
A31: Microsoft Goodyear | B31: likely | C31: 44368 | D31: 0 | E31: 0 | F31: 0 | G31: 0 | H31: =C31 -> 44368 | J31: =IF(AND(31<122,A32=A31),C32,DATE(2100,1,1)) -> 45040 | K31: =IF(AND(31<122,A32=A31),H32,DATE(2100,1,1)) -> 45040 | L31: =E31*MAX(0,MIN(J31,參數!$B$4)-MAX(C31,參數!$B$3)) -> 0 | M31: =E31*MAX(0,MIN(K31,參數!$B$4)-MAX(H31,參數!$B$3)) -> 0 | N31: =E31*MAX(0,MIN(J31,參數!$B$6)-MAX(C31,參數!$B$5)) -> 0 | O31: =E31*MAX(0,MIN(K31,參數!$B$6)-MAX(H31,參數!$B$5)) -> 0 | P31: =E31*(C31<=參數!$B$8)*(J31>參數!$B$8) -> 0 | Q31: =E31*(C31<=參數!$B$7)*(J31>參數!$B$7) -> 0 | R31: =E31*(H31<=參數!$B$7)*(K31>參數!$B$7) -> 0 | S31: =E31*(C31<=參數!$B$9)*(J31>參數!$B$9) -> 0 | T31: =E31*MAX(0,MIN(J31,參數!$B$11)-MAX(C31,參數!$B$10)) -> 0 | U31: =IF(AND(31>2,A30=A31,C31>=參數!$B$5,C31<參數!$B$3),E31-E30,0) -> 0
A32: Microsoft Goodyear | B32: likely | C32: 45040 | D32: 1 | E32: 40 | F32: 53 | G32: 29156.139 | H32: =C32 -> 45040 | J32: =IF(AND(32<122,A33=A32),C33,DATE(2100,1,1)) -> 45673 | K32: =IF(AND(32<122,A33=A32),H33,DATE(2100,1,1)) -> 45673 | L32: =E32*MAX(0,MIN(J32,參數!$B$4)-MAX(C32,參數!$B$3)) -> 0 | M32: =E32*MAX(0,MIN(K32,參數!$B$4)-MAX(H32,參數!$B$3)) -> 0 | N32: =E32*MAX(0,MIN(J32,參數!$B$6)-MAX(C32,參數!$B$5)) -> 0 | O32: =E32*MAX(0,MIN(K32,參數!$B$6)-MAX(H32,參數!$B$5)) -> 0 | P32: =E32*(C32<=參數!$B$8)*(J32>參數!$B$8) -> 0 | Q32: =E32*(C32<=參數!$B$7)*(J32>參數!$B$7) -> 0 | R32: =E32*(H32<=參數!$B$7)*(K32>參數!$B$7) -> 0 | S32: =E32*(C32<=參數!$B$9)*(J32>參數!$B$9) -> 40 | T32: =E32*MAX(0,MIN(J32,參數!$B$11)-MAX(C32,參數!$B$10)) -> 600 | U32: =IF(AND(32>2,A31=A32,C32>=參數!$B$5,C32<參數!$B$3),E32-E31,0) -> 0
A33: Microsoft Goodyear | B33: likely | C33: 45673 | D33: 2 | E33: 81 | F33: 105 | G33: 58110.157 | H33: =C33 -> 45673 | J33: =IF(AND(33<122,A34=A33),C34,DATE(2100,1,1)) -> 45901 | K33: =IF(AND(33<122,A34=A33),H34,DATE(2100,1,1)) -> 45901 | L33: =E33*MAX(0,MIN(J33,參數!$B$4)-MAX(C33,參數!$B$3)) -> 0 | M33: =E33*MAX(0,MIN(K33,參數!$B$4)-MAX(H33,參數!$B$3)) -> 0 | N33: =E33*MAX(0,MIN(J33,參數!$B$6)-MAX(C33,參數!$B$5)) -> 0 | O33: =E33*MAX(0,MIN(K33,參數!$B$6)-MAX(H33,參數!$B$5)) -> 0 | P33: =E33*(C33<=參數!$B$8)*(J33>參數!$B$8) -> 0 | Q33: =E33*(C33<=參數!$B$7)*(J33>參數!$B$7) -> 0 | R33: =E33*(H33<=參數!$B$7)*(K33>參數!$B$7) -> 0 | S33: =E33*(C33<=參數!$B$9)*(J33>參數!$B$9) -> 0 | T33: =E33*MAX(0,MIN(J33,參數!$B$11)-MAX(C33,參數!$B$10)) -> 18468 | U33: =IF(AND(33>2,A32=A33,C33>=參數!$B$5,C33<參數!$B$3),E33-E32,0) -> 0
A34: Microsoft Goodyear | B34: likely | C34: 45901 | D34: 4 | E34: 202 | F34: 263 | G34: 205154.12 | H34: =C34 -> 45901 | J34: =IF(AND(34<122,A35=A34),C35,DATE(2100,1,1)) -> 45973 | K34: =IF(AND(34<122,A35=A34),H35,DATE(2100,1,1)) -> 45973 | L34: =E34*MAX(0,MIN(J34,參數!$B$4)-MAX(C34,參數!$B$3)) -> 0 | M34: =E34*MAX(0,MIN(K34,參數!$B$4)-MAX(H34,參數!$B$3)) -> 0 | N34: =E34*MAX(0,MIN(J34,參數!$B$6)-MAX(C34,參數!$B$5)) -> 0 | O34: =E34*MAX(0,MIN(K34,參數!$B$6)-MAX(H34,參數!$B$5)) -> 0 | P34: =E34*(C34<=參數!$B$8)*(J34>參數!$B$8) -> 0 | Q34: =E34*(C34<=參數!$B$7)*(J34>參數!$B$7) -> 0 | R34: =E34*(H34<=參數!$B$7)*(K34>參數!$B$7) -> 0 | S34: =E34*(C34<=參數!$B$9)*(J34>參數!$B$9) -> 0 | T34: =E34*MAX(0,MIN(J34,參數!$B$11)-MAX(C34,參數!$B$10)) -> 14544 | U34: =IF(AND(34>2,A33=A34,C34>=參數!$B$5,C34<參數!$B$3),E34-E33,0) -> 0
A35: Microsoft Goodyear | B35: likely | C35: 45973 | D35: 4 | E35: 202 | F35: 263 | G35: 205154.12 | H35: =C35 -> 45973 | J35: =IF(AND(35<122,A36=A35),C36,DATE(2100,1,1)) -> 46139 | K35: =IF(AND(35<122,A36=A35),H36,DATE(2100,1,1)) -> 46139 | L35: =E35*MAX(0,MIN(J35,參數!$B$4)-MAX(C35,參數!$B$3)) -> 5252 | M35: =E35*MAX(0,MIN(K35,參數!$B$4)-MAX(H35,參數!$B$3)) -> 5252 | N35: =E35*MAX(0,MIN(J35,參數!$B$6)-MAX(C35,參數!$B$5)) -> 23432 | O35: =E35*MAX(0,MIN(K35,參數!$B$6)-MAX(H35,參數!$B$5)) -> 23432 | P35: =E35*(C35<=參數!$B$8)*(J35>參數!$B$8) -> 202 | Q35: =E35*(C35<=參數!$B$7)*(J35>參數!$B$7) -> 0 | R35: =E35*(H35<=參數!$B$7)*(K35>參數!$B$7) -> 0 | S35: =E35*(C35<=參數!$B$9)*(J35>參數!$B$9) -> 0 | T35: =E35*MAX(0,MIN(J35,參數!$B$11)-MAX(C35,參數!$B$10)) -> 10100 | U35: =IF(AND(35>2,A34=A35,C35>=參數!$B$5,C35<參數!$B$3),E35-E34,0) -> 0
A36: Microsoft Goodyear | B36: likely | C36: 46139 | D36: 4 | E36: 202 | F36: 263 | G36: 205154.12 | H36: =C36 -> 46139 | J36: =IF(AND(36<122,A37=A36),C37,DATE(2100,1,1)) -> 73051 | K36: =IF(AND(36<122,A37=A36),H37,DATE(2100,1,1)) -> 73051 | L36: =E36*MAX(0,MIN(J36,參數!$B$4)-MAX(C36,參數!$B$3)) -> 13130 | M36: =E36*MAX(0,MIN(K36,參數!$B$4)-MAX(H36,參數!$B$3)) -> 13130 | N36: =E36*MAX(0,MIN(J36,參數!$B$6)-MAX(C36,參數!$B$5)) -> 50298 | O36: =E36*MAX(0,MIN(K36,參數!$B$6)-MAX(H36,參數!$B$5)) -> 50298 | P36: =E36*(C36<=參數!$B$8)*(J36>參數!$B$8) -> 0 | Q36: =E36*(C36<=參數!$B$7)*(J36>參數!$B$7) -> 202 | R36: =E36*(H36<=參數!$B$7)*(K36>參數!$B$7) -> 202 | S36: =E36*(C36<=參數!$B$9)*(J36>參數!$B$9) -> 0 | T36: =E36*MAX(0,MIN(J36,參數!$B$11)-MAX(C36,參數!$B$10)) -> 0 | U36: =IF(AND(36>2,A35=A36,C36>=參數!$B$5,C36<參數!$B$3),E36-E35,0) -> 0
A37: Coreweave Helios | B37: speculative | C37: 45808 | D37: 0 | E37: 0 | F37: 0 | G37: 0 | H37: =C37 -> 45808 | J37: =IF(AND(37<122,A38=A37),C38,DATE(2100,1,1)) -> 45896 | K37: =IF(AND(37<122,A38=A37),H38,DATE(2100,1,1)) -> 45896 | L37: =E37*MAX(0,MIN(J37,參數!$B$4)-MAX(C37,參數!$B$3)) -> 0 | M37: =E37*MAX(0,MIN(K37,參數!$B$4)-MAX(H37,參數!$B$3)) -> 0 | N37: =E37*MAX(0,MIN(J37,參數!$B$6)-MAX(C37,參數!$B$5)) -> 0 | O37: =E37*MAX(0,MIN(K37,參數!$B$6)-MAX(H37,參數!$B$5)) -> 0 | P37: =E37*(C37<=參數!$B$8)*(J37>參數!$B$8) -> 0 | Q37: =E37*(C37<=參數!$B$7)*(J37>參數!$B$7) -> 0 | R37: =E37*(H37<=參數!$B$7)*(K37>參數!$B$7) -> 0 | S37: =E37*(C37<=參數!$B$9)*(J37>參數!$B$9) -> 0 | T37: =E37*MAX(0,MIN(J37,參數!$B$11)-MAX(C37,參數!$B$10)) -> 0 | U37: =IF(AND(37>2,A36=A37,C37>=參數!$B$5,C37<參數!$B$3),E37-E36,0) -> 0
A38: Coreweave Helios | B38: speculative | C38: 45896 | D38: 0 | E38: 0 | F38: 0 | G38: 0 | H38: =C38 -> 45896 | J38: =IF(AND(38<122,A39=A38),C39,DATE(2100,1,1)) -> 46116 | K38: =IF(AND(38<122,A39=A38),H39,DATE(2100,1,1)) -> 46116 | L38: =E38*MAX(0,MIN(J38,參數!$B$4)-MAX(C38,參數!$B$3)) -> 0 | M38: =E38*MAX(0,MIN(K38,參數!$B$4)-MAX(H38,參數!$B$3)) -> 0 | N38: =E38*MAX(0,MIN(J38,參數!$B$6)-MAX(C38,參數!$B$5)) -> 0 | O38: =E38*MAX(0,MIN(K38,參數!$B$6)-MAX(H38,參數!$B$5)) -> 0 | P38: =E38*(C38<=參數!$B$8)*(J38>參數!$B$8) -> 0 | Q38: =E38*(C38<=參數!$B$7)*(J38>參數!$B$7) -> 0 | R38: =E38*(H38<=參數!$B$7)*(K38>參數!$B$7) -> 0 | S38: =E38*(C38<=參數!$B$9)*(J38>參數!$B$9) -> 0 | T38: =E38*MAX(0,MIN(J38,參數!$B$11)-MAX(C38,參數!$B$10)) -> 0 | U38: =IF(AND(38>2,A37=A38,C38>=參數!$B$5,C38<參數!$B$3),E38-E37,0) -> 0
A39: Coreweave Helios | B39: speculative | C39: 46116 | D39: 0 | E39: 0 | F39: 0 | G39: 0 | H39: =C39 -> 46116 | J39: =IF(AND(39<122,A40=A39),C40,DATE(2100,1,1)) -> 46190 | K39: =IF(AND(39<122,A40=A39),H40,DATE(2100,1,1)) -> 46190 | L39: =E39*MAX(0,MIN(J39,參數!$B$4)-MAX(C39,參數!$B$3)) -> 0 | M39: =E39*MAX(0,MIN(K39,參數!$B$4)-MAX(H39,參數!$B$3)) -> 0 | N39: =E39*MAX(0,MIN(J39,參數!$B$6)-MAX(C39,參數!$B$5)) -> 0 | O39: =E39*MAX(0,MIN(K39,參數!$B$6)-MAX(H39,參數!$B$5)) -> 0 | P39: =E39*(C39<=參數!$B$8)*(J39>參數!$B$8) -> 0 | Q39: =E39*(C39<=參數!$B$7)*(J39>參數!$B$7) -> 0 | R39: =E39*(H39<=參數!$B$7)*(K39>參數!$B$7) -> 0 | S39: =E39*(C39<=參數!$B$9)*(J39>參數!$B$9) -> 0 | T39: =E39*MAX(0,MIN(J39,參數!$B$11)-MAX(C39,參數!$B$10)) -> 0 | U39: =IF(AND(39>2,A38=A39,C39>=參數!$B$5,C39<參數!$B$3),E39-E38,0) -> 0
A40: Coreweave Helios | B40: speculative | C40: 46190 | D40: 0 | E40: 0 | F40: 0 | G40: 0 | H40: =C40 -> 46190 | J40: =IF(AND(40<122,A41=A40),C41,DATE(2100,1,1)) -> 46264 | K40: =IF(AND(40<122,A41=A40),H41,DATE(2100,1,1)) -> 46191 | L40: =E40*MAX(0,MIN(J40,參數!$B$4)-MAX(C40,參數!$B$3)) -> 0 | M40: =E40*MAX(0,MIN(K40,參數!$B$4)-MAX(H40,參數!$B$3)) -> 0 | N40: =E40*MAX(0,MIN(J40,參數!$B$6)-MAX(C40,參數!$B$5)) -> 0 | O40: =E40*MAX(0,MIN(K40,參數!$B$6)-MAX(H40,參數!$B$5)) -> 0 | P40: =E40*(C40<=參數!$B$8)*(J40>參數!$B$8) -> 0 | Q40: =E40*(C40<=參數!$B$7)*(J40>參數!$B$7) -> 0 | R40: =E40*(H40<=參數!$B$7)*(K40>參數!$B$7) -> 0 | S40: =E40*(C40<=參數!$B$9)*(J40>參數!$B$9) -> 0 | T40: =E40*MAX(0,MIN(J40,參數!$B$11)-MAX(C40,參數!$B$10)) -> 0 | U40: =IF(AND(40>2,A39=A40,C40>=參數!$B$5,C40<參數!$B$3),E40-E39,0) -> 0
...

Sheet 站點彙總
A1: 站點 | B1: OpenAI 標記 | C1: 2025 年底 IT MW | D1: Q2 平均增量 MW（晚） | E1: Q2 平均增量 MW（早） | F1: 全年平均增量 MW（晚） | G1: 全年平均增量 MW（早） | H1: 2026 年底增量 MW（晚） | I1: 2026 年底增量 MW（早） | J1: 2024 年底 MW | K1: 2025 平均增量 MW（對 2024 年底） | L1: 2026 Q1 記錄之新增 MW
A2: Microsoft Fairwater Atlanta | B2: likely | C2: =SUMIFS(站點時間表!$P$2:$P$122,站點時間表!$A$2:$A$122,$A2) -> 321 | D2: =SUMIFS(站點時間表!$L$2:$L$122,站點時間表!$A$2:$A$122,$A2)/(參數!$B$4-參數!$B$3)-C2 -> 58.846154 | E2: =SUMIFS(站點時間表!$M$2:$M$122,站點時間表!$A$2:$A$122,$A2)/(參數!$B$4-參數!$B$3)-C2 -> 159.23077 | F2: =SUMIFS(站點時間表!$N$2:$N$122,站點時間表!$A$2:$A$122,$A2)/(參數!$B$6-參數!$B$5)-C2 -> 173.46575 | G2: =SUMIFS(站點時間表!$O$2:$O$122,站點時間表!$A$2:$A$122,$A2)/(參數!$B$6-參數!$B$5)-C2 -> 198.49315 | H2: =SUMIFS(站點時間表!$Q$2:$Q$122,站點時間表!$A$2:$A$122,$A2)-C2 -> 315 | I2: =SUMIFS(站點時間表!$R$2:$R$122,站點時間表!$A$2:$A$122,$A2)-C2 -> 315 | J2: =SUMIFS(站點時間表!$S$2:$S$122,站點時間表!$A$2:$A$122,$A2) -> 0 | K2: =SUMIFS(站點時間表!$T$2:$T$122,站點時間表!$A$2:$A$122,$A2)/(參數!$B$11-參數!$B$10)-J2 -> 69.476712 | L2: =SUMIFS(站點時間表!$U$2:$U$122,站點時間表!$A$2:$A$122,$A2) -> 0
A3: OpenAI Stargate Abilene | B3: confident | C3: =SUMIFS(站點時間表!$P$2:$P$122,站點時間表!$A$2:$A$122,$A3) -> 211 | D3: =SUMIFS(站點時間表!$L$2:$L$122,站點時間表!$A$2:$A$122,$A3)/(參數!$B$4-參數!$B$3)-C3 -> 90 | E3: =SUMIFS(站點時間表!$M$2:$M$122,站點時間表!$A$2:$A$122,$A3)/(參數!$B$4-參數!$B$3)-C3 -> 159.23077 | F3: =SUMIFS(站點時間表!$N$2:$N$122,站點時間表!$A$2:$A$122,$A3)/(參數!$B$6-參數!$B$5)-C3 -> 198.8274 | G3: =SUMIFS(站點時間表!$O$2:$O$122,站點時間表!$A$2:$A$122,$A3)/(參數!$B$6-參數!$B$5)-C3 -> 216.08767 | H3: =SUMIFS(站點時間表!$Q$2:$Q$122,站點時間表!$A$2:$A$122,$A3)-C3 -> 632 | I3: =SUMIFS(站點時間表!$R$2:$R$122,站點時間表!$A$2:$A$122,$A3)-C3 -> 632 | J3: =SUMIFS(站點時間表!$S$2:$S$122,站點時間表!$A$2:$A$122,$A3) -> 0 | K3: =SUMIFS(站點時間表!$T$2:$T$122,站點時間表!$A$2:$A$122,$A3)/(參數!$B$11-參數!$B$10)-J3 -> 30.227397 | L3: =SUMIFS(站點時間表!$U$2:$U$122,站點時間表!$A$2:$A$122,$A3) -> 0
A4: Microsoft Fairwater Wisconsin | B4: likely | C4: =SUMIFS(站點時間表!$P$2:$P$122,站點時間表!$A$2:$A$122,$A4) -> 0 | D4: =SUMIFS(站點時間表!$L$2:$L$122,站點時間表!$A$2:$A$122,$A4)/(參數!$B$4-參數!$B$3)-C4 -> 308.17582 | E4: =SUMIFS(站點時間表!$M$2:$M$122,站點時間表!$A$2:$A$122,$A4)/(參數!$B$4-參數!$B$3)-C4 -> 308.17582 | F4: =SUMIFS(站點時間表!$N$2:$N$122,站點時間表!$A$2:$A$122,$A4)/(參數!$B$6-參數!$B$5)-C4 -> 262.84932 | G4: =SUMIFS(站點時間表!$O$2:$O$122,站點時間表!$A$2:$A$122,$A4)/(參數!$B$6-參數!$B$5)-C4 -> 262.84932 | H4: =SUMIFS(站點時間表!$Q$2:$Q$122,站點時間表!$A$2:$A$122,$A4)-C4 -> 369 | I4: =SUMIFS(站點時間表!$R$2:$R$122,站點時間表!$A$2:$A$122,$A4)-C4 -> 369 | J4: =SUMIFS(站點時間表!$S$2:$S$122,站點時間表!$A$2:$A$122,$A4) -> 0 | K4: =SUMIFS(站點時間表!$T$2:$T$122,站點時間表!$A$2:$A$122,$A4)/(參數!$B$11-參數!$B$10)-J4 -> 0 | L4: =SUMIFS(站點時間表!$U$2:$U$122,站點時間表!$A$2:$A$122,$A4) -> 0
A5: CoreWeave Denton TX | B5: likely | C5: =SUMIFS(站點時間表!$P$2:$P$122,站點時間表!$A$2:$A$122,$A5) -> 67 | D5: =SUMIFS(站點時間表!$L$2:$L$122,站點時間表!$A$2:$A$122,$A5)/(參數!$B$4-參數!$B$3)-C5 -> 64 | E5: =SUMIFS(站點時間表!$M$2:$M$122,站點時間表!$A$2:$A$122,$A5)/(參數!$B$4-參數!$B$3)-C5 -> 195 | F5: =SUMIFS(站點時間表!$N$2:$N$122,站點時間表!$A$2:$A$122,$A5)/(參數!$B$6-參數!$B$5)-C5 -> 120.0274 | G5: =SUMIFS(站點時間表!$O$2:$O$122,站點時間表!$A$2:$A$122,$A5)/(參數!$B$6-參數!$B$5)-C5 -> 173.10685 | H5: =SUMIFS(站點時間表!$Q$2:$Q$122,站點時間表!$A$2:$A$122,$A5)-C5 -> 195 | I5: =SUMIFS(站點時間表!$R$2:$R$122,站點時間表!$A$2:$A$122,$A5)-C5 -> 195 | J5: =SUMIFS(站點時間表!$S$2:$S$122,站點時間表!$A$2:$A$122,$A5) -> 0 | K5: =SUMIFS(站點時間表!$T$2:$T$122,站點時間表!$A$2:$A$122,$A5)/(參數!$B$11-參數!$B$10)-J5 -> 4.8739726 | L5: =SUMIFS(站點時間表!$U$2:$U$122,站點時間表!$A$2:$A$122,$A5) -> 64
A6: Microsoft Goodyear | B6: likely | C6: =SUMIFS(站點時間表!$P$2:$P$122,站點時間表!$A$2:$A$122,$A6) -> 202 | D6: =SUMIFS(站點時間表!$L$2:$L$122,站點時間表!$A$2:$A$122,$A6)/(參數!$B$4-參數!$B$3)-C6 -> 0 | E6: =SUMIFS(站點時間表!$M$2:$M$122,站點時間表!$A$2:$A$122,$A6)/(參數!$B$4-參數!$B$3)-C6 -> 0 | F6: =SUMIFS(站點時間表!$N$2:$N$122,站點時間表!$A$2:$A$122,$A6)/(參數!$B$6-參數!$B$5)-C6 -> 0 | G6: =SUMIFS(站點時間表!$O$2:$O$122,站點時間表!$A$2:$A$122,$A6)/(參數!$B$6-參數!$B$5)-C6 -> 0 | H6: =SUMIFS(站點時間表!$Q$2:$Q$122,站點時間表!$A$2:$A$122,$A6)-C6 -> 0 | I6: =SUMIFS(站點時間表!$R$2:$R$122,站點時間表!$A$2:$A$122,$A6)-C6 -> 0 | J6: =SUMIFS(站點時間表!$S$2:$S$122,站點時間表!$A$2:$A$122,$A6) -> 40 | K6: =SUMIFS(站點時間表!$T$2:$T$122,站點時間表!$A$2:$A$122,$A6)/(參數!$B$11-參數!$B$10)-J6 -> 79.758904 | L6: =SUMIFS(站點時間表!$U$2:$U$122,站點時間表!$A$2:$A$122,$A6) -> 0
A7: Coreweave Helios | B7: speculative | C7: =SUMIFS(站點時間表!$P$2:$P$122,站點時間表!$A$2:$A$122,$A7) -> 0 | D7: =SUMIFS(站點時間表!$L$2:$L$122,站點時間表!$A$2:$A$122,$A7)/(參數!$B$4-參數!$B$3)-C7 -> 0 | E7: =SUMIFS(站點時間表!$M$2:$M$122,站點時間表!$A$2:$A$122,$A7)/(參數!$B$4-參數!$B$3)-C7 -> 18.857143 | F7: =SUMIFS(站點時間表!$N$2:$N$122,站點時間表!$A$2:$A$122,$A7)/(參數!$B$6-參數!$B$5)-C7 -> 44.843836 | G7: =SUMIFS(站點時間表!$O$2:$O$122,站點時間表!$A$2:$A$122,$A7)/(參數!$B$6-參數!$B$5)-C7 -> 71.243836 | H7: =SUMIFS(站點時間表!$Q$2:$Q$122,站點時間表!$A$2:$A$122,$A7)-C7 -> 132 | I7: =SUMIFS(站點時間表!$R$2:$R$122,站點時間表!$A$2:$A$122,$A7)-C7 -> 132 | J7: =SUMIFS(站點時間表!$S$2:$S$122,站點時間表!$A$2:$A$122,$A7) -> 0 | K7: =SUMIFS(站點時間表!$T$2:$T$122,站點時間表!$A$2:$A$122,$A7)/(參數!$B$11-參數!$B$10)-J7 -> 0 | L7: =SUMIFS(站點時間表!$U$2:$U$122,站點時間表!$A$2:$A$122,$A7) -> 0
A8: Microsoft Project Osmium | B8: speculative | C8: =SUMIFS(站點時間表!$P$2:$P$122,站點時間表!$A$2:$A$122,$A8) -> 190 | D8: =SUMIFS(站點時間表!$L$2:$L$122,站點時間表!$A$2:$A$122,$A8)/(參數!$B$4-參數!$B$3)-C8 -> 0 | E8: =SUMIFS(站點時間表!$M$2:$M$122,站點時間表!$A$2:$A$122,$A8)/(參數!$B$4-參數!$B$3)-C8 -> 0 | F8: =SUMIFS(站點時間表!$N$2:$N$122,站點時間表!$A$2:$A$122,$A8)/(參數!$B$6-參數!$B$5)-C8 -> 0 | G8: =SUMIFS(站點時間表!$O$2:$O$122,站點時間表!$A$2:$A$122,$A8)/(參數!$B$6-參數!$B$5)-C8 -> 0 | H8: =SUMIFS(站點時間表!$Q$2:$Q$122,站點時間表!$A$2:$A$122,$A8)-C8 -> 0 | I8: =SUMIFS(站點時間表!$R$2:$R$122,站點時間表!$A$2:$A$122,$A8)-C8 -> 0 | J8: =SUMIFS(站點時間表!$S$2:$S$122,站點時間表!$A$2:$A$122,$A8) -> 95 | K8: =SUMIFS(站點時間表!$T$2:$T$122,站點時間表!$A$2:$A$122,$A8)/(參數!$B$11-參數!$B$10)-J8 -> 79.643836 | L8: =SUMIFS(站點時間表!$U$2:$U$122,站點時間表!$A$2:$A$122,$A8) -> 0
A9: CoreWeave Ellendale ND | B9: speculative | C9: =SUMIFS(站點時間表!$P$2:$P$122,站點時間表!$A$2:$A$122,$A9) -> 68 | D9: =SUMIFS(站點時間表!$L$2:$L$122,站點時間表!$A$2:$A$122,$A9)/(參數!$B$4-參數!$B$3)-C9 -> 0 | E9: =SUMIFS(站點時間表!$M$2:$M$122,站點時間表!$A$2:$A$122,$A9)/(參數!$B$4-參數!$B$3)-C9 -> 0 | F9: =SUMIFS(站點時間表!$N$2:$N$122,站點時間表!$A$2:$A$122,$A9)/(參數!$B$6-參數!$B$5)-C9 -> 0.054794521 | G9: =SUMIFS(站點時間表!$O$2:$O$122,站點時間表!$A$2:$A$122,$A9)/(參數!$B$6-參數!$B$5)-C9 -> 0.054794521 | H9: =SUMIFS(站點時間表!$Q$2:$Q$122,站點時間表!$A$2:$A$122,$A9)-C9 -> 20 | I9: =SUMIFS(站點時間表!$R$2:$R$122,站點時間表!$A$2:$A$122,$A9)-C9 -> 20 | J9: =SUMIFS(站點時間表!$S$2:$S$122,站點時間表!$A$2:$A$122,$A9) -> 0 | K9: =SUMIFS(站點時間表!$T$2:$T$122,站點時間表!$A$2:$A$122,$A9)/(參數!$B$11-參數!$B$10)-J9 -> 10.915068 | L9: =SUMIFS(站點時間表!$U$2:$U$122,站點時間表!$A$2:$A$122,$A9) -> 0
A10: CoreWeave Chester VA | B10: speculative | C10: =SUMIFS(站點時間表!$P$2:$P$122,站點時間表!$A$2:$A$122,$A10) -> 27 | D10: =SUMIFS(站點時間表!$L$2:$L$122,站點時間表!$A$2:$A$122,$A10)/(參數!$B$4-參數!$B$3)-C10 -> 25.384615 | E10: =SUMIFS(站點時間表!$M$2:$M$122,站點時間表!$A$2:$A$122,$A10)/(參數!$B$4-參數!$B$3)-C10 -> 25.384615 | F10: =SUMIFS(站點時間表!$N$2:$N$122,站點時間表!$A$2:$A$122,$A10)/(參數!$B$6-參數!$B$5)-C10 -> 34.054795 | G10: =SUMIFS(站點時間表!$O$2:$O$122,站點時間表!$A$2:$A$122,$A10)/(參數!$B$6-參數!$B$5)-C10 -> 34.054795 | H10: =SUMIFS(站點時間表!$Q$2:$Q$122,站點時間表!$A$2:$A$122,$A10)-C10 -> 55 | I10: =SUMIFS(站點時間表!$R$2:$R$122,站點時間表!$A$2:$A$122,$A10)-C10 -> 55 | J10: =SUMIFS(站點時間表!$S$2:$S$122,站點時間表!$A$2:$A$122,$A10) -> 27 | K10: =SUMIFS(站點時間表!$T$2:$T$122,站點時間表!$A$2:$A$122,$A10)/(參數!$B$11-參數!$B$10)-J10 -> 0 | L10: =SUMIFS(站點時間表!$U$2:$U$122,站點時間表!$A$2:$A$122,$A10) -> 0
A11: CoreWeave Marble NC | B11: speculative | C11: =SUMIFS(站點時間表!$P$2:$P$122,站點時間表!$A$2:$A$122,$A11) -> 0 | D11: =SUMIFS(站點時間表!$L$2:$L$122,站點時間表!$A$2:$A$122,$A11)/(參數!$B$4-參數!$B$3)-C11 -> 53.846154 | E11: =SUMIFS(站點時間表!$M$2:$M$122,站點時間表!$A$2:$A$122,$A11)/(參數!$B$4-參數!$B$3)-C11 -> 53.846154 | F11: =SUMIFS(站點時間表!$N$2:$N$122,站點時間表!$A$2:$A$122,$A11)/(參數!$B$6-參數!$B$5)-C11 -> 48.065753 | G11: =SUMIFS(站點時間表!$O$2:$O$122,站點時間表!$A$2:$A$122,$A11)/(參數!$B$6-參數!$B$5)-C11 -> 48.065753 | H11: =SUMIFS(站點時間表!$Q$2:$Q$122,站點時間表!$A$2:$A$122,$A11)-C11 -> 65 | I11: =SUMIFS(站點時間表!$R$2:$R$122,站點時間表!$A$2:$A$122,$A11)-C11 -> 65 | J11: =SUMIFS(站點時間表!$S$2:$S$122,站點時間表!$A$2:$A$122,$A11) -> 0 | K11: =SUMIFS(站點時間表!$T$2:$T$122,站點時間表!$A$2:$A$122,$A11)/(參數!$B$11-參數!$B$10)-J11 -> 0 | L11: =SUMIFS(站點時間表!$U$2:$U$122,站點時間表!$A$2:$A$122,$A11) -> 36
A12: CoreWeave Norway | B12: speculative | C12: =SUMIFS(站點時間表!$P$2:$P$122,站點時間表!$A$2:$A$122,$A12) -> 42 | D12: =SUMIFS(站點時間表!$L$2:$L$122,站點時間表!$A$2:$A$122,$A12)/(參數!$B$4-參數!$B$3)-C12 -> 0 | E12: =SUMIFS(站點時間表!$M$2:$M$122,站點時間表!$A$2:$A$122,$A12)/(參數!$B$4-參數!$B$3)-C12 -> 0 | F12: =SUMIFS(站點時間表!$N$2:$N$122,站點時間表!$A$2:$A$122,$A12)/(參數!$B$6-參數!$B$5)-C12 -> 0 | G12: =SUMIFS(站點時間表!$O$2:$O$122,站點時間表!$A$2:$A$122,$A12)/(參數!$B$6-參數!$B$5)-C12 -> 0 | H12: =SUMIFS(站點時間表!$Q$2:$Q$122,站點時間表!$A$2:$A$122,$A12)-C12 -> 0 | I12: =SUMIFS(站點時間表!$R$2:$R$122,站點時間表!$A$2:$A$122,$A12)-C12 -> 0 | J12: =SUMIFS(站點時間表!$S$2:$S$122,站點時間表!$A$2:$A$122,$A12) -> 0 | K12: =SUMIFS(站點時間表!$T$2:$T$122,站點時間表!$A$2:$A$122,$A12)/(參數!$B$11-參數!$B$10)-J12 -> 18.180822 | L12: =SUMIFS(站點時間表!$U$2:$U$122,站點時間表!$A$2:$A$122,$A12) -> 0
A13: CoreWeave Dalton 1 & 2 | B13: speculative | C13: =SUMIFS(站點時間表!$P$2:$P$122,站點時間表!$A$2:$A$122,$A13) -> 0 | D13: =SUMIFS(站點時間表!$L$2:$L$122,站點時間表!$A$2:$A$122,$A13)/(參數!$B$4-參數!$B$3)-C13 -> 28 | E13: =SUMIFS(站點時間表!$M$2:$M$122,站點時間表!$A$2:$A$122,$A13)/(參數!$B$4-參數!$B$3)-C13 -> 28 | F13: =SUMIFS(站點時間表!$N$2:$N$122,站點時間表!$A$2:$A$122,$A13)/(參數!$B$6-參數!$B$5)-C13 -> 24.164384 | G13: =SUMIFS(站點時間表!$O$2:$O$122,站點時間表!$A$2:$A$122,$A13)/(參數!$B$6-參數!$B$5)-C13 -> 24.164384 | H13: =SUMIFS(站點時間表!$Q$2:$Q$122,站點時間表!$A$2:$A$122,$A13)-C13 -> 28 | I13: =SUMIFS(站點時間表!$R$2:$R$122,站點時間表!$A$2:$A$122,$A13)-C13 -> 28 | J13: =SUMIFS(站點時間表!$S$2:$S$122,站點時間表!$A$2:$A$122,$A13) -> 0 | K13: =SUMIFS(站點時間表!$T$2:$T$122,站點時間表!$A$2:$A$122,$A13)/(參數!$B$11-參數!$B$10)-J13 -> 0 | L13: =SUMIFS(站點時間表!$U$2:$U$122,站點時間表!$A$2:$A$122,$A13) -> 28
... A22: OpenAI Stargate Wisconsin | B22: confident | C22: =SUMIFS(站點時間表!$P$2:$P$122,站點時間表!$A$2:$A$122,$A22) -> 0 | D22: =SUMIFS(站點時間表!$L$2:$L$122,站點時間表!$A$2:$A$122,$A22)/(參數!$B$4-參數!$B$3)-C22 -> 0 | E22: =SUMIFS(站點時間表!$M$2:$M$122,站點時間表!$A$2:$A$122,$A22)/(參數!$B$4-參數!$B$3)-C22 -> 0 | F22: =SUMIFS(站點時間表!$N$2:$N$122,站點時間表!$A$2:$A$122,$A22)/(參數!$B$6-參數!$B$5)-C22 -> 0 | G22: =SUMIFS(站點時間表!$O$2:$O$122,站點時間表!$A$2:$A$122,$A22)/(參數!$B$6-參數!$B$5)-C22 -> 0 | H22: =SUMIFS(站點時間表!$Q$2:$Q$122,站點時間表!$A$2:$A$122,$A22)-C22 -> 0 | I22: =SUMIFS(站點時間表!$R$2:$R$122,站點時間表!$A$2:$A$122,$A22)-C22 -> 0 | J22: =SUMIFS(站點時間表!$S$2:$S$122,站點時間表!$A$2:$A$122,$A22) -> 0 | K22: =SUMIFS(站點時間表!$T$2:$T$122,站點時間表!$A$2:$A$122,$A22)/(參數!$B$11-參數!$B$10)-J22 -> 0 | L22: =SUMIFS(站點時間表!$U$2:$U$122,站點時間表!$A$2:$A$122,$A22) -> 0
A23: 合計（100% 計入） | C23: =SUM(C2:C22) -> 1128 | D23: =SUM(D2:D22) -> 628.25275 | E23: =SUM(E2:E22) -> 947.72527 | F23: =SUM(F2:F22) -> 923.53151 | G23: =SUM(G2:G22) -> 1045.2986 | H23: =SUM(H2:H22) -> 2081 | I23: =SUM(I2:I22) -> 2081 | J23: =SUM(J2:J22) -> 162 | ... L23: =SUM(L2:L22) -> 128
