Workbook

Sheet 建議值
A1: 建議值 — NonNV 第 5 列（AMD MI455X／Helios）以每 kW 方法重推｜C 段唯讀查證，未寫入 model/；與 B 段 TPU／Trn3、A 段 Maia／昇騰並排
A2: 第 4–5 列＝推導頁公式的原始結果（(a) 最高原生精度、(b) FP8 對齊）；第 8 列＝建議輸入值（r1；產出比四捨五入至 0.05；持有比保留兩位）；第 11 列＝TK v21.6 現值。H＝F÷C（每 token 成本比）、I＝E÷D（最佳角落）、J＝G÷B（最差角落），同 NonNV。
A3: 候選 | B3: 產出比 低 | C3: 產出比 基準 | D3: 產出比 高 | E3: 持有比 低 | F3: 持有比 基準 | G3: 持有比 高 | H3: 每 token 成本比 基準 | I3: 最佳角落 | J3: 最差角落 | K3: 標記 | L3: 說明
A4: AMD MI455X（(a) 最高原生精度；原始公式結果） | B4: =推導!D105 -> 0.69906277 | C4: =推導!E105 -> 0.80649467 | D4: =推導!F105 -> 1.1541676 | E4: =推導!D114 -> 0.67424649 | F4: =推導!E114 -> 0.8466149 | G4: =推導!F114 -> 1.1224043 | H4: =F4/C4 -> 1.0497464 | I4: =E4/D4 -> 0.58418422 | J4: =G4/B4 -> 1.6055845 | L4: 公式（連結推導頁）
A5: AMD MI455X（(b) FP8 對齊；原始公式結果） | B5: =推導!D120 -> 0.69908013 | C5: =推導!E120 -> 0.8065147 | D5: =推導!F120 -> 1.1541962 | E5: =推導!D114 -> 0.67424649 | F5: =推導!E114 -> 0.8466149 | G5: =推導!F114 -> 1.1224043 | H5: =F5/C5 -> 1.0497204 | I5: =E5/D5 -> 0.58416971 | J5: =G5/B5 -> 1.6055446 | L5: 公式（連結推導頁）
A7: 建議輸入值（若寫入 NonNV 第 5 列）
A8: AMD MI455X（Helios） | B8: 0.7 | C8: 0.8 | D8: 1.15 | E8: 0.67 | F8: 0.85 | G8: 1.12 | H8: =F8/C8 -> 1.0625 | I8: =E8/D8 -> 0.5826087 | J8: =G8/B8 -> 1.6 | K8: Assumed | L8: 每 kW 法：Helios 72 顆、機架 225–245 kW（AMD 數字經媒體；245 亦為散熱上限）→ 每顆 3.40 kW；MXFP4 40.27 PF（FP8 20.13），兩種精度口徑每 kW 峰值皆為 VR200 的 1.07；效率因子由 MLPerf v6.1 MI355X DeepSeek-R1 對 TK GB200／GB300／VR200 錨點還原（0.74–0.99），再乘算力÷頻寬轉換 0.89（Analogy）。持有比依 TK 買方取得價口徑：每架 $5.25M（Futurum 絕對價，口徑混用、下界）／$7.3M（AMD 自述隱含比 0.865 × VR200）／$10.5M（Futurum 同源比值 1.25 × VR200）推導（r1）。證據：docs/evidence/20261025_NonNV_AMD。
A10: TK v21.6 現值（NonNV 第 5 列；慣例值、未推導）
A11: AMD MI455X（Helios）（現值） | B11: 0.5 | C11: 0.7 | D11: 1 | E11: 0.8 | F11: 0.9 | G11: 1 | H11: =F11/C11 -> 1.2857143 | I11: =E11/D11 -> 0.8 | J11: =G11/B11 -> 2 | K11: Assumed | L11: model/20261025_Tokenomics_v21.6.xlsx NonNV!B5:G5
A13: 與 A、B 段並排（每 kW 峰值比為各自最高原生精度；TPU／Trn3 取 B 段建議值、Maia／昇騰取 TK v21.6 NonNV 現值）
A14: 候選 | B14: 每 kW 峰值 ÷ VR200（基準） | C14: 產出比 基準 | D14: 持有比 基準 | E14: 每 token 成本比 | F14: 產出比 區間 | G14: 持有比 區間 | H14: 來源
A15: AMD MI455X（本提案） | B15: =推導!E99 -> 1.0659073 | C15: =C8 -> 0.8 | D15: =F8 -> 0.85 | E15: =D15/C15 -> 1.0625 | F15: =TEXT(B8,"0.00")&"–"&TEXT(D8,"0.00") -> 0.70–1.15 | G15: =TEXT(E8,"0.00")&"–"&TEXT(G8,"0.00") -> 0.67–1.12 | H15: 本表
A16: Google TPU v7（B 段） | B16: 0.383 | C16: 0.35 | D16: 0.7 | E16: =D16/C16 -> 2 | F16: 0.25–0.40 | G16: 0.65–0.90 | H16: B 段（PR #172）建議值；持有比已寫入 v21.6（買方取得價，無口徑混用）
A17: AWS Trainium3（B 段） | B17: 0.176 | C17: 0.14 | D17: 0.55 | E17: =D17/C17 -> 3.9285714 | F17: 0.06–0.25 | G17: 0.45–0.70 | H17: B 段（PR #172）建議值；持有比已寫入 v21.6。r1 註：KGI 絕對價 ÷ TK 價為口徑混用，同源比值時約 0.59–0.63（README §10）
A18: Microsoft Maia 200（A 段） | B18: 0.676 | C18: 0.55 | D18: 0.5 | E18: =D18/C18 -> 0.90909091 | F18: 0.25–0.75 | G18: 0.40–0.60 | H18: A 段推導 D6；NonNV 第 11 列
A19: 華為昇騰 910C（A 段） | B19: 0.093 | C19: 0.08 | D19: 0.55 | E19: =D19/C19 -> 6.875 | F19: 0.05–0.15 | G19: 0.45–0.70 | H19: A 段推導 C6；NonNV 第 10 列

Sheet 推導
A1: 推導 — AMD Instinct MI455X（Helios，72 顆）相對 VR200 NVL72 的每 GW 產出比與持有成本比（C 段；方法同 A、B 段）
A2: 欄 D／E／F＝低端／基準／高端（產出列：悲觀→樂觀；持有列：成本低→成本高）。藍字＝輸入；黑字＝公式。標記沿用 Verified／Interested-party／Analogy／Assumed／Derived。VR200 分母取自 model/20261025_Tokenomics_v21.6.xlsx（基準成本欄 Interface!M）。證據編號 M01–M14 見『證據』頁。
A4: 編號 | B4: 物理量 | C4: 單位 | D4: 低端 | E4: 基準 | F4: 高端 | G4: 來源（證據編號／模型格） | H4: 標記 | I4: 算式或說明
A5: A. VR200 NVL72 分母（模型 v21.6；同層級、同 SLO）
A6: A1 | B6: VR200 每 GPU 計算用峰值（NVFP4 dense；模型服務精度） | C6: PF | D6: 35 | E6: 35 | F6: 35 | G6: Spec_Rack!F35（＝F23；F22 服務精度 NVFP4） | H6: Interested-party（NVIDIA 規格） | I6: AMD 自己的 1.15X 比較也用 35（M02）
A7: A2 | B7: VR200 機架配電設計功率（基準） | C7: kW | D7: 227 | E7: 227 | F7: 227 | G7: Spec_Rack!F9 | H7: Interested-party（Schneider 轉述 NVIDIA） | I7: Max-P 設計功率
A8: A3 | B8: 每機架 GPU 封裝數 | C8: 顆 | D8: 72 | E8: 72 | F8: 72 | G8: Spec_Rack!F6 | H8: Verified
A9: A4 | B9: VR200 每顆 GPU 所攤機架功率 | C9: kW | D9: =D7/D8 -> 3.1527778 | E9: =E7/E8 -> 3.1527778 | F9: =F7/F8 -> 3.1527778 | G9: Derived | H9: Derived | I9: 227÷72
A10: A5 | B10: VR200 每 kW 峰值算力（NVFP4） | C10: PF/kW | D10: =D6/D9 -> 11.101322 | E10: =E6/E9 -> 11.101322 | F10: =F6/F9 -> 11.101322 | G10: Derived | H10: Derived
A11: A6 | B11: VR200 每 GW 機架數 | C11: 架 | D11: 4052 | E11: 4052 | F11: 4052 | G11: Interface!M6 | H11: Derived（模型）
A12: A7 | B12: VR200 每 GW 機架 IT 功率（＝A6×A2） | C12: MW | D12: =D11*D7/1000 -> 919.804 | E12: =E11*E7/1000 -> 919.804 | F12: =F11*F7/1000 -> 919.804 | G12: Derived | H12: Derived | I12: 候選每 GW 架數＝此值 ÷ 候選機架功率（與 A、B 段相同）
A13: A8 | B13: VR200 機架價格（基準） | C13: $M | D13: 8.4 | E13: 8.4 | F13: 8.4 | G13: Spec_Rack!F12 | H13: Interested-party | I13: MS BOM 7.8 ×（1＋代工毛利 7.5%）
A14: A9 | B14: VR200 每 GW IT 設備資本支出（基準） | C14: $B | D14: 37.586352 | E14: 37.586352 | F14: 37.586352 | G14: Interface!M9 | H14: Derived（模型）
A15: A10 | B15: IT 資本支出 ÷（機架數×機架價）＝網路等加成 | C15: x | D15: =D14/(D11*D13/1000) -> 1.1042857 | E15: =E14/(E11*E13/1000) -> 1.1042857 | F15: =F14/(F11*F13/1000) -> 1.1042857 | G15: Derived | H15: Derived | I15: 約 1.10；候選沿用同一加成
A16: A11 | B16: VR200 每 GW 廠房資本支出（基準） | C16: $B | D16: 12.67 | E16: 12.67 | F16: 12.67 | G16: Interface!M10 | H16: Derived（模型）
A17: A12 | B17: VR200 每 GW 年持有成本 — 經濟口徑（基準） | C17: $B/年 | D17: 12.225471 | E17: 12.225471 | F17: 12.225471 | G17: Interface!M13 | H17: Derived（模型） | I17: 分母
A18: A13 | B18: VR200 每 GW 年持有成本 — 會計口徑（基準） | C18: $B/年 | D18: 8.9923042 | E18: 8.9923042 | F18: 8.9923042 | G18: Interface!M12 | H18: Derived（模型）
A19: A14 | B19: VR200 每 GW IT 折舊（基準） | C19: $B/年 | D19: 6.264392 | E19: 6.264392 | F19: 6.264392 | G19: Interface!M220 | H19: Derived（模型）
A20: A15 | B20: VR200 每 GW IT 維護（基準） | C20: $B/年 | D20: 0.59104579 | E20: 0.59104579 | F20: 0.59104579 | G20: Interface!M224 | H20: Derived（模型）
A21: A16 | B21: VR200 每 GW 財產稅與保險（基準） | C21: $B/年 | D21: 0.25128176 | E21: 0.25128176 | F21: 0.25128176 | G21: Interface!M227 | H21: Derived（模型）
A22: A17 | B22: 資金成本（經濟 − 會計） | C22: $B/年 | D22: =D17-D18 -> 3.2331668 | E22: =E17-E18 -> 3.2331668 | F22: =F17-F18 -> 3.2331668 | G22: Derived | H22: Derived
A23: A18 | B23: IT 設備占總資本支出比例 | C23: — | D23: =D14/(D14+D16) -> 0.74789256 | E23: =E14/(E14+E16) -> 0.74789256 | F23: =F14/(F14+F16) -> 0.74789256 | G23: Derived | H23: Derived
A24: A19 | B24: 持有成本中隨 IT 設備資本支出成比例的部分 | C24: $B/年 | D24: =D19+D20+(D21+D22)*D23 -> 9.461431 | E24: =E19+E20+(E21+E22)*E23 -> 9.461431 | F24: =F19+F20+(F21+F22)*F23 -> 9.461431 | G24: Derived | H24: Derived
A25: A20 | B25: 上述部分占 VR200 持有成本比例 s | C25: — | D25: =D24/D17 -> 0.77391136 | E25: =E24/E17 -> 0.77391136 | F25: =F24/F17 -> 0.77391136 | G25: Derived | H25: Derived | I25: 候選持有比 ＝ 1 − s×(1 − k)
A26: A21 | B26: VR200 每 GPU FP8 dense | C26: PF | D26: 17.5 | E26: 17.5 | F26: 17.5 | G26: Spec_Rack!F40 | H26: Interested-party | I26: E 節『FP8 對齊』用
A27: A22 | B27: VR200 GPU 功率（能量用） | C27: W | D27: 1800 | E27: 1800 | F27: 1800 | G27: Spec_Rack!F33 | H27: Interested-party
A28: A23 | B28: VR200 機架功率 ÷ 晶片功率總和 | C28: x | D28: =D7*1000/(D8*D27) -> 1.7515432 | E28: =E7*1000/(E8*E27) -> 1.7515432 | F28: =F7*1000/(F8*F27) -> 1.7515432 | G28: Derived | H28: Derived | I28: 1.75；Helios 旁證見 C3m
A29: A24 | B29: VR200 HBM 頻寬 | C29: TB/s | D29: 22 | E29: 22 | F29: 22 | G29: Spec_Rack!F26 | H29: Interested-party
A30: A25 | B30: VR200 ridge point（峰值 ÷ 頻寬） | C30: FLOP/byte | D30: =D6*1000/D29 -> 1590.9091 | E30: =E6*1000/E29 -> 1590.9091 | F30: =F6*1000/F29 -> 1590.9091 | G30: Spec_Rack!F36 | H30: Derived | I30: 1,591
A31: B. 還原既有世代：模型實際產出比 ÷ 『每 kW 峰值算力比』＝有效效率因子 f（同 A、B 段）
A32: B_H_pf | B32: Hopper H100 每 GPU 計算用峰值 | C32: PF | D32: 1.979 | E32: 1.979 | F32: 1.979 | G32: Spec_Rack!C35,C9,C6 | H32: Interested-party | I32: Hopper 為 FP8（無 FP4），其餘 NVFP4
A33: B_H_kw | B33: Hopper H100 機架配電功率（基準） | C33: kW | D33: 41 | E33: 41 | F33: 41 | G33: Spec_Rack!C35,C9,C6 | H33: Interested-party／Derived
A34: B_H_n | B34: Hopper H100 每機架 GPU | C34: 顆 | D34: 32 | E34: 32 | F34: 32 | G34: Spec_Rack!C35,C9,C6 | H34: Verified
A35: B_H_kwg | B35: Hopper H100 每顆所攤功率 | C35: kW | D35: =D33/D34 -> 1.28125 | E35: =E33/E34 -> 1.28125 | F35: =F33/F34 -> 1.28125 | G35: Derived | H35: Derived
A36: B_H_r | B36: Hopper H100 每 kW 峰值算力 ÷ VR200 | C36: — | D36: =(D32/D35)/D10 -> 0.13913527 | E36: =(E32/E35)/E10 -> 0.13913527 | F36: =(F32/F35)/F10 -> 0.13913527 | G36: Derived | H36: Derived
A37: B_G2_pf | B37: GB200 NVL72 每 GPU 計算用峰值 | C37: PF | D37: 10 | E37: 10 | F37: 10 | G37: Spec_Rack!D35,D9,D6 | H37: Interested-party | I37: Hopper 為 FP8（無 FP4），其餘 NVFP4
A38: B_G2_kw | B38: GB200 NVL72 機架配電功率（基準） | C38: kW | D38: 132 | E38: 132 | F38: 132 | G38: Spec_Rack!D35,D9,D6 | H38: Interested-party／Derived
A39: B_G2_n | B39: GB200 NVL72 每機架 GPU | C39: 顆 | D39: 72 | E39: 72 | F39: 72 | G39: Spec_Rack!D35,D9,D6 | H39: Verified
A40: B_G2_kwg | B40: GB200 NVL72 每顆所攤功率 | C40: kW | D40: =D38/D39 -> 1.8333333 | E40: =E38/E39 -> 1.8333333 | F40: =F38/F39 -> 1.8333333 | G40: Derived | H40: Derived
A41: B_G2_r | B41: GB200 NVL72 每 kW 峰值算力 ÷ VR200 | C41: — | D41: =(D37/D40)/D10 -> 0.49134199 | E41: =(E37/E40)/E10 -> 0.49134199 | F41: =(F37/F40)/F10 -> 0.49134199 | G41: Derived | H41: Derived
...

Sheet 證據
A1: 編號 | B1: 主張 | C1: 數值 | D1: 單位 | E1: 口徑 | F1: 出處網址 | G1: 來源等級 | H1: 立場 | I1: 標記 | J1: 取得方式與備註 | K1: 用於
A2: M01 | B2: AMD MI455X 資料表：MXFP4 峰值 40,265 TF、FP8／MXFP8 20,133 TF、FP16 5,033 TF；432 GB HBM4、23.3 TB/s；液冷 EAM；『designed to be deployed in the AMD Helios rackscale solution with 72 GPUs per rack』、每托盤 4 顆、18 托盤 | C2: 40,265；20,133；432；23.3；72 | D2: TF；TF；GB；TB/s；顆／架 | E2: 單顆峰值；r1：表有結構化稀疏欄，但 FP4／FP8 未列稀疏值，故 40,265 為 dense。ServeTheHome（『40 PFLOPS of dense FP4』）、Flopper（Dense 40,265、『vendor publishes no sparse figure』）與 Helios 簡介註 4（『MXFP4 dense Matrix datatype』）皆指 dense | F2: https://www.amd.com/content/dam/amd/en/documents/products/accelerators/instinct/amd-instinct-mi455x_brochure.pdf ；https://flopper.io/gpu/amd-instinct-mi455x ；https://www.servethehome.com/amd-instinct-mi455x-deep-dive-cdna-5-marks-the-next-era-of-instinct/ | G2: 1（AMD 資料表，2026-07-21）＋3 | H2: 支持 | I2: Interested-party（AMD 本人說） | J2: 全文（PDF 表格文字錯置，數值以 Flopper 引同一資料表與 STH 核對）。FP4:FP8＝2:1，與 VR200（35:17.5）同比例，所以兩種精度口徑的每 kW 峰值比相同（推導 C5、C6）。 | K2: C1、C2
A3: M02 | B3: AMD『Helios 5 reasons why』：MI455X『with a maximum TBP of 2500W in liquid-cooled EAM form factor』；FP4／FP8 峰值比 NVIDIA Vera Rubin GPU 高『1.15X』、FP16 高 1.26X；記憶體 1.5X | C3: 2,500；1.15 | D3: W；x | E3: 單顆最大 TBP（板卡功率上限）；峰值為理論值 | F3: https://www.amd.com/content/dam/amd/en/documents/products/rackscale-solutions/amd-helios-instinct-mi455X-5-reasons-why.pdf | G3: 1（AMD 官方文件） | H3: 支持 | I3: Interested-party（AMD 本人說） | J3: 全文。1.15X＝40.265÷35，表示 AMD 自己拿 VR200 的 35 PF（dense NVFP4，與 TK Spec_Rack!F23 同）作比較基準。旁證：SemiAnalysis X 貼文（2025-09-26，經 Wccftech 轉述）稱 MI450X TGP 由 2,300 W 調高至 2,500 W（傳聞，只作佐證）；ServeTheHome 2026-08-12『thought to be somewhere north of 2 kW』（記者推測）。r1 衝突註記：同一篇 STH 寫『AMD has not even disclosed the power consumption of MI455X』，與 AMD 2026-07 本文件的 2,500 W 衝突，以 AMD 原文為準。 | K3: C3、C3m
A4: M03 | B4: Helios 機架功率：The Register（2026-07-23）『under load can deliver between 225 and 245 kW』；36Kr（2026-07-24）『Official documentation states that the full rack power consumption ranges from 225kW to 245kW, depending on workloads』；StorageReview（2026-07-23）『The whole rack draws 225 to 245kW depending on workload』；ServeTheHome（2026-08-03）『According to AMD, the system requires a coolant flow rate of 385 liters per minute』以移除『up to 245kW of heat』；ServeTheHome（2026-08-12）『a Helios rack consuming upwards of 245 kW』；r1 補：Schneider Electric 與 AMD 共同 Helios 參考設計（2026-07-23 新聞稿；DCD、Fierce Network、Taiwan News）『rack densities of up to 246 kW』／『Ten 246 kW IT racks』（改建版） | C4: 225–245 | D4: kW／架 | E4: 整架、依負載；245 kW 同時是 AMD 所稱的散熱能力上限；是否含設施冷卻：不含（機架內液冷迴路；CDU 不在架內） | F4: https://www.theregister.com/systems/2026/07/23/amd-attacks-the-rack-with-helios-systems-that-rival-nvidias/5277246 ；https://eu.36kr.com/en/p/3908862210462850 ；https://www.storagereview.com/news/amd-mi455x-and-helios-432gb-hbm4-72-gpu-racks-and-a-real-answer-to-vera-rubin ；https://www.servethehome.com/amd-helios-architecture-deep-dive-amd-broadcom-hardware-combined/2/ ；https://www.datacenterdynamics.com/en/product-news/schneider-electric-and-amd-collaborate-to-enable-fast-resilient-and-efficient-amd-helios-rackscale-solution-cluster-deployment/ ；https://www.fierce-network.com/cloud/schneider-electric-amd-unveil-helios-ai-blueprint ；https://www.taiwannews.com.tw/en/news/6407255 | G4: 1（AMD＋Schneider 共同參考設計新聞稿）＋3（四家媒體轉述 AMD AAI 2026 資料） | H4: 支持 | I4: Interested-party（AMD 數字，經媒體轉述；36Kr 稱出自官方文件、STH 明寫 According to AMD；The Register 與 StorageReview 未逐字歸屬） | J4: 全文。AMD 官方 PDF（資料表、Helios 簡介、Supermicro 資料表）皆未列機架功率（已逐份讀過）。旁證：72×2.5 kW＝180 kW 晶片，245÷180＝1.36（TK GB300 為 1.35、VR200 Max-P 1.75）；heise 先前估『more than 200 kilowatts』（記者推測）。r1：246 kW 參考設計與 TK VR200 227 kW（Schneider 的 NVIDIA 參考設計 Max-P）同類，245 kW 基準證據強度由『中』上調為『中強』。ABI Research 的引述本代理未讀到。DCD 版本標『Sponsored／By Press Release』（2026-09-28 刊）。 | K4: C4
A5: M04 | B5: Helios 機架組成：72 顆 MI455X、18 顆 6th Gen EPYC、18 DPU；18 運算托盤＋6 交換托盤（4OU ORW 機架）；50 V 匯流排；整架 2.9 EF FP4（OCP MXFP4）、1.4 EF FP8、31 TB HBM4；性能註腳為『engineering projections by AMD Performance Labs in September 2025』 | C5: 72；2.9；1.4；31 | D5: 顆；EF；EF；TB | E5: 整架理論峰值（＝72 × 單顆） | F5: https://www.amd.com/content/dam/amd/en/documents/solutions/ai/amd-helios-bro.pdf ；https://www.supermicro.com/datasheet/datasheet_AMD_Helios.pdf ；https://www.datacenterdynamics.com/en/news/amd-officially-launches-helios-rackscale-system-with-mi455x-gpus-venice-epyc-cpus-and-pensando/ | G5: 1（AMD、Supermicro）＋3（DCD） | H5: 支持 | I5: Interested-party（AMD） | J5: 全文。2.9 EF ÷ 72＝40.3 PF，與 M01 自洽。DCD：2026-07-23 正式發表、全量生產、Q3 末出貨；Microsoft 為客戶。 | K5: C1、C4
A6: M05 | B6: MLPerf Inference v6.1（2026-09）每顆吞吐（Available、Closed；GPU Insights 依 MLCommons 官方條目換算每顆）：gpt-oss-120b Server／Offline——MI355X 14,155／15,227（8 顆，6.1-0003，AMD）、GB200 12,774／15,301（4 顆，6.1-0094）、GB300 16,118／16,635（72 顆，6.1-0025，CoreWeave）；Llama2-70b-99.9 Server——MI355X 13,068（6.1-0069）、GB200 12,648（72 顆，6.1-0023）、GB300 15,998（6.1-0088，Oracle）；DeepSeek-R1 Server——MI355X 4,698（512 顆，6.1-0026，Crusoe）、GB200 5,928（72 顆，6.1-0009）、GB300 8,517（8 顆，6.1-0088） | C6: 見數值欄 | D6: tok/s/GPU | E6: 同一基準、同一情境、同一精度要求（Closed）；MI355X 以 MXFP4 為主（DeepSeek-R1：MXFP4 專家＋BF16 MLA＋FP8 KV cache，AMD ROCm 部落格） | F6: https://gpuinsights.net/mlperf-inference-v6-1-per-gpu-results-2026/ ；https://rocm.blogs.amd.com/artificial-intelligence/mlperf-inf-v6.1/README.html ；https://mlcommons.org/wp-content/uploads/2026/09/Supplemental-MLCommons-MLPerf-Inference-v6.1.pdf | G6: 2（MLPerf 同儕審查結果；每顆換算為第三方） | H6: 支持 | I6: 第三方實測（MLCommons）；AMD 條目由 AMD 提交（本人提交，但經審查） | J6: 全文。核對：AMD ROCm 部落格系統總量 113,241／121,818（8 顆）＝每顆 14,155／15,227，與 GPU Insights 一致；Crusoe DeepSeek-R1 2,405,310÷512＝4,698；CoreWeave GB300 1.16M÷72≈16.1K；HPE B300 14,300／顆、HPE B300 DeepSeek-R1 8,500／顆（Supplemental）與 GB300 列同量級。MI455X 未提交（MI400 系列尚未出貨）。官方 MLCommons 總表（summary.xlsx）未直接讀取。 | K6: B 節 M 列、C7
A7: M06 | B7: MLPerf Inference v6.1 Vera Rubin（Preview 類別）：DeepSeek-R1 Server 每顆 16,427（Nebius VR200 NVL72，36 顆，6.1-0107）；Offline 16,435（72 顆，6.1-0106）；對 GB300 NVL72：Server 1.97×、Offline 1.74×、Interactive 2.57×（NVIDIA 自述『up to 2.5x』） | C7: 16,427 | D7: tok/s/GPU | E7: Preview（尚未正式供貨）；NVIDIA 的 TensorRT-LLM；是否使用 NVFP4 推論壓縮（50 PF 口徑）未說明 | F7: https://gpuinsights.net/mlperf-inference-v6-1-per-gpu-results-2026/ ；https://www.storagereview.com/news/mlperf-inference-v6-1-5-7x-per-accelerator-gains-a-512-gpu-run-and-vera-rubins-first-peer-reviewed-numbers | G7: 2（MLPerf Preview） | H7: 支持 | I7: 第三方實測（Preview） | J7: 全文。用於以 VR200 本身作錨點還原 MI355X 的效率因子（推導 B_V 列）。注意：TK 的 GB300 每顆只有 VR200 的 0.38（VR-eq 0.64 × 每 GW 顆數比），MLPerf 為 0.51，所以以 VR200 錨點得到的 f 比以 GB300 錨點高。 | K7: B 節 V 列
A8: M07 | B8: AMD 自述（AAI 2026）：MI455X 在 Kimi K2 Thinking 上『10 to 15% more tokens per second per GPU』、『up to 30% more tokens per dollar』（對 NVIDIA 公布數字，AMD 內部測試）；The Register：『AMD estimates Helios’ higher peak performance will give it a 30 percent performance per dollar lead』；AMD 實測 MAMF『MI455X achieved 20 petaFLOPS of FP4 performance — half of peak』 | C8: 1.10–1.15；1.30；20 | D8: x；x；PF | E8: AMD 內部測試，非獨立量測；tokens/$ 依『projected pricing』 | F8: https://www.storagereview.com/news/amd-mi455x-and-helios-432gb-hbm4-72-gpu-racks-and-a-real-answer-to-vera-rubin ；https://www.theregister.com/systems/2026/07/23/amd-attacks-the-rack-with-helios-systems-that-rival-nvidias/5277246 ；https://moorinsightsstrategy.com/field-notes/amd-advancing-ai-2026-helios-ships-venice-swings-and-the-software-moat-narrows/ | G8: 1（AMD 本人說，經媒體轉述） | H8: 支持（高端佐證） | I8: Interested-party（AMD） | J8: 全文。StorageReview 作者：『Those are AMD’s numbers against NVIDIA’s published numbers, not independent measurements.』Moorhead（分析師看法）：tokens/$ 說法『rests on projected pricing for systems neither vendor is selling at scale yet』，並指 AMD 的 FP4 為 MXFP4、NVIDIA 為 dense NVFP4。換算：每顆 +10–15% ⇒ f＝1.10–1.15 × 35 ÷ 40.265＝0.96–1.00（推導 C7c）；每顆 +10–15% 且每美元 +30% ⇒ AMD 假設的每架價格約為 VR200 的 0.85–0.88（推導 D9）。r1：比值 0.865 × TK $8.4M 作持有比基準（同口徑）。 | K8: C7 高端佐證、D2 基準
A9: M08 | B9: SemiAnalysis InferenceX（公開比較頁）：DeepSeek R1 8k/1k FP4，MI355X vs B200 每顆吞吐——87 tok/s/user 7,916 vs 7,986（『essentially tied』）、158：2,139 vs 2,053、230：781 vs 1,273（B200 多 63%）；DeepSeek V4 Pro（agentic traces，FP4）MI355X vs GB200 NVL72——119：21,980 vs 24,122、158：13,314 vs 9,790、197：5,217 vs 6,018 | C9: 見主張 | D9: tok/s/chip | E9: 單一來源；高互動區 AMD 明顯落後 | F9: https://inferencex.semianalysis.com/compare/deepseek-r1-b200-vs-mi355x ；https://inferencex.semianalysis.com/compare/deepseek-v4-gb200-vs-mi355x | G9: 2（第三方實測，SemiAnalysis） | H9: 支持（中互動）／衝突（高互動） | I9: 第三方；單一來源（SemiAnalysis），依本專案規則只作佐證、不單獨使用 | J9: 全文（公開頁；Run Date 未顯示）。每峰值換算：MI355X 10.07 PF vs B200 9 PF（HGX，dense FP4），同吞吐時 MI355X 每峰值效率約為 B200 的 0.89；高互動區約 0.55。與 MLPerf DeepSeek-R1 錨點的低端相容，只作佐證。 | K9: C7 佐證
A10: M09 | B10: Futurum（經 CNBC 2026-07-20）：Helios 每架『$5 million to $5.5 million』；同一來源 NVIDIA 第二代 Rubin 機架『$3.5 million to $4 million』；TrendForce：『Pricing, however, remains undisclosed』 | C10: 5.0–5.5；3.5–4.0 | D10: $M／架 | E10: 分析師估計；口徑未說明（是否含網路、是否為 AMD 開票額） | F10: https://www.itiger.com/news/1105556916 ；https://www.trendforce.com/news/2026/07/21/news-amds-first-rack-scale-ai-system-helios-challenges-nvidia-with-hbm4-memory-edge-but-reportedly-comes-at-a-higher-price/ ；https://wccftech.com/amd-is-reportedly-pricing-its-helios-rack-40-above-nvidias-second-gen-rubin-confident-that-customers-will-pay-the-premium/ ；https://www.digitalcitizen.life/amd-helios-ai-racks-could-cost-up-to-5-5-million-around-40-percent-more-than-nvidia-rubin/ | G10: 3（分析師，經媒體轉載；CNBC 原文未直接讀取） | H10: 支持（絕對值）／衝突（比值） | I10: 第三方估計 | J10: 轉載全文。r1：『約貴 40%』來源間不一致——Wccftech／Digital Citizen 為作者由兩個區間換算；iTiger（Deep News，2026-07-21）直接歸給 Futurum（『According to estimates from Futurum Group』…『approximately 40% higher than Nvidia’s Rubin』）。同源 Rubin $3.5–4M 遠低於 TK 的 VR200 $8.4M（MS BOM $7.8M、Bernstein $9.1M、KGI『超過 700 萬美元』），所以 Futurum 的價格口徑與 TK 不同（TK 口徑的 0.42–0.48）。r1（Project 決定）：絕對價 $5.25M 只作低端（口徑混用、下界）；同源比值 1.25 × TK $8.4M 作高端。 | K10: D2 低／高端、Q4
A11: M10 | B11: CLSA（2026-09-09，Investing.com 轉述）：『CLSA estimates the MI-455 GPU rack will have an average selling price of $5 million』、『implied pricing per GPU of $50,000』、『AMD will invoice approximately 70% of the rack’s ASP as revenue』 | C11: 5.0；50；70 | D11: $M／架；$K／顆；% | E11: 整架 ASP（含 ODM 與其他零組件；AMD 開票約 70%） | F11: https://www.investing.com/news/analyst-ratings/clsa-raises-amd-stock-price-target-to-710-on-mi455-gpu-outlook-93CH-4892806 | G11: 3（賣方研究，經媒體轉述） | H11: 支持 | I11: Interested-party（賣方研究，看多報告） | J11: 全文（轉述）。與 M09 同量級，兩者是否獨立不明（皆為 2026 下半年分析師估計）。r1：絕對價口徑與 TK 不同，只作 D1abs 對照。 | K11: D1abs
A12: M11 | B12: 低品質價格線索（不採用）：TechRadar（2025-10-19）OCP 展示的 Helios 參考設計『valued at roughly $3 million』（無出處）；X 貼文 MI455X『$45,000-$50,000』；Tech Insider 由 $5.25M ÷ 72 自行換算『roughly $73,000 per GPU』（記者推論，含 CPU、網路） | C12: 3；45–50；73 | D12: $M；$K；$K | E12: — | F12: https://www.techradar.com/pro/a-secret-amd-christmas-tree-nah-its-just-a-close-up-of-a-very-bright-usd3-million-72-gpu-mi450-helios-rack-monster-at-ocp-summit ；https://x.com/MikeLongTerm/status/2010026478843371996 ；https://tech-insider.org/amd-advancing-ai-2026/ | G12: 3（品質低） | H12: — | I12: Assumed | J12: 全文（X 貼文只讀搜尋摘要）。均無可追溯出處，只列出不進推導。 | K12: —
... A15: M14 | B15: 模型分母（VR200 NVL72，v21.6）：每 GPU 35 PF（NVFP4 dense；FP8 dense 17.5；高情境推論口徑 50）、HBM 22 TB/s、機架 227 kW、72 顆、GPU 1,800 W、機架價 $8.4M；每 GW 4,052 架、IT 資本支出 $37.59B、經濟持有成本 $12.23B／年；Hopper／GB200／GB300 VR-eq 三層平均 0.1036／0.5105／0.6409；GB200／GB300 HBM 8 TB/s；NonNV 現值 AMD 0.5/0.7/1.0、0.8/0.9/1.0 | C15: 見推導頁 A、B 節 | D15: — | E15: 每 GW＝IT 關鍵電力 | F15: model/20261025_Tokenomics_v21.6.xlsx（Spec_Rack、Interface、NonNV） | G15: 1（內部模型） | H15: — | I15: Derived（模型；VR200 規格本身 Interested-party） | J15: openpyxl data_only 逐格讀取；數值與 B 段用的 v21.5 相同。 | K15: A、B、建議值

Sheet 待判斷
A1: 編號 | B1: 題目 | C1: 預設（本提案採用） | D1: 替代方案 | E1: 影響
A2: Q1 | B2: 精度口徑：MI455X 有原生 FP4（MXFP4 40.265 PF）且 FP4:FP8＝2:1，與 VR200（NVFP4 35／FP8 17.5）同比例。兩種口徑的每 kW 峰值比相同（1.066），本段不存在 B 段 TPU／Trn3 的精度落差。是否接受以『最高原生精度』為主表？ | C2: 接受：主表＝(a) 最高原生精度（MXFP4 對 NVFP4）；(b) FP8 對齊的產出比數值與 (a) 相同（推導 E 節）。MXFP4（32 元素區塊、E8M0 尺度）與 NVFP4（16 元素、E4M3 尺度）精度不完全等價，差異已含在由 MLPerf（MI355X 以 MXFP4 達到 Closed 精度要求）還原的 f 內。 | D2: (a) 若 Project 對 TPU／Trn3 改採 FP8 對齊，AMD 列不受影響；(b) 若 VR200 改用高情境 50 PF（Spec_Rack!F24），MI455X 每 kW 峰值比降為 0.75，產出比約 ×0.7。 | E2: 精度口徑不改變本列結論；與 TPU／Trn3 的並排比較會因 Q1（B 段）的決定而改變相對位置。
A3: Q2 | B3: 機架功率：AMD 數字（經媒體）為『依負載 225–245 kW』，245 kW 同時是 AMD 所稱散熱上限。TK 的 VR200 227 kW 為配電設計功率（Max-P）。本表以 245 kW 為同口徑基準，225 kW 只作高端產出。是否接受？ | C3: 接受：低／基準／高端產出＝245／245／225 kW（每顆所攤 3.40／3.40／3.13 kW）。 | D3: (a) 基準改 235 kW（區間中點）：產出比 +4%；(b) 若出貨版功率高於 245（無證據），每 +10% 產出比 −9%。 | E3: 產出比基準 0.81（245）vs 0.84（235）。
A4: Q3 | B4: 效率因子 f（MLPerf 優先）：MI455X 未提交 MLPerf，以 MI355X 在 v6.1 的 DeepSeek-R1 Server 每顆吞吐、按每峰值換算，對 TK 的 GB200／GB300／VR200 三個錨點還原 f（0.82／0.74／0.99，平均 0.85），再乘 MI355X→MI455X 的『算力÷頻寬』轉換係數 t（以 TK GB200→GB300 的 f 對 ridge 彈性類比，約 0.89）。低＝GB300 錨點×t、基準＝三錨點平均×t、高＝VR200 錨點不打折（AMD 自述 Kimi K2 換算 0.96–1.00 佐證；Interested-party）。是否接受？ | C4: 接受：f＝0.656／0.757／0.994（Derived from MLPerf＋Analogy；標 Assumed）。gpt-oss-120b、Llama2-70b 的還原值（1.03–1.22）屬較小模型、較不像 TK 前沿負載，只放敏感度（平均×t＝0.92）。SemiAnalysis InferenceX 只作佐證。 | D4: (a) 不乘 t（假設 MI455X 保有 MI355X 每峰值效率）：基準 0.85、產出比 0.91；(b) 用全部九個還原值平均×t（0.92）：產出比 0.98；(c) 低端再扣首代機架級 UALoE／CDNA 5 軟體風險 ×0.8（比照 A 段 Maia 低端思路）：0.52、產出比 0.56；(d) r1：只用 GB200、GB300 兩錨點平均 × t（排除已知偏高的 VR200 Preview 錨點）：f≈0.692、產出比約 0.74（推導 F8）。注意：MI355X DeepSeek-R1 為 512 顆多節點（Crusoe），GB300 為 8 顆，規模不同。 | E4: 產出比基準 0.81；區間 0.56（c）–1.15；(d) 0.74。
A5: Q4 | B5: Helios 每架價格（r1：Project 決定改為同口徑）：TK VR200 $8.4M 是 Spec_Rack!F12 買方取得價（MS BOM 7.8 × 1.075）；Futurum 同源 Rubin 只 $3.5–4M（TK 口徑的 0.42–0.48），所以分析師 Helios 絕對價 ÷ TK $8.4M 是不同口徑相除。 | C5: 低＝Futurum 絕對價 $5.25M（口徑混用、下界）；基準＝AMD 自述隱含比 0.865 × $8.4M ≈ $7.27M；高＝Futurum 同源比值 1.25 × $8.4M ＝ $10.5M → 持有比 0.67／0.85／1.12（推導 D6）。 | D5: (a) Futurum 同源比值全區間 1.25／1.40／1.57 × $8.4M：持有比 1.12／1.23／1.35（推導 D7）；(b) r0 口徑（絕對價 $5.0／5.25／5.5M ÷ TK 價）：0.65／0.67／0.70（推導 D11，口徑混用）；(c) AMD 自述隱含比全區間 0.846–0.885：0.83–0.86（推導 D10）。 | E5: 持有比基準 0.85；每 token 成本比基準約 1.05（r0 為 0.84）。
A6: Q5 | B6: 是否寫進 TK 下一版 NonNV 第 5 列（AMD）？ | C6: 寫進：產出比與持有比都換（持有比用同口徑值）——產出比 0.70／0.80／1.15、持有比 0.67／0.85／1.12，標 Assumed，說明欄引本資料夾，移除『持有比為慣例值、未推導』字樣。 | D6: 保守替代：只換產出比（證據較強：官方功率＋MLPerf），持有比維持 0.8／0.9／1.0 待更好價格證據；或都不換，只在說明欄附本表區間。 | E6: 每 token 成本比 1.29 → 約 1.06（全換，建議輸入值）或約 1.13（只換產出比）。下游（OpenAI、Anthropic 模型的 AMD 份額）每 token 成本略降。
