Workbook

Sheet 證據表
A1: 編號 | B1: 項目 | C1: 來源（讀取日 2026-10-24） | D1: 日期 | E1: 原文摘錄（引號內為工具回傳原文；其餘為摘述） | F1: 數值 | G1: 單位 | H1: 口徑 | I1: 標記 | J1: 對 2026 GW／比值的意義
A2: G01 | B2: OpenAI 2025 年底算力（及 2023、2024） | C2: DCD 2026-01-21 轉述 Friar 的 2026-01 weekend update；Siliconangle、eWeek 同源 | D2: 2026-01-19 | E2: "AI firm OpenAI fielded some 1.9GW of compute by the end of 2025, the company's chief financial officer, Sarah Friar, has said."（0.2→0.6→1.9 GW） | F2: 1.9 | G2: GW | H2: 年底時點；IT 或設施：原文未說；上線或簽約：'fielded' 未明 | I2: Interested-party：OpenAI CFO，募資與 IPO 前有誘因展示算力 | J2: 基點 E0。與官方端點 0.6→1.9 一致（任務已知）
A3: G02 | B3: Epoch 把 G01 換成 H100e | C3: Epoch AI：AI chip users explorer、Gradient Update『frontier labs don't use most AI compute』 | D3: 2026-09-09 更新頁 | E3: OpenAI 2025-12：1,743,000 H100e（90% CI 1,251,000–2,185,000）；假設 OpenAI 報的是 IT 電力，若為設施電力則 H100e 最多再小約 30% | F3: 1743000 | G3: H100e | H3: IT（Epoch 假設）；年底；使用量非持有量 | I3: Analogy＋同源：與 G01 同一個電力數字，不另計一筆 | J3: GPU 換算交叉檢查（見『GPU換算』）
A4: G03 | B4: Altman：2025 年底前上線 well over 1 million GPUs | C4: 引自 chat 端前一資料夾 docs/evidence/20261024_Azure實付價_A段（分支 claude/evidence-azure-price）；本段未重讀原文 | D4: 2025-07-20 | E4: （沿用前段，本段未重查） | F4: 1000000 | G4: GPU 顆 | H4: 年底預期；預告性質 | I4: Interested-party：OpenAI CEO | J4: 與 1.9 GW × TK 每 GW 顆數相容（見『GPU換算』）
A5: G04 | B5: OpenAI 官方：Stargate 已超過 10GW 目標，過去 90 天『added』>3GW | C5: OpenAI 官方部落格『Building the compute infrastructure for the intelligence age』；Bloomberg Law 2026-04-30；DCD 2026-05-01 | D5: 2026-04-29 | E5: "more than 3GW added in the last 90 days alone"、"We are ahead of schedule."（OpenAI，經工具摘述）；Bloomberg："has signed contracts for 10 gigawatts of artificial intelligence computing capacity"；DCD：『believes the 10GW is likely contracted rather than live』 | F5: 10 | G5: GW | H5: 美國；簽約／確保，非上線（DCD 判斷；官方文未區分） | I5: Interested-party：OpenAI，募資與敘事誘因 | J5: 不是上線量。只證明合約面大幅超前，不能用來估 2026 平均上線 GW
A6: G05 | B6: OpenAI 致投資人備忘錄（Bloomberg 2026-04-09）：已識別 >8GW；2027 年容量「low double-digit」GW；估 Anthropic 2026 年底 3–4 GW | C6: Tae Kim（Key Context）2026-04-09 轉述；Bloomberg 2026-04-09〈OpenAI Tells Investors It Has Computing Advantage Over Anthropic〉；Epoch Gradient Update 2026-05-20 引 Bloomberg（r1 更正：2027 low double-digit 出自此備忘錄，與原 G14 同源，合併為一筆） | D6: 2026-04-09 | E6: OpenAI：2025 1.9 GW；Anthropic（OpenAI 估）2025 1.4 GW、2026 年底 3–4 GW、2027 年底 7–8 GW；OpenAI 自己 2026 年底：『Not stated』 | F6: 3.5 | G6: GW（Anthropic 估計中點，非 OpenAI） | H6: OpenAI 對對手的估計；口徑未明 | I6: Interested-party：OpenAI 向投資人（備忘錄）；報導（二手） | J6: 3.5 是 OpenAI 對 Anthropic 的估計中點，不是 OpenAI 的下界；對 OpenAI 只是 1.84 倍成長。OpenAI 自己 2026 年底：未載
A7: G06 | B7: Epoch：Stargate 各站上線量 | C7: Epoch AI『OpenAI Stargate: where the US sites stand』（Stewart & Cottier） | D7: 2026-04-17 | E7: "The most advanced—in Abilene, Texas—is already operating at an estimated capacity of 0.3 gigawatts (GW)."；"with an estimated four of the eight buildings already operational."；其餘站上線 0（五站預計 2028 Q4 完成，Lordstown 完工日不明） | F7: 0.3 | G7: GW（Abilene） | H7: 設施電力（Epoch 設施≈1.3×IT）；上線；僅新建 Stargate 站，不含 Azure／CoreWeave／AWS 既有容量；衛星影像推估 | I7: Analogy（第三方衛星推估；原估 0.6 GW，後依 Oracle 貼文隱含約 200MW 下修） | J7: Abilene 2026-04 約 0.3 GW，完工預計 2026 Q4 到 1.2 GW；其餘站 2028 年底前後才完成
A8: G07 | B8: Epoch 資料中心 hub：Abilene 目前算力與預測 | C8: Epoch AI frontier data centers／directory 頁（r1：目錄頁 Updated Jul. 17, 2026，非 10 月；本段原誤記 10-20） | D8: 約 2026-07 | E8: OpenAI Stargate Abilene：Current compute 509k H100e；Epoch 自給 421 MW IT；Epoch 預測 2026-11-01：1,019k H100e／843 MW（經獨立核對提供，本段未重讀） | F8: 509000 | G8: H100e | H8: 上線；以 Epoch H100e 計 | I8: Analogy（衛星＋模型） | J8: Abilene 約 2026-07 為 0.42 GW IT，約完工量一半（見『GPU換算』）
A9: G08 | B9: Epoch：新站交付時程 | C9: 同 G06 | D9: 2026-04-17 | E9: Shackelford 首棟預計 2026 年底交付；Milam 首棟預計 10 月前（監管文件）；Doña Ana、Port Washington、Saline 皆預計 2028 Q4；『Delivery dates refer to when a building is handed to the tenant』 | G9: — | H9: 交付日≠上線日 | I9: Analogy | J9: 2026 年新增上線幾乎只有 Abilene 補完＋既有雲端，新站貢獻在 2026 年底之後
A10: G09 | B10: Oracle FY2026（至 2026-05）法說：交付容量 | C10: Oracle Q4 FY26 earnings call 2026-06-10，經 erp.today 2026-06-11 轉述；未讀逐字稿 | D10: 2026-06-10 | E10: "delivered more than 1.2 gigawatts of capacity to customers in FY2026"；Q1 FY27 交付預計 approach 1 GW，約等於前四季合計 | F10: 1.2 | G10: GW（全部客戶） | H10: 口徑未明；交付；全客戶，OpenAI 占比未揭露 | I10: 報導（二手轉述公司法說）；OpenAI 占比：不可分離 | J10: 上界背景：Oracle 單季將交付近 1 GW（全客戶）。無法拆出 OpenAI
A11: G10 | B11: CoreWeave 2026 Q2：作用中電力 | C11: CoreWeave 8-K 新聞稿（SEC）2026-08-11；MarketBeat 2026-08-11 法說摘要 | D11: 2026-08-11 | E11: active power 約 1.5 GW（2026-06-30，Q2 增近 500MW，6 月單月>300MW）；年底指引>1.85 GW（原>1.7）；contracted 3.7 GW。新聞稿全文無 OpenAI 字樣 | F11: 1.5 | G11: GW（全客戶） | H11: active power（公司未定義 IT 或設施）；全客戶 | I11: Verified（公司申報）；OpenAI 占比：不可分離 | J11: 2025 年底約 0.85 GW（前段 Q4 數『more than 850 MW』）→2026-06 底 1.5 GW。OpenAI 合約金額 224 億（9a）只占 backlog 約 1/5，無法拆 GW
A12: G11 | B12: Microsoft FY26 Q4 法說 | C12: MarketBeat 法說摘要 2026-07-29 | D12: 2026-07-29 | E12: 『Microsoft added another gigawatt of capacity during the quarter』；『on track to roughly double its overall capacity in two years』；"continued to exceed available capacity"（Hood） | F12: 1 | G12: GW／季（全公司） | H12: 全公司；與 OpenAI 無關的整體 | I12: 報導（二手摘述公司法說）；OpenAI 占比：不可分離 | J12: 顯示雲端端容量仍緊，OpenAI 無法拆出
A13: G12 | B13: Friar：2026 年算力仍不足 | C13: All-In podcast，經 BigGo 2026-06-02 轉述；播出日未明 | D13: 2026-06-02（報導日） | E13: "In 26 we still won't have enough compute," she said.（另：每 GW 約 500 億美元、約 3 年建成；Michigan 站緩解不早於 2027 末／2028 初） | G13: — | H13: 定性 | I13: Interested-party：OpenAI CFO | J13: 方向：2026 全年供不應求，不是上線過剩
A14: G13 | B14: Brockman 法庭證詞：2026 年算力支出 | C14: Bloomberg 經 Let's Data Science 2026-05-05（Musk 訴 OpenAI 審理） | D14: 2026-05-05 | E14: Brockman：OpenAI 計畫 2026 年花 $50 billion 於算力（"tens of billions"） | F14: 50 | G14: 十億美元 | H14: 2026 全年計畫支出；含哪些算力：未明 | I14: Interested-party（證詞） | J14: 交叉檢查：支出倍數 50÷20.4（2025）＝2.45 倍（見『換算』）
A15: G15 | B15: AMD：MI450／Helios 對 OpenAI 的 1GW 首批 | C15: DCD 2025-10-06；AMD 2026 Q2 法說逐字稿（platformaeronaut） | D15: 2026 Q2 法說（約 2026-08） | E15: "We've said Q3 is the very beginning of the ramp. Q4 is a step up and then Q1 will be a further step up."；"Helios is now in production with initial shipments on track to begin later this quarter."（Su；未點名 OpenAI 的時程） | F15: 1 | G15: GW（首批目標，2026 下半年起） | H15: 目標；ramp 在 Q3 起、Q4 加速、2027 Q1 再加速 | I15: Interested-party：AMD | J15: 佐證 2026 年新增集中在下半年（後重）
A16: G16 | B16: Nvidia–OpenAI：首個 1GW（Vera Rubin）目標 2026 下半年 | C16: OpenAI／NVIDIA 公告 2025-09-24 | D16: 2025-09-24 | E16: "The first phase is targeted to come online in the second half of 2026 using NVIDIA's Vera Rubin platform." | F16: 1 | G16: GW（目標） | H16: 意向書；目標 | I16: Interested-party：Nvidia、OpenAI | J16: 同上：下半年起；本段未找到 2026 年實際交付量
A17: G17 | B17: Cerebras：OpenAI 750MW | C17: Cerebras Q1 2026 法說，經 Converge Digest 2026-06-23 | D17: 2026-06-23（報導日） | E17: OpenAI-related cloud revenue is "back-end loaded in 2026 as new data center capacity comes online" | F17: 0.75 | G17: GW（計畫，數年） | H17: 計畫；非上線 | I17: Interested-party：Cerebras | J17: 小量且後重
A18: G18 | B18: Jensen Huang：GPT-6 Astra 以 ~100K+ GB NVL72 機櫃（報導解讀為約 10 萬顆 GPU）訓練，另有計畫上線 40 萬顆 GPU | C18: PC Gamer 2026-09-07 轉述 Huang 的 X 貼文與 Brockman 訪談 | D18: 2026-09-07 | E18: 報導：計畫 400,000 GPUs online，無日期；單位混用（機櫃 vs GPU） | F18: 400000 | G18: GPU 顆 | H18: 計畫；時點未明 | I18: Interested-party：Nvidia | J18: 若 GB200 級：400k÷501,768＝約 0.8 GW（見『GPU換算』）；無時程不入區間
A19: G19 | B19: Oracle Project Jupiter（新墨西哥，2.45GW）不可抗力通知 | C19: Bloomberg 經 BNN／Insurance Journal／Pebblous 2026-09-24/25 | D19: 2026-09-24 | E19: 目標上線 2028；管線延後約半年至 2027-02；Oracle 發不可抗力通知 | F19: 2.45 | G19: GW（站） | H19: 計畫；2028 | I19: Verified（報導） | J19: 新站延遲風險：2026 內不貢獻上線量
A20: T01 | B20: API 吞吐量：每分鐘 6B token（2025-10） | C20: Let's Money 2025-10-20（2026-09-12 更新）；Exponential View 2026-04-06 貼文 | D20: 2025-10 | E20: 『cerca de 6 bilhões de tokens por minuto』；EV：『about 6 billion tokens per minute in October 2025』 | F20: 6000000000 | G20: token／分鐘 | H20: API；當期 | I20: Interested-party：OpenAI（DevDay 2025 公告） | J20: 基準
A21: T02 | B21: API 吞吐量：每分鐘 >15B token（2026 Q1 末） | C21: Exponential View（Substack）2026-04-06：『15 billion tokens per minute, a 2.5x increase in five months』；Creeta 2026-06-22：『>15B tokens per minute, quarter-end Q1 2026』；Mobile World Live 2026-06-03：『OpenAI disclosed … the API token figure in April』 | D21: 2026-04（Q1 末時點） | E21: "API usage exceeds 15 billion tokens per minute" | F21: 15000000000 | G21: token／分鐘 | H21: API；當期；2026 Q1 末 | I21: Interested-party：OpenAI 揭露 | J21: 與現用 SRC_DEM_011（150 億／分，2026-03）為同一個數字，沒有更新
A22: T03 | B22: Altman：OpenAI 內部 token 用量最高的人月用約 1,000 億 token | C22: Axios 經 Let's Data Science；TechNews 2026-06-04 | D22: 2026-06（活動日未明） | E22: "The token leader at OpenAI uses about 100 billion tokens a month."（Altman） | F22: 100000000000 | G22: token／月（單一使用者） | H22: 單一最高用戶 | I22: Interested-party：Altman | J22: 非總量，不可當 API 總量更新
A23: T04 | B23: Codex 占 OpenAI 內部輸出 token 99.8% | C23: Axios 2026-06-25；Bloomberg 2026-07-31；Crypto Briefing | D23: 2026-06-25 | E23: 『Codex generates 99.8% of its internal output tokens』（內部使用，OpenAI 論文） | G23: — | H23: 內部使用，非對外 API | I23: Interested-party | J23: 與外部 API 總量無法分離
A24: T05 | B24: ChatGPT 每日訊息數 | C24: OpenAI 2025-07 公告（經多家轉述）；superlines.io 稱 2.5B／日仍為最新揭露 | D24: 2025-07 | E24: 2.5+ billion messages per day（美國 330M+）；2026 新值：已搜尋，未找到；現用 3.6B／日：未找到出處 | F24: 2500000000 | G24: 則／日 | H24: 全球；當期；2025-07 | I24: Interested-party：OpenAI | J24: 3.6B 未能核實；最新可核實官方值仍是 2025-07 的 2.5B
A25: U01 | B25: ChatGPT 每週活躍用戶 | C25: TechCrunch 2026-02-27（900M WAU、5,000 萬付費）；Crypto Briefing 2026-09-29（OpenAI 2026-09-08 確認 >1B WAU，以 8 月中快照）；Bloomberg Law 2026-07-31（>1B 活躍用戶、>200 萬企業） | D25: 2026-02-27／2026-09-08 | E25: 900 million WAU（2026-02）；"officially crossed 1 billion weekly active users"（2026-09，Crypto Briefing 摘述） | F25: 1000000000 | G25: 人／週 | H25: 全球；當期 | I25: Interested-party：OpenAI | J25: 需求端佐證：Q1→Q3 用戶 +10% 以上。superlines 稱 DevDay 1.2B，只見單一二手，未採用
A26: R01 | B26: OpenAI 2026 Q2 營收（報導） | C26: WSJ 經 Crypto Briefing 2026-08-18；FutureSearch | D26: 2026-08-18 | E26: "OpenAI generated $6.7 billion in revenue during the second quarter of 2026"；Q1 $5.7B（WSJ，經二手轉述；people familiar，未經公司確認） | F26: 6.7 | G26: 十億美元（季度） | H26: 季度營收；是否 GAAP：未明 | I26: 報導（WSJ，二手轉述，未經公司確認） | J26: 年化 26.8 十億，與你用的 Q2 年化 26.3 差 2%；run-rate 另報：8 月 >40、9 月底約 50（Bloomberg、FT 經 FutureSearch，二手）
A27: G20 | B27: 第三方預測：OpenAI 與 Anthropic 各 5–6 GW 到今年底 | C27: Epoch Gradient Update 2026-05-20 引 X 帳號（經獨立核對提供，本段未重讀） | D27: 2026-05-20 | E27: OpenAI、Anthropic 各 5–6 GW 到 2026 年底 | F27: 5.5 | G27: GW（年底） | H27: 預測；口徑未明 | I27: Analogy（低品質，單一社群帳號） | J27: 約等於高情境 5.7
A28: G21 | B28: Abilene 擴建（>1.2 GW）於 2026-03 放棄 | C28: 報導（二手；Epoch 2026-04-17 亦述『OpenAI pulling out of the Abilene expansion』） | D28: 2026-03 | E28: Plans can change even after construction begins, as shown by OpenAI pulling out of the Abilene expansion. | F28: 1.2 | G28: GW（站上限） | H28: 計畫 | I28: 報導（二手） | J28: Abilene 上限約 1.2 GW
A29: G22 | B29: AWS 擴約 2 GW Trainium | C29: DCD 2026-05-01：2026 年 2 月底協議，AWS 合約增 $100bn | D29: 2026-02 | E29: an agreement to use 2GW of AWS Trainium chips, expanding the AWS cloud contract by $100bn | F29: 2 | G29: GW（簽約） | H29: 簽約，非上線；無上線年 | I29: 報導（二手） | J29: 2026 上線量不明
A30: G23 | B30: Friar：每 GW 約 100 億美元年營收 | C30: 經獨立核對提供（本段未重讀原文）；BigGo 2026-06-02 摘述亦有 About $10 billion in annual revenue expected per GW | D30: 2026 | E30: 每 GW 約 $10B 年營收 | F30: 10 | G30: 十億美元／GW·年 | H30: 預期，非實績 | I30: Interested-party：OpenAI CFO | J30: 直接對照比值法：100 億 ÷ 9.8 ≈ 1.02
A31: G24 | B31: Brockman：2026 年算力支出 triple 2025 | C31: 經獨立核對提供（Bloomberg 證詞報導） | D31: 2026-05-05 | E31: triple what it spent in 2025（隱含 2025 約 167 億） | F31: 16.7 | G31: 十億美元（隱含） | H31: 隱含值 | I31: Interested-party（證詞） | J31: 與 Epoch 160 億、chat 端 204 億並列；支出倍數 3.0
A32: G25 | B32: Nvidia 10 GW LOI 不照原案進行 | C32: 經獨立核對提供（二手，待查） | D32: 2026 | E32: （本段未找到原文） | G32: — | H32: 待查 | I32: 報導（二手，待查） | J32: 可能降低 2026 下半年 Nvidia 新增
A33: G26 | B33: lecompute.fr 推估：2026 年中上線 <2 GW | C33: 經獨立核對提供（衍生推估、低品質） | D33: 2026 | E33: 2026 年中上線 <2 GW | F33: 2 | G33: GW（上限） | H33: 推估；口徑未明 | I33: Analogy（衍生、低品質） | J33: 低於本段 Q2 區間 2.3–3.8；若屬實 Q2 口徑比值上升（門檻 2.17）。不入區間，列為反向風險
A34: G27 | B34: Broadcom 自研晶片 2026 年底商用 | C34: 經獨立核對提供 | D34: 2026 | E34: 2026 年底開始商用 | G34: — | H34: 時程 | I34: Interested-party：Broadcom | J34: 更偏 2026 年底後重

Sheet 未找到與不可分離
A1: 編號 | B1: 類別 | C1: 項目 | D1: 說明
A2: N01 | B2: 已搜尋，未找到 | C2: OpenAI 自己公布的任何 2026 年『上線』GW（Q1 末、Q2 末、最新） | D2: OpenAI 只公布 2025 年底 1.9 GW 與『簽約 10GW』（2026-04）；沒有 2026 上線量
A3: N02 | B3: 已搜尋，未找到 | C3: OpenAI 2026 年底上線 GW 官方目標 | D3: 備忘錄（G05）明寫對自己 2026 年底『Not stated』；只有『已識別 >8GW』『2027 low double-digit』『2030 30GW』
A4: N03 | B4: 已搜尋，未找到 | C4: OpenAI 2026 年任一時點的 GPU 顆數或 H100e（官方） | D4: Epoch 只有 2025-12 的 1.743M；AI chip users 資料在本環境讀不到 CSV（epoch.ai 被代理封鎖，只能用頁面摘述）
A5: N04 | B5: 已搜尋，未找到 | C5: 2026 Q2 或之後的 API 每分鐘 token 新數字 | D5: 最新仍是 2026 Q1 末 >15B／分鐘（T02）
A6: N05 | B6: 已搜尋，未找到 | C6: ChatGPT 每日訊息數 2026 新值；3.6B／日出處 | D6: 最新可核實為 2025-07 的 2.5B／日
A7: N06 | B7: 已搜尋，未找到 | C7: Microsoft、Oracle、CoreWeave、AWS、Google Cloud 對 OpenAI 的 2026 交付 GW | D7: 法說與新聞稿皆無 OpenAI 專屬 GW；CoreWeave 8-K 全文無 OpenAI 字樣
A8: N07 | B8: 已搜尋，未找到 | C8: Epoch 對 OpenAI 全體（非單站）2026 年的算力估計 | D8: Epoch 發表的只有 2025-12 全體與 Abilene 單站
A9: N08 | B9: 已搜尋，未找到 | C9: The Information、FT、Reuters 付費牆原文（2026 年底 GW 預測） | D9: 本環境讀不到原文；未見轉述出現 2026 年底 GW 數字
A10: N09 | B10: 不存在／不可分離 | C10: Stargate『10GW』 | D10: 是簽約／確保量，不是上線量（DCD 推定）
A11: N10 | B11: 不存在／不可分離 | C11: Oracle FY26 交付 >1.2 GW、CoreWeave active 1.5 GW、Microsoft 單季 +1 GW | D11: 皆為全客戶，OpenAI 占比未揭露，不能換成 OpenAI 的 GW
A12: N11 | B12: 不存在／不可分離 | C12: Codex 99.8% 內部輸出 token | D12: 內部使用，與對外 API 總量無法分離
A13: N12 | B13: 本環境限制 | C13: openai.com 部分頁、epoch.ai CSV、sec.gov 其他文件 | D13: 部分頁面只能取到摘述；逐字引用限於引號內

Sheet 換算
A1: 2026 年平均上線 GW 與 Q2 末時點 GW（Derived；藍字為輸入，其餘為公式）
A3: 輸入 | B3: 值 | C3: 單位 | D3: 標記 | E3: 依據
A4: E0：2025 年底上線 GW | B4: 1.9 | C4: GW | D4: Interested-party | E4: G01 Friar
A5: 2027 年容量目標（low double-digit 中點） | B5: 11 | C5: GW | D5: Assumed（區間 10–12） | E5: G05：Bloomberg 2026-04-09 備忘錄（Epoch 引）；中點為假設
A6: Friar 歷史年成長倍數 | B6: 3 | C6: 倍／年 | D6: Interested-party | E6: G01：0.2→0.6→1.9，約 3 倍／年
A7: 低情境 2026 年底：Anthropic 估計中點 | B7: =(3+4)/2 -> 3.5 | C7: GW | D7: Assumed（情境） | E7: G05：OpenAI 對 Anthropic 的估計，非 OpenAI 下界；對 OpenAI 只是 1.84 倍成長
A9: 形狀：2026 年新增量在各季末的累計占比（Assumed）
A10: 形狀 | B10: Q1 末 | C10: Q2 末 | D10: Q3 末 | E10: Q4 末 | F10: 依據
A11: 線性 | B11: 0.25 | C11: 0.5 | D11: 0.75 | E11: 1 | F11: 對照用
A12: 後重 | B12: 0.1 | C12: 0.25 | D12: 0.55 | E12: 1 | F12: 權重 0.10／0.25／0.55 為假設；方向依據 G08/G15/G16/G17
A14: 情境 | B14: 2026 年底 GW | C14: 形狀列 | D14: 新增 GW | E14: Q1 末 | F14: Q2 末 | G14: Q3 末 | H14: Q4 末 | I14: 2026 平均 GW（梯形） | J14: Q2 末 GW | K14: Q2 季平均 GW
A15: 情境（Assumed）低＋線性 | B15: =$B$7 -> 3.5 | C15: 11 | D15: =B15-$B$4 -> 1.6 | E15: =$B$4+D15*INDEX($B$11:$E$12,C15-10,1) -> 2.3 | F15: =$B$4+D15*INDEX($B$11:$E$12,C15-10,2) -> 2.7 | G15: =$B$4+D15*INDEX($B$11:$E$12,C15-10,3) -> 3.1 | H15: =$B$4+D15*INDEX($B$11:$E$12,C15-10,4) -> 3.5 | I15: =($B$4/2+E15+F15+G15+H15/2)/4 -> 2.7 | J15: =F15 -> 2.7 | K15: =(E15+F15)/2 -> 2.5
A16: 情境（Assumed）低＋後重 | B16: =$B$7 -> 3.5 | C16: 12 | D16: =B16-$B$4 -> 1.6 | E16: =$B$4+D16*INDEX($B$11:$E$12,C16-10,1) -> 2.06 | F16: =$B$4+D16*INDEX($B$11:$E$12,C16-10,2) -> 2.3 | G16: =$B$4+D16*INDEX($B$11:$E$12,C16-10,3) -> 2.78 | H16: =$B$4+D16*INDEX($B$11:$E$12,C16-10,4) -> 3.5 | I16: =($B$4/2+E16+F16+G16+H16/2)/4 -> 2.46 | J16: =F16 -> 2.3 | K16: =(E16+F16)/2 -> 2.18
A17: 情境（Assumed）基準＋線性 | B17: =$B$4*SQRT($B$5/$B$4) -> 4.5716518 | C17: 11 | D17: =B17-$B$4 -> 2.6716518 | E17: =$B$4+D17*INDEX($B$11:$E$12,C17-10,1) -> 2.5679129 | F17: =$B$4+D17*INDEX($B$11:$E$12,C17-10,2) -> 3.2358259 | G17: =$B$4+D17*INDEX($B$11:$E$12,C17-10,3) -> 3.9037388 | H17: =$B$4+D17*INDEX($B$11:$E$12,C17-10,4) -> 4.5716518 | I17: =($B$4/2+E17+F17+G17+H17/2)/4 -> 3.2358259 | J17: =F17 -> 3.2358259 | K17: =(E17+F17)/2 -> 2.9018694
A18: 情境（Assumed）基準＋後重 | B18: =$B$4*SQRT($B$5/$B$4) -> 4.5716518 | C18: 12 | D18: =B18-$B$4 -> 2.6716518 | E18: =$B$4+D18*INDEX($B$11:$E$12,C18-10,1) -> 2.1671652 | F18: =$B$4+D18*INDEX($B$11:$E$12,C18-10,2) -> 2.5679129 | G18: =$B$4+D18*INDEX($B$11:$E$12,C18-10,3) -> 3.3694085 | H18: =$B$4+D18*INDEX($B$11:$E$12,C18-10,4) -> 4.5716518 | I18: =($B$4/2+E18+F18+G18+H18/2)/4 -> 2.8350781 | J18: =F18 -> 2.5679129 | K18: =(E18+F18)/2 -> 2.3675391
A19: 情境（Assumed）高＋線性 | B19: =$B$4*$B$6 -> 5.7 | C19: 11 | D19: =B19-$B$4 -> 3.8 | E19: =$B$4+D19*INDEX($B$11:$E$12,C19-10,1) -> 2.85 | F19: =$B$4+D19*INDEX($B$11:$E$12,C19-10,2) -> 3.8 | G19: =$B$4+D19*INDEX($B$11:$E$12,C19-10,3) -> 4.75 | H19: =$B$4+D19*INDEX($B$11:$E$12,C19-10,4) -> 5.7 | I19: =($B$4/2+E19+F19+G19+H19/2)/4 -> 3.8 | J19: =F19 -> 3.8 | K19: =(E19+F19)/2 -> 3.325
A20: 情境（Assumed）高＋後重 | B20: =$B$4*$B$6 -> 5.7 | C20: 12 | D20: =B20-$B$4 -> 3.8 | E20: =$B$4+D20*INDEX($B$11:$E$12,C20-10,1) -> 2.28 | F20: =$B$4+D20*INDEX($B$11:$E$12,C20-10,2) -> 2.85 | G20: =$B$4+D20*INDEX($B$11:$E$12,C20-10,3) -> 3.99 | H20: =$B$4+D20*INDEX($B$11:$E$12,C20-10,4) -> 5.7 | I20: =($B$4/2+E20+F20+G20+H20/2)/4 -> 3.23 | J20: =F20 -> 2.85 | K20: =(E20+F20)/2 -> 2.565
A22: 區間（六情境）
A23: 最小 | I23: =MIN(I15:I20) -> 2.46 | J23: =MIN(J15:J20) -> 2.3 | K23: =MIN(K15:K20) -> 2.18
A24: 最大 | I24: =MAX(I15:I20) -> 3.8 | J24: =MAX(J15:J20) -> 3.8 | K24: =MAX(K15:K20) -> 3.325
A25: 基準（基準＋後重／基準＋線性） | I25: =I18 -> 2.8350781 | J25: =J18 -> 2.5679129 | K25: =K18 -> 2.3675391 | L25: 後重
A26: 基準＋線性 | I26: =I17 -> 3.2358259 | J26: =J17 -> 3.2358259 | K26: =K17 -> 2.9018694
A28: 交叉檢查：以 2026 支出倍數推平均 GW（不用上面的情境）
A29: 輸入 | B29: 值 | C29: 單位 | D29: 標記 | E29: 依據
A30: 2026 算力支出 | B30: 50 | C30: 十億美元 | D30: Interested-party | E30: G13 Brockman 證詞
A31: 2025 算力支出（chat 端 204 億） | B31: 20.4 | C31: 十億美元 | D31: chat 端 Derived | E31: 前段 Q側缺口 A 段
A32: 2025 算力支出（Epoch 160 億） | B32: 16 | C32: 十億美元 | D32: Analogy | E32: 前段；為查核帳下界附近
A33: 2025 平均 GW（TK 內插） | B33: 1.128 | C33: GW | D33: Derived | E33: AL_FleetGW25
A34: 2025 平均 GW（線性內插） | B34: 1.25 | C34: GW | D34: Derived | E34: 0.6→1.9 線性
A35: 每 GW 單價 2026÷2025（平價） | B35: 1 | C35: 倍 | D35: Assumed | E35: 區間 1.0–1.25
A36: 每 GW 單價 2026÷2025（+25%） | B36: 1.25 | C36: 倍 | D36: Assumed | E36: CoreWeave 2026-07 全 SKU 約漲 25%（G10 來源頁），僅作上限情境
A38: 情境 | B38: 平均 GW | C38: 說明
A39: S1 TK 內插、204 億、平價 | B39: =B33*B30/B31/B35 -> 2.7647059 | C39: 支出倍數 2.45 倍
A40: S2 TK 內插、204 億、單價+25% | B40: =B33*B30/B31/B36 -> 2.2117647 | C40: 單價上漲吸收一部分
A41: S3 TK 內插、160 億、平價 | B41: =B33*B30/B32/B35 -> 3.525 | C41: 支出倍數 3.13 倍
A42: S4 線性內插、160 億、平價 | B42: =B34*B30/B32/B35 -> 3.90625 | C42: 上端
A43: 最小 | B43: =MIN(B39:B42) -> 2.2117647
A44: 最大 | B44: =MAX(B39:B42) -> 3.90625
A46: 讀法：支出法假設 2026 全年花費全數對應當年上線算力；若含預付或未啟用容量，平均 GW 會較低。兩種方法只是互相對照，不是獨立證據（支出倍數與你的 h 共線）。

Sheet 比值
A1: 回本比值＝營收 ÷（GW × 每 GW 持有成本 h）；對 2025 的 1.239 之倍數（公式）
A3: 輸入 | B3: 值 | C3: 單位 | D3: 標記 | E3: 依據
A4: 2025 比值 | B4: 1.239 | C4: 倍 | D4: Derived | E4: 任務給定
A5: h：OpenAI 模型世代組合 | B5: 9.796 | C5: $B／GW·年 | D5: Derived | E5: 任務給定
A6: h：TK 組合 | B6: 9.731 | C6: $B／GW·年 | D6: Derived | E6: 任務給定
A7: 營收：Q2 年化 | B7: 26.3 | C7: 十億美元 | D7: 任務給定 | E7: 你的 263 億；WSJ Q2 GAAP 6.7B×4＝26.8（R01）
A8: 營收：FY2026 預測（不含廣告） | B8: 35 | C8: 十億美元 | D8: 任務給定 | E8: 你的 350 億；H1 實際 5.7＋6.7＝12.4（R01）
A9: 營收：9 月底 run-rate（FT，二手） | B9: 50 | C9: 十億美元 | D9: 報導（二手） | E9: 口徑與全年營收不同；僅第三口徑
A10: 持平門檻 GW（比值＝1.239）
A11: Q2 年化，h＝9.796 | B11: =B7/(B4*B5) -> 2.166884 | C11: Q2 末 GW 高於此值→比值低於 2025
A12: Q2 年化，h＝9.731 | B12: =B7/(B4*B6) -> 2.1813581
A13: FY2026，h＝9.796 | B13: =B8/(B4*B5) -> 2.883686 | C13: 全年平均 GW 高於此值→比值低於 2025
A14: FY2026，h＝9.731 | B14: =B8/(B4*B6) -> 2.9029481
A16: 表 A：Q2 年化營收 ÷ Q2 末 GW | B16: Q2 末 GW | C16: 比值（h 9.796） | D16: 倍數 vs 2025 | E16: 比值（h 9.731） | F16: 倍數 vs 2025
A17: =換算!A15 -> 情境（Assumed）低＋線性 | B17: =換算!J15 -> 2.7 | C17: =$B$7/(B17*$B$5) -> 0.994359 | D17: =C17/$B$4 -> 0.80254963 | E17: =$B$7/(B17*$B$6) -> 1.001001 | F17: =E17/$B$4 -> 0.80791041
A18: =換算!A16 -> 情境（Assumed）低＋後重 | B18: =換算!J16 -> 2.3 | C18: =$B$7/(B18*$B$5) -> 1.167291 | D18: =C18/$B$4 -> 0.94212348 | E18: =$B$7/(B18*$B$6) -> 1.1750881 | F18: =E18/$B$4 -> 0.94841657
A19: =換算!A17 -> 情境（Assumed）基準＋線性 | B19: =換算!J17 -> 3.2358259 | C19: =$B$7/(B19*$B$5) -> 0.82970141 | D19: =C19/$B$4 -> 0.66965408 | E19: =$B$7/(B19*$B$6) -> 0.83524355 | F19: =E19/$B$4 -> 0.67412716
A20: =換算!A18 -> 情境（Assumed）基準＋後重 | B20: =換算!J18 -> 2.5679129 | C20: =$B$7/(B20*$B$5) -> 1.0455064 | D20: =C20/$B$4 -> 0.84383079 | E20: =$B$7/(B20*$B$6) -> 1.05249 | F20: =E20/$B$4 -> 0.84946731
A21: =換算!A19 -> 情境（Assumed）高＋線性 | B21: =換算!J19 -> 3.8 | C21: =$B$7/(B21*$B$5) -> 0.70651824 | D21: =C21/$B$4 -> 0.57023264 | E21: =$B$7/(B21*$B$6) -> 0.71123755 | F21: =E21/$B$4 -> 0.57404161
A22: =換算!A20 -> 情境（Assumed）高＋後重 | B22: =換算!J20 -> 2.85 | C22: =$B$7/(B22*$B$5) -> 0.94202431 | D22: =C22/$B$4 -> 0.76031018 | E22: =$B$7/(B22*$B$6) -> 0.94831674 | F22: =E22/$B$4 -> 0.76538881
A24: 表 B：FY2026 營收 ÷ 全年平均 GW | B24: 平均 GW | C24: 比值（h 9.796） | D24: 倍數 vs 2025 | E24: 比值（h 9.731） | F24: 倍數 vs 2025
A25: =換算!A15 -> 情境（Assumed）低＋線性 | B25: =換算!I15 -> 2.7 | C25: =$B$8/(B25*$B$5) -> 1.3232914 | D25: =C25/$B$4 -> 1.0680318 | E25: =$B$8/(B25*$B$6) -> 1.3321306 | F25: =E25/$B$4 -> 1.0751659
A26: =換算!A16 -> 情境（Assumed）低＋後重 | B26: =換算!I16 -> 2.46 | C26: =$B$8/(B26*$B$5) -> 1.452393 | D26: =C26/$B$4 -> 1.1722301 | E26: =$B$8/(B26*$B$6) -> 1.4620946 | F26: =E26/$B$4 -> 1.1800602
A27: =換算!A17 -> 情境（Assumed）基準＋線性 | B27: =換算!I17 -> 3.2358259 | C27: =$B$8/(B27*$B$5) -> 1.1041654 | D27: =C27/$B$4 -> 0.89117463 | E27: =$B$8/(B27*$B$6) -> 1.1115408 | F27: =E27/$B$4 -> 0.8971274
A28: =換算!A18 -> 情境（Assumed）基準＋後重 | B28: =換算!I18 -> 2.8350781 | C28: =$B$8/(B28*$B$5) -> 1.2602428 | D28: =C28/$B$4 -> 1.0171451 | E28: =$B$8/(B28*$B$6) -> 1.2686609 | F28: =E28/$B$4 -> 1.0239394
A29: =換算!A19 -> 情境（Assumed）高＋線性 | B29: =換算!I19 -> 3.8 | C29: =$B$8/(B29*$B$5) -> 0.94023339 | D29: =C29/$B$4 -> 0.75886472 | E29: =$B$8/(B29*$B$6) -> 0.94651385 | F29: =E29/$B$4 -> 0.7639337
A30: =換算!A20 -> 情境（Assumed）高＋後重 | B30: =換算!I20 -> 3.23 | C30: =$B$8/(B30*$B$5) -> 1.1061569 | D30: =C30/$B$4 -> 0.89278203 | E30: =$B$8/(B30*$B$6) -> 1.1135457 | F30: =E30/$B$4 -> 0.89874553
A32: 表 C：FY2026 營收 ÷ 支出法平均 GW | B32: 平均 GW | C32: 比值（h 9.796） | D32: 倍數 vs 2025 | E32: 比值（h 9.731） | F32: 倍數 vs 2025
A33: =換算!A39 -> S1 TK 內插、204 億、平價 | B33: =換算!B39 -> 2.7647059 | C33: =$B$8/(B33*$B$5) -> 1.2923208 | D33: =C33/$B$4 -> 1.0430353 | E33: =$B$8/(B33*$B$6) -> 1.3009531 | F33: =E33/$B$4 -> 1.0500025
A34: =換算!A40 -> S2 TK 內插、204 億、單價+25% | B34: =換算!B40 -> 2.2117647 | C34: =$B$8/(B34*$B$5) -> 1.615401 | D34: =C34/$B$4 -> 1.3037942 | E34: =$B$8/(B34*$B$6) -> 1.6261914 | F34: =E34/$B$4 -> 1.3125031
A35: =換算!A41 -> S3 TK 內插、160 億、平價 | B35: =換算!B41 -> 3.525 | C35: =$B$8/(B35*$B$5) -> 1.0135849 | D35: =C35/$B$4 -> 0.81806694 | E35: =$B$8/(B35*$B$6) -> 1.0203554 | F35: =E35/$B$4 -> 0.82353136
A36: =換算!A42 -> S4 線性內插、160 億、平價 | B36: =換算!B42 -> 3.90625 | C36: =$B$8/(B36*$B$5) -> 0.91465904 | D36: =C36/$B$4 -> 0.7382236 | E36: =$B$8/(B36*$B$6) -> 0.92076868 | F36: =E36/$B$4 -> 0.7431547
A39: 表 D：敏感度（h 9.796） | B39: GW | C39: Q2 年化營收的倍數 | D39: FY2026 營收的倍數
B40: 2 | C40: =$B$7/(B40*$B$5)/$B$4 -> 1.083442 | D40: =$B$8/(B40*$B$5)/$B$4 -> 1.441843
B41: 2.25 | C41: =$B$7/(B41*$B$5)/$B$4 -> 0.96305956 | D41: =$B$8/(B41*$B$5)/$B$4 -> 1.2816382
B42: 2.5 | C42: =$B$7/(B42*$B$5)/$B$4 -> 0.86675361 | D42: =$B$8/(B42*$B$5)/$B$4 -> 1.1534744
B43: 2.75 | C43: =$B$7/(B43*$B$5)/$B$4 -> 0.78795782 | D43: =$B$8/(B43*$B$5)/$B$4 -> 1.0486131
B44: 3 | C44: =$B$7/(B44*$B$5)/$B$4 -> 0.72229467 | D44: =$B$8/(B44*$B$5)/$B$4 -> 0.96122865
B45: 3.25 | C45: =$B$7/(B45*$B$5)/$B$4 -> 0.66673354 | D45: =$B$8/(B45*$B$5)/$B$4 -> 0.88728798
B46: 3.5 | C46: =$B$7/(B46*$B$5)/$B$4 -> 0.61910972 | D46: =$B$8/(B46*$B$5)/$B$4 -> 0.82391027
...

Sheet GPU換算
A1: GPU 與 GW 互換（TK 每 GW 顆數；世代比例為 Assumed）
A3: 輸入 | B3: 值 | C3: 單位 | D3: 標記 | E3: 依據
A4: Hopper 每 GW 顆數 | B4: 718048 | C4: 顆／GW | D4: TK | E4: 任務給定
A5: GB200 每 GW 顆數 | B5: 501768 | C5: 顆／GW | D5: TK | E5: 任務給定
A6: 2025 年底 Hopper 占比 | B6: 0.6 | C6: 比例 | D6: Assumed（0.5–0.7） | E6: 與前段『約 63 萬顆／GW』相符
A7: 2026 年底 Hopper 占比 | B7: 0.4 | C7: 比例 | D7: Assumed（0.3–0.5） | E7: 新增以 GB200／後續世代為主
A9: 混合每 GW 顆數（2025 年底） | B9: =B6*B4+(1-B6)*B5 -> 631536
A10: 1.9 GW 對應 GPU 顆數 | B10: =換算!B4*B9 -> 1199918.4
A11: 對照 Altman『well over 1 million』（G03） | B11: =B10/1000000 -> 1.1999184 | C11: 倍（>1 即相容）
A12: Epoch 1.743M H100e ÷ 1.9 GW＝每 GW H100e | B12: =1743000/換算!B4 -> 917368.42
A14: Abilene 檢查（G06/G07）
A15: Epoch 完工 1.0M H100e 對 1.2 GW 設施 | B15: =1000000/1.2 -> 833333.33 | C15: H100e／設施 GW
A16: 509k H100e 對應設施 GW | B16: =509000/B15 -> 0.6108
A17: Epoch 自給 Abilene 約 2026-07 IT 電力（GW） | B17: 0.421
A18: Epoch 預測 2026-11-01：1,019k H100e／843 MW IT → 每 MW H100e | B18: =1019000/843 -> 1208.7782
A19: Huang 400,000 GPU（G18）換 GW
A20: 以 GB200 每 GW 顆數 | B20: =400000/B5 -> 0.79718117
A21: 以 Hopper 每 GW 顆數 | B21: =400000/B4 -> 0.55706582
A23: 2026 年底各情境 GW 對應 GPU 顆數（混合每 GW 顆數以 2026 占比）
A24: 2026 年底混合每 GW 顆數（新增部分全 GB200 的簡化不用，這裡用整體占比） | B24: =B7*B4+(1-B7)*B5 -> 588280
A25: ="低情境 2026 年底 GPU 顆數" -> 低情境 2026 年底 GPU 顆數 | B25: =換算!B15*$B$24 -> 2058980
A26: ="基準情境 2026 年底 GPU 顆數" -> 基準情境 2026 年底 GPU 顆數 | B26: =換算!B17*$B$24 -> 2689411.3
A27: ="高情境 2026 年底 GPU 顆數" -> 高情境 2026 年底 GPU 顆數 | B27: =換算!B19*$B$24 -> 3353196
