Workbook

Sheet 三因子
A1: 輸入（藍字＝來自 Tokenomics 或證據；其餘為公式）
A2: 推論支出 SRC_DEM_004（$B） | B2: 8.4
A3: 訓練支出 SRC_DEM_006（$B） | B3: 12
A4: 服務 GW（L1_ServeGW_GW25） | B4: 0.4624
A5: 機隊每 GW 年持有成本 AL_FleetHold（$B） | B5: 9.353
A6: 機隊平均上線 GW AL_FleetGW25 | B6: 1.128
A7: Epoch 引 2025 雲端算力總支出（$B） | B7: 16
A9: TK 服務算力成本（$B） | B9: =B4*B5
A10: 9a 缺口（推論÷TK 服務成本） | B10: =B2/B9
A11: 推論＋訓練（$B） | B11: =B2+B3
A12: 總缺口（204÷(平均GW×持有成本)） | B12: =B11/(B6*B5)
A13: Epoch 160 ÷ 204（s 的上限代理） | B13: =B7/B11
A15: (b) 平均 GW 取不同值時，扣除 GW 後剩餘缺口 R＝總缺口÷GW因子
A16: 平均 GW 情境 | B16: GW（實際） | C16: GW 因子＝GW÷1.128 | D16: 剩餘缺口 R＝B12÷GW因子
A17: 低（1.0） | B17: 1 | C17: =B17/$B$6 | D17: =$B$12/C17
A18: 模型（1.128） | B18: 1.128 | C18: =B18/$B$6 | D18: =$B$12/C18
A19: 高（1.25） | B19: 1.25 | C19: =B19/$B$6 | D19: =$B$12/C19
A21: (c) 必須為真：價格因子 P 給定時，口徑因子 1/s＝R÷P，s＝204 億中屬當年上線算力費用的比例
A22: 價格因子 P（OpenAI 實付÷9.353） | B22: 依據 | C22: 1/s（GW=1.0） | D22: s（GW=1.0） | E22: 1/s（GW=1.128） | F22: s（GW=1.128） | G22: 1/s（GW=1.25） | H22: s（GW=1.25）
A23: 0.89 | B23: 同口徑長約低端（B 段） | C23: =$D$17/$A23 | D23: =1/C23 | E23: =$D$18/$A23 | F23: =1/E23 | G23: =$D$19/$A23 | H23: =1/G23
A24: 1.07 | B24: CoreWeave 全客戶約 10 億／GW·年（W3-03，Derived） | C24: =$D$17/$A24 | D24: =1/C24 | E24: =$D$18/$A24 | F24: =1/E24 | G24: =$D$19/$A24 | H24: =1/G24
A25: 1.12 | B25: 同口徑長約高端（B 段） | C25: =$D$17/$A25 | D25: =1/C25 | E25: =$D$18/$A25 | F25: =1/E25 | G25: =$D$19/$A25 | H25: =1/G25
A26: 1.42 | B26: Oracle 3000 億／5 年／4.5 GW 高端（W3-01） | C26: =$D$17/$A26 | D26: =1/C26 | E26: =$D$18/$A26 | F26: =1/E26 | G26: =$D$19/$A26 | H26: =1/G26
A28: (d) 獨立證據相乘能否重現總缺口
A29: 情境 | B29: GW因子 | C29: 價格因子 | D29: 口徑因子 1/s | E29: 乘積 | F29: 對照總缺口(B12) | G29: 乘積÷總缺口
A30: 低 | B30: 0.887 | C30: 0.89 | D30: 1 | E30: =B30*C30*D30 | F30: =$B$12 | G30: =E30/F30
A31: 中 | B31: 1 | C31: 1.07 | D31: =1/B13 | E31: =B31*C31*D31 | F31: =$B$12 | G31: =E31/F31
A32: 高 | B32: 1.108 | C32: 1.42 | D32: =1/B13 | E32: =B32*C32*D32 | F32: =$B$12 | G32: =E32/F32
A34: 註：(d) 為舊版對照，口徑因子取 204÷160（Epoch 雲端總支出）；160 億已被查核帳取代（chat 端），不作結論。
A36: (e) 兩年一致性（Assumed 區間，不是來源值）
A37: 項目 | B37: 低 | C37: 高 | D37: 備註
A38: 2025 總算力支出（$B） | B38: =B7 | C38: =B7 | D38: Epoch 引報導
A39: 2025 平均 GW | B39: 1 | C39: 1.25 | D39: 官方端點內插區間
A40: 2025 支出÷GW（$B/GW·年） | B40: =B38/C39 | C40: =C38/B39 | D40: 高＝支出÷低GW
A41: 2026 總算力支出（$B） | B41: 50 | C41: 50 | D41: Brockman 證詞
A42: 2026 平均 GW（Assumed） | B42: 3 | C42: 4.5 | D42: 無來源；沿用上一輪粗估 3.5–4，這裡放寬
A43: 2026 支出÷GW（$B/GW·年） | B43: =B41/C42 | C43: =C41/B42
A44: ÷9.353 持有成本（2025） | B44: =B40/$B$5 | C44: =C40/$B$5
A45: ÷9.353 持有成本（2026） | B45: =B43/$B$5 | C45: =C43/$B$5
A47: (f) 依查核帳 s（chat 端）反推價格因子 P＝R÷(1/s)＝R×s（必須為真）
...

Sheet 證據
A1: 編號 | B1: 項目 | C1: 主張原句／內容 | D1: 數值 | E1: 單位 | F1: 口徑 | G1: 期間 | H1: 出處網址 | I1: 出處日期 | J1: 取得方式 | K1: 等級 | L1: 立場 | M1: 對應名稱 | N1: 支持或反駁
A2: W1-01 | B2: W1 | C2: The Information 報導（付費牆未讀）：2025 推論成本約 84 億，約為 2024 的 4 倍，高於夏季預測 66 億；其中免費用戶約 39 億、付費用戶約 45 億。 / Inference costs ~$8.4B, ~4x 2024, above the $6.6B summer forecast; ~$3.9B free users, ~$4.5B paying. | D2: 8.4 | E2: $B | F2: 推論成本（用於毛利率分子）；含免費用戶；是否含 RL／內部使用未明。39／45／66 三項細項僅見二手摘要，抽查未能核對 | G2: 2025 全年（報導於 2026-02 前後，為實際） | H2: https://finance.biggo.com/news/mRiPlZwBTwP6zY3HRxp-（及 aiafterhours、controlplane、safeguard 同源轉述） | I2: 約 2026-02-24 | J2: 二手（同源算 1 個） | K2: 3 | L2: The Information 為媒體；OpenAI 無誘因誇大成本 | M2: SRC_DEM_004 | N2: 口徑：84 億含免費；不含 Microsoft 自家產品推論為 Project 預設（Epoch 對 2024 的說法，未證實適用 2025）
A3: W1-02 | B3: W1 | C3: 毛利率 2025 為 33%，低於 2024 的 40% 與內部目標 46%；原因（二手摘要的轉述，非逐字引語）：需求超預期，以較貴價格追加算力。 / adjusted gross margin 33% vs 40% (2024), target 46%. | D3: 33 / 46 | E3: % | F3: adjusted gross margin（營收減推論成本） | G3: 2025 | H3: 同 W1-01 | I3: 約 2026-02 | J3: 二手 | K3: 3 | L3: 同上 | M3: SRC_DEM_004 | N3: 價格因子：隨需加價，但無金額或比例
A4: W1-03 | B4: W1 | C4: 內部指標 compute margin 2025-10 約 70%（2024 底 52%），不含訓練與管銷；OpenAI 發言人稱未公開。 / 'compute margin' ~70% Oct 2025, excludes training and overhead. | D4: 70 | E4: % | F4: 不同於 33% | G4: 2025-10 | H4: https://fortune.com/2025/12/21/openai-compute-margins-revenue-chatgpt-earnings-sam-altman/（搜尋摘要） | I4: 2025-12-21 | J4: 二手 | K4: 3 | L4: The Information 轉述 | M4: — | N4: 說明 84 億僅為推論，不含訓練
A5: W1-04 | B5: W1 | C5: Sacra：2025 推論 84 億，2026 預測 141 億（+68%）；多站轉述同一 Sacra 估計。 / Sacra: inference $8.4B 2025, $14.1B 2026. | D5: 8.4 / 14.1 | E5: $B | F5: 推論；2026 為預測 | G5: 2025／2026 | H5: https://sacra.com/c/openai/（搜尋摘要；本環境 DNS 失敗） | I5: 2026 | J5: 二手（同源） | K5: 3–4 | L5: Sacra 為研究賣方 | M5: SRC_DEM_004 | N5: 與 W1-01 同數，非獨立
A6: W1-05 | B6: W1 | C6: 搜尋摘要稱某電子報引 The Information「預期去年花 94 億美元於訓練算力」，抽查找不到該原文；最近可核對者為 2025-09 報導的『2025 訓練逾 90 億』（預測值）。 | D6: 9.4 | E6: $B | F6: 訓練算力；預測 vs 實際不明 | G6: 2025（預測） | H6: https://aiafterhours.substack.com/p/openai-vs-anthropic-the-121-billion（搜尋摘要；頁面本環境無法開啟，原文未核對） | I6: 未明 | J6: 二手（無法核對） | K6: 4 | L6: — | M6: SRC_DEM_006 | N6: 最接近的外部訓練數為約 90–94 億預測，非 120 億；但為預測、未核對原文
A7: W1-06 | B7: W1 | C7: 2025 訓練 120 億的外部原文：已搜尋，未找到（見「未找到」）。20261023 利用率 A 段另有 15 組查詢亦未找到。 | D7: — | E7: — | F7: — | G7: — | H7: — | I7: — | J7: — | K7: — | L7: — | M7: SRC_DEM_006 | N7: 無外部背書
A8: W1-07 | B8: W1 | C8: Epoch 對 2024：訓練 30 億、推論 18 億、研究算力 10 億（分攤兩年得 20 億）；R&D 算力合計 50 億；推論 'likely excludes Microsoft's own inference spending on licensed OpenAI models'。 | D8: 30 / 18 / 10 | E8: $B | F8: 2024 投資人文件經記者轉述 | G8: 2024 | H8: https://epoch.ai/data-insights/openai-compute-spend | I8: 2025 | J8: 原文 | K8: 3 | L8: 獨立研究機構 | M8: SRC_DEM_004/006 口徑 | N8: 口徑：R&D 算力含大量實驗；訓練與研究的邊界 OpenAI 未公開
A9: W1-08 | B9: W1 | C9: The Information 經 Habr 等二手轉述：OpenAI 計畫 2026 訓練花 320 億、2027 約 650 億（The Decoder 該頁報的是現金燃燒 250／570 億，不是訓練）。 / plans to spend $32B on model training in 2026 and ~$65B in 2027. | D9: 32 / 65 | E9: $B | F9: 訓練；預測 | G9: 2026／2027 | H9: https://the-decoder.com/openai-adds-111-billion-to-its-cash-burn-forecast-as-ai-costs-spiral-beyond-projections/ | I9: 2026-02 | J9: 二手（Habr）；Decoder 頁不支持此數 | K9: 4 | L9: — | M9: — | N9: W4：2026 訓練預測（可信度低）
A10: W1-09 | B10: W1 | C10: H1 2025 研發費用 67 億（營收 43 億；現金燃燒約 25 億），僅見 Storyboard18 轉述 The Information（抽查未在 Reuters 找到）。 / R&D cost $6.7B in the first half. | D10: 6.7 | E10: $B | F10: 研發費用整體（非僅算力） | G10: 2025 H1 | H10: https://finance.yahoo.com/news/openais-first-half-revenue-rises-043012507.html（搜尋摘要） | I10: 2025-09-29 | J10: 二手（Storyboard18 轉述） | K10: 3–4 | L10: — | M10: — | N10: 無法由此推全年算力；只可作研發費用方向
A11: W1-10 | B11: W1 | C11: OpenAI 2025 查核財報（chat 端已查，不重查）：營業成本 75、研發 191.8、付 Microsoft 172.1 億，其中研發 105.9。Zitron 另報付 Microsoft 項目：研發 10.59、營業成本 6.047、銷售 0.527、管理 0.042 十億。 | D11: 75 / 191.8 / 172.1 / 105.9 | E11: 億$ | F11: chat 端已查 | G11: 2025 | H11: 見 Drive 筆記（chat 端併入） | I11: 2026-06 | J11: chat 端已查 | K11: — | L11: — | M11: — | N11: （見 README）
A12: W1-11 | B12: W1 | C12: 研發付 Microsoft 105.9 億中訓練與研究推論的拆分：已搜尋，未找到任何報導拆分。Zitron 僅稱『研發』『最可能是訓練模型成本』（其個人推論）。 | D12: — | E12: — | F12: — | G12: 2025 | H12: — | I12: — | J12: — | K12: — | L12: — | M12: SRC_DEM_006 | N12: 無拆分
... A26: W4-04 | B26: W4 | C26: Sacra 2026 推論預測 141 億；The Information 2026 訓練計畫 320 億 → 合計 461 億，對 500 億支出（W4-01）約 0.92。 | D26: 46.1 | E26: $B | F26: 預測加總 | G26: 2026 | H26: 見 W1-04、W1-08 | I26: — | J26: Derived | K26: — | L26: — | M26: — | N26: 2026 兩項合計≈總支出；2025 兩項（204）＞總支出（160）

Sheet 合約換算
A1: 合約 | B1: 金額（$B） | C1: 年數 | D1: 容量（GW） | E1: 每年金額 | F1: 每 GW·年（$B） | G1: ÷9.353 持有成本 | H1: 備註
A2: Oracle（300 億／年版） | B2: 30 | C2: 1 | D2: 4.5 | E2: =B2/C2 | F2: =E2/D2 | G2: =F2/三因子!$B$5 | H2: W3-01；FY2028 起
A3: Oracle（3000 億／5 年版） | B3: 300 | C3: 5 | D3: 4.5 | E3: =B3/C3 | F3: =E3/D3 | G3: =F3/三因子!$B$5 | H3: W3-01 另一版本；兩版互相矛盾，未解
A4: Cerebras（3 年） | B4: 10 | C4: 3 | D4: 0.75 | E4: =B4/C4 | F4: =E4/D4 | G4: =F4/三因子!$B$5 | H4: W3-04；不同硬體
A5: Cerebras（2 年） | B5: 10 | C5: 2 | D5: 0.75 | E5: =B5/C5 | F5: =E5/D5 | G5: =F5/三因子!$B$5 | H5: W3-04
A6: AWS（7 年，無容量） | B6: 38 | C6: 7 | E6: =B6/C6 | F6: 無法換算 | H6: W3-05；無法換算
A8: CoreWeave（Q3 營收 $B，平均活躍 GW） | B8: 1.365 | C8: 0.25 | D8: 0.53 | E8: =B8/C8 | F8: =E8/D8 | G8: =F8/三因子!$B$5 | H8: 季營收×4÷平均活躍電力；全客戶；W3-03（Derived）

Sheet 未找到
A1: 編號 | B1: 項目 | C1: 查詢字串 | D1: 結果
A2: N01 | B2: W1 訓練 120 億原文 | C2: OpenAI 2025 training compute $12 billion；OpenAI 2025 training compute spending actual vs projected；OpenAI training compute 2025 $9.4 billion OR $12 billion The Information | D2: 最近為 94 億（W1-05，日期不明）；120 億未找到
A3: N02 | B3: W1 84 億原文 | C3: The Information Why OpenAI Anthropic Missed Their Own Gross Margin Forecasts；OpenAI inference $8.4 billion | D3: 只見二手轉述；原文付費牆
A4: N03 | B4: W1(c) 研發付 Microsoft 105.9 拆分 | C4: OpenAI paid Microsoft 10.59 billion research development training inference split | D4: 無報導拆分
A5: N04 | B5: W1 H1 2025 算力拆分 | C5: OpenAI H1 2025 R&D compute 6.7 billion compute-only breakdown | D5: 只有研發費用 67 億，無算力分項
A6: N05 | B6: W3 OpenAI 實付每 GPU 小時 | C6: OpenAI price per GPU hour Azure discount rate H100 GB200 OpenAI pays Microsoft below list price | D6: 無
A7: N06 | B7: W3 Microsoft 對 OpenAI 的關聯方定價 | C7: 同上 | D7: 無
A8: N07 | B8: W3 CoreWeave／AWS 合約 MW | C8: CoreWeave OpenAI contract MW capacity；OpenAI AWS 38 billion capacity | D8: 無 MW
A9: N08 | B9: W3 隨需購買金額或比例 | C9: OpenAI bought on-demand compute 2025 higher prices amount | D9: 無
A10: N09 | B10: W4 2026 平均上線 GW | C10: OpenAI 2026 year-end gigawatts target compute capacity end of 2026；Brockman testimony 2026 average capacity GW | D10: 無
A11: N10 | B11: W2 Azure 占比（承接上一輪） | C11: 見 W2_優先查證.md | D11: 無
A13: 交 chat 端
A14: openai.com 原文（HTTP 403）
A15: sec.gov：Microsoft 10-Q／10-K、CoreWeave、Oracle 申報
A16: wheresyoured.at、nextplatform.com、deepquarry.substack.com、sacra.com、aiafterhours.substack.com、safeguard.sh、controlplane.news、techcrunch.com、cnbc.com、finance.yahoo.com（本環境 DNS 失敗，改用搜尋摘要）
A17: The Information 原文（付費牆）

Sheet 待判斷
A1: 編號 | B1: 事項 | C1: 建議預設 | D1: 理由
A2: J1 | B2: SRC_DEM_006（訓練 120 億）出處標『待補』，數值先不改 | C2: 只標記，不改值 | D2: 本段未找到原文；最近外部數為 94 億（日期不明）
A3: J2 | B3: 204 億與 Epoch 160 億的差距，B4_Serve 分母是否調整 | C3: 維持 0.41，160 億已被查核帳取代 | D3: 查核帳框出 2025 全部算力約 172–210 億，與 204 億相容（s 約 0.85–1.0，chat 端）
A4: J3 | B4: 價格因子是否由 0.85 改採區間 | C4: 交 chat 端審閱檔 | D4: 本段無 OpenAI 實付價；chat 端 Derived 區間 1.4–2.3 倍
A5: J4 | B5: GW 因子 | C5: 維持 AL_FleetGW25=1.128（你已決定 GW 不調） | D5: 官方端點內插已落在 1.0–1.25
