Workbook

Sheet Claude Log
A1: Turn # | B1: Date | C1: User Request | D1: Action Taken | E1: Details | F1: Outcome
A2: 1 | B2: 46093 | C2: Re-wire DC_Cost_Model, Revenue_Model, and OpenAI_Sim to pull all inputs from Config sheet instead of hardcoded WP_VR72_1T_1M1000 / TL_VR72_1T_1M1000 scenario sheets. | D2: Updated 11 formula cells across DC_Cost_Model and Revenue_Model to reference Config (and TL_Param for latency). Updated source note annotations. Updated section headers. | E2: DC_Cost_Model: B5→Config!B5/1M, B6→Config!B6, B8→Config!B7, B9→Config!B8, B10→Config!B14. Revenue_Model: B5→Config!B30, B6→Config!B26, B7→Config!B27, B9→Config!B48, B10→Config!B51, B11→TL_Param!E29. OpenAI_Sim already chains through DC_Cost_Model & Revenue_Model — no direct changes needed. | F2: All three sheets now flow from Config. Values updated automatically (e.g., Revenue_Model now uses 1M/1M tokens and 1.5T model from Config vs old 1M/1K & 1T). Full chain: Config → WP_Param/TL_Param → Revenue_Model; Config → DC_Cost_Model → OpenAI_Sim.
A3: 2 | B3: 46093 | C3: Make data precision (FP8) selectable from Config, based on NVIDIA spec tiers (FP4/FP8/FP16). | D3: Added Precision dropdown (B42), Bytes per Parameter (B43), and Inference PFLOPS (B44) to Config. Updated 8 formulas in WP_Param that had hardcoded *1 (FP8) to reference Config!B43. Updated compute time formulas to use Config!B44 for precision-matched PFLOPS. Updated Config!B62 weight memory check. | E3: Config: B42=FP4/FP8/FP16 dropdown, B43=IF(FP4→0.5,FP8→1,FP16→2), B44=selects matching PFLOPS from B19/B21/B22. WP_Param updated: B37 (weight mem), B73 (prefill HBM wt/layer), B126 (decode HBM wt/layer), B143 (NVLink msg), B158 (GQA wt), B168 (batch wt), B68 (prefill compute time), B121 (decode compute time). All notes updated to reference Config Precision. | F3: Precision is now a single dropdown in Config!B42. Changing it cascades through WP_Param → TL_Param → Revenue_Model → OpenAI_Sim. Verified FP8 baseline values unchanged. Full chain: Config Precision → bytes/param + PFLOPS → weight memory, HBM traffic, compute times, latency, throughput, revenue.
A4: 3 | B4: 46093 | C4: Make token pricing correspond to model size automatically. Build market pricing tiers referenced from real API pricing data (Mar 2026). | D4: Built 5-tier pricing lookup table in Config E28:H42 (Nano/Small/Mid/Frontier/Premium). Added MATCH/INDEX formulas to auto-select Input/Output $/M based on Config!B30 parameters. Wired Revenue_Model B32:B33 to Config!F41:F42. | E4: Tiers: Nano <50B ($0.10/$0.40), Small 50-200B ($0.25/$2), Mid 200-500B ($1.25/$10), Frontier 500B-1.5T ($2.50/$10), Premium >1.5T ($5/$25). Sources: OpenAI (GPT-5/4o/Nano), Anthropic (Opus/Sonnet/Haiku), Mar 2026 market data. Used MATCH with approximate match on ascending thresholds. OpenAI_Sim API rates left independent (calibrated to OpenAI's actual pricing, not model-based). | F4: Revenue_Model now auto-prices at $5/$25 for 1.5T model (Premium tier). Changing B30 to e.g. 300B would auto-select Mid tier at $1.25/$10. Full chain: Config B30 → MATCH/INDEX → F41:F42 → Revenue_Model B32:B33 → revenue calcs → OpenAI_Sim.
A5: 4 | B5: 46093 | C5: Make number of racks depend on IT power. Rack count should be derived from Total Power / Power per Rack, not hardcoded. | D5: Added 'Power per Rack (kW)' row to Config rack presets (row 23): VR NVL72 = 132 kW, GB200 NVL72 = 120 kW. Changed F8 and G8 from hardcoded 4386 to =FLOOR(F5/1000/F23,1). B8 auto-selects via existing IF lookup. | E5: VR NVL72: 1GW / 132kW = 7,575 racks. GB200 NVL72: 1GW / 120kW = 8,333 racks. Power per rack values sourced from NVIDIA specs (GPU TDP × 72 + CPU + networking, liquid-cooled). Downstream: DC_Cost_Model racks, total GPUs, CapEx, OpEx, Revenue_Model throughput all update automatically. | F5: Rack count now fully derived from IT power and rack power draw. Changing Total Power (F5/G5) or Power per Rack (F23/G23) automatically recalculates racks. GB200 NVL72 went from 4,386 to 8,333 racks; total GPUs ~600K; CapEx ~$37.5B.
A6: 5 | B6: 46093 | C6: User asked where the '14/GPU B200' FP4 Training figure (G20) comes from. | D6: Researched NVIDIA Blackwell B200 specs. Compared sheet values against HGX B200 datasheet and multiple technical sources. | E6: NVIDIA official: B200 FP4 = 9 dense / 18 sparse PFLOPS/GPU, FP8 = 4.5/9, FP16 = 2.25/4.5. Sheet has 14/10/5 which don't match either tier cleanly. HGX B200 datasheet (8-GPU): FP4=144, FP8=72, FP16=36 PFLOPS (all with sparsity). Confirmed via primeline-solutions.com datasheet PDF, serversimply.com, cudocompute.com, and runpod.io. | F6: Presented discrepancy to user with dense vs sparse comparison table. Awaiting user decision on whether to update to official NVIDIA figures.
A7: 6 | B7: 46093 | C7: Update all NVIDIA PFLOPS specs to dense (no sparsity) values based on official datasheets. | D7: Updated F19:G22 and E19:E22 with dense PFLOPS. GB200: FP4=9/GPU (648/rack), FP8=4.5 (324), FP16=2.25 (162). Vera Rubin: FP4=35/GPU (2520/rack), FP8=16 (1152), FP16=3.6 (259.2). Updated labels to include 'Dense'. Updated WP_Param labels. Added source notes. | E7: Sources: NVIDIA HGX B200 datasheet (sparse values halved for dense), SemiAnalysis (Rubin 35 PFLOPS dense FP4, 3.5× over Blackwell), Tom's Hardware (Rubin ~16 FP8 PFLOPS/GPU). Previous values (14/10/5 per GPU B200) didn't match either dense or sparse tiers. FP4 Training = FP4 Inference for dense (sparsity only differentiates inference marketing numbers). | F7: All PFLOPS now use dense (no sparsity) consistently. Config B45 (precision-selected PFLOPS) correctly picks 324 for FP8 GB200. Full chain verified: Config → WP_Param compute times → TL_Param latency → Revenue_Model throughput.
A8: 7 | B8: 46093 | C8: Sanity check Revenue_Model margins and unit economics. Full review of pricing, throughput, costs, and profitability. | D8: Computed independent verification of all Revenue_Model sections. Ran sensitivity analysis on utilization (50-85%) and I/O ratio (1:1 to 20:1). Cross-referenced margins against industry benchmarks (AWS, NVIDIA, OpenAI). | E8: Key findings: (1) 49.6% operating margin (after depreciation) is plausible but optimistic — driven by 85% utilization assumption. (2) EBITDA margin 85.6% is extremely high because depreciation dominates OpEx. (3) 10:1 I/O ratio compresses blended rate to $3.18/M vs $6.25 at 1:1. (4) Payback 2.82yr is reasonable. (5) At 60% utilization margin drops to 28.6%. (6) No errors found in formulas — all calculations verified. | F8: Revenue_Model is internally consistent. Main risks: utilization assumption (85% is aggressive), I/O ratio sensitivity, and no R&D/SGA/overhead costs beyond DC OpEx. Presented findings to user.
A9: 8 | B9: 46093 | C9: User asked for detailed explanation of the '25-40% realistic margin' statement from the sanity check. | D9: Provided detailed breakdown of two margin compression factors: (1) utilization drag from 85% to 60-70%, (2) non-DC overhead costs (R&D, S&M, G&A, SBC) typically 15-40% of revenue. Cross-referenced OpenAI_Sim actuals for overhead benchmarks. | E9: Explained: 85%→70% util drops DC margin from 49.6% to ~39%. Adding 15% lean overhead gives ~24% net. Adding 25% moderate overhead gives ~9%. OpenAI-like growth overhead (40%) makes it negative. The 25-40% range assumes mature/lean infra provider at 65-70% util with 10-15% overhead. Revenue_Model is correctly scoped as DC-level P&L, not company-level. | F9: No changes made to spreadsheet. Analytical explanation only. User now understands the gap between DC operating margin and company-level margin.
A10: 9 | B10: 46093 | C10: User wants 1T model as the representative default, doesn't want Config more complicated. | D10: Confirmed 1T is already set in Config!B31. Validated it's the right market representative — GPT-4o ($2.50/$10) and Claude Sonnet ($3/$15) are in the 500B-1.5T range and are the highest-volume API models. | E10: No changes needed. Config!B31 = 1T maps to Frontier tier ($2.50/$10). User also adjusted Revenue_Model!B13 utilization from 85% to 70% per previous discussion. | F10: Config unchanged. 1T dense model is the correct representative for current frontier LLM market (GPT-4o, Claude Sonnet, Gemini 2.5 Pro class).
A11: 10 | B11: 46093 | C11: User asked how GPT-5 and Opus 4.6 fit into the pricing/model-size framework. | D11: Analyzed GPT-5 family pricing tiers (base $1.25/$10, 5.2 $1.75/$14, 5.2 Pro $21/$168) and Opus 4.6 ($5/$25). Mapped to model size estimates and existing Config tiers. | E11: GPT-5 base is Mid tier (~200-500B, likely MoE), not a bigger dense model. Opus 4.6 is Premium (>1.5T). GPT-4o/Sonnet 4.6/GPT-5.2 are Frontier class (~500B-1T). 1T dense at Frontier ($2.50/$10) remains the best representative for high-volume API workloads. | F11: No changes made. Confirmed 1T Frontier tier is correct default. GPT-5 base is actually cheaper (efficiency gains, not size), while Opus is premium niche.
A12: 11 | B12: 46093 | C12: User asked what typical/representative input/output token sizes are for the model. | D12: Researched market data on tokens per request by use case. Found current Config (500K/50K) represents extreme long-context, not typical API workload. Typical ranges: chatbots 500/200-1000, enterprise RAG 5K-50K/500-2K, support tickets 3K/400. | E12: Recommended representative default: ~4,000 input / 1,000 output (4:1 ratio, 5K total). Reflects weighted blend of enterprise RAG (majority of API revenue) and consumer chatbot (majority of volume). Median output-to-input pricing ratio is ~4×, suggesting providers design for 3-5:1 I/O. Current 500K/50K is entire-book-per-request territory. | F12: Presented analysis to user. Awaiting confirmation to update Config!B27 and B28 to representative values. Change would significantly affect latency, throughput, and revenue calculations.
A13: 12 | B13: 46093 | C13: User asked what the input/output token sizes of our own conversation look like. | D13: Estimated per-turn and cumulative token counts. Per-turn user messages ~10-30 tokens, but with conversation history the full input grows to ~10K-17K by turn 11. Output responses ~500-1,500 tokens. Session average: ~4K-8K input / ~700-1K output. | E13: Key insight: API input includes full conversation history, not just the latest message. I/O ratio ~5:1 to 8:1 in multi-turn conversation. This aligns with the 4,000/1,000 representative recommendation. Our conversation is a typical frontier model assistant workload. | F13: No changes made. Analysis-only response reinforcing the 4K/1K recommendation as representative.
... A59: 58 | B59: 46100 | C59: Fix 11 errors across physics, finance, and formatting: (1) FP4 Inference 2520→3600, (2) land depreciation GAAP violation, (3) CapEx per GW formula (marginal vs cumulative), (4) fleet efficiency factor (wrong ratio), (5) d_model values for 8B-700B, (6) batching latency fallacy note, (7) OOM warning on 1M/1M, (8) Grok pricing totals (missing fees), (9) Claude I/O ratio formula, (10) 'Onput' typo, (11) dangling data in Section 10C. | D59: Applied all 11 fixes: corrected formulas, added cell notes documenting each error and fix, updated annotations, cleared orphaned data. | E59: Config!F19: 2520→3600 (50/GPU×72). DC_Cost_Model!D67: =(D28-D25)/B67 excludes $20M land. OpenAI_Sim!C96:H96: CapEx÷new GW instead of year-end. C34: tok/s ratio via TL_Param!O34/N34 replacing broken rev/opex ratio; yields 0.271x (was 0.343x). ModelSize D5:E10: reference architectures (e.g., 8B d_model=4096 not 128). TL_Param!B35 note: batching ≠ latency compression. IO_Sensitivity!O21: OOM flag. Input&Output: Grok totals $0.0068/$0.0499; B22=45000/15500; 'Onput'→'Output'. I487:I488 cleared. | F59: All 11 errors corrected. Key downstream impact: fleet efficiency now 0.271x (correctly between H100 0.25x and GB200 0.32x); VR depreciation $140.0M/yr (was $140.67M); CapEx/GW now shows marginal cost ($25B/GW in 2026E vs old $11.4B). d_model fix flagged but latency values for 8B-700B need full pipeline rerun.

Sheet D_Transformer
A1: Vanilla Decode-Only Transformer | D1: Advanced Decode-Only Transformer

Sheet Context Window Evolution
A1: Context Window Evolution: Model-Level Timeline (2023–2026)
A2: Model | B2: Provider | C2: Release | D2: Context Window | E2: Max Output | F2: Primary Use Cases
A3: GPT-3.5 | B3: OpenAI | C3: 2023 | D3: 4K-16K | E3: 4K | F3: Chatbot, Q&A
A4: GPT-4 | B4: OpenAI | C4: 2023 | D4: 8K-32K | E4: 8K | F4: Reasoning, Code
A5: Claude 2 | B5: Anthropic | C5: 2023 | D5: 100K | E5: ~4K | F5: Doc analysis
A6: Gemini 1.0 Pro | B6: Google | C6: 2023 Q4 | D6: 32K | E6: 8K | F6: Multimodal chat
A7: GPT-4 Turbo | B7: OpenAI | C7: 2024 Q1 | D7: 128K | E7: 4K | F7: Long-doc, Code
A8: Claude 3 Opus | B8: Anthropic | C8: 2024 Q1 | D8: 200K | E8: 4K | F8: Research, Legal
A9: Gemini 1.5 Pro | B9: Google | C9: 2024 Q2 | D9: 1M | E9: 8K | F9: Video, Codebase
A10: Llama 3.1 405B | B10: Meta | C10: 2024 Q3 | D10: 128K | E10: 4K | F10: OSS General
A11: GPT-4.1 | B11: OpenAI | C11: 2025 Q2 | D11: 1M | E11: 32K | F11: Agent, Code
A12: Claude 4.5 Sonnet | B12: Anthropic | C12: 2025 Q3 | D12: 200K | E12: 16K | F12: Coding, Agent
A13: Gemini 2.5 Pro | B13: Google | C13: 2025 Q1 | D13: 1M | E13: 64K | F13: Multimodal, Deep
A14: DeepSeek V3 | B14: DeepSeek | C14: 2025 | D14: 128K | E14: 8K | F14: OSS Reasoning
A15: Llama 4 Scout | B15: Meta | C15: 2025 Q2 | D15: 10M | E15: ~8K | F15: Legal discovery
A16: Claude Opus 4.5/4.6 | B16: Anthropic | C16: 2025 Q4 | D16: 200K | E16: 32K | F16: Deep reasoning
A17: GPT-5.2 | B17: OpenAI | C17: 2025 Q4 | D17: 400K | E17: 32K | F17: Abstract reasoning
A18: Gemini 3 Pro | B18: Google | C18: 2025 Q4 | D18: 1M-10M | E18: 64K | F18: Enterprise multimodal
A20: Input-to-Output Token Ratios Across Real-World Scenarios
A21: Scenario | B21: Input (tokens) | C21: Output (tokens) | D21: I:O Ratio | E21: Typical Context | F21: Description & Real-World Examples
A22: Casual Chatbot | B22: 100-500 | C22: 100-400 | D22: ~1:1 | E22: 4K-8K | F22: Customer service, general Q&A; short turns, rapid exchanges
A23: RAG Q&A System | B23: 2K-8K | C23: 200-800 | D23: ~10:1 | E23: 16K-128K | F23: Enterprise knowledge base; retrieved chunks dominate input
A24: Code Generation | B24: 5K-30K | C24: 500-5K | D24: ~5:1 | E24: 128K-1M | F24: Codebase + prompt; entire repo uploaded for 'vibe coding'
A25: Coding Agent (Agentic) | B25: 10K-50K | C25: 1K-10K | D25: ~5:1 | E25: 128K-1M | F25: Multi-step tool-calling, planning, iterative code edits
A26: Document Summarization | B26: 10K-100K | C26: 500-3K | D26: ~30:1 | E26: 128K-1M | F26: Book-length or report-length text compressed to brief summary
A27: Legal Contract Review | B27: 50K-500K | C27: 2K-10K | D27: ~50:1 | E27: 200K-10M | F27: Full contracts, cross-reference clauses, compliance flagging
A28: Medical Record Analysis | B28: 20K-200K | C28: 1K-5K | D28: ~40:1 | E28: 200K-1M | F28: Multi-page patient records, holistic diagnosis support
A29: Financial Report Analysis | B29: 30K-300K | C29: 2K-8K | D29: ~40:1 | E29: 200K-1M | F29: Annual reports, earnings calls, regulatory filings
A30: Creative Writing | B30: 500-5K | C30: 1K-10K | D30: ~1:2 | E30: 32K-200K | F30: Novels, screenplays; output-heavy with narrative consistency
A31: Roleplay / Interactive Fiction | B31: 1K-5K | C31: 200-2K | D31: ~2:1 | E31: 32K-128K | F31: Character-based dialogue; 60% of roleplay tokens on OpenRouter
A32: Multi-turn Research Agent | B32: 20K-100K | C32: 2K-20K | D32: ~5:1 | E32: 200K-1M | F32: Deep research with web search, tool use, iterative refinement
... A34: Multimodal (Image+Text) | B34: 5K-20K | C34: 500-3K | D34: ~7:1 | E34: 128K-1M | F34: Image tokens add to input; output is text-based analysis
A36: Platform-Level Usage Trends (OpenRouter 100T Token Study)
A37: Metric | B37: Early 2024 / Pre-o1 | C37: Late 2025 / Early 2026 | D37: Key Insight
A38: Avg. Prompt Length | B38: ~1,500 tokens | C38: ~6,000+ tokens | D38: ~4x increase; driven by codebase uploads and agent workflows
A39: Avg. Completion Length | B39: ~150 tokens | C39: ~400 tokens | D39: ~2.7x increase; reasoning models produce longer deliberation traces
A40: Programming Prompts | B40: Often >10K tokens | C40: Often >20K tokens | D40: Entire files/repos passed in; largest driver of prompt complexity
A41: Reasoning Model Share | B41: ~0% (pre-o1) | C41: >50% of all tokens | D41: o1 launched Dec 2024; by late 2025 reasoning models dominate
A42: Tool-Calling Usage | B42: Minimal | C42: Central to high-value workflows | D42: Claude Sonnet and Gemini Flash lead tool-enabled traffic
A43: Open-Source Share | B43: ~15% | C43: ~33% | D43: DeepSeek, Qwen, Kimi K2, MiniMax; Chinese OSS near 30% share
...

Sheet Input&Output
A1: Claude- 200 token prompt 1 round conversation | G1: Claude- 160 token prompt 1 round conversation
A2: Conversation Link | B2: https://claude.ai/share/a8aedabd-a6df-4461-8d01-713e5a3ea16b | G2: Conversation Link | H2: https://grok.com/share/bGVnYWN5LWNvcHk_97f0b6e6-0e3e-433f-aa46-f5b8332efddb
A4: Component | B4: Category | C4: Tokens | D4: Rate | E4: Cost | G4: Component | H4: Token Category | I4: Price (Grok 4.1 Fast) | J4: Price (Grok 4) | K4: Real-World Example
A5: Your system prompt (custom, ~2K) | B5: Input | C5: 2000 | D5: $5/MTok | E5: 0.01 | G5: System prompt | H5: prompt_tokens | I5: $0.20 / M | J5: $3.00 / M | K5: 900 tokens → $0.00018 or $0.0027
A6: Tool definitions (5 tools) | B6: Input | C6: 3000 | D6: $5/MTok | E6: 0.015 | G6: Your user prompt | H6: prompt_tokens | I6: $0.20 / M | J6: $3.00 / M | K6: 160 tokens → $0.000032 or $0.00048
A7: Your user message | B7: Input | C7: 200 | D7: $5/MTok | E7: 0.001 | G7: Tool/search results | H7: prompt_tokens | I7: $0.20 / M | J7: $3.00 / M | K7: 2,400 tokens + $0.005 invocation
A8: Web search results (6 searches)* | B8: Input | C8: ~36,000 | D8: $5/MTok | E8: 0.18 | G8: Internal thinking | H8: reasoning_tokens | I8: $0.50 / M | J8: $15.00 / M | K8: 800 tokens → $0.0004 or $0.012
A9: Skill file content | B9: Input | C9: ~3,500 | D9: $5/MTok | E9: 0.018 | G9: Visible reply (output) | H9: completion_tokens | I9: $0.50 / M | J9: $15.00 / M | K9: 1,500 tokens → $0.00075 or $0.0225
A10: Bash tool outputs | B10: Input | C10: ~200 | D10: $5/MTok | E10: 0.001 | G10: Total* | H10: — | I10: ~$0.0068 | J10: ~$0.0499 | K10: —
A11: Total Input | C11: ~45,000 | E11: 0.225
A12: Tool call outputs (search requests, code) | B12: Output | C12: ~4,000 | D12: $25/MTok | E12: 0.1
A13: Thinking tokens (if enabled) | B13: Output | C13: ~4,000 | D13: $25/MTok | E13: 0.1
A14: Visible reply text | B14: Output | C14: ~2,500 | D14: $25/MTok | E14: 0.063
A15: Generated code (docx script) | B15: Output | C15: ~5,000 | D15: $25/MTok | E15: 0.125
A16: Total Output | C16: ~15,500 | E16: 0.388
A17: GRAND TOTAL | C17: ~60,500 | E17: ~$0.61
A18: * Tool call (1$10/1000 call) may apply | G18: *Tool invocations fee may apply(e.g., web_search = $5 / 1,000 calls; live search = $25 / 1,000 sources)
A20: Total input/Prompt | B20: =45000/C7 -> 225 | G20: Total input/Prompt | H20: =(900+160+2400)/160 -> 21.625
A21: Total Output/Visible reply | B21: =15500/(2500+5000) -> 2.0666667 | G21: Total Output/Visible reply | H21: =(800+1500)/1500 -> 1.5333333
A22: Total Input/Total Output | B22: =45000/15500 -> 2.9032258 | G22: Total Input/Total Output | H22: =(900+160+2400)/(800+1500) -> 1.5043478

Sheet Flowchart_TL
A2: \\\\\\\\\\\\\\\\\\\\\\\ | B2: Transformer Inference Pipeline — Optimization Flow (VR72 / 1.5T / 1M input, 1M output)
A4: `
B5: ① BASE LINE | D5: 1. Tokenization (CPU) Duration: 0.050s Bottleneck: CPU | I5: 2. Embedding Lookup + Broadcast Duration: 0.001s Bottleneck: Memory (HBM BW) | N5: 3. Prefill + KV Cache Write Duration: 22.85s Bottleneck: Compute (GPU) | S5: 4. Decode First Token Duration: 0.006s Bottleneck: Memory (HBM BW) | X5: 5. Decode All Tokens Duration: 6,428.69s Bottleneck: Memory (HBM BW) | AC5: 6. De-tokenization (CPU) Duration: 0.050s Bottleneck: CPU | AH5: E2E Total 6,451.64s Avg/Token: 0.00645s
H6: → | M6: → | R6: → | W6: → | AB6: → | AG6: →
X9: ▼ 8.4× faster (6,429→768s)
B10: ⬇ Optimization: GQA + Concurrent Requests (Batch Size 50) + Speculative Decoding ⬇
B12: ② GQA+ BATCH+ SPEC | D12: 1. Tokenization (CPU) Duration: 0.050s Bottleneck: CPU | I12: 2. Embedding Lookup + Broadcast Duration: 0.0003s Bottleneck: NVLink | N12: 3. Prefill + KV Cache Write Duration: 1,142.36s Bottleneck: Compute (GPU) | S12: 4. Decode First Token Duration: 0.001s Bottleneck: Memory (HBM BW) | X12: 5. Decode All Tokens Duration: 767.90s Bottleneck: NV Link | AC12: 6. De-tokenization (CPU) Duration: 0.050s Bottleneck: CPU | AH12: E2E Total 1,910.36s Avg/Token: 0.0000382s
H13: → | M13: → | R13: → | W13: → | AB13: → | AG13: →
X16: ▼ 2.9× faster (768→269s)
B17: ⬇ Optimization: + NVLink Optimization ⬇
B19: ③ +NV LINK OPT | D19: 1. Tokenization (CPU) Duration: 0.050s Bottleneck: CPU | I19: 2. Embedding Lookup + Broadcast Duration: 0.0003s Bottleneck: NVLink | N19: 3. Prefill + KV Cache Write Duration: 1,142.36s Bottleneck: Compute (GPU) | S19: 4. Decode First Token Duration: 0.001s Bottleneck: Memory (HBM BW) | X19: 5. Decode All Tokens Duration: 268.60s Bottleneck: Memory (HBM BW) | AC19: 6. De-tokenization (CPU) Duration: 0.050s Bottleneck: CPU | AH19: E2E Total 1,411.06s Avg/Token: 0.0000282s
H20: → | M20: → | R20: → | W20: → | AB20: → | AG20: →
AH23: Total: 4.6× E2E Speedup 229× better per-token latency
B25: Performance Comparison Summary
B27: Configuration | G27: E2E Time (s) | K27: Decode-All (s) | O27: Avg Time/Token (s) | S27: Speedup vs Base | W27: Key Bottleneck | AA27: Primary Optimizations | AG27: Legend
B28: ① Base Line | G28: 6451.64 | K28: 6428.69 | O28: 0.006452 | S28: 1.0× | W28: Decode-All (HBM BW) | AA28: None | AH28: Standard step
B29: ② GQA + Batch + Spec | G29: 1910.36 | K29: 767.9 | O29: 3.82e-05 | S29: 169× | W29: Prefill (Compute), Decode (HBM) | AA29: GQA, Batch=50, Speculative Decoding | AH29: Dominant bottleneck
B30: ③ + NVLink Opt | G30: 1411.06 | K30: 268.6 | O30: 2.82e-05 | S30: 229× | W30: Prefill (Compute), Decode (HBM) | AA30: +@ NVLink Optimization | AH30: Optimized step

Sheet TL_VR72_1.5T_1M1M
B1: Base Line
A2: # | B2: Step(time in s) | C2: Start Time | D2: Duration | E2: End Time | F2: Compute Time | G2: HBM BW Time | H2: NVLink Time | I2: Bottleneck | J2: Dominant Resource | K2: FLOPs Used | L2: HBM Bytes Moved
A3: 1 | B3: Tokenization (CPU) | C3: 0 | D3: 0.05 | E3: =C3+D3 -> 0.05 | F3: N/A(CPU) | G3: N/A | H3: N/A | I3: CPU | J3: CPU | K3: 0 | L3: 0
A4: 2 | B4: Embedding Lookup + Broadcast | C4: =E3 -> 0.05 | D4: =G4+H4 -> 0.00031235999 | E4: =C4+D4 -> 0.05031236 | F4: 0 | G4: ='WP_VR72_1.5T_1M1M'!B28*'WP_VR72_1.5T_1M1M'!B29/('WP_VR72_1.5T_1M1M'!B15*1000000000000) -> 1.6591392e-06 | H4: =2*'WP_VR72_1.5T_1M1M'!B22*'WP_VR72_1.5T_1M1M'!B29*2*(71/72)/('WP_VR72_1.5T_1M1M'!B12*1000000000000) -> 0.00031070085 | I4: Memory | J4: HBM BW | K4: 0 | L4: ='WP_VR72_1.5T_1M1M'!B22*'WP_VR72_1.5T_1M1M'!B29+'WP_VR72_1.5T_1M1M'!B28*'WP_VR72_1.5T_1M1M'!B29 -> 23101440000
A5: 3 | B5: Prefill+KV Cache Write | C5: =E4 -> 0.05031236 | D5: =F5+H5 -> 22.847222 | E5: =C5+D5 -> 22.897535 | F5: ='WP_VR72_1.5T_1M1M'!B70 -> 21.415513 | G5: ='WP_VR72_1.5T_1M1M'!B87 -> 0.01422438 | H5: ='WP_VR72_1.5T_1M1M'!B97 -> 1.4317095 | I5: Compute | J5: GPU | K5: ='WP_VR72_1.5T_1M1M'!B65 -> 1.3491773e+19 | L5: ='WP_VR72_1.5T_1M1M'!B84 -> 22474520000000
A6: 4 | B6: Decode-First Token | C6: =E5 -> 22.897535 | D6: =G6 -> 0.0064286869 | E6: =C6+D6 -> 22.903963 | F6: ='WP_VR72_1.5T_1M1M'!B121 -> 1.4868762e-05 | G6: ='WP_VR72_1.5T_1M1M'!B151 -> 0.0064286869 | H6: - | I6: Memory | J6: HBM BW | K6: ='WP_VR72_1.5T_1M1M'!B117 -> 18734640000000 | L6: ='WP_VR72_1.5T_1M1M'!B135 -> 9367325242880
A7: 5 | B7: Decode-All Tokens | C7: =E6 -> 22.903963 | D7: =G7+H7 -> 6428.6869 | E7: =C7+D7 -> 6451.5908 | F7: ='WP_VR72_1.5T_1M1M'!B122 -> 14.868762 | G7: ='WP_VR72_1.5T_1M1M'!B138*'WP_VR72_1.5T_1M1M'!B23 -> 5928.6869 | H7: ='WP_VR72_1.5T_1M1M'!B149*'WP_VR72_1.5T_1M1M'!B23 -> 500 | I7: Memory | J7: HBM BW | K7: ='WP_VR72_1.5T_1M1M'!B118 -> 1.873464e+19 | L7: ='WP_VR72_1.5T_1M1M'!B135*'WP_VR72_1.5T_1M1M'!B23 -> 9.3673252e+18
A8: 6 | B8: De-tokenization (CPU) | C8: =E7 -> 6451.5908 | D8: 0.05 | E8: =C8+D8 -> 6451.6408 | F8: N/A(CPU) | G8: N/A | H8: N/A | I8: CPU | J8: CPU | K8: 0 | L8: 0
B9: Avg Time per Output Token (s) | E9: =E8/'WP_VR72_1.5T_1M1M'!B23 -> 0.0064516408
B10: Output token per second | E10: =1/E9 -> 154.99933
B12: Optimized-GQA + Concurrent Requests - Batch Size + Speculative Decoding
A13: # | B13: Step(time in s) | C13: Start Time | D13: Duration | E13: End Time | F13: Compute Time | G13: HBM BW Time | H13: NVLink Time | I13: Bottleneck | J13: Dominant Resource | K13: FLOPs Used | L13: HBM Bytes Moved
A14: 1 | B14: Tokenization (CPU) | C14: 0 | D14: 0.05 | E14: =C14+D14 -> 0.05 | F14: N/A(CPU) | G14: N/A | H14: N/A | I14: CPU | J14: CPU | K14: 0 | L14: 0
A15: 2 | B15: Embedding Lookup + Broadcast | C15: =E14 -> 0.05 | D15: =G15+H15 -> 0.00031235999 | E15: =C15+D15 -> 0.05031236 | F15: 0 | G15: ='WP_VR72_1.5T_1M1M'!B28*'WP_VR72_1.5T_1M1M'!B29/('WP_VR72_1.5T_1M1M'!B15*1000000000000) -> 1.6591392e-06 | H15: =2*'WP_VR72_1.5T_1M1M'!B22*'WP_VR72_1.5T_1M1M'!B29*2*(71/72)/('WP_VR72_1.5T_1M1M'!B12*1000000000000) -> 0.00031070085 | I15: NVLink | J15: NVLink | K15: 0 | L15: ='WP_VR72_1.5T_1M1M'!B22*'WP_VR72_1.5T_1M1M'!B29+'WP_VR72_1.5T_1M1M'!B28*'WP_VR72_1.5T_1M1M'!B29 -> 23101440000
A16: 3 | B16: Prefill+KV Cache Write | C16: =E15 -> 0.05031236 | D16: =F16+H16 -> 1142.3611 | E16: =C16+D16 -> 1142.4114 | F16: ='WP_VR72_1.5T_1M1M'!B70*'WP_VR72_1.5T_1M1M'!B169 -> 1070.7756 | G16: ='WP_VR72_1.5T_1M1M'!B87*'WP_VR72_1.5T_1M1M'!B169 -> 0.71121899 | H16: ='WP_VR72_1.5T_1M1M'!B97*'WP_VR72_1.5T_1M1M'!B169 -> 71.585477 | I16: Compute | J16: GPU | K16: ='WP_VR72_1.5T_1M1M'!B65*'WP_VR72_1.5T_1M1M'!B169 -> 6.7458866e+20 | L16: ='WP_VR72_1.5T_1M1M'!B84*'WP_VR72_1.5T_1M1M'!B169 -> 1.123726e+15
A17: 4 | B17: Decode-First Token | C17: =E16 -> 1142.4114 | D17: =G17 -> 0.0012001367 | E17: =C17+D17 -> 1142.4126 | F17: ='WP_VR72_1.5T_1M1M'!B121 -> 1.4868762e-05 | G17: ='WP_VR72_1.5T_1M1M'!B164 -> 0.0012001367 | H17: - | I17: Memory | J17: HBM BW | K17: ='WP_VR72_1.5T_1M1M'!B117 -> 18734640000000 | L17: ='WP_VR72_1.5T_1M1M'!B163 -> 1896216000000
A18: 5 | B18: Decode-All Tokens | C18: =E17 -> 1142.4126 | D18: =G18+H18 -> 767.8962 | E18: =C18+D18 -> 1910.3088 | F18: ='WP_VR72_1.5T_1M1M'!B122 -> 14.868762 | G18: ='WP_VR72_1.5T_1M1M'!B172*'WP_VR72_1.5T_1M1M'!B23 -> 267.8962 | H18: ='WP_VR72_1.5T_1M1M'!B149*'WP_VR72_1.5T_1M1M'!B23 -> 500 | I18: NV Link | J18: NV Link | K18: ='WP_VR72_1.5T_1M1M'!B118 -> 1.873464e+19 | L18: ='WP_VR72_1.5T_1M1M'!B171*'WP_VR72_1.5T_1M1M'!B23 -> 2.11638e+19
A19: 6 | B19: De-tokenization (CPU) | C19: =E18 -> 1910.3088 | D19: 0.05 | E19: =C19+D19 -> 1910.3588 | F19: N/A(CPU) | G19: N/A | H19: N/A | I19: CPU | J19: CPU | K19: 0 | L19: 0
B20: Avg Time per Output Token (s) | E20: =E19/('WP_VR72_1.5T_1M1M'!B169*'WP_VR72_1.5T_1M1M'!B23) -> 3.8207177e-05 | G20: E2E / (Batch * Output) = Total / (50 * 1000000)
B21: Output token per second | E21: =1/E20 -> 26173.093 | F21: =E9/E20 -> 168.8594
B23: Optimized-GQA + Concurrent Requests - Batch Size + Speculative Decoding + NVLink Optimization
A24: # | B24: Step(time in s) | C24: Start Time | D24: Duration | E24: End Time | F24: Compute Time | G24: HBM BW Time | H24: NVLink Time | I24: Bottleneck | J24: Dominant Resource | K24: FLOPs Used | L24: HBM Bytes Moved
A25: 1 | B25: Tokenization (CPU) | C25: 0 | D25: 0.05 | E25: =C25+D25 -> 0.05 | F25: N/A(CPU) | G25: N/A | H25: N/A | I25: CPU | J25: CPU | K25: 0 | L25: 0
A26: 2 | B26: Embedding Lookup + Broadcast | C26: =E25 -> 0.05 | D26: =G26+H26 -> 0.00031235999 | E26: =C26+D26 -> 0.05031236 | F26: 0 | G26: ='WP_VR72_1.5T_1M1M'!B28*'WP_VR72_1.5T_1M1M'!B29/('WP_VR72_1.5T_1M1M'!B15*1000000000000) -> 1.6591392e-06 | H26: =2*'WP_VR72_1.5T_1M1M'!B22*'WP_VR72_1.5T_1M1M'!B29*2*(71/72)/('WP_VR72_1.5T_1M1M'!B12*1000000000000) -> 0.00031070085 | I26: NVLink | J26: NVLink | K26: 0 | L26: ='WP_VR72_1.5T_1M1M'!B22*'WP_VR72_1.5T_1M1M'!B29+'WP_VR72_1.5T_1M1M'!B28*'WP_VR72_1.5T_1M1M'!B29 -> 23101440000
A27: 3 | B27: Prefill+KV Cache Write | C27: =E26 -> 0.05031236 | D27: =F27+H27 -> 1142.3611 | E27: =C27+D27 -> 1142.4114 | F27: ='WP_VR72_1.5T_1M1M'!B70*'WP_VR72_1.5T_1M1M'!B169 -> 1070.7756 | G27: ='WP_VR72_1.5T_1M1M'!B87*'WP_VR72_1.5T_1M1M'!B169 -> 0.71121899 | H27: ='WP_VR72_1.5T_1M1M'!B97*'WP_VR72_1.5T_1M1M'!B169 -> 71.585477 | I27: Compute | J27: GPU | K27: ='WP_VR72_1.5T_1M1M'!B65*'WP_VR72_1.5T_1M1M'!B169 -> 6.7458866e+20 | L27: ='WP_VR72_1.5T_1M1M'!B84*'WP_VR72_1.5T_1M1M'!B169 -> 1.123726e+15
A28: 4 | B28: Decode-First Token | C28: =E27 -> 1142.4114 | D28: =G28 -> 0.0012001367 | E28: =C28+D28 -> 1142.4126 | F28: ='WP_VR72_1.5T_1M1M'!B121 -> 1.4868762e-05 | G28: ='WP_VR72_1.5T_1M1M'!B164 -> 0.0012001367 | H28: - | I28: Memory | J28: HBM BW | K28: ='WP_VR72_1.5T_1M1M'!B117 -> 18734640000000 | L28: ='WP_VR72_1.5T_1M1M'!B163 -> 1896216000000
A29: 5 | B29: Decode-All Tokens | C29: =E28 -> 1142.4126 | D29: =G29+H29 -> 268.60197 | E29: =C29+D29 -> 1411.0146 | F29: ='WP_VR72_1.5T_1M1M'!B122 -> 14.868762 | G29: ='WP_VR72_1.5T_1M1M'!B172*'WP_VR72_1.5T_1M1M'!B23 -> 267.8962 | H29: ='WP_VR72_1.5T_1M1M'!B206 -> 0.70577231 | I29: Memory | J29: HBM BW | K29: ='WP_VR72_1.5T_1M1M'!B118 -> 1.873464e+19 | L29: ='WP_VR72_1.5T_1M1M'!B171*'WP_VR72_1.5T_1M1M'!B23 -> 2.11638e+19
A30: 6 | B30: De-tokenization (CPU) | C30: =E29 -> 1411.0146 | D30: 0.05 | E30: =C30+D30 -> 1411.0646 | F30: N/A(CPU) | G30: N/A | H30: N/A | I30: CPU | J30: CPU | K30: 0 | L30: 0
B31: Avg Time per Output Token (s) | E31: =E30/('WP_VR72_1.5T_1M1M'!B169*'WP_VR72_1.5T_1M1M'!B23) -> 2.8221292e-05 | G31: E2E / (Batch * Output) = Total / (50 * 1000000)
B32: Output token per second | E32: =1/E31 -> 35434.239 | F32: =E9/E31 -> 228.60898

Sheet WP_VR72_1.5T_1M1M
A1: AI DC Spec. | B1: Data | C1: Note
A2: Total power(W) | B2: =1000000000 -> 1000000000
A3: PUE | B3: 1.2
A4: Rack Type | B4: Vera Rubin NVL72
A5: No.of racks | B5: 4386
A7: Rack Spec. | B7: Data | C7: Note
A8: CPU Type | B8: Vera CPU
A9: No. of CPU | B9: 36
A10: GPU Type | B10: Rubin GPU
A11: No. of GPU | B11: 72
A12: NVLink Bandwidth(TB/s) | B12: 260
A13: NVLink-C2C Bandwidth(TB/s) | B13: 65
A14: GPU Memory(TB) | B14: 20.7 | C14: 0.288/GPU
A15: Memory Bandwidth(TB) | B15: 1580 | C15: 22/GPU
A16: NVFP4 Inference(PFLOPS) | B16: 3600 | C16: 50/GPU
A17: NVFP4 Training(PFLOPS) | B17: =72*35 -> 2520 | C17: 35/GPU
A18: FP8/FP16 Training(PFLOPS) | B18: =17.5*72 -> 1260 | C18: 17.5/GPU
A19: FP16/BF16 | B19: =72*4 -> 288 | C19: 4/GPU
A21: Input/Output Tokens Setup | B21: Data | C21: Note
A22: Input Tokens: | B22: 1000000
A23: Output Tokens: | B23: 1000000
A25: Model Spec. | B25: Data | C25: Note
A26: Parameters | B26: 1503000000000 | C26: Given, 1.503T/128=11.744B Per Layer
A27: Type | B27: Dense
A28: vocab size(V) | B28: 128000
A29: Hidden Dimension(d_model) | B29: 20480 | C29: Given
A30: n_layers | B30: 128 | C30: Given
A31: n_heads | B31: 160
A32: d_head | B32: =B29/B31 -> 128
A33: d_ff(SwiGLU) | B33: =(B26/B30-4*B29^2)/(3*B29) -> 163809.67 | C33: derived:1.5 × 10¹² = 128 × (4 × 20,480² + 3 × 20,480 × d_ff)
A34: Parameters per Layer(Att) | B34: =4*B29^2 -> 1677721600 | C34: Q_W+K_W+V_W+O_W=4*20480^2
A35: Parameters per Layer(FFN) | B35: =3*B29*B33 -> 10064465900 | C35: FFN(x) = [SiLU(x · W_gate) ⊙ (x · W_up)] · W_down~= 3 × 20,480 × d_ff
A36: Total Parameters per Layer | B36: =B34+B35 -> 11742187500
A37: Weight Memory(Byte) | B37: =B26*1 -> 1503000000000 | C37: FP8, 1 parameter= 1 Byte
A38: Weight Memory(Byte)/GPU | B38: =B37/B11 -> 20875000000
A39: KV cache @ Begining(Byte) | B39: =2*B29*B22*B30 -> 5242880000000 | C39: K=V=d_model*layer*no.of Input tokens, Total =K+V
A40: KV cache @ End(Byte) | B40: =2*B29*(B22+B23)*B30 -> 10485760000000 | C40: K=V=d_model*layer*no.of (Input +Output tokens, Total =K+V
A41: KV cache per GPU @ End | B41: =B40/B11 -> 1.4563556e+11
A42: Memory required per GPU | B42: =B41+B38 -> 1.6651056e+11 | C42: Need addition memory for Activations
A43: GPU Memory Headroom | B43: =B14/B11*1000000000000-B42 -> 1.2098944e+11 | C43: Check if GPU has enough memory
...

Sheet TL_VR72_1T_1M1000
B1: Base Line
A2: # | B2: Step(time in s) | C2: Start Time | D2: Duration | E2: End Time | F2: Compute Time | G2: HBM BW Time | H2: NVLink Time | I2: Bottleneck | J2: Dominant Resource | K2: FLOPs Used | L2: HBM Bytes Moved
A3: 1 | B3: Tokenization (CPU) | C3: 0 | D3: 0.05 | E3: =C3+D3 -> 0.05 | F3: N/A(CPU) | G3: N/A | H3: N/A | I3: CPU | J3: CPU | K3: 0 | L3: 0
A4: 2 | B4: Embedding Lookup + Broadcast | C4: =E3 -> 0.05 | D4: =G4+H4 -> 0.00031235999 | E4: =C4+D4 -> 0.05031236 | F4: 0 | G4: =WP_VR72_1T_1M1000!B28*WP_VR72_1T_1M1000!B29/(WP_VR72_1T_1M1000!B15*1000000000000) -> 1.6591392e-06 | H4: =2*WP_VR72_1T_1M1000!B22*WP_VR72_1T_1M1000!B29*2*(71/72)/(WP_VR72_1T_1M1000!B12*1000000000000) -> 0.00031070085 | I4: NVLink | J4: NVLink | K4: 0 | L4: =WP_VR72_1T_1M1000!B22*WP_VR72_1T_1M1000!B29+WP_VR72_1T_1M1000!B28*WP_VR72_1T_1M1000!B29 -> 23101440000
A5: 3 | B5: Prefill+KV Cache Write | C5: =E4 -> 0.05031236 | D5: =F5+H5 -> 21.250397 | E5: =C5+D5 -> 21.300709 | F5: =WP_VR72_1T_1M1000!B70 -> 19.818687 | G5: =WP_VR72_1T_1M1000!B87 -> 0.013906025 | H5: =WP_VR72_1T_1M1000!B97 -> 1.4317095 | I5: Compute | J5: GPU | K5: =WP_VR72_1T_1M1000!B65 -> 1.2485773e+19 | L5: =WP_VR72_1T_1M1000!B84 -> 21971520000000
A6: 4 | B6: Decode-First Token | C6: =E5 -> 21.300709 | D6: =G6 -> 0.0044528523 | E6: =C6+D6 -> 21.305162 | F6: =WP_VR72_1T_1M1000!B121 -> 9.9134943e-06 | G6: =WP_VR72_1T_1M1000!B151 -> 0.0044528523 | H6: - | I6: Memory | J6: HBM BW | K6: =WP_VR72_1T_1M1000!B117 -> 12491002880000 | L6: =WP_VR72_1T_1M1000!B135 -> 6245506682880
A7: 5 | B7: Decode-All Tokens | C7: =E6 -> 21.305162 | D7: =G7+H7 -> 4.4528523 | E7: =C7+D7 -> 25.758015 | F7: =WP_VR72_1T_1M1000!B122 -> 0.0099134943 | G7: =WP_VR72_1T_1M1000!B138*WP_VR72_1T_1M1000!B23 -> 3.9528523 | H7: =WP_VR72_1T_1M1000!B149*WP_VR72_1T_1M1000!B23 -> 0.5 | I7: Memory | J7: HBM BW | K7: =WP_VR72_1T_1M1000!B118 -> 1.2491003e+16 | L7: =WP_VR72_1T_1M1000!B135*WP_VR72_1T_1M1000!B23 -> 6.2455067e+15
A8: 6 | B8: De-tokenization (CPU) | C8: =E7 -> 25.758015 | D8: 0.05 | E8: =C8+D8 -> 25.808015 | F8: N/A(CPU) | G8: N/A | H8: N/A | I8: CPU | J8: CPU | K8: 0 | L8: 0
B9: Avg Time per Output Token (s) | D9: =E8/(WP_VR72_1T_1M1000!B23) -> 0.025808015
B11: Optimized-GQA + Concurrent Requests - Batch Size + Speculative Decoding
A12: # | B12: Step(time in s) | C12: Start Time | D12: Duration | E12: End Time | F12: Compute Time | G12: HBM BW Time | H12: NVLink Time | I12: Bottleneck | J12: Dominant Resource | K12: FLOPs Used | L12: HBM Bytes Moved
A13: 1 | B13: Tokenization (CPU) | C13: 0 | D13: 0.05 | E13: =C13+D13 -> 0.05 | F13: N/A(CPU) | G13: N/A | H13: N/A | I13: CPU | J13: CPU | K13: 0 | L13: 0
A14: 2 | B14: Embedding Lookup + Broadcast | C14: =E13 -> 0.05 | D14: =G14+H14 -> 0.00031235999 | E14: =C14+D14 -> 0.05031236 | F14: 0 | G14: =WP_VR72_1T_1M1000!B28*WP_VR72_1T_1M1000!B29/(WP_VR72_1T_1M1000!B15*1000000000000) -> 1.6591392e-06 | H14: =2*WP_VR72_1T_1M1000!B22*WP_VR72_1T_1M1000!B29*2*(71/72)/(WP_VR72_1T_1M1000!B12*1000000000000) -> 0.00031070085 | I14: NVLink | J14: NVLink | K14: 0 | L14: =WP_VR72_1T_1M1000!B22*WP_VR72_1T_1M1000!B29+WP_VR72_1T_1M1000!B28*WP_VR72_1T_1M1000!B29 -> 23101440000
A15: 3 | B15: Prefill+KV Cache Write | C15: =E14 -> 0.05031236 | D15: =F15+H15 -> 1360.0254 | E15: =C15+D15 -> 1360.0757 | F15: =WP_VR72_1T_1M1000!B70*WP_VR72_1T_1M1000!B169 -> 1268.396 | G15: =WP_VR72_1T_1M1000!B87*WP_VR72_1T_1M1000!B169 -> 0.88998562 | H15: =WP_VR72_1T_1M1000!B97*WP_VR72_1T_1M1000!B169 -> 91.62941 | I15: Compute | J15: GPU | K15: =WP_VR72_1T_1M1000!B65*WP_VR72_1T_1M1000!B169 -> 7.9908948e+20 | L15: =WP_VR72_1T_1M1000!B84*WP_VR72_1T_1M1000!B169 -> 1.4061773e+15
A16: 4 | B16: Decode-First Token | C16: =E15 -> 1360.0757 | D16: =G16 -> 0.00079890827 | E16: =C16+D16 -> 1360.0765 | F16: =WP_VR72_1T_1M1000!B121 -> 9.9134943e-06 | G16: =WP_VR72_1T_1M1000!B164 -> 0.00079890827 | H16: - | I16: Memory | J16: HBM BW | K16: =WP_VR72_1T_1M1000!B117 -> 12491002880000 | L16: =WP_VR72_1T_1M1000!B163 -> 1262275072000
A17: 5 | B17: Decode-All Tokens | C17: =E16 -> 1360.0765 | D17: =G17+H17 -> 0.67588612 | E17: =C17+D17 -> 1360.7524 | F17: =WP_VR72_1T_1M1000!B122 -> 0.0099134943 | G17: =WP_VR72_1T_1M1000!B172*WP_VR72_1T_1M1000!B23 -> 0.17588612 | H17: =WP_VR72_1T_1M1000!B149*WP_VR72_1T_1M1000!B23 -> 0.5 | I17: NVLink | J17: NVLink | K17: =WP_VR72_1T_1M1000!B118 -> 1.2491003e+16 | L17: =WP_VR72_1T_1M1000!B171*WP_VR72_1T_1M1000!B23 -> 1.7785605e+16
A18: 6 | B18: De-tokenization (CPU) | C18: =E17 -> 1360.7524 | D18: 0.05 | E18: =C18+D18 -> 1360.8024 | F18: N/A(CPU) | G18: N/A | H18: N/A | I18: CPU | J18: CPU | K18: 0 | L18: 0
B19: Avg Time per Output Token (s) | D19: =E18/(WP_VR72_1T_1M1000!B169*WP_VR72_1T_1M1000!B23) -> 0.021262538 | G19: E2E / (Batch * Output) = Total / (64 * 1000)
A22: Optimized-GQA + Concurrent Requests - Batch Size + Speculative Decoding + NVLink Optimization
A23: # | B23: Step(time in s) | C23: Start Time | D23: Duration | E23: End Time | F23: Compute Time | G23: HBM BW Time | H23: NVLink Time | I23: Bottleneck | J23: Dominant Resource | K23: FLOPs Used | L23: HBM Bytes Moved
A24: 1 | B24: Tokenization (CPU) | C24: 0 | D24: 0.05 | E24: =C24+D24 -> 0.05 | F24: N/A(CPU) | G24: N/A | H24: N/A | I24: CPU | J24: CPU | K24: 0 | L24: 0
A25: 2 | B25: Embedding Lookup + Broadcast | C25: =E24 -> 0.05 | D25: =G25+H25 -> 0.00031235999 | E25: =C25+D25 -> 0.05031236 | F25: 0 | G25: =WP_VR72_1T_1M1000!B28*WP_VR72_1T_1M1000!B29/(WP_VR72_1T_1M1000!B15*1000000000000) -> 1.6591392e-06 | H25: =2*WP_VR72_1T_1M1000!B22*WP_VR72_1T_1M1000!B29*2*(71/72)/(WP_VR72_1T_1M1000!B12*1000000000000) -> 0.00031070085 | I25: NVLink | J25: NVLink | K25: 0 | L25: =WP_VR72_1T_1M1000!B22*WP_VR72_1T_1M1000!B29+WP_VR72_1T_1M1000!B28*WP_VR72_1T_1M1000!B29 -> 23101440000
A26: 3 | B26: Prefill+KV Cache Write | C26: =E25 -> 0.05031236 | D26: =F26+H26 -> 1360.0254 | E26: =C26+D26 -> 1360.0757 | F26: =WP_VR72_1T_1M1000!B70*WP_VR72_1T_1M1000!B169 -> 1268.396 | G26: =WP_VR72_1T_1M1000!B87*WP_VR72_1T_1M1000!B169 -> 0.88998562 | H26: =WP_VR72_1T_1M1000!B97*WP_VR72_1T_1M1000!B169 -> 91.62941 | I26: Compute | J26: GPU | K26: =WP_VR72_1T_1M1000!B65*WP_VR72_1T_1M1000!B169 -> 7.9908948e+20 | L26: =WP_VR72_1T_1M1000!B84*WP_VR72_1T_1M1000!B169 -> 1.4061773e+15
A27: 4 | B27: Decode-First Token | C27: =E26 -> 1360.0757 | D27: =G27 -> 0.00079890827 | E27: =C27+D27 -> 1360.0765 | F27: =WP_VR72_1T_1M1000!B121 -> 9.9134943e-06 | G27: =WP_VR72_1T_1M1000!B164 -> 0.00079890827 | H27: - | I27: Memory | J27: HBM BW | K27: =WP_VR72_1T_1M1000!B117 -> 12491002880000 | L27: =WP_VR72_1T_1M1000!B163 -> 1262275072000
A28: 5 | B28: Decode-All Tokens | C28: =E27 -> 1360.0765 | D28: =G28+H28 -> 0.17659189 | E28: =C28+D28 -> 1360.2531 | F28: =WP_VR72_1T_1M1000!B122 -> 0.0099134943 | G28: =WP_VR72_1T_1M1000!B172*WP_VR72_1T_1M1000!B23 -> 0.17588612 | H28: =WP_VR72_1T_1M1000!B206 -> 0.00070577231 | I28: Memory | J28: HBM BW | K28: =WP_VR72_1T_1M1000!B118 -> 1.2491003e+16 | L28: =WP_VR72_1T_1M1000!B171*WP_VR72_1T_1M1000!B23 -> 1.7785605e+16
A29: 6 | B29: De-tokenization (CPU) | C29: =E28 -> 1360.2531 | D29: 0.05 | E29: =C29+D29 -> 1360.3031 | F29: N/A(CPU) | G29: N/A | H29: N/A | I29: CPU | J29: CPU | K29: 0 | L29: 0
B30: Avg Time per Output Token (s) | D30: =E29/(WP_VR72_1T_1M1000!B169*WP_VR72_1T_1M1000!B23) -> 0.021254736 | G30: E2E / (Batch * Output) = Total / (64 * 1000)

Sheet WP_VR72_1T_1M1000
A1: zzxxxxq21 | B1: Data | C1: Note
A2: Total power(W) | B2: =1000000000 -> 1000000000
A3: PUE | B3: 1.2
A4: Rack Type | B4: Vera Rubin NVL72
A5: No.of racks | B5: 4386
A7: Rack Spec. | B7: Data | C7: Note
A8: CPU Type | B8: Vera CPU
A9: No. of CPU | B9: 36
A10: GPU Type | B10: Rubin GPU
A11: No. of GPU | B11: 72
A12: NVLink Bandwidth(TB/s) | B12: 260
A13: NVLink-C2C Bandwidth(TB/s) | B13: 65
A14: GPU Memory(TB) | B14: 20.7 | C14: 0.288/GPU
A15: Memory Bandwidth(TB) | B15: 1580 | C15: 22/GPU
A16: NVFP4 Inference(PFLOPS) | B16: 3600 | C16: 50/GPU
A17: NVFP4 Training(PFLOPS) | B17: =72*35 -> 2520 | C17: 35/GPU
A18: FP8/FP16 Training(PFLOPS) | B18: =17.5*72 -> 1260 | C18: 17.5/GPU
A19: FP16/BF16 | B19: =72*4 -> 288 | C19: 4/GPU
A21: Input/Output Tokens Setup | B21: Data | C21: Note
A22: Input Tokens: | B22: 1000000
A23: Output Tokens: | B23: 1000
A25: Model Spec. | B25: Data | C25: Note
A26: Parameters | B26: 1000000000000 | C26: Given, 1.503T/128=11.744B Per Layer
A27: Type | B27: Dense
A28: vocab size(V) | B28: 128000
A29: Hidden Dimension(d_model) | B29: =IF(B26<100000000,B26^(1/4),2^11*10^LOG((B26/10^11))) -> 20480 | C29: Given
A30: n_layers | B30: 128 | C30: Given
A31: n_heads | B31: 160
A32: d_head | B32: =B29/B31 -> 128
A33: d_ff(SwiGLU) | B33: =(B26/B30-4*B29^2)/(3*B29) -> 99849.909 | C33: derived:1.5 × 10¹² = 128 × (4 × 20,480² + 3 × 20,480 × d_ff)
A34: Parameters per Layer(Att) | B34: =4*B29^2 -> 1677721600 | C34: Q_W+K_W+V_W+O_W=4*20480^2
A35: Parameters per Layer(FFN) | B35: =3*B29*B33 -> 6134778400 | C35: FFN(x) = [SiLU(x · W_gate) ⊙ (x · W_up)] · W_down~= 3 × 20,480 × d_ff
A36: Total Parameters per Layer | B36: =B34+B35 -> 7812500000
A37: Weight Memory(Byte) | B37: =B26*1 -> 1000000000000 | C37: FP8, 1 parameter= 1 Byte
A38: Weight Memory(Byte)/GPU | B38: =B37/B11 -> 1.3888889e+10
A39: KV cache @ Begining(Byte) | B39: =2*B29*B22*B30 -> 5242880000000 | C39: K=V=d_model*layer*no.of Input tokens, Total =K+V
A40: KV cache @ End(Byte) | B40: =2*B29*(B22+B23)*B30 -> 5248122880000 | C40: K=V=d_model*layer*no.of (Input +Output tokens, Total =K+V
A41: KV cache per GPU @ End | B41: =B40/B11 -> 7.2890596e+10
A42: Memory required per GPU | B42: =B41+B38 -> 8.6779484e+10 | C42: Need addition memory for Activations
A43: GPU Memory Headroom | B43: =B14/B11*1000000000000-B42 -> 2.0072052e+11 | C43: Check if GPU has enough memory
...

Sheet Config
A1: PARAMETERIZED TOKEN GENERATION PIPELINE | E1: RACK PRESETS
A2: Change the blue cells below to experiment with different configurations | E2: Copy a column into Column B to switch racks
A4: AI DC Spec. | B4: Data | C4: Note | E4: AI DC Spec. | F4: Vera Rubin NVL72 | G4: GB200 NVL72 | H4: Note
A5: Total power(W) | B5: =IF($B$7=F$4,F5,G5) -> 1000000000 | E5: Total power(W) | F5: 1000000000 | G5: 1000000000
A6: PUE | B6: =IF($B$7=F$4,F6,G6) -> 1.2 | E6: PUE | F6: 1.2 | G6: 1.2
A7: Rack Type | B7: Vera Rubin NVL72 | E7: Rack Type | F7: Vera Rubin NVL72 | G7: GB200 NVL72
A8: No.of racks | B8: =IF($B$7=F$4,F8,G8) -> 5263 | C8: Derived: FLOOR(IT Power / Power per Rack) | E8: No.of racks | F8: =FLOOR(F5/1000/F23,1) -> 5263 | G8: =FLOOR(G5/1000/G23,1) -> 7194 | H8: Derived: FLOOR(Total Power / Power per Rack)
A10: Rack Spec. | B10: Data | C10: Note | E10: Rack Spec. | F10: Vera Rubin NVL72 | G10: GB200 NVL72 | H10: Note
A11: CPU Type | B11: =IF($B$7=F$4,F11,G11) -> Vera CPU | E11: CPU Type | F11: Vera CPU | G11: Grace CPU
A12: No. of CPU | B12: =IF($B$7=F$4,F12,G12) -> 36 | E12: No. of CPU | F12: 36 | G12: 36
A13: GPU Type | B13: =IF($B$7=F$4,F13,G13) -> Rubin GPU | E13: GPU Type | F13: Rubin GPU | G13: Blackwell B200
A14: No. of GPU | B14: =IF($B$7=F$4,F14,G14) -> 72 | C14: per rack | E14: No. of GPU | F14: 72 | G14: 72
A15: NVLink Bandwidth(TB/s) | B15: =IF($B$7=F$4,F15,G15) -> 260 | C15: total per rack | E15: NVLink BW(TB/s) | F15: 260 | G15: 130 | H15: Total per rack
A16: NVLink-C2C Bandwidth(TB/s) | B16: =IF($B$7=F$4,F16,G16) -> 65 | E16: NVLink-C2C BW(TB/s) | F16: 65 | G16: 32.4 | H16: 0.9 TB/s * 36 CPUs
A17: GPU Memory(TB) | B17: =IF($B$7=F$4,F17,G17) -> 20.7 | C17: 0.288/GPU | E17: GPU Memory(TB) | F17: 20.7 | G17: 13.5 | H17: Total per rack (0.1875/GPU for GB200)
A18: Memory Bandwidth(TB) | B18: =IF($B$7=F$4,F18,G18) -> 1580 | C18: 22/GPU | E18: Memory BW(TB) | F18: 1580 | G18: 576 | H18: Total per rack (8/GPU for GB200)
A19: FP4 Dense Inference(PFLOPS) | B19: =IF($B$7=F$4,F19,G19) -> 3600 | C19: 50/GPU | E19: FP4 Dense Inference(PFLOPS) | F19: 3600 | G19: 648 | H19: 50/GPU Rubin = 3600; 9/GPU B200 (dense, no sparsity). Fixed from 2520 (was using 35/GPU training value).
A20: FP4 Dense Training(PFLOPS) | B20: =IF($B$7=F$4,F20,G20) -> 2520 | C20: 35/GPU | E20: FP4 Dense Training(PFLOPS) | F20: 2520 | G20: 648 | H20: Same as inference for dense (sparsity only boosts inference marketing)
A21: FP8 Dense(PFLOPS) | B21: =IF($B$7=F$4,F21,G21) -> 1260 | C21: 17.5/GPU | E21: FP8 Dense(PFLOPS) | F21: 1260 | G21: 324 | H21: 16/GPU Rubin; 4.5/GPU B200 (dense)
A22: FP16/BF16 Dense(PFLOPS) | B22: =IF($B$7=F$4,F22,G22) -> 288 | C22: 4/GPU | E22: FP16/BF16 Dense(PFLOPS) | F22: 288 | G22: 162 | H22: 3.6/GPU Rubin; 2.25/GPU B200 (dense)
A23: Power per Rack (kW) | B23: =IF($B$7=F$4,F23,G23) -> 190 | C23: IT power draw per rack | E23: Power/Rack (kW) | F23: 190 | G23: 139 | H23: IT power only (excl. PUE overhead)
A24: Rack Price ($) | B24: =IF($B$7=F$4,F27,G27) -> 6000000 | C24: Auto-filled from dropdown; edit preset in F26/G26
A26: ▶ KEY INPUTS — Model & Tokens | B26: Data | C26: Note | E26: Pricing | F26: Vera Rubin NVL72 | G26: GB200 NVL72 | H26: Note
A27: Input Tokens | B27: 4000 | C27: ← Change this | E27: Rack Price ($) | F27: 6000000 | G27: 3000000 | H27: Est. $3M GB200; Rubin ~$6M (15-20% premium)
A28: Output Tokens | B28: =B27/4 -> 1000 | C28: ← Change this
E29: ▶ MARKET PRICING TIERS (Mar 2026)
A30: Model Spec. | B30: Data | C30: Note | E30: Auto-selects pricing based on model parameters (Column B30)
A31: Parameters | B31: 1000000000000 | C31: ← Change this (e.g. 500B, 1T, 1.5T) | E31: Tier | F31: Param Threshold | G31: Input $/M | H31: Output $/M
A32: Type | B32: Dense | E32: Nano (<50B) | F32: 0 | G32: 0.1 | H32: 0.4
A33: vocab size(V) | B33: 128000 | E33: Small (50B–200B) | F33: 50000000000 | G33: 0.25 | H33: 2
A34: Hidden Dimension(d_model) | B34: =IF(B31<100000000,B31^(1/4),2^11*10^LOG((B31/10^11))) -> 20480 | C34: Given or adjust for model size | E34: Mid (200B–500B) | F34: 200000000000 | G34: 1.25 | H34: 10
A35: n_layers | B35: 128 | C35: Given or adjust for model size | E35: Frontier (500B–1.5T) | F35: 500000000000 | G35: 2.5 | H35: 10
A36: n_heads | B36: 160 | E36: Premium (>1.5T) | F36: 1500000000000 | G36: 5 | H36: 25
A37: d_head | B37: =B34/B36 -> 128 | C37: d_model / n_heads
A38: d_ff(SwiGLU) | B38: =(B31/B35-4*B34^2)/(3*B34) -> 99849.909 | C38: derived from Parameters = n_layers × (4×d² + 3×d×d_ff) | E38: Sources: | F38: GPT-5 $1.25/$10, GPT-4o $2.50/$10, Opus 4.6 $5/$25, Haiku $1/$5, GPT-5 Nano $0.05/$0.40
A39: Parameters per Layer(Att) | B39: =4*B34^2 -> 1677721600 | C39: Q_W+K_W+V_W+O_W = 4×d_model²
A40: Parameters per Layer(FFN) | B40: =3*B34*B38 -> 6134778400 | C40: 3 × d_model × d_ff | E40: ▶ AUTO-SELECTED PRICING (from B30)
A41: Total Parameters per Layer | B41: =B39+B40 -> 7812500000 | E41: Matched Tier | F41: {=INDEX(E32:E36,MATCH(B31,F32:F36,1))} -> Frontier (500B–1.5T) | H41: Based on Config!B30 parameters
A42: MFU | B42: 0.5 | C42: Model FLOPS Utilization | E42: Input Price ($/M tokens) | F42: {=INDEX(G32:G36,MATCH(B31,F32:F36,1))} -> 2.5
A43: Precision | B43: FP8 | C43: ← Select: FP4, FP8, or FP16 | E43: Output Price ($/M tokens) | F43: {=INDEX(H32:H36,MATCH(B31,F32:F36,1))} -> 10
...

Sheet TL_Param
B1: Base Line
A2: # | B2: Step(time in s) | C2: Start Time | D2: Duration | E2: End Time | F2: Compute Time | G2: HBM BW Time | H2: NVLink Time | I2: Bottleneck | J2: Dominant Resource | K2: FLOPs Used | L2: HBM Bytes Moved
A3: 1 | B3: Tokenization (CPU) | C3: 0 | D3: 0.05 | E3: =C3+D3 -> 0.05 | F3: N/A(CPU) | G3: N/A | H3: N/A | I3: CPU | J3: CPU | K3: 0 | L3: 0
A4: 2 | B4: Embedding Lookup + Broadcast | C4: =E3 -> 0.05 | D4: =G4+H4 -> 0.0010016591 | E4: =C4+D4 -> 0.051001659 | F4: 0 | G4: =WP_Param!B28*WP_Param!B29/(WP_Param!B15*1000000000000) -> 1.6591392e-06 | H4: 0.001 | I4: Memory | J4: HBM BW | K4: 0 | L4: =WP_Param!B22*WP_Param!B29+WP_Param!B28*WP_Param!B29 -> 2703360000
A5: 3 | B5: Prefill+KV Cache Write | C5: =E4 -> 0.051001659 | D5: =F5+H5 -> 0.018691639 | E5: =C5+D5 -> 0.069693298 | F5: =WP_Param!B70 -> 0.012964801 | G5: =WP_Param!B87 -> 0.00068600385 | H5: =WP_Param!B97 -> 0.0057268382 | I5: Compute | J5: GPU | K5: =WP_Param!B65 -> 8.1678246e+15 | L5: =WP_Param!B84 -> 1083886080000
A6: 4 | B6: Decode-First Token | C6: =E5 -> 0.069693298 | D6: =G6 -> 0.001147847 | E6: =C6+D6 -> 0.070841145 | F6: =WP_Param!B121 -> 1.6247507e-06 | G6: =WP_Param!B151 -> 0.001147847 | H6: - | I6: Memory | J6: HBM BW | K6: =WP_Param!B117 -> 2047185920000 | L6: =WP_Param!B135 -> 1023598202880
A7: 5 | B7: Decode-All Tokens | C7: =E6 -> 0.070841145 | D7: =G7+H7 -> 1.147847 | E7: =C7+D7 -> 1.2186881 | F7: =WP_Param!B122 -> 0.0016247507 | G7: =WP_Param!B138*WP_Param!B23 -> 0.64784696 | H7: =WP_Param!B149*WP_Param!B23 -> 0.5 | I7: Memory | J7: HBM BW | K7: =WP_Param!B118 -> 2.0471859e+15 | L7: =WP_Param!B135*WP_Param!B23 -> 1.0235982e+15
A8: 6 | B8: De-tokenization (CPU) | C8: =E7 -> 1.2186881 | D8: 0.05 | E8: =C8+D8 -> 1.2686881 | F8: N/A(CPU) | G8: N/A | H8: N/A | I8: CPU | J8: CPU | K8: 0 | L8: 0
B9: Avg Time per Output Token (s) | E9: =E8/WP_Param!B23 -> 0.0012686881
B10: Total Output Token(s)/second | E10: =1/E9 -> 788.21579
B13: Optimized-GQA + Concurrent Requests - Batch Size + Speculative Decoding
A14: # | B14: Step(time in s) | C14: Start Time | D14: Duration | E14: End Time | F14: Compute Time | G14: HBM BW Time | H14: NVLink Time | I14: Bottleneck | J14: Dominant Resource | K14: FLOPs Used | L14: HBM Bytes Moved
A15: 1 | B15: Tokenization (CPU) | C15: 0 | D15: 0.05 | E15: =C15+D15 -> 0.05 | F15: N/A(CPU) | G15: N/A | H15: N/A | I15: CPU | J15: CPU | K15: 0 | L15: 0
A16: 2 | B16: Embedding Lookup + Broadcast | C16: =E15 -> 0.05 | D16: =G16+H16 -> 2.9019427e-06 | E16: =C16+D16 -> 0.050002902 | F16: 0 | G16: =WP_Param!B28*WP_Param!B29/(WP_Param!B15*1000000000000) -> 1.6591392e-06 | H16: =2*WP_Param!B22*WP_Param!B29*2*(71/72)/(WP_Param!B12*1000000000000) -> 1.2428034e-06 | I16: NVLink | J16: NVLink | K16: 0 | L16: =WP_Param!B22*WP_Param!B29+WP_Param!B28*WP_Param!B29 -> 2703360000
A17: 3 | B17: Prefill+KV Cache Write | C17: =E16 -> 0.050002902 | D17: =F17+H17 -> 1.1962649 | E17: =C17+D17 -> 1.2462678 | F17: =WP_Param!B70*WP_Param!B169 -> 0.82974726 | G17: =WP_Param!B87*WP_Param!B169 -> 0.043904246 | H17: =WP_Param!B97*WP_Param!B169 -> 0.36651764 | I17: Compute | J17: GPU | K17: =WP_Param!B65*WP_Param!B169 -> 5.2274077e+17 | L17: =WP_Param!B84*WP_Param!B169 -> 69368709120000
A18: 4 | B18: Decode-First Token | C18: =E17 -> 1.2462678 | D18: =G18 -> 0.00063365801 | E18: =C18+D18 -> 1.2469015 | F18: =WP_Param!B121 -> 1.6247507e-06 | G18: =WP_Param!B164 -> 0.00063365801 | H18: - | I18: Memory | J18: HBM BW | K18: =WP_Param!B117 -> 2047185920000 | L18: =WP_Param!B163 -> 1001179648000
A19: 5 | B19: Decode-All Tokens | C19: =E18 -> 1.2469015 | D19: =G19+H19 -> 1.1806946 | E19: =C19+D19 -> 2.4275961 | F19: =WP_Param!B122 -> 0.0016247507 | G19: =WP_Param!B172*WP_Param!B23*WP_Param!B169 -> 0.6806946 | H19: =WP_Param!B149*WP_Param!B23 -> 0.5 | I19: Memory | J19: HBM BW | K19: =WP_Param!B118 -> 2.0471859e+15 | L19: =WP_Param!B171*WP_Param!B23 -> 1.0754975e+15
A20: 6 | B20: De-tokenization (CPU) | C20: =E19 -> 2.4275961 | D20: 0.05 | E20: =C20+D20 -> 2.4775961 | F20: N/A(CPU) | G20: N/A | H20: N/A | I20: CPU | J20: CPU | K20: 0 | L20: 0
B21: Avg Time per Output Token (s) | E21: =E20/(WP_Param!B169*WP_Param!B23) -> 3.8712439e-05 | G21: E2E / (Batch * Output)
B22: Total Output Token(s)/second | E22: =1/E21 -> 25831.491
B25: Optimized-GQA + Concurrent Requests - Batch Size + Speculative Decoding + NVLink Optimization | N25: Rack-Independent Latency Outputs
A26: # | B26: Step(time in s) | C26: Start Time | D26: Duration | E26: End Time | F26: Compute Time | G26: HBM BW Time | H26: NVLink Time | I26: Bottleneck | J26: Dominant Resource | K26: FLOPs Used | L26: HBM Bytes Moved | N26: VR NVL72 E2E (s) | O26: GB200 NVL72 E2E (s)
A27: 1 | B27: Tokenization (CPU) | C27: 0 | D27: 0.05 | E27: =C27+D27 -> 0.05 | F27: N/A(CPU) | G27: N/A | H27: N/A | I27: CPU | J27: CPU | K27: 0 | L27: 0 | N27: =D27 -> 0.05 | O27: =D27 -> 0.05
A28: 2 | B28: Embedding Lookup + Broadcast | C28: =E27 -> 0.05 | D28: =G28+H28 -> 2.9019427e-06 | E28: =C28+D28 -> 0.050002902 | F28: 0 | G28: =WP_Param!B28*WP_Param!B29/(WP_Param!B15*1000000000000) -> 1.6591392e-06 | H28: =2*WP_Param!B22*WP_Param!B29*2*(71/72)/(WP_Param!B12*1000000000000) -> 1.2428034e-06 | I28: NVLink | J28: NVLink | K28: 0 | L28: =WP_Param!B22*WP_Param!B29+WP_Param!B28*WP_Param!B29 -> 2703360000 | N28: =IF(Config!B7="Vera Rubin NVL72", D28, G28*(Config!G18/Config!F18) + H28*(Config!G15/Config!F15)) -> 2.9019427e-06 | O28: =IF(Config!B7="Vera Rubin NVL72", G28*(Config!F18/Config!G18) + H28*(Config!F15/Config!G15), D28) -> 7.0367179e-06
A29: 3 | B29: Prefill+KV Cache Write | C29: =E28 -> 0.050002902 | D29: =F29+H29 -> 1.1962649 | E29: =C29+D29 -> 1.2462678 | F29: =WP_Param!B70*WP_Param!B169 -> 0.82974726 | G29: =WP_Param!B87*WP_Param!B169 -> 0.043904246 | H29: =WP_Param!B97*WP_Param!B169 -> 0.36651764 | I29: Compute | J29: GPU | K29: =WP_Param!B65*WP_Param!B169 -> 5.2274077e+17 | L29: =WP_Param!B84*WP_Param!B169 -> 69368709120000 | N29: =IF(Config!B7="Vera Rubin NVL72", D29, F29*(IF(Config!B43="FP4",Config!G19,IF(Config!B43="FP8",Config!G21,Config!G22))/IF(Config!B43="FP4",Config!F19,IF(Config!B43="FP8",Config!F21,Config!F22))) + H29*(Config!G15/Config!F15)) -> 1.1962649 | O29: =IF(Config!B7="Vera Rubin NVL72", F29*(IF(Config!B43="FP4",Config!F19,IF(Config!B43="FP8",Config!F21,Config!F22))/IF(Config!B43="FP4",Config!G19,IF(Config!B43="FP8",Config!G21,Config!G22))) + H29*(Config!F15/Config!G15), D29) -> 3.9598302
A30: 4 | B30: Decode-First Token | C30: =E29 -> 1.2462678 | D30: =G30 -> 0.00063365801 | E30: =C30+D30 -> 1.2469015 | F30: =WP_Param!B121 -> 1.6247507e-06 | G30: =WP_Param!B164 -> 0.00063365801 | H30: - | I30: Memory | J30: HBM BW | K30: =WP_Param!B117 -> 2047185920000 | L30: =WP_Param!B163 -> 1001179648000 | N30: =IF(Config!B7="Vera Rubin NVL72", D30, G30*(Config!G18/Config!F18)) -> 0.00063365801 | O30: =IF(Config!B7="Vera Rubin NVL72", G30*(Config!F18/Config!G18), D30) -> 0.0017381591
A31: 5 | B31: Decode-All Tokens | C31: =E30 -> 1.2469015 | D31: =G31+H31 -> 0.68140037 | E31: =C31+D31 -> 1.9283018 | F31: =WP_Param!B122 -> 0.0016247507 | G31: =WP_Param!B172*WP_Param!B23*WP_Param!B169 -> 0.6806946 | H31: =WP_Param!B206 -> 0.00070577231 | I31: Memory | J31: HBM BW | K31: =WP_Param!B118 -> 2.0471859e+15 | L31: =WP_Param!B171*WP_Param!B23 -> 1.0754975e+15 | N31: =IF(Config!B7="Vera Rubin NVL72", D31, G31*(Config!G18/Config!F18) + H31*(Config!G15/Config!F15)) -> 0.68140037 | O31: =IF(Config!B7="Vera Rubin NVL72", G31*(Config!F18/Config!G18) + H31*(Config!F15/Config!G15), D31) -> 1.8685947
A32: 6 | B32: De-tokenization (CPU) | C32: =E31 -> 1.9283018 | D32: 0.05 | E32: =C32+D32 -> 1.9783018 | F32: N/A(CPU) | G32: N/A | H32: N/A | I32: CPU | J32: CPU | K32: 0 | L32: 0 | N32: =D32 -> 0.05 | O32: =D32 -> 0.05
B33: Avg Time per Output Token (s) | E33: =E32/(WP_Param!B169*WP_Param!B23) -> 3.0910966e-05 | G33: E2E / (Batch * Output) | N33: =SUM(N27:N32)/(Config!B52*Config!B28) -> 3.0910966e-05 | O33: =SUM(O27:O32)/(Config!B52*Config!B28) -> 9.2658907e-05
B34: Total Output Token(s)/second | E34: =1/E33 -> 32350.978 | N34: =1/N33 -> 32350.978 | O34: =1/O33 -> 10792.271
N35: =SUM(N27:N31) -> 1.9283018 | O35: =SUM(O27:O31) -> 5.88017

Sheet WP_Param
A1: AI DC Spec. | B1: Data | C1: Note
A2: Total power(W) | B2: =Config!B5 -> 1000000000
A3: PUE | B3: =Config!B6 -> 1.2
A4: Rack Type | B4: =Config!B7 -> Vera Rubin NVL72
A5: No.of racks | B5: =Config!B8 -> 5263
A7: Rack Spec. | B7: Data | C7: Note
A8: CPU Type | B8: =Config!B11 -> Vera CPU
A9: No. of CPU | B9: =Config!B12 -> 36
A10: GPU Type | B10: =Config!B13 -> Rubin GPU
A11: No. of GPU | B11: =Config!B14 -> 72
A12: NVLink Bandwidth(TB/s) | B12: =Config!B15 -> 260
A13: NVLink-C2C Bandwidth(TB/s) | B13: =Config!B16 -> 65
A14: GPU Memory(TB) | B14: =Config!B17 -> 20.7 | C14: 0.288/GPU
A15: Memory Bandwidth(TB) | B15: =Config!B18 -> 1580 | C15: 22/GPU
A16: FP4 Dense Inference(PFLOPS) | B16: =Config!B19 -> 3600 | C16: 50/GPU
A17: FP4 Dense Training(PFLOPS) | B17: =Config!B20 -> 2520 | C17: 35/GPU
A18: FP8 Dense(PFLOPS) | B18: =Config!B21 -> 1260 | C18: 17.5/GPU
A19: FP16/BF16 Dense(PFLOPS) | B19: =Config!B22 -> 288 | C19: 4/GPU
A21: Input/Output Tokens Setup | B21: Data | C21: Note
A22: Input Tokens: | B22: =Config!B27 -> 4000
A23: Output Tokens: | B23: =Config!B28 -> 1000
A25: Model Spec. | B25: Data | C25: Note
A26: Parameters | B26: =Config!B31 -> 1000000000000 | C26: From Config sheet
A27: Type | B27: =Config!B32 -> Dense
A28: vocab size(V) | B28: =Config!B33 -> 128000
A29: Hidden Dimension(d_model) | B29: =Config!B34 -> 20480 | C29: Given
A30: n_layers | B30: =Config!B35 -> 128 | C30: Given
A31: n_heads | B31: =Config!B36 -> 160
A32: d_head | B32: =Config!B37 -> 128
A33: d_ff(SwiGLU) | B33: =Config!B38 -> 99849.909 | C33: derived from Parameters
A34: Parameters per Layer(Att) | B34: =Config!B39 -> 1677721600 | C34: Q_W+K_W+V_W+O_W=4*d_model^2
A35: Parameters per Layer(FFN) | B35: =Config!B40 -> 6134778400 | C35: 3 × d_model × d_ff
A36: Total Parameters per Layer | B36: =Config!B41 -> 7812500000
A37: Weight Memory(Byte) | B37: =B26*Config!B44 -> 1000000000000 | C37: Parameters × Bytes/param (from Config Precision)
A38: Weight Memory(Byte)/GPU | B38: =B37/B11 -> 1.3888889e+10
A39: KV cache @ Beginning(Byte) | B39: =2*B29*B22*B30 -> 20971520000 | C39: K=V=d_model*layer*no.of Input tokens, Total =K+V
A40: KV cache @ End(Byte) | B40: =2*B29*(B22+B23)*B30 -> 26214400000 | C40: K=V=d_model*layer*no.of (Input+Output tokens), Total =K+V
A41: KV cache per GPU @ End | B41: =B40/B11 -> 3.6408889e+08
A42: Memory required per GPU | B42: =B41+B38 -> 1.4252978e+10 | C42: Need additional memory for Activations
A43: GPU Memory Headroom | B43: =B14/B11*1000000000000-B42 -> 2.7324702e+11 | C43: Check if GPU has enough memory
...

Sheet DC_Cost_Model
A1: Data Center Cost Model — 1 GW Vera Rubin NVL72 Facility
A3: Section 1: Data Center Specifications (from Config)
A4: Item | B4: Value | C4: Unit | E4: Source / Note
A5: Total IT Power | B5: =Config!B5/1000000 -> 1000 | C5: MW | E5: Linked from Config!B5
A6: PUE | B6: =Config!B6 -> 1.2 | E6: Linked from Config!B6
A7: Total Facility Power (IT × PUE) | B7: =B5*B6 -> 1200 | C7: MW | E7: Total electrical load including cooling, lighting, etc.
A8: Rack Type | B8: =Config!B7 -> Vera Rubin NVL72 | E8: Linked from Config!B7
A9: Number of Racks | B9: =Config!B8 -> 5263 | C9: racks | E9: Linked from Config!B8
A10: GPUs per Rack | B10: =Config!B14 -> 72 | C10: GPUs | E10: Linked from Config!B14
A11: Total GPUs | B11: =B9*B10 -> 378936 | C11: GPUs | E11: Racks × GPUs per rack
A12: Power per Rack (est.) | B12: =B5*1000/B9 -> 190.0057 | C12: kW | E12: Total IT Power / Racks
A13: Total Facility Sq. Ft. (est.) | B13: =B9*80 -> 421040 | C13: sq ft | E13: ~80 sq ft per rack (AI liquid-cooled, incl. aisles + support)
A15: Section 2: Capital Expenditure (CapEx) Breakdown
A16: Category | B16: Unit Cost | C16: Quantity / Basis | D16: Total ($M) | E16: Assumption / Source | F16: % of CapEx
A17: 2A. IT Hardware (Servers & GPUs)
A18: =" "&Config!B7&" Racks" -> Vera Rubin NVL72 Racks | B18: =Config!B24 -> 6000000 | C18: =B9 -> 5263 | D18: =B18*C18/1000000 -> 31578 | E18: Est. $3.5M/rack; GB200 NVL72 ~$3M, Rubin gen premium ~15-20% | F18: =D18/$D$54 -> 0.73039455
A19: Scale-out Networking (InfiniBand/Ethernet) | B19: 150000 | C19: =B9 -> 5263 | D19: =B19*C19/1000000 -> 789.45 | E19: Quantum-X800 IB + Spectrum-X Ethernet per-rack allocation | F19: =D19/$D$54 -> 0.018259864
