Workbook

Sheet README
A1: Tokenomics v5.7 — Block 1＋2＋3：機架規格、每 GW 成本、各層級產出與每 token 成本、訓練與研發計畫
A2: 第 0 層規格來源。能力與理論營收於 Block 4 加入。
A4: 用途 | B4: 回答：每 1 GW IT 電力，各世代可容納多少機架、資本支出與持有成本（Block 1）；各層級 SLO 下的產出與依『世代 × 層級 × token 類型』的每 M token 成本（Block 2）；各層級代表模型的訓練與研發計畫需要多少 GPU 小時、成本與 1 GW 年，其中後訓練占多少（Block 3）。不含營收（Block 4）。
A5: 版本 | B5: 20261001_Tokenomics_v5.7（Block 1＋2＋3；v5.2 加第二來源驗證與生產折減；v5.3、v5.4 依 CC 回饋補具名範圍與驗證表；v5.5 加 Block 3：Tech_Registry、Train_In、Perf_Batch、Training、Sens_Train，並更正 Hopper FP8 峰值；v5.6 非同步 RL 併入基準、補 TR_ 與訓練世代具名範圍；v5.7 改為 Excel 優先：輸入值由 Excel 擁有，新增 DB_Evidence 證據登錄表）。v4 的 Config／TL_Param／WP_Param／Revenue_Model 由 Arch、Serving、Workload、Calib、Perf、Unit_Cost 取代。
A6: 電力口徑 | B6: GW＝IT 關鍵電力（Andy 2026-09-30 確認）。設施電力＝IT × PUE，於 DC_Cost 與 Interface 並列。
A7: 工作表 | B7: Inputs → Spec_Rack → Arch → Serving → Workload → Calib → Tech_Registry → Perf → Sens_Perf → Unit_Cost → DC_Cost → Train_In → Perf_Batch → Training → Sens_Train → Interface；Energy、NonNV、Sensitivity、Checks、Sources。
A8: Block 3 推導 | B8: 預訓練：FLOPs＝3 ×（2 × 啟用參數＋注意力 FLOPs × 被注意 token）× token；GPU 小時＝FLOPs ÷（FP8 訓練峰值 × MFU × goodput）。RL、蒸餾、合成資料、評測的推論型運算以 Perf_Batch（與 Perf 同公式，只換速度下限與參考任務）計價；RL 有效 MFU 為推導值。研發計畫＝最終訓練 GPU 小時 × 研發倍數。
A9: Block 3 決策 | B9: J7 訓練精度 FP8（NVFP4 預訓練在 Tech_Registry）；J8 Astra 預訓練與 Arch 一致，前沿錨點列 Checks；J9 RL 由下而上，基準校到 RL÷預訓練 GPU 小時 Luna／Sol 0.3、Astra 1.0；J10 研發倍數 8，家族合計、依最終訓練比例分攤；J11 用途 × 型態只列單一計畫；J12 rollout NVFP4（FP8 為情境）；J13 下游預設 VR200、GB300 並列；J14 主流＝至少兩家實驗室公開採用，可覆寫。
A10: Excel 優先（v5.7） | B10: 藍字＝輸入，由本活頁簿擁有：要改輸入，直接改 Excel。builder 重建 Block 2、3 時會先讀取所有藍字輸入，重建後依『工作表＋欄 A 標籤＋欄位』寫回，程式內的預設值只用於新增的輸入列。公式頁不要手改（重建時會被覆寫）。
A11: DB_Evidence（v5.7） | B11: 證據登錄表：所有比對過的新資訊（含不採納者），記錄主張、來源、標記、對應參數、當時值、新值、判定與處理版本。builder 只在本頁不存在時建立。
A12: Tech_Registry | B12: 每列＝技術 × 作用物理量；有效倍數＝1＋開關 × 採用比例 ×（倍數−1）；已在基準者不套倍數。掛鉤彙總表連到 Perf、Perf_Batch、Training。全部開關為 0 時 Block 2 數值與 v5.4 相同。
A13: Block 2 推導 | B13: prefill：tok/s＝η_p × 峰值 ÷ FLOPs/token。decode：每步時間＝固定延遲（權重讀取＋每層延遲 ×（層數＋草稿數））＋B × 每序列時間；在 SLO 下解出批次 B*，再受 HBM 容量限制。η_d 與每層延遲由 GB300 同一前緣兩點聯立解出（Calib）。
A14: 成本情境 | B14: 低成本／基準／高成本為角落情境。單一變數影響看 Sensitivity（Block 1）與 Sens_Perf（Block 2）。
A15: 功率情境 | B15: Inputs!E6 選 1／2／3，決定每架配電設計功率與每 GW 機架數。
... A21: 未結事項 | B21: (1) VR200 報價是否含網路（S11）。(2) 所有來源待 Andy 查核。(3) Rubin Ultra 為推估。(4) J6 基準利用率暫用 60%、生產折減暫用 1.0，皆待 Andy 給值。(5) VR200 無實測，η_d 與每層延遲沿用 GB300。(6) 交接錨點 6,182 屬舊軟體（vLLM 無 MTP），已改為 GB300 最新前緣兩點校準。(7) 快取命中只計載入時間，未計儲存成本。(8) Hopper 峰值更正為 FP8 1,979 TF，η_d 與 η_p 倍數同步減半以維持產出；S30 口徑待查後重推。(9) Block 3 的 Astra token、RL rollout 量、研發倍數皆為 Analogy／Assumed，看 Sens_Train。(10) v5.6：非同步 RL 併入基準（rollout 效率 0.85），RL rollout token 重校以維持 GPU 小時錨點（J9 (a)）。

Sheet Inputs
A1: Inputs — 全域輸入（藍字可改）
A2: 低成本／基準／高成本為角落情境；單值輸入只填基準欄
A3: 參數 | B3: 單位 | D3: 低成本 | E3: 基準 | F3: 高成本 | G3: 標記 | H3: 來源／說明
A4: 控制
A5: IT 電力規模 | B5: GW | D5: =E5 -> 1 | E5: 1 | F5: =E5 -> 1 | G5: Decision | H5: 口徑：IT 關鍵電力
A6: 功率情境（1 低／2 基準／3 高） | B6: 選擇 | D6: =E6 -> 2 | E6: 2 | F6: =E6 -> 2 | G6: Decision | H6: 決定每架配電設計功率；見 Spec_Rack 第 9–11 列
A7: 規模與電力
A8: 機架外 IT 電力占比 | B8: % | D8: =E8 -> 0.08 | E8: 0.08 | F8: =E8 -> 0.08 | G8: Assumed | H8: 管理、儲存、網路機櫃等；區間 5–12%（見 Sensitivity）。v4 未計
A9: PUE | B9: x | D9: 1.1 | E9: 1.2 | F9: 1.3 | G9: Analogy | H9: 液冷 AI 設施；v4＝1.2。S14
A10: 平均用電 ÷ 配電設計功率 | B10: % | D10: 0.7 | E10: 0.8 | F10: 0.9 | G10: Assumed | H10: Block 2 以逐步能量模型閉合檢查
A11: 電價 | B11: $/kWh | D11: 0.06 | E11: 0.08 | F11: 0.1 | G11: Verified/Analogy | H11: EIA 美國工業電價 2026 年約 8.6–8.7¢（S13）；低端為 PPA（v4＝0.06）
A12: IT 設備（機架以外）
A13: Scale-out 網路 ÷ 機架價格 | B13: % | D13: 0.05 | E13: 0.1 | F13: 0.15 | G13: Analogy | H13: 1,024 GPU 叢集網路約為 GPU BOM 4–8%（S10）；GW 級多一層以上交換，取 5–15%
A14: 儲存與管理設備 | B14: $/GPU | D14: 300 | E14: 500 | F14: 800 | G14: Assumed | H14: v4 約 $350/GPU（$25K/架）
A15: 廠房（每 MW IT，$M）
A16: 土地 | B16: $M/MW | D16: 0.02 | E16: 0.02 | F16: 0.02 | G16: Assumed | H16: v4：100 英畝 × $200K／GW
A17: 建物與基地工程 | B17: $M/MW | D17: 3 | E17: 3.6 | F17: 4.5 | G17: Assumed | H17: 分項為假設；總額以 JLL 校準（S12）
A18: 電力設施（變電、中壓、發電機、UPS） | B18: $M/MW | D18: 3.8 | E18: 4.5 | F18: 5.5 | G18: Assumed | H18: 同上
A19: 機械與散熱（液冷迴路、散熱設備） | B19: $M/MW | D19: 2 | E19: 2.5 | F19: 3.2 | G19: Assumed | H19: 機架內冷板與 manifold 含在機架價格
A20: 光纖、佈線、保全、BMS | B20: $M/MW | D20: 0.3 | E20: 0.4 | F20: 0.5 | G20: Assumed | H20: 同上
A21: 設計、管理與預備費 | B21: % 廠房 | D21: 0.12 | E21: 0.15 | F21: 0.18 | G21: Assumed | H21: v4＝15%
A22: 年限與資金成本
A23: IT 設備折舊年限 | B23: 年 | D23: 6 | E23: 6 | F23: 4 | G23: Verified | H23: CoreWeave 與主要 hyperscaler 6 年；Nebius 4 年、Lambda 5 年（S15）。高成本情境取 4
A24: 建物年限 | B24: 年 | D24: =E24 -> 30 | E24: 30 | F24: =E24 -> 30 | G24: Analogy | H24: v4
A25: 電力設施年限 | B25: 年 | D25: =E25 -> 20 | E25: 20 | F25: =E25 -> 20 | G25: Analogy | H25: v4
A26: 機械與散熱年限 | B26: 年 | D26: =E26 -> 15 | E26: 15 | F26: =E26 -> 15 | G26: Analogy | H26: v4
A27: 光纖與保全年限 | B27: 年 | D27: =E27 -> 10 | E27: 10 | F27: =E27 -> 10 | G27: Analogy | H27: v4
A28: WACC（經濟口徑） | B28: % | D28: 0.08 | E28: 0.1 | F28: 0.13 | G28: Assumed | H28: 與擁有者無關的單一假設；下游公司模型以自身 WACC 覆寫（Andy 2026-09-30 決定）
A29: 營運費用
A30: IT 維護 | B30: % IT 資本/年 | D30: 0.02 | E30: 0.03 | F30: 0.04 | G30: Analogy | H30: v4＝3%
A31: 廠房維護 | B31: % 廠房資本/年 | D31: 0.015 | E31: 0.02 | F31: 0.025 | G31: Analogy | H31: v4＝2%
A32: 人員 | B32: $M/GW/年 | D32: 50 | E32: 75 | F32: 100 | G32: Assumed | H32: v4：500 FTE × $150K
A33: 軟體授權與連線 | B33: $M/GW/年 | D33: 150 | E33: 200 | F33: 250 | G33: Assumed | H33: v4＝$200M
A34: 水與耗材 | B34: $M/MW/年 | D34: 0.04 | E34: 0.05 | F34: 0.06 | G34: Assumed | H34: v4＝$50K/MW
A35: 財產稅與保險 | B35: % 總資本/年 | D35: 0.003 | E35: 0.005 | F35: 0.008 | G35: Analogy | H35: v4＝0.5%

Sheet Spec_Rack
A1: Spec_Rack — 各世代機架規格（Block 1 只含功率與價格；效能規格於 Block 2 加入）
A2: 價格為買方取得價（CSP/hyperscaler 口徑）；Hopper 以 4 台 HGX 構成一架（32 GPU）以便比較
A4: 世代 | C4: Hopper H100 | D4: GB200 NVL72 | E4: GB300 NVL72 | F4: VR200 NVL72 | G4: Rubin Ultra NVL576 | H4: 標記／來源
A5: 平台／出貨 | C5: HGX ×4（32 GPU） | D5: 2024–25 出貨 | E5: 2025–26 主力 | F5: 2026 下半年開始出貨 | G5: 2027 預估（Kyber）
A6: GPU 封裝／架 | C6: 32 | D6: 72 | E6: 72 | F6: 72 | G6: 144
A7: 冷卻 | C7: 氣冷 | D7: 液冷 | E7: 液冷 | F7: 液冷（必須） | G7: 液冷
A8: 配電設計功率 低（kW） | C8: 38 | D8: 120 | E8: 132 | F8: 190 | G8: 550
A9: 配電設計功率 基準（kW） | C9: 41 | D9: 130 | E9: 137 | F9: 227 | G9: 600
A10: 配電設計功率 高（kW） | C10: 44 | D10: 140 | E10: 142 | F10: 230 | G10: 650
A11: 機架價格 低（$M） | C11: 0.9 | D11: 2.8 | E11: 4 | F11: 6.7 | G11: 23.4
A12: 機架價格 基準（$M） | C12: 1.1 | D12: 3.1 | E12: 5 | F12: 7.8 | G12: 31.2
A13: 機架價格 高（$M） | C13: 1.3 | D13: 3.4 | E13: 6.5 | F13: 9.1 | G13: 39
A14: 價格涵蓋範圍 | C14: 8 GPU 伺服器 + CPU、NIC、機內儲存；以部署當時取得價計 | D14: 運算匣＋NVLink 交換匣＋機架內冷卻 | E14: 同上 | F14: 運算匣＋交換匣＋冷卻＋約 $1M NAND；是否含部分網路待查（S11） | G14: 144 封裝；價格＝VR 每 GPU 價 × 1.5／2.0／2.5（推估）
A15: 功率來源 | C15: DGX H100 最大 10.2 kW／8 GPU（S1） | D15: 約 120–130 kW（S3）；v4＝139 | E15: 132–142 kW（S3、S5） | F15: Max-Q 約 190、Max-P 約 230 kW（S7）；Supermicro DLC-2 設計點 227 kW（S8） | G15: 約 600 kW（S7）
A16: 價格來源 | C16: HGX H100 8 GPU 伺服器約 $220–320K（S2，弱證據） | D16: $2.8–3.4M（S4）；Barron's 約 $3M | E16: MS 約 $4M；2026-08 採購單約 $5M；媒體 $6–6.5M（S4、S6） | F16: MS $7.8M（自購記憶體 $6.7M）；Bernstein $9.09M；報價 $5–7M（S9） | G16: 無公開報價；純推估，不進基準比較
A17: 標記 | C17: Analogy | D17: Interested-party | E17: Interested-party | F17: Interested-party | G17: Assumed
A19: 註：GPU 數為封裝數（Rubin Ultra 為 144 封裝，NVIDIA 以 576 die 命名為 NVL576）。
A21: B2. 效能規格（Block 2；藍字＝輸入；每 GPU 封裝）
A22: 服務精度 | C22: FP8 | D22: NVFP4 | E22: NVFP4 | F22: NVFP4 | G22: NVFP4 | H22: Hopper 不支援 FP4，以 FP8 服務
A23: 峰值 dense（基準）PF/GPU | C23: 1.979 | D23: 10 | E23: 15 | F23: 35 | G23: 73 | H23: Interested-party（NVIDIA 規格）：H100 FP8 dense 1,979 TF（v5.5 更正；v5.4 誤填 BF16 的 989）；GB200 FP4 10 PF（HGX B200 為 9）；B300 15；Rubin NVFP4 訓練 35；RU＝104×35/50 推估 [Derived]。S28
A24: 峰值（高情境：NVFP4 推論口徑）PF/GPU | C24: 1.979 | D24: 10 | E24: 15 | F24: 50 | G24: 104 | H24: Rubin 50 PF 含自適應壓縮；RU NVL576 15 EF ÷ 144。J2：只作高情境
A25: HBM 容量 GB/GPU | C25: 80 | D25: 186 | E25: 288 | F25: 288 | G25: 1024 | H25: GB200 NVL72 13.4 TB ÷ 72；InferenceX 以 192 計。RU HBM4e 約 1 TB/封裝。S28
A26: HBM 頻寬 TB/s/GPU | C26: 3.35 | D26: 8 | E26: 8 | F26: 22 | G26: 32 | H26: Rubin 22 TB/s（NVIDIA 2026 上修）；RU 4.6 PB/s ÷ 144。S28
A27: EP 通訊頻寬 TB/s/GPU（單向） | C27: 0.05 | D27: 0.9 | E27: 0.9 | F27: 1.8 | G27: 1.8 | H27: Hopper EP 跨節點走 400G IB；NVLink 5＝900 GB/s；NVLink 6＝1.8 TB/s（InferenceX 規格表 S20）；RU 取同 VR [Assumed]
A28: Scale-up 域 GPU 數 | C28: 8 | D28: 72 | E28: 72 | F28: 72 | G28: 144
A29: decode EP 基準寬度 | C29: 64 | D29: 32 | E29: 32 | F29: 32 | G29: 64 | H29: GB300 公開配方 dep32（S21）；Hopper 跨節點 [Analogy DeepSeek]；RU [Assumed]。權重放不下時自動加寬
A30: 專家權重 bytes/param | C30: 1 | D30: 0.5625 | E30: 0.5625 | F30: 0.5625 | G30: 0.5625 | H30: NVFP4＝4 bit＋每 16 值 8 bit scale＝0.5625 B；Hopper FP8
A31: 非專家權重 bytes/param | C31: 1 | D31: 1 | E31: 1 | F31: 1 | G31: 1 | H31: 注意力、路由、embedding 以 FP8 存放 [Analogy V4]
A32: 每 prefill 實例 GPU 數（算 TTFT） | C32: 8 | D32: 4 | E32: 4 | F32: 4 | G32: 8 | H32: GB300 配方 dep4 prefill（S21）
A33: GPU 功率 W/封裝（能量用） | C33: 700 | D33: 1200 | E33: 1400 | F33: 1800 | G33: 3600 | H33: Interested-party；Rubin 約 1.8 kW、RU 推估。僅用於能量下限估算
A34: HBM 存取能量 pJ/byte | C34: 31 | D34: 25 | E34: 25 | F34: 20 | G34: 18 | H34: Analogy：HBM3 約 3.9 pJ/bit、HBM3e 約 3、HBM4 約 2.5；區間 ±30%（S29）
A35: 計算用峰值 PF/GPU（依 Serving 峰值情境） | C35: =IF(Serving!$C$16=2,C24,C23) -> 1.979 | D35: =IF(Serving!$C$16=2,D24,D23) -> 10 | E35: =IF(Serving!$C$16=2,E24,E23) -> 15 | F35: =IF(Serving!$C$16=2,F24,F23) -> 35 | G35: =IF(Serving!$C$16=2,G24,G23) -> 73
A36: Ridge point（FLOP/byte） | C36: =C35*1000/C26 -> 590.74627 | D36: =D35*1000/D26 -> 1250 | E36: =E35*1000/E26 -> 1875 | F36: =F35*1000/F26 -> 1590.9091 | G36: =G35*1000/G26 -> 2281.25
A38: B3. 訓練峰值（Block 3；dense；每 GPU 封裝；MFU 以 FP8 列為分母，J7）
A39: BF16 dense PF/GPU | C39: 0.989 | D39: 2.5 | E39: 2.5 | F39: 4 | G39: 8 | H39: Interested-party（NVIDIA）：H100 989 TF；GB200／GB300 2.5；VR NVL72 288 PF ÷ 72＝4.0（S36）；RU 取 VR×2 [Assumed]
A40: FP8 dense PF/GPU（訓練基準，J7） | C40: 1.979 | D40: 5 | E40: 5 | F40: 17.5 | G40: 34.7 | H40: Interested-party（NVIDIA）：H100 1,979 TF；GB200／GB300 FP8 5 PF（B300 未提升 FP8）；VR NVL72 1,260 PF ÷ 72＝17.5（S36）；RU NVL576 5 EF ÷ 144 [模型內建知識，待查]
A41: NVFP4 訓練 dense PF/GPU（Tech_Registry 情境） | C41: 1.979 | D41: 10 | E41: 15 | F41: 35 | G41: 73 | H41: Hopper 無 FP4，取 FP8；GB200 10（NVIDIA：Rubin 為 Blackwell 3.5 倍）；GB300 15 [Assumed，區間 10–15]；VR 2,520 PF ÷ 72＝35（S36）；RU＝VR × 104/50 [Derived]

Sheet Arch
A1: Arch — 三層級代表架構（D5：每層級一個代表；參數為公開模型卡或推估）
A2: Luna／Sol 以公開權重模型為物理代表 [Analogy：對應封閉層級]；Astra 為封閉前沿代理，KV 以情境處理（J1）
A4: 參數 | B4: 單位 | C4: Luna（低層） | D4: Sol（中層） | E4: Astra（頂層） | F4: 標記 | G4: 來源／說明
A5: 代表架構 | C5: DeepSeek V4-Flash 類 | D5: DeepSeek V4-Pro 類 | E5: 封閉前沿代理 | F5: Decision | G5: D5；Andy 2026-09-30 確認
A6: 總參數 | B6: B | C6: 284 | D6: 1600 | E6: 4000 | F6: Verified／Assumed | G6: V4-Flash 284B、V4-Pro 1.6T（模型卡，S27）；Astra 4T [Assumed，區間 2–10T]
A7: 啟用參數 | B7: B | C7: 13 | D7: 49 | E7: 180 | F7: Verified／Assumed | G7: V4-Flash 13B、V4-Pro 49B；Astra 180B [Assumed，區間 60–250B]
A8: 層數 | B8: 層 | C8: 43 | D8: 61 | E8: 100 | F8: Verified／Assumed | G8: V4-Pro 61（config.json）；V4-Flash 43（二手）；Astra [Assumed]
A9: d_model | C9: 4096 | D9: 7168 | E9: 12288 | F9: Verified／Derived | G9: V4-Pro 7168；V4-Flash 由專家維度反推；Astra [Assumed]
A10: query heads | C10: 64 | D10: 128 | E10: 96 | F10: Verified／Analogy | G10: V4-Pro 128；V4-Flash 取 Pro 一半 [Analogy]
A11: head_dim | C11: 512 | D11: 512 | E11: 128 | F11: Verified／Assumed | G11: V4 單一 512 維 KV head；Astra 128
A12: routed experts | C12: 256 | D12: 384 | E12: 512 | F12: Verified／Assumed
A13: 每 token 啟用 routed experts | C13: 6 | D13: 6 | E13: 16 | F13: Verified／Assumed
A14: shared experts | C14: 1 | D14: 1 | E14: 1 | F14: Verified
A15: vocab | C15: 129280 | D15: 129280 | E15: 200000 | F15: Verified／Assumed
A16: 全注意力層比例 | B16: % | C16: 0.5 | D16: 0.5 | E16: 1 | F16: Verified／Assumed | G16: V4：CSA 與 HCA 約各半；Astra 全層注意力
A17: 全注意力層跨度上限（0＝全上下文） | B17: tok | C17: 4224 | D17: 4224 | E17: 0 | F17: Derived | G17: V4 CSA：top-k 1,024 壓縮塊 × 4 ＋ 128 窗口
A18: 其他層壓縮比 | B18: x | C18: 128 | D18: 128 | E18: 1 | F18: Verified | G18: V4 HCA 128× 壓縮
A19: 其他層滑動窗 | B19: tok | C19: 128 | D19: 128 | E19: 0 | F19: Verified
A20: Astra KV 情境（1 混合／2 全層 MLA／3 GQA-8） | B20: 選擇 | E20: 2 | F20: Decision | G20: J1：基準 2（Andy 2026-09-30 確認）
A21: KV bytes/token — 情境 1 | B21: B | C21: 2795 | D21: 3965 | E21: 14976 | F21: Derived／Assumed | G21: Luna 65×43、Sol 65×61（v4 推導，FP8 KV）；Astra 混合：26% 層 × 576 × 100 層（類 K3）
A22: KV bytes/token — 情境 2 | B22: B | C22: 2795 | D22: 3965 | E22: 57600 | F22: Derived／Assumed | G22: Astra 全層 MLA：576 × 100
A23: KV bytes/token — 情境 3 | B23: B | C23: 2795 | D23: 3965 | E23: 204800 | F23: Derived／Assumed | G23: Astra GQA-8：8 × 128 × 2 × 100
A24: 導出
A25: KV bytes/token（採用） | B25: B | C25: =CHOOSE(IF(C20="",1,C20),C21,C22,C23) -> 2795 | D25: =CHOOSE(IF(D20="",1,D20),D21,D22,D23) -> 3965 | E25: =CHOOSE(IF(E20="",1,E20),E21,E22,E23) -> 57600
A26: Embedding＋LM head 參數 | B26: B | C26: =C15*C9*2/1000000000 -> 1.0590618 | D26: =D15*D9*2/1000000000 -> 1.8533581 | E26: =E15*E9*2/1000000000 -> 4.9152
A27: 每 routed expert 參數 | B27: B | C27: =(C6-C7)/(C8*(C12-C13)) -> 0.025209302 | D27: =(D6-D7)/(D8*(D12-D13)) -> 0.067265157 | E27: =(E6-E7)/(E8*(E12-E13)) -> 0.077016129 | G27: 由公開總參數與啟用參數反推，確保總數吻合（v4 方法）
A28: 非專家參數（注意力、路由、embedding） | B28: B | C28: =C7-C8*(C13+C14)*C27 -> 5.412 | D28: =D7-D8*(D13+D14)*D27 -> 20.277778 | E28: =E7-E8*(E13+E14)*E27 -> 49.072581
A29: 專家參數 | B29: B | C29: =C6-C28 -> 278.588 | D29: =D6-D28 -> 1579.7222 | E29: =E6-E28 -> 3950.9274
A30: 注意力 FLOPs／每個被注意的 token | B30: FLOP | C30: =4*C10*C11*C8 -> 5636096 | D30: =4*D10*D11*D8 -> 15990784 | E30: =4*E10*E11*E8 -> 4915200
A31: 128K 上下文每序列 KV | B31: GB | C31: =C25*128000/1000000000 -> 0.35776 | D31: =D25*128000/1000000000 -> 0.50752 | E31: =E25*128000/1000000000 -> 7.3728

Sheet Serving
A1: Serving — 服務設定與各層級 SLO（主流：分離式 P/D、wide EP、attention DP、NVFP4、MTP、前綴快取）
A2: 藍字＝輸入。SLO 依 J3 採市場觀測輸出速度（Artificial Analysis 2026-09，S26）
A4: 全域設定 | B4: 單位 | C4: 值 | D4: 標記 | F4: 說明
A5: 服務架構 | C5: 分離式 P/D＋wide EP＋attention DP | D5: Decision | F5: D6 與 Block 2 命題
A6: MTP 草稿數 N | B6: tok | C6: 3 | D6: Analogy | F6: DeepSeek MTP；區間 1–5
A7: 每個草稿 token 接受率 α | B7: % | C7: 0.7 | D7: Verified-measured | F7: SGLang 修正後 0.57→0.70（S21）；區間 0.6–0.8
A8: 每步期望接受 token a | B8: tok | C8: =(1-C7^(C6+1))/(1-C7) -> 2.533 | D8: Derived | F8: (1−α^(N+1))/(1−α)
A9: HBM 保留比例（啟用值、工作區） | B9: % | C9: 0.1 | D9: Assumed | F9: 區間 5–20%
A10: 非專家權重占可用 HBM 上限 | B10: % | C10: 0.2 | D10: Assumed | F10: 超過時自動以注意力 TP 切分
A11: 專家權重占可用 HBM 上限 | B11: % | C11: 0.4 | D11: Assumed | F11: 超過時自動加寬 EP
A12: EP 啟用值 bytes/元素（dispatch＋combine） | B12: B | C12: 3 | D12: Analogy | F12: FP8 dispatch 1 B＋BF16 combine 2 B
A13: KV 讀取頻寬效率 η_mem | B13: % | C13: 0.7 | D13: Analogy | F13: 區間 0.5–0.85
A14: EP 通訊效率 η_link | B14: % | C14: 0.7 | D14: Analogy | F14: 區間 0.5–0.85
A15: 快取命中 KV 載入頻寬 | B15: TB/s/GPU | C15: 0.1 | D15: Assumed | F15: 主機記憶體／SSD 經 NIC 載入；區間 0.05–0.4。未計快取儲存成本
A16: 峰值情境（1＝dense 基準／2＝NVFP4 推論高） | B16: 選擇 | C16: 1 | D16: Decision | F16: J2：基準 1
A17: 基準利用率（第 0 層） | B17: % | C17: 0.6 | D17: Assumed | F17: J6：Andy 尚未給值，暫沿用 OpenAI v0.5 的 60%（區間 40–80%）。Unit_Cost 同時輸出 100% 版
A18: 實測→生產效率折減 | B18: x | C18: 1 | D18: Assumed | F18: 待 Andy 決定。基準測試為固定長度、穩態負載；生產環境另有長度變異、路由不均、故障。1.0＝不折減。作用：η_p、η_d 乘此值，每層延遲除以此值。第二來源（MLPerf、DeepSeek 自揭）目前均高於本模型，見 Calib H 節
A19: 各層級 SLO 與參考任務
A20: 項目 | B20: 單位 | C20: =Arch!C4 -> Luna（低層） | D20: =Arch!D4 -> Sol（中層） | E20: =Arch!E4 -> Astra（頂層） | F20: 說明
A21: SLO：每用戶 decode 速度下限 | B21: tok/s | C21: 120 | D21: 65 | E21: 55 | F21: Verified-measured（市場觀測）：GPT-5.6 Luna 約 120、GPT-5.6 Sol 約 68、GPT-6 Astra 約 52–56、Opus 5 約 54 tok/s（S26）。區間 Luna 100–300、Sol 50–100、Astra 30–75
A22: TTFT 上限（只作檢查） | B22: s | C22: 2 | D22: 3 | E22: 5 | F22: Assumed
A23: 參考 ISL（每次請求輸入） | B23: tok | C23: 8192 | D23: 16384 | E23: 32768 | F23: Assumed：Astra 用於長任務；上下文敏感度見 Sens_Perf
A24: 參考 OSL（含思考） | B24: tok | C24: 1024 | D24: 2048 | E24: 4096 | F24: Assumed
A25: decode 平均上下文 | B25: tok | C25: =C23+C24/2 -> 8704 | D25: =D23+D24/2 -> 17408 | E25: =E23+E24/2 -> 34816 | F25: Derived
A26: prefill 平均位置 | B26: tok | C26: =C23/2 -> 4096 | D26: =D23/2 -> 8192 | E26: =E23/2 -> 16384 | F26: Derived

Sheet Workload
A1: Workload — 任務制工作負載（每任務的 token 結構；思考 token 在物理上屬 decode）
A2: 任務組合權重不在第 0 層（J5）；本頁只定義標準任務。harness token 倍數預設 1.0，Block 5 接手
A4: 參數 | B4: 單位 | C4: 一般聊天 | D4: 推理聊天 | E4: 單代理（工具迴圈） | F4: 多代理研究 | G4: Coding agent（長程） | H4: 說明
A5: 輪數 T | B5: 輪 | C5: 1 | D5: 1 | E5: 4 | F5: 4 | G5: 30 | H5: Assumed
A6: 初始上下文 S（系統提示、歷史、工具定義） | B6: tok | C6: 2000 | D6: 2000 | E6: 3000 | F6: 3000 | G6: 12000 | H6: Assumed
A7: 每輪新輸入 u（使用者或工具結果） | B7: tok | C7: 500 | D7: 500 | E7: 1200 | F7: 1200 | G7: 2000 | H7: Assumed
A8: 每輪思考 token h | B8: tok | C8: 0 | D8: 3000 | E8: 400 | F8: 400 | G8: 600 | H8: Assumed；服務端思考占比待查
A9: 每輪可見輸出 o | B9: tok | C9: 500 | D9: 700 | E9: 200 | F9: 200 | G9: 400 | H9: Assumed
A10: 思考保留於上下文比例 ρ | B10: % | C10: 0 | D10: 0 | E10: 0 | F10: 0 | G10: 0 | H10: Assumed：多數 API 不保留前輪思考
A11: 歷史快取命中率 χ | B11: % | C11: 0.5 | D11: 0.5 | E11: 0.9 | F11: 0.9 | G11: 0.9 | H11: Assumed；代理迴圈前綴重用高
A12: 並行子代理數 m | B12: 個 | C12: 0 | D12: 0 | E12: 0 | F12: 3 | G12: 0 | H12: Assumed：子代理沿用單代理參數
A13: harness token 倍數 | B13: x | C13: 1 | D13: 1 | E13: 1 | F13: 1 | G13: 1 | H13: 預設 1.0（Block 5）
A15: 導出（每任務）
A16: 每輪上下文增量 u＋o＋ρh | B16: tok | C16: =C7+C9+C10*C8 -> 1000 | D16: =D7+D9+D10*D8 -> 1200 | E16: =E7+E9+E10*E8 -> 1400 | F16: =F7+F9+F10*F8 -> 1400 | G16: =G7+G9+G10*G8 -> 2400
A17: 單代理輸入總量 | B17: tok | C17: =C5*(C6+C7)+C16*C5*(C5-1)/2 -> 2500 | D17: =D5*(D6+D7)+D16*D5*(D5-1)/2 -> 2500 | E17: =E5*(E6+E7)+E16*E5*(E5-1)/2 -> 25200 | F17: =F5*(F6+F7)+F16*F5*(F5-1)/2 -> 25200 | G17: =G5*(G6+G7)+G16*G5*(G5-1)/2 -> 1464000
A18: 其中可快取（前綴） | B18: tok | C18: =C11*(C5*C6+C16*C5*(C5-1)/2) -> 1000 | D18: =D11*(D5*D6+D16*D5*(D5-1)/2) -> 1000 | E18: =E11*(E5*E6+E16*E5*(E5-1)/2) -> 18360 | F18: =F11*(F5*F6+F16*F5*(F5-1)/2) -> 18360 | G18: =G11*(G5*G6+G16*G5*(G5-1)/2) -> 1263600
A19: 其中新鮮 | B19: tok | C19: =C17-C18 -> 1500 | D19: =D17-D18 -> 1500 | E19: =E17-E18 -> 6840 | F19: =F17-F18 -> 6840 | G19: =G17-G18 -> 200400
A20: 單代理 decode（思考＋可見） | B20: tok | C20: =C5*(C8+C9) -> 500 | D20: =D5*(D8+D9) -> 3700 | E20: =E5*(E8+E9) -> 2400 | F20: =F5*(F8+F9) -> 2400 | G20: =G5*(G8+G9) -> 30000
A21: 系統倍數（1＋m）× harness | B21: x | C21: =(1+C12)*C13 -> 1 | D21: =(1+D12)*D13 -> 1 | E21: =(1+E12)*E13 -> 1 | F21: =(1+F12)*F13 -> 4 | G21: =(1+G12)*G13 -> 1
A22: 任務新鮮 prefill | B22: tok | C22: =C19*C21 -> 1500 | D22: =D19*D21 -> 1500 | E22: =E19*E21 -> 6840 | F22: =F19*F21 -> 27360 | G22: =G19*G21 -> 200400
A23: 任務快取 prefill | B23: tok | C23: =C18*C21 -> 1000 | D23: =D18*D21 -> 1000 | E23: =E18*E21 -> 18360 | F23: =F18*F21 -> 73440 | G23: =G18*G21 -> 1263600
A24: 任務 decode | B24: tok | C24: =C20*C21 -> 500 | D24: =D20*D21 -> 3700 | E24: =E20*E21 -> 2400 | F24: =F20*F21 -> 9600 | G24: =G20*G21 -> 30000
A25: 任務總 token | B25: tok | C25: =C22+C23+C24 -> 3000 | D25: =D22+D23+D24 -> 6200 | E25: =E22+E23+E24 -> 27600 | F25: =F22+F23+F24 -> 110400 | G25: =G22+G23+G24 -> 1494000
A26: decode 平均上下文 | B26: tok | C26: =C6+C7+(C5-1)/2*C16+(C8+C9)/2 -> 2750 | D26: =D6+D7+(D5-1)/2*D16+(D8+D9)/2 -> 4350 | E26: =E6+E7+(E5-1)/2*E16+(E8+E9)/2 -> 6600 | F26: =F6+F7+(F5-1)/2*F16+(F8+F9)/2 -> 6600 | G26: =G6+G7+(G5-1)/2*G16+(G8+G9)/2 -> 49300 | H26: Unit_Cost 的 decode 成本取各層級參考上下文；本列顯示任務實際上下文，差距大時看 Sens_Perf 的 ISL 情境
A27: 思考占 decode | B27: % | C27: =IF(C8+C9>0,C8/(C8+C9),0) -> 0 | D27: =IF(D8+D9>0,D8/(D8+D9),0) -> 0.81081081 | E27: =IF(E8+E9>0,E8/(E8+E9),0) -> 0.66666667 | F27: =IF(F8+F9>0,F8/(F8+F9),0) -> 0.66666667 | G27: =IF(G8+G9>0,G8/(G8+G9),0) -> 0.6
A28: 總 token ÷ 一般聊天 | B28: x | C28: =C25/$C$25 -> 1 | D28: =D25/$C$25 -> 2.0666667 | E28: =E25/$C$25 -> 9.2 | F28: =F25/$C$25 -> 36.8 | G28: =G25/$C$25 -> 498
A29: 總 token ÷ 推理聊天 | B29: x | C29: =C25/$D$25 -> 0.48387097 | D29: =D25/$D$25 -> 1 | E29: =E25/$D$25 -> 4.4516129 | F29: =F25/$D$25 -> 17.806452 | G29: =G25/$D$25 -> 240.96774
A30: 參照：Anthropic 揭露倍數（相對聊天） | B30: x | C30: 1 | E30: 4 | F30: 15 | H30: Interested-party：Anthropic 2025-06 多代理研究系統文章，agent 約 4 倍、多代理約 15 倍聊天 token（S25）。其『聊天』口徑未說明是否含思考，故兩個倍數並列
A32: 每任務成本（$／任務；經濟口徑、基準成本情境、基準利用率）
A33: VR200 × Luna | B33: $ | C33: =IF(ISNUMBER(Unit_Cost!M21),(C22*Unit_Cost!M19+C23*Unit_Cost!M20+C24*Unit_Cost!M21)/1000000,"SLO 不可達") -> 9.5539556e-05 | D33: =IF(ISNUMBER(Unit_Cost!M21),(D22*Unit_Cost!M19+D23*Unit_Cost!M20+D24*Unit_Cost!M21)/1000000,"SLO 不可達") -> 0.00063074831 | E33: =IF(ISNUMBER(Unit_Cost!M21),(E22*Unit_Cost!M19+E23*Unit_Cost!M20+E24*Unit_Cost!M21)/1000000,"SLO 不可達") -> 0.00045657296 | F33: =IF(ISNUMBER(Unit_Cost!M21),(F22*Unit_Cost!M19+F23*Unit_Cost!M20+F24*Unit_Cost!M21)/1000000,"SLO 不可達") -> 0.0018262919 | G33: =IF(ISNUMBER(Unit_Cost!M21),(G22*Unit_Cost!M19+G23*Unit_Cost!M20+G24*Unit_Cost!M21)/1000000,"SLO 不可達") -> 0.0066781516
A34: VR200 × Sol | B34: $ | C34: =IF(ISNUMBER(Unit_Cost!M34),(C22*Unit_Cost!M32+C23*Unit_Cost!M33+C24*Unit_Cost!M34)/1000000,"SLO 不可達") -> 0.00031048515 | D34: =IF(ISNUMBER(Unit_Cost!M34),(D22*Unit_Cost!M32+D23*Unit_Cost!M33+D24*Unit_Cost!M34)/1000000,"SLO 不可達") -> 0.0020308889 | E34: =IF(ISNUMBER(Unit_Cost!M34),(E22*Unit_Cost!M32+E23*Unit_Cost!M33+E24*Unit_Cost!M34)/1000000,"SLO 不可達") -> 0.0014815223 | F34: =IF(ISNUMBER(Unit_Cost!M34),(F22*Unit_Cost!M32+F23*Unit_Cost!M33+F24*Unit_Cost!M34)/1000000,"SLO 不可達") -> 0.005926089 | G34: =IF(ISNUMBER(Unit_Cost!M34),(G22*Unit_Cost!M32+G23*Unit_Cost!M33+G24*Unit_Cost!M34)/1000000,"SLO 不可達") -> 0.021794011
A35: VR200 × Astra | B35: $ | C35: =IF(ISNUMBER(Unit_Cost!M47),(C22*Unit_Cost!M45+C23*Unit_Cost!M46+C24*Unit_Cost!M47)/1000000,"SLO 不可達") -> 0.001522567 | D35: =IF(ISNUMBER(Unit_Cost!M47),(D22*Unit_Cost!M45+D23*Unit_Cost!M46+D24*Unit_Cost!M47)/1000000,"SLO 不可達") -> 0.010379432 | E35: =IF(ISNUMBER(Unit_Cost!M47),(E22*Unit_Cost!M45+E23*Unit_Cost!M46+E24*Unit_Cost!M47)/1000000,"SLO 不可達") -> 0.0072923954 | F35: =IF(ISNUMBER(Unit_Cost!M47),(F22*Unit_Cost!M45+F23*Unit_Cost!M46+F24*Unit_Cost!M47)/1000000,"SLO 不可達") -> 0.029169582 | G35: =IF(ISNUMBER(Unit_Cost!M47),(G22*Unit_Cost!M45+G23*Unit_Cost!M46+G24*Unit_Cost!M47)/1000000,"SLO 不可達") -> 0.10298231
A36: GB300 × Luna | B36: $ | C36: =IF(ISNUMBER(Unit_Cost!J21),(C22*Unit_Cost!J19+C23*Unit_Cost!J20+C24*Unit_Cost!J21)/1000000,"SLO 不可達") -> 0.00014928998 | D36: =IF(ISNUMBER(Unit_Cost!J21),(D22*Unit_Cost!J19+D23*Unit_Cost!J20+D24*Unit_Cost!J21)/1000000,"SLO 不可達") -> 0.00099239332 | E36: =IF(ISNUMBER(Unit_Cost!J21),(E22*Unit_Cost!J19+E23*Unit_Cost!J20+E24*Unit_Cost!J21)/1000000,"SLO 不可達") -> 0.00071291214 | F36: =IF(ISNUMBER(Unit_Cost!J21),(F22*Unit_Cost!J19+F23*Unit_Cost!J20+F24*Unit_Cost!J21)/1000000,"SLO 不可達") -> 0.0028516486 | G36: =IF(ISNUMBER(Unit_Cost!J21),(G22*Unit_Cost!J19+G23*Unit_Cost!J20+G24*Unit_Cost!J21)/1000000,"SLO 不可達") -> 0.010293136
A37: GB300 × Sol | B37: $ | C37: =IF(ISNUMBER(Unit_Cost!J34),(C22*Unit_Cost!J32+C23*Unit_Cost!J33+C24*Unit_Cost!J34)/1000000,"SLO 不可達") -> 0.00052566753 | D37: =IF(ISNUMBER(Unit_Cost!J34),(D22*Unit_Cost!J32+D23*Unit_Cost!J33+D24*Unit_Cost!J34)/1000000,"SLO 不可達") -> 0.0034962472 | E37: =IF(ISNUMBER(Unit_Cost!J34),(E22*Unit_Cost!J32+E23*Unit_Cost!J33+E24*Unit_Cost!J34)/1000000,"SLO 不可達") -> 0.0025091975 | F37: =IF(ISNUMBER(Unit_Cost!J34),(F22*Unit_Cost!J32+F23*Unit_Cost!J33+F24*Unit_Cost!J34)/1000000,"SLO 不可達") -> 0.01003679 | G37: =IF(ISNUMBER(Unit_Cost!J34),(G22*Unit_Cost!J32+G23*Unit_Cost!J33+G24*Unit_Cost!J34)/1000000,"SLO 不可達") -> 0.036129486
A38: GB300 × Astra | B38: $ | C38: =IF(ISNUMBER(Unit_Cost!J47),(C22*Unit_Cost!J45+C23*Unit_Cost!J46+C24*Unit_Cost!J47)/1000000,"SLO 不可達") -> 0.0035581725 | D38: =IF(ISNUMBER(Unit_Cost!J47),(D22*Unit_Cost!J45+D23*Unit_Cost!J46+D24*Unit_Cost!J47)/1000000,"SLO 不可達") -> 0.025025535 | E38: =IF(ISNUMBER(Unit_Cost!J47),(E22*Unit_Cost!J45+E23*Unit_Cost!J46+E24*Unit_Cost!J47)/1000000,"SLO 不可達") -> 0.017041287 | F38: =IF(ISNUMBER(Unit_Cost!J47),(F22*Unit_Cost!J45+F23*Unit_Cost!J46+F24*Unit_Cost!J47)/1000000,"SLO 不可達") -> 0.068165147 | G38: =IF(ISNUMBER(Unit_Cost!J47),(G22*Unit_Cost!J45+G23*Unit_Cost!J46+G24*Unit_Cost!J47)/1000000,"SLO 不可達") -> 0.22939741

Sheet Calib
A1: Calib — 以實測錨點校準效率係數（實測只校準係數，不取代推導）
A2: 錨點：DeepSeek V4-Pro（＝Sol 代表架構）、FP4、8K/1K、分離式 P/D，tok/s/GPU 為總 token 口徑。GB300 同一前緣上兩點聯立解出 η_d 與每層延遲；其餘各點為樣本外驗證
A4: A. 輸入
A5: η_p：prefill 達成峰值比例 | B5: % | C5: 0.3 | J5: Analogy：DeepSeek H800 線上 prefill 約 0.37（S30，待查）；區間 0.15–0.45。擬合結果對此不敏感（見 G 節）
A7: B. 錨點（每欄一個實測點）
A8: 項目 | B8: 單位
A9: 用途 | C9: 擬合點 1 | D9: 擬合點 2 | E9: 驗證 | F9: 驗證（舊軟體） | G9: 驗證（舊軟體） | H9: 驗證（口徑待查） | I9: 驗證（口徑待查）
A10: 世代索引 | C10: 3 | D10: 3 | E10: 3 | F10: 3 | G10: 2 | H10: 2 | I10: 3
A11: 世代 | C11: =INDEX(Spec_Rack!$C$4:$G$4,C10) -> GB300 NVL72 | D11: =INDEX(Spec_Rack!$C$4:$G$4,D10) -> GB300 NVL72 | E11: =INDEX(Spec_Rack!$C$4:$G$4,E10) -> GB300 NVL72 | F11: =INDEX(Spec_Rack!$C$4:$G$4,F10) -> GB300 NVL72 | G11: =INDEX(Spec_Rack!$C$4:$G$4,G10) -> GB200 NVL72 | H11: =INDEX(Spec_Rack!$C$4:$G$4,H10) -> GB200 NVL72 | I11: =INDEX(Spec_Rack!$C$4:$G$4,I10) -> GB300 NVL72
A12: 軟體／日期 | C12: InferenceX 最佳前緣（約 2026-07） | D12: InferenceX 最佳前緣（約 2026-07） | E12: SGLang＋MTP，2026-06 | F12: vLLM 無 MTP，2026-05-22 | G12: vLLM 無 MTP，2026-05-22 | H12: InferenceX 比較頁（0813） | I12: InferenceX 比較頁（0813）
A13: MTP（1＝有） | C13: 1 | D13: 1 | E13: 1 | F13: 0 | G13: 0 | H13: 1 | I13: 1
A14: 每用戶速度 | B14: tok/s | C14: 72 | D14: 130 | E14: 50 | F14: 27 | G14: 27 | H14: 110 | I14: 110
A15: ISL | B15: tok | C15: 8192 | D15: 8192 | E15: 8192 | F15: 8192 | G15: 8192 | H15: 8192 | I15: 8192
A16: OSL | B16: tok | C16: 1024 | D16: 1024 | E16: 1024 | F16: 1024 | G16: 1024 | H16: 1024 | I16: 1024
A17: 實測 tok/s/GPU（總 token） | B17: tok/s | C17: 9384.4 | D17: 3473.9 | E17: 11200 | F17: 6182 | G17: 2189 | H17: 3795.5 | I17: 6522.4
A18: 來源 | C18: S22 | D18: S22 | E18: S21 | F18: S20 | G18: S20 | H18: S23 | I18: S23
A19: 量測平台（獨立性） | C19: InferenceX（SemiAnalysis） | D19: InferenceX（SemiAnalysis） | E19: InferenceX（SemiAnalysis） | F19: InferenceX（SemiAnalysis） | G19: InferenceX（SemiAnalysis） | H19: InferenceX（SemiAnalysis） | I19: InferenceX（SemiAnalysis） | J19: 七個點全部來自同一平台（S21 為 SGLang 作者轉述 InferenceX 資料，不構成獨立來源）。第二來源見 H 節
A20: 點位標籤（世代｜用途｜速度） | C20: =C11&"｜"&C9&"｜"&TEXT(C14,"0")&" tok/s" -> GB300 NVL72｜擬合點 1｜72 tok/s | D20: =D11&"｜"&D9&"｜"&TEXT(D14,"0")&" tok/s" -> GB300 NVL72｜擬合點 2｜130 tok/s | E20: =E11&"｜"&E9&"｜"&TEXT(E14,"0")&" tok/s" -> GB300 NVL72｜驗證｜50 tok/s | F20: =F11&"｜"&F9&"｜"&TEXT(F14,"0")&" tok/s" -> GB300 NVL72｜驗證（舊軟體）｜27 tok/s | G20: =G11&"｜"&G9&"｜"&TEXT(G14,"0")&" tok/s" -> GB200 NVL72｜驗證（舊軟體）｜27 tok/s | H20: =H11&"｜"&H9&"｜"&TEXT(H14,"0")&" tok/s" -> GB200 NVL72｜驗證（口徑待查）｜110 tok/s | I20: =I11&"｜"&I9&"｜"&TEXT(I14,"0")&" tok/s" -> GB300 NVL72｜驗證（口徑待查）｜110 tok/s
A21: 口徑 | C21: 總 token（輸入＋輸出） | D21: 總 token（輸入＋輸出） | E21: 總 token（輸入＋輸出） | F21: 總 token（輸入＋輸出） | G21: 總 token（輸入＋輸出） | H21: 總 token（輸入＋輸出） | I21: 總 token（輸入＋輸出）
A22: C. 各點的模型量（Sol 架構；與 Perf 同一套公式）
A23: 計算用峰值 | B23: PF/GPU | C23: =INDEX(Spec_Rack!$C$35:$G$35,C10) -> 15 | D23: =INDEX(Spec_Rack!$C$35:$G$35,D10) -> 15 | E23: =INDEX(Spec_Rack!$C$35:$G$35,E10) -> 15 | F23: =INDEX(Spec_Rack!$C$35:$G$35,F10) -> 15 | G23: =INDEX(Spec_Rack!$C$35:$G$35,G10) -> 10 | H23: =INDEX(Spec_Rack!$C$35:$G$35,H10) -> 10 | I23: =INDEX(Spec_Rack!$C$35:$G$35,I10) -> 15
A24: HBM 容量 | B24: GB | C24: =INDEX(Spec_Rack!$C$25:$G$25,C10) -> 288 | D24: =INDEX(Spec_Rack!$C$25:$G$25,D10) -> 288 | E24: =INDEX(Spec_Rack!$C$25:$G$25,E10) -> 288 | F24: =INDEX(Spec_Rack!$C$25:$G$25,F10) -> 288 | G24: =INDEX(Spec_Rack!$C$25:$G$25,G10) -> 186 | H24: =INDEX(Spec_Rack!$C$25:$G$25,H10) -> 186 | I24: =INDEX(Spec_Rack!$C$25:$G$25,I10) -> 288
A25: HBM 頻寬 | B25: TB/s | C25: =INDEX(Spec_Rack!$C$26:$G$26,C10) -> 8 | D25: =INDEX(Spec_Rack!$C$26:$G$26,D10) -> 8 | E25: =INDEX(Spec_Rack!$C$26:$G$26,E10) -> 8 | F25: =INDEX(Spec_Rack!$C$26:$G$26,F10) -> 8 | G25: =INDEX(Spec_Rack!$C$26:$G$26,G10) -> 8 | H25: =INDEX(Spec_Rack!$C$26:$G$26,H10) -> 8 | I25: =INDEX(Spec_Rack!$C$26:$G$26,I10) -> 8
A26: EP 通訊頻寬 | B26: TB/s | C26: =INDEX(Spec_Rack!$C$27:$G$27,C10) -> 0.9 | D26: =INDEX(Spec_Rack!$C$27:$G$27,D10) -> 0.9 | E26: =INDEX(Spec_Rack!$C$27:$G$27,E10) -> 0.9 | F26: =INDEX(Spec_Rack!$C$27:$G$27,F10) -> 0.9 | G26: =INDEX(Spec_Rack!$C$27:$G$27,G10) -> 0.9 | H26: =INDEX(Spec_Rack!$C$27:$G$27,H10) -> 0.9 | I26: =INDEX(Spec_Rack!$C$27:$G$27,I10) -> 0.9
A27: EP 基準寬度 | C27: =INDEX(Spec_Rack!$C$29:$G$29,C10) -> 32 | D27: =INDEX(Spec_Rack!$C$29:$G$29,D10) -> 32 | E27: =INDEX(Spec_Rack!$C$29:$G$29,E10) -> 32 | F27: =INDEX(Spec_Rack!$C$29:$G$29,F10) -> 32 | G27: =INDEX(Spec_Rack!$C$29:$G$29,G10) -> 32 | H27: =INDEX(Spec_Rack!$C$29:$G$29,H10) -> 32 | I27: =INDEX(Spec_Rack!$C$29:$G$29,I10) -> 32
A28: 專家 bytes/param | B28: B | C28: =INDEX(Spec_Rack!$C$30:$G$30,C10) -> 0.5625 | D28: =INDEX(Spec_Rack!$C$30:$G$30,D10) -> 0.5625 | E28: =INDEX(Spec_Rack!$C$30:$G$30,E10) -> 0.5625 | F28: =INDEX(Spec_Rack!$C$30:$G$30,F10) -> 0.5625 | G28: =INDEX(Spec_Rack!$C$30:$G$30,G10) -> 0.5625 | H28: =INDEX(Spec_Rack!$C$30:$G$30,H10) -> 0.5625 | I28: =INDEX(Spec_Rack!$C$30:$G$30,I10) -> 0.5625
A29: 非專家 bytes/param | B29: B | C29: =INDEX(Spec_Rack!$C$31:$G$31,C10) -> 1 | D29: =INDEX(Spec_Rack!$C$31:$G$31,D10) -> 1 | E29: =INDEX(Spec_Rack!$C$31:$G$31,E10) -> 1 | F29: =INDEX(Spec_Rack!$C$31:$G$31,F10) -> 1 | G29: =INDEX(Spec_Rack!$C$31:$G$31,G10) -> 1 | H29: =INDEX(Spec_Rack!$C$31:$G$31,H10) -> 1 | I29: =INDEX(Spec_Rack!$C$31:$G$31,I10) -> 1
A30: 啟用參數 | B30: B | C30: =Arch!$D$7 -> 49 | D30: =Arch!$D$7 -> 49 | E30: =Arch!$D$7 -> 49 | F30: =Arch!$D$7 -> 49 | G30: =Arch!$D$7 -> 49 | H30: =Arch!$D$7 -> 49 | I30: =Arch!$D$7 -> 49
A31: 層數 | C31: =Arch!$D$8 -> 61 | D31: =Arch!$D$8 -> 61 | E31: =Arch!$D$8 -> 61 | F31: =Arch!$D$8 -> 61 | G31: =Arch!$D$8 -> 61 | H31: =Arch!$D$8 -> 61 | I31: =Arch!$D$8 -> 61
A32: d_model | C32: =Arch!$D$9 -> 7168 | D32: =Arch!$D$9 -> 7168 | E32: =Arch!$D$9 -> 7168 | F32: =Arch!$D$9 -> 7168 | G32: =Arch!$D$9 -> 7168 | H32: =Arch!$D$9 -> 7168 | I32: =Arch!$D$9 -> 7168
A33: 啟用專家 | C33: =Arch!$D$13 -> 6 | D33: =Arch!$D$13 -> 6 | E33: =Arch!$D$13 -> 6 | F33: =Arch!$D$13 -> 6 | G33: =Arch!$D$13 -> 6 | H33: =Arch!$D$13 -> 6 | I33: =Arch!$D$13 -> 6
A34: 非專家參數 | B34: B | C34: =Arch!$D$28 -> 20.277778 | D34: =Arch!$D$28 -> 20.277778 | E34: =Arch!$D$28 -> 20.277778 | F34: =Arch!$D$28 -> 20.277778 | G34: =Arch!$D$28 -> 20.277778 | H34: =Arch!$D$28 -> 20.277778 | I34: =Arch!$D$28 -> 20.277778
A35: 專家參數 | B35: B | C35: =Arch!$D$29 -> 1579.7222 | D35: =Arch!$D$29 -> 1579.7222 | E35: =Arch!$D$29 -> 1579.7222 | F35: =Arch!$D$29 -> 1579.7222 | G35: =Arch!$D$29 -> 1579.7222 | H35: =Arch!$D$29 -> 1579.7222 | I35: =Arch!$D$29 -> 1579.7222
A36: KV bytes/token | B36: B | C36: =Arch!$D$25 -> 3965 | D36: =Arch!$D$25 -> 3965 | E36: =Arch!$D$25 -> 3965 | F36: =Arch!$D$25 -> 3965 | G36: =Arch!$D$25 -> 3965 | H36: =Arch!$D$25 -> 3965 | I36: =Arch!$D$25 -> 3965
A37: 注意力 FLOPs／被注意 token | C37: =Arch!$D$30 -> 15990784 | D37: =Arch!$D$30 -> 15990784 | E37: =Arch!$D$30 -> 15990784 | F37: =Arch!$D$30 -> 15990784 | G37: =Arch!$D$30 -> 15990784 | H37: =Arch!$D$30 -> 15990784 | I37: =Arch!$D$30 -> 15990784
A38: 全注意力層比例 | B38: % | C38: =Arch!$D$16 -> 0.5 | D38: =Arch!$D$16 -> 0.5 | E38: =Arch!$D$16 -> 0.5 | F38: =Arch!$D$16 -> 0.5 | G38: =Arch!$D$16 -> 0.5 | H38: =Arch!$D$16 -> 0.5 | I38: =Arch!$D$16 -> 0.5
A39: 跨度上限 | C39: =Arch!$D$17 -> 4224 | D39: =Arch!$D$17 -> 4224 | E39: =Arch!$D$17 -> 4224 | F39: =Arch!$D$17 -> 4224 | G39: =Arch!$D$17 -> 4224 | H39: =Arch!$D$17 -> 4224 | I39: =Arch!$D$17 -> 4224
A40: 壓縮比 | C40: =Arch!$D$18 -> 128 | D40: =Arch!$D$18 -> 128 | E40: =Arch!$D$18 -> 128 | F40: =Arch!$D$18 -> 128 | G40: =Arch!$D$18 -> 128 | H40: =Arch!$D$18 -> 128 | I40: =Arch!$D$18 -> 128
A41: 滑動窗 | C41: =Arch!$D$19 -> 128 | D41: =Arch!$D$19 -> 128 | E41: =Arch!$D$19 -> 128 | F41: =Arch!$D$19 -> 128 | G41: =Arch!$D$19 -> 128 | H41: =Arch!$D$19 -> 128 | I41: =Arch!$D$19 -> 128
A42: decode 平均上下文 | B42: tok | C42: =C15+C16/2 -> 8704 | D42: =D15+D16/2 -> 8704 | E42: =E15+E16/2 -> 8704 | F42: =F15+F16/2 -> 8704 | G42: =G15+G16/2 -> 8704 | H42: =H15+H16/2 -> 8704 | I42: =I15+I16/2 -> 8704
...

Sheet Tech_Registry
A1: Tech_Registry — 新技術登錄與掛鉤（每列＝技術 × 作用物理量；基準值只在『已在基準＝否』且開關＝1 時套用）
A2: 有效倍數＝1＋開關 × 採用比例 ×（所選倍數−1）；已在基準者恆為 1，避免重複計算。主流判定（J14）：至少兩家實驗室公開採用；L 欄可由 Andy 覆寫
A4: ID | B4: 技術 | C4: 掛鉤代碼 | D4: 作用物理量 | E4: 倍數 低 | F4: 倍數 基準 | G4: 倍數 高 | H4: 情境（1／2／3） | I4: 狀態 | J4: 公開採用實驗室數 | K4: 主流判定（J14） | L4: Andy 覆寫 | M4: 已在基準 | N4: 採用比例 | O4: 開關（0／1） | P4: 有效倍數 | Q4: 證據標記 | R4: 來源／說明 | S4: 下次檢查觸發 | T4: 一致性檢查
A5: T01 | B5: MTP 推測解碼 | C5: — | D5: Serving!C6:C8（N、α） | E5: 1 | F5: 1 | G5: 1 | H5: 2 | I5: 主流 | J5: 3 | K5: =IF(J5>=2,"主流","非主流") -> 主流 | M5: 是 | N5: 1 | O5: 1 | P5: =IF(M5="是",1,1+O5*N5*(CHOOSE(H5,E5,F5,G5)-1)) -> 1 | Q5: Verified | R5: DeepSeek V3／V4、GLM-4.5、MiMo 公開採用；已在 Serving 基準 | S5: — | T5: =IF(AND(IF(L5="",K5,L5)="主流",M5="否"),"主流但未入基準：須 Andy 判定",IF(AND(IF(L5="",K5,L5)="非主流",M5="是",I5<>"早期採用"),"非主流卻在基準","一致")) -> 一致
A6: T02 | B6: 壓縮／稀疏注意力（CSA/HCA 類） | C6: — | D6: Arch 列 16–19 | E6: 1 | F6: 1 | G6: 1 | H6: 2 | I6: 主流 | J6: 3 | K6: =IF(J6>=2,"主流","非主流") -> 主流 | M6: 是 | N6: 1 | O6: 1 | P6: =IF(M6="是",1,1+O6*N6*(CHOOSE(H6,E6,F6,G6)-1)) -> 1 | Q6: Verified | R6: DeepSeek V4 CSA/HCA、DeepSeek／GLM 稀疏注意力、Qwen3-Next 混合注意力；Luna／Sol 基準已含（S27、S35） | S6: — | T6: =IF(AND(IF(L6="",K6,L6)="主流",M6="否"),"主流但未入基準：須 Andy 判定",IF(AND(IF(L6="",K6,L6)="非主流",M6="是",I6<>"早期採用"),"非主流卻在基準","一致")) -> 一致
A7: T03 | B7: FP4 權重推論（NVFP4／MXFP4） | C7: — | D7: Spec_Rack 專家 bytes/param | E7: 1 | F7: 1 | G7: 1 | H7: 2 | I7: 主流 | J7: 2 | K7: =IF(J7>=2,"主流","非主流") -> 主流 | M7: 是 | N7: 1 | O7: 1 | P7: =IF(M7="是",1,1+O7*N7*(CHOOSE(H7,E7,F7,G7)-1)) -> 1 | Q7: Verified | R7: DeepSeek V4 原生 FP4 專家權重、OpenAI gpt-oss MXFP4；已在基準 | S7: — | T7: =IF(AND(IF(L7="",K7,L7)="主流",M7="否"),"主流但未入基準：須 Andy 判定",IF(AND(IF(L7="",K7,L7)="非主流",M7="是",I7<>"早期採用"),"非主流卻在基準","一致")) -> 一致
A8: T04 | B8: FP4 量化感知訓練（後訓練） | C8: — | D8: Spec_Rack 專家 bytes/param | E8: 1 | F8: 1 | G8: 1 | H8: 2 | I8: 主流 | J8: 2 | K8: =IF(J8>=2,"主流","非主流") -> 主流 | M8: 是 | N8: 1 | O8: 1 | P8: =IF(M8="是",1,1+O8*N8*(CHOOSE(H8,E8,F8,G8)-1)) -> 1 | Q8: Interested-party | R8: DeepSeek V4：主權重量化到 FP4 再反量化到 FP8 計算，沿用 FP8 訓練框架（S35） | S8: — | T8: =IF(AND(IF(L8="",K8,L8)="主流",M8="否"),"主流但未入基準：須 Andy 判定",IF(AND(IF(L8="",K8,L8)="非主流",M8="是",I8<>"早期採用"),"非主流卻在基準","一致")) -> 一致
A9: T05 | B9: On-policy 蒸餾（多專家整合） | C9: — | D9: Training G 節 | E9: 1 | F9: 1 | G9: 1 | H9: 2 | I9: 主流 | J9: 2 | K9: =IF(J9>=2,"主流","非主流") -> 主流 | M9: 是 | N9: 1 | O9: 1 | P9: =IF(M9="是",1,1+O9*N9*(CHOOSE(H9,E9,F9,G9)-1)) -> 1 | Q9: Interested-party | R9: DeepSeek V4（專家 SFT＋GRPO 後以 on-policy 蒸餾整合，S35）、Qwen3；已在 Training 基準 | S9: — | T9: =IF(AND(IF(L9="",K9,L9)="主流",M9="否"),"主流但未入基準：須 Andy 判定",IF(AND(IF(L9="",K9,L9)="非主流",M9="是",I9<>"早期採用"),"非主流卻在基準","一致")) -> 一致
A10: T06 | B10: Muon 優化器 | C10: H_TOK | D10: 預訓練所需 token | E10: 0.7 | F10: 0.85 | G10: 1 | H10: 2 | I10: 早期採用 | J10: 2 | K10: =IF(J10>=2,"主流","非主流") -> 主流 | M10: 是 | N10: 1 | O10: 0 | P10: =IF(M10="是",1,1+O10*N10*(CHOOSE(H10,E10,F10,G10)-1)) -> 1 | Q10: Interested-party | R10: Moonshot Kimi K2、DeepSeek V4 採用；Luna／Sol 的 token 數為實際值，已隱含其效果，故不套倍數 | S10: 第三家前沿實驗室採用，或公開同品質 token 節省的對照實驗 | T10: =IF(AND(IF(L10="",K10,L10)="主流",M10="否"),"主流但未入基準：須 Andy 判定",IF(AND(IF(L10="",K10,L10)="非主流",M10="是",I10<>"早期採用"),"非主流卻在基準","一致")) -> 一致
A11: T07 | B11: NVFP4 預訓練 | C11: H_TPK | D11: 訓練峰值 | E11: 1.5 | F11: 2 | G11: 3 | H11: 2 | I11: 早期採用 | J11: 1 | K11: =IF(J11>=2,"主流","非主流") -> 非主流 | M11: 否 | N11: 1 | O11: 0 | P11: =IF(M11="是",1,1+O11*N11*(CHOOSE(H11,E11,F11,G11)-1)) -> 1 | Q11: Interested-party | R11: 倍數＝NVFP4 訓練峰值 ÷ FP8（VR 35/17.5＝2；GB300 15/5＝3 [Assumed]）。NVIDIA 公開 12B 模型 10T token NVFP4 預訓練；前沿實驗室未見公開採用。MFU 可能同步下降，未計 | S11: 任一前沿實驗室公開以 FP4 完成主預訓練 | T11: =IF(AND(IF(L11="",K11,L11)="主流",M11="否"),"主流但未入基準：須 Andy 判定",IF(AND(IF(L11="",K11,L11)="非主流",M11="是",I11<>"早期採用"),"非主流卻在基準","一致")) -> 一致
A12: T08 | B12: Looped transformer（權重共享迴圈）— 計算量 | C12: H_FLOP | D12: 每 token FLOPs | E12: 1.5 | F12: 2 | G12: 4 | H12: 2 | I12: 研究 | J12: 0 | K12: =IF(J12>=2,"主流","非主流") -> 非主流 | M12: 否 | N12: 1 | O12: 0 | P12: =IF(M12="是",1,1+O12*N12*(CHOOSE(H12,E12,F12,G12)-1)) -> 1 | Q12: Assumed | R12: 同一組權重迴圈 k 次：FLOPs × k、權重 bytes × 1；能力增量於 Block 4（H_CAP）處理 | S12: 前沿模型卡或技術報告揭露迴圈深度 | T12: =IF(AND(IF(L12="",K12,L12)="主流",M12="否"),"主流但未入基準：須 Andy 判定",IF(AND(IF(L12="",K12,L12)="非主流",M12="是",I12<>"早期採用"),"非主流卻在基準","一致")) -> 一致
A13: T09 | B13: Looped transformer — 每層延遲 | C13: H_TL | D13: 每步逐層延遲 | E13: 1.5 | F13: 2 | G13: 4 | H13: 2 | I13: 研究 | J13: 0 | K13: =IF(J13>=2,"主流","非主流") -> 非主流 | M13: 否 | N13: 1 | O13: 0 | P13: =IF(M13="是",1,1+O13*N13*(CHOOSE(H13,E13,F13,G13)-1)) -> 1 | Q13: Assumed | R13: 迴圈使有效層數 × k，逐層延遲同比增加；與 T08 同時開關 | S13: 同 T08 | T13: =IF(AND(IF(L13="",K13,L13)="主流",M13="否"),"主流但未入基準：須 Andy 判定",IF(AND(IF(L13="",K13,L13)="非主流",M13="是",I13<>"早期採用"),"非主流卻在基準","一致")) -> 一致
A14: T10 | B14: 非同步 RL（rollout 與訓練解耦、部分 rollout） | C14: H_ROLL | D14: rollout 效率 | E14: 1.2 | F14: 1.4 | G14: 1.6 | H14: 2 | I14: 主流 | J14: 4 | K14: =IF(J14>=2,"主流","非主流") -> 主流 | M14: 是 | N14: 1 | O14: 0 | P14: =IF(M14="是",1,1+O14*N14*(CHOOSE(H14,E14,F14,G14)-1)) -> 1 | Q14: Interested-party | R14: 旗艦模型公開採用：DeepSeek V4.1（幾乎全部 RL 與 OPD，S45）、Zhipu GLM-5（slime，S46）、Moonshot Kimi-Researcher（完全非同步 rollout，S47）、Meta Llama 3（LlamaRL，S48）。閉源四家未找到披露。v5.6 起併入基準：Train_In rollout 效率 0.85（Andy 2026-10-01 決定 (a)） | S14: 閉源實驗室披露同步做法，或前沿規模對照實驗顯示 off-policy 偏差抵銷吞吐增益 | T14: =IF(AND(IF(L14="",K14,L14)="主流",M14="否"),"主流但未入基準：須 Andy 判定",IF(AND(IF(L14="",K14,L14)="非主流",M14="是",I14<>"早期採用"),"非主流卻在基準","一致")) -> 一致
A15: T11 | B15: KV 快取壓縮（FP4 KV 等） | C15: H_KV | D15: KV bytes/token | E15: 0.5 | F15: 0.5 | G15: 0.75 | H15: 2 | I15: 早期採用 | J15: 1 | K15: =IF(J15>=2,"主流","非主流") -> 非主流 | M15: 否 | N15: 1 | O15: 0 | P15: =IF(M15="是",1,1+O15*N15*(CHOOSE(H15,E15,F15,G15)-1)) -> 1 | Q15: Assumed | R15: FP8 → FP4 KV：bytes × 0.5；準確率損失待查 | S15: 第二家實驗室在生產服務公開採用 | T15: =IF(AND(IF(L15="",K15,L15)="主流",M15="否"),"主流但未入基準：須 Andy 判定",IF(AND(IF(L15="",K15,L15)="非主流",M15="是",I15<>"早期採用"),"非主流卻在基準","一致")) -> 一致
A16: T12 | B16: Harness（代理框架） | C16: H_HAR | D16: Block 5 占位 | E16: 1 | F16: 1 | G16: 1 | H16: 2 | I16: 追蹤中 | J16: 0 | K16: =IF(J16>=2,"主流","非主流") -> 非主流 | M16: 否 | N16: 1 | O16: 0 | P16: =IF(M16="是",1,1+O16*N16*(CHOOSE(H16,E16,F16,G16)-1)) -> 1 | Q16: Assumed | R16: ARC-AGI-3：GPT-6 Astra 標準 harness 62.7% → Provider Adapter 99.9%；Opus 5 30.2% → Strands 99.95%。Block 5 參數化 | S16: Block 5 | T16: =IF(AND(IF(L16="",K16,L16)="主流",M16="否"),"主流但未入基準：須 Andy 判定",IF(AND(IF(L16="",K16,L16)="非主流",M16="是",I16<>"早期採用"),"非主流卻在基準","一致")) -> 一致
A18: 掛鉤彙總（同一掛鉤多條目時取乘積；Perf、Perf_Batch、Training 連結本表 E 欄）
A19: 代碼 | B19: 意義 | D19: 作用位置 | E19: 倍數
A20: H_ETAD | B20: decode η_d 倍數 | D20: Perf／Perf_Batch：etadm 列 | E20: =EXP(SUMPRODUCT(($C$5:$C$16="H_ETAD")*LN($P$5:$P$16))) -> 1
A21: H_TL | B21: 每層延遲倍數 | D21: Perf／Perf_Batch：tlm 列 | E21: =EXP(SUMPRODUCT(($C$5:$C$16="H_TL")*LN($P$5:$P$16))) -> 1
A22: H_FLOP | B22: 每 token FLOPs 倍數（推論與訓練） | D22: Perf／Perf_Batch：hflop 列；Training：hflop 列 | E22: =EXP(SUMPRODUCT(($C$5:$C$16="H_FLOP")*LN($P$5:$P$16))) -> 1
A23: H_KV | B23: KV bytes/token 倍數 | D23: Perf／Perf_Batch：hkv 列 | E23: =EXP(SUMPRODUCT(($C$5:$C$16="H_KV")*LN($P$5:$P$16))) -> 1
A24: H_WB | B24: 權重 bytes/param 倍數 | D24: Perf／Perf_Batch：hwb 列 | E24: =EXP(SUMPRODUCT(($C$5:$C$16="H_WB")*LN($P$5:$P$16))) -> 1
A25: H_TPK | B25: 訓練峰值倍數 | D25: Training：htpk 列 | E25: =EXP(SUMPRODUCT(($C$5:$C$16="H_TPK")*LN($P$5:$P$16))) -> 1
A26: H_MFU | B26: 訓練 MFU 倍數 | D26: Training：hmfu 列 | E26: =EXP(SUMPRODUCT(($C$5:$C$16="H_MFU")*LN($P$5:$P$16))) -> 1
A27: H_TOK | B27: 達同等預訓練品質所需 token 倍數 | D27: Training：htok 列 | E27: =EXP(SUMPRODUCT(($C$5:$C$16="H_TOK")*LN($P$5:$P$16))) -> 1
A28: H_ROLL | B28: rollout 效率倍數 | D28: Training：hroll 列 | E28: =EXP(SUMPRODUCT(($C$5:$C$16="H_ROLL")*LN($P$5:$P$16))) -> 1
A29: H_CAP | B29: 能力增量（Block 4 占位，尚無作用） | D29: Block 4 | E29: =EXP(SUMPRODUCT(($C$5:$C$16="H_CAP")*LN($P$5:$P$16))) -> 1
A30: H_HAR | B30: harness（Block 5 占位，尚無作用） | D30: Block 5 | E30: =EXP(SUMPRODUCT(($C$5:$C$16="H_HAR")*LN($P$5:$P$16))) -> 1
A32: 注意 | B32: 掛鉤作用於全部世代與層級。新條目：在表中插入一列（範圍內），填倍數、狀態與證據；開關預設 0。Sens_Perf 的 η_d 與每層延遲情境為覆寫值，不受 Registry 影響。

Sheet Perf
A1: Perf — 每架產出引擎（世代 × 層級；各層級 SLO 與參考任務；100% 利用率）
A2: decode：每步時間＝固定延遲＋B × 每序列時間；在 SLO 下解出批次 B*，再受 HBM 容量限制。prefill 為算力受限。黃底為關鍵輸出
A4: 世代 | C4: =INDEX(Spec_Rack!$C$4:$G$4,C6) -> Hopper H100 | D4: =INDEX(Spec_Rack!$C$4:$G$4,D6) -> Hopper H100 | E4: =INDEX(Spec_Rack!$C$4:$G$4,E6) -> Hopper H100 | F4: =INDEX(Spec_Rack!$C$4:$G$4,F6) -> GB200 NVL72 | G4: =INDEX(Spec_Rack!$C$4:$G$4,G6) -> GB200 NVL72 | H4: =INDEX(Spec_Rack!$C$4:$G$4,H6) -> GB200 NVL72 | I4: =INDEX(Spec_Rack!$C$4:$G$4,I6) -> GB300 NVL72 | J4: =INDEX(Spec_Rack!$C$4:$G$4,J6) -> GB300 NVL72 | ... Q4: =INDEX(Spec_Rack!$C$4:$G$4,Q6) -> Rubin Ultra NVL576
A5: 層級 | C5: =INDEX(Arch!$C$4:$E$4,C7) -> Luna（低層） | D5: =INDEX(Arch!$C$4:$E$4,D7) -> Sol（中層） | E5: =INDEX(Arch!$C$4:$E$4,E7) -> Astra（頂層） | F5: =INDEX(Arch!$C$4:$E$4,F7) -> Luna（低層） | G5: =INDEX(Arch!$C$4:$E$4,G7) -> Sol（中層） | H5: =INDEX(Arch!$C$4:$E$4,H7) -> Astra（頂層） | I5: =INDEX(Arch!$C$4:$E$4,I7) -> Luna（低層） | J5: =INDEX(Arch!$C$4:$E$4,J7) -> Sol（中層） | ... Q5: =INDEX(Arch!$C$4:$E$4,Q7) -> Astra（頂層）
A6: 世代索引 | C6: 1 | D6: 1 | E6: 1 | F6: 2 | G6: 2 | H6: 2 | I6: 3 | J6: 3 | K6: 3 | L6: 4 | M6: 4 | N6: 4 | O6: 5 | P6: 5 | Q6: 5
A7: 層級索引 | C7: 1 | D7: 2 | E7: 3 | F7: 1 | G7: 2 | H7: 3 | I7: 1 | J7: 2 | K7: 3 | L7: 1 | M7: 2 | N7: 3 | O7: 1 | P7: 2 | Q7: 3
A9: 0. Tech_Registry 掛鉤（基準＝1；Registry 未啟用任何條目時與 v5.4 相同）
A10: FLOPs/token 倍數（H_FLOP） | B10: x | C10: =Tech_Registry!$E$22 -> 1 | D10: =Tech_Registry!$E$22 -> 1 | E10: =Tech_Registry!$E$22 -> 1 | F10: =Tech_Registry!$E$22 -> 1 | G10: =Tech_Registry!$E$22 -> 1 | H10: =Tech_Registry!$E$22 -> 1 | I10: =Tech_Registry!$E$22 -> 1 | J10: =Tech_Registry!$E$22 -> 1 | ... Q10: =Tech_Registry!$E$22 -> 1
A11: KV bytes/token 倍數（H_KV） | B11: x | C11: =Tech_Registry!$E$23 -> 1 | D11: =Tech_Registry!$E$23 -> 1 | E11: =Tech_Registry!$E$23 -> 1 | F11: =Tech_Registry!$E$23 -> 1 | G11: =Tech_Registry!$E$23 -> 1 | H11: =Tech_Registry!$E$23 -> 1 | I11: =Tech_Registry!$E$23 -> 1 | J11: =Tech_Registry!$E$23 -> 1 | ... Q11: =Tech_Registry!$E$23 -> 1
A12: 權重 bytes/param 倍數（H_WB） | B12: x | C12: =Tech_Registry!$E$24 -> 1 | D12: =Tech_Registry!$E$24 -> 1 | E12: =Tech_Registry!$E$24 -> 1 | F12: =Tech_Registry!$E$24 -> 1 | G12: =Tech_Registry!$E$24 -> 1 | H12: =Tech_Registry!$E$24 -> 1 | I12: =Tech_Registry!$E$24 -> 1 | J12: =Tech_Registry!$E$24 -> 1 | ... Q12: =Tech_Registry!$E$24 -> 1
A13: A. 規格（連結 Spec_Rack、DC_Cost）
A14: 計算用峰值 | B14: PF/GPU | C14: =INDEX(Spec_Rack!$C$35:$G$35,C$6) -> 1.979 | D14: =INDEX(Spec_Rack!$C$35:$G$35,D$6) -> 1.979 | E14: =INDEX(Spec_Rack!$C$35:$G$35,E$6) -> 1.979 | F14: =INDEX(Spec_Rack!$C$35:$G$35,F$6) -> 10 | G14: =INDEX(Spec_Rack!$C$35:$G$35,G$6) -> 10 | H14: =INDEX(Spec_Rack!$C$35:$G$35,H$6) -> 10 | I14: =INDEX(Spec_Rack!$C$35:$G$35,I$6) -> 15 | J14: =INDEX(Spec_Rack!$C$35:$G$35,J$6) -> 15 | ... Q14: =INDEX(Spec_Rack!$C$35:$G$35,Q$6) -> 73
A15: HBM 容量 | B15: GB/GPU | C15: =INDEX(Spec_Rack!$C$25:$G$25,C$6) -> 80 | D15: =INDEX(Spec_Rack!$C$25:$G$25,D$6) -> 80 | E15: =INDEX(Spec_Rack!$C$25:$G$25,E$6) -> 80 | F15: =INDEX(Spec_Rack!$C$25:$G$25,F$6) -> 186 | G15: =INDEX(Spec_Rack!$C$25:$G$25,G$6) -> 186 | H15: =INDEX(Spec_Rack!$C$25:$G$25,H$6) -> 186 | I15: =INDEX(Spec_Rack!$C$25:$G$25,I$6) -> 288 | J15: =INDEX(Spec_Rack!$C$25:$G$25,J$6) -> 288 | ... Q15: =INDEX(Spec_Rack!$C$25:$G$25,Q$6) -> 1024
A16: HBM 頻寬 | B16: TB/s/GPU | C16: =INDEX(Spec_Rack!$C$26:$G$26,C$6) -> 3.35 | D16: =INDEX(Spec_Rack!$C$26:$G$26,D$6) -> 3.35 | E16: =INDEX(Spec_Rack!$C$26:$G$26,E$6) -> 3.35 | F16: =INDEX(Spec_Rack!$C$26:$G$26,F$6) -> 8 | G16: =INDEX(Spec_Rack!$C$26:$G$26,G$6) -> 8 | H16: =INDEX(Spec_Rack!$C$26:$G$26,H$6) -> 8 | I16: =INDEX(Spec_Rack!$C$26:$G$26,I$6) -> 8 | J16: =INDEX(Spec_Rack!$C$26:$G$26,J$6) -> 8 | ... Q16: =INDEX(Spec_Rack!$C$26:$G$26,Q$6) -> 32
A17: EP 通訊頻寬（單向） | B17: TB/s/GPU | C17: =INDEX(Spec_Rack!$C$27:$G$27,C$6) -> 0.05 | D17: =INDEX(Spec_Rack!$C$27:$G$27,D$6) -> 0.05 | E17: =INDEX(Spec_Rack!$C$27:$G$27,E$6) -> 0.05 | F17: =INDEX(Spec_Rack!$C$27:$G$27,F$6) -> 0.9 | G17: =INDEX(Spec_Rack!$C$27:$G$27,G$6) -> 0.9 | H17: =INDEX(Spec_Rack!$C$27:$G$27,H$6) -> 0.9 | I17: =INDEX(Spec_Rack!$C$27:$G$27,I$6) -> 0.9 | J17: =INDEX(Spec_Rack!$C$27:$G$27,J$6) -> 0.9 | ... Q17: =INDEX(Spec_Rack!$C$27:$G$27,Q$6) -> 1.8
A18: decode EP 基準寬度 | B18: GPU | C18: =INDEX(Spec_Rack!$C$29:$G$29,C$6) -> 64 | D18: =INDEX(Spec_Rack!$C$29:$G$29,D$6) -> 64 | E18: =INDEX(Spec_Rack!$C$29:$G$29,E$6) -> 64 | F18: =INDEX(Spec_Rack!$C$29:$G$29,F$6) -> 32 | G18: =INDEX(Spec_Rack!$C$29:$G$29,G$6) -> 32 | H18: =INDEX(Spec_Rack!$C$29:$G$29,H$6) -> 32 | I18: =INDEX(Spec_Rack!$C$29:$G$29,I$6) -> 32 | J18: =INDEX(Spec_Rack!$C$29:$G$29,J$6) -> 32 | ... Q18: =INDEX(Spec_Rack!$C$29:$G$29,Q$6) -> 64
A19: 專家權重 bytes/param（含 H_WB） | B19: B | C19: =INDEX(Spec_Rack!$C$30:$G$30,C$6)*C12 -> 1 | D19: =INDEX(Spec_Rack!$C$30:$G$30,D$6)*D12 -> 1 | E19: =INDEX(Spec_Rack!$C$30:$G$30,E$6)*E12 -> 1 | F19: =INDEX(Spec_Rack!$C$30:$G$30,F$6)*F12 -> 0.5625 | G19: =INDEX(Spec_Rack!$C$30:$G$30,G$6)*G12 -> 0.5625 | H19: =INDEX(Spec_Rack!$C$30:$G$30,H$6)*H12 -> 0.5625 | I19: =INDEX(Spec_Rack!$C$30:$G$30,I$6)*I12 -> 0.5625 | J19: =INDEX(Spec_Rack!$C$30:$G$30,J$6)*J12 -> 0.5625 | ... Q19: =INDEX(Spec_Rack!$C$30:$G$30,Q$6)*Q12 -> 0.5625
A20: 非專家權重 bytes/param（含 H_WB） | B20: B | C20: =INDEX(Spec_Rack!$C$31:$G$31,C$6)*C12 -> 1 | D20: =INDEX(Spec_Rack!$C$31:$G$31,D$6)*D12 -> 1 | E20: =INDEX(Spec_Rack!$C$31:$G$31,E$6)*E12 -> 1 | F20: =INDEX(Spec_Rack!$C$31:$G$31,F$6)*F12 -> 1 | G20: =INDEX(Spec_Rack!$C$31:$G$31,G$6)*G12 -> 1 | H20: =INDEX(Spec_Rack!$C$31:$G$31,H$6)*H12 -> 1 | I20: =INDEX(Spec_Rack!$C$31:$G$31,I$6)*I12 -> 1 | J20: =INDEX(Spec_Rack!$C$31:$G$31,J$6)*J12 -> 1 | ... Q20: =INDEX(Spec_Rack!$C$31:$G$31,Q$6)*Q12 -> 1
A21: 每 prefill 實例 GPU 數 | B21: GPU | C21: =INDEX(Spec_Rack!$C$32:$G$32,C$6) -> 8 | D21: =INDEX(Spec_Rack!$C$32:$G$32,D$6) -> 8 | E21: =INDEX(Spec_Rack!$C$32:$G$32,E$6) -> 8 | F21: =INDEX(Spec_Rack!$C$32:$G$32,F$6) -> 4 | G21: =INDEX(Spec_Rack!$C$32:$G$32,G$6) -> 4 | H21: =INDEX(Spec_Rack!$C$32:$G$32,H$6) -> 4 | I21: =INDEX(Spec_Rack!$C$32:$G$32,I$6) -> 4 | J21: =INDEX(Spec_Rack!$C$32:$G$32,J$6) -> 4 | ... Q21: =INDEX(Spec_Rack!$C$32:$G$32,Q$6) -> 8
A22: GPU 封裝／架 | B22: 顆 | C22: =INDEX(Spec_Rack!$C$6:$G$6,C$6) -> 32 | D22: =INDEX(Spec_Rack!$C$6:$G$6,D$6) -> 32 | E22: =INDEX(Spec_Rack!$C$6:$G$6,E$6) -> 32 | F22: =INDEX(Spec_Rack!$C$6:$G$6,F$6) -> 72 | G22: =INDEX(Spec_Rack!$C$6:$G$6,G$6) -> 72 | H22: =INDEX(Spec_Rack!$C$6:$G$6,H$6) -> 72 | I22: =INDEX(Spec_Rack!$C$6:$G$6,I$6) -> 72 | J22: =INDEX(Spec_Rack!$C$6:$G$6,J$6) -> 72 | ... Q22: =INDEX(Spec_Rack!$C$6:$G$6,Q$6) -> 144
A23: GPU 功率 | B23: W | C23: =INDEX(Spec_Rack!$C$33:$G$33,C$6) -> 700 | D23: =INDEX(Spec_Rack!$C$33:$G$33,D$6) -> 700 | E23: =INDEX(Spec_Rack!$C$33:$G$33,E$6) -> 700 | F23: =INDEX(Spec_Rack!$C$33:$G$33,F$6) -> 1200 | G23: =INDEX(Spec_Rack!$C$33:$G$33,G$6) -> 1200 | H23: =INDEX(Spec_Rack!$C$33:$G$33,H$6) -> 1200 | I23: =INDEX(Spec_Rack!$C$33:$G$33,I$6) -> 1400 | J23: =INDEX(Spec_Rack!$C$33:$G$33,J$6) -> 1400 | ... Q23: =INDEX(Spec_Rack!$C$33:$G$33,Q$6) -> 3600
A24: HBM 存取能量 | B24: pJ/B | C24: =INDEX(Spec_Rack!$C$34:$G$34,C$6) -> 31 | D24: =INDEX(Spec_Rack!$C$34:$G$34,D$6) -> 31 | E24: =INDEX(Spec_Rack!$C$34:$G$34,E$6) -> 31 | F24: =INDEX(Spec_Rack!$C$34:$G$34,F$6) -> 25 | G24: =INDEX(Spec_Rack!$C$34:$G$34,G$6) -> 25 | H24: =INDEX(Spec_Rack!$C$34:$G$34,H$6) -> 25 | I24: =INDEX(Spec_Rack!$C$34:$G$34,I$6) -> 25 | J24: =INDEX(Spec_Rack!$C$34:$G$34,J$6) -> 25 | ... Q24: =INDEX(Spec_Rack!$C$34:$G$34,Q$6) -> 18
A25: 每 GW 機架數（功率情境） | B25: 架 | C25: =INDEX(DC_Cost!$C$12:$Q$12,3*(C$6-1)+2) -> 22439 | D25: =INDEX(DC_Cost!$C$12:$Q$12,3*(D$6-1)+2) -> 22439 | E25: =INDEX(DC_Cost!$C$12:$Q$12,3*(E$6-1)+2) -> 22439 | F25: =INDEX(DC_Cost!$C$12:$Q$12,3*(F$6-1)+2) -> 7076 | G25: =INDEX(DC_Cost!$C$12:$Q$12,3*(G$6-1)+2) -> 7076 | H25: =INDEX(DC_Cost!$C$12:$Q$12,3*(H$6-1)+2) -> 7076 | I25: =INDEX(DC_Cost!$C$12:$Q$12,3*(I$6-1)+2) -> 6715 | J25: =INDEX(DC_Cost!$C$12:$Q$12,3*(J$6-1)+2) -> 6715 | ... Q25: =INDEX(DC_Cost!$C$12:$Q$12,3*(Q$6-1)+2) -> 1533
A26: 每架配電設計功率 | B26: kW | C26: =INDEX(DC_Cost!$C$11:$Q$11,3*(C$6-1)+2) -> 41 | D26: =INDEX(DC_Cost!$C$11:$Q$11,3*(D$6-1)+2) -> 41 | E26: =INDEX(DC_Cost!$C$11:$Q$11,3*(E$6-1)+2) -> 41 | F26: =INDEX(DC_Cost!$C$11:$Q$11,3*(F$6-1)+2) -> 130 | G26: =INDEX(DC_Cost!$C$11:$Q$11,3*(G$6-1)+2) -> 130 | H26: =INDEX(DC_Cost!$C$11:$Q$11,3*(H$6-1)+2) -> 130 | I26: =INDEX(DC_Cost!$C$11:$Q$11,3*(I$6-1)+2) -> 137 | J26: =INDEX(DC_Cost!$C$11:$Q$11,3*(J$6-1)+2) -> 137 | ... Q26: =INDEX(DC_Cost!$C$11:$Q$11,3*(Q$6-1)+2) -> 600
A27: B. 架構（連結 Arch）
A28: 啟用參數 | B28: B | C28: =INDEX(Arch!$C$7:$E$7,C$7) -> 13 | D28: =INDEX(Arch!$C$7:$E$7,D$7) -> 49 | E28: =INDEX(Arch!$C$7:$E$7,E$7) -> 180 | F28: =INDEX(Arch!$C$7:$E$7,F$7) -> 13 | G28: =INDEX(Arch!$C$7:$E$7,G$7) -> 49 | H28: =INDEX(Arch!$C$7:$E$7,H$7) -> 180 | I28: =INDEX(Arch!$C$7:$E$7,I$7) -> 13 | J28: =INDEX(Arch!$C$7:$E$7,J$7) -> 49 | ... Q28: =INDEX(Arch!$C$7:$E$7,Q$7) -> 180
A29: 層數 | B29: 層 | C29: =INDEX(Arch!$C$8:$E$8,C$7) -> 43 | D29: =INDEX(Arch!$C$8:$E$8,D$7) -> 61 | E29: =INDEX(Arch!$C$8:$E$8,E$7) -> 100 | F29: =INDEX(Arch!$C$8:$E$8,F$7) -> 43 | G29: =INDEX(Arch!$C$8:$E$8,G$7) -> 61 | H29: =INDEX(Arch!$C$8:$E$8,H$7) -> 100 | I29: =INDEX(Arch!$C$8:$E$8,I$7) -> 43 | J29: =INDEX(Arch!$C$8:$E$8,J$7) -> 61 | ... Q29: =INDEX(Arch!$C$8:$E$8,Q$7) -> 100
A30: d_model | C30: =INDEX(Arch!$C$9:$E$9,C$7) -> 4096 | D30: =INDEX(Arch!$C$9:$E$9,D$7) -> 7168 | E30: =INDEX(Arch!$C$9:$E$9,E$7) -> 12288 | F30: =INDEX(Arch!$C$9:$E$9,F$7) -> 4096 | G30: =INDEX(Arch!$C$9:$E$9,G$7) -> 7168 | H30: =INDEX(Arch!$C$9:$E$9,H$7) -> 12288 | I30: =INDEX(Arch!$C$9:$E$9,I$7) -> 4096 | J30: =INDEX(Arch!$C$9:$E$9,J$7) -> 7168 | ... Q30: =INDEX(Arch!$C$9:$E$9,Q$7) -> 12288
A31: 啟用 routed experts | C31: =INDEX(Arch!$C$13:$E$13,C$7) -> 6 | D31: =INDEX(Arch!$C$13:$E$13,D$7) -> 6 | E31: =INDEX(Arch!$C$13:$E$13,E$7) -> 16 | F31: =INDEX(Arch!$C$13:$E$13,F$7) -> 6 | G31: =INDEX(Arch!$C$13:$E$13,G$7) -> 6 | H31: =INDEX(Arch!$C$13:$E$13,H$7) -> 16 | I31: =INDEX(Arch!$C$13:$E$13,I$7) -> 6 | J31: =INDEX(Arch!$C$13:$E$13,J$7) -> 6 | ... Q31: =INDEX(Arch!$C$13:$E$13,Q$7) -> 16
A32: 非專家參數 | B32: B | C32: =INDEX(Arch!$C$28:$E$28,C$7) -> 5.412 | D32: =INDEX(Arch!$C$28:$E$28,D$7) -> 20.277778 | E32: =INDEX(Arch!$C$28:$E$28,E$7) -> 49.072581 | F32: =INDEX(Arch!$C$28:$E$28,F$7) -> 5.412 | G32: =INDEX(Arch!$C$28:$E$28,G$7) -> 20.277778 | H32: =INDEX(Arch!$C$28:$E$28,H$7) -> 49.072581 | I32: =INDEX(Arch!$C$28:$E$28,I$7) -> 5.412 | J32: =INDEX(Arch!$C$28:$E$28,J$7) -> 20.277778 | ... Q32: =INDEX(Arch!$C$28:$E$28,Q$7) -> 49.072581
A33: 專家參數 | B33: B | C33: =INDEX(Arch!$C$29:$E$29,C$7) -> 278.588 | D33: =INDEX(Arch!$C$29:$E$29,D$7) -> 1579.7222 | E33: =INDEX(Arch!$C$29:$E$29,E$7) -> 3950.9274 | F33: =INDEX(Arch!$C$29:$E$29,F$7) -> 278.588 | G33: =INDEX(Arch!$C$29:$E$29,G$7) -> 1579.7222 | H33: =INDEX(Arch!$C$29:$E$29,H$7) -> 3950.9274 | I33: =INDEX(Arch!$C$29:$E$29,I$7) -> 278.588 | J33: =INDEX(Arch!$C$29:$E$29,J$7) -> 1579.7222 | ... Q33: =INDEX(Arch!$C$29:$E$29,Q$7) -> 3950.9274
A34: KV bytes/token（含 H_KV） | B34: B | C34: =INDEX(Arch!$C$25:$E$25,C$7)*C11 -> 2795 | D34: =INDEX(Arch!$C$25:$E$25,D$7)*D11 -> 3965 | E34: =INDEX(Arch!$C$25:$E$25,E$7)*E11 -> 57600 | F34: =INDEX(Arch!$C$25:$E$25,F$7)*F11 -> 2795 | G34: =INDEX(Arch!$C$25:$E$25,G$7)*G11 -> 3965 | H34: =INDEX(Arch!$C$25:$E$25,H$7)*H11 -> 57600 | I34: =INDEX(Arch!$C$25:$E$25,I$7)*I11 -> 2795 | J34: =INDEX(Arch!$C$25:$E$25,J$7)*J11 -> 3965 | ... Q34: =INDEX(Arch!$C$25:$E$25,Q$7)*Q11 -> 57600
A35: 注意力 FLOPs／被注意 token | B35: FLOP | C35: =INDEX(Arch!$C$30:$E$30,C$7) -> 5636096 | D35: =INDEX(Arch!$C$30:$E$30,D$7) -> 15990784 | E35: =INDEX(Arch!$C$30:$E$30,E$7) -> 4915200 | F35: =INDEX(Arch!$C$30:$E$30,F$7) -> 5636096 | G35: =INDEX(Arch!$C$30:$E$30,G$7) -> 15990784 | H35: =INDEX(Arch!$C$30:$E$30,H$7) -> 4915200 | I35: =INDEX(Arch!$C$30:$E$30,I$7) -> 5636096 | J35: =INDEX(Arch!$C$30:$E$30,J$7) -> 15990784 | ... Q35: =INDEX(Arch!$C$30:$E$30,Q$7) -> 4915200
A36: 全注意力層比例 | B36: % | C36: =INDEX(Arch!$C$16:$E$16,C$7) -> 0.5 | D36: =INDEX(Arch!$C$16:$E$16,D$7) -> 0.5 | E36: =INDEX(Arch!$C$16:$E$16,E$7) -> 1 | F36: =INDEX(Arch!$C$16:$E$16,F$7) -> 0.5 | G36: =INDEX(Arch!$C$16:$E$16,G$7) -> 0.5 | H36: =INDEX(Arch!$C$16:$E$16,H$7) -> 1 | I36: =INDEX(Arch!$C$16:$E$16,I$7) -> 0.5 | J36: =INDEX(Arch!$C$16:$E$16,J$7) -> 0.5 | ... Q36: =INDEX(Arch!$C$16:$E$16,Q$7) -> 1
A37: 全注意力跨度上限 | B37: tok | C37: =INDEX(Arch!$C$17:$E$17,C$7) -> 4224 | D37: =INDEX(Arch!$C$17:$E$17,D$7) -> 4224 | E37: =INDEX(Arch!$C$17:$E$17,E$7) -> 0 | F37: =INDEX(Arch!$C$17:$E$17,F$7) -> 4224 | G37: =INDEX(Arch!$C$17:$E$17,G$7) -> 4224 | H37: =INDEX(Arch!$C$17:$E$17,H$7) -> 0 | I37: =INDEX(Arch!$C$17:$E$17,I$7) -> 4224 | J37: =INDEX(Arch!$C$17:$E$17,J$7) -> 4224 | ... Q37: =INDEX(Arch!$C$17:$E$17,Q$7) -> 0
A38: 其他層壓縮比 | B38: x | C38: =INDEX(Arch!$C$18:$E$18,C$7) -> 128 | D38: =INDEX(Arch!$C$18:$E$18,D$7) -> 128 | E38: =INDEX(Arch!$C$18:$E$18,E$7) -> 1 | F38: =INDEX(Arch!$C$18:$E$18,F$7) -> 128 | G38: =INDEX(Arch!$C$18:$E$18,G$7) -> 128 | H38: =INDEX(Arch!$C$18:$E$18,H$7) -> 1 | I38: =INDEX(Arch!$C$18:$E$18,I$7) -> 128 | J38: =INDEX(Arch!$C$18:$E$18,J$7) -> 128 | ... Q38: =INDEX(Arch!$C$18:$E$18,Q$7) -> 1
A39: 其他層滑動窗 | B39: tok | C39: =INDEX(Arch!$C$19:$E$19,C$7) -> 128 | D39: =INDEX(Arch!$C$19:$E$19,D$7) -> 128 | E39: =INDEX(Arch!$C$19:$E$19,E$7) -> 0 | F39: =INDEX(Arch!$C$19:$E$19,F$7) -> 128 | G39: =INDEX(Arch!$C$19:$E$19,G$7) -> 128 | H39: =INDEX(Arch!$C$19:$E$19,H$7) -> 0 | I39: =INDEX(Arch!$C$19:$E$19,I$7) -> 128 | J39: =INDEX(Arch!$C$19:$E$19,J$7) -> 128 | ... Q39: =INDEX(Arch!$C$19:$E$19,Q$7) -> 0
A40: C. 服務、SLO 與校準參數
A41: SLO：每用戶 decode 速度下限 | B41: tok/s | C41: =INDEX(Serving!$C$21:$E$21,C$7) -> 120 | D41: =INDEX(Serving!$C$21:$E$21,D$7) -> 65 | E41: =INDEX(Serving!$C$21:$E$21,E$7) -> 55 | F41: =INDEX(Serving!$C$21:$E$21,F$7) -> 120 | G41: =INDEX(Serving!$C$21:$E$21,G$7) -> 65 | H41: =INDEX(Serving!$C$21:$E$21,H$7) -> 55 | I41: =INDEX(Serving!$C$21:$E$21,I$7) -> 120 | J41: =INDEX(Serving!$C$21:$E$21,J$7) -> 65 | ... Q41: =INDEX(Serving!$C$21:$E$21,Q$7) -> 55
A42: TTFT 上限 | B42: s | C42: =INDEX(Serving!$C$22:$E$22,C$7) -> 2 | D42: =INDEX(Serving!$C$22:$E$22,D$7) -> 3 | E42: =INDEX(Serving!$C$22:$E$22,E$7) -> 5 | F42: =INDEX(Serving!$C$22:$E$22,F$7) -> 2 | G42: =INDEX(Serving!$C$22:$E$22,G$7) -> 3 | H42: =INDEX(Serving!$C$22:$E$22,H$7) -> 5 | I42: =INDEX(Serving!$C$22:$E$22,I$7) -> 2 | J42: =INDEX(Serving!$C$22:$E$22,J$7) -> 3 | ... Q42: =INDEX(Serving!$C$22:$E$22,Q$7) -> 5
...

Sheet Sens_Perf
A1: Sens_Perf — VR200 對 GB300 的單變數敏感度（先看敏感度，再看基準）
A2: 每組兩欄：左 VR200、右 GB300。黃底藍字＝該情境改動的輸入。GB300 為校準世代，VR200 的 η_d 與每層延遲為沿用值 [Analogy]，故 VR 專屬情境只動 VR 欄
A3: 情境 | C3: 基準 | E3: VR η_d × 0.5（新世代軟體未成熟） | G3: VR η_d × 1.5 | I3: VR 每層延遲 × 0.7 | K3: VR 每層延遲 × 1.5 | M3: VR 峰值 50 PF（J2 高情境） | O3: SLO 40 tok/s | Q3: SLO 100 tok/s | S3: MTP 接受率 0.60 | U3: MTP 接受率 0.80 | W3: ISL 4K | Y3: ISL 64K | AA3: 生產折減 0.7（兩世代） | AC3: Astra KV 情境 1（混合） | AE3: Astra KV 情境 2（全層 MLA，基準） | AG3: Astra KV 情境 3（GQA-8）
A4: 世代 | C4: =INDEX(Spec_Rack!$C$4:$G$4,C6) -> VR200 NVL72 | D4: =INDEX(Spec_Rack!$C$4:$G$4,D6) -> GB300 NVL72 | E4: =INDEX(Spec_Rack!$C$4:$G$4,E6) -> VR200 NVL72 | F4: =INDEX(Spec_Rack!$C$4:$G$4,F6) -> GB300 NVL72 | G4: =INDEX(Spec_Rack!$C$4:$G$4,G6) -> VR200 NVL72 | H4: =INDEX(Spec_Rack!$C$4:$G$4,H6) -> GB300 NVL72 | I4: =INDEX(Spec_Rack!$C$4:$G$4,I6) -> VR200 NVL72 | J4: =INDEX(Spec_Rack!$C$4:$G$4,J6) -> GB300 NVL72 | ... AH4: =INDEX(Spec_Rack!$C$4:$G$4,AH6) -> GB300 NVL72
A5: 層級 | C5: =INDEX(Arch!$C$4:$E$4,C7) -> Sol（中層） | D5: =INDEX(Arch!$C$4:$E$4,D7) -> Sol（中層） | E5: =INDEX(Arch!$C$4:$E$4,E7) -> Sol（中層） | F5: =INDEX(Arch!$C$4:$E$4,F7) -> Sol（中層） | G5: =INDEX(Arch!$C$4:$E$4,G7) -> Sol（中層） | H5: =INDEX(Arch!$C$4:$E$4,H7) -> Sol（中層） | I5: =INDEX(Arch!$C$4:$E$4,I7) -> Sol（中層） | J5: =INDEX(Arch!$C$4:$E$4,J7) -> Sol（中層） | ... AH5: =INDEX(Arch!$C$4:$E$4,AH7) -> Astra（頂層）
A6: 世代索引 | C6: 4 | D6: 3 | E6: 4 | F6: 3 | G6: 4 | H6: 3 | I6: 4 | J6: 3 | K6: 4 | L6: 3 | M6: 4 | N6: 3 | O6: 4 | P6: 3 | Q6: 4 | R6: 3 | S6: 4 | T6: 3 | U6: 4 | V6: 3 | W6: 4 | X6: 3 | Y6: 4 | Z6: 3 | AA6: 4 | AB6: 3 | AC6: 4 | AD6: 3 | AE6: 4 | AF6: 3 | AG6: 4 | AH6: 3
A7: 層級索引 | C7: 2 | D7: 2 | E7: 2 | F7: 2 | G7: 2 | H7: 2 | I7: 2 | J7: 2 | K7: 2 | L7: 2 | M7: 2 | N7: 2 | O7: 2 | P7: 2 | Q7: 2 | R7: 2 | S7: 2 | T7: 2 | U7: 2 | V7: 2 | W7: 2 | X7: 2 | Y7: 2 | Z7: 2 | AA7: 2 | AB7: 2 | AC7: 3 | AD7: 3 | AE7: 3 | AF7: 3 | AG7: 3 | AH7: 3
A9: 0. Tech_Registry 掛鉤（基準＝1；Registry 未啟用任何條目時與 v5.4 相同）
A10: FLOPs/token 倍數（H_FLOP） | B10: x | C10: =Tech_Registry!$E$22 -> 1 | D10: =Tech_Registry!$E$22 -> 1 | E10: =Tech_Registry!$E$22 -> 1 | F10: =Tech_Registry!$E$22 -> 1 | G10: =Tech_Registry!$E$22 -> 1 | H10: =Tech_Registry!$E$22 -> 1 | I10: =Tech_Registry!$E$22 -> 1 | J10: =Tech_Registry!$E$22 -> 1 | ... AH10: =Tech_Registry!$E$22 -> 1
A11: KV bytes/token 倍數（H_KV） | B11: x | C11: =Tech_Registry!$E$23 -> 1 | D11: =Tech_Registry!$E$23 -> 1 | E11: =Tech_Registry!$E$23 -> 1 | F11: =Tech_Registry!$E$23 -> 1 | G11: =Tech_Registry!$E$23 -> 1 | H11: =Tech_Registry!$E$23 -> 1 | I11: =Tech_Registry!$E$23 -> 1 | J11: =Tech_Registry!$E$23 -> 1 | ... AH11: =Tech_Registry!$E$23 -> 1
A12: 權重 bytes/param 倍數（H_WB） | B12: x | C12: =Tech_Registry!$E$24 -> 1 | D12: =Tech_Registry!$E$24 -> 1 | E12: =Tech_Registry!$E$24 -> 1 | F12: =Tech_Registry!$E$24 -> 1 | G12: =Tech_Registry!$E$24 -> 1 | H12: =Tech_Registry!$E$24 -> 1 | I12: =Tech_Registry!$E$24 -> 1 | J12: =Tech_Registry!$E$24 -> 1 | ... AH12: =Tech_Registry!$E$24 -> 1
A13: A. 規格（連結 Spec_Rack、DC_Cost）
A14: 計算用峰值 | B14: PF/GPU | C14: =INDEX(Spec_Rack!$C$35:$G$35,C$6) -> 35 | D14: =INDEX(Spec_Rack!$C$35:$G$35,D$6) -> 15 | E14: =INDEX(Spec_Rack!$C$35:$G$35,E$6) -> 35 | F14: =INDEX(Spec_Rack!$C$35:$G$35,F$6) -> 15 | G14: =INDEX(Spec_Rack!$C$35:$G$35,G$6) -> 35 | H14: =INDEX(Spec_Rack!$C$35:$G$35,H$6) -> 15 | I14: =INDEX(Spec_Rack!$C$35:$G$35,I$6) -> 35 | J14: =INDEX(Spec_Rack!$C$35:$G$35,J$6) -> 15 | ... L14: =INDEX(Spec_Rack!$C$35:$G$35,L$6) -> 15 | M14: 50 | N14: =INDEX(Spec_Rack!$C$35:$G$35,N$6) -> 15 | O14: =INDEX(Spec_Rack!$C$35:$G$35,O$6) -> 35 | P14: =INDEX(Spec_Rack!$C$35:$G$35,P$6) -> 15 | Q14: =INDEX(Spec_Rack!$C$35:$G$35,Q$6) -> 35 | R14: =INDEX(Spec_Rack!$C$35:$G$35,R$6) -> 15 | S14: =INDEX(Spec_Rack!$C$35:$G$35,S$6) -> 35 | T14: =INDEX(Spec_Rack!$C$35:$G$35,T$6) -> 15 | U14: =INDEX(Spec_Rack!$C$35:$G$35,U$6) -> 35 | ... AH14: =INDEX(Spec_Rack!$C$35:$G$35,AH$6) -> 15
A15: HBM 容量 | B15: GB/GPU | C15: =INDEX(Spec_Rack!$C$25:$G$25,C$6) -> 288 | D15: =INDEX(Spec_Rack!$C$25:$G$25,D$6) -> 288 | E15: =INDEX(Spec_Rack!$C$25:$G$25,E$6) -> 288 | F15: =INDEX(Spec_Rack!$C$25:$G$25,F$6) -> 288 | G15: =INDEX(Spec_Rack!$C$25:$G$25,G$6) -> 288 | H15: =INDEX(Spec_Rack!$C$25:$G$25,H$6) -> 288 | I15: =INDEX(Spec_Rack!$C$25:$G$25,I$6) -> 288 | J15: =INDEX(Spec_Rack!$C$25:$G$25,J$6) -> 288 | ... AH15: =INDEX(Spec_Rack!$C$25:$G$25,AH$6) -> 288
A16: HBM 頻寬 | B16: TB/s/GPU | C16: =INDEX(Spec_Rack!$C$26:$G$26,C$6) -> 22 | D16: =INDEX(Spec_Rack!$C$26:$G$26,D$6) -> 8 | E16: =INDEX(Spec_Rack!$C$26:$G$26,E$6) -> 22 | F16: =INDEX(Spec_Rack!$C$26:$G$26,F$6) -> 8 | G16: =INDEX(Spec_Rack!$C$26:$G$26,G$6) -> 22 | H16: =INDEX(Spec_Rack!$C$26:$G$26,H$6) -> 8 | I16: =INDEX(Spec_Rack!$C$26:$G$26,I$6) -> 22 | J16: =INDEX(Spec_Rack!$C$26:$G$26,J$6) -> 8 | ... AH16: =INDEX(Spec_Rack!$C$26:$G$26,AH$6) -> 8
A17: EP 通訊頻寬（單向） | B17: TB/s/GPU | C17: =INDEX(Spec_Rack!$C$27:$G$27,C$6) -> 1.8 | D17: =INDEX(Spec_Rack!$C$27:$G$27,D$6) -> 0.9 | E17: =INDEX(Spec_Rack!$C$27:$G$27,E$6) -> 1.8 | F17: =INDEX(Spec_Rack!$C$27:$G$27,F$6) -> 0.9 | G17: =INDEX(Spec_Rack!$C$27:$G$27,G$6) -> 1.8 | H17: =INDEX(Spec_Rack!$C$27:$G$27,H$6) -> 0.9 | I17: =INDEX(Spec_Rack!$C$27:$G$27,I$6) -> 1.8 | J17: =INDEX(Spec_Rack!$C$27:$G$27,J$6) -> 0.9 | ... AH17: =INDEX(Spec_Rack!$C$27:$G$27,AH$6) -> 0.9
