Workbook

Sheet Config
A1: PARAMETERIZED TOKEN GENERATION PIPELINE — v4 (frontier MoE presets, Sep 2026) | E1: RACK PRESETS
A2: Change the blue cells below to experiment with different configurations | E2: Copy a column into Column B to switch racks
A4: AI DC Spec. | B4: Data | C4: Note | E4: AI DC Spec. | F4: Vera Rubin NVL72 | G4: GB200 NVL72 | H4: Note
A5: Total power(W) | B5: =IF($B$7=F$4,F5,G5) -> 1000000000 | E5: Total power(W) | F5: 1000000000 | G5: 1000000000
A6: PUE | B6: =IF($B$7=F$4,F6,G6) -> 1.2 | E6: PUE | F6: 1.2 | G6: 1.2
A7: Rack Type | B7: Vera Rubin NVL72 | E7: Rack Type | F7: Vera Rubin NVL72 | G7: GB200 NVL72
A8: No.of racks | B8: =IF($B$7=F$4,F8,G8) -> 5263 | C8: Derived: FLOOR(IT Power / Power per Rack) | E8: No.of racks | F8: =FLOOR(F5/1000/F23,1) -> 5263 | G8: =FLOOR(G5/1000/G23,1) -> 7194 | H8: Derived: FLOOR(Total Power / Power per Rack)
A10: Rack Spec. | B10: Data | C10: Note | E10: Rack Spec. | F10: Vera Rubin NVL72 | G10: GB200 NVL72 | H10: Note
A11: CPU Type | B11: =IF($B$7=F$4,F11,G11) -> Vera CPU | E11: CPU Type | F11: Vera CPU | G11: Grace CPU
A12: No. of CPU | B12: =IF($B$7=F$4,F12,G12) -> 36 | E12: No. of CPU | F12: 36 | G12: 36
A13: GPU Type | B13: =IF($B$7=F$4,F13,G13) -> Rubin GPU | E13: GPU Type | F13: Rubin GPU | G13: Blackwell B200
A14: No. of GPU | B14: =IF($B$7=F$4,F14,G14) -> 72 | C14: per rack | E14: No. of GPU | F14: 72 | G14: 72
A15: NVLink Bandwidth(TB/s) | B15: =IF($B$7=F$4,F15,G15) -> 260 | C15: total per rack | E15: NVLink BW(TB/s) | F15: 260 | G15: 130 | H15: Total per rack
A16: NVLink-C2C Bandwidth(TB/s) | B16: =IF($B$7=F$4,F16,G16) -> 65 | E16: NVLink-C2C BW(TB/s) | F16: 65 | G16: 32.4 | H16: 0.9 TB/s * 36 CPUs
A17: GPU Memory(TB) | B17: =IF($B$7=F$4,F17,G17) -> 20.7 | C17: 0.288/GPU | E17: GPU Memory(TB) | F17: 20.7 | G17: 13.5 | H17: Total per rack (0.1875/GPU for GB200)
A18: Memory Bandwidth(TB) | B18: =IF($B$7=F$4,F18,G18) -> 1580 | C18: 22/GPU | E18: Memory BW(TB) | F18: 1580 | G18: 576 | H18: Total per rack (8/GPU for GB200)
A19: FP4 Dense Inference(PFLOPS) | B19: =IF($B$7=F$4,F19,G19) -> 3600 | C19: 50/GPU | E19: FP4 Dense Inference(PFLOPS) | F19: 3600 | G19: 648 | H19: 50/GPU Rubin = 3600; 9/GPU B200 (dense, no sparsity). Fixed from 2520 (was using 35/GPU training value).
A20: FP4 Dense Training(PFLOPS) | B20: =IF($B$7=F$4,F20,G20) -> 2520 | C20: 35/GPU | E20: FP4 Dense Training(PFLOPS) | F20: 2520 | G20: 648 | H20: 35 PFLOPS/GPU Rubin = 2520; 9 PFLOPS/GPU B200 = 648 (dense training)
A21: FP8 Dense(PFLOPS) | B21: =IF($B$7=F$4,F21,G21) -> 1152 | C21: 16/GPU (was 17.5) | E21: FP8 Dense(PFLOPS) | F21: 1152 | G21: 324 | H21: 16/GPU Rubin; 4.5/GPU B200 (dense)
A22: FP16/BF16 Dense(PFLOPS) | B22: =IF($B$7=F$4,F22,G22) -> 288 | C22: 4/GPU | E22: FP16/BF16 Dense(PFLOPS) | F22: 288 | G22: 162 | H22: 3.6/GPU Rubin; 2.25/GPU B200 (dense)
A23: Power per Rack (kW) | B23: =IF($B$7=F$4,F23,G23) -> 190 | C23: IT power draw per rack | E23: Power/Rack (kW) | F23: 190 | G23: 139 | H23: IT power only (excl. PUE overhead)
A24: Rack Price ($) | B24: =IF($B$7=F$4,F27,G27) -> 6000000 | C24: Auto-filled from dropdown; edit preset in F27/G27
A26: ▶ KEY INPUTS — Model & Tokens | B26: Data | C26: Note | E26: Pricing | F26: Vera Rubin NVL72 | G26: GB200 NVL72 | H26: Note | J26: ▶ FRONTIER MODEL PRESETS (Sep 2026) — select in B29; column K feeds column B
A27: Input Tokens | B27: 16000 | C27: [Analogy] agentic/coding mix: OpenRouter avg prompt >6K (Nov-2025), programming >20K; range 6K–32K | E27: Rack Price ($) | F27: 6000000 | G27: 3000000 | H27: Est. $3M GB200; Rubin ~$6M (15-20% premium) | J27: Blue = published/assumed input · black = derived. Tags in column Q. Published = vendor model card / config.json.
A28: Output Tokens | B28: 1000 | C28: [Analogy] avg completion ~400 (Nov-2025) rising with reasoning; range 400–2,000. Link =B27/4 removed (I:O now ~16:1) | J28: Parameter | K28: ▶ Selected | L28: DeepSeek V4-Pro | M28: Kimi K3 | N28: DeepSeek V4-Flash | O28: Closed-frontier proxy | P28: Legacy 1T Dense (v3) | Q28: Source / Tag
A29: Model Preset | B29: DeepSeek V4-Pro | C29: ← Select frontier architecture (table J26:Q55); feeds B31–B48, B55 | E29: ▶ MARKET PRICING TIERS (Sep 2026) | J29: Total parameters (published) | K29: =IF(INDEX($L29:$P29,MATCH($B$29,$L$28:$P$28,0))="","",INDEX($L29:$P29,MATCH($B$29,$L$28:$P$28,0))) -> 1600000000000 | L29: 1600000000000 | M29: 2800000000000 | N29: 284000000000 | O29: 4000000000000 | P29: 1000000000000 | Q29: V4-Pro 1.6T (preview; GA-0813 card 1.7T incl. DSpark) [Verified: HF card]; K3 2.8T [Verified: model card]; V4-Flash 284B [Verified: arXiv 2606.19348]; proxy [Assumed, range 2–10T]; legacy = v3 default
A30: Model Spec. | B30: Data | C30: Note | E30: Select tier in F41 (independent of architecture preset) | J30: Active parameters / token (published) | K30: =IF(INDEX($L30:$P30,MATCH($B$29,$L$28:$P$28,0))="","",INDEX($L30:$P30,MATCH($B$29,$L$28:$P$28,0))) -> 49000000000 | L30: 49000000000 | M30: 104000000000 | N30: 13000000000 | O30: 180000000000 | P30: 1000000000000 | Q30: V4-Pro 49B, K3 104B, V4-Flash 13B [Verified]; proxy [Assumed, range 60–250B]
A31: Parameters | B31: =K29 -> 1600000000000 | C31: Total params (from preset K29) | E31: Tier | F31: Representative models (list $/M in/out) | G31: Input $/M | H31: Output $/M | J31: Type | K31: =IF(INDEX($L31:$P31,MATCH($B$29,$L$28:$P$28,0))="","",INDEX($L31:$P31,MATCH($B$29,$L$28:$P$28,0))) -> MoE | L31: MoE | M31: MoE | N31: MoE | O31: MoE | P31: Dense
A32: Type | B32: =K31 -> MoE | C32: Dense / MoE (from preset; overwrite to test) | E32: Nano | F32: Qwen3.7 Flash $0.03/$0.13; Nova Micro $0.035/$0.14 | G32: 0.035 | H32: 0.14 | J32: n_layers (blank = auto-scale) | K32: =IF(INDEX($L32:$P32,MATCH($B$29,$L$28:$P$28,0))="","",INDEX($L32:$P32,MATCH($B$29,$L$28:$P$28,0))) -> 61 | L32: 61 | M32: 93 | N32: 43 | O32: 100 | Q32: V4-Pro 61 (config.json); K3 93 = 24 Gated-MLA + 69 KDA; V4-Flash 43 [secondary: clore.ai]; proxy [Assumed]
A33: Total Experts | B33: =N(K36) -> 384 | C33: Routed experts (from preset) | E33: Small / Flash | F33: GPT-5.6 Luna $0.20/$1.20; DeepSeek V4-Flash $0.44/$1.32; Gemini 3.8 Flash $0.75/$3.75 (median) | G33: 0.44 | H33: 1.32 | J33: d_model (blank = auto-scale) | K33: =IF(INDEX($L33:$P33,MATCH($B$29,$L$28:$P$28,0))="","",INDEX($L33:$P33,MATCH($B$29,$L$28:$P$28,0))) -> 7168 | L33: 7168 | M33: 7168 | N33: =N55 -> 4096 | O33: 12288 | Q33: V4-Pro/K3 hidden 7168 [Verified]; V4-Flash derived in row 55; proxy [Assumed]
A34: Active Experts | B34: =N(K37) -> 6 | C34: Active routed experts (from preset) | E34: Open-weight frontier | F34: DeepSeek V4-Pro $1.32/$3.96 (peak); GLM-5.3 $1.40/$4.40 (mean) | G34: 1.36 | H34: 4.18 | J34: Attention heads (query) | K34: =IF(INDEX($L34:$P34,MATCH($B$29,$L$28:$P$28,0))="","",INDEX($L34:$P34,MATCH($B$29,$L$28:$P$28,0))) -> 128 | L34: 128 | M34: 96 | N34: 64 | O34: 96 | Q34: V4-Pro 128; K3 96 [Verified]; V4-Flash 64 [Analogy: half of Pro]; proxy [Assumed]
A35: FFN Compute Ratio | B35: =IF(B32="Dense",1,(B34+N(K38))/(B33+N(K38))) -> 0.018181818 | C35: Dense=1; MoE=(active+shared)/(routed+shared) | E35: Mid | F35: Claude Sonnet 5 $3/$15; Kimi K3 $3/$15; Gemini 3.1 Pro $2/$12 (median) | G35: 3 | H35: 15 | J35: Attention head dim (for QK/AV FLOPs) | K35: =IF(INDEX($L35:$P35,MATCH($B$29,$L$28:$P$28,0))="","",INDEX($L35:$P35,MATCH($B$29,$L$28:$P$28,0))) -> 512 | L35: 512 | M35: 128 | N35: 512 | O35: 128 | P35: 128 | Q35: V4-Pro head_dim 512 [Verified]; K3 128 [Analogy: K2 MLA v-head]; V4-Flash [Analogy: Pro]
A36: Active Parameters | B36: =IF(B32="Dense",B31,B39*(B43+B44*B35)+K40) -> 49000000000 | C36: MoE = layers×(non-expert + FFN×ratio) + embeddings; ties to published active | E36: Frontier (closed) | F36: Claude Opus 5 $5/$25; Opus 4.8 $5/$25; GPT-5.6 Sol $5/$30 list, $4/$20 promo (median) | G36: 5 | H36: 25 | J36: Routed experts | K36: =IF(INDEX($L36:$P36,MATCH($B$29,$L$28:$P$28,0))="","",INDEX($L36:$P36,MATCH($B$29,$L$28:$P$28,0))) -> 384 | L36: 384 | M36: 896 | N36: 256 | O36: 512 | P36: 0 | Q36: V4-Pro 384 (config.json); K3 896; V4-Flash 256 [Verified]; proxy [Assumed]
A37: vocab size(V) | B37: =K39 -> 129280 | C37: From preset | E37: Premium | F37: Claude Fable 5.1 $10/$50 | G37: 10 | H37: 50 | J37: Active routed experts / token | K37: =IF(INDEX($L37:$P37,MATCH($B$29,$L$28:$P$28,0))="","",INDEX($L37:$P37,MATCH($B$29,$L$28:$P$28,0))) -> 6 | L37: 6 | M37: 16 | N37: 6 | O37: 16 | P37: 0 | Q37: V4-Pro 6, K3 16, V4-Flash 6 [Verified]
A38: Hidden Dimension(d_model) | B38: =IF(N(K33)>0,K33,MROUND(160*B39,128)) -> 7168 | C38: Preset value; blank → auto (aspect 160) | E38: Sources: | F38: Vendor list prices via price trackers checked 2026-08-19 to 2026-09-18 (CloudZero, Morph, Layer3, BenchLM, Spheron). [Verified-secondary]; promo and off-peak rates noted, not used. | J38: Shared experts | K38: =IF(INDEX($L38:$P38,MATCH($B$29,$L$28:$P$28,0))="","",INDEX($L38:$P38,MATCH($B$29,$L$28:$P$28,0))) -> 1 | L38: 1 | M38: 2 | N38: 1 | O38: 1 | P38: 0 | Q38: V4-Pro 1, K3 2, V4-Flash 1 [Verified]
A39: n_layers | B39: =IF(N(K32)>0,K32,ROUND((B31/(12*160^2))^(1/3),0)) -> 61 | C39: Preset value; blank → auto (P/(12r²))^(1/3) | J39: Vocab size | K39: =IF(INDEX($L39:$P39,MATCH($B$29,$L$28:$P$28,0))="","",INDEX($L39:$P39,MATCH($B$29,$L$28:$P$28,0))) -> 129280 | L39: 129280 | M39: 163840 | N39: 129280 | O39: 200000 | P39: 128000 | Q39: V4 129,280; K3 163,840 [Verified]; proxy [Assumed]
A40: n_heads | B40: =IF(N(K34)>0,K34,B38/B41) -> 128 | C40: Query heads (preset; else d_model/d_head) | E40: ▶ SELECTED PRICING | J40: Embedding + LM-head params [Derived] | K40: =INDEX($L40:$P40,MATCH($B$29,$L$28:$P$28,0)) -> 1853358080 | L40: =L39*IF(N(L33)>0,L33,$B$38)*2 -> 1853358080 | M40: =M39*IF(N(M33)>0,M33,$B$38)*2 -> 2348810240 | N40: =N39*IF(N(N33)>0,N33,$B$38)*2 -> 1059061760 | O40: =O39*IF(N(O33)>0,O33,$B$38)*2 -> 4915200000 | P40: =P39*IF(N(P33)>0,P33,$B$38)*2 -> 1835008000 | Q40: vocab × d_model × 2 (untied input embedding + output head)
A41: d_head | B41: =IF(N(K35)>0,K35,128) -> 512 | C41: Attention head dim (preset; else 128) | E41: Pricing Tier | F41: Frontier (closed) | H41: ← Dropdown. Default = closed-frontier list price (lab monetization view); choose "Open-weight frontier" to price the preset at its own API rate | J41: Params per routed expert [Derived] | K41: =IF(INDEX($L41:$P41,MATCH($B$29,$L$28:$P$28,0))="","",INDEX($L41:$P41,MATCH($B$29,$L$28:$P$28,0))) -> 67265157 | L41: =IF(L31="MoE",(L29-L30)/(L32*(L36-L37)),"") -> 67265157 | M41: =IF(M31="MoE",(M29-M30)/(M32*(M36-M37)),"") -> 32942326 | N41: =IF(N31="MoE",(N29-N30)/(N32*(N36-N37)),"") -> 25209302 | O41: =IF(O31="MoE",(O29-O30)/(O32*(O36-O37)),"") -> 77016129 | P41: =IF(P31="MoE",(P29-P30)/(P32*(P36-P37)),"") | Q41: (total − active) / (layers × (routed − active)); ties exactly to published totals. V4-Pro gives 67.3M vs 66.1M from config (3×7168×3072), −1.8%
A42: d_ff(SwiGLU) | B42: =IF(B32="MoE",K43,(B31/B39-4*B38^2)/(3*B38)) -> 1204291.6 | C42: MoE: effective d_ff of all experts (K43); Dense: derived from params | E42: Input Price ($/M tokens) | F42: =INDEX(G32:G37,MATCH(F41,E32:E37,0)) -> 5 | J42: Non-expert params per layer (attn, router, norms) [Derived] | K42: =IF(INDEX($L42:$P42,MATCH($B$29,$L$28:$P$28,0))="","",INDEX($L42:$P42,MATCH($B$29,$L$28:$P$28,0))) -> 3.0203967e+08 | L42: =IF(L31="MoE",(L30-L40-L32*(L37+L38)*L41)/L32,"") -> 3.0203967e+08 | M42: =IF(M31="MoE",(M30-M40-M32*(M37+M38)*M41)/M32,"") -> 5.0006167e+08 | N42: =IF(N31="MoE",(N30-N40-N32*(N37+N38)*N41)/N32,"") -> 1.0123112e+08 | O42: =IF(O31="MoE",(O30-O40-O32*(O37+O38)*O41)/O32,"") -> 4.4157381e+08 | P42: =IF(P31="MoE",(P30-P40-P32*(P37+P38)*P41)/P32,"") | Q42: (active − embed − layers × (active+shared) × expert) / layers. Includes attention, indexer, mHC, router
A43: Parameters per Layer(Att) | B43: =IF(B32="MoE",K42,4*B38^2) -> 3.0203967e+08 | C43: MoE: non-expert params/layer (K42); Dense: 4×d² | E43: Output Price ($/M tokens) | F43: =INDEX(H32:H37,MATCH(F41,E32:E37,0)) -> 25 | J43: Effective FFN intermediate d_ff (all experts, in d_model units) [Derived] | K43: =IF(INDEX($L43:$P43,MATCH($B$29,$L$28:$P$28,0))="","",INDEX($L43:$P43,MATCH($B$29,$L$28:$P$28,0))) -> 1204291.6 | L43: =IF(L31="MoE",(L36+L38)*L41/(3*IF(N(L33)>0,L33,$B$38)),"") -> 1204291.6 | M43: =IF(M31="MoE",(M36+M38)*M41/(3*IF(N(M33)>0,M33,$B$38)),"") -> 1375660.8 | N43: =IF(N31="MoE",(N36+N38)*N41/(3*IF(N(N33)>0,N33,$B$38)),"") -> 527245.34 | O43: =IF(O31="MoE",(O36+O38)*O41/(3*IF(N(O33)>0,O33,$B$38)),"") -> 1071757.7 | P43: =IF(P31="MoE",(P36+P38)*P41/(3*IF(N(P33)>0,P33,$B$38)),"") | Q43: (routed+shared) × expert params / (3 × d_model) → keeps 3·d·d_ff = total FFN params in WP_Param formulas
...

Sheet TL_Param
B1: Base Line
A2: # | B2: Step(time in s) | C2: Start Time | D2: Duration | E2: End Time | F2: Compute Time | G2: HBM BW Time | H2: NVLink Time | I2: Inter-Rack Time | J2: Bottleneck | K2: Dominant Resource | L2: FLOPs Used | M2: HBM Bytes Moved
A3: 1 | B3: Tokenization (CPU) | C3: 0 | D3: 0.05 | E3: =C3+D3 -> 0.05 | F3: N/A(CPU) | G3: N/A | H3: N/A | I3: N/A | J3: CPU | K3: CPU | L3: 0 | M3: 0
A4: 2 | B4: Embedding Lookup + Broadcast | C4: =E3 -> 0.05 | D4: =G4+H4+I4 -> 2.6264305e-06 | E4: =C4+D4 -> 0.050002626 | F4: 0 | G4: =WP_Param!B28*WP_Param!B29/(WP_Param!B15*1000000000000) -> 5.8650572e-07 | H4: =H17 -> 1.7399248e-06 | I4: =WP_Param!B293 -> 3e-07 | J4: =IF(MAX(F4,G4,H4,I4)=0,"N/A",IF(AND(MAX(F4,G4)>=H4,MAX(F4,G4)>=I4),"Memory",IF(H4>=I4,"NVLink","Inter-Rack"))) -> NVLink | K4: =IF(MAX(F4,G4,H4,I4)=0,"N/A",IF(AND(G4>=F4,G4>=H4,G4>=I4),"HBM BW",IF(AND(F4>=G4,F4>=H4,F4>=I4),"GPU",IF(H4>=I4,"NVLink","Inter-Rack")))) -> NVLink | L4: 0 | M4: =WP_Param!B22*WP_Param!B29+WP_Param!B28*WP_Param!B29 -> 1041367040
A5: 3 | B5: Prefill+KV Cache Write | C5: =E4 -> 0.050002626 | D5: =MAX(F5,G5)+H5+I5 -> 0.0092940014 | E5: =C5+D5 -> 0.059296628 | F5: =WP_Param!B70 -> 0.0016522518 | G5: =WP_Param!B87 -> 0.00053943012 | H5: =WP_Param!B96 -> 0.0076417497 | I5: =WP_Param!B294 -> 0 | J5: =IF(F5>=MAX(G5,H5,I5),"Compute",IF(G5>=MAX(H5,I5),"Memory",IF(H5>=I5,"NVLink","Inter-Rack"))) -> NVLink | K5: =IF(F5>=MAX(G5,H5,I5),"GPU",IF(G5>=MAX(H5,I5),"HBM BW",IF(H5>=I5,"NVLink","Inter-Rack"))) -> NVLink | L5: =WP_Param!B65 -> 2.0818372e+15 | M5: =WP_Param!B84 -> 8.522996e+11
A6: 4 | B6: Decode-First Token | C6: =E5 -> 0.059296628 | D6: =MAX(F6,G6) -> 1.517011e-05 | E6: =C6+D6 -> 0.059311798 | F6: =WP_Param!B121 -> 3.61424e-08 | G6: =WP_Param!B138 -> 1.517011e-05 | H6: - | I6: - | J6: =IF(F6>=MAX(G6,H6,I6),"Compute",IF(G6>=MAX(H6,I6),"Memory",IF(H6>=I6,"NVLink","Inter-Rack"))) -> Memory | K6: =IF(F6>=MAX(G6,H6,I6),"GPU",IF(G6>=MAX(H6,I6),"HBM BW",IF(H6>=I6,"NVLink","Inter-Rack"))) -> HBM BW | L6: =WP_Param!B117 -> 130112640000 | M6: =WP_Param!B135 -> 2.3968774e+10
A7: 5 | B7: Decode-All Tokens | C7: =E6 -> 0.059311798 | D7: =MAX(F7,G7)+H7+I7 -> 0.26000555 | E7: =C7+D7 -> 0.31931735 | F7: =WP_Param!B122 -> 3.61424e-05 | G7: =WP_Param!B138*WP_Param!B23 -> 0.01517011 | H7: =WP_Param!$B$149*WP_Param!$B$23+WP_Param!$B$200*WP_Param!$B$23 -> 0.24423544 | I7: =WP_Param!B295 -> 0.0006 | J7: =IF(F7>=MAX(G7,H7,I7),"Compute",IF(G7>=MAX(H7,I7),"Memory",IF(H7>=I7,"NVLink","Inter-Rack"))) -> NVLink | K7: =IF(F7>=MAX(G7,H7,I7),"GPU",IF(G7>=MAX(H7,I7),"HBM BW",IF(H7>=I7,"NVLink","Inter-Rack"))) -> NVLink | L7: =WP_Param!B118 -> 130112640000000 | M7: =WP_Param!B135*WP_Param!B23 -> 23968773918440
A8: 6 | B8: De-tokenization (CPU) | C8: =E7 -> 0.31931735 | D8: 0.05 | E8: =C8+D8 -> 0.36931735 | F8: N/A(CPU) | G8: N/A | H8: N/A | I8: N/A | J8: CPU | K8: CPU | L8: 0 | M8: 0
B9: Avg Time per Output Token (s) | E9: =E8/WP_Param!B23 -> 0.00036931735
B10: Total Output Token(s)/second | E10: =1/E9 -> 2707.6984
B14: Optimized — architecture KV + Concurrent Batch + Speculative Decoding + NVLink Optimization (v4: MoE-aware)
A15: # | B15: Step(time in s) | C15: Start Time | D15: Duration | E15: End Time | F15: Compute Time | G15: HBM BW Time | H15: NVLink Time | I15: Inter-Rack Time | J15: Bottleneck | K15: Dominant Resource | L15: FLOPs Used | M15: HBM Bytes Moved
A16: 1 | B16: Tokenization (CPU) | C16: 0 | D16: 0.05 | E16: =C16+D16 -> 0.05 | F16: N/A(CPU) | G16: N/A | H16: N/A | I16: N/A | J16: CPU | K16: CPU | L16: 0 | M16: 0
A17: 2 | B17: Embedding Lookup + Broadcast | C17: =E16 -> 0.05 | D17: =G17+H17+I17 -> 2.6264305e-06 | E17: =C17+D17 -> 0.050002626 | F17: 0 | G17: =WP_Param!B28*WP_Param!B29/(WP_Param!B15*1000000000000) -> 5.8650572e-07 | H17: =2*WP_Param!B22*WP_Param!B29*2*(71/72)/(WP_Param!B12*1000000000000) -> 1.7399248e-06 | I17: =WP_Param!B297 -> 3e-07 | J17: =IF(MAX(F17,G17,H17,I17)=0,"N/A",IF(AND(MAX(F17,G17)>=H17,MAX(F17,G17)>=I17),"Memory",IF(H17>=I17,"NVLink","Inter-Rack"))) -> NVLink | K17: =IF(MAX(F17,G17,H17,I17)=0,"N/A",IF(AND(G17>=F17,G17>=H17,G17>=I17),"HBM BW",IF(AND(F17>=G17,F17>=H17,F17>=I17),"GPU",IF(H17>=I17,"NVLink","Inter-Rack")))) -> NVLink | L17: 0 | M17: =WP_Param!B22*WP_Param!B29+WP_Param!B28*WP_Param!B29 -> 1041367040
A18: 3 | B18: Prefill+KV Cache Write | C18: =E17 -> 0.050002626 | D18: =MAX(F18,G18)+H18+I18 -> 0.3502801 | E18: =C18+D18 -> 0.40028273 | F18: =WP_Param!B70*WP_Param!B169 -> 0.10574411 | G18: =WP_Param!B87*WP_Param!B169 -> 0.034523528 | H18: =WP_Param!B97*WP_Param!B169 -> 0.24453599 | I18: =WP_Param!B294 -> 0 | J18: =IF(F18>=MAX(G18,H18,I18),"Compute",IF(G18>=MAX(H18,I18),"Memory",IF(H18>=I18,"NVLink","Inter-Rack"))) -> NVLink | K18: =IF(F18>=MAX(G18,H18,I18),"GPU",IF(G18>=MAX(H18,I18),"HBM BW",IF(H18>=I18,"NVLink","Inter-Rack"))) -> NVLink | L18: =WP_Param!B65*WP_Param!B169 -> 1.3323758e+17 | M18: =WP_Param!B84*WP_Param!B169 -> 5.4547174e+13
A19: 4 | B19: Decode-First Token | C19: =E18 -> 0.40028273 | D19: =MAX(F19,G19) -> 1.5170108e-05 | E19: =C19+D19 -> 0.4002979 | F19: =WP_Param!B121 -> 3.61424e-08 | G19: =WP_Param!B164 -> 1.5170108e-05 | H19: - | I19: - | J19: =IF(F19>=MAX(G19,H19,I19),"Compute",IF(G19>=MAX(H19,I19),"Memory",IF(H19>=I19,"NVLink","Inter-Rack"))) -> Memory | K19: =IF(F19>=MAX(G19,H19,I19),"GPU",IF(G19>=MAX(H19,I19),"HBM BW",IF(H19>=I19,"NVLink","Inter-Rack"))) -> HBM BW | L19: =WP_Param!B117 -> 130112640000 | M19: =WP_Param!B163 -> 2.396877e+10
A20: 5 | B20: Decode-All Tokens | C20: =E19 -> 0.4002979 | D20: =MAX(F20,G20)+H20+I20 -> 0.15678195 | E20: =C20+D20 -> 0.55707985 | F20: =WP_Param!B122*WP_Param!B169*(Config!B57+1)/Config!B59/Config!B46 -> 0.013482178 | G20: =WP_Param!B172*WP_Param!B23*WP_Param!B169/WP_Param!B178 -> 0.11262025 | H20: =(WP_Param!$B$205*WP_Param!$B$169+WP_Param!B206)*WP_Param!$B$23/WP_Param!$B$178 -> 0.044041697 | I20: =WP_Param!B296 -> 0.00012 | J20: =IF(F20>=MAX(G20,H20,I20),"Compute",IF(G20>=MAX(H20,I20),"Memory",IF(H20>=I20,"NVLink","Inter-Rack"))) -> Memory | K20: =IF(F20>=MAX(G20,H20,I20),"GPU",IF(G20>=MAX(H20,I20),"HBM BW",IF(H20>=I20,"NVLink","Inter-Rack"))) -> HBM BW | L20: =WP_Param!B118 -> 130112640000000 | M20: =WP_Param!B171*WP_Param!B23 -> 523351795827173 | N20: F20 fix (v4): decode compute × batch × (draft N+1)/accepted ÷ MFU; v3 ignored batch
A21: 6 | B21: De-tokenization (CPU) | C21: =E20 -> 0.55707985 | D21: 0.05 | E21: =C21+D21 -> 0.60707985 | F21: N/A(CPU) | G21: N/A | H21: N/A | I21: N/A | J21: CPU | K21: CPU | L21: 0 | M21: 0
B22: Avg Time per Output Token (s) | E22: =E21/(WP_Param!B169*WP_Param!B23) -> 9.4856227e-06 | G22: E2E / (Batch * Output)
B23: Total Output Token(s)/second | E23: =1/E22 -> 105422.71
B28: Rack-Independent Latency Outputs (with Inter-Rack Network)
C29: VR NVL72 E2E (s) | D29: GB200 NVL72 E2E (s)
C30: =D16 -> 0.05 | D30: =D16 -> 0.05
C31: =IF(Config!B7="Vera Rubin NVL72", D17, G17*(Config!G18/Config!F18) + H17*(Config!G15/Config!F15) + I17) -> 2.6264305e-06 | D31: =IF(Config!B7="Vera Rubin NVL72", G17*(Config!F18/Config!G18) + H17*(Config!F15/Config!G15) + I17, D17) -> 5.3886674e-06
C32: =IF(Config!B7="Vera Rubin NVL72", D18, F18*(IF(Config!B47="FP4",Config!G19,IF(Config!B47="FP8",Config!G21,Config!G22))/IF(Config!B47="FP4",Config!F19,IF(Config!B47="FP8",Config!F21,Config!F22))) + H18*(Config!G15/Config!F15) + I18) -> 0.3502801 | D32: =IF(Config!B7="Vera Rubin NVL72", F18*(IF(Config!B47="FP4",Config!F19,IF(Config!B47="FP8",Config!F21,Config!F22))/IF(Config!B47="FP4",Config!G19,IF(Config!B47="FP8",Config!G21,Config!G22))) + H18*(Config!F15/Config!G15) + I18, D18) -> 1.0765393
C33: =IF(Config!B7="Vera Rubin NVL72", D19, G19*(Config!G18/Config!F18)) -> 1.5170108e-05 | D33: =IF(Config!B7="Vera Rubin NVL72", G19*(Config!F18/Config!G18), D19) -> 4.1612448e-05
C34: =IF(Config!B7="Vera Rubin NVL72", D20, G20*(Config!G18/Config!F18) + H20*(Config!G15/Config!F15) + I20) -> 0.15678195 | D34: =IF(Config!B7="Vera Rubin NVL72", G20*(Config!F18/Config!G18) + H20*(Config!F15/Config!G15) + I20, D20) -> 0.39712701
C35: =D21 -> 0.05 | D35: =D21 -> 0.05
B36: Avg Time/Output Token (s) | C36: =SUM(C30:C35)/(Config!B56*Config!B28) -> 9.4856227e-06 | D36: =SUM(D30:D35)/(Config!B56*Config!B28) -> 2.458927e-05
B37: Tokens/sec per Rack | C37: =1/C36 -> 105422.71 | D37: =1/D36 -> 40668.145
B38: E2E Latency (s) | C38: =SUM(C30:C35) -> 0.60707985 | D38: =SUM(D30:D35) -> 1.5737133
B39: Inter-Rack Overhead % | C39: =(I17+I18+I20)/C38 -> 0.00019816174 | D39: =(I17+I18+I20)/D38 -> 7.6443404e-05
B42: ▶ INTER-RACK STRESS TEST — Scenario Comparison (VR NVL72)
B44: Parameter / Metric | C44: Current (IB XDR, Colocated) | D44: Scenario A Std Ethernet | E44: Scenario B Disaggregated | F44: Scenario C 16:1 Oversub | G44: Scenario D Ethernet + Disagg | H44: Scenario E All Worst-Case
B45: Network Assumptions
B46: Fabric Type | C46: IB XDR | D46: Std Ethernet | E46: IB XDR | F46: IB XDR | G46: Std Ethernet | H46: Std Ethernet
B47: Switch Latency (μs/hop) | C47: =Config!B76 -> 0.1 | D47: 5 | E47: =C47 -> 0.1 | F47: =C47 -> 0.1 | G47: =D47 -> 5 | H47: =D47 -> 5
B48: Network Hops | C48: =Config!B77 -> 3 | D48: =C48 -> 3 | E48: =C48 -> 3 | F48: =C48 -> 3 | G48: =C48 -> 3 | H48: 5
B49: One-Way Latency (s) | C49: =C47*C48/1000000 -> 3e-07 | D49: =D47*D48/1000000 -> 1.5e-05 | E49: =E47*E48/1000000 -> 3e-07 | F49: =F47*F48/1000000 -> 3e-07 | G49: =G47*G48/1000000 -> 1.5e-05 | H49: =H47*H48/1000000 -> 2.5e-05
B50: Oversubscription Ratio | C50: =Config!B78 -> 2 | D50: =C50 -> 2 | E50: =C50 -> 2 | F50: 16 | G50: =C50 -> 2 | H50: =F50 -> 16
...

Sheet WP_Param
A1: AI DC Spec. | B1: Data | C1: Note
A2: Total power(W) | B2: =Config!B5 -> 1000000000
A3: PUE | B3: =Config!B6 -> 1.2
A4: Rack Type | B4: =Config!B7 -> Vera Rubin NVL72
A5: No.of racks | B5: =Config!B8 -> 5263
A7: Rack Spec. | B7: Data | C7: Note
A8: CPU Type | B8: =Config!B11 -> Vera CPU
A9: No. of CPU | B9: =Config!B12 -> 36
A10: GPU Type | B10: =Config!B13 -> Rubin GPU
A11: No. of GPU | B11: =Config!B14 -> 72
A12: NVLink Bandwidth(TB/s) | B12: =Config!B15 -> 260
A13: NVLink-C2C Bandwidth(TB/s) | B13: =Config!B16 -> 65
A14: GPU Memory(TB) | B14: =Config!B17 -> 20.7 | C14: 0.288/GPU
A15: Memory Bandwidth(TB) | B15: =Config!B18 -> 1580 | C15: 22/GPU
A16: FP4 Dense Inference(PFLOPS) | B16: =Config!B19 -> 3600 | C16: 50 PFLOPS/GPU (FP4 dense inference)
A17: FP4 Dense Training(PFLOPS) | B17: =Config!B20 -> 2520 | C17: 35/GPU
A18: FP8 Dense(PFLOPS) | B18: =Config!B21 -> 1152 | C18: 16 PFLOPS/GPU (FP8 dense)
A19: FP16/BF16 Dense(PFLOPS) | B19: =Config!B22 -> 288 | C19: 4/GPU
A21: Input/Output Tokens Setup | B21: Data | C21: Note
A22: Input Tokens: | B22: =Config!B27 -> 16000
A23: Output Tokens: | B23: =Config!B28 -> 1000
A25: Model Spec. | B25: Data | C25: Note
A26: Parameters | B26: =Config!B31 -> 1600000000000 | C26: From Config sheet
A27: Type | B27: =Config!B32 -> MoE
A28: vocab size(V) | B28: =Config!B37 -> 129280
A29: Hidden Dimension(d_model) | B29: =Config!B38 -> 7168 | C29: Given
A30: n_layers | B30: =Config!B39 -> 61 | C30: Given
A31: n_heads | B31: =Config!B40 -> 128
A32: d_head | B32: =Config!B41 -> 512
A33: d_ff(SwiGLU) | B33: =Config!B42 -> 1204291.6 | C33: derived from Parameters
A34: Parameters per Layer(Att) | B34: =Config!B43 -> 3.0203967e+08 | C34: Q_W+K_W+V_W+O_W=4*d_model^2
A35: Parameters per Layer(FFN) | B35: =Config!B44 -> 2.5897086e+10 | C35: 3 × d_model × d_ff
A36: Total Parameters per Layer | B36: =Config!B45 -> 2.6199125e+10
A37: Weight Memory(Byte) | B37: =B26*Config!B48 -> 811200000000 | C37: Parameters × Bytes/param (from Config Precision)
A38: Weight Memory(Byte)/GPU | B38: =B37/B11 -> 1.1266667e+10
A39: KV cache @ Beginning(Byte) | B39: =B161*B22*B30*Config!$K$46 -> 63440000 | C39: Architecture KV (MLA/CSA/GQA) × input × layers × KV bytes
A40: KV cache @ End(Byte) | B40: =B161*(B22+B23)*B30*Config!$K$46 -> 67405000 | C40: Architecture KV × (input+output) × layers × KV bytes
A41: KV cache per GPU @ End | B41: =B40/B11 -> 936180.56
A42: Memory required per GPU | B42: =B41*B169+B38 -> 1.1326582e+10 | C42: KV/GPU × Batch_Size + Weights/GPU (production serving)
A43: GPU Memory Headroom | B43: =B14/B11*1000000000000-B42 -> 2.7617342e+11 | C43: Check if GPU has enough memory
...

Sheet DC_Cost_Model
A1: Data Center Cost Model — 1 GW Vera Rubin NVL72 Facility
A3: Section 1: Data Center Specifications (from Config)
A4: Item | B4: Value | C4: Unit | E4: Source / Note
A5: Total IT Power | B5: =Config!F5/1000000 -> 1000 | C5: MW | E5: Config!F5 (VR preset, dropdown-independent)
A6: PUE | B6: =Config!F6 -> 1.2 | E6: Config!F6 (VR preset, dropdown-independent)
A7: Total Facility Power (IT × PUE) | B7: =B5*B6 -> 1200 | C7: MW | E7: Total electrical load including cooling, lighting, etc.
A8: Rack Type | B8: =Config!F7 -> Vera Rubin NVL72 | E8: Config!F7 (VR preset, dropdown-independent)
A9: Number of Racks | B9: =Config!F8 -> 5263 | C9: racks | E9: Config!F8 (VR preset, dropdown-independent)
A10: GPUs per Rack | B10: =Config!F14 -> 72 | C10: GPUs | E10: Config!F14 (VR preset, dropdown-independent)
A11: Total GPUs | B11: =B9*B10 -> 378936 | C11: GPUs | E11: Racks × GPUs per rack
A12: Power per Rack (est.) | B12: =B5*1000/B9 -> 190.0057 | C12: kW | E12: Total IT Power / Racks
A13: Total Facility Sq. Ft. (est.) | B13: =B9*80 -> 421040 | C13: sq ft | E13: ~80 sq ft per rack (AI liquid-cooled, incl. aisles + support)
A15: Section 2: Capital Expenditure (CapEx) Breakdown
A16: Category | B16: Unit Cost | C16: Quantity / Basis | D16: Total ($M) | E16: Assumption / Source | F16: % of CapEx
A17: 2A. IT Hardware (Servers & GPUs)
A18: =" "&Config!F7&" Racks" -> Vera Rubin NVL72 Racks | B18: =Config!F27 -> 6000000 | C18: =B9 -> 5263 | D18: =B18*C18/1000000 -> 31578 | E18: Est. $6M/rack per Config VR preset (F27); GB200 ~$3M, Rubin gen premium ~15-20% | F18: =D18/$D$54 -> 0.73039455
A19: Scale-out Networking (InfiniBand/Ethernet) | B19: 150000 | C19: =B9 -> 5263 | D19: =B19*C19/1000000 -> 789.45 | E19: Quantum-X800 IB + Spectrum-X Ethernet per-rack allocation | F19: =D19/$D$54 -> 0.018259864
A20: Top-of-Rack & Spine Switches | B20: 35000 | C20: =B9 -> 5263 | D20: =B20*C20/1000000 -> 184.205 | E20: Mgmt network, OOB, storage fabric per-rack allocation | F20: =D20/$D$54 -> 0.0042606349
A21: Storage & Boot Infrastructure | B21: 25000 | C21: =B9 -> 5263 | D21: =B21*C21/1000000 -> 131.575 | E21: NVMe boot drives, shared storage, cabling per rack | F21: =D21/$D$54 -> 0.0030433106
A22: Subtotal IT Hardware | D22: =SUM(D18:D21) -> 32683.23 | F22: =D22/$D$54 -> 0.75595836
A24: 2B. Land, Building & Site Work
A25: Land Acquisition (est. 100 acres) | B25: 200000 | C25: 100 | D25: =B25*C25/1000000 -> 20 | E25: ~100 acres; $200K/acre (semi-rural US, utility-adjacent) | F25: =D25/$D$54 -> 0.00046259709
A26: Building Shell & Core | B26: 3000000 | C26: =B7 -> 1200 | D26: =B26*C26/1000000 -> 3600 | E26: $3M/MW facility power; foundation, structure, envelope | F26: =D26/$D$54 -> 0.083267476
A27: Site Work & Civil (roads, grading, fencing) | B27: 500000 | C27: =B7 -> 1200 | D27: =B27*C27/1000000 -> 600 | E27: $500K/MW facility power; roads, grading, security fence | F27: =D27/$D$54 -> 0.013877913
A28: Subtotal Land & Building | D28: =SUM(D25:D27) -> 4220 | F28: =D28/$D$54 -> 0.097607986
A30: 2C. Electrical Infrastructure
A31: Substation & Grid Interconnection | B31: 1500000 | C31: =B7 -> 1200 | D31: =B31*C31/1000000 -> 1800 | E31: $1.5M/MW; HV substation, transformers, HV switchgear | F31: =D31/$D$54 -> 0.041633738
A32: Medium Voltage Distribution & PDUs | B32: 800000 | C32: =B7 -> 1200 | D32: =B32*C32/1000000 -> 960 | E32: $800K/MW; MV switchgear, busway, rack-level PDUs | F32: =D32/$D$54 -> 0.02220466
A33: Backup Generators (N+1 diesel/gas) | B33: 600000 | C33: =B7 -> 1200 | D33: =B33*C33/1000000 -> 720 | E33: $600K/MW; diesel/gas turbine gen-sets with N+1 redundancy | F33: =D33/$D$54 -> 0.016653495
A34: UPS & Battery Storage | B34: 400000 | C34: =B5 -> 1000 | D34: =B34*C34/1000000 -> 400 | E34: $400K/MW IT; UPS systems + Li-ion BESS for ride-through | F34: =D34/$D$54 -> 0.0092519418
A35: Subtotal Electrical | D35: =SUM(D31:D34) -> 3880 | F35: =D35/$D$54 -> 0.089743836
A37: 2D. Cooling & Mechanical Systems
A38: Liquid Cooling (CDUs, piping, cold plates) | B38: 56000 | C38: =B9 -> 5263 | D38: =B38*C38/1000000 -> 294.728 | E38: ~$56K/rack; Morgan Stanley est. cold plates + CDU piping | F38: =D38/$D$54 -> 0.0068170158
A39: Cooling Towers & Heat Rejection Plant | B39: 300000 | C39: =B7 -> 1200 | D39: =B39*C39/1000000 -> 360 | E39: $300K/MW; cooling towers, chillers, pumps, water treatment | F39: =D39/$D$54 -> 0.0083267476
A40: Fire Suppression & HVAC (non-IT areas) | B40: 100000 | C40: =B7 -> 1200 | D40: =B40*C40/1000000 -> 120 | E40: $100K/MW; clean agent suppression, office HVAC | F40: =D40/$D$54 -> 0.0027755825
A41: Subtotal Cooling & Mechanical | D41: =SUM(D38:D40) -> 774.728 | F41: =D41/$D$54 -> 0.017919346
A43: 2E. Fiber, Cabling & Security
A44: Fiber Optic & Structured Cabling | B44: 200000 | C44: =B7 -> 1200 | D44: =B44*C44/1000000 -> 240 | E44: $200K/MW; intra-campus dark fiber, cable trays, patch panels | F44: =D44/$D$54 -> 0.0055511651
A45: Physical Security & BMS | B45: 50000 | C45: =B7 -> 1200 | D45: =B45*C45/1000000 -> 60 | E45: $50K/MW; CCTV, access control, DCIM, BMS sensors | F45: =D45/$D$54 -> 0.0013877913
A46: Subtotal Fiber, Cabling & Security | D46: =SUM(D44:D45) -> 300 | F46: =D46/$D$54 -> 0.0069389564
...

Sheet Revenue_Model
A1: Token Generation & Revenue Model — 1 GW Vera Rubin NVL72 Inference Facility
A3: Section 1: Inference Configuration (per Rack) — from Config
A4: Parameter | B4: Value | C4: Unit | E4: Source / Note
A5: Model Parameters | B5: =Config!B31 -> 1600000000000 | C5: params | E5: Linked from Config!B30
A6: Input Tokens per Request | B6: =Config!B27 -> 16000 | C6: tokens | E6: Linked from Config!B26
A7: Output Tokens per Request | B7: =Config!B28 -> 1000 | C7: tokens | E7: Linked from Config!B27
A8: Total Tokens per Request | B8: =B6+B7 -> 17000 | C8: tokens | E8: Input + Output
A9: Batch Size (concurrent requests) | B9: =Config!B56 -> 64 | C9: requests | E9: Linked from Config!B48
A10: Speculative Decoding Gain | B10: =Config!B59 -> 2.94117 | C10: tokens/step | E10: Expected tokens accepted per step, Config!B51
A11: End-to-End Latency per Request (optimized) | B11: =TL_Param!C38 -> 0.60707985 | C11: seconds | E11: From TL_Param!C38 (VR-specific, dropdown-independent)
A12: Number of Racks | B12: =Config!F8 -> 5263 | C12: racks | E12: Config!F8 (VR rack count, dropdown-independent)
A13: GPU Utilization Rate | B13: 0.7 | E13: Realistic + lean overhead; accounts for maintenance, failures, model swap
A14: Uptime (scheduled) | B14: 0.995 | E14: 99.5% SLA; ~43.8 hrs downtime/year
A15: Effective Annual Seconds per Rack | B15: =8760*3600*B13*B14 -> 21964824 | C15: seconds/yr | E15: 8,760 hrs × 3,600 s/hr × utilization × uptime
A16: Requests per Rack per Year | B16: =FLOOR(B15/B11,1)*B9 -> 2315591104 | C16: requests/yr | E16: (Effective seconds / Latency) × Batch Size
A18: Section 2: Annual Token Throughput (Entire DC)
A19: Metric | B19: Value | C19: Unit | E19: Calculation
A20: Total Requests per Year (all racks) | B20: =B16*B12 -> 12186955980352 | C20: requests/yr | E20: Requests/rack/yr × racks
A21: Annual Input Tokens | B21: =B20*B6 -> 1.949913e+17 | C21: tokens/yr | E21: Total requests × input tokens/request
A22: Annual Output Tokens | B22: =B20*B7 -> 1.2186956e+16 | C22: tokens/yr | E22: Total requests × output tokens/request
A23: Annual Total Tokens | B23: =B21+B22 -> 2.0717825e+17 | C23: tokens/yr | E23: Input + Output
A24: Annual Total Tokens (M) | B24: =B23/1000000 -> 2.0717825e+11 | C24: M tokens/yr | E24: Total / 1,000,000
A25: Annual Input Tokens (M) | B25: =B21/1000000 -> 1.949913e+11 | C25: M tokens/yr
A26: Annual Output Tokens (M) | B26: =B22/1000000 -> 1.2186956e+10 | C26: M tokens/yr
A27: Tokens per Second (DC-wide) | B27: =B23/(8760*3600) -> 6.5695793e+09 | C27: tokens/sec | E27: Annual tokens / seconds per year (gross throughput)
A28: Requests per Second (DC-wide) | B28: =B20/(8760*3600) -> 386445.84 | C28: req/sec | E28: Annual requests / seconds per year
A30: Section 3: Market Pricing & Annual Revenue
A31: Pricing Tier | B31: Value | C31: Unit | E31: Source / Note
A32: Market Rate — Input Tokens | B32: =Config!F42 -> 5 | C32: $/M input tokens | E32: Auto-selected from Config pricing tiers based on model size
A33: Market Rate — Output Tokens | B33: =Config!F43 -> 25 | C33: $/M output tokens | E33: Auto-selected from Config pricing tiers based on model size
A34: Blended Rate (weighted by I/O mix) | B34: =(B32*B25+B33*B26)/(B25+B26) -> 6.1764706 | C34: $/M tokens | E34: (Input rev + Output rev) / Total M tokens
A36: Revenue Calculation
A37: Annual Input Token Revenue | B37: =B25*B32/1000000 -> 974956.48 | C37: $M/year | E37: Input M tokens × $/M input
A38: Annual Output Token Revenue | B38: =B26*B33/1000000 -> 304673.9 | C38: $M/year | E38: Output M tokens × $/M output
A39: TOTAL ANNUAL REVENUE | B39: =B37+B38 -> 1279630.4 | C39: $M/year
A41: Revenue Composition
A42: Input token revenue share | B42: =B37/B39 -> 0.76190476
A43: Output token revenue share | B43: =B38/B39 -> 0.23809524
A44: Revenue per rack per year | B44: =B39/B12*1000000 -> 2.4313707e+08 | C44: $/rack/yr
A46: Rrevenue to opex | B46: =B39/DC_Cost_Model!D88 -> 137.62164
...

Sheet OpenAI_Sim
A1: OpenAI Financial Simulation — Calibrating 1 GW VR72 DC Model to OpenAI's Disclosed Financials (Feb 2026 Funding Round)
A3: Section 1: OpenAI Disclosed Financials & Operating Metrics (Feb-2026 base; Sep-2026 FT update applied — see FT_Sep2026)
A4: Metric | B4: 2024A | C4: 2025A | D4: 2026E | E4: 2027E | F4: 2028E | G4: 2029E | H4: 2030E | I4: Source / Note
A5: Revenue ($B) | B5: 3.7 | C5: 13.1 | D5: =FT_Sep2026!E6 -> 36 | H5: =FT_Sep2026!E8 -> 350 | I5: 2025A $13.1B (CNBC). 2026E $36B / 2030E $350B: Jul-2026 deck per FT 2026-09-18 [Interested-party]; prior 2030 target $280B (Feb-2026)
A6: ARR ($B, exit rate) | B6: 6 | C6: 20 | I6: OpenAI CFO blog: $2B (2023) → $6B (2024) → $20B+ (2025)
A7: YoY Revenue Growth | B7: =B5/3.7-1 -> 0 | C7: =C5/B5-1 -> 2.5405405 | I7: Implied from reported revenue figures
A8: Cash Burn ($B) | B8: -5 | C8: -8 | D8: -25 | E8: -57 | H8: 39 | I8: Feb-2026 vintage (The Information): 2026 −$25B, 2027 −$57B, 2026–29 cum −$218B (2028–29 not split), 2030 +$39B. Jul-2026 vintage: 2026–30 cum −$278B (FT) → FT_Sep2026
A9: Gross Margin | B9: 0.4 | C9: 0.33
A11: Compute Capacity, Year-End (GW) | B11: 0.6 | C11: 1.9 | D11: 3.5 | E11: 4.5 | F11: 5.75 | G11: 7 | H11: 10 | I11: Year-end capacity: 0.6 GW (2024) → 1.9 GW (2025) → 10 GW (2030 Stargate)
A12: Compute Capacity, FY Avg (GW) | B12: =(0.2+B11)/2 -> 0.4 | C12: =(B11+C11)/2 -> 1.25 | D12: =(C11+D11)/2 -> 2.7 | E12: =(D11+E11)/2 -> 4 | F12: =(E11+F11)/2 -> 5.125 | G12: =(F11+G11)/2 -> 6.375 | H12: =(G11+H11)/2 -> 8.5 | I12: FY average = midpoint of prior year-end and current year-end (linear ramp)
A13: Weekly Active Users (M) | C13: 900 | I13: 900M WAU, 50M+ paid subscribers (Feb 2026)
A14: Paid Subscribers (M) | C14: 50 | I14: 50M+ consumer subscribers
A16: Latest Funding Round
A17: Total Raised | B17: $122B | I17: Closed 2026-03-31: $122B committed (Amazon / Nvidia / SoftBank anchor) [Verified]
A18: Pre-Money Valuation | B18: $730B | I18: Pre-money $730B; post-money $852B
A19: Post-Money Valuation | B19: $852B | I19: Largest private funding round in history
A20: Implied Revenue Multiple (on 2025 rev) | B20: =B113/C5 -> 65.038168 | I20: Post-money valuation / 2025 actual revenue
A21: Implied Revenue Multiple (on 2030E rev) | B21: =B113/H5 -> 2.4342857 | I21: Post-money valuation / 2030E target revenue
A22: Infrastructure Spend Target (by 2030) | B22: $856B | I22: Jul-2026 deck: ~$856B compute & infrastructure through 2030 (Feb-2026: ~$600B "compute"; category may differ)
A23: Stargate Capacity Target | B23: 10 GW | I23: Stargate: $500B / 4 yrs / 10 GW US-based AI infra
A24: New Round Talks (Sep 2026, valuation ≥) | B24: =FT_Sep2026!E19 -> 1200 | I24: FT/Bloomberg: investors discussed ≥$1.2T; OpenAI seeking higher [Interested-party]
A25: Section 2: Infrastructure Calibration — Scaling Our 1 GW VR72 Model to OpenAI's 1.9 GW (2025)
A26: Parameter | B26: Our 1 GW Model | C26: OpenAI 1.9 GW | D26: Unit | I26: Note
A27: IT Power (MW) | B27: =Config!F5/1000000 -> 1000 | C27: =C11*1000 -> 1900 | D27: MW | I27: Config!F5 (VR preset, dropdown-independent); OpenAI from CFO blog
A28: PUE | B28: =Config!F6 -> 1.2 | C28: 1.25 | I28: Mixed fleet PUE slightly higher (H100/A100 legacy + newer)
A29: Total Facility Power (MW) | B29: =B27*B28 -> 1200 | C29: =C27*C28 -> 2375 | D29: MW | I29: IT Power × PUE
A30: Scale Factor (vs our 1 GW model) | B30: 1 | C30: =C27/B27 -> 1.9 | I30: Simple linear scaling of IT power
A32: Hardware Mix Adjustment
A33: Current Fleet (est.) | B33: 100% VR NVL72 | C33: Mixed (H100/GB200/VR) | I33: OpenAI runs mixed generations; our model = next-gen only
A34: Inference Efficiency Factor | B34: 1 | C34: =C100*0.25+C101*(TL_Param!D37/TL_Param!C37)+C102*1 -> 0.2907288 | I34: Fleet-weighted VR-equiv factor: H100=0.25x, GB200≈0.39x (TL_Param!D37/C37), VR=1.0x
A35: Effective VR-Equivalent Power (MW) | B35: =B27*B34 -> 1000 | C35: =C27*C34 -> 552.38473 | D35: MW-eq | I35: Reference facility IT power × fleet efficiency factor = VR-equivalent MW
A37: Implied from Financials
A38: Our Model CapEx ($B) | B38: =DC_Cost_Model!D54/1000 -> 43.234167 | I38: From DC_Cost_Model total CapEx
A39: OpenAI Implied CapEx at 1.9 GW ($B) | C39: =B38*C30 -> 82.144918 | I39: Scaled linearly from our 1 GW model
A40: Our Model Annual OpEx ($B) | B40: =DC_Cost_Model!D88/1000 -> 9.2981768 | I40: From DC_Cost_Model total annual OpEx
A41: OpenAI Implied DC OpEx at 1.9 GW ($B) | C41: =B40*C30 -> 17.666536 | I41: DC-only OpEx; does not include R&D, S&M, G&A, SBC
A43: Section 3: OpenAI P&L Simulation — Reverse-Engineering from Disclosed Numbers
A44: Line Item | B44: 2024A ($B) | C44: 2025A ($B) | D44: 2026E ($B) | E44: 2027E ($B) | F44: 2028E ($B) | G44: 2029E ($B) | H44: 2030E ($B) | I44: Assumption / Source
A45: Assumptions
A46: Revenue Growth Rate (YoY) | C46: =C7 -> 2.5405405 | D46: =FT_Sep2026!B25 -> 1.7480916 | E46: =FT_Sep2026!C25 -> 1.0861111 | F46: =FT_Sep2026!D25 -> 0.88415446 | G46: =FT_Sep2026!E25 -> 0.67773852 | H46: =FT_Sep2026!F25 -> 0.47430497 | I46: 2025 actual 254%; 2026–30 from FT_Sep2026 row 25 (Jul-2026 deck path: $36B → $350B, Σ $840B)
...

Sheet FT_Sep2026
A1: FT Update (2026-09-18 report on OpenAI July-2026 deck) — Vintages, Revenue Path, Cash Bridge v3, Runway, Capacity Tension
A2: Legend: blue = hardcoded input / lever · black = formula · green = link to another sheet · yellow fill = key assumption. Tags in column H: [Verified] [Interested-party] [Analogy] [Assumed] [Derived].
A4: Section A: OpenAI projection vintages ($B) — as reported
A5: Metric | B5: Sep-2025 | C5: Feb-2026 | D5: May-2026 | E5: Jul-2026 | H5: Source / Tag
A6: Revenue 2026E | C6: 30 | E6: 36 | H6: Feb: The Information via the-decoder (2026-02-21); Jul: FT 2026-09-18. [Interested-party: OpenAI; Jul deck prepared for a compute deal amid ≥$1.2T round talks]
A7: Revenue 2027E | C7: 62 | H7: Feb: The Information (~$62B). Jul: not disclosed
A8: Revenue 2030E | C8: 280 | E8: 350 | H8: Feb: $280B target; Jul: FT
A9: Cumulative revenue 2026–30 | E9: 840 | H9: FT: "$840bn between now and the end of 2030" — reading assumed = FY2026–FY2030 (see note row 20)
A10: FCF 2026E | B10: -17 | C10: -25 | H10: Sep-25: The Information via CNBC 2025-09-06; Feb: The Information
A11: FCF 2027E | B11: -35 | C11: -57 | H11: same
A12: FCF 2028E | B12: -45 | H12: Sep-25 only; Feb gives 2026–29 cumulative only
A13: Cumulative FCF 2026–29 | C13: -218 | H13: Feb: The Information / Sherwood 2026-02-23
A14: FCF 2030E | C14: 39 | H14: Feb: first positive year 2030 (+$39B)
A15: Cumulative FCF 2026–30 | C15: =C13+C14 -> -179 | D15: -305 | E15: -278 | H15: Feb [Derived]=−218+39; May & Jul: FT
A16: Compute / infra spend through 2030 | C16: 600 | E16: 856 | H16: Feb: ~$600B "compute"; Jul: ~$856B "computing power and infrastructure" — category may differ
A17: Latest round raised | E17: 122 | H17: OpenAI 2026-03-31: $122B committed [Verified]
A18: Post-money valuation | E18: 852 | H18: OpenAI 2026-03-31 [Verified]
A19: New round talks (valuation, ≥) | E19: 1200 | H19: FT/Bloomberg Sep-2026; OpenAI pushing higher [Interested-party]
A20: Note: "$840bn between now and end of 2030" admits two readings: (a) FY2026–30 (adopted); (b) from report date. Reading (b) implies an even more front-loaded path.
A22: Section B: v3 revenue path — drives OpenAI_Sim!D46:H46
A23: Metric | B23: 2026E | C23: 2027E | D23: 2028E | E23: 2029E | F23: 2030E | G23: Total 26–30 | H23: Source / Tag
A24: Revenue anchors / inputs ($B) | B24: =E6 -> 36 | C24: 75.1 | D24: 141.5 | E24: =E9-B24-C24-D24-F24 -> 237.4 | F24: =E8 -> 350 | G24: =SUM(B24:F24) -> 840 | H24: 2026/2030 = Jul deck. 2027–28 [Derived]: fitted path with linearly decelerating growth that closes $36B→$350B and Σ=$840B. 2029 = residual so Σ ties to $840B exactly.
A25: YoY growth | B25: =B24/OpenAI_Sim!C68-1 -> 1.7480916 | C25: =C24/B24-1 -> 1.0861111 | D25: =D24/C24-1 -> 0.88415446 | E25: =E24/D24-1 -> 0.67773852 | F25: =F24/E24-1 -> 0.47430497 | H25: Linked into OpenAI_Sim row 46 (2026 vs 2025A actual)
A26: v2 path (July model) for reference | B26: 32.75 | C26: 60.5875 | D26: 112.0869 | E26: 179.339 | F26: 286.9424 | G26: =SUM(B26:F26) -> 671.7058 | H26: Frozen v2 values (20260715_Tokenomics_v2 OpenAI_Sim D68:H68)
A27: v3 vs v2 | B27: =B24/B26-1 -> 0.099236641 | C27: =C24/C26-1 -> 0.23952961 | D27: =D24/D26-1 -> 0.26241336 | E27: =E24/E26-1 -> 0.32374999 | F27: =F24/F26-1 -> 0.219757 | G27: =G24/G26-1 -> 0.25054749
A28: Check: equal-growth path Σ (36→350) | G28: =SUMPRODUCT(B24*((F24/B24)^({0,1,2,3,4}/4))) -> 760.029 | H28: If Σ(equal-growth) < $840B, the deck implies a front-loaded path (faster 2027–28)
A30: Section C: Free-cash-flow bridge v3 (cash basis; replaces v2 row-86 formula for 2026–30)
A31: Line ($B) | B31: 2026E | C31: 2027E | D31: 2028E | E31: 2029E | F31: 2030E | G31: Total 26–30 | H31: Logic / Tag
A32: Lever: compute & infra total 2026–30 | B32: =E16 -> 856 | H32: Jul deck $856B [Interested-party]. Allocation across years uses row 34 key.
A33: Lever: R&D share that is compute (inside row 32) | B33: 0.6 | H33: [Assumed] range 40–80%. Prevents counting training compute twice (R&D line + compute line).
A34: Allocation key: owned CapEx path (OpenAI_Sim row 53) | B34: =OpenAI_Sim!D53 -> 40 | C34: =OpenAI_Sim!E53 -> 60 | D34: =OpenAI_Sim!F53 -> 100 | E34: =OpenAI_Sim!G53 -> 125 | F34: =OpenAI_Sim!H53 -> 150 | G34: =SUM(B34:F34) -> 475 | H34: [Assumed] v2 CapEx path = balance-sheet (owned) portion; also used as timing key for total spend
A35: Lever: partner-financed share of compute (off OAI FCF) | B35: 0 | H35: [Assumed] 0% base. >0% if partners fund build outside OpenAI cash flow; raises off-balance-sheet commitments instead.
A37: Gross revenue | B37: =OpenAI_Sim!D68 -> 36 | C37: =OpenAI_Sim!E68 -> 75.1 | D37: =OpenAI_Sim!F68 -> 141.5 | E37: =OpenAI_Sim!G68 -> 237.4 | F37: =OpenAI_Sim!H68 -> 350 | G37: =SUM(B37:F37) -> 840 | H37: OpenAI_Sim row 68 (now v3 path)
A38: Less: Microsoft revenue share | B38: =OpenAI_Sim!D69 -> -7.2 | C38: =OpenAI_Sim!E69 -> -13.1425 | D38: =OpenAI_Sim!F69 -> -21.225 | E38: =OpenAI_Sim!G69 -> -29.675 | F38: =OpenAI_Sim!H69 -> -35 | G38: =SUM(B38:F38) -> -106.2425 | H38: OpenAI_Sim row 69
A39: Compute & infra spend (total) | B39: =-$B$32*B34/$G$34 -> -72.084211 | C39: =-$B$32*C34/$G$34 -> -108.12632 | D39: =-$B$32*D34/$G$34 -> -180.21053 | E39: =-$B$32*E34/$G$34 -> -225.26316 | F39: =-$B$32*F34/$G$34 -> -270.31579 | G39: =SUM(B39:F39) -> -856 | H39: Total × timing key
A40: of which owned (balance-sheet CapEx) | B40: =-B34 -> -40 | C40: =-C34 -> -60 | D40: =-D34 -> -100 | E40: =-E34 -> -125 | F40: =-F34 -> -150 | G40: =SUM(B40:F40) -> -475 | H40: Split item 4: owned
A41: of which leased / contracted (cash opex) | B41: =B39-B40 -> -32.084211 | C41: =C39-C40 -> -48.126316 | D41: =D39-D40 -> -80.210526 | E41: =E39-E40 -> -100.26316 | F41: =F39-F40 -> -120.31579 | G41: =SUM(B41:F41) -> -381 | H41: Split item 4: leased = total − owned
A42: Add back: partner-financed portion | B42: =-B39*$B$35 -> 0 | C42: =-C39*$B$35 -> 0 | D42: =-D39*$B$35 -> 0 | E42: =-E39*$B$35 -> 0 | F42: =-F39*$B$35 -> 0 | G42: =SUM(B42:F42) -> 0 | H42: Excluded from OAI FCF
A43: R&D excl. compute (cash) | B43: =OpenAI_Sim!D76*(1-$B$33) -> -5.76 | C43: =OpenAI_Sim!E76*(1-$B$33) -> -9.012 | D43: =OpenAI_Sim!F76*(1-$B$33) -> -14.15 | E43: =OpenAI_Sim!G76*(1-$B$33) -> -18.992 | F43: =OpenAI_Sim!H76*(1-$B$33) -> -21 | G43: =SUM(B43:F43) -> -68.914 | H43: OpenAI_Sim row 76 × (1 − compute share)
A44: S&M (cash) | B44: =OpenAI_Sim!D77 -> -4.32 | C44: =OpenAI_Sim!E77 -> -7.51 | D44: =OpenAI_Sim!F77 -> -11.32 | E44: =OpenAI_Sim!G77 -> -15.431 | F44: =OpenAI_Sim!H77 -> -17.5 | G44: =SUM(B44:F44) -> -56.081 | H44: OpenAI_Sim row 77
...

Sheet Claude Log
A1: Turn # | B1: Date | C1: User Request | D1: Action Taken | E1: Details | F1: Outcome
A2: 1 | B2: 46106 | C2: Expand model with inter-rack networking (InfiniBand XDR, Spectrum-X, Ethernet) across Config, TL_Param, and WP_Param sheets to make token/revenue calculations more realistic. | D2: Added inter-rack network fabric section to Config (rows 65-85), inter-rack network analysis to WP_Param (rows 208-270), and inter-rack adjusted E2E latency section to TL_Param (rows 26-33). | E2: Config: Added NIC specs (ConnectX-8 800Gb/s), switch specs (Quantum-X800 Q3400 144-port), latency (sub-100ns/hop IB XDR), oversubscription (2:1), SHARP v4 reduction (50%), multi-rack parallelism (DP replicas, KV cache transfer for disaggregated inference). WP_Param: 3 sub-sections—DP all-reduce, KV cache transfer, decode overhead—plus combined E2E impact for colocated vs disaggregated scenarios. TL_Param: Added rows 26-33 showing network-adjusted E2E for both VR NVL72 and GB200 NVL72. | F2: Colocated inference: ~0.04% overhead (negligible). Disaggregated inference: ~24.7% throughput reduction due to KV cache transfer across racks. All values dynamically linked to Config blue-cell inputs.
A3: 2 | B3: 46106 | C3: Integrate inter-rack network overhead into each of the 6 steps of the token generation pipeline in TL_Param, just like how NVLink time is integrated. | D3: Added column M 'Inter-Rack Time' to the optimized pipeline in TL_Param. Updated Duration formulas (D17, D18, D20) to include inter-rack. Rebuilt Rack-Independent outputs (O26:P38) with inter-rack. Fixed Revenue_Model linkage. | E3: Step 1 (Tokenization): N/A. Step 2 (Embedding): +3.0E-7s (LB routing latency). Step 3 (Prefill): 0 for colocated. Step 4 (Decode-First): N/A. Step 5 (Decode-All): +0.00012s (token streaming, 80% overlapped). Step 6 (De-tokenization): N/A. Token streaming uses (1-overlap) factor from Config!B82. Cleaned up old separate inter-rack section (rows 26-33) and replaced with integrated approach. | F3: VR NVL72: 39,901 tok/s (0.008% inter-rack overhead). GB200 NVL72: 13,240 tok/s (0.002% overhead). Inter-rack is negligible for colocated inference with IB XDR. Revenue_Model auto-updates via TL_Param!O36/P36 references.
A4: 3 | B4: 46106 | C4: Add Inter-Rack Time column to the Baseline section and reposition it right next to NVLink (column I) in both Baseline and Optimized sections. | D4: Inserted column I between NVLink (H) and Bottleneck (J). Populated Inter-Rack Time for both Baseline and Optimized pipelines. Updated all Duration formulas (D4, D7, D17, D18, D20). Migrated Rack-Independent formulas (O/P) from old col N to col I. Deleted orphan column N. Verified Revenue_Model auto-shifted to O36/P36. | E4: Baseline Inter-Rack: Step 2 = 3E-7s (routing), Step 5 = 0.0006s (full streaming, no overlap since baseline has no optimizations). Optimized Inter-Rack: Step 2 = 3E-7s, Step 5 = 0.00012s (80% overlapped). Column order now: Compute | HBM BW | NVLink | Inter-Rack | Bottleneck | Dominant | FLOPs | HBM Bytes. | F4: Baseline: 777 tok/s (was 777.4 without inter-rack). Optimized: 39,901 tok/s (unchanged). Both sections now have consistent 8-resource-column layout. Revenue_Model correctly references O36/P36 for VR/GB200 E2E.
A5: 4 | B5: 46106 | C5: User asked if I23 was doing anything; confirmed it was a redundant duplicate of E23 and cleared it. | D5: Cleared TL_Param!I23 (was =1/E22, duplicate of E23). | E5: I23 was not referenced by any downstream formula. | F5: Cell cleared. No impact on model.
A6: 5 | B6: 46106 | C6: User surprised inter-rack overhead is so small. Asked for walkthrough of main reasons. | D6: Provided analysis-only explanation. No spreadsheet changes. | E6: 3 reasons: (1) 1T model fits in 1 rack (20.7TB >> 1TB), no cross-rack compute traffic. (2) IB XDR = 0.3μs one-way, 6 orders of magnitude below decode bottleneck. (3) Only last-mile routing+streaming crosses fabric. Also noted when it would matter: disaggregated (~25% hit), multi-rack TP, or Ethernet. | F6: Key numbers: Inter-rack step 5 = 0.00012s vs HBM 0.213s (710,000× gap). Model fits in rack = no TP/PP across fabric.
A7: 6 | B7: 46106 | C7: Make Bottleneck (J) and Dominant Resource (K) columns dynamic instead of hardcoded, for both Baseline and Optimized. | D7: Replaced hardcoded text with IF/MAX formulas comparing F (Compute), G (HBM), H (NVLink), I (Inter-Rack). Steps 1 & 6 remain 'CPU' (hardcoded, always CPU). Steps 2-5 use nested IF(MAX(...)) logic. | E7: Bottleneck (J): returns Compute/Memory/NVLink/Inter-Rack based on which time column is largest. Dominant (K): returns GPU/HBM BW/NVLink/Inter-Rack. Step 2 Optimized corrected from hardcoded 'NVLink' to formula-derived 'Memory/HBM BW' (HBM 1.66E-6 > NVLink 1.24E-6). | F7: All 8 formula cells verified against actual time values. Results auto-update when Config parameters change (e.g., switching to Ethernet could flip Step 2 to Inter-Rack bottleneck).
A8: 7 | B8: 46106 | C8: User asked how to stress test inter-rack overhead. Built side-by-side scenario comparison table with 5 scenarios. | D8: Created stress test table at TL_Param rows 42-68 with 6 columns: Current + 5 scenarios (Std Ethernet, Disaggregated, 16:1 Oversub, Ethernet+Disagg, All Worst-Case). Each scenario independently varies fabric latency, oversubscription, disaggregation, and overlap. | E8: All formulas are self-contained — scenario parameters feed into Step 2/3/5 overhead calculations, then into adjusted E2E, tok/s, throughput loss %, and annual revenue impact ($M) linked to Revenue_Model!B38. | F8: Results: A=0.37% loss ($169M), B=24.6% ($11.4B), C=0% ($0), D=25.2% ($11.6B), E=72.5% ($33.4B). Disaggregation is the dominant factor; Ethernet alone is minor; 16:1 oversubscription alone is negligible; combined worst-case is devastating.
A10: 9 | B10: 46106 | C10: User changed model size 1T→10T, asked why inter-rack numbers don't change | D10: Traced formula chain from TL_Param I7/I20 → WP_Param B235 → Config B77; diagnosed root cause | E10: Inter-rack formulas depend on network latency × output_tokens, NOT model size. Model size affects compute/HBM but not token streaming overhead. DP all-reduce (WP_Param B221-B228) DOES scale with model size but isn't wired into pipeline steps. | F10: Explained to user; offered to add model-size-dependent inter-rack component (DP all-reduce) into pipeline
A11: 10 | B11: 46106 | C11: d_ff goes negative when model size increases from 1E12 to 1E13 | D11: Replaced d_model and n_layers with auto-scaling formulas; fixed circular ref in n_heads/d_head | E11: Root cause: d_model formula scaled linearly with P (10× params → 10× d), causing 4d² to exceed P/n_layers. Fix: n_layers = (P/(12×160²))^(1/3), d_model = MROUND(160×n_layers, 128). d_head fixed at 128. B34-B36 changed from blue (input) to black (formula). Verified at 1E12 and 1E13. | F11: All model specs now auto-scale correctly: 1E12→(n=148,d=23680), 1E13→(n=319,d=51072), d_ff positive at all sizes. B31 restored to 1E12.
A12: 11 | B12: 46106 | C12: At 1E14, model exceeds 1 rack memory but inter-rack numbers don't change | D12: Built multi-rack TP section (WP_Param B272:C297); rewired TL_Param I4:I20 to use model-size-aware inter-rack formulas; fixed D5 missing +I5 | E12: When B43<0 (model won't fit), auto-computes racks needed for TP, cross-rack activation transfer per layer (decode + prefill), total overhead. At 1E14: 5 racks needed, prefill adds 1.68s inter-rack, decode adds 0.42s (baseline) / 0.08s (optimized). At 1E12: all multi-rack terms =0 (model fits in 1 rack). Bottleneck column now shows 'Inter-Rack' for Step 3 prefill at 1E14. | F12: Model is now fully model-size-aware for inter-rack. B31 left at 1E14 per user's testing.
A13: 12 | B13: 46106 | C13: User asked if it's common for advanced models not to fit in one rack | D13: Provided industry context: MoE architectures, NVLink domain scaling (NVL72→NVL576), quantization (FP4), and multi-rack TP reality | E13: Explained that dense >20T models exceed NVL72 rack capacity (20.7 TB HBM). Industry uses MoE (sparse activation), larger NVLink domains (Rubin Ultra NVL576 ~150+ TB), and FP4 quantization. Mentioned GPT-5, Claude Opus, Gemini Ultra as likely multi-rack models. Noted user's 1E14 model is realistic for 2027-2028 era. | F13: Q&A turn — no spreadsheet modifications. User's model at 1E14 correctly shows inter-rack as prefill bottleneck.
A14: 13 | B14: 46106 | C14: User challenged: 10T model fits in rack, why is multi-rack common? | D14: Explained production reality: KV cache × batch_size is the real memory pressure, not just weights. Offered to extend B42/B43 to include batch-aware KV cache. | E14: Current B42 = weight/GPU + KV_end/GPU for 1 request. In production with batch=64 concurrent requests, KV cache alone can be 10+ TB for a 10T model at 5K context. Long-context (1M tokens) makes it worse. Also noted latency SLA reasons for multi-rack TP. User's model only accounts for single-request KV. | F14: Q&A — offered to make memory headroom batch-aware. Awaiting user decision.
... A33: 33 | B33: 46287 | C33: 以主流前沿模型 (Sep 2026) 更新 Config / TL_Param / WP_Param。 | D33: Config: 新增前沿模型預設表 J26:Q55 (DeepSeek V4-Pro、Kimi K3、DeepSeek V4-Flash、閉源前沿代理[Assumed]、舊 1T Dense), B29 選單; B31–B48/B55/B87 改由預設驅動; 定價層級改為 Sep-2026 六層並以 F41 選單選擇; 輸入/輸出 16K/1K; MFU 0.35; 推測解碼 N=5; F71/F72 改 CX-9; 修正 B32:B36 資料驗證範圍。WP: 注意力 FLOPs/參數泛化 (heads×head_dim、稀疏/壓縮注意力跨度)、KV 改架構實際 (MLA/CSA/HCA/GQA) 並計 KV bytes、批次解碼權重讀取改 MoE 命中機率、B46 TP 連結錯誤修正、B143 啟動值位元組。TL: F20 解碼運算乘上批次與推測驗證、除以 MFU。 | E33: 預設 V4-Pro + Frontier (closed) 定價: VR 機櫃 105K output tok/s, 1GW 年營收 $1.28T (v3: 34.9K tok/s, $80.8B)。主因: 49B active vs 1T dense、FP4、壓縮 KV、定價 $5/$25。Legacy 預設在新工作負載下為 7.5K tok/s。 | F33: 重算後公式零新錯誤。Revenue_Model 未納入 prompt caching 折價 — 營收為上限值。詳 Audit_Report 第 97 列起。

Sheet Audit_Report
A1: Workbook Formula, Linkage & Dynamic-Response Audit
A3: Audit date | B3: 46218
A4: Workbook | B4: 20260715_Tokenomics_inter-rack_energy.xlsx
A5: Scope | B5: All 7 original worksheets; formulas, cross-sheet links, recalculation errors, and parameter sensitivity.
A7: Executive conclusion | B7: 2026-07-15 複核版: 全簿 1,805 個公式重算零錯誤; 8 項參數敏感度實測全數連動。本次複核另發現並修正 4 項重大語意缺陷 (GQA KV 傳輸、營收衝擊基底、2027-2030 I/O 拆分、DC VR 專區下拉依賴) 及 2 項動態性缺陷 (all-reduce 數硬編 256、Overhead% 漏項)。詳見第 58 列起之複核修正表與未結事項。
A9: Worksheet | B9: Role | C9: Formula cells | D9: Cross-sheet formulas | E9: Recalc status | F9: Dynamic status | G9: Risk | H9: Key conclusion
A10: Claude Log | B10: Change log | C10: 0 | D10: 0 | E10: Pass | F10: N/A | G10: Low | H10: Narrative log only; no calculation role.
A11: Config | B11: Inputs & presets | C11: 56 | D11: 0 | E11: Pass | F11: Pass after fix | G11: Medium | H11: Rack/model/network controls feed downstream sheets. MoE active-parameter formula corrected.
A12: TL_Param | B12: Pipeline latency | C12: 193 | D12: 82 | E12: Pass after fix | F12: Pass after fix | G12: High | H12: Three optimized duration formulas now respect changing bottlenecks; stress-test base no longer double-counts current network overhead.
A13: WP_Param | B13: Workload mechanics | C13: 211 | D13: 67 | E13: Pass after fix | F13: Pass after fix | G13: High | H13: Network comparison no longer double-counts integrated routing/streaming terms.
A14: DC_Cost_Model | B14: CapEx/OpEx | C14: 236 | D14: 14 | E14: Pass | F14: Pass | G14: Medium | H14: Derived totals are formula-driven; unit-cost and operating assumptions are intentionally hardcoded inputs.
A15: Revenue_Model | B15: Throughput/revenue | C15: 60 | D15: 20 | E15: Pass | F15: Pass | G15: Medium | H15: VR and GB200 sections link to independent latency/rack outputs; utilization and uptime are explicit assumptions.
A16: OpenAI_Sim | B16: Financial scenarios | C16: 1049 | D16: 39 | E16: Pass after fix | F16: Partial by design | G16: High | H16: 2030 valuation multiple error corrected. Forecast assumptions and segment scenarios intentionally contain many hardcoded controls.
A19: Corrections applied
A20: Sheet | B20: Cell | C20: Previous formula/value | D20: Corrected formula/value | E20: Reason
A21: TL_Param | B21: D18 | C21: '=F18+H18+I18 | D21: '=MAX(F18,G18)+H18+I18 | E21: Optimized prefill duration omitted HBM time when HBM becomes slower than compute.
A22: TL_Param | B22: D19 | C22: '=G19 | D22: '=MAX(F19,G19) | E22: Optimized first-token duration was hard-linked to HBM only and ignored a possible compute bottleneck.
A23: TL_Param | B23: D20 | C23: '=G20+H20+I20 | D23: '=MAX(F20,G20)+H20+I20 | E23: Optimized decode-all duration omitted compute time when compute becomes slower than HBM.
A24: OpenAI_Sim | B24: B21 | C24: '=840/F5 | D24: '=840/H5 | E24: 2030 valuation multiple referenced blank F5 instead of 2030 target in H5, causing #DIV/0!.
A25: Config | B25: B36 | C25: '=IF(B32="Dense",B31,B31*B35) | D25: '=IF(B32="Dense",B31,B39*(B43+B44*B35)) | E25: MoE active parameters must retain shared attention parameters and scale only expert FFN parameters.
A26: Config | B26: C36 | C26: Dense=total, MoE=total×ratio | D26: Dense=total; MoE=n_layers×(attention + FFN×active/total) | E26: Clarified corrected MoE active-parameter definition.
A27: TL_Param | B27: C62 | C27: '=C38 | D27: '=C38-SUM(I17,I18,I20) | E27: Intra-rack base must exclude inter-rack overhead already integrated into C38 before scenario overhead is added.
A28: WP_Param | B28: B240 | C28: '=TL_Param!E21 | D28: '=TL_Param!E21-SUM(TL_Param!I17,TL_Param!I18,TL_Param!I20) | E28: Base latency should exclude integrated network terms.
A29: WP_Param | B29: C240 | C29: From TL_Param (now includes inter-rack in steps 2,5) | D29: TL optimized E2E less integrated inter-rack terms | E29: Updated description to match formula.
A30: WP_Param | B30: A241 | C30: Load Balancer + Return Overhead (s) | D30: Load Balancer Routing Overhead (s) | E30: Clarified that only one-way routing is added here.
A31: WP_Param | B31: B241 | C31: '=B233+B234 | D31: '=B233 | E31: Use the same one-way routing term integrated in TL_Param.
... A40: WP_Param | B40: C16 | C40: 50/GPU | D40: 16 PFLOPS/GPU | E40: Corrected stale note after FP8 rack performance audit.
A42: Dynamic-response tests
A43: Control changed | B43: Baseline | C43: Test value | D43: Observed downstream response | E43: Result
