Workbook

Sheet 0_說明
B1: L 閱讀版（Tokenomics v21.3）
B2: 建立：2026-10-20，chat 端（Claude）；2026-10-24 換版到 Tokenomics v21.3（見修訂紀錄）。用途：讓 Andy 直觀理解 L（壽命期價格係數）與回本判讀怎麼推出來。核對範圍：tools/reading_workbooks/check_reading.py 對 Tokenomics v21.3 逐項檢查——2_輸入 第 6–34 列全部藍字輸入、1_公式樹 G 欄全部「Tokenomics 原值」（含區間文字）與三態判讀、3_L逐世代 情境摘要與各世代 L_rel、所需 L 與持有成本、錯誤值與差異欄；另經未參與製作的代理獨立核對（2026-10-24，不符 0）。1_公式樹 的推導說明文字與 4_必須為真 的格點結果不在逐格核對範圍內（格點由本簿公式重算）。本簿是版本快照，不隨 Tokenomics 自動同步。
B4: 分頁
B5: 1_公式樹：從回本條件出發，逐層拆到所需 L、L 的四個需求面前提、L 的逐步組成（跌價→降級→折現→世代起點）、世代加權、三段拆分、閉式解、必須為真、需求角度的開放問題。建議先讀這頁。 1_公式樹 末段 L9 是舊主口徑（只含推論）所需 L 的對照。
B6: 2_輸入：全部輸入（藍字，基準／低端組合／高端組合）。黃底＝Assumed。
B7: 3_L逐世代：每個情境 × 世代一列，把價格路徑的積分拆成三段；情境摘要對照 Tokenomics v21.3 原值。
B8: 4_必須為真：g、ρ、T1 的格點（每一格完整重算），內插出損益兩平值。
B10: 顏色
B11: 藍字＝輸入；黑字＝公式；綠字＝連結其他分頁；黃底＝Assumed；淺綠底＝主要結果；淡黃底＝重點判讀。
B13: 範圍與限制
B14: 1. 基準模型 v21.3 已合併（master aa17328，model/20261024_Tokenomics_v21.3.xlsx）。
B15: 2. 每 GW 年付費營收（世代權重的一部分）由 m 的計算鏈產生，本簿以值輸入，改 m 的輸入不會連動到這裡。
... B20: 修訂紀錄：v21.2 r0（2026-10-24）：L 輸入對 Tokenomics v21.2 更新——ρ 低端 0.1704→0.2007（v19.1）；四個世代每 GW 年付費營收（v19.1）：Hopper 4.633→4.698、GB200 22.800→23.116、GB300 27.810→28.173、VR200 45.733→46.415；計價倍數 0.85（0.73–1.17）→1.8（0.85–2.3）（v21.2，只影響舊口徑對照）。所需 L 主口徑改 L1_LReqFleet_Full（0.807，0.716–0.895；2_輸入新增 E 節 IN_Hold），L1_LReqFleet_IdNoK 改對照（L9；0.756→0.357）。（輸入由 72 格增為 75 格：新增 IN_Hold 基準／低／高。）
A21: 修訂紀錄：v21.3 r0（2026-10-24）：L 輸入對 Tokenomics v21.3 更新——ρ 低端 0.2007→0.2057（v21.3 機架價低端 7.8→7.5 連動）；3_L逐世代 情境摘要原值 L1_LTotalFleetVDisc_Lo 0.4785→0.4794。其他 24 列輸入、所需 L 與基準值不變。另修 2_輸入 I12、1_公式樹 E63 兩句說明的 ρ 低端。check_reading.py 通過；經未參與製作的代理獨立核對。

Sheet 1_公式樹
A1: L 的公式樹：機隊能不能靠營收回收自己的持有成本
A2: 讀法：由上往下，每一層把上一層的一個量拆開。全部是公式，連到 2_輸入（藍字）與 3_L逐世代。G 欄＝Tokenomics v21.3 原值（貼上），H 欄＝差異。
A3: L＝硬體壽命期內，同一批 GPU 每年能收到的營收，平均是 2025 年的幾倍（只讓價格變、量固定）。所需 L＝年持有成本 ÷ 2025 營收。
A5: 層 | B5: 項目 | C5: 值 | D5: 單位 | E5: 怎麼算（白話＋公式） | F5: 標記 | G5: Tokenomics 原值 | H5: 差異
A6: L0 | B6: 回本條件：壽命期內平均年營收 ≥ 年持有成本
B7: L（機隊；世代起點＋折現） | C7: =LS_L -> 0.75859737 | D7: 倍 | E7: L 側：由 L3–L5 推出（Tokenomics L1_LTotalFleetVDisc）；回本判讀的 L | F7: Derived | G7: 0.75859737 | H7: =IF(ISNUMBER(C7),IF(G7=0,C7-G7,C7/G7-1),"—") -> 0
B8: 所需 L（主口徑：全部算力持有成本） | C8: =IN_Hold/IN_Rev -> 0.80707823 | D8: 倍 | E8: 由 L1 推出（Tokenomics L1_LReqFleet_Full）。v20.0 起的現行主口徑；舊口徑（只含推論、經計價倍數）改為對照，見 L9 | F8: Derived | G8: 0.80707823 | H8: =IF(ISNUMBER(C8),IF(G8=0,C8-G8,C8/G8-1),"—") -> 0
B9: L ÷ 所需 L | C9: =C7/C8 -> 0.9399304 | D9: 倍 | E9: ≥1＝基準下回本；＜1＝基準下未回本。最後判讀看區間（C14），不只看基準。Tokenomics 無此比值格，所以 G 欄留空 | F9: Derived
B10: 換成金額：壽命期平均年營收 | C10: =IN_Rev*C7 -> 9.9148676 | D10: $B/年 | E10: ＝2025 營收 × L | F10: Derived
B11: 年持有成本（全部算力機隊） | C11: =IN_Hold -> 10.548512 | D11: $B/年 | E11: ＝平均上線 GW × 機隊每 GW 年持有成本（Tokenomics L1_HoldFleet25）；不只服務推論 | F11: Derived | G11: 10.548512 | H11: =IF(ISNUMBER(C11),IF(G11=0,C11-G11,C11/G11-1),"—") -> 0
B12: L 區間（低端組合／高端組合） | C12: =TEXT(LS_L_Lo,"0.000")&"–"&TEXT(LS_L_Hi,"0.000") -> 0.479–1.138 | E12: 端點組合（同一組低值一起用；見 2_輸入） | F12: Derived | G12: 0.479–1.138 | H12: =IF(C12=G12,0,"不同") -> 0
B13: 所需 L 區間 | C13: =TEXT(IN_Hold_Lo/IN_Rev,"0.000")&"–"&TEXT(IN_Hold_Hi/IN_Rev,"0.000") -> 0.716–0.895 | E13: 低端＝GW 1.0 的全部算力持有成本 ÷ 營收；高端＝GW 1.25 的持有成本 ÷ 營收 | F13: Derived | G13: 0.716–0.895 | H13: =IF(C13=G13,0,"不同") -> 0
B14: 判讀（三態） | C14: =IF(AND(ISNUMBER(LS_L),ISNUMBER(LS_L_Lo),ISNUMBER(LS_L_Hi)),IF(LS_L_Hi<IN_Hold_Lo/IN_Rev,"未回本（L 區間全在所需 L 之下）",IF(LS_L_Lo>IN_Hold_Hi/IN_Rev,"回本（L 區間全在所需 L 之上）","未定（區間重疊；基準 L "&TEXT(LS_L,"0.000")&" 對所需 L "&TEXT(LQ,"0.000")&"）")),"所需 L 或 L 非數字（本情境）") -> 未定（區間重疊；基準 L 0.759 對所需 L 0.807） | E14: 三態規則同 Tokenomics Cap_In C242：L 區間上端＜所需 L 區間下端＝未回本；L 區間下端＞所需 L 區間上端＝回本；其餘＝未定 | F14: Derived | G14: 未定（區間重疊；基準 L 0.759 對所需 L 0.807） | H14: =IF(C14=G14,0,"不同") -> 0
A16: L1 | B16: 所需 L（主口徑）：2025 每 1 元營收要養多少「全部算力」持有成本
B17: 全部算力年持有成本 | C17: =IN_Hold -> 10.548512 | D17: $B/年 | E17: ＝平均上線 GW × 機隊每 GW 年持有成本（Tokenomics L1_HoldFleet25）。v20.0 起不只含服務推論，是全部算力 | F17: Derived | G17: 10.548512 | H17: =IF(ISNUMBER(C17),IF(G17=0,C17-G17,C17/G17-1),"—") -> 0
B18: 2025 營收 | C18: =IN_Rev -> 13.07 | D18: $B | F18: Verified | G18: 13.07 | H18: =IF(ISNUMBER(C18),IF(G18=0,C18-G18,C18/G18-1),"—") -> 0
B19: → 所需 L | C19: =IN_Hold/IN_Rev -> 0.80707823 | D19: 倍 | E19: 營收可以平均衰減到 2025 年的這個比例仍打平。不含計價倍數與 κ，因為成本已經是持有成本（Tokenomics L1_LReqFleet_Full） | F19: Derived | G19: 0.80707823 | H19: =IF(ISNUMBER(C19),IF(G19=0,C19-G19,C19/G19-1),"—") -> 0
B20: 所需 L 低端（GW 1.0） | C20: =IN_Hold_Lo/IN_Rev -> 0.71561734 | D20: 倍 | E20: 全部算力持有成本取 GW 1.0 的端點 | F20: Derived | G20: 0.71561734 | H20: =IF(ISNUMBER(C20),IF(G20=0,C20-G20,C20/G20-1),"—") -> 0
B21: 所需 L 高端（GW 1.25） | C21: =IN_Hold_Hi/IN_Rev -> 0.89452167 | D21: 倍 | E21: 全部算力持有成本取 GW 1.25 的端點 | F21: Derived | G21: 0.89452167 | H21: =IF(ISNUMBER(C21),IF(G21=0,C21-G21,C21/G21-1),"—") -> 0
A23: L2 | B23: L 對需求面隱含的四個假設（不是計算，是讀 L 時要記得的前提）
B24: ① 量固定：機隊每年都被需求吃滿，營收只隨單價變 | F24: Assumed（結構）
B25: ② 單價沿中階 token 牌價走：每年變化 g（基準 −9%） | F25: Derived
B26: ③ 降級：服務 T1 年後，需求移往新模型，舊硬體改賣低階 token，價值剩 ρ 倍 | F26: Assumed／Derived
B27: ④ 全部營收都跟 token 牌價走，包括約八成的訂閱與席次營收（見 L8） | F27: Assumed（結構）
A29: L3 | B29: L 怎麼一步步算出來（每一步只加一個效果）
B30: S1 只有跌價：2025 當第 0 年、不降級、不折現 | C30: =LS_L_price -> 0.76366528 | D30: 倍 | E30: L_price＝[(1+g)^T − 1] ÷ [T × ln(1+g)]。牌價每年 −9%，6 年平均剩 76% | F30: Derived | G30: 0.76366528 | H30: =IF(ISNUMBER(C30),IF(G30=0,C30-G30,C30/G30-1),"—") -> 0
B31: S2 ＋降級 | C31: =LS_L_total -> 0.65950567 | D31: 倍 | E31: 第 T1＝4 年後價值剩 ρ＝0.5 倍 → 再打折 | F31: Derived | G31: 0.65950567 | H31: =IF(ISNUMBER(C31),IF(G31=0,C31-G31,C31/G31-1),"—") -> 0
B32: 降級的影響 | C32: =C31-C30 -> -0.10415961 | D32: 倍 | E32: 負值＝降級拉低 L | F32: Derived
B33: S3 ＋折現 | C33: =LS_L_disc -> 0.69884453 | D33: 倍 | E33: 持有成本是 WACC 10% 的年金（早年的錢比較值錢）；L 用同口徑折現後，早年的高價權重變大 | F33: Derived | G33: 0.69884453 | H33: =IF(ISNUMBER(C33),IF(G33=0,C33-G33,C33/G33-1),"—") -> 0
B34: 折現的影響 | C34: =C33-C31 -> 0.039338853 | D34: 倍 | F34: Derived
B35: S4 ＋世代起點（＝L，主口徑） | C35: =LS_L -> 0.75859737 | D35: 倍 | E35: 每個世代從自己的服務起點算：Hopper 在 2025 年中已服務 2 年，之前賣的是更高的價格 | F35: Derived | G35: 0.75859737 | H35: =IF(ISNUMBER(C35),IF(G35=0,C35-G35,C35/G35-1),"—") -> 0
B36: 世代起點的影響 | C36: =C35-C33 -> 0.059752841 | D36: 倍 | F36: Derived
B37: 對照：世代起點、不折現（v16.0 口徑） | C37: =LS_L_v16 -> 0.71589495 | D37: 倍 | E37: 換個順序看：先加世代起點（0.660→0.716），再加折現（→0.759）。效果有交互作用，拆分大小與順序有關 | F37: Derived | G37: 0.71589495 | H37: =IF(ISNUMBER(C37),IF(G37=0,C37-G37,C37/G37-1),"—") -> 0
A39: L4 | B39: 機隊 L＝各世代 L 以 2025 營收加權
B40: Hopper：2025 營收權重 | C40: =3_L逐世代!R28/SUM(3_L逐世代!R28:R31) -> 0.2336333 | D40: % | E40: ＝60% × 每 GW 營收 47.0 億 | F40: Derived
B41: Hopper：錨點時已服務年數 t0 | C41: =3_L逐世代!C28 -> 2 | D41: 年 | E41: ＝MAX(0, 2025.5 − 服務起點) | F41: Derived
B42: Hopper：L_rel | C42: =3_L逐世代!Q28 -> 0.84391321 | D42: 倍 | E42: 該世代壽命期平均價格 ÷ 錨點價格（折現）（Tokenomics Cap_In!C322） | F42: Derived | G42: 0.84391321 | H42: =IF(ISNUMBER(C42),IF(G42=0,C42-G42,C42/G42-1),"—") -> 0
B43: GB200：2025 營收權重 | C43: =3_L逐世代!R29/SUM(3_L逐世代!R28:R31) -> 0.7663667 | D43: % | E43: ＝服務 GW 占比 × 每 GW 營收。GB200 每 GW 營收約為 Hopper 的 4.9 倍，所以 GW 只占 40% 卻占營收權重約 77% | F43: Derived
B44: GB200：錨點時已服務年數 t0 | C44: =3_L逐世代!C29 -> 0.5 | D44: 年 | E44: ＝MAX(0, 2025.5 − 服務起點) | F44: Derived
B45: GB200：L_rel | C45: =3_L逐世代!Q29 -> 0.73258812 | D45: 倍 | E45: 該世代壽命期平均價格 ÷ 錨點價格（折現）（Tokenomics Cap_In!D322） | F45: Derived | G45: 0.73258812 | H45: =IF(ISNUMBER(C45),IF(G45=0,C45-G45,C45/G45-1),"—") -> 0
...

Sheet 2_輸入
A1: L 推導的全部輸入（藍字可改）。值取自 Tokenomics v21.3（model/20261024_Tokenomics_v21.3.xlsx，master aa17328）。
A2: 「低端組合」「高端組合」＝Tokenomics 用來算 L 與所需 L 區間端點的那一組值（同一欄的值一起用，不是各自的區間）。
A4: ID | B4: 項目 | C4: 基準 | D4: 低端組合 | E4: 高端組合 | F4: 單位 | G4: 標記 | H4: Tokenomics v21.3 位置 | I4: 說明
A5: A. 2025 營收與成本（決定所需 L）
A6: IN_Rev | B6: OpenAI 2025 營收 | C6: 13.07 | D6: 13.07 | E6: 13.07 | F6: $B | G6: Verified（查核財報） | H6: SRC_Demand!C11 | I6: SRC_DEM_007；三欄同值
A7: IN_Spend | B7: OpenAI 2025 推論支出 | C7: 8.4 | D7: 7.5 | E7: 8.8 | F7: $B | G7: Interested-party | H7: SRC_Demand!C8:E8 | I7: SRC_DEM_004；OpenAI 投資人資料（經 The Information）
A8: IN_SB | B8: 計價倍數（推論支出 ÷ 經濟持有成本） | C8: 1.8 | D8: 2.3 | E8: 0.85 | F8: 倍 | G8: Derived | H8: Alloc_In!C23:E23（低端組合／高端組合欄與 Tokenomics 欄序相反：此處依 L 端點組合排列） | I8: 所需 L 低端用 2.3、高端用 0.85（倍數越大，同樣支出代表的持有成本越小）。v21.2 由 0.85（0.73–1.17）改為 1.8（0.85–2.3）；本簿只用於「舊口徑對照」（1_公式樹 L9）
A9: B. 價格路徑（決定 L）
A10: IN_g | B10: 中階 token 牌價年變化率 g | C10: -0.09 | D10: -0.2 | E10: 0.05 | F10: %/年 | G10: Derived | H10: Cap_In!C226:E226 | I10: 牌價序列迴歸（等級 3，待一手確認）
A11: IN_T1 | B11: 降級前服務中階的年數 T1 | C11: 4 | D11: 3 | E11: 5 | F11: 年 | G11: Assumed | H11: Cap_In!C227:E227 | I11: 硬體所服務層級的更替
A12: IN_rho | B12: 降級後價值比 ρ | C12: 0.5 | D12: 0.20572251 | E12: 0.7 | F12: 倍 | G12: Derived（兩種讀法） | H12: Cap_In!C228:E228 | I12: 低端＝低階單價 ÷ 中階單價 × 低階每 GPU 吞吐倍數（原為公式，此處以值輸入）。v19.1 起低端由 0.1704 改為 0.2007；v21.3 起 0.2057（機架價低端 7.8→7.5 連動低階吞吐成本比）
A13: IN_T | B13: 硬體壽命 T | C13: 6 | D13: 6 | E13: 6 | F13: 年 | G13: Derived | H13: Cap_In!C229:E229 | I13: ＝IT 折舊年限
A14: IN_gpre | B14: 錨點前中階牌價年變化率 g_pre | C14: -0.09 | D14: -0.09 | E14: -0.3 | F14: %/年 | G14: Assumed | H14: Cap_In!C304:E304（低端組合／高端組合欄與 Tokenomics 欄序相反：此處依 L 端點組合排列） | I14: 2025 年以前的跌價速度；低端組合用 −0.09、高端組合用 −0.30（跌得越快，早年價格越高）
A15: IN_WACC | B15: 折現率 WACC | C15: 0.1 | D15: 0.08 | E15: 0.13 | F15: %/年 | G15: Assumed | H15: Inputs!E28／D28／F28 | I15: 與持有成本年金同口徑
A16: IN_A | B16: 校準錨點年 A（2025 營收與支出的年中） | C16: 2025.5 | D16: 2025.5 | E16: 2025.5 | F16: 年 | G16: Decision | H16: Cap_In!C303
A17: C. 機隊世代（決定機隊 L 的加權）
A18: IN_sv_H | B18: 世代服務起點 s_v：Hopper | C18: 2023.5 | D18: 2024 | E18: 2023 | F18: 年 | G18: Assumed | H18: Cap_In!C300:C302（低端組合／高端組合欄與 Tokenomics 欄序相反：此處依 L 端點組合排列） | I18: 低端組合取較晚（已服務年數少）、高端組合取較早
A19: IN_sv_G | B19: 世代服務起點 s_v：GB200 | C19: 2025 | D19: 2025.5 | E19: 2025 | F19: 年 | G19: Assumed | H19: Cap_In!D300:D302（低端組合／高端組合欄與 Tokenomics 欄序相反：此處依 L 端點組合排列）
A20: IN_sv_3 | B20: 世代服務起點 s_v：GB300 | C20: 2025.5 | D20: 2025.6 | E20: 2025.5 | F20: 年 | G20: Assumed | H20: Cap_In!E300:E302（低端組合／高端組合欄與 Tokenomics 欄序相反：此處依 L 端點組合排列） | I20: 2025 服務占比 0
A21: IN_sv_V | B21: 世代服務起點 s_v：VR200 | C21: 2026.75 | D21: 2027 | E21: 2026.75 | F21: 年 | G21: Assumed | H21: Cap_In!F300:F302（低端組合／高端組合欄與 Tokenomics 欄序相反：此處依 L 端點組合排列） | I21: 2025 服務占比 0
A22: IN_sh_H | B22: 2025 服務 GW 占比：Hopper | C22: 0.6 | D22: 0.6 | E22: 0.6 | F22: % | G22: Assumed | H22: Alloc!C18（AL_ShareGen） | I22: 三欄同值
A23: IN_sh_G | B23: 2025 服務 GW 占比：GB200 | C23: 0.4 | D23: 0.4 | E23: 0.4 | F23: % | G23: Assumed | H23: Alloc!D18
A24: IN_sh_3 | B24: 2025 服務 GW 占比：GB300 | C24: 0 | D24: 0 | E24: 0 | F24: % | G24: — | H24: Alloc!E18
A25: IN_sh_V | B25: 2025 服務 GW 占比：VR200 | C25: 0 | D25: 0 | E25: 0 | F25: % | G25: — | H25: Alloc!F18
A26: IN_rg_H | B26: 每 GW 年付費營收（2025 單價）：Hopper | C26: 4.6981425 | D26: 4.6981425 | E26: 4.6981425 | F26: $B/(GW·年) | G26: Derived（貼上值） | H26: Alloc!C153（AL_RevGW25） | I26: 由 m 的計算鏈產生（機隊每 GW 營收 × 實收 ÷ 牌價）；本簿以值輸入。v19.1 起四個世代的值都改變（Hopper 原 4.633、GB200 原 22.800、GB300 原 27.810、VR200 原 45.733）
A27: IN_rg_G | B27: 每 GW 年付費營收（2025 單價）：GB200 | C27: 23.116354 | D27: 23.116354 | E27: 23.116354 | F27: $B/(GW·年) | G27: Derived（貼上值） | H27: Alloc!D153
A28: IN_rg_3 | B28: 每 GW 年付費營收（2025 單價）：GB300 | C28: 28.172983 | D28: 28.172983 | E28: 28.172983 | F28: $B/(GW·年) | G28: Derived（貼上值） | H28: Alloc!E153
A29: IN_rg_V | B29: 每 GW 年付費營收（2025 單價）：VR200 | C29: 46.414791 | D29: 46.414791 | E29: 46.414791 | F29: $B/(GW·年) | G29: Derived（貼上值） | H29: Alloc!F153
A30: D. 營收結構（只用於 1_公式樹 L8 的需求角度問題；Tokenomics 的 L 不用）
A31: IN_SubShare | B31: 消費訂閱占 2025 營收 | C31: 0.7 | D31: 0.61208875 | E31: 0.82 | F31: % | G31: Derived（N10；OpenAI 自述約 70%） | H31: Cap_In!C70 | I31: OpenAI 自述約值
A32: IN_SeatShare | B32: 商用席次占 2025 營收 | C32: 0.1 | D32: 0.05 | E32: 0.15 | F32: % | G32: Assumed | H32: Cap_In!C131
A33: E. 全部算力年持有成本（決定主口徑所需 L；v20.0 起）
A34: IN_Hold | B34: 2025 全部算力年持有成本（平均上線 GW × 機隊每 GW 年持有成本） | C34: 10.548512 | D34: 9.3531186 | E34: 11.691398 | F34: $B/年 | G34: Derived（貼上值） | H34: L1!D137:F137（L1_HoldFleet25；Cap_In!C336:E336） | I34: 低端＝GW 1.0 × 每 GW 持有成本；高端＝GW 1.25 × 每 GW 持有成本（持有成本取基準，只隨 GW 端點）。全部算力，不只服務推論；本簿以值輸入，所需 L＝本列 ÷ IN_Rev

Sheet 3_L逐世代
A1: L 的逐世代計算：每一列＝一個情境下的一個世代。價格路徑以錨點（2025 年中）為 1；積分拆成三段後除以分母。全部公式。
A2: 段 1＝錨點前已經賣過的高價期（只有 t0>0 的世代有）；段 2＝錨點後、降級前，賣中階 token；段 3＝降級後，價值為中階的 ρ 倍。折現率＝0 表示不折現。
A4: 情境摘要（機隊 L＝Σ w × L_rel ÷ Σ w）
A5: 情境 | B5: 名稱 | C5: 機隊 L | D5: Tokenomics v21.3 原值 | E5: 差異 | F5: Tokenomics 名稱
A6: S1 只有跌價（2025＝第 0 年、不降級、不折現） | B6: L_price | C6: =IF(SUMPRODUCT(ISTEXT(Q16:Q19)*(R16:R19>0))>0,"含 t0>T1 的世代",SUMPRODUCT(R16:R19,Q16:Q19)/SUM(R16:R19)) -> 0.76366528 | D6: 0.76366528 | E6: =IF(ISNUMBER(C6),C6/D6-1,"—") -> 0 | F6: L1_LPrice
A7: S2 ＋降級 | B7: L_total | C7: =IF(SUMPRODUCT(ISTEXT(Q20:Q23)*(R20:R23>0))>0,"含 t0>T1 的世代",SUMPRODUCT(R20:R23,Q20:Q23)/SUM(R20:R23)) -> 0.65950567 | D7: 0.65950567 | E7: =IF(ISNUMBER(C7),C7/D7-1,"—") -> 0 | F7: L1_LTotal
A8: S3 ＋折現 | B8: L_disc | C8: =IF(SUMPRODUCT(ISTEXT(Q24:Q27)*(R24:R27>0))>0,"含 t0>T1 的世代",SUMPRODUCT(R24:R27,Q24:Q27)/SUM(R24:R27)) -> 0.69884453 | D8: 0.69884453 | E8: =IF(ISNUMBER(C8),C8/D8-1,"—") -> 0 | F8: L1_LTotalDisc
A9: S4 ＋世代起點（主口徑） | B9: L | C9: =IF(SUMPRODUCT(ISTEXT(Q28:Q31)*(R28:R31>0))>0,"含 t0>T1 的世代",SUMPRODUCT(R28:R31,Q28:Q31)/SUM(R28:R31)) -> 0.75859737 | D9: 0.75859737 | E9: =IF(ISNUMBER(C9),C9/D9-1,"—") -> 0 | F9: L1_LTotalFleetVDisc
A10: S5 對照：世代起點、不折現（v16.0 口徑） | B10: L_v16 | C10: =IF(SUMPRODUCT(ISTEXT(Q32:Q35)*(R32:R35>0))>0,"含 t0>T1 的世代",SUMPRODUCT(R32:R35,Q32:Q35)/SUM(R32:R35)) -> 0.71589495 | D10: 0.71589495 | E10: =IF(ISNUMBER(C10),C10/D10-1,"—") -> 0 | F10: L1_LTotalFleetV
A11: S6 低端組合 | B11: L_Lo | C11: =IF(SUMPRODUCT(ISTEXT(Q36:Q39)*(R36:R39>0))>0,"含 t0>T1 的世代",SUMPRODUCT(R36:R39,Q36:Q39)/SUM(R36:R39)) -> 0.47944189 | D11: 0.47944189 | E11: =IF(ISNUMBER(C11),C11/D11-1,"—") -> 0 | F11: L1_LTotalFleetVDisc_Lo
A12: S7 高端組合 | B12: L_Hi | C12: =IF(SUMPRODUCT(ISTEXT(Q40:Q43)*(R40:R43>0))>0,"含 t0>T1 的世代",SUMPRODUCT(R40:R43,Q40:Q43)/SUM(R40:R43)) -> 1.1382722 | D12: 1.1382722 | E12: =IF(ISNUMBER(C12),C12/D12-1,"—") -> 3.5527137e-15 | F12: L1_LTotalFleetVDisc_Hi
A15: 情境 | B15: 世代 | C15: t0（錨點時已服務年數） | D15: g | E15: g_pre | F15: T1 | G15: ρ | H15: T | I15: 折現率 | J15: k＝ln(1+g) | K15: k_pre＝ln(1+g_pre) | L15: δ＝ln(1+折現率) | M15: 段 1：錨點前 | N15: 段 2：中階服務 | O15: 段 3：降級後 | P15: 分母：∫e^(−δt) | Q15: L_rel | R15: 2025 營收權重 w
A16: S1 只有跌價（2025＝第 0 年、不降級、不折現） | B16: Hopper | C16: =0 -> 0 | D16: =IN_g -> -0.09 | E16: =IN_gpre -> -0.09 | F16: =IN_T1 -> 4 | G16: =1 -> 1 | H16: =IN_T -> 6 | I16: =0 -> 0 | J16: =LN(1+D16) -> -0.094310679 | K16: =LN(1+E16) -> -0.094310679 | L16: =LN(1+I16) -> 0 | M16: =IF(C16>0,EXP(-K16*C16)*IF(ABS(K16-L16)<0.000000000001,(C16)-(0),(EXP((K16-L16)*(C16))-EXP((K16-L16)*(0)))/(K16-L16)),0) -> 0 | N16: =EXP(-J16*C16)*IF(ABS(J16-L16)<0.000000000001,(F16)-(C16),(EXP((J16-L16)*(F16))-EXP((J16-L16)*(C16)))/(J16-L16)) -> 3.3320764 | O16: =G16*EXP(-J16*C16)*IF(ABS(J16-L16)<0.000000000001,(H16)-(F16),(EXP((J16-L16)*(H16))-EXP((J16-L16)*(F16)))/(J16-L16)) -> 1.2499153 | P16: =IF(ABS(-L16)<0.000000000001,(H16)-(0),(EXP((-L16)*(H16))-EXP((-L16)*(0)))/(-L16)) -> 6 | Q16: =IF(C16>F16,"t0>T1（未支援）",(M16+N16+O16)/P16) -> 0.76366528 | R16: =IN_sh_H*IN_rg_H -> 2.8188855
A17: S1 只有跌價（2025＝第 0 年、不降級、不折現） | B17: GB200 | C17: =0 -> 0 | D17: =IN_g -> -0.09 | E17: =IN_gpre -> -0.09 | F17: =IN_T1 -> 4 | G17: =1 -> 1 | H17: =IN_T -> 6 | I17: =0 -> 0 | J17: =LN(1+D17) -> -0.094310679 | K17: =LN(1+E17) -> -0.094310679 | L17: =LN(1+I17) -> 0 | M17: =IF(C17>0,EXP(-K17*C17)*IF(ABS(K17-L17)<0.000000000001,(C17)-(0),(EXP((K17-L17)*(C17))-EXP((K17-L17)*(0)))/(K17-L17)),0) -> 0 | N17: =EXP(-J17*C17)*IF(ABS(J17-L17)<0.000000000001,(F17)-(C17),(EXP((J17-L17)*(F17))-EXP((J17-L17)*(C17)))/(J17-L17)) -> 3.3320764 | O17: =G17*EXP(-J17*C17)*IF(ABS(J17-L17)<0.000000000001,(H17)-(F17),(EXP((J17-L17)*(H17))-EXP((J17-L17)*(F17)))/(J17-L17)) -> 1.2499153 | P17: =IF(ABS(-L17)<0.000000000001,(H17)-(0),(EXP((-L17)*(H17))-EXP((-L17)*(0)))/(-L17)) -> 6 | Q17: =IF(C17>F17,"t0>T1（未支援）",(M17+N17+O17)/P17) -> 0.76366528 | R17: =IN_sh_G*IN_rg_G -> 9.2465417
A18: S1 只有跌價（2025＝第 0 年、不降級、不折現） | B18: GB300 | C18: =0 -> 0 | D18: =IN_g -> -0.09 | E18: =IN_gpre -> -0.09 | F18: =IN_T1 -> 4 | G18: =1 -> 1 | H18: =IN_T -> 6 | I18: =0 -> 0 | J18: =LN(1+D18) -> -0.094310679 | K18: =LN(1+E18) -> -0.094310679 | L18: =LN(1+I18) -> 0 | M18: =IF(C18>0,EXP(-K18*C18)*IF(ABS(K18-L18)<0.000000000001,(C18)-(0),(EXP((K18-L18)*(C18))-EXP((K18-L18)*(0)))/(K18-L18)),0) -> 0 | N18: =EXP(-J18*C18)*IF(ABS(J18-L18)<0.000000000001,(F18)-(C18),(EXP((J18-L18)*(F18))-EXP((J18-L18)*(C18)))/(J18-L18)) -> 3.3320764 | O18: =G18*EXP(-J18*C18)*IF(ABS(J18-L18)<0.000000000001,(H18)-(F18),(EXP((J18-L18)*(H18))-EXP((J18-L18)*(F18)))/(J18-L18)) -> 1.2499153 | P18: =IF(ABS(-L18)<0.000000000001,(H18)-(0),(EXP((-L18)*(H18))-EXP((-L18)*(0)))/(-L18)) -> 6 | Q18: =IF(C18>F18,"t0>T1（未支援）",(M18+N18+O18)/P18) -> 0.76366528 | R18: =IN_sh_3*IN_rg_3 -> 0
A19: S1 只有跌價（2025＝第 0 年、不降級、不折現） | B19: VR200 | C19: =0 -> 0 | D19: =IN_g -> -0.09 | E19: =IN_gpre -> -0.09 | F19: =IN_T1 -> 4 | G19: =1 -> 1 | H19: =IN_T -> 6 | I19: =0 -> 0 | J19: =LN(1+D19) -> -0.094310679 | K19: =LN(1+E19) -> -0.094310679 | L19: =LN(1+I19) -> 0 | M19: =IF(C19>0,EXP(-K19*C19)*IF(ABS(K19-L19)<0.000000000001,(C19)-(0),(EXP((K19-L19)*(C19))-EXP((K19-L19)*(0)))/(K19-L19)),0) -> 0 | N19: =EXP(-J19*C19)*IF(ABS(J19-L19)<0.000000000001,(F19)-(C19),(EXP((J19-L19)*(F19))-EXP((J19-L19)*(C19)))/(J19-L19)) -> 3.3320764 | O19: =G19*EXP(-J19*C19)*IF(ABS(J19-L19)<0.000000000001,(H19)-(F19),(EXP((J19-L19)*(H19))-EXP((J19-L19)*(F19)))/(J19-L19)) -> 1.2499153 | P19: =IF(ABS(-L19)<0.000000000001,(H19)-(0),(EXP((-L19)*(H19))-EXP((-L19)*(0)))/(-L19)) -> 6 | Q19: =IF(C19>F19,"t0>T1（未支援）",(M19+N19+O19)/P19) -> 0.76366528 | R19: =IN_sh_V*IN_rg_V -> 0
A20: S2 ＋降級 | B20: Hopper | C20: =0 -> 0 | D20: =IN_g -> -0.09 | E20: =IN_gpre -> -0.09 | F20: =IN_T1 -> 4 | G20: =IN_rho -> 0.5 | H20: =IN_T -> 6 | I20: =0 -> 0 | J20: =LN(1+D20) -> -0.094310679 | K20: =LN(1+E20) -> -0.094310679 | L20: =LN(1+I20) -> 0 | M20: =IF(C20>0,EXP(-K20*C20)*IF(ABS(K20-L20)<0.000000000001,(C20)-(0),(EXP((K20-L20)*(C20))-EXP((K20-L20)*(0)))/(K20-L20)),0) -> 0 | N20: =EXP(-J20*C20)*IF(ABS(J20-L20)<0.000000000001,(F20)-(C20),(EXP((J20-L20)*(F20))-EXP((J20-L20)*(C20)))/(J20-L20)) -> 3.3320764 | O20: =G20*EXP(-J20*C20)*IF(ABS(J20-L20)<0.000000000001,(H20)-(F20),(EXP((J20-L20)*(H20))-EXP((J20-L20)*(F20)))/(J20-L20)) -> 0.62495763 | P20: =IF(ABS(-L20)<0.000000000001,(H20)-(0),(EXP((-L20)*(H20))-EXP((-L20)*(0)))/(-L20)) -> 6 | Q20: =IF(C20>F20,"t0>T1（未支援）",(M20+N20+O20)/P20) -> 0.65950567 | R20: =IN_sh_H*IN_rg_H -> 2.8188855
A21: S2 ＋降級 | B21: GB200 | C21: =0 -> 0 | D21: =IN_g -> -0.09 | E21: =IN_gpre -> -0.09 | F21: =IN_T1 -> 4 | G21: =IN_rho -> 0.5 | H21: =IN_T -> 6 | I21: =0 -> 0 | J21: =LN(1+D21) -> -0.094310679 | K21: =LN(1+E21) -> -0.094310679 | L21: =LN(1+I21) -> 0 | M21: =IF(C21>0,EXP(-K21*C21)*IF(ABS(K21-L21)<0.000000000001,(C21)-(0),(EXP((K21-L21)*(C21))-EXP((K21-L21)*(0)))/(K21-L21)),0) -> 0 | N21: =EXP(-J21*C21)*IF(ABS(J21-L21)<0.000000000001,(F21)-(C21),(EXP((J21-L21)*(F21))-EXP((J21-L21)*(C21)))/(J21-L21)) -> 3.3320764 | O21: =G21*EXP(-J21*C21)*IF(ABS(J21-L21)<0.000000000001,(H21)-(F21),(EXP((J21-L21)*(H21))-EXP((J21-L21)*(F21)))/(J21-L21)) -> 0.62495763 | P21: =IF(ABS(-L21)<0.000000000001,(H21)-(0),(EXP((-L21)*(H21))-EXP((-L21)*(0)))/(-L21)) -> 6 | Q21: =IF(C21>F21,"t0>T1（未支援）",(M21+N21+O21)/P21) -> 0.65950567 | R21: =IN_sh_G*IN_rg_G -> 9.2465417
A22: S2 ＋降級 | B22: GB300 | C22: =0 -> 0 | D22: =IN_g -> -0.09 | E22: =IN_gpre -> -0.09 | F22: =IN_T1 -> 4 | G22: =IN_rho -> 0.5 | H22: =IN_T -> 6 | I22: =0 -> 0 | J22: =LN(1+D22) -> -0.094310679 | K22: =LN(1+E22) -> -0.094310679 | L22: =LN(1+I22) -> 0 | M22: =IF(C22>0,EXP(-K22*C22)*IF(ABS(K22-L22)<0.000000000001,(C22)-(0),(EXP((K22-L22)*(C22))-EXP((K22-L22)*(0)))/(K22-L22)),0) -> 0 | N22: =EXP(-J22*C22)*IF(ABS(J22-L22)<0.000000000001,(F22)-(C22),(EXP((J22-L22)*(F22))-EXP((J22-L22)*(C22)))/(J22-L22)) -> 3.3320764 | O22: =G22*EXP(-J22*C22)*IF(ABS(J22-L22)<0.000000000001,(H22)-(F22),(EXP((J22-L22)*(H22))-EXP((J22-L22)*(F22)))/(J22-L22)) -> 0.62495763 | P22: =IF(ABS(-L22)<0.000000000001,(H22)-(0),(EXP((-L22)*(H22))-EXP((-L22)*(0)))/(-L22)) -> 6 | Q22: =IF(C22>F22,"t0>T1（未支援）",(M22+N22+O22)/P22) -> 0.65950567 | R22: =IN_sh_3*IN_rg_3 -> 0
A23: S2 ＋降級 | B23: VR200 | C23: =0 -> 0 | D23: =IN_g -> -0.09 | E23: =IN_gpre -> -0.09 | F23: =IN_T1 -> 4 | G23: =IN_rho -> 0.5 | H23: =IN_T -> 6 | I23: =0 -> 0 | J23: =LN(1+D23) -> -0.094310679 | K23: =LN(1+E23) -> -0.094310679 | L23: =LN(1+I23) -> 0 | M23: =IF(C23>0,EXP(-K23*C23)*IF(ABS(K23-L23)<0.000000000001,(C23)-(0),(EXP((K23-L23)*(C23))-EXP((K23-L23)*(0)))/(K23-L23)),0) -> 0 | N23: =EXP(-J23*C23)*IF(ABS(J23-L23)<0.000000000001,(F23)-(C23),(EXP((J23-L23)*(F23))-EXP((J23-L23)*(C23)))/(J23-L23)) -> 3.3320764 | O23: =G23*EXP(-J23*C23)*IF(ABS(J23-L23)<0.000000000001,(H23)-(F23),(EXP((J23-L23)*(H23))-EXP((J23-L23)*(F23)))/(J23-L23)) -> 0.62495763 | P23: =IF(ABS(-L23)<0.000000000001,(H23)-(0),(EXP((-L23)*(H23))-EXP((-L23)*(0)))/(-L23)) -> 6 | Q23: =IF(C23>F23,"t0>T1（未支援）",(M23+N23+O23)/P23) -> 0.65950567 | R23: =IN_sh_V*IN_rg_V -> 0
A24: S3 ＋折現 | B24: Hopper | C24: =0 -> 0 | D24: =IN_g -> -0.09 | E24: =IN_gpre -> -0.09 | F24: =IN_T1 -> 4 | G24: =IN_rho -> 0.5 | H24: =IN_T -> 6 | I24: =IN_WACC -> 0.1 | J24: =LN(1+D24) -> -0.094310679 | K24: =LN(1+E24) -> -0.094310679 | L24: =LN(1+I24) -> 0.09531018 | M24: =IF(C24>0,EXP(-K24*C24)*IF(ABS(K24-L24)<0.000000000001,(C24)-(0),(EXP((K24-L24)*(C24))-EXP((K24-L24)*(0)))/(K24-L24)),0) -> 0 | N24: =EXP(-J24*C24)*IF(ABS(J24-L24)<0.000000000001,(F24)-(C24),(EXP((J24-L24)*(F24))-EXP((J24-L24)*(C24)))/(J24-L24)) -> 2.8036145 | O24: =G24*EXP(-J24*C24)*IF(ABS(J24-L24)<0.000000000001,(H24)-(F24),(EXP((J24-L24)*(H24))-EXP((J24-L24)*(F24)))/(J24-L24)) -> 0.38980106 | P24: =IF(ABS(-L24)<0.000000000001,(H24)-(0),(EXP((-L24)*(H24))-EXP((-L24)*(0)))/(-L24)) -> 4.5695651 | Q24: =IF(C24>F24,"t0>T1（未支援）",(M24+N24+O24)/P24) -> 0.69884453 | R24: =IN_sh_H*IN_rg_H -> 2.8188855
A25: S3 ＋折現 | B25: GB200 | C25: =0 -> 0 | D25: =IN_g -> -0.09 | E25: =IN_gpre -> -0.09 | F25: =IN_T1 -> 4 | G25: =IN_rho -> 0.5 | H25: =IN_T -> 6 | I25: =IN_WACC -> 0.1 | J25: =LN(1+D25) -> -0.094310679 | K25: =LN(1+E25) -> -0.094310679 | L25: =LN(1+I25) -> 0.09531018 | M25: =IF(C25>0,EXP(-K25*C25)*IF(ABS(K25-L25)<0.000000000001,(C25)-(0),(EXP((K25-L25)*(C25))-EXP((K25-L25)*(0)))/(K25-L25)),0) -> 0 | N25: =EXP(-J25*C25)*IF(ABS(J25-L25)<0.000000000001,(F25)-(C25),(EXP((J25-L25)*(F25))-EXP((J25-L25)*(C25)))/(J25-L25)) -> 2.8036145 | O25: =G25*EXP(-J25*C25)*IF(ABS(J25-L25)<0.000000000001,(H25)-(F25),(EXP((J25-L25)*(H25))-EXP((J25-L25)*(F25)))/(J25-L25)) -> 0.38980106 | P25: =IF(ABS(-L25)<0.000000000001,(H25)-(0),(EXP((-L25)*(H25))-EXP((-L25)*(0)))/(-L25)) -> 4.5695651 | Q25: =IF(C25>F25,"t0>T1（未支援）",(M25+N25+O25)/P25) -> 0.69884453 | R25: =IN_sh_G*IN_rg_G -> 9.2465417
A26: S3 ＋折現 | B26: GB300 | C26: =0 -> 0 | D26: =IN_g -> -0.09 | E26: =IN_gpre -> -0.09 | F26: =IN_T1 -> 4 | G26: =IN_rho -> 0.5 | H26: =IN_T -> 6 | I26: =IN_WACC -> 0.1 | J26: =LN(1+D26) -> -0.094310679 | K26: =LN(1+E26) -> -0.094310679 | L26: =LN(1+I26) -> 0.09531018 | M26: =IF(C26>0,EXP(-K26*C26)*IF(ABS(K26-L26)<0.000000000001,(C26)-(0),(EXP((K26-L26)*(C26))-EXP((K26-L26)*(0)))/(K26-L26)),0) -> 0 | N26: =EXP(-J26*C26)*IF(ABS(J26-L26)<0.000000000001,(F26)-(C26),(EXP((J26-L26)*(F26))-EXP((J26-L26)*(C26)))/(J26-L26)) -> 2.8036145 | O26: =G26*EXP(-J26*C26)*IF(ABS(J26-L26)<0.000000000001,(H26)-(F26),(EXP((J26-L26)*(H26))-EXP((J26-L26)*(F26)))/(J26-L26)) -> 0.38980106 | P26: =IF(ABS(-L26)<0.000000000001,(H26)-(0),(EXP((-L26)*(H26))-EXP((-L26)*(0)))/(-L26)) -> 4.5695651 | Q26: =IF(C26>F26,"t0>T1（未支援）",(M26+N26+O26)/P26) -> 0.69884453 | R26: =IN_sh_3*IN_rg_3 -> 0
A27: S3 ＋折現 | B27: VR200 | C27: =0 -> 0 | D27: =IN_g -> -0.09 | E27: =IN_gpre -> -0.09 | F27: =IN_T1 -> 4 | G27: =IN_rho -> 0.5 | H27: =IN_T -> 6 | I27: =IN_WACC -> 0.1 | J27: =LN(1+D27) -> -0.094310679 | K27: =LN(1+E27) -> -0.094310679 | L27: =LN(1+I27) -> 0.09531018 | M27: =IF(C27>0,EXP(-K27*C27)*IF(ABS(K27-L27)<0.000000000001,(C27)-(0),(EXP((K27-L27)*(C27))-EXP((K27-L27)*(0)))/(K27-L27)),0) -> 0 | N27: =EXP(-J27*C27)*IF(ABS(J27-L27)<0.000000000001,(F27)-(C27),(EXP((J27-L27)*(F27))-EXP((J27-L27)*(C27)))/(J27-L27)) -> 2.8036145 | O27: =G27*EXP(-J27*C27)*IF(ABS(J27-L27)<0.000000000001,(H27)-(F27),(EXP((J27-L27)*(H27))-EXP((J27-L27)*(F27)))/(J27-L27)) -> 0.38980106 | P27: =IF(ABS(-L27)<0.000000000001,(H27)-(0),(EXP((-L27)*(H27))-EXP((-L27)*(0)))/(-L27)) -> 4.5695651 | Q27: =IF(C27>F27,"t0>T1（未支援）",(M27+N27+O27)/P27) -> 0.69884453 | R27: =IN_sh_V*IN_rg_V -> 0
A28: S4 ＋世代起點（主口徑） | B28: Hopper | C28: =MAX(0,IN_A-IN_sv_H) -> 2 | D28: =IN_g -> -0.09 | E28: =IN_gpre -> -0.09 | F28: =IN_T1 -> 4 | G28: =IN_rho -> 0.5 | H28: =IN_T -> 6 | I28: =IN_WACC -> 0.1 | J28: =LN(1+D28) -> -0.094310679 | K28: =LN(1+E28) -> -0.094310679 | L28: =LN(1+I28) -> 0.09531018 | M28: =IF(C28>0,EXP(-K28*C28)*IF(ABS(K28-L28)<0.000000000001,(C28)-(0),(EXP((K28-L28)*(C28))-EXP((K28-L28)*(0)))/(K28-L28)),0) -> 2.0099969 | N28: =EXP(-J28*C28)*IF(ABS(J28-L28)<0.000000000001,(F28)-(C28),(EXP((J28-L28)*(F28))-EXP((J28-L28)*(C28)))/(J28-L28)) -> 1.375602 | O28: =G28*EXP(-J28*C28)*IF(ABS(J28-L28)<0.000000000001,(H28)-(F28),(EXP((J28-L28)*(H28))-EXP((J28-L28)*(F28)))/(J28-L28)) -> 0.47071737 | P28: =IF(ABS(-L28)<0.000000000001,(H28)-(0),(EXP((-L28)*(H28))-EXP((-L28)*(0)))/(-L28)) -> 4.5695651 | Q28: =IF(C28>F28,"t0>T1（未支援）",(M28+N28+O28)/P28) -> 0.84391321 | R28: =IN_sh_H*IN_rg_H -> 2.8188855
A29: S4 ＋世代起點（主口徑） | B29: GB200 | C29: =MAX(0,IN_A-IN_sv_G) -> 0.5 | D29: =IN_g -> -0.09 | E29: =IN_gpre -> -0.09 | F29: =IN_T1 -> 4 | G29: =IN_rho -> 0.5 | H29: =IN_T -> 6 | I29: =IN_WACC -> 0.1 | J29: =LN(1+D29) -> -0.094310679 | K29: =LN(1+E29) -> -0.094310679 | L29: =LN(1+I29) -> 0.09531018 | M29: =IF(C29>0,EXP(-K29*C29)*IF(ABS(K29-L29)<0.000000000001,(C29)-(0),(EXP((K29-L29)*(C29))-EXP((K29-L29)*(0)))/(K29-L29)),0) -> 0.50006232 | N29: =EXP(-J29*C29)*IF(ABS(J29-L29)<0.000000000001,(F29)-(C29),(EXP((J29-L29)*(F29))-EXP((J29-L29)*(C29)))/(J29-L29)) -> 2.4389242 | O29: =G29*EXP(-J29*C29)*IF(ABS(J29-L29)<0.000000000001,(H29)-(F29),(EXP((J29-L29)*(H29))-EXP((J29-L29)*(F29)))/(J29-L29)) -> 0.40862254 | P29: =IF(ABS(-L29)<0.000000000001,(H29)-(0),(EXP((-L29)*(H29))-EXP((-L29)*(0)))/(-L29)) -> 4.5695651 | Q29: =IF(C29>F29,"t0>T1（未支援）",(M29+N29+O29)/P29) -> 0.73258812 | R29: =IN_sh_G*IN_rg_G -> 9.2465417
A30: S4 ＋世代起點（主口徑） | B30: GB300 | C30: =MAX(0,IN_A-IN_sv_3) -> 0 | D30: =IN_g -> -0.09 | E30: =IN_gpre -> -0.09 | F30: =IN_T1 -> 4 | G30: =IN_rho -> 0.5 | H30: =IN_T -> 6 | I30: =IN_WACC -> 0.1 | J30: =LN(1+D30) -> -0.094310679 | K30: =LN(1+E30) -> -0.094310679 | L30: =LN(1+I30) -> 0.09531018 | M30: =IF(C30>0,EXP(-K30*C30)*IF(ABS(K30-L30)<0.000000000001,(C30)-(0),(EXP((K30-L30)*(C30))-EXP((K30-L30)*(0)))/(K30-L30)),0) -> 0 | N30: =EXP(-J30*C30)*IF(ABS(J30-L30)<0.000000000001,(F30)-(C30),(EXP((J30-L30)*(F30))-EXP((J30-L30)*(C30)))/(J30-L30)) -> 2.8036145 | O30: =G30*EXP(-J30*C30)*IF(ABS(J30-L30)<0.000000000001,(H30)-(F30),(EXP((J30-L30)*(H30))-EXP((J30-L30)*(F30)))/(J30-L30)) -> 0.38980106 | P30: =IF(ABS(-L30)<0.000000000001,(H30)-(0),(EXP((-L30)*(H30))-EXP((-L30)*(0)))/(-L30)) -> 4.5695651 | Q30: =IF(C30>F30,"t0>T1（未支援）",(M30+N30+O30)/P30) -> 0.69884453 | R30: =IN_sh_3*IN_rg_3 -> 0
A31: S4 ＋世代起點（主口徑） | B31: VR200 | C31: =MAX(0,IN_A-IN_sv_V) -> 0 | D31: =IN_g -> -0.09 | E31: =IN_gpre -> -0.09 | F31: =IN_T1 -> 4 | G31: =IN_rho -> 0.5 | H31: =IN_T -> 6 | I31: =IN_WACC -> 0.1 | J31: =LN(1+D31) -> -0.094310679 | K31: =LN(1+E31) -> -0.094310679 | L31: =LN(1+I31) -> 0.09531018 | M31: =IF(C31>0,EXP(-K31*C31)*IF(ABS(K31-L31)<0.000000000001,(C31)-(0),(EXP((K31-L31)*(C31))-EXP((K31-L31)*(0)))/(K31-L31)),0) -> 0 | N31: =EXP(-J31*C31)*IF(ABS(J31-L31)<0.000000000001,(F31)-(C31),(EXP((J31-L31)*(F31))-EXP((J31-L31)*(C31)))/(J31-L31)) -> 2.8036145 | O31: =G31*EXP(-J31*C31)*IF(ABS(J31-L31)<0.000000000001,(H31)-(F31),(EXP((J31-L31)*(H31))-EXP((J31-L31)*(F31)))/(J31-L31)) -> 0.38980106 | P31: =IF(ABS(-L31)<0.000000000001,(H31)-(0),(EXP((-L31)*(H31))-EXP((-L31)*(0)))/(-L31)) -> 4.5695651 | Q31: =IF(C31>F31,"t0>T1（未支援）",(M31+N31+O31)/P31) -> 0.69884453 | R31: =IN_sh_V*IN_rg_V -> 0
A32: S5 對照：世代起點、不折現（v16.0 口徑） | B32: Hopper | C32: =MAX(0,IN_A-IN_sv_H) -> 2 | D32: =IN_g -> -0.09 | E32: =IN_gpre -> -0.09 | F32: =IN_T1 -> 4 | G32: =IN_rho -> 0.5 | H32: =IN_T -> 6 | I32: =0 -> 0 | J32: =LN(1+D32) -> -0.094310679 | K32: =LN(1+E32) -> -0.094310679 | L32: =LN(1+I32) -> 0 | M32: =IF(C32>0,EXP(-K32*C32)*IF(ABS(K32-L32)<0.000000000001,(C32)-(0),(EXP((K32-L32)*(C32))-EXP((K32-L32)*(0)))/(K32-L32)),0) -> 2.2010617 | N32: =EXP(-J32*C32)*IF(ABS(J32-L32)<0.000000000001,(F32)-(C32),(EXP((J32-L32)*(F32))-EXP((J32-L32)*(C32)))/(J32-L32)) -> 1.8226992 | O32: =G32*EXP(-J32*C32)*IF(ABS(J32-L32)<0.000000000001,(H32)-(F32),(EXP((J32-L32)*(H32))-EXP((J32-L32)*(F32)))/(J32-L32)) -> 0.7546886 | P32: =IF(ABS(-L32)<0.000000000001,(H32)-(0),(EXP((-L32)*(H32))-EXP((-L32)*(0)))/(-L32)) -> 6 | Q32: =IF(C32>F32,"t0>T1（未支援）",(M32+N32+O32)/P32) -> 0.79640825 | R32: =IN_sh_H*IN_rg_H -> 2.8188855
A33: S5 對照：世代起點、不折現（v16.0 口徑） | B33: GB200 | C33: =MAX(0,IN_A-IN_sv_G) -> 0.5 | D33: =IN_g -> -0.09 | E33: =IN_gpre -> -0.09 | F33: =IN_T1 -> 4 | G33: =IN_rho -> 0.5 | H33: =IN_T -> 6 | I33: =0 -> 0 | J33: =LN(1+D33) -> -0.094310679 | K33: =LN(1+E33) -> -0.094310679 | L33: =LN(1+I33) -> 0 | M33: =IF(C33>0,EXP(-K33*C33)*IF(ABS(K33-L33)<0.000000000001,(C33)-(0),(EXP((K33-L33)*(C33))-EXP((K33-L33)*(0)))/(K33-L33)),0) -> 0.51197634 | N33: =EXP(-J33*C33)*IF(ABS(J33-L33)<0.000000000001,(F33)-(C33),(EXP((J33-L33)*(F33))-EXP((J33-L33)*(C33)))/(J33-L33)) -> 2.9809888 | O33: =G33*EXP(-J33*C33)*IF(ABS(J33-L33)<0.000000000001,(H33)-(F33),(EXP((J33-L33)*(H33))-EXP((J33-L33)*(F33)))/(J33-L33)) -> 0.65513361 | P33: =IF(ABS(-L33)<0.000000000001,(H33)-(0),(EXP((-L33)*(H33))-EXP((-L33)*(0)))/(-L33)) -> 6 | Q33: =IF(C33>F33,"t0>T1（未支援）",(M33+N33+O33)/P33) -> 0.6913498 | R33: =IN_sh_G*IN_rg_G -> 9.2465417
A34: S5 對照：世代起點、不折現（v16.0 口徑） | B34: GB300 | C34: =MAX(0,IN_A-IN_sv_3) -> 0 | D34: =IN_g -> -0.09 | E34: =IN_gpre -> -0.09 | F34: =IN_T1 -> 4 | G34: =IN_rho -> 0.5 | H34: =IN_T -> 6 | I34: =0 -> 0 | J34: =LN(1+D34) -> -0.094310679 | K34: =LN(1+E34) -> -0.094310679 | L34: =LN(1+I34) -> 0 | M34: =IF(C34>0,EXP(-K34*C34)*IF(ABS(K34-L34)<0.000000000001,(C34)-(0),(EXP((K34-L34)*(C34))-EXP((K34-L34)*(0)))/(K34-L34)),0) -> 0 | N34: =EXP(-J34*C34)*IF(ABS(J34-L34)<0.000000000001,(F34)-(C34),(EXP((J34-L34)*(F34))-EXP((J34-L34)*(C34)))/(J34-L34)) -> 3.3320764 | O34: =G34*EXP(-J34*C34)*IF(ABS(J34-L34)<0.000000000001,(H34)-(F34),(EXP((J34-L34)*(H34))-EXP((J34-L34)*(F34)))/(J34-L34)) -> 0.62495763 | P34: =IF(ABS(-L34)<0.000000000001,(H34)-(0),(EXP((-L34)*(H34))-EXP((-L34)*(0)))/(-L34)) -> 6 | Q34: =IF(C34>F34,"t0>T1（未支援）",(M34+N34+O34)/P34) -> 0.65950567 | R34: =IN_sh_3*IN_rg_3 -> 0
A35: S5 對照：世代起點、不折現（v16.0 口徑） | B35: VR200 | C35: =MAX(0,IN_A-IN_sv_V) -> 0 | D35: =IN_g -> -0.09 | E35: =IN_gpre -> -0.09 | F35: =IN_T1 -> 4 | G35: =IN_rho -> 0.5 | H35: =IN_T -> 6 | I35: =0 -> 0 | J35: =LN(1+D35) -> -0.094310679 | K35: =LN(1+E35) -> -0.094310679 | L35: =LN(1+I35) -> 0 | M35: =IF(C35>0,EXP(-K35*C35)*IF(ABS(K35-L35)<0.000000000001,(C35)-(0),(EXP((K35-L35)*(C35))-EXP((K35-L35)*(0)))/(K35-L35)),0) -> 0 | N35: =EXP(-J35*C35)*IF(ABS(J35-L35)<0.000000000001,(F35)-(C35),(EXP((J35-L35)*(F35))-EXP((J35-L35)*(C35)))/(J35-L35)) -> 3.3320764 | O35: =G35*EXP(-J35*C35)*IF(ABS(J35-L35)<0.000000000001,(H35)-(F35),(EXP((J35-L35)*(H35))-EXP((J35-L35)*(F35)))/(J35-L35)) -> 0.62495763 | P35: =IF(ABS(-L35)<0.000000000001,(H35)-(0),(EXP((-L35)*(H35))-EXP((-L35)*(0)))/(-L35)) -> 6 | Q35: =IF(C35>F35,"t0>T1（未支援）",(M35+N35+O35)/P35) -> 0.65950567 | R35: =IN_sh_V*IN_rg_V -> 0
A36: S6 低端組合 | B36: Hopper | C36: =MAX(0,IN_A-IN_sv_H_Lo) -> 1.5 | D36: =IN_g_Lo -> -0.2 | E36: =IN_gpre_Lo -> -0.09 | F36: =IN_T1_Lo -> 3 | G36: =IN_rho_Lo -> 0.20572251 | H36: =IN_T_Lo -> 6 | I36: =IN_WACC_Lo -> 0.08 | J36: =LN(1+D36) -> -0.22314355 | K36: =LN(1+E36) -> -0.094310679 | L36: =LN(1+I36) -> 0.076961041 | M36: =IF(C36>0,EXP(-K36*C36)*IF(ABS(K36-L36)<0.000000000001,(C36)-(0),(EXP((K36-L36)*(C36))-EXP((K36-L36)*(0)))/(K36-L36)),0) -> 1.5238285 | N36: =EXP(-J36*C36)*IF(ABS(J36-L36)<0.000000000001,(F36)-(C36),(EXP((J36-L36)*(F36))-EXP((J36-L36)*(C36)))/(J36-L36)) -> 1.0761332 | O36: =G36*EXP(-J36*C36)*IF(ABS(J36-L36)<0.000000000001,(H36)-(F36),(EXP((J36-L36)*(H36))-EXP((J36-L36)*(F36)))/(J36-L36)) -> 0.23111917 | P36: =IF(ABS(-L36)<0.000000000001,(H36)-(0),(EXP((-L36)*(H36))-EXP((-L36)*(0)))/(-L36)) -> 4.8054232 | Q36: =IF(C36>F36,"t0>T1（未支援）",(M36+N36+O36)/P36) -> 0.58914288 | R36: =IN_sh_H*IN_rg_H -> 2.8188855
A37: S6 低端組合 | B37: GB200 | C37: =MAX(0,IN_A-IN_sv_G_Lo) -> 0 | D37: =IN_g_Lo -> -0.2 | E37: =IN_gpre_Lo -> -0.09 | F37: =IN_T1_Lo -> 3 | G37: =IN_rho_Lo -> 0.20572251 | H37: =IN_T_Lo -> 6 | I37: =IN_WACC_Lo -> 0.08 | J37: =LN(1+D37) -> -0.22314355 | K37: =LN(1+E37) -> -0.094310679 | L37: =LN(1+I37) -> 0.076961041 | M37: =IF(C37>0,EXP(-K37*C37)*IF(ABS(K37-L37)<0.000000000001,(C37)-(0),(EXP((K37-L37)*(C37))-EXP((K37-L37)*(0)))/(K37-L37)),0) -> 0 | N37: =EXP(-J37*C37)*IF(ABS(J37-L37)<0.000000000001,(F37)-(C37),(EXP((J37-L37)*(F37))-EXP((J37-L37)*(C37)))/(J37-L37)) -> 1.9778368 | O37: =G37*EXP(-J37*C37)*IF(ABS(J37-L37)<0.000000000001,(H37)-(F37),(EXP((J37-L37)*(H37))-EXP((J37-L37)*(F37)))/(J37-L37)) -> 0.16537541 | P37: =IF(ABS(-L37)<0.000000000001,(H37)-(0),(EXP((-L37)*(H37))-EXP((-L37)*(0)))/(-L37)) -> 4.8054232 | Q37: =IF(C37>F37,"t0>T1（未支援）",(M37+N37+O37)/P37) -> 0.44599863 | R37: =IN_sh_G*IN_rg_G -> 9.2465417
A38: S6 低端組合 | B38: GB300 | C38: =MAX(0,IN_A-IN_sv_3_Lo) -> 0 | D38: =IN_g_Lo -> -0.2 | E38: =IN_gpre_Lo -> -0.09 | F38: =IN_T1_Lo -> 3 | G38: =IN_rho_Lo -> 0.20572251 | H38: =IN_T_Lo -> 6 | I38: =IN_WACC_Lo -> 0.08 | J38: =LN(1+D38) -> -0.22314355 | K38: =LN(1+E38) -> -0.094310679 | L38: =LN(1+I38) -> 0.076961041 | M38: =IF(C38>0,EXP(-K38*C38)*IF(ABS(K38-L38)<0.000000000001,(C38)-(0),(EXP((K38-L38)*(C38))-EXP((K38-L38)*(0)))/(K38-L38)),0) -> 0 | N38: =EXP(-J38*C38)*IF(ABS(J38-L38)<0.000000000001,(F38)-(C38),(EXP((J38-L38)*(F38))-EXP((J38-L38)*(C38)))/(J38-L38)) -> 1.9778368 | O38: =G38*EXP(-J38*C38)*IF(ABS(J38-L38)<0.000000000001,(H38)-(F38),(EXP((J38-L38)*(H38))-EXP((J38-L38)*(F38)))/(J38-L38)) -> 0.16537541 | P38: =IF(ABS(-L38)<0.000000000001,(H38)-(0),(EXP((-L38)*(H38))-EXP((-L38)*(0)))/(-L38)) -> 4.8054232 | Q38: =IF(C38>F38,"t0>T1（未支援）",(M38+N38+O38)/P38) -> 0.44599863 | R38: =IN_sh_3*IN_rg_3 -> 0
A39: S6 低端組合 | B39: VR200 | C39: =MAX(0,IN_A-IN_sv_V_Lo) -> 0 | D39: =IN_g_Lo -> -0.2 | E39: =IN_gpre_Lo -> -0.09 | F39: =IN_T1_Lo -> 3 | G39: =IN_rho_Lo -> 0.20572251 | H39: =IN_T_Lo -> 6 | I39: =IN_WACC_Lo -> 0.08 | J39: =LN(1+D39) -> -0.22314355 | K39: =LN(1+E39) -> -0.094310679 | L39: =LN(1+I39) -> 0.076961041 | M39: =IF(C39>0,EXP(-K39*C39)*IF(ABS(K39-L39)<0.000000000001,(C39)-(0),(EXP((K39-L39)*(C39))-EXP((K39-L39)*(0)))/(K39-L39)),0) -> 0 | N39: =EXP(-J39*C39)*IF(ABS(J39-L39)<0.000000000001,(F39)-(C39),(EXP((J39-L39)*(F39))-EXP((J39-L39)*(C39)))/(J39-L39)) -> 1.9778368 | O39: =G39*EXP(-J39*C39)*IF(ABS(J39-L39)<0.000000000001,(H39)-(F39),(EXP((J39-L39)*(H39))-EXP((J39-L39)*(F39)))/(J39-L39)) -> 0.16537541 | P39: =IF(ABS(-L39)<0.000000000001,(H39)-(0),(EXP((-L39)*(H39))-EXP((-L39)*(0)))/(-L39)) -> 4.8054232 | Q39: =IF(C39>F39,"t0>T1（未支援）",(M39+N39+O39)/P39) -> 0.44599863 | R39: =IN_sh_V*IN_rg_V -> 0
A40: S7 高端組合 | B40: Hopper | C40: =MAX(0,IN_A-IN_sv_H_Hi) -> 2.5 | D40: =IN_g_Hi -> 0.05 | E40: =IN_gpre_Hi -> -0.3 | F40: =IN_T1_Hi -> 5 | G40: =IN_rho_Hi -> 0.7 | H40: =IN_T_Hi -> 6 | I40: =IN_WACC_Hi -> 0.13 | J40: =LN(1+D40) -> 0.048790164 | K40: =LN(1+E40) -> -0.35667494 | L40: =LN(1+I40) -> 0.12221763 | M40: =IF(C40>0,EXP(-K40*C40)*IF(ABS(K40-L40)<0.000000000001,(C40)-(0),(EXP((K40-L40)*(C40))-EXP((K40-L40)*(0)))/(K40-L40)),0) -> 3.555118 | N40: =EXP(-J40*C40)*IF(ABS(J40-L40)<0.000000000001,(F40)-(C40),(EXP((J40-L40)*(F40))-EXP((J40-L40)*(C40)))/(J40-L40)) -> 1.6826434 | O40: =G40*EXP(-J40*C40)*IF(ABS(J40-L40)<0.000000000001,(H40)-(F40),(EXP((J40-L40)*(H40))-EXP((J40-L40)*(F40)))/(J40-L40)) -> 0.41383961 | P40: =IF(ABS(-L40)<0.000000000001,(H40)-(0),(EXP((-L40)*(H40))-EXP((-L40)*(0)))/(-L40)) -> 4.252099 | Q40: =IF(C40>F40,"t0>T1（未支援）",(M40+N40+O40)/P40) -> 1.329132 | R40: =IN_sh_H*IN_rg_H -> 2.8188855
A41: S7 高端組合 | B41: GB200 | C41: =MAX(0,IN_A-IN_sv_G_Hi) -> 0.5 | D41: =IN_g_Hi -> 0.05 | E41: =IN_gpre_Hi -> -0.3 | F41: =IN_T1_Hi -> 5 | G41: =IN_rho_Hi -> 0.7 | H41: =IN_T_Hi -> 6 | I41: =IN_WACC_Hi -> 0.13 | J41: =LN(1+D41) -> 0.048790164 | K41: =LN(1+E41) -> -0.35667494 | L41: =LN(1+I41) -> 0.12221763 | M41: =IF(C41>0,EXP(-K41*C41)*IF(ABS(K41-L41)<0.000000000001,(C41)-(0),(EXP((K41-L41)*(C41))-EXP((K41-L41)*(0)))/(K41-L41)),0) -> 0.53145059 | N41: =EXP(-J41*C41)*IF(ABS(J41-L41)<0.000000000001,(F41)-(C41),(EXP((J41-L41)*(F41))-EXP((J41-L41)*(C41)))/(J41-L41)) -> 3.604928 | O41: =G41*EXP(-J41*C41)*IF(ABS(J41-L41)<0.000000000001,(H41)-(F41),(EXP((J41-L41)*(H41))-EXP((J41-L41)*(F41)))/(J41-L41)) -> 0.45625817 | P41: =IF(ABS(-L41)<0.000000000001,(H41)-(0),(EXP((-L41)*(H41))-EXP((-L41)*(0)))/(-L41)) -> 4.252099 | Q41: =IF(C41>F41,"t0>T1（未支援）",(M41+N41+O41)/P41) -> 1.080087 | R41: =IN_sh_G*IN_rg_G -> 9.2465417
A42: S7 高端組合 | B42: GB300 | C42: =MAX(0,IN_A-IN_sv_3_Hi) -> 0 | D42: =IN_g_Hi -> 0.05 | E42: =IN_gpre_Hi -> -0.3 | F42: =IN_T1_Hi -> 5 | G42: =IN_rho_Hi -> 0.7 | H42: =IN_T_Hi -> 6 | I42: =IN_WACC_Hi -> 0.13 | J42: =LN(1+D42) -> 0.048790164 | K42: =LN(1+E42) -> -0.35667494 | L42: =LN(1+I42) -> 0.12221763 | M42: =IF(C42>0,EXP(-K42*C42)*IF(ABS(K42-L42)<0.000000000001,(C42)-(0),(EXP((K42-L42)*(C42))-EXP((K42-L42)*(0)))/(K42-L42)),0) -> 0 | N42: =EXP(-J42*C42)*IF(ABS(J42-L42)<0.000000000001,(F42)-(C42),(EXP((J42-L42)*(F42))-EXP((J42-L42)*(C42)))/(J42-L42)) -> 4.1848849 | O42: =G42*EXP(-J42*C42)*IF(ABS(J42-L42)<0.000000000001,(H42)-(F42),(EXP((J42-L42)*(H42))-EXP((J42-L42)*(F42)))/(J42-L42)) -> 0.4675255 | P42: =IF(ABS(-L42)<0.000000000001,(H42)-(0),(EXP((-L42)*(H42))-EXP((-L42)*(0)))/(-L42)) -> 4.252099 | Q42: =IF(C42>F42,"t0>T1（未支援）",(M42+N42+O42)/P42) -> 1.0941444 | R42: =IN_sh_3*IN_rg_3 -> 0
A43: S7 高端組合 | B43: VR200 | C43: =MAX(0,IN_A-IN_sv_V_Hi) -> 0 | D43: =IN_g_Hi -> 0.05 | E43: =IN_gpre_Hi -> -0.3 | F43: =IN_T1_Hi -> 5 | G43: =IN_rho_Hi -> 0.7 | H43: =IN_T_Hi -> 6 | I43: =IN_WACC_Hi -> 0.13 | J43: =LN(1+D43) -> 0.048790164 | K43: =LN(1+E43) -> -0.35667494 | L43: =LN(1+I43) -> 0.12221763 | M43: =IF(C43>0,EXP(-K43*C43)*IF(ABS(K43-L43)<0.000000000001,(C43)-(0),(EXP((K43-L43)*(C43))-EXP((K43-L43)*(0)))/(K43-L43)),0) -> 0 | N43: =EXP(-J43*C43)*IF(ABS(J43-L43)<0.000000000001,(F43)-(C43),(EXP((J43-L43)*(F43))-EXP((J43-L43)*(C43)))/(J43-L43)) -> 4.1848849 | O43: =G43*EXP(-J43*C43)*IF(ABS(J43-L43)<0.000000000001,(H43)-(F43),(EXP((J43-L43)*(H43))-EXP((J43-L43)*(F43)))/(J43-L43)) -> 0.4675255 | P43: =IF(ABS(-L43)<0.000000000001,(H43)-(0),(EXP((-L43)*(H43))-EXP((-L43)*(0)))/(-L43)) -> 4.252099 | Q43: =IF(C43>F43,"t0>T1（未支援）",(M43+N43+O43)/P43) -> 1.0941444 | R43: =IN_sh_V*IN_rg_V -> 0

Sheet 4_必須為真
A1: 必須為真：單獨改一個變數（其餘維持基準；L 與所需 L 都用主口徑），機隊 L ÷ 所需 L 何時跨過 1。全部公式；格點的每一列都完整重算四個世代。
A3: 格點：g
A4: g | B4: 機隊 L | C4: L ÷ 所需 L | D4: 判讀
A5: -0.25 | B5: =IF(SUMPRODUCT(ISTEXT(Q23:Q26)*(R23:R26>0))>0,"含 t0>T1 的世代",SUMPRODUCT(R23:R26,Q23:Q26)/SUM(R23:R26)) -> 0.5968773 | C5: =B5/LQ -> 0.73955322 | D5: =IF(C5>=1,"回本","未回本") -> 未回本
A6: -0.225 | B6: =IF(SUMPRODUCT(ISTEXT(Q27:Q30)*(R27:R30>0))>0,"含 t0>T1 的世代",SUMPRODUCT(R27:R30,Q27:Q30)/SUM(R27:R30)) -> 0.61880469 | C6: =B6/LQ -> 0.76672207 | D6: =IF(C6>=1,"回本","未回本") -> 未回本
A7: -0.2 | B7: =IF(SUMPRODUCT(ISTEXT(Q31:Q34)*(R31:R34>0))>0,"含 t0>T1 的世代",SUMPRODUCT(R31:R34,Q31:Q34)/SUM(R31:R34)) -> 0.64187633 | C7: =B7/LQ -> 0.79530869 | D7: =IF(C7>=1,"回本","未回本") -> 未回本
A8: -0.175 | B8: =IF(SUMPRODUCT(ISTEXT(Q35:Q38)*(R35:R38>0))>0,"含 t0>T1 的世代",SUMPRODUCT(R35:R38,Q35:Q38)/SUM(R35:R38)) -> 0.66615371 | C8: =B8/LQ -> 0.82538927 | D8: =IF(C8>=1,"回本","未回本") -> 未回本
A9: -0.15 | B9: =IF(SUMPRODUCT(ISTEXT(Q39:Q42)*(R39:R42>0))>0,"含 t0>T1 的世代",SUMPRODUCT(R39:R42,Q39:Q42)/SUM(R39:R42)) -> 0.69170079 | C9: =B9/LQ -> 0.85704305 | D9: =IF(C9>=1,"回本","未回本") -> 未回本
A10: -0.125 | B10: =IF(SUMPRODUCT(ISTEXT(Q43:Q46)*(R43:R46>0))>0,"含 t0>T1 的世代",SUMPRODUCT(R43:R46,Q43:Q46)/SUM(R43:R46)) -> 0.71858403 | C10: =B10/LQ -> 0.89035239 | D10: =IF(C10>=1,"回本","未回本") -> 未回本
A11: -0.1 | B11: =IF(SUMPRODUCT(ISTEXT(Q47:Q50)*(R47:R50>0))>0,"含 t0>T1 的世代",SUMPRODUCT(R47:R50,Q47:Q50)/SUM(R47:R50)) -> 0.74687252 | C11: =B11/LQ -> 0.92540288 | D11: =IF(C11>=1,"回本","未回本") -> 未回本
A12: -0.075 | B12: =IF(SUMPRODUCT(ISTEXT(Q51:Q54)*(R51:R54>0))>0,"含 t0>T1 的世代",SUMPRODUCT(R51:R54,Q51:Q54)/SUM(R51:R54)) -> 0.77663801 | C12: =B12/LQ -> 0.96228344 | D12: =IF(C12>=1,"回本","未回本") -> 未回本
A13: -0.05 | B13: =IF(SUMPRODUCT(ISTEXT(Q55:Q58)*(R55:R58>0))>0,"含 t0>T1 的世代",SUMPRODUCT(R55:R58,Q55:Q58)/SUM(R55:R58)) -> 0.80795502 | C13: =B13/LQ -> 1.0010864 | D13: =IF(C13>=1,"回本","未回本") -> 回本
A14: -0.025 | B14: =IF(SUMPRODUCT(ISTEXT(Q59:Q62)*(R59:R62>0))>0,"含 t0>T1 的世代",SUMPRODUCT(R59:R62,Q59:Q62)/SUM(R59:R62)) -> 0.84090086 | C14: =B14/LQ -> 1.0419075 | D14: =IF(C14>=1,"回本","未回本") -> 回本
A15: 0 | B15: =IF(SUMPRODUCT(ISTEXT(Q63:Q66)*(R63:R66>0))>0,"含 t0>T1 的世代",SUMPRODUCT(R63:R66,Q63:Q66)/SUM(R63:R66)) -> 0.87555575 | C15: =B15/LQ -> 1.0848462 | D15: =IF(C15>=1,"回本","未回本") -> 回本
A16: 0.025 | B16: =IF(SUMPRODUCT(ISTEXT(Q67:Q70)*(R67:R70>0))>0,"含 t0>T1 的世代",SUMPRODUCT(R67:R70,Q67:Q70)/SUM(R67:R70)) -> 0.91200288 | C16: =B16/LQ -> 1.1300055 | D16: =IF(C16>=1,"回本","未回本") -> 回本
A17: 0.05 | B17: =IF(SUMPRODUCT(ISTEXT(Q71:Q74)*(R71:R74>0))>0,"含 t0>T1 的世代",SUMPRODUCT(R71:R74,Q71:Q74)/SUM(R71:R74)) -> 0.95032845 | C17: =B17/LQ -> 1.1774924 | D17: =IF(C17>=1,"回本","未回本") -> 回本
A18: 損益兩平的 g（線性內插） | B18: =IFERROR(INDEX(A5:A17,MATCH(1,C5:C17,1))+(1-INDEX(C5:C17,MATCH(1,C5:C17,1)))*(INDEX(A5:A17,MATCH(1,C5:C17,1)+1)-INDEX(A5:A17,MATCH(1,C5:C17,1)))/(INDEX(C5:C17,MATCH(1,C5:C17,1)+1)-INDEX(C5:C17,MATCH(1,C5:C17,1))),"格點內未跨過 1") -> -0.050699931
A19: 損益兩平的 g（精確值） | B19: 精確值另算：g −5.068%（2026-10-24 chat 端獨立核對以 Python 算；與上方內插 −5.07% 一致） | D19: Derived
A20: 註 | B20: 損益兩平 g 只動錨點後的 g，g_pre 固定 −9%（錨點前回推不變）
A21: （g 格點的逐世代計算）
A22: 情境 | B22: 世代 | C22: t0（錨點時已服務年數） | D22: g | E22: g_pre | F22: T1 | G22: ρ | H22: T | I22: 折現率 | J22: k＝ln(1+g) | K22: k_pre＝ln(1+g_pre) | L22: δ＝ln(1+折現率) | M22: 段 1：錨點前 | N22: 段 2：中階服務 | O22: 段 3：降級後 | P22: 分母：∫e^(−δt) | Q22: L_rel | R22: 2025 營收權重 w
A23: g＝格點第 1 列 | B23: Hopper | C23: =MAX(0,IN_A-IN_sv_H) -> 2 | D23: =$A$5 -> -0.25 | E23: =IN_gpre -> -0.09 | F23: =IN_T1 -> 4 | G23: =IN_rho -> 0.5 | H23: =IN_T -> 6 | I23: =IN_WACC -> 0.1 | J23: =LN(1+D23) -> -0.28768207 | K23: =LN(1+E23) -> -0.094310679 | L23: =LN(1+I23) -> 0.09531018 | M23: =IF(C23>0,EXP(-K23*C23)*IF(ABS(K23-L23)<0.000000000001,(C23)-(0),(EXP((K23-L23)*(C23))-EXP((K23-L23)*(0)))/(K23-L23)),0) -> 2.0099969 | N23: =EXP(-J23*C23)*IF(ABS(J23-L23)<0.000000000001,(F23)-(C23),(EXP((J23-L23)*(F23))-EXP((J23-L23)*(C23)))/(J23-L23)) -> 1.1547263 | O23: =G23*EXP(-J23*C23)*IF(ABS(J23-L23)<0.000000000001,(H23)-(F23),(EXP((J23-L23)*(H23))-EXP((J23-L23)*(F23)))/(J23-L23)) -> 0.26840228 | P23: =IF(ABS(-L23)<0.000000000001,(H23)-(0),(EXP((-L23)*(H23))-EXP((-L23)*(0)))/(-L23)) -> 4.5695651 | Q23: =IF(C23>F23,"t0>T1（未支援）",(M23+N23+O23)/P23) -> 0.75130246 | R23: =IN_sh_H*IN_rg_H -> 2.8188855
A24: g＝格點第 1 列 | B24: GB200 | C24: =MAX(0,IN_A-IN_sv_G) -> 0.5 | D24: =$A$5 -> -0.25 | E24: =IN_gpre -> -0.09 | F24: =IN_T1 -> 4 | G24: =IN_rho -> 0.5 | H24: =IN_T -> 6 | I24: =IN_WACC -> 0.1 | J24: =LN(1+D24) -> -0.28768207 | K24: =LN(1+E24) -> -0.094310679 | L24: =LN(1+I24) -> 0.09531018 | M24: =IF(C24>0,EXP(-K24*C24)*IF(ABS(K24-L24)<0.000000000001,(C24)-(0),(EXP((K24-L24)*(C24))-EXP((K24-L24)*(0)))/(K24-L24)),0) -> 0.50006232 | N24: =EXP(-J24*C24)*IF(ABS(J24-L24)<0.000000000001,(F24)-(C24),(EXP((J24-L24)*(F24))-EXP((J24-L24)*(C24)))/(J24-L24)) -> 1.8379499 | O24: =G24*EXP(-J24*C24)*IF(ABS(J24-L24)<0.000000000001,(H24)-(F24),(EXP((J24-L24)*(H24))-EXP((J24-L24)*(F24)))/(J24-L24)) -> 0.1743324 | P24: =IF(ABS(-L24)<0.000000000001,(H24)-(0),(EXP((-L24)*(H24))-EXP((-L24)*(0)))/(-L24)) -> 4.5695651 | Q24: =IF(C24>F24,"t0>T1（未支援）",(M24+N24+O24)/P24) -> 0.5497995 | R24: =IN_sh_G*IN_rg_G -> 9.2465417
A25: g＝格點第 1 列 | B25: GB300 | C25: =MAX(0,IN_A-IN_sv_3) -> 0 | D25: =$A$5 -> -0.25 | E25: =IN_gpre -> -0.09 | F25: =IN_T1 -> 4 | G25: =IN_rho -> 0.5 | H25: =IN_T -> 6 | I25: =IN_WACC -> 0.1 | J25: =LN(1+D25) -> -0.28768207 | K25: =LN(1+E25) -> -0.094310679 | L25: =LN(1+I25) -> 0.09531018 | M25: =IF(C25>0,EXP(-K25*C25)*IF(ABS(K25-L25)<0.000000000001,(C25)-(0),(EXP((K25-L25)*(C25))-EXP((K25-L25)*(0)))/(K25-L25)),0) -> 0 | N25: =EXP(-J25*C25)*IF(ABS(J25-L25)<0.000000000001,(F25)-(C25),(EXP((J25-L25)*(F25))-EXP((J25-L25)*(C25)))/(J25-L25)) -> 2.0467523 | O25: =G25*EXP(-J25*C25)*IF(ABS(J25-L25)<0.000000000001,(H25)-(F25),(EXP((J25-L25)*(H25))-EXP((J25-L25)*(F25)))/(J25-L25)) -> 0.15097628 | P25: =IF(ABS(-L25)<0.000000000001,(H25)-(0),(EXP((-L25)*(H25))-EXP((-L25)*(0)))/(-L25)) -> 4.5695651 | Q25: =IF(C25>F25,"t0>T1（未支援）",(M25+N25+O25)/P25) -> 0.48094918 | R25: =IN_sh_3*IN_rg_3 -> 0
A26: g＝格點第 1 列 | B26: VR200 | C26: =MAX(0,IN_A-IN_sv_V) -> 0 | D26: =$A$5 -> -0.25 | E26: =IN_gpre -> -0.09 | F26: =IN_T1 -> 4 | G26: =IN_rho -> 0.5 | H26: =IN_T -> 6 | I26: =IN_WACC -> 0.1 | J26: =LN(1+D26) -> -0.28768207 | K26: =LN(1+E26) -> -0.094310679 | L26: =LN(1+I26) -> 0.09531018 | M26: =IF(C26>0,EXP(-K26*C26)*IF(ABS(K26-L26)<0.000000000001,(C26)-(0),(EXP((K26-L26)*(C26))-EXP((K26-L26)*(0)))/(K26-L26)),0) -> 0 | N26: =EXP(-J26*C26)*IF(ABS(J26-L26)<0.000000000001,(F26)-(C26),(EXP((J26-L26)*(F26))-EXP((J26-L26)*(C26)))/(J26-L26)) -> 2.0467523 | O26: =G26*EXP(-J26*C26)*IF(ABS(J26-L26)<0.000000000001,(H26)-(F26),(EXP((J26-L26)*(H26))-EXP((J26-L26)*(F26)))/(J26-L26)) -> 0.15097628 | P26: =IF(ABS(-L26)<0.000000000001,(H26)-(0),(EXP((-L26)*(H26))-EXP((-L26)*(0)))/(-L26)) -> 4.5695651 | Q26: =IF(C26>F26,"t0>T1（未支援）",(M26+N26+O26)/P26) -> 0.48094918 | R26: =IN_sh_V*IN_rg_V -> 0
A27: g＝格點第 2 列 | B27: Hopper | C27: =MAX(0,IN_A-IN_sv_H) -> 2 | D27: =$A$6 -> -0.225 | E27: =IN_gpre -> -0.09 | F27: =IN_T1 -> 4 | G27: =IN_rho -> 0.5 | H27: =IN_T -> 6 | I27: =IN_WACC -> 0.1 | J27: =LN(1+D27) -> -0.25489225 | K27: =LN(1+E27) -> -0.094310679 | L27: =LN(1+I27) -> 0.09531018 | M27: =IF(C27>0,EXP(-K27*C27)*IF(ABS(K27-L27)<0.000000000001,(C27)-(0),(EXP((K27-L27)*(C27))-EXP((K27-L27)*(0)))/(K27-L27)),0) -> 2.0099969 | N27: =EXP(-J27*C27)*IF(ABS(J27-L27)<0.000000000001,(F27)-(C27),(EXP((J27-L27)*(F27))-EXP((J27-L27)*(C27)))/(J27-L27)) -> 1.1884878 | O27: =G27*EXP(-J27*C27)*IF(ABS(J27-L27)<0.000000000001,(H27)-(F27),(EXP((J27-L27)*(H27))-EXP((J27-L27)*(F27)))/(J27-L27)) -> 0.29497335 | P27: =IF(ABS(-L27)<0.000000000001,(H27)-(0),(EXP((-L27)*(H27))-EXP((-L27)*(0)))/(-L27)) -> 4.5695651 | Q27: =IF(C27>F27,"t0>T1（未支援）",(M27+N27+O27)/P27) -> 0.7645056 | R27: =IN_sh_H*IN_rg_H -> 2.8188855
A28: g＝格點第 2 列 | B28: GB200 | C28: =MAX(0,IN_A-IN_sv_G) -> 0.5 | D28: =$A$6 -> -0.225 | E28: =IN_gpre -> -0.09 | F28: =IN_T1 -> 4 | G28: =IN_rho -> 0.5 | H28: =IN_T -> 6 | I28: =IN_WACC -> 0.1 | J28: =LN(1+D28) -> -0.25489225 | K28: =LN(1+E28) -> -0.094310679 | L28: =LN(1+I28) -> 0.09531018 | M28: =IF(C28>0,EXP(-K28*C28)*IF(ABS(K28-L28)<0.000000000001,(C28)-(0),(EXP((K28-L28)*(C28))-EXP((K28-L28)*(0)))/(K28-L28)),0) -> 0.50006232 | N28: =EXP(-J28*C28)*IF(ABS(J28-L28)<0.000000000001,(F28)-(C28),(EXP((J28-L28)*(F28))-EXP((J28-L28)*(C28)))/(J28-L28)) -> 1.9233847 | O28: =G28*EXP(-J28*C28)*IF(ABS(J28-L28)<0.000000000001,(H28)-(F28),(EXP((J28-L28)*(H28))-EXP((J28-L28)*(F28)))/(J28-L28)) -> 0.20124974 | P28: =IF(ABS(-L28)<0.000000000001,(H28)-(0),(EXP((-L28)*(H28))-EXP((-L28)*(0)))/(-L28)) -> 4.5695651 | Q28: =IF(C28>F28,"t0>T1（未支援）",(M28+N28+O28)/P28) -> 0.57438655 | R28: =IN_sh_G*IN_rg_G -> 9.2465417
A29: g＝格點第 2 列 | B29: GB300 | C29: =MAX(0,IN_A-IN_sv_3) -> 0 | D29: =$A$6 -> -0.225 | E29: =IN_gpre -> -0.09 | F29: =IN_T1 -> 4 | G29: =IN_rho -> 0.5 | H29: =IN_T -> 6 | I29: =IN_WACC -> 0.1 | J29: =LN(1+D29) -> -0.25489225 | K29: =LN(1+E29) -> -0.094310679 | L29: =LN(1+I29) -> 0.09531018 | M29: =IF(C29>0,EXP(-K29*C29)*IF(ABS(K29-L29)<0.000000000001,(C29)-(0),(EXP((K29-L29)*(C29))-EXP((K29-L29)*(0)))/(K29-L29)),0) -> 0 | N29: =EXP(-J29*C29)*IF(ABS(J29-L29)<0.000000000001,(F29)-(C29),(EXP((J29-L29)*(F29))-EXP((J29-L29)*(C29)))/(J29-L29)) -> 2.1519058 | O29: =G29*EXP(-J29*C29)*IF(ABS(J29-L29)<0.000000000001,(H29)-(F29),(EXP((J29-L29)*(H29))-EXP((J29-L29)*(F29)))/(J29-L29)) -> 0.17716837 | P29: =IF(ABS(-L29)<0.000000000001,(H29)-(0),(EXP((-L29)*(H29))-EXP((-L29)*(0)))/(-L29)) -> 4.5695651 | Q29: =IF(C29>F29,"t0>T1（未支援）",(M29+N29+O29)/P29) -> 0.50969274 | R29: =IN_sh_3*IN_rg_3 -> 0
A30: g＝格點第 2 列 | B30: VR200 | C30: =MAX(0,IN_A-IN_sv_V) -> 0 | D30: =$A$6 -> -0.225 | E30: =IN_gpre -> -0.09 | F30: =IN_T1 -> 4 | G30: =IN_rho -> 0.5 | H30: =IN_T -> 6 | I30: =IN_WACC -> 0.1 | J30: =LN(1+D30) -> -0.25489225 | K30: =LN(1+E30) -> -0.094310679 | L30: =LN(1+I30) -> 0.09531018 | M30: =IF(C30>0,EXP(-K30*C30)*IF(ABS(K30-L30)<0.000000000001,(C30)-(0),(EXP((K30-L30)*(C30))-EXP((K30-L30)*(0)))/(K30-L30)),0) -> 0 | N30: =EXP(-J30*C30)*IF(ABS(J30-L30)<0.000000000001,(F30)-(C30),(EXP((J30-L30)*(F30))-EXP((J30-L30)*(C30)))/(J30-L30)) -> 2.1519058 | O30: =G30*EXP(-J30*C30)*IF(ABS(J30-L30)<0.000000000001,(H30)-(F30),(EXP((J30-L30)*(H30))-EXP((J30-L30)*(F30)))/(J30-L30)) -> 0.17716837 | P30: =IF(ABS(-L30)<0.000000000001,(H30)-(0),(EXP((-L30)*(H30))-EXP((-L30)*(0)))/(-L30)) -> 4.5695651 | Q30: =IF(C30>F30,"t0>T1（未支援）",(M30+N30+O30)/P30) -> 0.50969274 | R30: =IN_sh_V*IN_rg_V -> 0
A31: g＝格點第 3 列 | B31: Hopper | C31: =MAX(0,IN_A-IN_sv_H) -> 2 | D31: =$A$7 -> -0.2 | E31: =IN_gpre -> -0.09 | F31: =IN_T1 -> 4 | G31: =IN_rho -> 0.5 | H31: =IN_T -> 6 | I31: =IN_WACC -> 0.1 | J31: =LN(1+D31) -> -0.22314355 | K31: =LN(1+E31) -> -0.094310679 | L31: =LN(1+I31) -> 0.09531018 | M31: =IF(C31>0,EXP(-K31*C31)*IF(ABS(K31-L31)<0.000000000001,(C31)-(0),(EXP((K31-L31)*(C31))-EXP((K31-L31)*(0)))/(K31-L31)),0) -> 2.0099969 | N31: =EXP(-J31*C31)*IF(ABS(J31-L31)<0.000000000001,(F31)-(C31),(EXP((J31-L31)*(F31))-EXP((J31-L31)*(C31)))/(J31-L31)) -> 1.2225251 | O31: =G31*EXP(-J31*C31)*IF(ABS(J31-L31)<0.000000000001,(H31)-(F31),(EXP((J31-L31)*(H31))-EXP((J31-L31)*(F31)))/(J31-L31)) -> 0.32331241 | P31: =IF(ABS(-L31)<0.000000000001,(H31)-(0),(EXP((-L31)*(H31))-EXP((-L31)*(0)))/(-L31)) -> 4.5695651 | Q31: =IF(C31>F31,"t0>T1（未支援）",(M31+N31+O31)/P31) -> 0.77815598 | R31: =IN_sh_H*IN_rg_H -> 2.8188855
A32: g＝格點第 3 列 | B32: GB200 | C32: =MAX(0,IN_A-IN_sv_G) -> 0.5 | D32: =$A$7 -> -0.2 | E32: =IN_gpre -> -0.09 | F32: =IN_T1 -> 4 | G32: =IN_rho -> 0.5 | H32: =IN_T -> 6 | I32: =IN_WACC -> 0.1 | J32: =LN(1+D32) -> -0.22314355 | K32: =LN(1+E32) -> -0.094310679 | L32: =LN(1+I32) -> 0.09531018 | M32: =IF(C32>0,EXP(-K32*C32)*IF(ABS(K32-L32)<0.000000000001,(C32)-(0),(EXP((K32-L32)*(C32))-EXP((K32-L32)*(0)))/(K32-L32)),0) -> 0.50006232 | N32: =EXP(-J32*C32)*IF(ABS(J32-L32)<0.000000000001,(F32)-(C32),(EXP((J32-L32)*(F32))-EXP((J32-L32)*(C32)))/(J32-L32)) -> 2.0118427 | O32: =G32*EXP(-J32*C32)*IF(ABS(J32-L32)<0.000000000001,(H32)-(F32),(EXP((J32-L32)*(H32))-EXP((J32-L32)*(F32)))/(J32-L32)) -> 0.23134353 | P32: =IF(ABS(-L32)<0.000000000001,(H32)-(0),(EXP((-L32)*(H32))-EXP((-L32)*(0)))/(-L32)) -> 4.5695651 | Q32: =IF(C32>F32,"t0>T1（未支援）",(M32+N32+O32)/P32) -> 0.60033034 | R32: =IN_sh_G*IN_rg_G -> 9.2465417
A33: g＝格點第 3 列 | B33: GB300 | C33: =MAX(0,IN_A-IN_sv_3) -> 0 | D33: =$A$7 -> -0.2 | E33: =IN_gpre -> -0.09 | F33: =IN_T1 -> 4 | G33: =IN_rho -> 0.5 | H33: =IN_T -> 6 | I33: =IN_WACC -> 0.1 | J33: =LN(1+D33) -> -0.22314355 | K33: =LN(1+E33) -> -0.094310679 | L33: =LN(1+I33) -> 0.09531018 | M33: =IF(C33>0,EXP(-K33*C33)*IF(ABS(K33-L33)<0.000000000001,(C33)-(0),(EXP((K33-L33)*(C33))-EXP((K33-L33)*(0)))/(K33-L33)),0) -> 0 | N33: =EXP(-J33*C33)*IF(ABS(J33-L33)<0.000000000001,(F33)-(C33),(EXP((J33-L33)*(F33))-EXP((J33-L33)*(C33)))/(J33-L33)) -> 2.2616714 | O33: =G33*EXP(-J33*C33)*IF(ABS(J33-L33)<0.000000000001,(H33)-(F33),(EXP((J33-L33)*(H33))-EXP((J33-L33)*(F33)))/(J33-L33)) -> 0.20691995 | P33: =IF(ABS(-L33)<0.000000000001,(H33)-(0),(EXP((-L33)*(H33))-EXP((-L33)*(0)))/(-L33)) -> 4.5695651 | Q33: =IF(C33>F33,"t0>T1（未支援）",(M33+N33+O33)/P33) -> 0.54022457 | R33: =IN_sh_3*IN_rg_3 -> 0
A34: g＝格點第 3 列 | B34: VR200 | C34: =MAX(0,IN_A-IN_sv_V) -> 0 | D34: =$A$7 -> -0.2 | E34: =IN_gpre -> -0.09 | F34: =IN_T1 -> 4 | G34: =IN_rho -> 0.5 | H34: =IN_T -> 6 | I34: =IN_WACC -> 0.1 | J34: =LN(1+D34) -> -0.22314355 | K34: =LN(1+E34) -> -0.094310679 | L34: =LN(1+I34) -> 0.09531018 | M34: =IF(C34>0,EXP(-K34*C34)*IF(ABS(K34-L34)<0.000000000001,(C34)-(0),(EXP((K34-L34)*(C34))-EXP((K34-L34)*(0)))/(K34-L34)),0) -> 0 | N34: =EXP(-J34*C34)*IF(ABS(J34-L34)<0.000000000001,(F34)-(C34),(EXP((J34-L34)*(F34))-EXP((J34-L34)*(C34)))/(J34-L34)) -> 2.2616714 | O34: =G34*EXP(-J34*C34)*IF(ABS(J34-L34)<0.000000000001,(H34)-(F34),(EXP((J34-L34)*(H34))-EXP((J34-L34)*(F34)))/(J34-L34)) -> 0.20691995 | P34: =IF(ABS(-L34)<0.000000000001,(H34)-(0),(EXP((-L34)*(H34))-EXP((-L34)*(0)))/(-L34)) -> 4.5695651 | Q34: =IF(C34>F34,"t0>T1（未支援）",(M34+N34+O34)/P34) -> 0.54022457 | R34: =IN_sh_V*IN_rg_V -> 0
A35: g＝格點第 4 列 | B35: Hopper | C35: =MAX(0,IN_A-IN_sv_H) -> 2 | D35: =$A$8 -> -0.175 | E35: =IN_gpre -> -0.09 | F35: =IN_T1 -> 4 | G35: =IN_rho -> 0.5 | H35: =IN_T -> 6 | I35: =IN_WACC -> 0.1 | J35: =LN(1+D35) -> -0.19237189 | K35: =LN(1+E35) -> -0.094310679 | L35: =LN(1+I35) -> 0.09531018 | M35: =IF(C35>0,EXP(-K35*C35)*IF(ABS(K35-L35)<0.000000000001,(C35)-(0),(EXP((K35-L35)*(C35))-EXP((K35-L35)*(0)))/(K35-L35)),0) -> 2.0099969 | N35: =EXP(-J35*C35)*IF(ABS(J35-L35)<0.000000000001,(F35)-(C35),(EXP((J35-L35)*(F35))-EXP((J35-L35)*(C35)))/(J35-L35)) -> 1.2568397 | O35: =G35*EXP(-J35*C35)*IF(ABS(J35-L35)<0.000000000001,(H35)-(F35),(EXP((J35-L35)*(H35))-EXP((J35-L35)*(F35)))/(J35-L35)) -> 0.35348616 | P35: =IF(ABS(-L35)<0.000000000001,(H35)-(0),(EXP((-L35)*(H35))-EXP((-L35)*(0)))/(-L35)) -> 4.5695651 | Q35: =IF(C35>F35,"t0>T1（未支援）",(M35+N35+O35)/P35) -> 0.79226857 | R35: =IN_sh_H*IN_rg_H -> 2.8188855
A36: g＝格點第 4 列 | B36: GB200 | C36: =MAX(0,IN_A-IN_sv_G) -> 0.5 | D36: =$A$8 -> -0.175 | E36: =IN_gpre -> -0.09 | F36: =IN_T1 -> 4 | G36: =IN_rho -> 0.5 | H36: =IN_T -> 6 | I36: =IN_WACC -> 0.1 | J36: =LN(1+D36) -> -0.19237189 | K36: =LN(1+E36) -> -0.094310679 | L36: =LN(1+I36) -> 0.09531018 | M36: =IF(C36>0,EXP(-K36*C36)*IF(ABS(K36-L36)<0.000000000001,(C36)-(0),(EXP((K36-L36)*(C36))-EXP((K36-L36)*(0)))/(K36-L36)),0) -> 0.50006232 | N36: =EXP(-J36*C36)*IF(ABS(J36-L36)<0.000000000001,(F36)-(C36),(EXP((J36-L36)*(F36))-EXP((J36-L36)*(C36)))/(J36-L36)) -> 2.103401 | O36: =G36*EXP(-J36*C36)*IF(ABS(J36-L36)<0.000000000001,(H36)-(F36),(EXP((J36-L36)*(H36))-EXP((J36-L36)*(F36)))/(J36-L36)) -> 0.26488255 | P36: =IF(ABS(-L36)<0.000000000001,(H36)-(0),(EXP((-L36)*(H36))-EXP((-L36)*(0)))/(-L36)) -> 4.5695651 | Q36: =IF(C36>F36,"t0>T1（未支援）",(M36+N36+O36)/P36) -> 0.62770655 | R36: =IN_sh_G*IN_rg_G -> 9.2465417
A37: g＝格點第 4 列 | B37: GB300 | C37: =MAX(0,IN_A-IN_sv_3) -> 0 | D37: =$A$8 -> -0.175 | E37: =IN_gpre -> -0.09 | F37: =IN_T1 -> 4 | G37: =IN_rho -> 0.5 | H37: =IN_T -> 6 | I37: =IN_WACC -> 0.1 | J37: =LN(1+D37) -> -0.19237189 | K37: =LN(1+E37) -> -0.094310679 | L37: =LN(1+I37) -> 0.09531018 | M37: =IF(C37>0,EXP(-K37*C37)*IF(ABS(K37-L37)<0.000000000001,(C37)-(0),(EXP((K37-L37)*(C37))-EXP((K37-L37)*(0)))/(K37-L37)),0) -> 0 | N37: =EXP(-J37*C37)*IF(ABS(J37-L37)<0.000000000001,(F37)-(C37),(EXP((J37-L37)*(F37))-EXP((J37-L37)*(C37)))/(J37-L37)) -> 2.3762125 | O37: =G37*EXP(-J37*C37)*IF(ABS(J37-L37)<0.000000000001,(H37)-(F37),(EXP((J37-L37)*(H37))-EXP((J37-L37)*(F37)))/(J37-L37)) -> 0.24059152 | P37: =IF(ABS(-L37)<0.000000000001,(H37)-(0),(EXP((-L37)*(H37))-EXP((-L37)*(0)))/(-L37)) -> 4.5695651 | Q37: =IF(C37>F37,"t0>T1（未支援）",(M37+N37+O37)/P37) -> 0.57265933 | R37: =IN_sh_3*IN_rg_3 -> 0
A38: g＝格點第 4 列 | B38: VR200 | C38: =MAX(0,IN_A-IN_sv_V) -> 0 | D38: =$A$8 -> -0.175 | E38: =IN_gpre -> -0.09 | F38: =IN_T1 -> 4 | G38: =IN_rho -> 0.5 | H38: =IN_T -> 6 | I38: =IN_WACC -> 0.1 | J38: =LN(1+D38) -> -0.19237189 | K38: =LN(1+E38) -> -0.094310679 | L38: =LN(1+I38) -> 0.09531018 | M38: =IF(C38>0,EXP(-K38*C38)*IF(ABS(K38-L38)<0.000000000001,(C38)-(0),(EXP((K38-L38)*(C38))-EXP((K38-L38)*(0)))/(K38-L38)),0) -> 0 | N38: =EXP(-J38*C38)*IF(ABS(J38-L38)<0.000000000001,(F38)-(C38),(EXP((J38-L38)*(F38))-EXP((J38-L38)*(C38)))/(J38-L38)) -> 2.3762125 | O38: =G38*EXP(-J38*C38)*IF(ABS(J38-L38)<0.000000000001,(H38)-(F38),(EXP((J38-L38)*(H38))-EXP((J38-L38)*(F38)))/(J38-L38)) -> 0.24059152 | P38: =IF(ABS(-L38)<0.000000000001,(H38)-(0),(EXP((-L38)*(H38))-EXP((-L38)*(0)))/(-L38)) -> 4.5695651 | Q38: =IF(C38>F38,"t0>T1（未支援）",(M38+N38+O38)/P38) -> 0.57265933 | R38: =IN_sh_V*IN_rg_V -> 0
A39: g＝格點第 5 列 | B39: Hopper | C39: =MAX(0,IN_A-IN_sv_H) -> 2 | D39: =$A$9 -> -0.15 | E39: =IN_gpre -> -0.09 | F39: =IN_T1 -> 4 | G39: =IN_rho -> 0.5 | H39: =IN_T -> 6 | I39: =IN_WACC -> 0.1 | J39: =LN(1+D39) -> -0.16251893 | K39: =LN(1+E39) -> -0.094310679 | L39: =LN(1+I39) -> 0.09531018 | M39: =IF(C39>0,EXP(-K39*C39)*IF(ABS(K39-L39)<0.000000000001,(C39)-(0),(EXP((K39-L39)*(C39))-EXP((K39-L39)*(0)))/(K39-L39)),0) -> 2.0099969 | N39: =EXP(-J39*C39)*IF(ABS(J39-L39)<0.000000000001,(F39)-(C39),(EXP((J39-L39)*(F39))-EXP((J39-L39)*(C39)))/(J39-L39)) -> 1.2914332 | O39: =G39*EXP(-J39*C39)*IF(ABS(J39-L39)<0.000000000001,(H39)-(F39),(EXP((J39-L39)*(H39))-EXP((J39-L39)*(F39)))/(J39-L39)) -> 0.38556217 | P39: =IF(ABS(-L39)<0.000000000001,(H39)-(0),(EXP((-L39)*(H39))-EXP((-L39)*(0)))/(-L39)) -> 4.5695651 | Q39: =IF(C39>F39,"t0>T1（未支援）",(M39+N39+O39)/P39) -> 0.80685846 | R39: =IN_sh_H*IN_rg_H -> 2.8188855
A40: g＝格點第 5 列 | B40: GB200 | C40: =MAX(0,IN_A-IN_sv_G) -> 0.5 | D40: =$A$9 -> -0.15 | E40: =IN_gpre -> -0.09 | F40: =IN_T1 -> 4 | G40: =IN_rho -> 0.5 | H40: =IN_T -> 6 | I40: =IN_WACC -> 0.1 | J40: =LN(1+D40) -> -0.16251893 | K40: =LN(1+E40) -> -0.094310679 | L40: =LN(1+I40) -> 0.09531018 | M40: =IF(C40>0,EXP(-K40*C40)*IF(ABS(K40-L40)<0.000000000001,(C40)-(0),(EXP((K40-L40)*(C40))-EXP((K40-L40)*(0)))/(K40-L40)),0) -> 0.50006232 | N40: =EXP(-J40*C40)*IF(ABS(J40-L40)<0.000000000001,(F40)-(C40),(EXP((J40-L40)*(F40))-EXP((J40-L40)*(C40)))/(J40-L40)) -> 2.1981366 | O40: =G40*EXP(-J40*C40)*IF(ABS(J40-L40)<0.000000000001,(H40)-(F40),(EXP((J40-L40)*(H40))-EXP((J40-L40)*(F40)))/(J40-L40)) -> 0.30215014 | P40: =IF(ABS(-L40)<0.000000000001,(H40)-(0),(EXP((-L40)*(H40))-EXP((-L40)*(0)))/(-L40)) -> 4.5695651 | Q40: =IF(C40>F40,"t0>T1（未支援）",(M40+N40+O40)/P40) -> 0.65659401 | R40: =IN_sh_G*IN_rg_G -> 9.2465417
A41: g＝格點第 5 列 | B41: GB300 | C41: =MAX(0,IN_A-IN_sv_3) -> 0 | D41: =$A$9 -> -0.15 | E41: =IN_gpre -> -0.09 | F41: =IN_T1 -> 4 | G41: =IN_rho -> 0.5 | H41: =IN_T -> 6 | I41: =IN_WACC -> 0.1 | J41: =LN(1+D41) -> -0.16251893 | K41: =LN(1+E41) -> -0.094310679 | L41: =LN(1+I41) -> 0.09531018 | M41: =IF(C41>0,EXP(-K41*C41)*IF(ABS(K41-L41)<0.000000000001,(C41)-(0),(EXP((K41-L41)*(C41))-EXP((K41-L41)*(0)))/(K41-L41)),0) -> 0 | N41: =EXP(-J41*C41)*IF(ABS(J41-L41)<0.000000000001,(F41)-(C41),(EXP((J41-L41)*(F41))-EXP((J41-L41)*(C41)))/(J41-L41)) -> 2.4956946 | O41: =G41*EXP(-J41*C41)*IF(ABS(J41-L41)<0.000000000001,(H41)-(F41),(EXP((J41-L41)*(H41))-EXP((J41-L41)*(F41)))/(J41-L41)) -> 0.27856867 | P41: =IF(ABS(-L41)<0.000000000001,(H41)-(0),(EXP((-L41)*(H41))-EXP((-L41)*(0)))/(-L41)) -> 4.5695651 | Q41: =IF(C41>F41,"t0>T1（未支援）",(M41+N41+O41)/P41) -> 0.60711757 | R41: =IN_sh_3*IN_rg_3 -> 0
...
