Workbook

Sheet 輸入
A1: 項目 | B1: 值 | C1: 單位 | D1: 標記 | E1: 依據
A2: E0：2025 年底 OpenAI 上線 GW | B2: 1.9 | C2: GW | D2: Interested-party：OpenAI CFO（募資／IPO 誘因） | E2: J7 參數!B2
A3: 2025 回本比值（基準） | B3: 1.239 | C3: 倍 | D3: Derived | E3: J7 參數!B12
A4: h 2026 每 GW 持有成本 | B4: 9.796 | C4: $B／GW·年 | D4: Derived | E4: J7 參數!B13
A5: 營收：Q2 年化 | B5: 26.3 | C5: $B | D5: Derived | E5: J7 參數!B14
A6: 營收：Q2 年化（WSJ 67 億×4） | B6: 26.8 | C6: $B | D6: 報導（WSJ，二手） | E6: J7 參數!B17
A7: 非 Fairwater 站 Q2 平均增量，低占比加權（晚） | B7: =B13*1+B14*0.5 -> 122 | C7: MW | D7: Derived（Epoch 站點；Abilene 90×1＋Denton 64×0.5＋speculative×0） | E7: J7 站點彙總 D3、D5；參數!B24:D24
A8: 非 Fairwater 站 Q2 平均增量，低占比加權（早） | B8: 256.73077 | C8: MW | D8: Derived | E8: J7 站點彙總 E3＋E5×0.5
A9: 非 Fairwater 站 Q2 平均增量，中占比加權（晚） | B9: =B13*1+B14*0.75+B15*0.25 -> 164.80769 | C9: MW | D9: Derived | E9: 由下列 Epoch 站點值以中占比（confident 1／likely 0.75／speculative 0.25）加權
A10: Fairwater Wisconsin Q2 平均增量（晚＝早） | B10: 308.17582 | C10: MW | D10: Analogy：Epoch（Building 1 於 2026-04-16 上線） | E10: J7 站點彙總 D4
A11: Fairwater Atlanta Q2 平均增量（晚） | B11: 58.846154 | C11: MW | D11: Analogy：Epoch（Building 3–4 於 2026-06-14 快照判定上線） | E11: J7 站點彙總 D2
A12: Fairwater Atlanta Q2 平均增量（早） | B12: 159.23077 | C12: MW | D12: Derived（J7 證據下限日期） | E12: J7 站點彙總 E2
A13: Abilene Q2 平均增量（晚） | B13: 90 | C13: MW | D13: Analogy：Epoch | E13: J7 站點彙總 D3
A14: Denton Q2 平均增量（晚） | B14: 64 | C14: MW | D14: Analogy：Epoch | E14: J7 站點彙總 D5
A15: speculative 站 Q2 平均增量合計（晚） | B15: 107.23077 | C15: MW | D15: Analogy：Epoch（Chester 25.38＋Marble 53.85＋Dalton 28） | E15: J7 站點彙總 D10、D11、D13
A16: MAI-Base-2 預訓練 GPU 數 | B16: 16000 | C16: 顆 GB200 | D16: Interested-party：Microsoft AI（〈Frontier Pre-training at Microsoft AI〉2026-10-15；展示自研能力的誘因） | E16: 2026 年 8–9 月，38 天；未載站點
A17: Fairwater Wisconsin GPU 數（Epoch 估） | B17: 176391 | C17: 顆 | D17: Analogy：Epoch（computeatlas 2026-10-07 轉引） | E17: Microsoft 只說「hundreds of thousands」
A18: Fairwater Atlanta GPU 數（Epoch 估） | B18: 304279 | C18: 顆 | D18: Analogy：Epoch（同上）
A19: Fairwater Wisconsin IT 電力（Epoch） | B19: 369 | C19: MW | D19: Analogy：Epoch | E19: 目錄頁 2026-07-25
A22: token 帳輸入（照抄 token帳缺口_A段.xlsx 輸入頁，未改） | B22: 值 | C22: 單位 | D22: 標記 | E22: 依據
A23: 2026 Q2 季平均上線 GW（J7 中＋晚） | B23: 2.34 | C23: GW | D23: Derived | E23: token A段 輸入!B2
A24: 2025 年底上線 GW | B24: 1.9 | C24: GW | D24: Interested-party | E24: 輸入!B3
A25: B4_Serve | B25: 0.41 | C25: x | D25: Interested-party／Derived | E25: 輸入!B4
A26: IF_FreeShare（產能側） | B26: 0.46 | C26: x | D26: Interested-party | E26: 輸入!B5
A27: AL_UtilActual | B27: 0.41 | C27: x | D27: Assumed | E27: 輸入!B6
A28: CTL_ProdDerate | B28: 0.85 | C28: x | D28: Assumed | E28: 輸入!B7
A29: 每 GW 付費產能 Hopper | B29: 2.6017337e+10 | C29: M tok/GW/年 | D29: Derived | E29: 輸入!B8
A30: 每 GW 付費產能 GB200 | B30: 1.2801356e+11 | C30: M tok/GW/年 | D30: Derived | E30: 輸入!B9
A31: 每 GW 付費產能 GB300 | B31: 1.5601612e+11 | C31: M tok/GW/年 | D31: Derived | E31: 輸入!B10
A32: 每 GW 付費產能 VR200 | B32: 2.5703546e+11 | C32: M tok/GW/年 | D32: Derived | E32: 輸入!B11
A33: 組合 Hopper | B33: 0.25 | C33: x | D33: Assumed | E33: 輸入!B12
A34: 組合 GB200 | B34: 0.45 | C34: x | D34: Assumed | E34: 輸入!B13
... A48: A 段候選 S2 基準 | B48: 0.8 | C48: x | D48: Assumed | E48: 輸入!C33
A50: 本段新證據（需求面） | B50: 值 | C50: 單位 | D50: 標記 | E50: 依據
A51: Codex 占輸出 token（Codex＋ChatGPT）：組織用戶 | B51: 0.633 | C51: x | D51: Interested-party：OpenAI 研究團隊（arXiv 2606.26959，2026-06-11 時點；推廣 Codex 的誘因） | E51: Business／Enterprise 方案；彙總比或平均值未明，圖說讀作總量比
A52: Codex 占輸出 token：個人用戶（含免費） | B52: 0.165 | C52: x | D52: Interested-party：同上 | E52: Free／Go／Plus／Pro
A53: 組織用戶占 ChatGPT token 的比例 w（低） | B53: 0.1 | C53: x | D53: Assumed | E53: 無來源；企業收入占比 >40%（OpenAI 2026-04-08）不等於 token 占比
A54: w（基準） | B54: 0.2 | C54: x | D54: Assumed
A55: w（高） | B55: 0.3 | C55: x | D55: Assumed
A56: Q2 平均 ÷ 6 月 11 日時點（Codex） | B56: 0.7 | C56: x | D56: Assumed | E56: Codex 週活 4/8 逾 300 萬 → 4/21 逾 400 萬 → 6/2 逾 500 萬（OpenAI）
...

Sheet Fairwater
A1: Q1：OpenAI 在 Fairwater 兩站的占比 f → Q2 季平均 GW 與倍數（沿用 J7「結果」頁 B40:H47 算法：其他站維持低占比，只動 f）
A3: 持平門檻 GW | B3: =輸入!B5/(輸入!B3*輸入!B4) -> 2.166884 | C3: 營收 ÷（2025 比值 × h）
A4: 持平門檻 GW（268 億） | B4: =輸入!B6/(輸入!B3*輸入!B4) -> 2.2080795
A5: Fairwater 兩站 Q2 平均增量（晚）MW | B5: =輸入!B10+輸入!B11 -> 367.02198
A6: Fairwater 兩站 Q2 平均增量（早）MW | B6: =輸入!B10+輸入!B12 -> 467.40659
A7: 對照 J7：f＝0 時 Q2 GW（晚）應為 2.022 | B7: =輸入!B2+輸入!B7/1000 -> 2.022
A8: 對照 J7：f＝0 時 Q2 GW（早）應為 2.1567 | B8: =輸入!B2+輸入!B8/1000 -> 2.1567308
A10: f | B10: Q2 GW（晚） | C10: Q2 倍數（晚） | D10: Q2 倍數（晚，268 億） | E10: Q2 GW（早） | F10: Q2 倍數（早） | G10: Q2 GW（晚，其他站中占比） | H10: Q2 倍數（晚，其他站中占比） | I10: 標記
A11: 0 | B11: =輸入!$B$2+(輸入!$B$7+A11*$B$5)/1000 -> 2.022 | C11: =$B$3/B11 -> 1.0716538 | D11: =$B$4/B11 -> 1.0920275 | E11: =輸入!$B$2+(輸入!$B$8+A11*$B$6)/1000 -> 2.1567308 | F11: =$B$3/E11 -> 1.0047077 | G11: =輸入!$B$2+(輸入!$B$9+A11*$B$5)/1000 -> 2.0648077 | H11: =$B$3/G11 -> 1.0494362
A12: 0.25 | B12: =輸入!$B$2+(輸入!$B$7+A12*$B$5)/1000 -> 2.1137555 | C12: =$B$3/B12 -> 1.0251347 | D12: =$B$4/B12 -> 1.0446239 | E12: =輸入!$B$2+(輸入!$B$8+A12*$B$6)/1000 -> 2.2735824 | F12: =$B$3/E12 -> 0.95307036 | G12: =輸入!$B$2+(輸入!$B$9+A12*$B$5)/1000 -> 2.1565632 | H12: =$B$3/G12 -> 1.0047858
A13: 0.4 | B13: =輸入!$B$2+(輸入!$B$7+A13*$B$5)/1000 -> 2.1688088 | C13: =$B$3/B13 -> 0.99911252 | D13: =$B$4/B13 -> 1.0181071 | E13: =輸入!$B$2+(輸入!$B$8+A13*$B$6)/1000 -> 2.3436934 | F13: =$B$3/E13 -> 0.9245595 | G13: =輸入!$B$2+(輸入!$B$9+A13*$B$5)/1000 -> 2.2116165 | H13: =$B$3/G13 -> 0.97977386 | I13: f 為 Assumed；本段判斷區間 0.4–0.9（見 README）
A14: 0.5 | B14: =輸入!$B$2+(輸入!$B$7+A14*$B$5)/1000 -> 2.205511 | C14: =$B$3/B14 -> 0.98248616 | D14: =$B$4/B14 -> 1.0011646 | E14: =輸入!$B$2+(輸入!$B$8+A14*$B$6)/1000 -> 2.3904341 | F14: =$B$3/E14 -> 0.9064814 | G14: =輸入!$B$2+(輸入!$B$9+A14*$B$5)/1000 -> 2.2483187 | H14: =$B$3/G14 -> 0.96377975
A15: 0.6 | B15: =輸入!$B$2+(輸入!$B$7+A15*$B$5)/1000 -> 2.2422132 | C15: =$B$3/B15 -> 0.9664041 | D15: =$B$4/B15 -> 0.9847768 | E15: =輸入!$B$2+(輸入!$B$8+A15*$B$6)/1000 -> 2.4371747 | F15: =$B$3/E15 -> 0.8890967 | G15: =輸入!$B$2+(輸入!$B$9+A15*$B$5)/1000 -> 2.2850209 | H15: =$B$3/G15 -> 0.94829944
A16: 0.65 | B16: =輸入!$B$2+(輸入!$B$7+A16*$B$5)/1000 -> 2.2605643 | C16: =$B$3/B16 -> 0.9585589 | D16: =$B$4/B16 -> 0.97678245 | E16: =輸入!$B$2+(輸入!$B$8+A16*$B$6)/1000 -> 2.4605451 | F16: =$B$3/E16 -> 0.88065204 | G16: =輸入!$B$2+(輸入!$B$9+A16*$B$5)/1000 -> 2.303372 | H16: =$B$3/G16 -> 0.94074428 | I16: f 為 Assumed；本段判斷區間 0.4–0.9（見 README）
A17: 0.7 | B17: =輸入!$B$2+(輸入!$B$7+A17*$B$5)/1000 -> 2.2789154 | C17: =$B$3/B17 -> 0.95084005 | D17: =$B$4/B17 -> 0.96891686 | E17: =輸入!$B$2+(輸入!$B$8+A17*$B$6)/1000 -> 2.4839154 | F17: =$B$3/E17 -> 0.87236628 | G17: =輸入!$B$2+(輸入!$B$9+A17*$B$5)/1000 -> 2.3217231 | H17: =$B$3/G17 -> 0.93330856
A18: 0.8 | B18: =輸入!$B$2+(輸入!$B$7+A18*$B$5)/1000 -> 2.3156176 | C18: =$B$3/B18 -> 0.93576937 | D18: =$B$4/B18 -> 0.95355967 | E18: =輸入!$B$2+(輸入!$B$8+A18*$B$6)/1000 -> 2.530656 | F18: =$B$3/E18 -> 0.85625386 | G18: =輸入!$B$2+(輸入!$B$9+A18*$B$5)/1000 -> 2.3584253 | H18: =$B$3/G18 -> 0.91878426
A19: 0.9 | B19: =輸入!$B$2+(輸入!$B$7+A19*$B$5)/1000 -> 2.3523198 | C19: =$B$3/B19 -> 0.92116898 | D19: =$B$4/B19 -> 0.9386817 | E19: =輸入!$B$2+(輸入!$B$8+A19*$B$6)/1000 -> 2.5773967 | F19: =$B$3/E19 -> 0.84072584 | G19: =輸入!$B$2+(輸入!$B$9+A19*$B$5)/1000 -> 2.3951275 | H19: =$B$3/G19 -> 0.90470509 | I19: f 為 Assumed；本段判斷區間 0.4–0.9（見 README）
A20: 1 | B20: =輸入!$B$2+(輸入!$B$7+A20*$B$5)/1000 -> 2.389022 | C20: =$B$3/B20 -> 0.9070172 | D20: =$B$4/B20 -> 0.92426087 | E20: =輸入!$B$2+(輸入!$B$8+A20*$B$6)/1000 -> 2.6241374 | F20: =$B$3/E20 -> 0.82575099 | G20: =輸入!$B$2+(輸入!$B$9+A20*$B$5)/1000 -> 2.4318297 | H20: =$B$3/G20 -> 0.8910509
A22: 持平所需最低 f（晚，263 億） | B22: =($B$3-$B$7)*1000/$B$5 -> 0.39475569
A23: 持平所需最低 f（晚，268 億） | B23: =($B$4-$B$7)*1000/$B$5 -> 0.50699832
A24: 持平所需最低 f（早，263 億） | B24: =($B$3-$B$8)*1000/$B$6 -> 0.021722511
A25: 持平所需最低 f（晚，其他站中占比） | B25: =($B$3-(輸入!$B$2+輸入!$B$9/1000))*1000/$B$5 -> 0.27812046
A27: 本段判斷區間的 Q2 倍數（晚）：f＝0.4／0.65／0.9 | B27: =C13 -> 0.99911252 | C27: =C16 -> 0.9585589 | D27: =C19 -> 0.92116898
A28: 同上（早） | B28: =F13 -> 0.9245595 | C28: =F16 -> 0.88065204 | D28: =F19 -> 0.84072584
A30: MAI 自用規模對照（上界檢查）
A31: MAI-Base-2 GPU ÷ Fairwater 兩站 GPU | B31: =輸入!B16/(輸入!B17+輸入!B18) -> 0.03328687 | C31: Derived：Epoch GPU 數為 Analogy；MAI-Base-2 在 8–9 月，晚於 Q2；未載站點
A32: MAI-Base-2 GPU ÷ Wisconsin GPU | B32: =輸入!B16/輸入!B17 -> 0.090707576
A33: Wisconsin 每 GPU 隱含 IT kW（Epoch） | B33: =輸入!B19*1000/輸入!B17 -> 2.0919435
A34: MAI-Base-2 隱含 IT MW | B34: =輸入!B16*B33/1000 -> 33.471095
A35: 若 MAI 只占這次預訓練的量，Fairwater Q2 平均增量中 MAI 上限占比（極端讀法，只作量級） | B35: =B34/B5 -> 0.091196434

Sheet token帳
A1: Q2：GW 路線 token 帳（起點 2.10）逐項只改一個因子（沿用 token帳缺口_A段.xlsx「拆解」頁公式；輸入頁 23–48 列為照抄值）
A3: 每 GW 混合付費產能 | B3: =(輸入!$B$29*輸入!$B$33+輸入!$B$30*輸入!$B$34+輸入!$B$31*輸入!$B$35+輸入!$B$32*輸入!$B$36) -> 1.1596624e+11
A4: GW 路線模型付費 token（M tok/年） | B4: =輸入!$B$23*輸入!$B$25*(1-輸入!$B$26)*B3*輸入!$B$27*輸入!$B$28 -> 2.0937645e+10
A5: 需求面 ChatGPT 付費 token（M tok/年） | B5: =輸入!$B$38*1000000000*輸入!$B$39*365/1000000*(1-輸入!$B$40) -> 2102400000
A6: 需求面付費 token（M tok/年） | B6: =輸入!$B$37+B5 -> 9986400000
A7: 起點 token 帳（應為 2.0966） | B7: =B4/B6 -> 2.0966159
A9: D2 新證據：Codex token 由 Codex 輸出份額推算
A10: ChatGPT 全部 token／日（T，含免費；TK 則數 × 每則） | B10: =輸入!$B$38*輸入!$B$39/1000 -> 14.4
A11: 個人：Codex／ChatGPT 輸出比 | B11: =輸入!$B$52/(1-輸入!$B$52) -> 0.19760479
A12: 組織：Codex／ChatGPT 輸出比 | B12: =輸入!$B$51/(1-輸入!$B$51) -> 1.7247956
B13: w 低 | C13: w 基準 | D13: w 高
A14: 加權 Codex／ChatGPT 比 | B14: =(1-輸入!$B$53)*$B$11+輸入!$B$53*$B$12 -> 0.35032388 | C14: =(1-輸入!$B$54)*$B$11+輸入!$B$54*$B$12 -> 0.50304296 | D14: =(1-輸入!$B$55)*$B$11+輸入!$B$55*$B$12 -> 0.65576205 | E14: Derived（份額為 Interested-party，w、時點比、k 為 Assumed）
A15: Codex token／日，6 月 11 日時點（T，k＝1） | B15: =$B$10*B14*輸入!$B$57 -> 5.0446638 | C15: =$B$10*C14*輸入!$B$57 -> 7.2438186 | D15: =$B$10*D14*輸入!$B$57 -> 9.4429735
A16: Codex token／日，Q2 平均（T，k＝1） | B16: =B15*輸入!$B$56 -> 3.5312647 | C16: =C15*輸入!$B$56 -> 5.070673 | D16: =D15*輸入!$B$56 -> 6.6100814
A17: Codex token／日，Q2 平均（T，k＝2） | B17: =B16*輸入!$B$58/輸入!$B$57 -> 7.0625293 | C17: =C16*輸入!$B$58/輸入!$B$57 -> 10.141346 | D17: =D16*輸入!$B$58/輸入!$B$57 -> 13.220163
A18: token 帳：D2＝Q2 平均（k＝1） | B18: =$B$4/($B$6+B16*1000000000000*365/1000000) -> 1.856946 | C18: =$B$4/($B$6+C16*1000000000000*365/1000000) -> 1.7688012 | D18: =$B$4/($B$6+D16*1000000000000*365/1000000) -> 1.6886451
A19: token 帳：D2＝Q2 平均（k＝2） | B19: =$B$4/($B$6+B17*1000000000000*365/1000000) -> 1.6664496 | C19: =$B$4/($B$6+C17*1000000000000*365/1000000) -> 1.5296361 | D19: =$B$4/($B$6+D17*1000000000000*365/1000000) -> 1.4135826
A20: 對照：A 段 D2 基準 8 T／日的 token 帳（應為 1.622） | B20: =$B$4/($B$6+輸入!$B$45*1000000000000*365/1000000) -> 1.6222684
A22: ChatGPT 每日則數：以 Q2 平均週活 0.95B 重算
A23: 每日則數（B） | B23: =輸入!$B$41*輸入!$B$59/輸入!$B$43 -> 3.3928571
A24: token 帳 | B24: =$B$4/(輸入!$B$37+B23*1000000000*輸入!$B$39*365/1000000*(1-輸入!$B$40)) -> 2.122325
A26: D1（API 季平均倍數）、D3（每則 token）：本段無新值，沿用 A 段 1.87／1.90（基準）
A28: 組合：A 段基準組合（D1 1.15、D2 8、D3 6,000、S1 0.2、S2 0.8）與本段替換
A29: A 段基準組合（應為 1.0138） | B29: =((輸入!$B$24*輸入!$B$25+(輸入!$B$23-輸入!$B$24)*輸入!$B$47)*(1-輸入!$B$26)*(輸入!$B$33*輸入!$B$29+(輸入!$B$34*輸入!$B$30+輸入!$B$35*輸入!$B$31+輸入!$B$36*輸入!$B$32)*輸入!$B$48)*輸入!$B$27*輸入!$B$28)/(輸入!$B$37*輸入!$B$44+輸入!$B$45*1000000000000*365/1000000+輸入!$B$38*1000000000*輸入!$B$46*365/1000000*(1-輸入!$B$40)) -> 1.0138016
A30: 本段：D2 改為 Q2 平均（w 基準、k＝1），其餘同 A 段基準 | B30: =((輸入!$B$24*輸入!$B$25+(輸入!$B$23-輸入!$B$24)*輸入!$B$47)*(1-輸入!$B$26)*(輸入!$B$33*輸入!$B$29+(輸入!$B$34*輸入!$B$30+輸入!$B$35*輸入!$B$31+輸入!$B$36*輸入!$B$32)*輸入!$B$48)*輸入!$B$27*輸入!$B$28)/(輸入!$B$37*輸入!$B$44+$C$16*1000000000000*365/1000000+輸入!$B$38*1000000000*輸入!$B$46*365/1000000*(1-輸入!$B$40)) -> 1.0908368
A31: 本段：D2（w 基準、k＝1）＋週活 0.95 | B31: =((輸入!$B$24*輸入!$B$25+(輸入!$B$23-輸入!$B$24)*輸入!$B$47)*(1-輸入!$B$26)*(輸入!$B$33*輸入!$B$29+(輸入!$B$34*輸入!$B$30+輸入!$B$35*輸入!$B$31+輸入!$B$36*輸入!$B$32)*輸入!$B$48)*輸入!$B$27*輸入!$B$28)/(輸入!$B$37*輸入!$B$44+$C$16*1000000000000*365/1000000+$B$23*1000000000*輸入!$B$46*365/1000000*(1-輸入!$B$40)) -> 1.1050878
A32: 本段：D2（w 基準、k＝2）＋週活 0.95 | B32: =((輸入!$B$24*輸入!$B$25+(輸入!$B$23-輸入!$B$24)*輸入!$B$47)*(1-輸入!$B$26)*(輸入!$B$33*輸入!$B$29+(輸入!$B$34*輸入!$B$30+輸入!$B$35*輸入!$B$31+輸入!$B$36*輸入!$B$32)*輸入!$B$48)*輸入!$B$27*輸入!$B$28)/(輸入!$B$37*輸入!$B$44+$C$17*1000000000000*365/1000000+$B$23*1000000000*輸入!$B$46*365/1000000*(1-輸入!$B$40)) -> 0.97514827

Sheet 證據表
A1: 編號 | B1: 項目 | C1: 內容（改寫） | D1: 日期 | E1: 標記與誘因 | F1: 用途
A2: F01 | B2: Microsoft 官方 Fairwater 使用者 | C2: 網路供 OpenAI、MAI 超級智慧團隊、Copilot 及其他 AI 工作負載；無比例 | D2: 2025-11-12 | E2: Interested-party：Microsoft（展示規模與多客戶） | F2: 定性；不得換算比例
A3: F02 | B3: Microsoft 對 Atlanta 用途（AP 經 Yahoo） | C3: 供 Microsoft 自家、OpenAI 及其他開發者使用；無比例 | D3: 2025-11-12 | E3: Interested-party：Microsoft | F3: 定性
A4: F03 | B4: Nadella（Dwarkesh 訪談） | C4: 不想只當單一公司的託管商；Fairwater 2 不會永遠只跑一種工作負載；無比例 | D4: 2025-11 | E4: Interested-party：Microsoft（淡化對 OpenAI 依賴） | F4: 下修方向定性
A5: F04 | B5: Hood FY26 Q2 法說 | C5: 新 GPU 先給 Copilot 等第一方，再給 R&D，其餘給 Azure；若全給 Azure，Azure 成長逾 40%；問 Fairwater 時答不聚焦特定地點 | D5: 2026-01-28 | E5: Interested-party：Microsoft CFO | F5: 下修方向定性（第一方優先）
A6: F05 | B6: Nadella FY26 Q3 法說 | C6: Wisconsin 提前約六週上線，得以提前認列營收；未說是誰的營收 | D6: 2026-04-29 | E6: Interested-party：Microsoft | F6: 上修方向定性（有付費客戶承接）；推論
A7: F06 | B7: OpenAI〈MRC supercomputer networking〉 | C7: MRC 部署於 OpenAI 最大的 GB200 超級電腦，含 Microsoft Fairwater；未載份額 | D7: 2026-05-05 | E7: Interested-party：OpenAI | F7: f > 0 的直接證據
A8: F07 | B8: Epoch 目錄頁（Wisconsin、Atlanta） | C8: 使用者 OpenAI、Microsoft 皆 likely；稱可能提供 OpenAI 訓練算力；無比例 | D8: 2026-07-17／07-25 | E8: Analogy：Epoch（衛星＋揭露） | F8: 定性
A9: F08 | B9: SemiAnalysis〈Microsoft AI strategy deconstructed〉 | C9: 稱 Wisconsin 完全供 OpenAI；Azure 大型叢集容量多直接給 OpenAI | D9: 2025-11-12 | E9: Analogy：第三方產業研究（付費客戶導向）；依規不可單獨使用 | F9: 上修方向；需與 F05、F06 並用
A10: F09 | B10: SiliconANGLE | C10: 稱 OpenAI 為 Atlanta 最大客戶之一，另有 Mistral、xAI，Microsoft 保留部分自用；未標出處 | D10: 2025-11-12 | E10: 報導（二手，未標來源） | F10: 弱
A11: F10 | B11: Microsoft AI〈Frontier Pre-training at Microsoft AI〉 | C11: MAI-Base-2 用 16k GB200、38 天、2026 年 8–9 月；未載站點；MAI 算力快速擴張但未給總量 | D11: 2026-10-15 | E11: Interested-party：Microsoft AI | F11: MAI 自用量級上界檢查
A12: F11 | B12: Microsoft FY26 Q4 法說 | C12: 當季新增 1 GW；Maia 200 同時支援 OpenAI 與 MAI 模型；未提 Fairwater 與分配 | D12: 2026-07-29 | E12: Interested-party：Microsoft | F12: 已搜尋，未找到分配
... A23: T08 | B23: DigitalToday（OpenAI Enterprise Signal 報告） | C23: 企業客戶輸出 token 64% 來自 Codex；無絕對量 | D23: 2026-08-13 | E23: Interested-party：OpenAI；二手 | F23: 與 T03 一致
